20250411-02:06:43.227604000 : 8=FIXT.1.19=58235=W49=Coinbase56=24ab46f784d1b20db435b852086e325034=19350=TEST52=20250411-02:06:42.847473369=2262=ecae6588-1a56-49ad-9a18-1bac314fe7a483=1597589724893=Y55=BTC-USD1682=full_trading268=5269=1278=124e6fc1-6dde-452b-be03-c00113c8ebdb270=900000.00271=0.00011111269=1278=b71cc7f5-d7c6-4fc0-a0de-59b0eb7fd063270=1000000.00271=1.00000000269=1278=afec127b-a98c-49cb-893f-e385a7e35d32270=1000000.00271=1.00000000269=1278=06df7c57-366d-4d2c-acc2-e6c26d60e9c3270=1000000.00271=1.00000000269=1278=b1c4eb2b-90df-44e0-ae4f-515df4086a9d270=9999999.00271=0.0000100010=227
20250411-02:06:43.229956000 : 8=FIXT.1.19=14235=334=4649=24ab46f784d1b20db435b852086e325052=20250411-02:06:43.22856=Coinbase45=19358=Tag appears more than once371=269372=W373=1310=052
20250411-02:06:43.230213000 : 8=FIXT.1.19=28335=X49=Coinbase56=24ab46f784d1b20db435b852086e325034=19450=TEST52=20250411-02:06:43.063223369=2262=ecae6588-1a56-49ad-9a18-1bac314fe7a4268=1279=0269=083=159758972555=BTC-USD270=3.39271=0.6232294660=20250411-02:06:43.06163840=237=0b2956b9-567d-4ccd-9f8c-345c32321b8110=107
20250411-02:06:43.230514000 : 8=FIXT.1.19=27935=X49=Coinbase56=24ab46f784d1b20db435b852086e325034=19550=TEST52=20250411-02:06:43.063231369=2262=ecae6588-1a56-49ad-9a18-1bac314fe7a4268=1279=0269=0278=0b2956b9-567d-4ccd-9f8c-345c32321b8183=159758972655=BTC-USD270=3.39271=0.6232294660=20250411-02:06:43.06163810=212
20250411-02:06:43.654984000 : 8=FIXT.1.19=27935=X49=Coinbase56=24ab46f784d1b20db435b852086e325034=19650=TEST52=20250411-02:06:43.536266369=46262=ecae6588-1a56-49ad-9a18-1bac314fe7a4268=1279=0269=083=159758972755=BTC-USD29004=2.208895519560=20250411-02:06:43.53422840=137=0865ac18-169a-4db3-b65f-4cf11c21ca8310=059
20250411-02:06:43.655640000 : 8=FIXT.1.19=32735=X49=Coinbase56=24ab46f784d1b20db435b852086e325034=19750=TEST52=20250411-02:06:43.536273369=46262=ecae6588-1a56-49ad-9a18-1bac314fe7a4268=1279=0269=2278=c5b88ea9-605d-4595-ac52-f7c3f08523ba83=159758972855=BTC-USD270=3.55271=0.6222240960=20250411-02:06:43.53422837=0865ac18-169a-4db3-b65f-4cf11c21ca835797=110=204
20250411-02:06:43.656056000 : 8=FIXT.1.19=26635=X49=Coinbase56=24ab46f784d1b20db435b852086e325034=19850=TEST52=20250411-02:06:43.536278369=46262=ecae6588-1a56-49ad-9a18-1bac314fe7a4268=1279=2269=0278=0865ac18-169a-4db3-b65f-4cf11c21ca8383=159758972955=BTC-USD60=20250411-02:06:43.53422858=FILLED10=078
20250411-02:06:43.684238000 : 8=FIXT.1.19=27535=X49=Coinbase56=24ab46f784d1b20db435b852086e325034=19950=TEST52=20250411-02:06:43.563621369=46262=ecae6588-1a56-49ad-9a18-1bac314fe7a4268=1279=0269=183=159758973055=BTC-USD271=0.6232294660=20250411-02:06:43.56214840=137=2252594e-b87b-41f5-9193-89d6594bbe1d10=234
20250411-02:06:43.684385000 : 8=FIXT.1.19=32735=X49=Coinbase56=24ab46f784d1b20db435b852086e325034=20050=TEST52=20250411-02:06:43.563628369=46262=ecae6588-1a56-49ad-9a18-1bac314fe7a4268=1279=0269=2278=4d60a78e-b39b-420e-b830-bc0f3f4fdde283=159758973155=BTC-USD270=3.53271=0.6232294660=20250411-02:06:43.56214837=2252594e-b87b-41f5-9193-89d6594bbe1d5797=210=212
20250411-02:06:43.684534000 : 8=FIXT.1.19=28135=X49=Coinbase56=24ab46f784d1b20db435b852086e325034=20150=TEST52=20250411-02:06:43.563632369=46262=ecae6588-1a56-49ad-9a18-1bac314fe7a4268=1279=2269=1278=2252594e-b87b-41f5-9193-89d6594bbe1d83=159758973255=BTC-USD271=0.0000000060=20250411-02:06:43.56214858=FILLED10=122
20250411-02:06:43.883741000 : 8=FIXT.1.19=27935=X49=Coinbase56=24ab46f784d1b20db435b852086e325034=20250=TEST52=20250411-02:06:43.764022369=46262=ecae6588-1a56-49ad-9a18-1bac314fe7a4268=1279=0269=083=159758973355=BTC-USD29004=2.208895519560=20250411-02:06:43.76228240=137=718ee2de-3b11-49b0-b51f-7aec36463fec10=144
20250411-02:06:43.884482000 : 8=FIXT.1.19=32735=X49=Coinbase56=24ab46f784d1b20db435b852086e325034=20350=TEST52=20250411-02:06:43.764083369=46262=ecae6588-1a56-49ad-9a18-1bac314fe7a4268=1279=0269=2278=c5b88ea9-605d-4595-ac52-f7c3f08523ba83=159758973455=BTC-USD270=3.55271=0.6222240960=20250411-02:06:43.76228237=718ee2de-3b11-49b0-b51f-7aec36463fec5797=110=042
20250411-02:06:43.884717000 : 8=FIXT.1.19=26635=X49=Coinbase56=24ab46f784d1b20db435b852086e325034=20450=TEST52=20250411-02:06:43.764090369=46262=ecae6588-1a56-49ad-9a18-1bac314fe7a4268=1279=2269=0278=718ee2de-3b11-49b0-b51f-7aec36463fec83=159758973555=BTC-USD60=20250411-02:06:43.76228258=FILLED10=165
20250411-02:06:43.912662000 : 8=FIXT.1.19=27535=X49=Coinbase56=24ab46f784d1b20db435b852086e325034=20550=TEST52=20250411-02:06:43.792405369=46262=ecae6588-1a56-49ad-9a18-1bac314fe7a4268=1279=0269=183=159758973655=BTC-USD271=0.6232294660=20250411-02:06:43.79139040=137=f7e46ec8-b95f-479a-a134-e233298d422f10=071
20250411-02:06:43.913142000 : 8=FIXT.1.19=32735=X49=Coinbase56=24ab46f784d1b20db435b852086e325034=20650=TEST52=20250411-02:06:43.792411369=46262=ecae6588-1a56-49ad-9a18-1bac314fe7a4268=1279=0269=2278=4d60a78e-b39b-420e-b830-bc0f3f4fdde283=159758973755=BTC-USD270=3.53271=0.6232294660=20250411-02:06:43.79139037=f7e46ec8-b95f-479a-a134-e233298d422f5797=210=057
20250411-02:06:43.913308000 : 8=FIXT.1.19=28135=X49=Coinbase56=24ab46f784d1b20db435b852086e325034=20750=TEST52=20250411-02:06:43.792415369=46262=ecae6588-1a56-49ad-9a18-1bac314fe7a4268=1279=2269=1278=f7e46ec8-b95f-479a-a134-e233298d422f83=159758973855=BTC-USD271=0.0000000060=20250411-02:06:43.79139058=FILLED10=232
20250411-02:06:43.940156000 : 8=FIXT.1.19=27935=X49=Coinbase56=24ab46f784d1b20db435b852086e325034=20850=TEST52=20250411-02:06:43.820905369=46262=ecae6588-1a56-49ad-9a18-1bac314fe7a4268=1279=0269=083=159758973955=BTC-USD29004=2.208895519560=20250411-02:06:43.81983140=137=8df532b1-2c7e-4611-a799-cb8bac70eb5410=117
20250411-02:06:43.940416000 : 8=FIXT.1.19=32735=X49=Coinbase56=24ab46f784d1b20db435b852086e325034=20950=TEST52=20250411-02:06:43.820912369=46262=ecae6588-1a56-49ad-9a18-1bac314fe7a4268=1279=0269=2278=c5b88ea9-605d-4595-ac52-f7c3f08523ba83=159758974055=BTC-USD270=3.55271=0.6222240960=20250411-02:06:43.81983137=8df532b1-2c7e-4611-a799-cb8bac70eb545797=110=253
20250411-02:06:43.940592000 : 8=FIXT.1.19=26635=X49=Coinbase56=24ab46f784d1b20db435b852086e325034=21050=TEST52=20250411-02:06:43.820915369=46262=ecae6588-1a56-49ad-9a18-1bac314fe7a4268=1279=2269=0278=8df532b1-2c7e-4611-a799-cb8bac70eb5483=159758974155=BTC-USD60=20250411-02:06:43.81983158=FILLED10=116
20250411-02:06:43.968869000 : 8=FIXT.1.19=27535=X49=Coinbase56=24ab46f784d1b20db435b852086e325034=21150=TEST52=20250411-02:06:43.849375369=46262=ecae6588-1a56-49ad-9a18-1bac314fe7a4268=1279=0269=183=159758974255=BTC-USD271=0.6197183160=20250411-02:06:43.84802140=137=0abd22e2-2b22-4850-a195-8b8a140aa49d10=026
20250411-02:06:43.969210000 : 8=FIXT.1.19=32735=X49=Coinbase56=24ab46f784d1b20db435b852086e325034=21250=TEST52=20250411-02:06:43.849390369=46262=ecae6588-1a56-49ad-9a18-1bac314fe7a4268=1279=0269=2278=4d60a78e-b39b-420e-b830-bc0f3f4fdde283=159758974355=BTC-USD270=3.53271=0.6197183160=20250411-02:06:43.84802137=0abd22e2-2b22-4850-a195-8b8a140aa49d5797=210=012
20250411-02:06:43.969391000 : 8=FIXT.1.19=28135=X49=Coinbase56=24ab46f784d1b20db435b852086e325034=21350=TEST52=20250411-02:06:43.849394369=46262=ecae6588-1a56-49ad-9a18-1bac314fe7a4268=1279=2269=1278=0abd22e2-2b22-4850-a195-8b8a140aa49d83=159758974455=BTC-USD271=0.0000000060=20250411-02:06:43.84802158=FILLED10=185
20250411-02:06:44.054340000 : 8=FIXT.1.19=27935=X49=Coinbase56=24ab46f784d1b20db435b852086e325034=21450=TEST52=20250411-02:06:43.935713369=46262=ecae6588-1a56-49ad-9a18-1bac314fe7a4268=1279=0269=083=159758974555=BTC-USD29004=2.208895519560=20250411-02:06:43.93389340=137=5d65a451-b4f7-4850-8776-e9c1a955be9c10=000
20250411-02:06:44.054773000 : 8=FIXT.1.19=32735=X49=Coinbase56=24ab46f784d1b20db435b852086e325034=21550=TEST52=20250411-02:06:43.935717369=46262=ecae6588-1a56-49ad-9a18-1bac314fe7a4268=1279=0269=2278=c5b88ea9-605d-4595-ac52-f7c3f08523ba83=159758974655=BTC-USD270=3.55271=0.6222240960=20250411-02:06:43.93389337=5d65a451-b4f7-4850-8776-e9c1a955be9c5797=110=151
20250411-02:06:44.054962000 : 8=FIXT.1.19=26635=X49=Coinbase56=24ab46f784d1b20db435b852086e325034=21650=TEST52=20250411-02:06:43.935722369=46262=ecae6588-1a56-49ad-9a18-1bac314fe7a4268=1279=2269=0278=5d65a451-b4f7-4850-8776-e9c1a955be9c83=159758974755=BTC-USD60=20250411-02:06:43.93389358=FILLED10=016
20250411-02:06:44.083704000 : 8=FIXT.1.19=27535=X49=Coinbase56=24ab46f784d1b20db435b852086e325034=21750=TEST52=20250411-02:06:43.964020369=46262=ecae6588-1a56-49ad-9a18-1bac314fe7a4268=1279=0269=183=159758974855=BTC-USD271=0.6232294660=20250411-02:06:43.96223740=137=2ecd1039-923a-4159-8255-7d15182e864510=078
20250411-02:06:44.084060000 : 8=FIXT.1.19=32735=X49=Coinbase56=24ab46f784d1b20db435b852086e325034=21850=TEST52=20250411-02:06:43.964026369=46262=ecae6588-1a56-49ad-9a18-1bac314fe7a4268=1279=0269=2278=4d60a78e-b39b-420e-b830-bc0f3f4fdde283=159758974955=BTC-USD270=3.53271=0.6232294660=20250411-02:06:43.96223737=2ecd1039-923a-4159-8255-7d15182e86455797=210=073
20250411-02:06:44.084218000 : 8=FIXT.1.19=28135=X49=Coinbase56=24ab46f784d1b20db435b852086e325034=21950=TEST52=20250411-02:06:43.964030369=46262=ecae6588-1a56-49ad-9a18-1bac314fe7a4268=1279=2269=1278=2ecd1039-923a-4159-8255-7d15182e864583=159758975055=BTC-USD271=0.0000000060=20250411-02:06:43.96223758=FILLED10=230
20250411-02:06:44.112537000 : 8=FIXT.1.19=27935=X49=Coinbase56=24ab46f784d1b20db435b852086e325034=22050=TEST52=20250411-02:06:43.993433369=46262=ecae6588-1a56-49ad-9a18-1bac314fe7a4268=1279=0269=083=159758975155=BTC-USD29004=2.208895519560=20250411-02:06:43.99149540=137=75a05270-54fe-4df9-b6ee-53e85cab384b10=128
20250411-02:06:44.112748000 : 8=FIXT.1.19=32735=X49=Coinbase56=24ab46f784d1b20db435b852086e325034=22150=TEST52=20250411-02:06:43.993437369=46262=ecae6588-1a56-49ad-9a18-1bac314fe7a4268=1279=0269=2278=c5b88ea9-605d-4595-ac52-f7c3f08523ba83=159758975255=BTC-USD270=3.55271=0.6222240960=20250411-02:06:43.99149537=75a05270-54fe-4df9-b6ee-53e85cab384b5797=110=023
20250411-02:06:44.112899000 : 8=FIXT.1.19=26635=X49=Coinbase56=24ab46f784d1b20db435b852086e325034=22250=TEST52=20250411-02:06:43.993441369=46262=ecae6588-1a56-49ad-9a18-1bac314fe7a4268=1279=2269=0278=75a05270-54fe-4df9-b6ee-53e85cab384b83=159758975355=BTC-USD60=20250411-02:06:43.99149558=FILLED10=143
20250411-02:06:44.140763000 : 8=FIXT.1.19=27535=X49=Coinbase56=24ab46f784d1b20db435b852086e325034=22350=TEST52=20250411-02:06:44.021387369=46262=ecae6588-1a56-49ad-9a18-1bac314fe7a4268=1279=0269=183=159758975455=BTC-USD271=0.6197183160=20250411-02:06:44.01955240=137=1e1c3033-330c-4a10-91ec-f89ee3509e5610=242
20250411-02:06:44.141034000 : 8=FIXT.1.19=32735=X49=Coinbase56=24ab46f784d1b20db435b852086e325034=22450=TEST52=20250411-02:06:44.021433369=46262=ecae6588-1a56-49ad-9a18-1bac314fe7a4268=1279=0269=2278=4d60a78e-b39b-420e-b830-bc0f3f4fdde283=159758975555=BTC-USD270=3.53271=0.6197183160=20250411-02:06:44.01955237=1e1c3033-330c-4a10-91ec-f89ee3509e565797=210=223
20250411-02:06:44.141177000 : 8=FIXT.1.19=28135=X49=Coinbase56=24ab46f784d1b20db435b852086e325034=22550=TEST52=20250411-02:06:44.021439369=46262=ecae6588-1a56-49ad-9a18-1bac314fe7a4268=1279=2269=1278=1e1c3033-330c-4a10-91ec-f89ee3509e5683=159758975655=BTC-USD271=0.0000000060=20250411-02:06:44.01955258=FILLED10=142
20250411-02:06:44.261281000 : 8=FIXT.1.19=28435=X49=Coinbase56=24ab46f784d1b20db435b852086e325034=22650=TEST52=20250411-02:06:44.137821369=46262=ecae6588-1a56-49ad-9a18-1bac314fe7a4268=1279=0269=183=159758975755=BTC-USD270=3.18271=0.6232294660=20250411-02:06:44.13612740=237=8ded5394-9ef6-4747-ba2f-42f9e4fbb0b310=115
20250411-02:06:44.261576000 : 8=FIXT.1.19=32735=X49=Coinbase56=24ab46f784d1b20db435b852086e325034=22750=TEST52=20250411-02:06:44.137831369=46262=ecae6588-1a56-49ad-9a18-1bac314fe7a4268=1279=0269=2278=4d60a78e-b39b-420e-b830-bc0f3f4fdde283=159758975855=BTC-USD270=3.53271=0.6232294660=20250411-02:06:44.13612737=8ded5394-9ef6-4747-ba2f-42f9e4fbb0b35797=210=199
20250411-02:06:44.261757000 : 8=FIXT.1.19=29035=X49=Coinbase56=24ab46f784d1b20db435b852086e325034=22850=TEST52=20250411-02:06:44.137835369=46262=ecae6588-1a56-49ad-9a18-1bac314fe7a4268=1279=2269=1278=8ded5394-9ef6-4747-ba2f-42f9e4fbb0b383=159758975955=BTC-USD270=3.18271=0.0000000060=20250411-02:06:44.13612758=FILLED10=023
20250411-02:06:44.314143000 : 8=FIXT.1.19=28435=X49=Coinbase56=24ab46f784d1b20db435b852086e325034=22950=TEST52=20250411-02:06:44.192251369=46262=ecae6588-1a56-49ad-9a18-1bac314fe7a4268=1279=0269=083=159758976055=BTC-USD270=3.78271=0.6232294660=20250411-02:06:44.19155440=237=eeaeda94-ba22-4e41-b5f2-8f873abd544f10=198
20250411-02:06:44.314438000 : 8=FIXT.1.19=32735=X49=Coinbase56=24ab46f784d1b20db435b852086e325034=23050=TEST52=20250411-02:06:44.192263369=46262=ecae6588-1a56-49ad-9a18-1bac314fe7a4268=1279=0269=2278=c5b88ea9-605d-4595-ac52-f7c3f08523ba83=159758976155=BTC-USD270=3.55271=0.6232294660=20250411-02:06:44.19155437=eeaeda94-ba22-4e41-b5f2-8f873abd544f5797=110=143
20250411-02:06:44.314615000 : 8=FIXT.1.19=29035=X49=Coinbase56=24ab46f784d1b20db435b852086e325034=23150=TEST52=20250411-02:06:44.192267369=46262=ecae6588-1a56-49ad-9a18-1bac314fe7a4268=1279=2269=0278=eeaeda94-ba22-4e41-b5f2-8f873abd544f83=159758976255=BTC-USD270=3.78271=0.0000000060=20250411-02:06:44.19155458=FILLED10=099
20250411-02:06:44.372006000 : 8=FIXT.1.19=28435=X49=Coinbase56=24ab46f784d1b20db435b852086e325034=23250=TEST52=20250411-02:06:44.252736369=46262=ecae6588-1a56-49ad-9a18-1bac314fe7a4268=1279=0269=083=159758976355=BTC-USD270=3.78271=0.6197183160=20250411-02:06:44.25073940=237=99a7a6ea-acfc-4553-99cc-e585f5e2f80a10=176
20250411-02:06:44.372532000 : 8=FIXT.1.19=32735=X49=Coinbase56=24ab46f784d1b20db435b852086e325034=23350=TEST52=20250411-02:06:44.252748369=46262=ecae6588-1a56-49ad-9a18-1bac314fe7a4268=1279=0269=2278=c5b88ea9-605d-4595-ac52-f7c3f08523ba83=159758976455=BTC-USD270=3.55271=0.6197183160=20250411-02:06:44.25073937=99a7a6ea-acfc-4553-99cc-e585f5e2f80a5797=110=130
20250411-02:06:44.372872000 : 8=FIXT.1.19=29035=X49=Coinbase56=24ab46f784d1b20db435b852086e325034=23450=TEST52=20250411-02:06:44.252752369=46262=ecae6588-1a56-49ad-9a18-1bac314fe7a4268=1279=2269=0278=99a7a6ea-acfc-4553-99cc-e585f5e2f80a83=159758976555=BTC-USD270=3.78271=0.0000000060=20250411-02:06:44.25073958=FILLED10=075
20250411-02:06:44.428466000 : 8=FIXT.1.19=28335=X49=Coinbase56=24ab46f784d1b20db435b852086e325034=23550=TEST52=20250411-02:06:44.307799369=46262=ecae6588-1a56-49ad-9a18-1bac314fe7a4268=1279=0269=183=159758976655=BTC-USD270=3.3271=0.6197183160=20250411-02:06:44.30662140=237=cb1b8c54-73e7-4c66-ac82-c7843d5f923110=177
20250411-02:06:44.429028000 : 8=FIXT.1.19=32735=X49=Coinbase56=24ab46f784d1b20db435b852086e325034=23650=TEST52=20250411-02:06:44.307811369=46262=ecae6588-1a56-49ad-9a18-1bac314fe7a4268=1279=0269=2278=4d60a78e-b39b-420e-b830-bc0f3f4fdde283=159758976755=BTC-USD270=3.53271=0.6197183160=20250411-02:06:44.30662137=cb1b8c54-73e7-4c66-ac82-c7843d5f92315797=210=044
20250411-02:06:44.429349000 : 8=FIXT.1.19=28935=X49=Coinbase56=24ab46f784d1b20db435b852086e325034=23750=TEST52=20250411-02:06:44.307826369=46262=ecae6588-1a56-49ad-9a18-1bac314fe7a4268=1279=2269=1278=cb1b8c54-73e7-4c66-ac82-c7843d5f923183=159758976855=BTC-USD270=3.3271=0.0000000060=20250411-02:06:44.30662158=FILLED10=078
20250411-02:06:44.798224000 : 8=FIXT.1.19=27935=X49=Coinbase56=24ab46f784d1b20db435b852086e325034=23850=TEST52=20250411-02:06:44.677593369=46262=ecae6588-1a56-49ad-9a18-1bac314fe7a4268=1279=0269=083=159758976955=BTC-USD29004=2.208895519560=20250411-02:06:44.67625240=137=e81df3ee-0d68-460d-9a14-ddeef614fc7b10=033
20250411-02:06:44.799811000 : 8=FIXT.1.19=32735=X49=Coinbase56=24ab46f784d1b20db435b852086e325034=23950=TEST52=20250411-02:06:44.677602369=46262=ecae6588-1a56-49ad-9a18-1bac314fe7a4268=1279=0269=2278=c5b88ea9-605d-4595-ac52-f7c3f08523ba83=159758977055=BTC-USD270=3.55271=0.6222240960=20250411-02:06:44.67625237=e81df3ee-0d68-460d-9a14-ddeef614fc7b5797=110=162
20250411-02:06:44.800039000 : 8=FIXT.1.19=26635=X49=Coinbase56=24ab46f784d1b20db435b852086e325034=24050=TEST52=20250411-02:06:44.677606369=46262=ecae6588-1a56-49ad-9a18-1bac314fe7a4268=1279=2269=0278=e81df3ee-0d68-460d-9a14-ddeef614fc7b83=159758977155=BTC-USD60=20250411-02:06:44.67625258=FILLED10=026
20250411-02:06:44.826569000 : 8=FIXT.1.19=27535=X49=Coinbase56=24ab46f784d1b20db435b852086e325034=24150=TEST52=20250411-02:06:44.707147369=46262=ecae6588-1a56-49ad-9a18-1bac314fe7a4268=1279=0269=183=159758977255=BTC-USD271=0.6232294660=20250411-02:06:44.70540340=137=dde0f70f-4fd1-4684-a768-a25ba8a0030810=086
20250411-02:06:44.826744000 : 8=FIXT.1.19=32735=X49=Coinbase56=24ab46f784d1b20db435b852086e325034=24250=TEST52=20250411-02:06:44.707155369=46262=ecae6588-1a56-49ad-9a18-1bac314fe7a4268=1279=0269=2278=4d60a78e-b39b-420e-b830-bc0f3f4fdde283=159758977355=BTC-USD270=3.53271=0.6232294660=20250411-02:06:44.70540337=dde0f70f-4fd1-4684-a768-a25ba8a003085797=210=074
20250411-02:06:44.827182000 : 8=FIXT.1.19=28135=X49=Coinbase56=24ab46f784d1b20db435b852086e325034=24350=TEST52=20250411-02:06:44.707159369=46262=ecae6588-1a56-49ad-9a18-1bac314fe7a4268=1279=2269=1278=dde0f70f-4fd1-4684-a768-a25ba8a0030883=159758977455=BTC-USD271=0.0000000060=20250411-02:06:44.70540358=FILLED10=249
20250411-02:06:44.829715000 : 8=FIXT.1.19=28435=X49=Coinbase56=24ab46f784d1b20db435b852086e325034=24450=TEST52=20250411-02:06:44.710746369=46262=ecae6588-1a56-49ad-9a18-1bac314fe7a4268=1279=0269=083=159758977555=BTC-USD270=3.79271=0.6197183160=20250411-02:06:44.70913740=237=bfeefa67-f3a4-4001-a816-d778a241cd1b10=104
20250411-02:06:44.829955000 : 8=FIXT.1.19=32735=X49=Coinbase56=24ab46f784d1b20db435b852086e325034=24550=TEST52=20250411-02:06:44.710751369=46262=ecae6588-1a56-49ad-9a18-1bac314fe7a4268=1279=0269=2278=c5b88ea9-605d-4595-ac52-f7c3f08523ba83=159758977655=BTC-USD270=3.55271=0.6197183160=20250411-02:06:44.70913737=bfeefa67-f3a4-4001-a816-d778a241cd1b5797=110=050
20250411-02:06:44.830130000 : 8=FIXT.1.19=29035=X49=Coinbase56=24ab46f784d1b20db435b852086e325034=24650=TEST52=20250411-02:06:44.710754369=46262=ecae6588-1a56-49ad-9a18-1bac314fe7a4268=1279=2269=0278=bfeefa67-f3a4-4001-a816-d778a241cd1b83=159758977755=BTC-USD270=3.79271=0.0000000060=20250411-02:06:44.70913758=FILLED10=004
20250411-02:06:44.883822000 : 8=FIXT.1.19=28435=X49=Coinbase56=24ab46f784d1b20db435b852086e325034=24750=TEST52=20250411-02:06:44.764848369=46262=ecae6588-1a56-49ad-9a18-1bac314fe7a4268=1279=0269=183=159758977855=BTC-USD270=3.35271=0.6197183160=20250411-02:06:44.76295340=237=efec44df-fe6d-4363-ae2f-b6af0832289e10=239
20250411-02:06:44.884356000 : 8=FIXT.1.19=32735=X49=Coinbase56=24ab46f784d1b20db435b852086e325034=24850=TEST52=20250411-02:06:44.764855369=46262=ecae6588-1a56-49ad-9a18-1bac314fe7a4268=1279=0269=2278=4d60a78e-b39b-420e-b830-bc0f3f4fdde283=159758977955=BTC-USD270=3.53271=0.6197183160=20250411-02:06:44.76295337=efec44df-fe6d-4363-ae2f-b6af0832289e5797=210=065
20250411-02:06:44.884538000 : 8=FIXT.1.19=29035=X49=Coinbase56=24ab46f784d1b20db435b852086e325034=24950=TEST52=20250411-02:06:44.764862369=46262=ecae6588-1a56-49ad-9a18-1bac314fe7a4268=1279=2269=1278=efec44df-fe6d-4363-ae2f-b6af0832289e83=159758978055=BTC-USD270=3.35271=0.0000000060=20250411-02:06:44.76295358=FILLED10=127
20250411-02:06:45.083846000 : 8=FIXT.1.19=27935=X49=Coinbase56=24ab46f784d1b20db435b852086e325034=25050=TEST52=20250411-02:06:44.963045369=46262=ecae6588-1a56-49ad-9a18-1bac314fe7a4268=1279=0269=083=159758978155=BTC-USD29004=2.208895519560=20250411-02:06:44.96195340=137=991eb6e7-37ea-4367-8cc9-4721b85c7d9f10=056
20250411-02:06:45.084507000 : 8=FIXT.1.19=32735=X49=Coinbase56=24ab46f784d1b20db435b852086e325034=25150=TEST52=20250411-02:06:44.963051369=46262=ecae6588-1a56-49ad-9a18-1bac314fe7a4268=1279=0269=2278=c5b88ea9-605d-4595-ac52-f7c3f08523ba83=159758978255=BTC-USD270=3.55271=0.6222240960=20250411-02:06:44.96195337=991eb6e7-37ea-4367-8cc9-4721b85c7d9f5797=110=200
20250411-02:06:45.084684000 : 8=FIXT.1.19=26635=X49=Coinbase56=24ab46f784d1b20db435b852086e325034=25250=TEST52=20250411-02:06:44.963054369=46262=ecae6588-1a56-49ad-9a18-1bac314fe7a4268=1279=2269=0278=991eb6e7-37ea-4367-8cc9-4721b85c7d9f83=159758978355=BTC-USD60=20250411-02:06:44.96195358=FILLED10=072
20250411-02:06:45.112241000 : 8=FIXT.1.19=27535=X49=Coinbase56=24ab46f784d1b20db435b852086e325034=25350=TEST52=20250411-02:06:44.992443369=46262=ecae6588-1a56-49ad-9a18-1bac314fe7a4268=1279=0269=183=159758978455=BTC-USD271=0.6232294660=20250411-02:06:44.99078740=137=9eb377a9-cd98-4c25-9321-07c8eba04bea10=178
20250411-02:06:45.112672000 : 8=FIXT.1.19=32735=X49=Coinbase56=24ab46f784d1b20db435b852086e325034=25450=TEST52=20250411-02:06:44.992449369=46262=ecae6588-1a56-49ad-9a18-1bac314fe7a4268=1279=0269=2278=4d60a78e-b39b-420e-b830-bc0f3f4fdde283=159758978555=BTC-USD270=3.53271=0.6232294660=20250411-02:06:44.99078737=9eb377a9-cd98-4c25-9321-07c8eba04bea5797=210=173
20250411-02:06:45.112871000 : 8=FIXT.1.19=28135=X49=Coinbase56=24ab46f784d1b20db435b852086e325034=25550=TEST52=20250411-02:06:44.992454369=46262=ecae6588-1a56-49ad-9a18-1bac314fe7a4268=1279=2269=1278=9eb377a9-cd98-4c25-9321-07c8eba04bea83=159758978655=BTC-USD271=0.0000000060=20250411-02:06:44.99078758=FILLED10=084
20250411-02:06:45.171436000 : 8=FIXT.1.19=28435=X49=Coinbase56=24ab46f784d1b20db435b852086e325034=25650=TEST52=20250411-02:06:45.051248369=46262=ecae6588-1a56-49ad-9a18-1bac314fe7a4268=1279=0269=083=159758978755=BTC-USD270=3.76271=0.6232294660=20250411-02:06:45.05007640=237=e4ab93de-7faa-4c76-9eee-5b80d6b2613010=155
20250411-02:06:45.171654000 : 8=FIXT.1.19=32735=X49=Coinbase56=24ab46f784d1b20db435b852086e325034=25750=TEST52=20250411-02:06:45.051254369=46262=ecae6588-1a56-49ad-9a18-1bac314fe7a4268=1279=0269=2278=c5b88ea9-605d-4595-ac52-f7c3f08523ba83=159758978855=BTC-USD270=3.55271=0.6232294660=20250411-02:06:45.05007637=e4ab93de-7faa-4c76-9eee-5b80d6b261305797=110=105
20250411-02:06:45.171842000 : 8=FIXT.1.19=29035=X49=Coinbase56=24ab46f784d1b20db435b852086e325034=25850=TEST52=20250411-02:06:45.051256369=46262=ecae6588-1a56-49ad-9a18-1bac314fe7a4268=1279=2269=0278=e4ab93de-7faa-4c76-9eee-5b80d6b2613083=159758978955=BTC-USD270=3.76271=0.0000000060=20250411-02:06:45.05007658=FILLED10=057
20250411-02:06:45.227976000 : 8=FIXT.1.19=28435=X49=Coinbase56=24ab46f784d1b20db435b852086e325034=25950=TEST52=20250411-02:06:45.107029369=46262=ecae6588-1a56-49ad-9a18-1bac314fe7a4268=1279=0269=183=159758979055=BTC-USD270=3.26271=0.6232294660=20250411-02:06:45.10614640=237=af457ec7-4016-41f3-b93b-6d5e4c0782f710=216
20250411-02:06:45.228332000 : 8=FIXT.1.19=32735=X49=Coinbase56=24ab46f784d1b20db435b852086e325034=26050=TEST52=20250411-02:06:45.107033369=46262=ecae6588-1a56-49ad-9a18-1bac314fe7a4268=1279=0269=2278=4d60a78e-b39b-420e-b830-bc0f3f4fdde283=159758979155=BTC-USD270=3.53271=0.6232294660=20250411-02:06:45.10614637=af457ec7-4016-41f3-b93b-6d5e4c0782f75797=210=030
20250411-02:06:45.228536000 : 8=FIXT.1.19=29035=X49=Coinbase56=24ab46f784d1b20db435b852086e325034=26150=TEST52=20250411-02:06:45.107036369=46262=ecae6588-1a56-49ad-9a18-1bac314fe7a4268=1279=2269=1278=af457ec7-4016-41f3-b93b-6d5e4c0782f783=159758979255=BTC-USD270=3.26271=0.0000000060=20250411-02:06:45.10614658=FILLED10=108
20250411-02:06:45.721865000 : 8=FIXT.1.19=27935=X49=Coinbase56=24ab46f784d1b20db435b852086e325034=26250=TEST52=20250411-02:06:45.594023369=46262=ecae6588-1a56-49ad-9a18-1bac314fe7a4268=1279=0269=083=159758979355=BTC-USD29004=2.208895519560=20250411-02:06:45.59278040=137=18358f63-d93b-4b5e-81cc-4f376e6876de10=053
20250411-02:06:45.722541000 : 8=FIXT.1.19=32735=X49=Coinbase56=24ab46f784d1b20db435b852086e325034=26350=TEST52=20250411-02:06:45.594030369=46262=ecae6588-1a56-49ad-9a18-1bac314fe7a4268=1279=0269=2278=c5b88ea9-605d-4595-ac52-f7c3f08523ba83=159758979455=BTC-USD270=3.55271=0.6222240960=20250411-02:06:45.59278037=18358f63-d93b-4b5e-81cc-4f376e6876de5797=110=198
20250411-02:06:45.722877000 : 8=FIXT.1.19=26635=X49=Coinbase56=24ab46f784d1b20db435b852086e325034=26450=TEST52=20250411-02:06:45.594034369=46262=ecae6588-1a56-49ad-9a18-1bac314fe7a4268=1279=2269=0278=18358f63-d93b-4b5e-81cc-4f376e6876de83=159758979555=BTC-USD60=20250411-02:06:45.59278058=FILLED10=071
20250411-02:06:45.752395000 : 8=FIXT.1.19=27535=X49=Coinbase56=24ab46f784d1b20db435b852086e325034=26550=TEST52=20250411-02:06:45.621579369=46262=ecae6588-1a56-49ad-9a18-1bac314fe7a4268=1279=0269=183=159758979655=BTC-USD271=0.6232294660=20250411-02:06:45.61951640=137=3479bf21-2992-4797-86ef-6f1400479e9f10=172
20250411-02:06:45.753447000 : 8=FIXT.1.19=32735=X49=Coinbase56=24ab46f784d1b20db435b852086e325034=26650=TEST52=20250411-02:06:45.621588369=46262=ecae6588-1a56-49ad-9a18-1bac314fe7a4268=1279=0269=2278=4d60a78e-b39b-420e-b830-bc0f3f4fdde283=159758979755=BTC-USD270=3.53271=0.6232294660=20250411-02:06:45.61951637=3479bf21-2992-4797-86ef-6f1400479e9f5797=210=161
20250411-02:06:45.755273000 : 8=FIXT.1.19=28135=X49=Coinbase56=24ab46f784d1b20db435b852086e325034=26750=TEST52=20250411-02:06:45.621592369=46262=ecae6588-1a56-49ad-9a18-1bac314fe7a4268=1279=2269=1278=3479bf21-2992-4797-86ef-6f1400479e9f83=159758979855=BTC-USD271=0.0000000060=20250411-02:06:45.61951658=FILLED10=071
20250411-02:06:46.115111000 : 8=FIXT.1.19=27935=X49=Coinbase56=24ab46f784d1b20db435b852086e325034=26850=TEST52=20250411-02:06:45.991803369=46262=ecae6588-1a56-49ad-9a18-1bac314fe7a4268=1279=0269=083=159758979955=BTC-USD29004=2.208895519560=20250411-02:06:45.99073440=137=474422bf-df9b-4684-9d68-ba51e9369e1a10=066
20250411-02:06:46.115878000 : 8=FIXT.1.19=32735=X49=Coinbase56=24ab46f784d1b20db435b852086e325034=26950=TEST52=20250411-02:06:45.991810369=46262=ecae6588-1a56-49ad-9a18-1bac314fe7a4268=1279=0269=2278=c5b88ea9-605d-4595-ac52-f7c3f08523ba83=159758980055=BTC-USD270=3.55271=0.6222240960=20250411-02:06:45.99073437=474422bf-df9b-4684-9d68-ba51e9369e1a5797=110=193
20250411-02:06:46.116078000 : 8=FIXT.1.19=26635=X49=Coinbase56=24ab46f784d1b20db435b852086e325034=27050=TEST52=20250411-02:06:45.991814369=46262=ecae6588-1a56-49ad-9a18-1bac314fe7a4268=1279=2269=0278=474422bf-df9b-4684-9d68-ba51e9369e1a83=159758980155=BTC-USD60=20250411-02:06:45.99073458=FILLED10=057
20250411-02:06:46.142426000 : 8=FIXT.1.19=27535=X49=Coinbase56=24ab46f784d1b20db435b852086e325034=27150=TEST52=20250411-02:06:46.021702369=46262=ecae6588-1a56-49ad-9a18-1bac314fe7a4268=1279=0269=183=159758980255=BTC-USD271=0.6232294660=20250411-02:06:46.02029340=137=faa88fce-7526-496c-a5dc-e5bca487afde10=124
20250411-02:06:46.142801000 : 8=FIXT.1.19=32735=X49=Coinbase56=24ab46f784d1b20db435b852086e325034=27250=TEST52=20250411-02:06:46.021707369=46262=ecae6588-1a56-49ad-9a18-1bac314fe7a4268=1279=0269=2278=4d60a78e-b39b-420e-b830-bc0f3f4fdde283=159758980355=BTC-USD270=3.53271=0.6232294660=20250411-02:06:46.02029337=faa88fce-7526-496c-a5dc-e5bca487afde5797=210=118
20250411-02:06:46.142955000 : 8=FIXT.1.19=28135=X49=Coinbase56=24ab46f784d1b20db435b852086e325034=27350=TEST52=20250411-02:06:46.021711369=46262=ecae6588-1a56-49ad-9a18-1bac314fe7a4268=1279=2269=1278=faa88fce-7526-496c-a5dc-e5bca487afde83=159758980455=BTC-USD271=0.0000000060=20250411-02:06:46.02029358=FILLED10=028
20250411-02:06:46.210147000 : 8=FIXT.1.19=28835=X49=Coinbase56=24ab46f784d1b20db435b852086e325034=27450=TEST52=20250411-02:06:46.088923369=46262=ecae6588-1a56-49ad-9a18-1bac314fe7a4268=1279=0269=083=159758980555=BTC-USD270=3.54271=27915.8566519360=20250411-02:06:46.08741440=237=24de32b2-a7f5-469c-a714-c9b10ee2cce510=075
20250411-02:06:46.210627000 : 8=FIXT.1.19=28435=X49=Coinbase56=24ab46f784d1b20db435b852086e325034=27550=TEST52=20250411-02:06:46.088929369=46262=ecae6588-1a56-49ad-9a18-1bac314fe7a4268=1279=0269=0278=24de32b2-a7f5-469c-a714-c9b10ee2cce583=159758980655=BTC-USD270=3.54271=27915.8566519360=20250411-02:06:46.08741410=178
20250411-02:06:46.541426000 : 8=FIXT.1.19=27935=X49=Coinbase56=24ab46f784d1b20db435b852086e325034=27650=TEST52=20250411-02:06:46.335577369=46262=ecae6588-1a56-49ad-9a18-1bac314fe7a4268=1279=0269=083=159758980755=BTC-USD29004=2.208895519560=20250411-02:06:46.33448140=137=23bba792-3418-47eb-bce2-a116502907cf10=014
20250411-02:06:46.541732000 : 8=FIXT.1.19=32735=X49=Coinbase56=24ab46f784d1b20db435b852086e325034=27750=TEST52=20250411-02:06:46.335584369=46262=ecae6588-1a56-49ad-9a18-1bac314fe7a4268=1279=0269=2278=c5b88ea9-605d-4595-ac52-f7c3f08523ba83=159758980855=BTC-USD270=3.55271=0.6222240960=20250411-02:06:46.33448137=23bba792-3418-47eb-bce2-a116502907cf5797=110=159
20250411-02:06:46.541918000 : 8=FIXT.1.19=26635=X49=Coinbase56=24ab46f784d1b20db435b852086e325034=27850=TEST52=20250411-02:06:46.335588369=46262=ecae6588-1a56-49ad-9a18-1bac314fe7a4268=1279=2269=0278=23bba792-3418-47eb-bce2-a116502907cf83=159758980955=BTC-USD60=20250411-02:06:46.33448158=FILLED10=032
20250411-02:06:46.542078000 : 8=FIXT.1.19=27535=X49=Coinbase56=24ab46f784d1b20db435b852086e325034=27950=TEST52=20250411-02:06:46.363886369=46262=ecae6588-1a56-49ad-9a18-1bac314fe7a4268=1279=0269=183=159758981055=BTC-USD271=0.6232294660=20250411-02:06:46.36241340=137=b77fdb70-2716-4da6-b83d-c8caae228b0b10=244
20250411-02:06:46.542233000 : 8=FIXT.1.19=32735=X49=Coinbase56=24ab46f784d1b20db435b852086e325034=28050=TEST52=20250411-02:06:46.363895369=46262=ecae6588-1a56-49ad-9a18-1bac314fe7a4268=1279=0269=2278=24de32b2-a7f5-469c-a714-c9b10ee2cce583=159758981155=BTC-USD270=3.54271=0.6232294660=20250411-02:06:46.36241337=b77fdb70-2716-4da6-b83d-c8caae228b0b5797=210=178
20250411-02:06:46.542384000 : 8=FIXT.1.19=28135=X49=Coinbase56=24ab46f784d1b20db435b852086e325034=28150=TEST52=20250411-02:06:46.363899369=46262=ecae6588-1a56-49ad-9a18-1bac314fe7a4268=1279=2269=1278=b77fdb70-2716-4da6-b83d-c8caae228b0b83=159758981255=BTC-USD271=0.0000000060=20250411-02:06:46.36241358=FILLED10=143
20250411-02:06:46.542533000 : 8=FIXT.1.19=27935=X49=Coinbase56=24ab46f784d1b20db435b852086e325034=28250=TEST52=20250411-02:06:46.393211369=46262=ecae6588-1a56-49ad-9a18-1bac314fe7a4268=1279=0269=083=159758981355=BTC-USD29004=2.208895519560=20250411-02:06:46.39179340=137=cc082e61-53a2-4826-9498-0b4994ecf93310=149
20250411-02:06:46.542682000 : 8=FIXT.1.19=32735=X49=Coinbase56=24ab46f784d1b20db435b852086e325034=28350=TEST52=20250411-02:06:46.393218369=46262=ecae6588-1a56-49ad-9a18-1bac314fe7a4268=1279=0269=2278=c5b88ea9-605d-4595-ac52-f7c3f08523ba83=159758981455=BTC-USD270=3.55271=0.6222240960=20250411-02:06:46.39179337=cc082e61-53a2-4826-9498-0b4994ecf9335797=110=047
20250411-02:06:46.542929000 : 8=FIXT.1.19=26635=X49=Coinbase56=24ab46f784d1b20db435b852086e325034=28450=TEST52=20250411-02:06:46.393222369=46262=ecae6588-1a56-49ad-9a18-1bac314fe7a4268=1279=2269=0278=cc082e61-53a2-4826-9498-0b4994ecf93383=159758981555=BTC-USD60=20250411-02:06:46.39179358=FILLED10=167
20250411-02:06:46.543128000 : 8=FIXT.1.19=27535=X49=Coinbase56=24ab46f784d1b20db435b852086e325034=28550=TEST52=20250411-02:06:46.420584369=46262=ecae6588-1a56-49ad-9a18-1bac314fe7a4268=1279=0269=183=159758981655=BTC-USD271=0.6197183160=20250411-02:06:46.41917740=137=d91faaeb-4217-41d2-a285-90f2cd93772810=066
20250411-02:06:46.543339000 : 8=FIXT.1.19=32735=X49=Coinbase56=24ab46f784d1b20db435b852086e325034=28650=TEST52=20250411-02:06:46.420591369=46262=ecae6588-1a56-49ad-9a18-1bac314fe7a4268=1279=0269=2278=24de32b2-a7f5-469c-a714-c9b10ee2cce583=159758981755=BTC-USD270=3.54271=0.6197183160=20250411-02:06:46.41917737=d91faaeb-4217-41d2-a285-90f2cd9377285797=210=007
20250411-02:06:46.543485000 : 8=FIXT.1.19=28135=X49=Coinbase56=24ab46f784d1b20db435b852086e325034=28750=TEST52=20250411-02:06:46.420594369=46262=ecae6588-1a56-49ad-9a18-1bac314fe7a4268=1279=2269=1278=d91faaeb-4217-41d2-a285-90f2cd93772883=159758981855=BTC-USD271=0.0000000060=20250411-02:06:46.41917758=FILLED10=225
20250411-02:06:47.362059000 : 8=FIXT.1.19=27935=X49=Coinbase56=24ab46f784d1b20db435b852086e325034=28850=TEST52=20250411-02:06:47.134910369=46262=ecae6588-1a56-49ad-9a18-1bac314fe7a4268=1279=0269=083=159758981955=BTC-USD29004=2.208895519560=20250411-02:06:47.13342440=137=4b6c6040-2281-47e6-82cc-a2df6f3d60d410=011
20250411-02:06:47.362813000 : 8=FIXT.1.19=32735=X49=Coinbase56=24ab46f784d1b20db435b852086e325034=28950=TEST52=20250411-02:06:47.134944369=46262=ecae6588-1a56-49ad-9a18-1bac314fe7a4268=1279=0269=2278=c5b88ea9-605d-4595-ac52-f7c3f08523ba83=159758982055=BTC-USD270=3.55271=0.6222240960=20250411-02:06:47.13342437=4b6c6040-2281-47e6-82cc-a2df6f3d60d45797=110=156
20250411-02:06:47.363004000 : 8=FIXT.1.19=26635=X49=Coinbase56=24ab46f784d1b20db435b852086e325034=29050=TEST52=20250411-02:06:47.134949369=46262=ecae6588-1a56-49ad-9a18-1bac314fe7a4268=1279=2269=0278=4b6c6040-2281-47e6-82cc-a2df6f3d60d483=159758982155=BTC-USD60=20250411-02:06:47.13342458=FILLED10=021
20250411-02:06:47.363167000 : 8=FIXT.1.19=27535=X49=Coinbase56=24ab46f784d1b20db435b852086e325034=29150=TEST52=20250411-02:06:47.163189369=46262=ecae6588-1a56-49ad-9a18-1bac314fe7a4268=1279=0269=183=159758982255=BTC-USD271=0.6214689360=20250411-02:06:47.16191840=137=bdea3e58-cd88-427b-8436-f224b5f7924b10=128
20250411-02:06:47.363344000 : 8=FIXT.1.19=32735=X49=Coinbase56=24ab46f784d1b20db435b852086e325034=29250=TEST52=20250411-02:06:47.163197369=46262=ecae6588-1a56-49ad-9a18-1bac314fe7a4268=1279=0269=2278=24de32b2-a7f5-469c-a714-c9b10ee2cce583=159758982355=BTC-USD270=3.54271=0.6214689360=20250411-02:06:47.16191837=bdea3e58-cd88-427b-8436-f224b5f7924b5797=210=070
20250411-02:06:47.363496000 : 8=FIXT.1.19=28135=X49=Coinbase56=24ab46f784d1b20db435b852086e325034=29350=TEST52=20250411-02:06:47.163201369=46262=ecae6588-1a56-49ad-9a18-1bac314fe7a4268=1279=2269=1278=bdea3e58-cd88-427b-8436-f224b5f7924b83=159758982455=BTC-USD271=0.0000000060=20250411-02:06:47.16191858=FILLED10=012
20250411-02:06:47.369734000 : 8=FIXT.1.19=27935=X49=Coinbase56=24ab46f784d1b20db435b852086e325034=29450=TEST52=20250411-02:06:47.249431369=46262=ecae6588-1a56-49ad-9a18-1bac314fe7a4268=1279=0269=083=159758982555=BTC-USD29004=2.208895519560=20250411-02:06:47.24755840=137=2ee38464-f724-4116-a184-4a0fc6d0672710=142
20250411-02:06:47.370004000 : 8=FIXT.1.19=32735=X49=Coinbase56=24ab46f784d1b20db435b852086e325034=29550=TEST52=20250411-02:06:47.249439369=46262=ecae6588-1a56-49ad-9a18-1bac314fe7a4268=1279=0269=2278=c5b88ea9-605d-4595-ac52-f7c3f08523ba83=159758982655=BTC-USD270=3.55271=0.6222240960=20250411-02:06:47.24755837=2ee38464-f724-4116-a184-4a0fc6d067275797=110=041
20250411-02:06:47.370171000 : 8=FIXT.1.19=26635=X49=Coinbase56=24ab46f784d1b20db435b852086e325034=29650=TEST52=20250411-02:06:47.249442369=46262=ecae6588-1a56-49ad-9a18-1bac314fe7a4268=1279=2269=0278=2ee38464-f724-4116-a184-4a0fc6d0672783=159758982755=BTC-USD60=20250411-02:06:47.24755858=FILLED10=160
20250411-02:06:47.401884000 : 8=FIXT.1.19=27535=X49=Coinbase56=24ab46f784d1b20db435b852086e325034=29750=TEST52=20250411-02:06:47.277785369=46262=ecae6588-1a56-49ad-9a18-1bac314fe7a4268=1279=0269=183=159758982855=BTC-USD271=0.6214689360=20250411-02:06:47.27611740=137=70112c1a-e901-4efa-af76-38bd0add981f10=216
20250411-02:06:47.402536000 : 8=FIXT.1.19=32735=X49=Coinbase56=24ab46f784d1b20db435b852086e325034=29850=TEST52=20250411-02:06:47.277808369=46262=ecae6588-1a56-49ad-9a18-1bac314fe7a4268=1279=0269=2278=24de32b2-a7f5-469c-a714-c9b10ee2cce583=159758982955=BTC-USD270=3.54271=0.6214689360=20250411-02:06:47.27611737=70112c1a-e901-4efa-af76-38bd0add981f5797=210=155
20250411-02:06:47.402854000 : 8=FIXT.1.19=28135=X49=Coinbase56=24ab46f784d1b20db435b852086e325034=29950=TEST52=20250411-02:06:47.277812369=46262=ecae6588-1a56-49ad-9a18-1bac314fe7a4268=1279=2269=1278=70112c1a-e901-4efa-af76-38bd0add981f83=159758983055=BTC-USD271=0.0000000060=20250411-02:06:47.27611758=FILLED10=097
20250411-02:06:47.572090000 : 8=FIXT.1.19=28435=X49=Coinbase56=24ab46f784d1b20db435b852086e325034=30050=TEST52=20250411-02:06:47.451581369=46262=ecae6588-1a56-49ad-9a18-1bac314fe7a4268=1279=0269=083=159758983155=BTC-USD270=3.82271=0.6214689360=20250411-02:06:47.45051840=237=b8ca52e8-73c0-494a-af77-dcf54e78b05010=058
20250411-02:06:47.572679000 : 8=FIXT.1.19=32735=X49=Coinbase56=24ab46f784d1b20db435b852086e325034=30150=TEST52=20250411-02:06:47.451585369=46262=ecae6588-1a56-49ad-9a18-1bac314fe7a4268=1279=0269=2278=c5b88ea9-605d-4595-ac52-f7c3f08523ba83=159758983255=BTC-USD270=3.55271=0.6214689360=20250411-02:06:47.45051837=b8ca52e8-73c0-494a-af77-dcf54e78b0505797=110=018
20250411-02:06:47.572875000 : 8=FIXT.1.19=29035=X49=Coinbase56=24ab46f784d1b20db435b852086e325034=30250=TEST52=20250411-02:06:47.451588369=46262=ecae6588-1a56-49ad-9a18-1bac314fe7a4268=1279=2269=0278=b8ca52e8-73c0-494a-af77-dcf54e78b05083=159758983355=BTC-USD270=3.82271=0.0000000060=20250411-02:06:47.45051858=FILLED10=219
20250411-02:06:47.598633000 : 8=FIXT.1.19=27935=X49=Coinbase56=24ab46f784d1b20db435b852086e325034=30350=TEST52=20250411-02:06:47.477519369=46262=ecae6588-1a56-49ad-9a18-1bac314fe7a4268=1279=0269=083=159758983455=BTC-USD29004=2.208895519560=20250411-02:06:47.47593640=137=e272b10e-7f7f-4a01-bf47-b73fb170835710=032
20250411-02:06:47.599284000 : 8=FIXT.1.19=32735=X49=Coinbase56=24ab46f784d1b20db435b852086e325034=30450=TEST52=20250411-02:06:47.477524369=46262=ecae6588-1a56-49ad-9a18-1bac314fe7a4268=1279=0269=2278=c5b88ea9-605d-4595-ac52-f7c3f08523ba83=159758983555=BTC-USD270=3.55271=0.6222240960=20250411-02:06:47.47593637=e272b10e-7f7f-4a01-bf47-b73fb17083575797=110=175
20250411-02:06:47.599535000 : 8=FIXT.1.19=26635=X49=Coinbase56=24ab46f784d1b20db435b852086e325034=30550=TEST52=20250411-02:06:47.477528369=46262=ecae6588-1a56-49ad-9a18-1bac314fe7a4268=1279=2269=0278=e272b10e-7f7f-4a01-bf47-b73fb170835783=159758983655=BTC-USD60=20250411-02:06:47.47593658=FILLED10=048
20250411-02:06:47.627269000 : 8=FIXT.1.19=27535=X49=Coinbase56=24ab46f784d1b20db435b852086e325034=30650=TEST52=20250411-02:06:47.507331369=46262=ecae6588-1a56-49ad-9a18-1bac314fe7a4268=1279=0269=183=159758983755=BTC-USD271=0.6214689360=20250411-02:06:47.50517440=137=6606a784-82ea-4cf9-8d7a-2f49a8e4ec1710=126
20250411-02:06:47.627648000 : 8=FIXT.1.19=32735=X49=Coinbase56=24ab46f784d1b20db435b852086e325034=30750=TEST52=20250411-02:06:47.507339369=46262=ecae6588-1a56-49ad-9a18-1bac314fe7a4268=1279=0269=2278=24de32b2-a7f5-469c-a714-c9b10ee2cce583=159758983855=BTC-USD270=3.54271=0.6214689360=20250411-02:06:47.50517437=6606a784-82ea-4cf9-8d7a-2f49a8e4ec175797=210=077
20250411-02:06:47.628681000 : 8=FIXT.1.19=28135=X49=Coinbase56=24ab46f784d1b20db435b852086e325034=30850=TEST52=20250411-02:06:47.507343369=46262=ecae6588-1a56-49ad-9a18-1bac314fe7a4268=1279=2269=1278=6606a784-82ea-4cf9-8d7a-2f49a8e4ec1783=159758983955=BTC-USD271=0.0000000060=20250411-02:06:47.50517458=FILLED10=028
20250411-02:06:47.636944000 : 8=FIXT.1.19=28435=X49=Coinbase56=24ab46f784d1b20db435b852086e325034=30950=TEST52=20250411-02:06:47.507399369=46262=ecae6588-1a56-49ad-9a18-1bac314fe7a4268=1279=0269=183=159758984055=BTC-USD270=3.34271=0.6214689360=20250411-02:06:47.50619840=237=eca08279-bc62-440b-941d-cb17fe3e666c10=074
20250411-02:06:47.637506000 : 8=FIXT.1.19=32735=X49=Coinbase56=24ab46f784d1b20db435b852086e325034=31050=TEST52=20250411-02:06:47.507408369=46262=ecae6588-1a56-49ad-9a18-1bac314fe7a4268=1279=0269=2278=24de32b2-a7f5-469c-a714-c9b10ee2cce583=159758984155=BTC-USD270=3.54271=0.6214689360=20250411-02:06:47.50619837=eca08279-bc62-440b-941d-cb17fe3e666c5797=210=095
20250411-02:06:47.637802000 : 8=FIXT.1.19=29035=X49=Coinbase56=24ab46f784d1b20db435b852086e325034=31150=TEST52=20250411-02:06:47.507412369=46262=ecae6588-1a56-49ad-9a18-1bac314fe7a4268=1279=2269=1278=eca08279-bc62-440b-941d-cb17fe3e666c83=159758984255=BTC-USD270=3.34271=0.0000000060=20250411-02:06:47.50619858=FILLED10=205
20250411-02:06:47.656189000 : 8=FIXT.1.19=27935=X49=Coinbase56=24ab46f784d1b20db435b852086e325034=31250=TEST52=20250411-02:06:47.535589369=46262=ecae6588-1a56-49ad-9a18-1bac314fe7a4268=1279=0269=083=159758984355=BTC-USD29004=2.208895519560=20250411-02:06:47.53429340=137=cd16fd92-3954-44d2-aec0-b882e155fa0710=077
20250411-02:06:47.656761000 : 8=FIXT.1.19=32735=X49=Coinbase56=24ab46f784d1b20db435b852086e325034=31350=TEST52=20250411-02:06:47.535594369=46262=ecae6588-1a56-49ad-9a18-1bac314fe7a4268=1279=0269=2278=c5b88ea9-605d-4595-ac52-f7c3f08523ba83=159758984455=BTC-USD270=3.55271=0.6222240960=20250411-02:06:47.53429337=cd16fd92-3954-44d2-aec0-b882e155fa075797=110=220
20250411-02:06:47.656938000 : 8=FIXT.1.19=26635=X49=Coinbase56=24ab46f784d1b20db435b852086e325034=31450=TEST52=20250411-02:06:47.535598369=46262=ecae6588-1a56-49ad-9a18-1bac314fe7a4268=1279=2269=0278=cd16fd92-3954-44d2-aec0-b882e155fa0783=159758984555=BTC-USD60=20250411-02:06:47.53429358=FILLED10=093
20250411-02:06:47.684359000 : 8=FIXT.1.19=27535=X49=Coinbase56=24ab46f784d1b20db435b852086e325034=31550=TEST52=20250411-02:06:47.563997369=46262=ecae6588-1a56-49ad-9a18-1bac314fe7a4268=1279=0269=183=159758984655=BTC-USD271=0.6197183160=20250411-02:06:47.56283340=137=db19a541-7cd2-4abc-b5bf-214107ad363d10=197
20250411-02:06:47.684731000 : 8=FIXT.1.19=32735=X49=Coinbase56=24ab46f784d1b20db435b852086e325034=31650=TEST52=20250411-02:06:47.564002369=46262=ecae6588-1a56-49ad-9a18-1bac314fe7a4268=1279=0269=2278=24de32b2-a7f5-469c-a714-c9b10ee2cce583=159758984755=BTC-USD270=3.54271=0.6197183160=20250411-02:06:47.56283337=db19a541-7cd2-4abc-b5bf-214107ad363d5797=210=118
20250411-02:06:47.684904000 : 8=FIXT.1.19=28135=X49=Coinbase56=24ab46f784d1b20db435b852086e325034=31750=TEST52=20250411-02:06:47.564006369=46262=ecae6588-1a56-49ad-9a18-1bac314fe7a4268=1279=2269=1278=db19a541-7cd2-4abc-b5bf-214107ad363d83=159758984855=BTC-USD271=0.0000000060=20250411-02:06:47.56283358=FILLED10=081
20250411-02:06:47.712416000 : 8=FIXT.1.19=27935=X49=Coinbase56=24ab46f784d1b20db435b852086e325034=31850=TEST52=20250411-02:06:47.592567369=46262=ecae6588-1a56-49ad-9a18-1bac314fe7a4268=1279=0269=083=159758984955=BTC-USD29004=2.208895519560=20250411-02:06:47.59040540=137=c76aa0d0-2aa1-47e3-8648-409608fe501310=187
20250411-02:06:47.712867000 : 8=FIXT.1.19=32735=X49=Coinbase56=24ab46f784d1b20db435b852086e325034=31950=TEST52=20250411-02:06:47.592575369=46262=ecae6588-1a56-49ad-9a18-1bac314fe7a4268=1279=0269=2278=c5b88ea9-605d-4595-ac52-f7c3f08523ba83=159758985055=BTC-USD270=3.55271=0.6222240960=20250411-02:06:47.59040537=c76aa0d0-2aa1-47e3-8648-409608fe50135797=110=068
20250411-02:06:47.713066000 : 8=FIXT.1.19=26635=X49=Coinbase56=24ab46f784d1b20db435b852086e325034=32050=TEST52=20250411-02:06:47.592579369=46262=ecae6588-1a56-49ad-9a18-1bac314fe7a4268=1279=2269=0278=c76aa0d0-2aa1-47e3-8648-409608fe501383=159758985155=BTC-USD60=20250411-02:06:47.59040558=FILLED10=188
20250411-02:06:47.741643000 : 8=FIXT.1.19=27535=X49=Coinbase56=24ab46f784d1b20db435b852086e325034=32150=TEST52=20250411-02:06:47.621554369=46262=ecae6588-1a56-49ad-9a18-1bac314fe7a4268=1279=0269=183=159758985255=BTC-USD271=0.6197183160=20250411-02:06:47.61974340=137=c5dca85f-be75-4438-969a-242c02fa200010=050
20250411-02:06:47.742128000 : 8=FIXT.1.19=32735=X49=Coinbase56=24ab46f784d1b20db435b852086e325034=32250=TEST52=20250411-02:06:47.621560369=46262=ecae6588-1a56-49ad-9a18-1bac314fe7a4268=1279=0269=2278=24de32b2-a7f5-469c-a714-c9b10ee2cce583=159758985355=BTC-USD270=3.54271=0.6197183160=20250411-02:06:47.61974337=c5dca85f-be75-4438-969a-242c02fa20005797=210=246
20250411-02:06:47.742385000 : 8=FIXT.1.19=28135=X49=Coinbase56=24ab46f784d1b20db435b852086e325034=32350=TEST52=20250411-02:06:47.621565369=46262=ecae6588-1a56-49ad-9a18-1bac314fe7a4268=1279=2269=1278=c5dca85f-be75-4438-969a-242c02fa200083=159758985455=BTC-USD271=0.0000000060=20250411-02:06:47.61974358=FILLED10=210
20250411-02:06:47.769659000 : 8=FIXT.1.19=27935=X49=Coinbase56=24ab46f784d1b20db435b852086e325034=32450=TEST52=20250411-02:06:47.649936369=46262=ecae6588-1a56-49ad-9a18-1bac314fe7a4268=1279=0269=083=159758985555=BTC-USD29004=2.208895519560=20250411-02:06:47.64864440=137=7ebc1ea8-a602-4ecc-b072-ff6e7a3a588110=230
20250411-02:06:47.770027000 : 8=FIXT.1.19=32735=X49=Coinbase56=24ab46f784d1b20db435b852086e325034=32550=TEST52=20250411-02:06:47.649940369=46262=ecae6588-1a56-49ad-9a18-1bac314fe7a4268=1279=0269=2278=c5b88ea9-605d-4595-ac52-f7c3f08523ba83=159758985655=BTC-USD270=3.55271=0.6222240960=20250411-02:06:47.64864437=7ebc1ea8-a602-4ecc-b072-ff6e7a3a58815797=110=116
20250411-02:06:47.770210000 : 8=FIXT.1.19=26635=X49=Coinbase56=24ab46f784d1b20db435b852086e325034=32650=TEST52=20250411-02:06:47.649944369=46262=ecae6588-1a56-49ad-9a18-1bac314fe7a4268=1279=2269=0278=7ebc1ea8-a602-4ecc-b072-ff6e7a3a588183=159758985755=BTC-USD60=20250411-02:06:47.64864458=FILLED10=245
20250411-02:06:47.799330000 : 8=FIXT.1.19=27535=X49=Coinbase56=24ab46f784d1b20db435b852086e325034=32750=TEST52=20250411-02:06:47.677285369=46262=ecae6588-1a56-49ad-9a18-1bac314fe7a4268=1279=0269=183=159758985855=BTC-USD271=0.6197183160=20250411-02:06:47.67570240=137=8f8ce562-c278-45d6-8ad6-7b4e87980bd410=112
20250411-02:06:47.799981000 : 8=FIXT.1.19=32735=X49=Coinbase56=24ab46f784d1b20db435b852086e325034=32850=TEST52=20250411-02:06:47.677289369=46262=ecae6588-1a56-49ad-9a18-1bac314fe7a4268=1279=0269=2278=24de32b2-a7f5-469c-a714-c9b10ee2cce583=159758985955=BTC-USD270=3.54271=0.6197183160=20250411-02:06:47.67570237=8f8ce562-c278-45d6-8ad6-7b4e87980bd45797=210=059
20250411-02:06:47.800362000 : 8=FIXT.1.19=28135=X49=Coinbase56=24ab46f784d1b20db435b852086e325034=32950=TEST52=20250411-02:06:47.677293369=46262=ecae6588-1a56-49ad-9a18-1bac314fe7a4268=1279=2269=1278=8f8ce562-c278-45d6-8ad6-7b4e87980bd483=159758986055=BTC-USD271=0.0000000060=20250411-02:06:47.67570258=FILLED10=004
20250411-02:06:47.997516000 : 8=FIXT.1.19=27935=X49=Coinbase56=24ab46f784d1b20db435b852086e325034=33050=TEST52=20250411-02:06:47.877399369=46262=ecae6588-1a56-49ad-9a18-1bac314fe7a4268=1279=0269=083=159758986155=BTC-USD29004=2.208895519560=20250411-02:06:47.87619940=137=a482271f-ba7a-4641-a492-de4216cf144310=246
20250411-02:06:47.998067000 : 8=FIXT.1.19=32735=X49=Coinbase56=24ab46f784d1b20db435b852086e325034=33150=TEST52=20250411-02:06:47.877408369=46262=ecae6588-1a56-49ad-9a18-1bac314fe7a4268=1279=0269=2278=c5b88ea9-605d-4595-ac52-f7c3f08523ba83=159758986255=BTC-USD270=3.55271=0.6222240960=20250411-02:06:47.87619937=a482271f-ba7a-4641-a492-de4216cf14435797=110=128
20250411-02:06:47.998401000 : 8=FIXT.1.19=26635=X49=Coinbase56=24ab46f784d1b20db435b852086e325034=33250=TEST52=20250411-02:06:47.877411369=46262=ecae6588-1a56-49ad-9a18-1bac314fe7a4268=1279=2269=0278=a482271f-ba7a-4641-a492-de4216cf144383=159758986355=BTC-USD60=20250411-02:06:47.87619958=FILLED10=247
20250411-02:06:48.026047000 : 8=FIXT.1.19=27535=X49=Coinbase56=24ab46f784d1b20db435b852086e325034=33350=TEST52=20250411-02:06:47.905669369=46262=ecae6588-1a56-49ad-9a18-1bac314fe7a4268=1279=0269=183=159758986455=BTC-USD271=0.6214689360=20250411-02:06:47.90429140=137=4c45ac62-7e17-47b4-b218-da51d810263010=219
20250411-02:06:48.026506000 : 8=FIXT.1.19=32735=X49=Coinbase56=24ab46f784d1b20db435b852086e325034=33450=TEST52=20250411-02:06:47.905676369=46262=ecae6588-1a56-49ad-9a18-1bac314fe7a4268=1279=0269=2278=24de32b2-a7f5-469c-a714-c9b10ee2cce583=159758986555=BTC-USD270=3.54271=0.6214689360=20250411-02:06:47.90429137=4c45ac62-7e17-47b4-b218-da51d81026305797=210=160
20250411-02:06:48.026797000 : 8=FIXT.1.19=28135=X49=Coinbase56=24ab46f784d1b20db435b852086e325034=33550=TEST52=20250411-02:06:47.905681369=46262=ecae6588-1a56-49ad-9a18-1bac314fe7a4268=1279=2269=1278=4c45ac62-7e17-47b4-b218-da51d810263083=159758986655=BTC-USD271=0.0000000060=20250411-02:06:47.90429158=FILLED10=112
20250411-02:06:48.168590000 : 8=FIXT.1.19=27935=X49=Coinbase56=24ab46f784d1b20db435b852086e325034=33650=TEST52=20250411-02:06:48.048434369=46262=ecae6588-1a56-49ad-9a18-1bac314fe7a4268=1279=0269=083=159758986755=BTC-USD29004=2.208895519560=20250411-02:06:48.04715540=137=a2d3247a-cc72-469f-aae3-01a846a96e5d10=118
20250411-02:06:48.169540000 : 8=FIXT.1.19=32735=X49=Coinbase56=24ab46f784d1b20db435b852086e325034=33750=TEST52=20250411-02:06:48.048440369=46262=ecae6588-1a56-49ad-9a18-1bac314fe7a4268=1279=0269=2278=c5b88ea9-605d-4595-ac52-f7c3f08523ba83=159758986855=BTC-USD270=3.55271=0.6222240960=20250411-02:06:48.04715537=a2d3247a-cc72-469f-aae3-01a846a96e5d5797=110=006
20250411-02:06:48.169885000 : 8=FIXT.1.19=26635=X49=Coinbase56=24ab46f784d1b20db435b852086e325034=33850=TEST52=20250411-02:06:48.048443369=46262=ecae6588-1a56-49ad-9a18-1bac314fe7a4268=1279=2269=0278=a2d3247a-cc72-469f-aae3-01a846a96e5d83=159758986955=BTC-USD60=20250411-02:06:48.04715558=FILLED10=134
20250411-02:06:48.198188000 : 8=FIXT.1.19=27535=X49=Coinbase56=24ab46f784d1b20db435b852086e325034=33950=TEST52=20250411-02:06:48.077867369=46262=ecae6588-1a56-49ad-9a18-1bac314fe7a4268=1279=0269=183=159758987055=BTC-USD271=0.6214689360=20250411-02:06:48.07646040=137=a381fc5b-f5cf-46c4-8e39-5f8331aacdb610=019
20250411-02:06:48.199151000 : 8=FIXT.1.19=32735=X49=Coinbase56=24ab46f784d1b20db435b852086e325034=34050=TEST52=20250411-02:06:48.077873369=46262=ecae6588-1a56-49ad-9a18-1bac314fe7a4268=1279=0269=2278=24de32b2-a7f5-469c-a714-c9b10ee2cce583=159758987155=BTC-USD270=3.54271=0.6214689360=20250411-02:06:48.07646037=a381fc5b-f5cf-46c4-8e39-5f8331aacdb65797=210=206
20250411-02:06:48.199745000 : 8=FIXT.1.19=28135=X49=Coinbase56=24ab46f784d1b20db435b852086e325034=34150=TEST52=20250411-02:06:48.077877369=46262=ecae6588-1a56-49ad-9a18-1bac314fe7a4268=1279=2269=1278=a381fc5b-f5cf-46c4-8e39-5f8331aacdb683=159758987255=BTC-USD271=0.0000000060=20250411-02:06:48.07646058=FILLED10=166
20250411-02:06:48.341698000 : 8=FIXT.1.19=27935=X49=Coinbase56=24ab46f784d1b20db435b852086e325034=34250=TEST52=20250411-02:06:48.221580369=46262=ecae6588-1a56-49ad-9a18-1bac314fe7a4268=1279=0269=083=159758987355=BTC-USD29004=2.208895519560=20250411-02:06:48.21988140=137=f971cbdb-0673-478a-8973-b74ded0107fe10=084
20250411-02:06:48.342296000 : 8=FIXT.1.19=32735=X49=Coinbase56=24ab46f784d1b20db435b852086e325034=34350=TEST52=20250411-02:06:48.221586369=46262=ecae6588-1a56-49ad-9a18-1bac314fe7a4268=1279=0269=2278=c5b88ea9-605d-4595-ac52-f7c3f08523ba83=159758987455=BTC-USD270=3.55271=0.6222240960=20250411-02:06:48.21988137=f971cbdb-0673-478a-8973-b74ded0107fe5797=110=237
20250411-02:06:48.342527000 : 8=FIXT.1.19=26635=X49=Coinbase56=24ab46f784d1b20db435b852086e325034=34450=TEST52=20250411-02:06:48.221590369=46262=ecae6588-1a56-49ad-9a18-1bac314fe7a4268=1279=2269=0278=f971cbdb-0673-478a-8973-b74ded0107fe83=159758987555=BTC-USD60=20250411-02:06:48.21988158=FILLED10=101
20250411-02:06:48.371623000 : 8=FIXT.1.19=27535=X49=Coinbase56=24ab46f784d1b20db435b852086e325034=34550=TEST52=20250411-02:06:48.250822369=46262=ecae6588-1a56-49ad-9a18-1bac314fe7a4268=1279=0269=183=159758987655=BTC-USD271=0.6214689360=20250411-02:06:48.24900240=137=4ca67ee2-93f1-4a6a-8190-d9c73e47c88910=082
20250411-02:06:48.371869000 : 8=FIXT.1.19=32735=X49=Coinbase56=24ab46f784d1b20db435b852086e325034=34650=TEST52=20250411-02:06:48.250828369=46262=ecae6588-1a56-49ad-9a18-1bac314fe7a4268=1279=0269=2278=24de32b2-a7f5-469c-a714-c9b10ee2cce583=159758987755=BTC-USD270=3.54271=0.6214689360=20250411-02:06:48.24900237=4ca67ee2-93f1-4a6a-8190-d9c73e47c8895797=210=031
20250411-02:06:48.372139000 : 8=FIXT.1.19=28135=X49=Coinbase56=24ab46f784d1b20db435b852086e325034=34750=TEST52=20250411-02:06:48.250832369=46262=ecae6588-1a56-49ad-9a18-1bac314fe7a4268=1279=2269=1278=4ca67ee2-93f1-4a6a-8190-d9c73e47c88983=159758987855=BTC-USD271=0.0000000060=20250411-02:06:48.24900258=FILLED10=238
20250411-02:06:48.570241000 : 8=FIXT.1.19=27935=X49=Coinbase56=24ab46f784d1b20db435b852086e325034=34850=TEST52=20250411-02:06:48.449151369=46262=ecae6588-1a56-49ad-9a18-1bac314fe7a4268=1279=0269=083=159758987955=BTC-USD29004=2.208895519560=20250411-02:06:48.44789140=137=1610b3cf-b2fe-4811-9bd6-414aacfb651810=126
20250411-02:06:48.570712000 : 8=FIXT.1.19=32735=X49=Coinbase56=24ab46f784d1b20db435b852086e325034=34950=TEST52=20250411-02:06:48.449160369=46262=ecae6588-1a56-49ad-9a18-1bac314fe7a4268=1279=0269=2278=c5b88ea9-605d-4595-ac52-f7c3f08523ba83=159758988055=BTC-USD270=3.55271=0.6222240960=20250411-02:06:48.44789137=1610b3cf-b2fe-4811-9bd6-414aacfb65185797=110=008
20250411-02:06:48.571012000 : 8=FIXT.1.19=26635=X49=Coinbase56=24ab46f784d1b20db435b852086e325034=35050=TEST52=20250411-02:06:48.449165369=46262=ecae6588-1a56-49ad-9a18-1bac314fe7a4268=1279=2269=0278=1610b3cf-b2fe-4811-9bd6-414aacfb651883=159758988155=BTC-USD60=20250411-02:06:48.44789158=FILLED10=129
20250411-02:06:48.598474000 : 8=FIXT.1.19=27535=X49=Coinbase56=24ab46f784d1b20db435b852086e325034=35150=TEST52=20250411-02:06:48.478127369=46262=ecae6588-1a56-49ad-9a18-1bac314fe7a4268=1279=0269=183=159758988255=BTC-USD271=0.6214689360=20250411-02:06:48.47623440=137=6e8b27fa-accd-4dce-854c-10c7b50a62c710=048
20250411-02:06:48.598687000 : 8=FIXT.1.19=32735=X49=Coinbase56=24ab46f784d1b20db435b852086e325034=35250=TEST52=20250411-02:06:48.478136369=46262=ecae6588-1a56-49ad-9a18-1bac314fe7a4268=1279=0269=2278=24de32b2-a7f5-469c-a714-c9b10ee2cce583=159758988355=BTC-USD270=3.54271=0.6214689360=20250411-02:06:48.47623437=6e8b27fa-accd-4dce-854c-10c7b50a62c75797=210=247
20250411-02:06:48.598858000 : 8=FIXT.1.19=28135=X49=Coinbase56=24ab46f784d1b20db435b852086e325034=35350=TEST52=20250411-02:06:48.478140369=46262=ecae6588-1a56-49ad-9a18-1bac314fe7a4268=1279=2269=1278=6e8b27fa-accd-4dce-854c-10c7b50a62c783=159758988455=BTC-USD271=0.0000000060=20250411-02:06:48.47623458=FILLED10=198
20250411-02:06:48.600943000 : 8=FIXT.1.19=28335=X49=Coinbase56=24ab46f784d1b20db435b852086e325034=35450=TEST52=20250411-02:06:48.479753369=46262=ecae6588-1a56-49ad-9a18-1bac314fe7a4268=1279=0269=083=159758988555=BTC-USD270=3.8271=0.6197183160=20250411-02:06:48.47882040=237=c5cc81f9-79b9-4e84-8870-082ece7fa95710=233
20250411-02:06:48.601111000 : 8=FIXT.1.19=32735=X49=Coinbase56=24ab46f784d1b20db435b852086e325034=35550=TEST52=20250411-02:06:48.479758369=46262=ecae6588-1a56-49ad-9a18-1bac314fe7a4268=1279=0269=2278=c5b88ea9-605d-4595-ac52-f7c3f08523ba83=159758988655=BTC-USD270=3.55271=0.6197183160=20250411-02:06:48.47882037=c5cc81f9-79b9-4e84-8870-082ece7fa9575797=110=245
20250411-02:06:48.601509000 : 8=FIXT.1.19=28935=X49=Coinbase56=24ab46f784d1b20db435b852086e325034=35650=TEST52=20250411-02:06:48.479762369=46262=ecae6588-1a56-49ad-9a18-1bac314fe7a4268=1279=2269=0278=c5cc81f9-79b9-4e84-8870-082ece7fa95783=159758988755=BTC-USD270=3.8271=0.0000000060=20250411-02:06:48.47882058=FILLED10=143
20250411-02:06:48.655328000 : 8=FIXT.1.19=28435=X49=Coinbase56=24ab46f784d1b20db435b852086e325034=35750=TEST52=20250411-02:06:48.535172369=46262=ecae6588-1a56-49ad-9a18-1bac314fe7a4268=1279=0269=183=159758988855=BTC-USD270=3.26271=0.6197183160=20250411-02:06:48.53443940=237=e9a87f94-78cc-4595-a3f9-c79eca4f230810=064
20250411-02:06:48.655582000 : 8=FIXT.1.19=32735=X49=Coinbase56=24ab46f784d1b20db435b852086e325034=35850=TEST52=20250411-02:06:48.535296369=46262=ecae6588-1a56-49ad-9a18-1bac314fe7a4268=1279=0269=2278=24de32b2-a7f5-469c-a714-c9b10ee2cce583=159758988955=BTC-USD270=3.54271=0.6197183160=20250411-02:06:48.53443937=e9a87f94-78cc-4595-a3f9-c79eca4f23085797=210=109
20250411-02:06:48.655878000 : 8=FIXT.1.19=29035=X49=Coinbase56=24ab46f784d1b20db435b852086e325034=35950=TEST52=20250411-02:06:48.535344369=46262=ecae6588-1a56-49ad-9a18-1bac314fe7a4268=1279=2269=1278=e9a87f94-78cc-4595-a3f9-c79eca4f230883=159758989055=BTC-USD270=3.26271=0.0000000060=20250411-02:06:48.53443958=FILLED10=213
20250411-02:06:48.715330000 : 8=FIXT.1.19=28435=X49=Coinbase56=24ab46f784d1b20db435b852086e325034=36050=TEST52=20250411-02:06:48.594874369=46262=ecae6588-1a56-49ad-9a18-1bac314fe7a4268=1279=0269=083=159758989155=BTC-USD270=3.84271=0.6214689360=20250411-02:06:48.59368040=237=5fa7bbf5-f396-44a9-b5dc-34e8b3501c8210=094
20250411-02:06:48.715928000 : 8=FIXT.1.19=32735=X49=Coinbase56=24ab46f784d1b20db435b852086e325034=36150=TEST52=20250411-02:06:48.594882369=46262=ecae6588-1a56-49ad-9a18-1bac314fe7a4268=1279=0269=2278=c5b88ea9-605d-4595-ac52-f7c3f08523ba83=159758989255=BTC-USD270=3.55271=0.6214689360=20250411-02:06:48.59368037=5fa7bbf5-f396-44a9-b5dc-34e8b3501c825797=110=047
20250411-02:06:48.716195000 : 8=FIXT.1.19=29035=X49=Coinbase56=24ab46f784d1b20db435b852086e325034=36250=TEST52=20250411-02:06:48.594886369=46262=ecae6588-1a56-49ad-9a18-1bac314fe7a4268=1279=2269=0278=5fa7bbf5-f396-44a9-b5dc-34e8b3501c8283=159758989355=BTC-USD270=3.84271=0.0000000060=20250411-02:06:48.59368058=FILLED10=251
20250411-02:06:48.769611000 : 8=FIXT.1.19=28435=X49=Coinbase56=24ab46f784d1b20db435b852086e325034=36350=TEST52=20250411-02:06:48.649434369=46262=ecae6588-1a56-49ad-9a18-1bac314fe7a4268=1279=0269=183=159758989455=BTC-USD270=3.28271=0.6214689360=20250411-02:06:48.64847540=237=8bdb34b8-3c05-4c9b-a205-e115131f410e10=224
20250411-02:06:48.769905000 : 8=FIXT.1.19=32735=X49=Coinbase56=24ab46f784d1b20db435b852086e325034=36450=TEST52=20250411-02:06:48.649438369=46262=ecae6588-1a56-49ad-9a18-1bac314fe7a4268=1279=0269=2278=24de32b2-a7f5-469c-a714-c9b10ee2cce583=159758989555=BTC-USD270=3.54271=0.6214689360=20250411-02:06:48.64847537=8bdb34b8-3c05-4c9b-a205-e115131f410e5797=210=008
20250411-02:06:48.770088000 : 8=FIXT.1.19=29035=X49=Coinbase56=24ab46f784d1b20db435b852086e325034=36550=TEST52=20250411-02:06:48.649442369=46262=ecae6588-1a56-49ad-9a18-1bac314fe7a4268=1279=2269=1278=8bdb34b8-3c05-4c9b-a205-e115131f410e83=159758989655=BTC-USD270=3.28271=0.0000000060=20250411-02:06:48.64847558=FILLED10=121
20250411-02:06:49.101736000 : 8=FIXT.1.19=27935=X49=Coinbase56=24ab46f784d1b20db435b852086e325034=36650=TEST52=20250411-02:06:48.963067369=46262=ecae6588-1a56-49ad-9a18-1bac314fe7a4268=1279=0269=083=159758989755=BTC-USD29004=2.208895519560=20250411-02:06:48.96147440=137=2939c891-727e-4983-9db0-66a08d27ccb810=235
20250411-02:06:49.102250000 : 8=FIXT.1.19=32735=X49=Coinbase56=24ab46f784d1b20db435b852086e325034=36750=TEST52=20250411-02:06:48.963074369=46262=ecae6588-1a56-49ad-9a18-1bac314fe7a4268=1279=0269=2278=c5b88ea9-605d-4595-ac52-f7c3f08523ba83=159758989855=BTC-USD270=3.55271=0.6222240960=20250411-02:06:48.96147437=2939c891-727e-4983-9db0-66a08d27ccb85797=110=124
20250411-02:06:49.102454000 : 8=FIXT.1.19=26635=X49=Coinbase56=24ab46f784d1b20db435b852086e325034=36850=TEST52=20250411-02:06:48.963084369=46262=ecae6588-1a56-49ad-9a18-1bac314fe7a4268=1279=2269=0278=2939c891-727e-4983-9db0-66a08d27ccb883=159758989955=BTC-USD60=20250411-02:06:48.96147458=FILLED10=250
20250411-02:06:49.111852000 : 8=FIXT.1.19=27535=X49=Coinbase56=24ab46f784d1b20db435b852086e325034=36950=TEST52=20250411-02:06:48.991457369=46262=ecae6588-1a56-49ad-9a18-1bac314fe7a4268=1279=0269=183=159758990055=BTC-USD271=0.6214689360=20250411-02:06:48.99034640=137=b849d086-94e2-415d-84f7-0189c100fc8a10=254
20250411-02:06:49.112439000 : 8=FIXT.1.19=32735=X49=Coinbase56=24ab46f784d1b20db435b852086e325034=37050=TEST52=20250411-02:06:48.991466369=46262=ecae6588-1a56-49ad-9a18-1bac314fe7a4268=1279=0269=2278=24de32b2-a7f5-469c-a714-c9b10ee2cce583=159758990155=BTC-USD270=3.54271=0.6214689360=20250411-02:06:48.99034637=b849d086-94e2-415d-84f7-0189c100fc8a5797=210=188
20250411-02:06:49.112626000 : 8=FIXT.1.19=28135=X49=Coinbase56=24ab46f784d1b20db435b852086e325034=37150=TEST52=20250411-02:06:48.991470369=46262=ecae6588-1a56-49ad-9a18-1bac314fe7a4268=1279=2269=1278=b849d086-94e2-415d-84f7-0189c100fc8a83=159758990255=BTC-USD271=0.0000000060=20250411-02:06:48.99034658=FILLED10=139
20250411-02:06:49.173669000 : 8=FIXT.1.19=28435=X49=Coinbase56=24ab46f784d1b20db435b852086e325034=37250=TEST52=20250411-02:06:49.052799369=46262=ecae6588-1a56-49ad-9a18-1bac314fe7a4268=1279=0269=083=159758990355=BTC-USD270=3.79271=0.6214689360=20250411-02:06:49.05154240=237=f5f01932-dedf-4774-a406-7a81944ee75510=201
20250411-02:06:49.173968000 : 8=FIXT.1.19=32735=X49=Coinbase56=24ab46f784d1b20db435b852086e325034=37350=TEST52=20250411-02:06:49.052857369=46262=ecae6588-1a56-49ad-9a18-1bac314fe7a4268=1279=0269=2278=c5b88ea9-605d-4595-ac52-f7c3f08523ba83=159758990455=BTC-USD270=3.55271=0.6214689360=20250411-02:06:49.05154237=f5f01932-dedf-4774-a406-7a81944ee7555797=110=146
20250411-02:06:49.174191000 : 8=FIXT.1.19=29035=X49=Coinbase56=24ab46f784d1b20db435b852086e325034=37450=TEST52=20250411-02:06:49.052864369=46262=ecae6588-1a56-49ad-9a18-1bac314fe7a4268=1279=2269=0278=f5f01932-dedf-4774-a406-7a81944ee75583=159758990555=BTC-USD270=3.79271=0.0000000060=20250411-02:06:49.05154258=FILLED10=092
20250411-02:06:49.230548000 : 8=FIXT.1.19=28435=X49=Coinbase56=24ab46f784d1b20db435b852086e325034=37550=TEST52=20250411-02:06:49.107850369=46262=ecae6588-1a56-49ad-9a18-1bac314fe7a4268=1279=0269=183=159758990655=BTC-USD270=3.32271=0.6214689360=20250411-02:06:49.10604240=237=847cc2c6-a3c8-4b9a-b5a5-68d593c492bb10=062
20250411-02:06:49.231049000 : 8=FIXT.1.19=32735=X49=Coinbase56=24ab46f784d1b20db435b852086e325034=37650=TEST52=20250411-02:06:49.107858369=46262=ecae6588-1a56-49ad-9a18-1bac314fe7a4268=1279=0269=2278=24de32b2-a7f5-469c-a714-c9b10ee2cce583=159758990755=BTC-USD270=3.54271=0.6214689360=20250411-02:06:49.10604237=847cc2c6-a3c8-4b9a-b5a5-68d593c492bb5797=210=111
20250411-02:06:49.231353000 : 8=FIXT.1.19=29035=X49=Coinbase56=24ab46f784d1b20db435b852086e325034=37750=TEST52=20250411-02:06:49.107862369=46262=ecae6588-1a56-49ad-9a18-1bac314fe7a4268=1279=2269=1278=847cc2c6-a3c8-4b9a-b5a5-68d593c492bb83=159758990855=BTC-USD270=3.32271=0.0000000060=20250411-02:06:49.10604258=FILLED10=219
20250411-02:06:49.256537000 : 8=FIXT.1.19=27935=X49=Coinbase56=24ab46f784d1b20db435b852086e325034=37850=TEST52=20250411-02:06:49.136324369=46262=ecae6588-1a56-49ad-9a18-1bac314fe7a4268=1279=0269=083=159758990955=BTC-USD29004=2.208895519560=20250411-02:06:49.13524840=137=e333eaeb-9b7c-4ee2-a25f-fecb7b607e4110=058
20250411-02:06:49.256727000 : 8=FIXT.1.19=32735=X49=Coinbase56=24ab46f784d1b20db435b852086e325034=37950=TEST52=20250411-02:06:49.136329369=46262=ecae6588-1a56-49ad-9a18-1bac314fe7a4268=1279=0269=2278=c5b88ea9-605d-4595-ac52-f7c3f08523ba83=159758991055=BTC-USD270=3.55271=0.6222240960=20250411-02:06:49.13524837=e333eaeb-9b7c-4ee2-a25f-fecb7b607e415797=110=201
20250411-02:06:49.256936000 : 8=FIXT.1.19=26635=X49=Coinbase56=24ab46f784d1b20db435b852086e325034=38050=TEST52=20250411-02:06:49.136333369=46262=ecae6588-1a56-49ad-9a18-1bac314fe7a4268=1279=2269=0278=e333eaeb-9b7c-4ee2-a25f-fecb7b607e4183=159758991155=BTC-USD60=20250411-02:06:49.13524858=FILLED10=056
20250411-02:06:49.285383000 : 8=FIXT.1.19=27535=X49=Coinbase56=24ab46f784d1b20db435b852086e325034=38150=TEST52=20250411-02:06:49.163642369=46262=ecae6588-1a56-49ad-9a18-1bac314fe7a4268=1279=0269=183=159758991255=BTC-USD271=0.6197183160=20250411-02:06:49.16164340=137=c6304775-1756-438f-9c7d-9ff33da4625110=187
20250411-02:06:49.285948000 : 8=FIXT.1.19=32735=X49=Coinbase56=24ab46f784d1b20db435b852086e325034=38250=TEST52=20250411-02:06:49.163647369=46262=ecae6588-1a56-49ad-9a18-1bac314fe7a4268=1279=0269=2278=24de32b2-a7f5-469c-a714-c9b10ee2cce583=159758991355=BTC-USD270=3.54271=0.6197183160=20250411-02:06:49.16164337=c6304775-1756-438f-9c7d-9ff33da462515797=210=135
20250411-02:06:49.286121000 : 8=FIXT.1.19=28135=X49=Coinbase56=24ab46f784d1b20db435b852086e325034=38350=TEST52=20250411-02:06:49.163652369=46262=ecae6588-1a56-49ad-9a18-1bac314fe7a4268=1279=2269=1278=c6304775-1756-438f-9c7d-9ff33da4625183=159758991455=BTC-USD271=0.0000000060=20250411-02:06:49.16164358=FILLED10=090
20250411-02:06:49.770382000 : 8=FIXT.1.19=27935=X49=Coinbase56=24ab46f784d1b20db435b852086e325034=38450=TEST52=20250411-02:06:49.650120369=46262=ecae6588-1a56-49ad-9a18-1bac314fe7a4268=1279=0269=083=159758991555=BTC-USD29004=2.208895519560=20250411-02:06:49.64786840=137=e68b2ba9-f66d-4d70-913d-9fabceb6b28110=233
20250411-02:06:49.770907000 : 8=FIXT.1.19=32735=X49=Coinbase56=24ab46f784d1b20db435b852086e325034=38550=TEST52=20250411-02:06:49.650128369=46262=ecae6588-1a56-49ad-9a18-1bac314fe7a4268=1279=0269=2278=c5b88ea9-605d-4595-ac52-f7c3f08523ba83=159758991655=BTC-USD270=3.55271=0.6222240960=20250411-02:06:49.64786837=e68b2ba9-f66d-4d70-913d-9fabceb6b2815797=110=132
20250411-02:06:49.771083000 : 8=FIXT.1.19=26635=X49=Coinbase56=24ab46f784d1b20db435b852086e325034=38650=TEST52=20250411-02:06:49.650132369=46262=ecae6588-1a56-49ad-9a18-1bac314fe7a4268=1279=2269=0278=e68b2ba9-f66d-4d70-913d-9fabceb6b28183=159758991755=BTC-USD60=20250411-02:06:49.64786858=FILLED10=252
20250411-02:06:49.800950000 : 8=FIXT.1.19=27535=X49=Coinbase56=24ab46f784d1b20db435b852086e325034=38750=TEST52=20250411-02:06:49.679402369=46262=ecae6588-1a56-49ad-9a18-1bac314fe7a4268=1279=0269=183=159758991855=BTC-USD271=0.6214689360=20250411-02:06:49.67779740=137=ea512fb0-9ee2-4ebb-9d72-a36eb713c8ab10=074
20250411-02:06:49.801376000 : 8=FIXT.1.19=32735=X49=Coinbase56=24ab46f784d1b20db435b852086e325034=38850=TEST52=20250411-02:06:49.679407369=46262=ecae6588-1a56-49ad-9a18-1bac314fe7a4268=1279=0269=2278=24de32b2-a7f5-469c-a714-c9b10ee2cce583=159758991955=BTC-USD270=3.54271=0.6214689360=20250411-02:06:49.67779737=ea512fb0-9ee2-4ebb-9d72-a36eb713c8ab5797=210=022
20250411-02:06:49.801540000 : 8=FIXT.1.19=28135=X49=Coinbase56=24ab46f784d1b20db435b852086e325034=38950=TEST52=20250411-02:06:49.679411369=46262=ecae6588-1a56-49ad-9a18-1bac314fe7a4268=1279=2269=1278=ea512fb0-9ee2-4ebb-9d72-a36eb713c8ab83=159758992055=BTC-USD271=0.0000000060=20250411-02:06:49.67779758=FILLED10=220
20250411-02:06:49.827989000 : 8=FIXT.1.19=27935=X49=Coinbase56=24ab46f784d1b20db435b852086e325034=39050=TEST52=20250411-02:06:49.706837369=46262=ecae6588-1a56-49ad-9a18-1bac314fe7a4268=1279=0269=083=159758992155=BTC-USD29004=2.208895519560=20250411-02:06:49.70568340=137=d9a8cbb3-ddfd-4e4d-9a02-21dccf0e006510=052
20250411-02:06:49.828460000 : 8=FIXT.1.19=32735=X49=Coinbase56=24ab46f784d1b20db435b852086e325034=39150=TEST52=20250411-02:06:49.706843369=46262=ecae6588-1a56-49ad-9a18-1bac314fe7a4268=1279=0269=2278=c5b88ea9-605d-4595-ac52-f7c3f08523ba83=159758992255=BTC-USD270=3.55271=0.6222240960=20250411-02:06:49.70568337=d9a8cbb3-ddfd-4e4d-9a02-21dccf0e00655797=110=196
20250411-02:06:49.828651000 : 8=FIXT.1.19=26635=X49=Coinbase56=24ab46f784d1b20db435b852086e325034=39250=TEST52=20250411-02:06:49.706847369=46262=ecae6588-1a56-49ad-9a18-1bac314fe7a4268=1279=2269=0278=d9a8cbb3-ddfd-4e4d-9a02-21dccf0e006583=159758992355=BTC-USD60=20250411-02:06:49.70568358=FILLED10=069
20250411-02:06:49.859781000 : 8=FIXT.1.19=27535=X49=Coinbase56=24ab46f784d1b20db435b852086e325034=39350=TEST52=20250411-02:06:49.736198369=46262=ecae6588-1a56-49ad-9a18-1bac314fe7a4268=1279=0269=183=159758992455=BTC-USD271=0.6197183160=20250411-02:06:49.73485240=137=e8840a24-0068-40da-8e24-f65ad97aaf4610=083
20250411-02:06:49.860055000 : 8=FIXT.1.19=32735=X49=Coinbase56=24ab46f784d1b20db435b852086e325034=39450=TEST52=20250411-02:06:49.736204369=46262=ecae6588-1a56-49ad-9a18-1bac314fe7a4268=1279=0269=2278=24de32b2-a7f5-469c-a714-c9b10ee2cce583=159758992555=BTC-USD270=3.54271=0.6197183160=20250411-02:06:49.73485237=e8840a24-0068-40da-8e24-f65ad97aaf465797=210=014
20250411-02:06:49.860200000 : 8=FIXT.1.19=28135=X49=Coinbase56=24ab46f784d1b20db435b852086e325034=39550=TEST52=20250411-02:06:49.736207369=46262=ecae6588-1a56-49ad-9a18-1bac314fe7a4268=1279=2269=1278=e8840a24-0068-40da-8e24-f65ad97aaf4683=159758992655=BTC-USD271=0.0000000060=20250411-02:06:49.73485258=FILLED10=232
20250411-02:06:50.088454000 : 8=FIXT.1.19=28435=X49=Coinbase56=24ab46f784d1b20db435b852086e325034=39650=TEST52=20250411-02:06:49.967649369=46262=ecae6588-1a56-49ad-9a18-1bac314fe7a4268=1279=0269=183=159758992755=BTC-USD270=3.32271=0.6214689360=20250411-02:06:49.96584240=237=ec1b9512-1eec-418f-af1a-1364d1177bfb10=134
20250411-02:06:50.088939000 : 8=FIXT.1.19=32735=X49=Coinbase56=24ab46f784d1b20db435b852086e325034=39750=TEST52=20250411-02:06:49.967662369=46262=ecae6588-1a56-49ad-9a18-1bac314fe7a4268=1279=0269=2278=24de32b2-a7f5-469c-a714-c9b10ee2cce583=159758992855=BTC-USD270=3.54271=0.6214689360=20250411-02:06:49.96584237=ec1b9512-1eec-418f-af1a-1364d1177bfb5797=210=170
20250411-02:06:50.089117000 : 8=FIXT.1.19=29035=X49=Coinbase56=24ab46f784d1b20db435b852086e325034=39850=TEST52=20250411-02:06:49.967667369=46262=ecae6588-1a56-49ad-9a18-1bac314fe7a4268=1279=2269=1278=ec1b9512-1eec-418f-af1a-1364d1177bfb83=159758992955=BTC-USD270=3.32271=0.0000000060=20250411-02:06:49.96584258=FILLED10=032
20250411-02:06:50.089285000 : 8=FIXT.1.19=28435=X49=Coinbase56=24ab46f784d1b20db435b852086e325034=39950=TEST52=20250411-02:06:49.967671369=46262=ecae6588-1a56-49ad-9a18-1bac314fe7a4268=1279=0269=183=159758993055=BTC-USD270=3.25271=0.6214689360=20250411-02:06:49.96584240=237=367c393f-b3f0-4224-bd00-eee7645c427f10=254
20250411-02:06:50.089443000 : 8=FIXT.1.19=32735=X49=Coinbase56=24ab46f784d1b20db435b852086e325034=40050=TEST52=20250411-02:06:49.967675369=46262=ecae6588-1a56-49ad-9a18-1bac314fe7a4268=1279=0269=2278=24de32b2-a7f5-469c-a714-c9b10ee2cce583=159758993155=BTC-USD270=3.54271=0.6214689360=20250411-02:06:49.96584237=367c393f-b3f0-4224-bd00-eee7645c427f5797=210=023
20250411-02:06:50.089590000 : 8=FIXT.1.19=29035=X49=Coinbase56=24ab46f784d1b20db435b852086e325034=40150=TEST52=20250411-02:06:49.967679369=46262=ecae6588-1a56-49ad-9a18-1bac314fe7a4268=1279=2269=1278=367c393f-b3f0-4224-bd00-eee7645c427f83=159758993255=BTC-USD270=3.25271=0.0000000060=20250411-02:06:49.96584258=FILLED10=142
20250411-02:06:50.169002000 : 8=FIXT.1.19=27935=X49=Coinbase56=24ab46f784d1b20db435b852086e325034=40250=TEST52=20250411-02:06:50.048915369=46262=ecae6588-1a56-49ad-9a18-1bac314fe7a4268=1279=0269=083=159758993355=BTC-USD29004=2.208895519560=20250411-02:06:50.04760040=137=0b397a89-d5e9-4243-a12f-e85211e462e210=162
20250411-02:06:50.169394000 : 8=FIXT.1.19=32735=X49=Coinbase56=24ab46f784d1b20db435b852086e325034=40350=TEST52=20250411-02:06:50.048920369=46262=ecae6588-1a56-49ad-9a18-1bac314fe7a4268=1279=0269=2278=c5b88ea9-605d-4595-ac52-f7c3f08523ba83=159758993455=BTC-USD270=3.55271=0.6222240960=20250411-02:06:50.04760037=0b397a89-d5e9-4243-a12f-e85211e462e25797=110=049
20250411-02:06:50.169599000 : 8=FIXT.1.19=26635=X49=Coinbase56=24ab46f784d1b20db435b852086e325034=40450=TEST52=20250411-02:06:50.048924369=46262=ecae6588-1a56-49ad-9a18-1bac314fe7a4268=1279=2269=0278=0b397a89-d5e9-4243-a12f-e85211e462e283=159758993555=BTC-USD60=20250411-02:06:50.04760058=FILLED10=178
20250411-02:06:50.198187000 : 8=FIXT.1.19=27535=X49=Coinbase56=24ab46f784d1b20db435b852086e325034=40550=TEST52=20250411-02:06:50.078334369=46262=ecae6588-1a56-49ad-9a18-1bac314fe7a4268=1279=0269=183=159758993655=BTC-USD271=0.6214689360=20250411-02:06:50.07643540=137=4543da99-7f43-4641-9355-e64660e99a2410=093
20250411-02:06:50.198590000 : 8=FIXT.1.19=32735=X49=Coinbase56=24ab46f784d1b20db435b852086e325034=40650=TEST52=20250411-02:06:50.078340369=46262=ecae6588-1a56-49ad-9a18-1bac314fe7a4268=1279=0269=2278=24de32b2-a7f5-469c-a714-c9b10ee2cce583=159758993755=BTC-USD270=3.54271=0.6214689360=20250411-02:06:50.07643537=4543da99-7f43-4641-9355-e64660e99a245797=210=033
20250411-02:06:50.198802000 : 8=FIXT.1.19=28135=X49=Coinbase56=24ab46f784d1b20db435b852086e325034=40750=TEST52=20250411-02:06:50.078344369=46262=ecae6588-1a56-49ad-9a18-1bac314fe7a4268=1279=2269=1278=4543da99-7f43-4641-9355-e64660e99a2483=159758993855=BTC-USD271=0.0000000060=20250411-02:06:50.07643558=FILLED10=249
20250411-02:06:50.198984000 : 8=FIXT.1.19=28435=X49=Coinbase56=24ab46f784d1b20db435b852086e325034=40850=TEST52=20250411-02:06:50.078397369=46262=ecae6588-1a56-49ad-9a18-1bac314fe7a4268=1279=0269=083=159758993955=BTC-USD270=3.75271=0.6214689360=20250411-02:06:50.07724740=237=48821956-26c5-47e7-afce-1e6160ff24d510=200
20250411-02:06:50.199142000 : 8=FIXT.1.19=32735=X49=Coinbase56=24ab46f784d1b20db435b852086e325034=40950=TEST52=20250411-02:06:50.078406369=46262=ecae6588-1a56-49ad-9a18-1bac314fe7a4268=1279=0269=2278=c5b88ea9-605d-4595-ac52-f7c3f08523ba83=159758994055=BTC-USD270=3.55271=0.6214689360=20250411-02:06:50.07724737=48821956-26c5-47e7-afce-1e6160ff24d55797=110=136
20250411-02:06:50.199290000 : 8=FIXT.1.19=29035=X49=Coinbase56=24ab46f784d1b20db435b852086e325034=41050=TEST52=20250411-02:06:50.078409369=46262=ecae6588-1a56-49ad-9a18-1bac314fe7a4268=1279=2269=0278=48821956-26c5-47e7-afce-1e6160ff24d583=159758994155=BTC-USD270=3.75271=0.0000000060=20250411-02:06:50.07724758=FILLED10=074
20250411-02:06:51.356311000 : 8=FIXT.1.19=27935=X49=Coinbase56=24ab46f784d1b20db435b852086e325034=41150=TEST52=20250411-02:06:51.192637369=46262=ecae6588-1a56-49ad-9a18-1bac314fe7a4268=1279=0269=083=159758994255=BTC-USD29004=2.208895519560=20250411-02:06:51.19116240=137=b87da9d3-4b3a-45f3-a768-df7ec7daf9ef10=060
20250411-02:06:51.357158000 : 8=FIXT.1.19=32735=X49=Coinbase56=24ab46f784d1b20db435b852086e325034=41250=TEST52=20250411-02:06:51.192644369=46262=ecae6588-1a56-49ad-9a18-1bac314fe7a4268=1279=0269=2278=c5b88ea9-605d-4595-ac52-f7c3f08523ba83=159758994355=BTC-USD270=3.55271=0.6222240960=20250411-02:06:51.19116237=b87da9d3-4b3a-45f3-a768-df7ec7daf9ef5797=110=205
20250411-02:06:51.357399000 : 8=FIXT.1.19=26635=X49=Coinbase56=24ab46f784d1b20db435b852086e325034=41350=TEST52=20250411-02:06:51.192648369=46262=ecae6588-1a56-49ad-9a18-1bac314fe7a4268=1279=2269=0278=b87da9d3-4b3a-45f3-a768-df7ec7daf9ef83=159758994455=BTC-USD60=20250411-02:06:51.19116258=FILLED10=078
20250411-02:06:51.357632000 : 8=FIXT.1.19=27535=X49=Coinbase56=24ab46f784d1b20db435b852086e325034=41450=TEST52=20250411-02:06:51.219869369=46262=ecae6588-1a56-49ad-9a18-1bac314fe7a4268=1279=0269=183=159758994555=BTC-USD271=0.6197183160=20250411-02:06:51.21885140=137=64ba5333-b44e-4e86-b385-eb6b7156561910=231
20250411-02:06:51.357804000 : 8=FIXT.1.19=32735=X49=Coinbase56=24ab46f784d1b20db435b852086e325034=41550=TEST52=20250411-02:06:51.219878369=46262=ecae6588-1a56-49ad-9a18-1bac314fe7a4268=1279=0269=2278=24de32b2-a7f5-469c-a714-c9b10ee2cce583=159758994655=BTC-USD270=3.54271=0.6197183160=20250411-02:06:51.21885137=64ba5333-b44e-4e86-b385-eb6b715656195797=210=174
20250411-02:06:51.357958000 : 8=FIXT.1.19=28135=X49=Coinbase56=24ab46f784d1b20db435b852086e325034=41650=TEST52=20250411-02:06:51.219882369=46262=ecae6588-1a56-49ad-9a18-1bac314fe7a4268=1279=2269=1278=64ba5333-b44e-4e86-b385-eb6b7156561983=159758994755=BTC-USD271=0.0000000060=20250411-02:06:51.21885158=FILLED10=128
20250411-02:06:51.371528000 : 8=FIXT.1.19=27935=X49=Coinbase56=24ab46f784d1b20db435b852086e325034=41750=TEST52=20250411-02:06:51.250447369=46262=ecae6588-1a56-49ad-9a18-1bac314fe7a4268=1279=0269=083=159758994855=BTC-USD29004=2.208895519560=20250411-02:06:51.24924440=137=b28ff60f-392a-4116-bbb9-0b84d8b5d99310=072
20250411-02:06:51.371687000 : 8=FIXT.1.19=32735=X49=Coinbase56=24ab46f784d1b20db435b852086e325034=41850=TEST52=20250411-02:06:51.250454369=46262=ecae6588-1a56-49ad-9a18-1bac314fe7a4268=1279=0269=2278=c5b88ea9-605d-4595-ac52-f7c3f08523ba83=159758994955=BTC-USD270=3.55271=0.6222240960=20250411-02:06:51.24924437=b28ff60f-392a-4116-bbb9-0b84d8b5d9935797=110=217
20250411-02:06:51.371857000 : 8=FIXT.1.19=26635=X49=Coinbase56=24ab46f784d1b20db435b852086e325034=41950=TEST52=20250411-02:06:51.250458369=46262=ecae6588-1a56-49ad-9a18-1bac314fe7a4268=1279=2269=0278=b28ff60f-392a-4116-bbb9-0b84d8b5d99383=159758995055=BTC-USD60=20250411-02:06:51.24924458=FILLED10=081
20250411-02:06:51.398845000 : 8=FIXT.1.19=27535=X49=Coinbase56=24ab46f784d1b20db435b852086e325034=42050=TEST52=20250411-02:06:51.277848369=46262=ecae6588-1a56-49ad-9a18-1bac314fe7a4268=1279=0269=183=159758995155=BTC-USD271=0.6197183160=20250411-02:06:51.27586340=137=ae0ef415-e174-4a26-b37b-19cf9853160110=009
20250411-02:06:51.399188000 : 8=FIXT.1.19=32735=X49=Coinbase56=24ab46f784d1b20db435b852086e325034=42150=TEST52=20250411-02:06:51.277855369=46262=ecae6588-1a56-49ad-9a18-1bac314fe7a4268=1279=0269=2278=24de32b2-a7f5-469c-a714-c9b10ee2cce583=159758995255=BTC-USD270=3.54271=0.6197183160=20250411-02:06:51.27586337=ae0ef415-e174-4a26-b37b-19cf985316015797=210=206
20250411-02:06:51.399331000 : 8=FIXT.1.19=28135=X49=Coinbase56=24ab46f784d1b20db435b852086e325034=42250=TEST52=20250411-02:06:51.277859369=46262=ecae6588-1a56-49ad-9a18-1bac314fe7a4268=1279=2269=1278=ae0ef415-e174-4a26-b37b-19cf9853160183=159758995355=BTC-USD271=0.0000000060=20250411-02:06:51.27586358=FILLED10=169
20250411-02:06:51.483362000 : 8=FIXT.1.19=27935=X49=Coinbase56=24ab46f784d1b20db435b852086e325034=42350=TEST52=20250411-02:06:51.363420369=46262=ecae6588-1a56-49ad-9a18-1bac314fe7a4268=1279=0269=083=159758995455=BTC-USD29004=2.208895519560=20250411-02:06:51.36209640=137=4446df44-4ab2-498c-890b-c97029642f1310=131
20250411-02:06:51.483587000 : 8=FIXT.1.19=32735=X49=Coinbase56=24ab46f784d1b20db435b852086e325034=42450=TEST52=20250411-02:06:51.363426369=46262=ecae6588-1a56-49ad-9a18-1bac314fe7a4268=1279=0269=2278=c5b88ea9-605d-4595-ac52-f7c3f08523ba83=159758995555=BTC-USD270=3.55271=0.6222240960=20250411-02:06:51.36209637=4446df44-4ab2-498c-890b-c97029642f135797=110=028
20250411-02:06:51.483800000 : 8=FIXT.1.19=26635=X49=Coinbase56=24ab46f784d1b20db435b852086e325034=42550=TEST52=20250411-02:06:51.363429369=46262=ecae6588-1a56-49ad-9a18-1bac314fe7a4268=1279=2269=0278=4446df44-4ab2-498c-890b-c97029642f1383=159758995655=BTC-USD60=20250411-02:06:51.36209658=FILLED10=156
20250411-02:06:51.511804000 : 8=FIXT.1.19=27535=X49=Coinbase56=24ab46f784d1b20db435b852086e325034=42650=TEST52=20250411-02:06:51.391859369=46262=ecae6588-1a56-49ad-9a18-1bac314fe7a4268=1279=0269=183=159758995755=BTC-USD271=0.6214689360=20250411-02:06:51.39053740=137=eb224df3-c7bd-4be4-bd66-301ccdaf570310=041
20250411-02:06:51.512250000 : 8=FIXT.1.19=32735=X49=Coinbase56=24ab46f784d1b20db435b852086e325034=42750=TEST52=20250411-02:06:51.391866369=46262=ecae6588-1a56-49ad-9a18-1bac314fe7a4268=1279=0269=2278=24de32b2-a7f5-469c-a714-c9b10ee2cce583=159758995855=BTC-USD270=3.54271=0.6214689360=20250411-02:06:51.39053737=eb224df3-c7bd-4be4-bd66-301ccdaf57035797=210=238
20250411-02:06:51.512562000 : 8=FIXT.1.19=28135=X49=Coinbase56=24ab46f784d1b20db435b852086e325034=42850=TEST52=20250411-02:06:51.391871369=46262=ecae6588-1a56-49ad-9a18-1bac314fe7a4268=1279=2269=1278=eb224df3-c7bd-4be4-bd66-301ccdaf570383=159758995955=BTC-USD271=0.0000000060=20250411-02:06:51.39053758=FILLED10=190
20250411-02:06:51.655710000 : 8=FIXT.1.19=27935=X49=Coinbase56=24ab46f784d1b20db435b852086e325034=42950=TEST52=20250411-02:06:51.535115369=46262=ecae6588-1a56-49ad-9a18-1bac314fe7a4268=1279=0269=083=159758996055=BTC-USD29004=2.208895519560=20250411-02:06:51.53372940=137=db766301-c541-482d-8992-0a432622e9ea10=127
20250411-02:06:51.656271000 : 8=FIXT.1.19=32735=X49=Coinbase56=24ab46f784d1b20db435b852086e325034=43050=TEST52=20250411-02:06:51.535121369=46262=ecae6588-1a56-49ad-9a18-1bac314fe7a4268=1279=0269=2278=c5b88ea9-605d-4595-ac52-f7c3f08523ba83=159758996155=BTC-USD270=3.55271=0.6222240960=20250411-02:06:51.53372937=db766301-c541-482d-8992-0a432622e9ea5797=110=006
20250411-02:06:51.656507000 : 8=FIXT.1.19=26635=X49=Coinbase56=24ab46f784d1b20db435b852086e325034=43150=TEST52=20250411-02:06:51.535125369=46262=ecae6588-1a56-49ad-9a18-1bac314fe7a4268=1279=2269=0278=db766301-c541-482d-8992-0a432622e9ea83=159758996255=BTC-USD60=20250411-02:06:51.53372958=FILLED10=135
20250411-02:06:51.684181000 : 8=FIXT.1.19=27535=X49=Coinbase56=24ab46f784d1b20db435b852086e325034=43250=TEST52=20250411-02:06:51.563407369=46262=ecae6588-1a56-49ad-9a18-1bac314fe7a4268=1279=0269=183=159758996355=BTC-USD271=0.6214689360=20250411-02:06:51.56253740=137=5a1dc09c-ab61-4c93-9c3a-577cd6459d9d10=163
20250411-02:06:51.684363000 : 8=FIXT.1.19=32735=X49=Coinbase56=24ab46f784d1b20db435b852086e325034=43350=TEST52=20250411-02:06:51.563415369=46262=ecae6588-1a56-49ad-9a18-1bac314fe7a4268=1279=0269=2278=24de32b2-a7f5-469c-a714-c9b10ee2cce583=159758996455=BTC-USD270=3.54271=0.6214689360=20250411-02:06:51.56253737=5a1dc09c-ab61-4c93-9c3a-577cd6459d9d5797=210=105
20250411-02:06:51.684504000 : 8=FIXT.1.19=28135=X49=Coinbase56=24ab46f784d1b20db435b852086e325034=43450=TEST52=20250411-02:06:51.563419369=46262=ecae6588-1a56-49ad-9a18-1bac314fe7a4268=1279=2269=1278=5a1dc09c-ab61-4c93-9c3a-577cd6459d9d83=159758996555=BTC-USD271=0.0000000060=20250411-02:06:51.56253758=FILLED10=065
20250411-02:06:51.884905000 : 8=FIXT.1.19=27935=X49=Coinbase56=24ab46f784d1b20db435b852086e325034=43550=TEST52=20250411-02:06:51.764049369=46262=ecae6588-1a56-49ad-9a18-1bac314fe7a4268=1279=0269=083=159758996655=BTC-USD29004=2.208895519560=20250411-02:06:51.76236140=137=7680b41c-65ad-4df2-b50c-57e52ddf03a210=109
20250411-02:06:51.885405000 : 8=FIXT.1.19=32735=X49=Coinbase56=24ab46f784d1b20db435b852086e325034=43650=TEST52=20250411-02:06:51.764057369=46262=ecae6588-1a56-49ad-9a18-1bac314fe7a4268=1279=0269=2278=c5b88ea9-605d-4595-ac52-f7c3f08523ba83=159758996755=BTC-USD270=3.55271=0.6222240960=20250411-02:06:51.76236137=7680b41c-65ad-4df2-b50c-57e52ddf03a25797=110=255
20250411-02:06:51.885573000 : 8=FIXT.1.19=26635=X49=Coinbase56=24ab46f784d1b20db435b852086e325034=43750=TEST52=20250411-02:06:51.764061369=46262=ecae6588-1a56-49ad-9a18-1bac314fe7a4268=1279=2269=0278=7680b41c-65ad-4df2-b50c-57e52ddf03a283=159758996855=BTC-USD60=20250411-02:06:51.76236158=FILLED10=119
20250411-02:06:51.911726000 : 8=FIXT.1.19=27535=X49=Coinbase56=24ab46f784d1b20db435b852086e325034=43850=TEST52=20250411-02:06:51.791335369=46262=ecae6588-1a56-49ad-9a18-1bac314fe7a4268=1279=0269=183=159758996955=BTC-USD271=0.6214689360=20250411-02:06:51.79035840=137=be4388fd-c2a8-4fbc-b3b7-71000539eec210=215
20250411-02:06:51.912085000 : 8=FIXT.1.19=32735=X49=Coinbase56=24ab46f784d1b20db435b852086e325034=43950=TEST52=20250411-02:06:51.791343369=46262=ecae6588-1a56-49ad-9a18-1bac314fe7a4268=1279=0269=2278=24de32b2-a7f5-469c-a714-c9b10ee2cce583=159758997055=BTC-USD270=3.54271=0.6214689360=20250411-02:06:51.79035837=be4388fd-c2a8-4fbc-b3b7-71000539eec25797=210=148
20250411-02:06:51.912351000 : 8=FIXT.1.19=28135=X49=Coinbase56=24ab46f784d1b20db435b852086e325034=44050=TEST52=20250411-02:06:51.791347369=46262=ecae6588-1a56-49ad-9a18-1bac314fe7a4268=1279=2269=1278=be4388fd-c2a8-4fbc-b3b7-71000539eec283=159758997155=BTC-USD271=0.0000000060=20250411-02:06:51.79035858=FILLED10=099
