20250411-02:00:27.188810000 : 8=FIXT.1.19=90835=W49=Coinbase56=24ab46f784d1b20db435b852086e325034=3650=TEST52=20250411-02:00:27.061671369=2262=38b76e38-5a27-4fa7-8aa2-3c519fd2251e83=1597582071893=N55=BTC-USD1682=full_trading268=10269=0278=75bce2b7-bc58-4479-8bfb-144f88f2262b270=1.93271=0.52331606269=0278=1f6e2a79-8b10-4a7f-89de-0f1fa03692c7270=1.93271=0.52331606269=0278=d1b80bf5-9b17-44b4-9577-6fe71170b578270=1.93271=0.52331606269=0278=b891e26a-c20c-4fce-ba1c-487fe139a4cc270=1.93271=0.52331606269=0278=5d06d3f6-3189-4394-b3c5-6a2bda14b6d1270=1.93271=0.52331606269=0278=e5791c0f-3937-4a66-9b98-26f79a3891be270=1.93271=0.52331606269=0278=c62591c6-7dfa-46a7-8f20-6a5f22804999270=1.93271=0.52331606269=0278=7c503558-c0b8-457b-8c46-71ece3f7fc8a270=1.93271=0.52331606269=0278=f763bb56-2f21-4a9b-bd48-f84dc1bd5ee5270=1.93271=0.52331606269=0278=42214b03-1fc2-46b3-9e83-91b23a510e5a270=1.93271=0.5233160610=232
20250411-02:00:27.189583000 : 8=FIXT.1.19=14135=334=1249=24ab46f784d1b20db435b852086e325052=20250411-02:00:27.18956=Coinbase45=3658=Tag appears more than once371=269372=W373=1310=250
20250411-02:00:27.190091000 : 8=FIXT.1.19=90835=W49=Coinbase56=24ab46f784d1b20db435b852086e325034=3750=TEST52=20250411-02:00:27.061921369=2262=38b76e38-5a27-4fa7-8aa2-3c519fd2251e83=1597582071893=N55=BTC-USD1682=full_trading268=10269=0278=1c7c52ed-7d39-4326-b3b8-98f05a9b3ef0270=1.93271=0.52331606269=0278=3313309e-45e7-4e7b-8c55-4f9a8ec1b351270=1.93271=0.52331606269=0278=78801ffb-ec5a-4c74-9d08-3e86fd9db4dd270=1.93271=0.52331606269=0278=abe6eea4-1d9c-47d7-847f-2f44aa561b3f270=1.93271=0.52331606269=0278=6a6eb56d-2010-43e2-b78e-5f098081bb64270=1.93271=0.52331606269=0278=b53c01ff-f450-4b05-8ad1-e7894b45e0e0270=1.93271=0.52331606269=0278=4747863e-c0a6-4ef5-8faf-e8934bca4f8b270=1.93271=0.52331606269=0278=81a8a629-57f4-4e3a-ac25-2e9ee1f357c2270=1.93271=0.52331606269=0278=1e239259-7be4-476a-845d-1b92fd951d8b270=1.93271=0.52331606269=0278=189eb272-48f9-4915-b7e1-a86dcc505c4a270=1.93271=0.5233160610=068
20250411-02:00:27.191231000 : 8=FIXT.1.19=14135=334=1349=24ab46f784d1b20db435b852086e325052=20250411-02:00:27.19056=Coinbase45=3758=Tag appears more than once371=269372=W373=1310=244
20250411-02:00:27.206061000 : 8=FIXT.1.19=90835=W49=Coinbase56=24ab46f784d1b20db435b852086e325034=3850=TEST52=20250411-02:00:27.062171369=2262=38b76e38-5a27-4fa7-8aa2-3c519fd2251e83=1597582071893=N55=BTC-USD1682=full_trading268=10269=0278=0562b9f7-aae3-4961-bd97-f5b8cde0ec34270=1.93271=0.52331606269=0278=5103331b-7300-487b-bc2c-a6032bf4be7e270=1.93271=0.52331606269=0278=78ac85ac-2478-4991-a084-7286982b77cc270=1.93271=0.52331606269=0278=6993b26d-d6dc-4f99-8a53-9500ae5b4ff1270=1.93271=0.52331606269=0278=1c96ab9d-04a6-465a-87e5-3ed33970178f270=1.93271=0.52331606269=0278=6fc0282b-d538-4aa3-8982-bda02bb1b054270=1.93271=0.52331606269=0278=80870aa3-04a2-4d2a-8669-93215130ffee270=1.93271=0.52331606269=0278=b274e872-6923-45fd-b48a-68e685e769cb270=1.93271=0.52331606269=0278=2d4364c0-239c-4f4b-8ce4-2acfe0bb343d270=1.12271=1.00000000269=0278=8fa16a4f-377f-4deb-9a8e-1020aed9edf4270=1.00271=1.0000000010=223
20250411-02:00:27.206649000 : 8=FIXT.1.19=14135=334=1449=24ab46f784d1b20db435b852086e325052=20250411-02:00:27.20656=Coinbase45=3858=Tag appears more than once371=269372=W373=1310=244
20250411-02:00:27.206731000 : 8=FIXT.1.19=92335=W49=Coinbase56=24ab46f784d1b20db435b852086e325034=3950=TEST52=20250411-02:00:27.062421369=2262=38b76e38-5a27-4fa7-8aa2-3c519fd2251e83=1597582071893=N55=BTC-USD1682=full_trading268=10269=1278=c5b88ea9-605d-4595-ac52-f7c3f08523ba270=3.55271=5573.01232776269=1278=81523bd3-8912-4789-8761-89a9ee42794b270=3.55271=0.30518966269=1278=60fc75ca-0052-40b7-9f18-a6aad9d31b84270=3.56271=18037.00000000269=1278=ad00e2cd-d925-46a4-9e7e-941c6faed2c7270=3.57271=18027.00000000269=1278=fec191b5-64da-4a15-ab4b-36a0d3d10750270=3.57271=0.29025301269=1278=792fa54a-2068-4c20-ba3f-6579c5d1b042270=3.57271=0.62184873269=1278=0d43f23a-5517-46ec-8191-7b19b0c83f70270=3.57271=0.62322946269=1278=cdf1353d-a3bb-4f74-95ad-759d60d356a0270=3.57271=0.62322946269=1278=02a780aa-8154-4638-a5ca-53b8198cc724270=3.58271=16937.00000000269=1278=911349fb-1960-4904-9a38-0e2497fb7ccb270=3.58271=0.2989631210=158
20250411-02:00:27.207411000 : 8=FIXT.1.19=14135=334=1549=24ab46f784d1b20db435b852086e325052=20250411-02:00:27.20756=Coinbase45=3958=Tag appears more than once371=269372=W373=1310=247
20250411-02:00:27.207499000 : 8=FIXT.1.19=93235=W49=Coinbase56=24ab46f784d1b20db435b852086e325034=4050=TEST52=20250411-02:00:27.062671369=2262=38b76e38-5a27-4fa7-8aa2-3c519fd2251e83=1597582071893=N55=BTC-USD1682=full_trading268=10269=1278=d91e89d4-ac5c-4853-9879-ec8ff5e00a71270=3.59271=17163.00000000269=1278=341d0ad8-6c15-4b5e-aebb-e3caa5af575c270=3.60271=17926.00000000269=1278=19f17d37-d517-4a55-bfc5-9d93c206d1ba270=3.60271=0.62322946269=1278=9d239e03-1215-4cc7-ad44-3f4097ee70ea270=3.61271=18058.08928020269=1278=dbb0f332-4189-4df5-879b-e55860b13def270=3.62271=0.28062774269=1278=f7639c39-7e8b-44d1-a2f2-9807e2a3228c270=3.62271=0.27709851269=1278=83be9389-2099-4173-a322-b0933bc99358270=3.62271=19973.00000000269=1278=b89abc22-6b6c-4474-b3fc-ffe21f05cd4e270=3.63271=20016.00000000269=1278=ce0af8a3-149c-4603-905a-be65625fe014270=3.64271=0.27806002269=1278=94b8615f-6fa7-4dc9-bbfa-435fe535bebc270=3.64271=22352.6348945910=057
20250411-02:00:27.208036000 : 8=FIXT.1.19=14135=334=1649=24ab46f784d1b20db435b852086e325052=20250411-02:00:27.20756=Coinbase45=4058=Tag appears more than once371=269372=W373=1310=240
20250411-02:00:27.208122000 : 8=FIXT.1.19=90835=W49=Coinbase56=24ab46f784d1b20db435b852086e325034=4150=TEST52=20250411-02:00:27.062921369=2262=38b76e38-5a27-4fa7-8aa2-3c519fd2251e83=1597582071893=N55=BTC-USD1682=full_trading268=10269=1278=cae3885d-f5b2-4de1-830c-0085e27bbb69270=3.69271=0.27722678269=1278=98b269f7-e916-4d1c-936f-585d9d9b2a38270=3.70271=0.62322946269=1278=b9732128-11b1-44fd-bea3-94da9fc853fb270=3.71271=0.28488329269=1278=818b83a4-e14e-4ad5-b094-6733f0504003270=3.75271=0.27930225269=1278=3e6990a0-8ef4-4968-8ee8-89b7346c197d270=3.76271=0.28131365269=1278=342794c8-a9d2-4aa5-9886-a819398d69c6270=3.88271=0.27719712269=1278=2839680b-48b3-4f53-86b1-9269987275e7270=3.91271=0.26621275269=1278=fd7b5361-29f8-4b35-bae5-232a64f657b4270=3.95271=0.26131406269=1278=5edaeed0-fae9-4f36-8c77-6fbedf61eefc270=4.02271=0.25091227269=1278=fdbbfd04-ba67-4b23-bbc1-f87f929e7e81270=4.07271=0.2481264210=105
20250411-02:00:27.208618000 : 8=FIXT.1.19=14135=334=1749=24ab46f784d1b20db435b852086e325052=20250411-02:00:27.20856=Coinbase45=4158=Tag appears more than once371=269372=W373=1310=243
20250411-02:00:27.218414000 : 8=FIXT.1.19=92435=W49=Coinbase56=24ab46f784d1b20db435b852086e325034=4250=TEST52=20250411-02:00:27.063171369=2262=38b76e38-5a27-4fa7-8aa2-3c519fd2251e83=1597582071893=N55=BTC-USD1682=full_trading268=10269=1278=534b2a85-0852-420d-928b-70cdb6ba2457270=4.10271=0.26961968269=1278=b009f8a1-4a39-493b-b96e-d783e981c915270=4.26271=0.25019574269=1278=729a899c-ac2d-4541-b0a2-cbdd5df9bf98270=10.00271=10.00000000269=1278=eb1e5d45-d081-4ef8-a83e-1f5348fbda96270=10.00271=10.00000000269=1278=0cd67977-85eb-45fa-ae72-d45b92ca24f4270=10.00271=10.00000000269=1278=5d931559-6758-4b75-9d6d-6438d25b497f270=10.00271=10.00000000269=1278=57e43d1d-644a-493e-acd3-69dc5e64dcde270=10.00271=10.00000000269=1278=c1566121-2b63-494d-ac2d-973e9f0115c0270=10.00271=10.00000000269=1278=d0c4a771-9035-4db9-ae7b-ad2d1db5646d270=10.00271=10.00000000269=1278=52c644ea-628a-4576-8e7e-27ec4c90398b270=10.00271=10.0000000010=072
20250411-02:00:27.219365000 : 8=FIXT.1.19=14135=334=1849=24ab46f784d1b20db435b852086e325052=20250411-02:00:27.21856=Coinbase45=4258=Tag appears more than once371=269372=W373=1310=246
20250411-02:00:27.219484000 : 8=FIXT.1.19=93135=W49=Coinbase56=24ab46f784d1b20db435b852086e325034=4350=TEST52=20250411-02:00:27.063421369=2262=38b76e38-5a27-4fa7-8aa2-3c519fd2251e83=1597582071893=N55=BTC-USD1682=full_trading268=10269=1278=c3483f66-d8ce-489a-90b9-2bce69e054ee270=10.00271=10.00000000269=1278=55992a5c-cbcd-464a-8f8d-8b58e81e5c0b270=10.00271=10.00000000269=1278=19077009-6f26-4e2d-9dab-04a28231b752270=10.00271=10.00000000269=1278=692097d1-c978-4024-95e9-2bf348b64bbd270=10.00271=10.00000000269=1278=99a92935-11b7-4f21-a64c-c746b53d1777270=10.00271=10.00000000269=1278=dc024b0b-0337-4215-9669-5e5636834397270=10.00271=10.00000000269=1278=c90fcc3a-a36c-4c14-b57f-6db78762e017270=10.00271=10.00000000269=1278=7841891a-bb7c-4034-97c1-41164185edc7270=1000.00271=3.10000000269=1278=381c9fa7-1add-4dd2-9233-f41e2c8821fe270=1000.00271=3.10000000269=1278=928e65c2-7e2d-478b-9310-414fb77f5aae270=1000.00271=3.1000000010=157
20250411-02:00:27.220136000 : 8=FIXT.1.19=14135=334=1949=24ab46f784d1b20db435b852086e325052=20250411-02:00:27.21956=Coinbase45=4358=Tag appears more than once371=269372=W373=1310=249
20250411-02:00:27.220237000 : 8=FIXT.1.19=93835=W49=Coinbase56=24ab46f784d1b20db435b852086e325034=4450=TEST52=20250411-02:00:27.063671369=2262=38b76e38-5a27-4fa7-8aa2-3c519fd2251e83=1597582071893=N55=BTC-USD1682=full_trading268=10269=1278=ad4bd3ac-9276-40d5-90f9-e47b1d8ee953270=1000.00271=3.10000000269=1278=79e799dc-4a3d-4922-ad1a-f74eb7eff789270=1000.00271=3.10000000269=1278=04f642b7-750f-4967-b786-0d48eea0f158270=1000.00271=3.10000000269=1278=d0ad653d-3272-4a3b-ba7a-a52029a67a92270=1000.00271=3.10000000269=1278=cad40464-4c62-4bf3-8444-c487fcc8dd01270=1000.00271=3.10000000269=1278=426c6428-d481-4ff7-9de3-f00ff219d654270=1000.00271=3.10000000269=1278=1ed1152d-8c1a-4b29-acdd-bbd1a5c5f35f270=1000.00271=3.10000000269=1278=66526051-b5cb-442f-af90-c609be0a9796270=1000.00271=3.10000000269=1278=f68e4659-5785-4ee9-ac24-3186640a2752270=1000.00271=3.10000000269=1278=38070d38-80a9-4898-8ef7-a0a9da5a4123270=1000.00271=3.1000000010=015
20250411-02:00:27.220887000 : 8=FIXT.1.19=14135=334=2049=24ab46f784d1b20db435b852086e325052=20250411-02:00:27.22056=Coinbase45=4458=Tag appears more than once371=269372=W373=1310=234
20250411-02:00:27.401758000 : 8=FIXT.1.19=93835=W49=Coinbase56=24ab46f784d1b20db435b852086e325034=4550=TEST52=20250411-02:00:27.063921369=2262=38b76e38-5a27-4fa7-8aa2-3c519fd2251e83=1597582071893=N55=BTC-USD1682=full_trading268=10269=1278=e4d2d308-ed11-49db-850e-3cbd8258395d270=1000.00271=3.10000000269=1278=d6cfaadc-97ea-43c1-898d-40faea9c1477270=1000.00271=3.10000000269=1278=36876bea-9e3a-4018-b0ac-b75cb8c16953270=1000.00271=3.10000000269=1278=eb244bc5-49e8-4aa3-af8b-3d1a67c90a08270=1000.00271=3.10000000269=1278=3efba776-29ad-4aeb-82d8-0824f161471e270=1000.00271=3.10000000269=1278=de0ddebd-0ca8-4eca-9985-77c10c8629a9270=1000.00271=3.10000000269=1278=dde4408a-fb6b-441c-a7f3-7b8b23ffdb1f270=1000.00271=3.10000000269=1278=3ebd6434-070f-4b4d-8cf3-00368112466d270=1000.00271=3.10000000269=1278=7aa98e13-65f3-4058-9f91-c1f452d02710270=1000.00271=3.10000000269=1278=e86a1fec-3610-460d-8d85-4e1e222ee159270=1000.00271=3.1000000010=070
20250411-02:00:27.402711000 : 8=FIXT.1.19=14135=334=2149=24ab46f784d1b20db435b852086e325052=20250411-02:00:27.40256=Coinbase45=4558=Tag appears more than once371=269372=W373=1310=238
20250411-02:00:27.402819000 : 8=FIXT.1.19=93835=W49=Coinbase56=24ab46f784d1b20db435b852086e325034=4650=TEST52=20250411-02:00:27.064171369=2262=38b76e38-5a27-4fa7-8aa2-3c519fd2251e83=1597582071893=N55=BTC-USD1682=full_trading268=10269=1278=6dfac057-72b1-4f2c-b110-03766dea0d31270=1000.00271=3.10000000269=1278=bbb7d0ea-d251-4612-b53e-e528cc0a24ab270=1000.00271=3.10000000269=1278=0782ca37-48cf-4ff3-a74a-35674661586c270=1000.00271=3.10000000269=1278=aead437d-4b62-457f-ac83-62c7cc329fd1270=1000.00271=3.10000000269=1278=af5d47bc-a008-4567-b24f-b0298f250471270=1000.00271=3.10000000269=1278=4c260f58-c427-4a9a-969a-44024ae0c714270=1000.00271=3.10000000269=1278=8c7672e5-7ee8-4fbd-8fdf-7e74e9a77db7270=1000.00271=3.10000000269=1278=b53ec3cc-9abe-4570-b903-34d52148073e270=1000.00271=3.10000000269=1278=37ce984a-0387-4ac9-9094-b83f722036ba270=1000.00271=3.10000000269=1278=0d383649-dc6c-4df2-b821-aa0018f132c7270=1000.00271=3.1000000010=023
20250411-02:00:27.403711000 : 8=FIXT.1.19=14135=334=2249=24ab46f784d1b20db435b852086e325052=20250411-02:00:27.40356=Coinbase45=4658=Tag appears more than once371=269372=W373=1310=241
20250411-02:00:27.403789000 : 8=FIXT.1.19=93835=W49=Coinbase56=24ab46f784d1b20db435b852086e325034=4750=TEST52=20250411-02:00:27.064421369=2262=38b76e38-5a27-4fa7-8aa2-3c519fd2251e83=1597582071893=N55=BTC-USD1682=full_trading268=10269=1278=e39ae0ce-9e7f-4f0d-a765-5308d473bb61270=1000.00271=3.10000000269=1278=4882324e-3b5c-4b7a-b096-e8c6d9888671270=1000.00271=3.10000000269=1278=6e5c7dbd-a2cc-401f-a5b2-3902088f4ab2270=1000.00271=3.10000000269=1278=10ffac08-946a-4a30-b57a-0d78450345d9270=1000.00271=3.10000000269=1278=67784af5-72bf-4d16-a6b3-25336e2c1843270=1000.00271=3.10000000269=1278=4d8b3bbc-0dc2-4044-875c-c079ec538136270=1000.00271=3.10000000269=1278=dfba5f1e-21f5-48e3-adce-b8b6bfe71467270=1000.00271=3.10000000269=1278=e51b4e33-5eaa-46ef-936b-a74a890397e8270=1000.00271=3.10000000269=1278=8cf5dfa8-858b-48a3-9d94-78522c257473270=1000.00271=3.10000000269=1278=a153b9d2-993d-4f03-a974-b8a081e128e8270=1000.00271=3.1000000010=055
20250411-02:00:27.404273000 : 8=FIXT.1.19=14135=334=2349=24ab46f784d1b20db435b852086e325052=20250411-02:00:27.40356=Coinbase45=4758=Tag appears more than once371=269372=W373=1310=243
20250411-02:00:27.404354000 : 8=FIXT.1.19=93835=W49=Coinbase56=24ab46f784d1b20db435b852086e325034=4850=TEST52=20250411-02:00:27.064671369=2262=38b76e38-5a27-4fa7-8aa2-3c519fd2251e83=1597582071893=N55=BTC-USD1682=full_trading268=10269=1278=1eebe866-0f6e-4d4a-a28b-78f4e3368b0a270=1000.00271=3.10000000269=1278=300132d8-113f-4bf7-ba0c-4d93a272f55b270=1000.00271=3.10000000269=1278=757f3122-27d2-4f32-90b8-ead1eef9b936270=1000.00271=3.10000000269=1278=2b68b5de-4153-4cac-ace3-102e4fa788fd270=1000.00271=3.10000000269=1278=b01f252a-1657-4df0-a122-58a23109a7c2270=1000.00271=3.10000000269=1278=dbc57e4e-6abd-4d66-8d18-bd13caaa77b1270=1000.00271=3.10000000269=1278=948b05dc-a481-409f-b8ad-a502eb595906270=1000.00271=3.10000000269=1278=e00f9703-6e16-4237-a2c6-701829d11bf1270=1000.00271=3.10000000269=1278=fd52f47a-3f11-47bc-9952-9708617d0ecd270=1000.00271=3.10000000269=1278=f7f75b14-27c3-469c-89fb-6a98b43c61bf270=1000.00271=3.1000000010=217
20250411-02:00:27.404941000 : 8=FIXT.1.19=14135=334=2449=24ab46f784d1b20db435b852086e325052=20250411-02:00:27.40456=Coinbase45=4858=Tag appears more than once371=269372=W373=1310=246
20250411-02:00:27.405025000 : 8=FIXT.1.19=93835=W49=Coinbase56=24ab46f784d1b20db435b852086e325034=4950=TEST52=20250411-02:00:27.064922369=2262=38b76e38-5a27-4fa7-8aa2-3c519fd2251e83=1597582071893=N55=BTC-USD1682=full_trading268=10269=1278=25dbeb09-7901-4280-b0c3-720d7ed03d7d270=1000.00271=3.10000000269=1278=52164a1f-599f-4c43-a9ed-f93403506e67270=1000.00271=3.10000000269=1278=c71c35ea-f60f-4a41-b43a-4947bbcbafad270=1000.00271=3.10000000269=1278=2de342bc-a1be-46f3-9fc6-731297726934270=1000.00271=3.10000000269=1278=7ff4c5fc-bc9b-4845-940b-4837a672e13a270=1000.00271=3.10000000269=1278=2d270775-33eb-4328-8dad-7d206612f9f6270=1000.00271=3.10000000269=1278=c4754378-f787-4100-81af-564443a86a91270=1000.00271=3.10000000269=1278=59e16255-05eb-4fdc-8be1-3c4f83fc094e270=1000.00271=3.10000000269=1278=041b2f98-1185-49cb-964a-f0456b71e692270=1000.00271=3.10000000269=1278=9a2f3529-481e-4e50-a123-7a2095fe6b2c270=1000.00271=3.1000000010=114
20250411-02:00:27.405776000 : 8=FIXT.1.19=14135=334=2549=24ab46f784d1b20db435b852086e325052=20250411-02:00:27.40556=Coinbase45=4958=Tag appears more than once371=269372=W373=1310=249
20250411-02:00:27.405856000 : 8=FIXT.1.19=93835=W49=Coinbase56=24ab46f784d1b20db435b852086e325034=5050=TEST52=20250411-02:00:27.065171369=2262=38b76e38-5a27-4fa7-8aa2-3c519fd2251e83=1597582071893=N55=BTC-USD1682=full_trading268=10269=1278=9ed552a3-3295-4878-85dd-87b7b5590212270=1000.00271=3.10000000269=1278=54bec5c2-bafd-4d7d-851d-59e3553a053f270=1000.00271=3.10000000269=1278=543c1acf-52f2-442b-a893-f7aa9a5dfbd1270=1000.00271=3.10000000269=1278=fec999be-cbd0-42ef-b9c3-82ca92ef0b58270=1000.00271=3.10000000269=1278=24528176-3fc6-45b2-b2f3-9f784c01495a270=1000.00271=3.10000000269=1278=12081678-66a6-4435-a3d7-b65f959cf2ac270=1000.00271=3.10000000269=1278=e7fb6165-8f1a-4b5e-b095-e232b83ee951270=1000.00271=3.10000000269=1278=83ce6582-410a-40bf-9831-8f3d20e3a629270=1000.00271=3.10000000269=1278=bc3a930b-0567-46ba-86a4-712f76466b0b270=1000.00271=3.10000000269=1278=15704973-f5ff-457d-ab31-8f99bb76bf7e270=1000.00271=3.1000000010=013
20250411-02:00:27.406437000 : 8=FIXT.1.19=14135=334=2649=24ab46f784d1b20db435b852086e325052=20250411-02:00:27.40656=Coinbase45=5058=Tag appears more than once371=269372=W373=1310=243
20250411-02:00:27.406517000 : 8=FIXT.1.19=93835=W49=Coinbase56=24ab46f784d1b20db435b852086e325034=5150=TEST52=20250411-02:00:27.065421369=2262=38b76e38-5a27-4fa7-8aa2-3c519fd2251e83=1597582071893=N55=BTC-USD1682=full_trading268=10269=1278=7159045b-cbd5-458f-b91f-9fa5241b14b5270=1000.00271=3.10000000269=1278=9fa52a90-f03f-4940-b5ee-39ab937b86f1270=1000.00271=3.10000000269=1278=220f55cd-a279-4bf0-9c80-1dca086d85dc270=1000.00271=3.10000000269=1278=2b1eb468-6bcd-4117-a7c0-214d643ddad4270=1000.00271=3.10000000269=1278=cc23185d-e72e-42cb-8210-61bab29cd778270=1000.00271=3.10000000269=1278=69bb228b-973b-4176-8708-3231cc40102a270=1000.00271=3.10000000269=1278=2ec8035d-7962-4195-8388-c9fbad52ac8a270=1000.00271=3.10000000269=1278=7d39e416-0b7b-471f-a9ac-455ab1bce5a7270=1000.00271=3.10000000269=1278=7067378d-2a65-41f2-acb0-ef30ddbc3e5a270=1000.00271=3.10000000269=1278=bf3fde78-6cff-4477-b381-4b5d2e68f36f270=1000.00271=3.1000000010=063
20250411-02:00:27.407215000 : 8=FIXT.1.19=14135=334=2749=24ab46f784d1b20db435b852086e325052=20250411-02:00:27.40656=Coinbase45=5158=Tag appears more than once371=269372=W373=1310=245
20250411-02:00:27.407299000 : 8=FIXT.1.19=93835=W49=Coinbase56=24ab46f784d1b20db435b852086e325034=5250=TEST52=20250411-02:00:27.065672369=2262=38b76e38-5a27-4fa7-8aa2-3c519fd2251e83=1597582071893=N55=BTC-USD1682=full_trading268=10269=1278=93a2a8a3-61d4-410c-9446-8eabaafc5f29270=1000.00271=3.10000000269=1278=5afddb61-63ab-417b-a28a-41c4c03a6612270=1000.00271=3.10000000269=1278=a4280417-189c-4f76-9d2e-6ec652010bf5270=1000.00271=3.10000000269=1278=ddeb78a2-e110-4828-ba3d-c9b4837e7dd7270=1000.00271=3.10000000269=1278=fcec6c90-441a-4f4a-a94e-9003355657ef270=1000.00271=3.10000000269=1278=6db15389-dfb3-4156-8a4e-ce2ac80f2b15270=1000.00271=3.10000000269=1278=47dfefc3-6f05-4b57-8aec-2bf3e6c70c2d270=1000.00271=3.10000000269=1278=fb9fd019-4b4f-4880-82bb-3df6d1ef468a270=1000.00271=3.10000000269=1278=2cff9acd-42cb-43a5-8d50-51e676b7e763270=1000.00271=3.10000000269=1278=6e6eeb59-4728-4811-9a44-c857df6aca42270=1000.00271=3.1000000010=173
20250411-02:00:27.408255000 : 8=FIXT.1.19=14135=334=2849=24ab46f784d1b20db435b852086e325052=20250411-02:00:27.40756=Coinbase45=5258=Tag appears more than once371=269372=W373=1310=248
20250411-02:00:27.408384000 : 8=FIXT.1.19=93835=W49=Coinbase56=24ab46f784d1b20db435b852086e325034=5350=TEST52=20250411-02:00:27.065922369=2262=38b76e38-5a27-4fa7-8aa2-3c519fd2251e83=1597582071893=N55=BTC-USD1682=full_trading268=10269=1278=81798560-263f-4819-a528-5f3fbbc7b042270=1000.00271=3.10000000269=1278=81fbf9a8-82f4-4fe4-9fa5-3773b212ebf4270=1000.00271=3.10000000269=1278=5d3b9566-276d-47fe-a111-12c17f53f501270=1000.00271=3.10000000269=1278=8eb1b3b3-c813-48b1-b839-993672108d91270=1000.00271=3.10000000269=1278=4feb6e93-6149-481b-8d58-e1c8e6c5cda1270=1000.00271=3.10000000269=1278=f8611e72-4056-4b7c-9779-4d54cd151d44270=1000.00271=3.10000000269=1278=7a129f7c-d9ba-4ea3-a267-b7d82b2e07d9270=1000.00271=3.10000000269=1278=01f359f0-c38f-416b-af00-183907218793270=1000.00271=3.10000000269=1278=11741cec-9c08-4a20-99dc-6b9f63130b0e270=1000.00271=3.10000000269=1278=08db2574-ad52-4520-ab5b-c3c7591eb781270=1000.00271=3.1000000010=235
20250411-02:00:27.409063000 : 8=FIXT.1.19=14135=334=2949=24ab46f784d1b20db435b852086e325052=20250411-02:00:27.40856=Coinbase45=5358=Tag appears more than once371=269372=W373=1310=251
20250411-02:00:27.409144000 : 8=FIXT.1.19=93835=W49=Coinbase56=24ab46f784d1b20db435b852086e325034=5450=TEST52=20250411-02:00:27.066172369=2262=38b76e38-5a27-4fa7-8aa2-3c519fd2251e83=1597582071893=N55=BTC-USD1682=full_trading268=10269=1278=b06f2249-179c-4a15-8e98-7b76083b808b270=1000.00271=3.10000000269=1278=9e88fede-6d19-4c1f-863b-5a7d66781436270=1000.00271=3.10000000269=1278=75e1d8b4-7201-41fe-a687-7d93420af323270=1000.00271=3.10000000269=1278=d00aa7dd-ce7f-4f8b-9a2e-880c1ea30845270=1000.00271=3.10000000269=1278=584a483f-23bf-4d8b-809f-69cf3c110f60270=1000.00271=3.10000000269=1278=dc98524e-27e2-4863-99e4-7a0097a6ee90270=1000.00271=3.10000000269=1278=82a11ac9-4f46-44b7-a0bc-a5a4cfe686e0270=1000.00271=3.10000000269=1278=f946bb05-900c-41fc-9908-41489e97ff20270=1000.00271=3.10000000269=1278=1f9186d6-0312-4677-ba96-fdb014cdff2c270=1000.00271=3.10000000269=1278=c3b67be7-2b63-4884-b311-80f28496c2c4270=1000.00271=3.1000000010=007
20250411-02:00:27.409656000 : 8=FIXT.1.19=14135=334=3049=24ab46f784d1b20db435b852086e325052=20250411-02:00:27.40956=Coinbase45=5458=Tag appears more than once371=269372=W373=1310=245
20250411-02:00:27.409734000 : 8=FIXT.1.19=93835=W49=Coinbase56=24ab46f784d1b20db435b852086e325034=5550=TEST52=20250411-02:00:27.066422369=2262=38b76e38-5a27-4fa7-8aa2-3c519fd2251e83=1597582071893=N55=BTC-USD1682=full_trading268=10269=1278=6576c7f8-a4e2-4417-b854-5fef0e705fbe270=1000.00271=3.10000000269=1278=c2102c71-62f0-4eee-ae60-0777ed26a8e6270=1000.00271=3.10000000269=1278=c823a2b6-849e-4839-a2fd-cd9f459cae6c270=1000.00271=3.10000000269=1278=a051e195-4472-4a8a-8591-08a2c04a33c4270=1000.00271=3.10000000269=1278=ec81b8c4-b703-4afd-a701-ce34011f60f6270=1000.00271=3.10000000269=1278=b1172677-f493-4f32-a200-0710cf8c397f270=1000.00271=3.10000000269=1278=b1a58a75-5fca-43db-b9c6-a26920e8f66e270=1000.00271=3.10000000269=1278=038bea41-b91d-4884-b992-3e5431ef9857270=1000.00271=3.10000000269=1278=55063782-f2ea-4c84-9491-8e8e89d1dfd1270=1000.00271=3.10000000269=1278=bb2011e8-d05d-40ac-9e9c-3b720422e38d270=1000.00271=3.1000000010=179
20250411-02:00:27.410243000 : 8=FIXT.1.19=14135=334=3149=24ab46f784d1b20db435b852086e325052=20250411-02:00:27.40956=Coinbase45=5558=Tag appears more than once371=269372=W373=1310=247
20250411-02:00:27.410323000 : 8=FIXT.1.19=93835=W49=Coinbase56=24ab46f784d1b20db435b852086e325034=5650=TEST52=20250411-02:00:27.066672369=2262=38b76e38-5a27-4fa7-8aa2-3c519fd2251e83=1597582071893=N55=BTC-USD1682=full_trading268=10269=1278=64dd3b4a-ce8a-4b63-9937-266e832c0f21270=1000.00271=3.10000000269=1278=d64f7d2a-aa83-486c-92a8-3314c4eddd58270=1000.00271=3.10000000269=1278=0df9641b-d89d-4222-a8ea-bcddf0d555f5270=1000.00271=3.10000000269=1278=7a315b16-a05f-408d-b8c1-2704af9bf767270=1000.00271=3.10000000269=1278=0e9712a8-d00f-4864-a478-f7f591718f91270=1000.00271=3.10000000269=1278=94db025d-eada-49e3-b13c-b667ca07f829270=1000.00271=3.10000000269=1278=a88ccd1f-8f8d-46af-8fb6-20adba35f7d1270=1000.00271=3.10000000269=1278=99d4e235-c8ec-4efc-938c-9a1923eafc96270=1000.00271=3.10000000269=1278=a4fc7173-7583-4f8b-b256-2921bef83c84270=1000.00271=3.10000000269=1278=18f8afd4-8bbc-4ffa-8e8f-0c1834d74472270=1000.00271=3.1000000010=207
20250411-02:00:27.410887000 : 8=FIXT.1.19=14135=334=3249=24ab46f784d1b20db435b852086e325052=20250411-02:00:27.41056=Coinbase45=5658=Tag appears more than once371=269372=W373=1310=241
20250411-02:00:27.411132000 : 8=FIXT.1.19=93835=W49=Coinbase56=24ab46f784d1b20db435b852086e325034=5750=TEST52=20250411-02:00:27.066922369=2262=38b76e38-5a27-4fa7-8aa2-3c519fd2251e83=1597582071893=N55=BTC-USD1682=full_trading268=10269=1278=21fc8cb6-f894-4d09-884e-810b8ebf2ef3270=1000.00271=3.10000000269=1278=0c13b9e6-6797-4b3e-90ce-a1885b26ba53270=1000.00271=3.10000000269=1278=6d8da581-3998-4fc0-99b6-3c5edbd514cb270=1000.00271=3.10000000269=1278=67a70307-be50-4065-872b-47e0de473bc4270=1000.00271=3.10000000269=1278=8ce7be0b-98de-46d0-b1b6-307a4bec36e2270=1000.00271=3.10000000269=1278=856b22f8-5884-4739-adc0-bdd851c5c07d270=1000.00271=3.10000000269=1278=c00ae651-a76b-4bfd-be16-3672b345fe29270=1000.00271=3.10000000269=1278=cae248f9-16fc-44ea-9b79-1dacfc285db6270=1000.00271=3.10000000269=1278=42bb223c-88c6-4a18-8ff3-4fd8d9efda8d270=1000.00271=3.10000000269=1278=d7188b01-22b6-4837-a720-077601f7f483270=1000.00271=3.1000000010=194
20250411-02:00:27.412003000 : 8=FIXT.1.19=14135=334=3349=24ab46f784d1b20db435b852086e325052=20250411-02:00:27.41156=Coinbase45=5758=Tag appears more than once371=269372=W373=1310=244
20250411-02:00:27.412118000 : 8=FIXT.1.19=93835=W49=Coinbase56=24ab46f784d1b20db435b852086e325034=5850=TEST52=20250411-02:00:27.067172369=2262=38b76e38-5a27-4fa7-8aa2-3c519fd2251e83=1597582071893=N55=BTC-USD1682=full_trading268=10269=1278=5d85a0a6-ddd9-4e0e-9a1a-7f418ef588e5270=1000.00271=3.10000000269=1278=bff4c39f-7a80-42ce-a178-b1221792e445270=1000.00271=3.10000000269=1278=9ea3d263-b5ab-46c5-bf27-8c0e3e0e5e9e270=1000.00271=3.10000000269=1278=b93347df-d2ab-48ec-b326-4454e64f1d4e270=1000.00271=3.10000000269=1278=57acc40d-8478-444a-990f-067a8e8e846e270=1000.00271=3.10000000269=1278=34419ae2-2c16-427b-a290-845419760fd5270=1000.00271=3.10000000269=1278=ab41de2d-5def-4986-b56e-243d2f99a57c270=1000.00271=3.10000000269=1278=9025524c-03a9-407a-a58a-5258c4ea0a0b270=1000.00271=3.10000000269=1278=60766318-112b-4d83-a384-55693de75519270=1000.00271=3.10000000269=1278=c19b6a2c-086b-4fc1-8dfe-51cb2dc12c1d270=1000.00271=3.1000000010=081
20250411-02:00:27.413028000 : 8=FIXT.1.19=14135=334=3449=24ab46f784d1b20db435b852086e325052=20250411-02:00:27.41256=Coinbase45=5858=Tag appears more than once371=269372=W373=1310=247
20250411-02:00:27.413117000 : 8=FIXT.1.19=93835=W49=Coinbase56=24ab46f784d1b20db435b852086e325034=5950=TEST52=20250411-02:00:27.067422369=2262=38b76e38-5a27-4fa7-8aa2-3c519fd2251e83=1597582071893=N55=BTC-USD1682=full_trading268=10269=1278=11126433-0f9c-4450-a35a-39b878e85e68270=1000.00271=3.10000000269=1278=e2e620ee-44fb-4630-a890-d331ba5b2fae270=1000.00271=3.10000000269=1278=9ccf6d4b-a6ca-4a1f-a7bb-77f400ace0c8270=1000.00271=3.10000000269=1278=0e8d6c10-8421-4f19-97dc-d70e715d9033270=1000.00271=3.10000000269=1278=f31ecd5d-8231-44ea-a5c2-0fcc5a699401270=1000.00271=3.10000000269=1278=37fbb559-dc52-48fe-ab65-24910edc338a270=1000.00271=3.10000000269=1278=bc1435c5-c59c-4017-9e59-f1073f04c7e2270=1000.00271=3.10000000269=1278=9c8e1397-0cee-4b05-a66f-5594040791c4270=1000.00271=3.10000000269=1278=248b6703-f829-42bb-a551-4be3075c381e270=1000.00271=3.10000000269=1278=16d257b0-bc92-44f0-822d-3eba61af4bda270=1000.00271=3.1000000010=057
20250411-02:00:27.415718000 : 8=FIXT.1.19=14135=334=3549=24ab46f784d1b20db435b852086e325052=20250411-02:00:27.41456=Coinbase45=5958=Tag appears more than once371=269372=W373=1310=251
20250411-02:00:27.415887000 : 8=FIXT.1.19=93835=W49=Coinbase56=24ab46f784d1b20db435b852086e325034=6050=TEST52=20250411-02:00:27.067672369=2262=38b76e38-5a27-4fa7-8aa2-3c519fd2251e83=1597582071893=N55=BTC-USD1682=full_trading268=10269=1278=06257aa1-4043-4cdb-9286-4342b8e59108270=1000.00271=3.10000000269=1278=210ec210-1443-47dc-9e43-9c9ea720a6c3270=1000.00271=3.10000000269=1278=8b79da5d-b78c-4011-b55f-b35c16dc3724270=1000.00271=3.10000000269=1278=076c3703-1104-4e15-a38a-d95bf133f0c5270=1000.00271=3.10000000269=1278=f5a3155c-e449-4102-870d-ab8c8dd24c3d270=1000.00271=3.10000000269=1278=1af2681f-2dec-4d25-aaeb-89b8867b4a3c270=1000.00271=3.10000000269=1278=65c3088d-192a-4213-85a3-7257aa8b20a3270=1000.00271=3.10000000269=1278=2aa7989b-5601-4899-8143-01dda3255e4f270=1000.00271=3.10000000269=1278=099b432c-fa2e-4fd7-952e-22f6debf6877270=1000.00271=3.10000000269=1278=2e71cc31-1235-4b7b-a728-e3335631fe5a270=1000.00271=3.1000000010=242
20250411-02:00:27.417395000 : 8=FIXT.1.19=14135=334=3649=24ab46f784d1b20db435b852086e325052=20250411-02:00:27.41656=Coinbase45=6058=Tag appears more than once371=269372=W373=1310=246
20250411-02:00:27.417497000 : 8=FIXT.1.19=93835=W49=Coinbase56=24ab46f784d1b20db435b852086e325034=6150=TEST52=20250411-02:00:27.067922369=2262=38b76e38-5a27-4fa7-8aa2-3c519fd2251e83=1597582071893=N55=BTC-USD1682=full_trading268=10269=1278=ce471ffc-1e26-4afe-afab-27ee5ac8debe270=1000.00271=3.10000000269=1278=113b7fc6-8574-40eb-8682-d077245b84f2270=1000.00271=3.10000000269=1278=bcebce2c-eda8-4b85-841d-27ede39fc5a1270=1000.00271=3.10000000269=1278=0aedaae5-6cc6-4a34-8e48-5e67a5ccc148270=1000.00271=3.10000000269=1278=206e10a5-1173-4860-87b5-7c88afe061f6270=1000.00271=3.10000000269=1278=5c32d94b-696a-4d9b-afa0-665970356008270=1000.00271=3.10000000269=1278=0b7da819-cc1e-4525-a382-ce5b90dc485c270=1000.00271=3.10000000269=1278=2241b3bf-cbbe-44f2-ac75-8032f6283aa8270=1000.00271=3.10000000269=1278=88cada69-adb1-466a-afcd-66e063ad27c0270=1000.00271=3.10000000269=1278=34a52ef5-31c1-4c63-9230-21c85a9a6ba3270=1000.00271=3.1000000010=018
20250411-02:00:27.418063000 : 8=FIXT.1.19=14135=334=3749=24ab46f784d1b20db435b852086e325052=20250411-02:00:27.41756=Coinbase45=6158=Tag appears more than once371=269372=W373=1310=249
20250411-02:00:27.418151000 : 8=FIXT.1.19=93835=W49=Coinbase56=24ab46f784d1b20db435b852086e325034=6250=TEST52=20250411-02:00:27.068172369=2262=38b76e38-5a27-4fa7-8aa2-3c519fd2251e83=1597582071893=N55=BTC-USD1682=full_trading268=10269=1278=e109c2c8-fb1d-4ef9-a640-368381323507270=1000.00271=3.10000000269=1278=38fd36c4-4c62-4b4c-8f24-1fe39be94fa1270=1000.00271=3.10000000269=1278=f83f64c8-7d33-472d-a516-9b664ff9c966270=1000.00271=3.10000000269=1278=3411c368-380b-42e6-b656-8552d92904d5270=1000.00271=3.10000000269=1278=4803796e-79f3-4aa4-a8cb-37f13899bf01270=1000.00271=3.10000000269=1278=823f8fbf-7e6d-4ae3-adb9-3a822ff6d09a270=1000.00271=3.10000000269=1278=135624df-a204-490f-a68b-63d74ee09908270=1000.00271=3.10000000269=1278=47cfdedf-22b9-402c-93bd-f311103fd3e0270=1000.00271=3.10000000269=1278=f9173d5e-d872-4661-93f6-28f527e931f7270=1000.00271=3.10000000269=1278=06ab1365-fd39-4701-bd7f-1915ad3c7602270=1000.00271=3.1000000010=167
20250411-02:00:27.418894000 : 8=FIXT.1.19=14135=334=3849=24ab46f784d1b20db435b852086e325052=20250411-02:00:27.41856=Coinbase45=6258=Tag appears more than once371=269372=W373=1310=252
20250411-02:00:27.419009000 : 8=FIXT.1.19=93835=W49=Coinbase56=24ab46f784d1b20db435b852086e325034=6350=TEST52=20250411-02:00:27.068422369=2262=38b76e38-5a27-4fa7-8aa2-3c519fd2251e83=1597582071893=N55=BTC-USD1682=full_trading268=10269=1278=012a7c59-5ae4-4da5-97ba-2e3254c889fb270=1000.00271=3.10000000269=1278=a9a0d42f-ad9e-4ea9-8bf0-d5a441fded40270=1000.00271=3.10000000269=1278=f3f3930e-be0e-40b4-a97d-d19501a54885270=1000.00271=3.10000000269=1278=261922d0-5c81-4ab6-832f-4eff45f64890270=1000.00271=3.10000000269=1278=3af4e45f-56f6-4c69-894d-d56a14894a98270=1000.00271=3.10000000269=1278=1c1dd248-49e4-44aa-9e69-323b0f41fa0e270=1000.00271=3.10000000269=1278=b16b002d-1cd6-4869-9c1b-f15c758611bf270=1000.00271=3.10000000269=1278=a0520e61-28ad-448d-87c1-49f0c7358628270=1000.00271=3.10000000269=1278=152d0b57-086f-48cc-80b3-ff14ee9375ed270=1000.00271=3.10000000269=1278=c55fc264-67d2-4e9c-8cce-6c834feff648270=1000.00271=3.1000000010=165
20250411-02:00:27.419701000 : 8=FIXT.1.19=14135=334=3949=24ab46f784d1b20db435b852086e325052=20250411-02:00:27.41956=Coinbase45=6358=Tag appears more than once371=269372=W373=1310=255
20250411-02:00:27.419781000 : 8=FIXT.1.19=93835=W49=Coinbase56=24ab46f784d1b20db435b852086e325034=6450=TEST52=20250411-02:00:27.068672369=2262=38b76e38-5a27-4fa7-8aa2-3c519fd2251e83=1597582071893=N55=BTC-USD1682=full_trading268=10269=1278=27361968-189a-4fa6-a3a2-eead03c640d6270=1000.00271=3.10000000269=1278=f5b01c67-f98f-44b9-a511-7f07f8883d9e270=1000.00271=3.10000000269=1278=75a5c14f-8434-4533-a10e-0bf6e92e1000270=1000.00271=3.10000000269=1278=a9b0a826-3659-4105-9ecc-21bcd27b736f270=1000.00271=3.10000000269=1278=1b1bab77-5c52-459b-98e3-e27ff6f8cd04270=1000.00271=3.10000000269=1278=346695f1-fe03-4364-8fc5-006796c8f82f270=1000.00271=3.10000000269=1278=cbbaa36d-2a03-45a2-a230-bd5845d832cd270=1000.00271=3.10000000269=1278=745d4fc0-6710-4c5c-97c3-7b29c4e06839270=1000.00271=3.10000000269=1278=e95fdfba-5db2-4461-8e9c-7bfdf8a9238c270=1000.00271=3.10000000269=1278=33611b39-1fbf-45cc-bf5e-a02bc1f84736270=1000.00271=3.1000000010=085
20250411-02:00:27.420332000 : 8=FIXT.1.19=14135=334=4049=24ab46f784d1b20db435b852086e325052=20250411-02:00:27.42056=Coinbase45=6458=Tag appears more than once371=269372=W373=1310=240
20250411-02:00:27.420416000 : 8=FIXT.1.19=93835=W49=Coinbase56=24ab46f784d1b20db435b852086e325034=6550=TEST52=20250411-02:00:27.068922369=2262=38b76e38-5a27-4fa7-8aa2-3c519fd2251e83=1597582071893=N55=BTC-USD1682=full_trading268=10269=1278=51f77b2d-1a69-432d-934b-234eb9e1dfac270=1000.00271=3.10000000269=1278=ab09fdc3-8d50-432f-ab0f-97e8627eac24270=1000.00271=3.10000000269=1278=dde04213-6104-44c5-a811-15834c27b515270=1000.00271=3.10000000269=1278=9af2b85c-4997-4e1b-9147-7d400f059b01270=1000.00271=3.10000000269=1278=40870860-7a8a-4419-a117-e511f779abfa270=1000.00271=3.10000000269=1278=3e8fa7bd-dde0-4fe4-bb2e-e6279841b019270=1000.00271=3.10000000269=1278=4dde1422-98d8-405b-88df-bf245291ad7a270=1000.00271=3.10000000269=1278=6ee8b5a8-bc2f-4a0a-9ae4-7ff1b5dae941270=1000.00271=3.10000000269=1278=3ebc1f7a-2bb5-4ef0-a82f-844b9540f6e8270=1000.00271=3.10000000269=1278=a82d5bb9-1f1a-4575-b580-8d9b60863b10270=1000.00271=3.1000000010=030
20250411-02:00:27.420953000 : 8=FIXT.1.19=14135=334=4149=24ab46f784d1b20db435b852086e325052=20250411-02:00:27.42056=Coinbase45=6558=Tag appears more than once371=269372=W373=1310=242
20250411-02:00:27.421035000 : 8=FIXT.1.19=93835=W49=Coinbase56=24ab46f784d1b20db435b852086e325034=6650=TEST52=20250411-02:00:27.069172369=2262=38b76e38-5a27-4fa7-8aa2-3c519fd2251e83=1597582071893=N55=BTC-USD1682=full_trading268=10269=1278=14f89bd5-0233-435c-b608-2e19131b8f6c270=1000.00271=3.10000000269=1278=a2e319e5-aab7-41d4-9d19-98d771a3f1d3270=1000.00271=3.10000000269=1278=dc965e0b-075a-4ba4-a498-02c96d1664ba270=1000.00271=3.10000000269=1278=67b6e68f-ac11-4c05-a54a-2adb555b0123270=1000.00271=3.10000000269=1278=866f52a1-dad9-49d7-ac4a-9da3075407a3270=1000.00271=3.10000000269=1278=0e38234d-a010-40f6-9c6f-a0d574e773cf270=1000.00271=3.10000000269=1278=d6af6749-e3c8-4938-8741-1d5f177cf8e1270=1000.00271=3.10000000269=1278=45ff5e59-2c4d-45ac-9fde-403662dfd1ca270=1000.00271=3.10000000269=1278=dcac314e-c54f-44e3-b96d-ef71539766ed270=1000.00271=3.10000000269=1278=dd6d14ea-760f-4884-a546-1d3c40ebdd7c270=1000.00271=3.1000000010=100
20250411-02:00:27.421577000 : 8=FIXT.1.19=14135=334=4249=24ab46f784d1b20db435b852086e325052=20250411-02:00:27.42156=Coinbase45=6658=Tag appears more than once371=269372=W373=1310=245
20250411-02:00:27.421729000 : 8=FIXT.1.19=94835=W49=Coinbase56=24ab46f784d1b20db435b852086e325034=6750=TEST52=20250411-02:00:27.069422369=2262=38b76e38-5a27-4fa7-8aa2-3c519fd2251e83=1597582071893=N55=BTC-USD1682=full_trading268=10269=1278=4f3da0c6-46eb-4b64-b973-cc43e24abccb270=1000.00271=3.10000000269=1278=aa40cda8-4abd-4f52-999a-1a90ed5bf41a270=1000.00271=3.10000000269=1278=687ee4fc-f626-4e4f-abee-1f0ee5af3f72270=1000.00271=3.10000000269=1278=b1ad1135-67ec-4c96-99cb-a626137f3f16270=10000.00271=1.00000000269=1278=e9320f5f-80ae-41ab-af7a-86518d456fb0270=10000.00271=1.00000000269=1278=cd95aff0-36fa-4804-887f-2c3fce3cdc86270=10000.00271=1.00000000269=1278=fbdbcee1-8c29-4478-97df-358d209d8808270=10000.00271=1.00000000269=1278=140f39da-834b-4e42-8e15-6e25287df1f0270=900000.00271=0.00011111269=1278=49f064c5-76fe-4b38-bede-48b60a0a5aec270=900000.00271=0.00011111269=1278=681cf73b-9d37-4101-b940-9da9b1ff61ed270=900000.00271=0.0001111110=109
20250411-02:00:27.422276000 : 8=FIXT.1.19=14135=334=4349=24ab46f784d1b20db435b852086e325052=20250411-02:00:27.42156=Coinbase45=6758=Tag appears more than once371=269372=W373=1310=247
20250411-02:00:27.422356000 : 8=FIXT.1.19=95835=W49=Coinbase56=24ab46f784d1b20db435b852086e325034=6850=TEST52=20250411-02:00:27.069672369=2262=38b76e38-5a27-4fa7-8aa2-3c519fd2251e83=1597582071893=N55=BTC-USD1682=full_trading268=10269=1278=3dea1587-e474-4258-b6e8-485c21b56670270=900000.00271=0.00011111269=1278=afd96a7b-3d48-459e-b810-e4ee88353a31270=900000.00271=0.00011111269=1278=a68ae029-b920-4ae7-a775-ccdb800fc252270=900000.00271=0.00001111269=1278=d44508b7-1c9f-4b4f-acb8-99c93d2b99e8270=900000.00271=0.00001111269=1278=304ff106-de40-4381-89c5-c93f7f3e32ae270=900000.00271=0.00001111269=1278=08a0fef8-fcbb-4857-8463-2599cf331386270=900000.00271=0.00011111269=1278=07b2856d-f899-417c-82d5-886f0d85125e270=900000.00271=0.00011111269=1278=12ecb45e-6af8-4804-a942-5c997b9d1502270=900000.00271=0.00011111269=1278=98676c5f-b851-473c-817a-b29243092a25270=900000.00271=0.00001111269=1278=09afe685-e71f-4ea0-b164-c27737db126d270=900000.00271=0.0000111110=181
20250411-02:00:27.422878000 : 8=FIXT.1.19=14135=334=4449=24ab46f784d1b20db435b852086e325052=20250411-02:00:27.42256=Coinbase45=6858=Tag appears more than once371=269372=W373=1310=250
20250411-02:00:27.422967000 : 8=FIXT.1.19=65735=W49=Coinbase56=24ab46f784d1b20db435b852086e325034=6950=TEST52=20250411-02:00:27.069922369=2262=38b76e38-5a27-4fa7-8aa2-3c519fd2251e83=1597582071893=Y55=BTC-USD1682=full_trading268=6269=1278=e71ee98f-c329-428d-9893-629b53015ff6270=900000.00271=0.00001111269=1278=124e6fc1-6dde-452b-be03-c00113c8ebdb270=900000.00271=0.00011111269=1278=b71cc7f5-d7c6-4fc0-a0de-59b0eb7fd063270=1000000.00271=1.00000000269=1278=afec127b-a98c-49cb-893f-e385a7e35d32270=1000000.00271=1.00000000269=1278=06df7c57-366d-4d2c-acc2-e6c26d60e9c3270=1000000.00271=1.00000000269=1278=b1c4eb2b-90df-44e0-ae4f-515df4086a9d270=9999999.00271=0.0000100010=085
20250411-02:00:27.423435000 : 8=FIXT.1.19=14135=334=4549=24ab46f784d1b20db435b852086e325052=20250411-02:00:27.42356=Coinbase45=6958=Tag appears more than once371=269372=W373=1310=253
20250411-02:00:27.423511000 : 8=FIXT.1.19=28935=X49=Coinbase56=24ab46f784d1b20db435b852086e325034=7050=TEST52=20250411-02:00:27.164611369=2262=38b76e38-5a27-4fa7-8aa2-3c519fd2251e268=1279=2269=1278=98b269f7-e916-4d1c-936f-585d9d9b2a3883=159758207255=BTC-USD270=3.7271=0.6232294660=20250411-02:00:27.16331158=CANCELED10=191
20250411-02:00:27.567351000 : 8=FIXT.1.19=29135=X49=Coinbase56=24ab46f784d1b20db435b852086e325034=7150=TEST52=20250411-02:00:27.450749369=20262=38b76e38-5a27-4fa7-8aa2-3c519fd2251e268=1279=2269=0278=b9eb1261-8bf8-4e3c-af53-33aa2b72067b83=159758207355=BTC-USD270=3.38271=0.6232294660=20250411-02:00:27.44916158=CANCELED10=145
20250411-02:00:27.615035000 : 8=FIXT.1.19=28335=X49=Coinbase56=24ab46f784d1b20db435b852086e325034=7250=TEST52=20250411-02:00:27.497450369=20262=38b76e38-5a27-4fa7-8aa2-3c519fd2251e268=1279=0269=183=159758207455=BTC-USD270=3.28271=0.6232294660=20250411-02:00:27.49580440=237=c2f83b59-7e8a-47bc-ba70-15490d6fc2d510=106
20250411-02:00:27.615834000 : 8=FIXT.1.19=32635=X49=Coinbase56=24ab46f784d1b20db435b852086e325034=7350=TEST52=20250411-02:00:27.497458369=20262=38b76e38-5a27-4fa7-8aa2-3c519fd2251e268=1279=0269=2278=4d60a78e-b39b-420e-b830-bc0f3f4fdde283=159758207555=BTC-USD270=3.53271=0.6232294660=20250411-02:00:27.49580437=c2f83b59-7e8a-47bc-ba70-15490d6fc2d55797=210=196
20250411-02:00:27.623265000 : 8=FIXT.1.19=28935=X49=Coinbase56=24ab46f784d1b20db435b852086e325034=7450=TEST52=20250411-02:00:27.497462369=20262=38b76e38-5a27-4fa7-8aa2-3c519fd2251e268=1279=2269=1278=c2f83b59-7e8a-47bc-ba70-15490d6fc2d583=159758207655=BTC-USD270=3.28271=0.0000000060=20250411-02:00:27.49580458=FILLED10=021
20250411-02:00:27.668302000 : 8=FIXT.1.19=28335=X49=Coinbase56=24ab46f784d1b20db435b852086e325034=7550=TEST52=20250411-02:00:27.551780369=45262=38b76e38-5a27-4fa7-8aa2-3c519fd2251e268=1279=0269=083=159758207755=BTC-USD270=3.82271=0.6232294660=20250411-02:00:27.55054540=237=04e1010c-c7c9-4e41-b4c2-a161bc41413a10=224
20250411-02:00:27.669361000 : 8=FIXT.1.19=32635=X49=Coinbase56=24ab46f784d1b20db435b852086e325034=7650=TEST52=20250411-02:00:27.551799369=45262=38b76e38-5a27-4fa7-8aa2-3c519fd2251e268=1279=0269=2278=c5b88ea9-605d-4595-ac52-f7c3f08523ba83=159758207855=BTC-USD270=3.55271=0.6232294660=20250411-02:00:27.55054537=04e1010c-c7c9-4e41-b4c2-a161bc41413a5797=110=190
20250411-02:00:27.669969000 : 8=FIXT.1.19=28935=X49=Coinbase56=24ab46f784d1b20db435b852086e325034=7750=TEST52=20250411-02:00:27.551803369=45262=38b76e38-5a27-4fa7-8aa2-3c519fd2251e268=1279=2269=0278=04e1010c-c7c9-4e41-b4c2-a161bc41413a83=159758207955=BTC-USD270=3.82271=0.0000000060=20250411-02:00:27.55054558=FILLED10=132
20250411-02:00:27.851248000 : 8=FIXT.1.19=29135=X49=Coinbase56=24ab46f784d1b20db435b852086e325034=7850=TEST52=20250411-02:00:27.735544369=45262=38b76e38-5a27-4fa7-8aa2-3c519fd2251e268=1279=2269=0278=b7a2004c-41b5-42c2-80e8-60bb80b63a1183=159758208055=BTC-USD270=3.36271=0.6232294660=20250411-02:00:27.73433358=CANCELED10=241
20250411-02:00:28.460829000 : 8=FIXT.1.19=28235=X49=Coinbase56=24ab46f784d1b20db435b852086e325034=7950=TEST52=20250411-02:00:28.344523369=45262=38b76e38-5a27-4fa7-8aa2-3c519fd2251e268=1279=0269=183=159758208155=BTC-USD270=3.2271=0.6197183160=20250411-02:00:28.34276440=237=ab8cffef-401e-41dd-b4b4-6604cf8b28b810=190
20250411-02:00:28.461839000 : 8=FIXT.1.19=32635=X49=Coinbase56=24ab46f784d1b20db435b852086e325034=8050=TEST52=20250411-02:00:28.344529369=45262=38b76e38-5a27-4fa7-8aa2-3c519fd2251e268=1279=0269=2278=4d60a78e-b39b-420e-b830-bc0f3f4fdde283=159758208255=BTC-USD270=3.53271=0.6197183160=20250411-02:00:28.34276437=ab8cffef-401e-41dd-b4b4-6604cf8b28b85797=210=070
20250411-02:00:28.463685000 : 8=FIXT.1.19=28835=X49=Coinbase56=24ab46f784d1b20db435b852086e325034=8150=TEST52=20250411-02:00:28.344533369=45262=38b76e38-5a27-4fa7-8aa2-3c519fd2251e268=1279=2269=1278=ab8cffef-401e-41dd-b4b4-6604cf8b28b883=159758208355=BTC-USD270=3.2271=0.0000000060=20250411-02:00:28.34276458=FILLED10=092
20250411-02:00:28.527705000 : 8=FIXT.1.19=28335=X49=Coinbase56=24ab46f784d1b20db435b852086e325034=8250=TEST52=20250411-02:00:28.411383369=45262=38b76e38-5a27-4fa7-8aa2-3c519fd2251e268=1279=0269=183=159758208455=BTC-USD270=3.34271=0.6232294660=20250411-02:00:28.40968940=237=326352eb-0077-4927-a499-e9f8e3d4bc1f10=232
20250411-02:00:28.528276000 : 8=FIXT.1.19=32635=X49=Coinbase56=24ab46f784d1b20db435b852086e325034=8350=TEST52=20250411-02:00:28.411392369=45262=38b76e38-5a27-4fa7-8aa2-3c519fd2251e268=1279=0269=2278=4d60a78e-b39b-420e-b830-bc0f3f4fdde283=159758208555=BTC-USD270=3.53271=0.6232294660=20250411-02:00:28.40968937=326352eb-0077-4927-a499-e9f8e3d4bc1f5797=210=061
20250411-02:00:28.529740000 : 8=FIXT.1.19=28935=X49=Coinbase56=24ab46f784d1b20db435b852086e325034=8450=TEST52=20250411-02:00:28.411396369=45262=38b76e38-5a27-4fa7-8aa2-3c519fd2251e268=1279=2269=1278=326352eb-0077-4927-a499-e9f8e3d4bc1f83=159758208655=BTC-USD270=3.34271=0.0000000060=20250411-02:00:28.40968958=FILLED10=148
20250411-02:00:28.530040000 : 8=FIXT.1.19=28335=X49=Coinbase56=24ab46f784d1b20db435b852086e325034=8550=TEST52=20250411-02:00:28.411447369=45262=38b76e38-5a27-4fa7-8aa2-3c519fd2251e268=1279=0269=183=159758208755=BTC-USD270=3.25271=0.6232294660=20250411-02:00:28.40968940=237=2be13580-a6d0-4890-8b12-84619617da4410=078
20250411-02:00:28.530324000 : 8=FIXT.1.19=32635=X49=Coinbase56=24ab46f784d1b20db435b852086e325034=8650=TEST52=20250411-02:00:28.411452369=45262=38b76e38-5a27-4fa7-8aa2-3c519fd2251e268=1279=0269=2278=4d60a78e-b39b-420e-b830-bc0f3f4fdde283=159758208855=BTC-USD270=3.53271=0.6232294660=20250411-02:00:28.40968937=2be13580-a6d0-4890-8b12-84619617da445797=210=159
20250411-02:00:28.530877000 : 8=FIXT.1.19=28935=X49=Coinbase56=24ab46f784d1b20db435b852086e325034=8750=TEST52=20250411-02:00:28.411456369=45262=38b76e38-5a27-4fa7-8aa2-3c519fd2251e268=1279=2269=1278=2be13580-a6d0-4890-8b12-84619617da4483=159758208955=BTC-USD270=3.25271=0.0000000060=20250411-02:00:28.40968958=FILLED10=246
20250411-02:00:28.640816000 : 8=FIXT.1.19=28335=X49=Coinbase56=24ab46f784d1b20db435b852086e325034=8850=TEST52=20250411-02:00:28.525321369=45262=38b76e38-5a27-4fa7-8aa2-3c519fd2251e268=1279=0269=083=159758209055=BTC-USD270=3.74271=0.6232294660=20250411-02:00:28.52332640=237=51ba1427-7a4a-4e1b-9056-df2f3d2f53dc10=082
20250411-02:00:28.641293000 : 8=FIXT.1.19=32635=X49=Coinbase56=24ab46f784d1b20db435b852086e325034=8950=TEST52=20250411-02:00:28.525328369=45262=38b76e38-5a27-4fa7-8aa2-3c519fd2251e268=1279=0269=2278=c5b88ea9-605d-4595-ac52-f7c3f08523ba83=159758209155=BTC-USD270=3.55271=0.6232294660=20250411-02:00:28.52332637=51ba1427-7a4a-4e1b-9056-df2f3d2f53dc5797=110=044
20250411-02:00:28.641458000 : 8=FIXT.1.19=28935=X49=Coinbase56=24ab46f784d1b20db435b852086e325034=9050=TEST52=20250411-02:00:28.525333369=45262=38b76e38-5a27-4fa7-8aa2-3c519fd2251e268=1279=2269=0278=51ba1427-7a4a-4e1b-9056-df2f3d2f53dc83=159758209255=BTC-USD270=3.74271=0.0000000060=20250411-02:00:28.52332658=FILLED10=244
20250411-02:00:28.641646000 : 8=FIXT.1.19=28335=X49=Coinbase56=24ab46f784d1b20db435b852086e325034=9150=TEST52=20250411-02:00:28.525337369=45262=38b76e38-5a27-4fa7-8aa2-3c519fd2251e268=1279=0269=083=159758209355=BTC-USD270=3.87271=0.6232294660=20250411-02:00:28.52332640=237=c41fb26a-e1ac-41b8-b3c0-a0d0a9e4880c10=171
20250411-02:00:28.641913000 : 8=FIXT.1.19=32635=X49=Coinbase56=24ab46f784d1b20db435b852086e325034=9250=TEST52=20250411-02:00:28.525341369=45262=38b76e38-5a27-4fa7-8aa2-3c519fd2251e268=1279=0269=2278=c5b88ea9-605d-4595-ac52-f7c3f08523ba83=159758209455=BTC-USD270=3.55271=0.6232294660=20250411-02:00:28.52332637=c41fb26a-e1ac-41b8-b3c0-a0d0a9e4880c5797=110=117
20250411-02:00:28.642805000 : 8=FIXT.1.19=28935=X49=Coinbase56=24ab46f784d1b20db435b852086e325034=9350=TEST52=20250411-02:00:28.525345369=45262=38b76e38-5a27-4fa7-8aa2-3c519fd2251e268=1279=2269=0278=c41fb26a-e1ac-41b8-b3c0-a0d0a9e4880c83=159758209555=BTC-USD270=3.87271=0.0000000060=20250411-02:00:28.52332658=FILLED10=082
20250411-02:00:28.708972000 : 8=FIXT.1.19=29135=X49=Coinbase56=24ab46f784d1b20db435b852086e325034=9450=TEST52=20250411-02:00:28.593215369=45262=38b76e38-5a27-4fa7-8aa2-3c519fd2251e268=1279=2269=0278=be5191de-eb81-4170-aece-43cb79ec15b883=159758209655=BTC-USD270=3.42271=0.6232294660=20250411-02:00:28.59134858=CANCELED10=008
20250411-02:00:29.042912000 : 8=FIXT.1.19=29135=X49=Coinbase56=24ab46f784d1b20db435b852086e325034=9550=TEST52=20250411-02:00:28.878917369=45262=38b76e38-5a27-4fa7-8aa2-3c519fd2251e268=1279=2269=1278=792fa54a-2068-4c20-ba3f-6579c5d1b04283=159758209755=BTC-USD270=3.57271=0.6218487360=20250411-02:00:28.87708458=CANCELED10=051
20250411-02:00:29.335387000 : 8=FIXT.1.19=28335=X49=Coinbase56=24ab46f784d1b20db435b852086e325034=9650=TEST52=20250411-02:00:29.210283369=45262=38b76e38-5a27-4fa7-8aa2-3c519fd2251e268=1279=0269=183=159758209855=BTC-USD270=3.26271=0.6197183160=20250411-02:00:29.20858340=237=f3d1223e-3e35-40f0-bce4-74fce8ba643610=099
20250411-02:00:29.336481000 : 8=FIXT.1.19=32635=X49=Coinbase56=24ab46f784d1b20db435b852086e325034=9750=TEST52=20250411-02:00:29.210336369=45262=38b76e38-5a27-4fa7-8aa2-3c519fd2251e268=1279=0269=2278=4d60a78e-b39b-420e-b830-bc0f3f4fdde283=159758209955=BTC-USD270=3.53271=0.6197183160=20250411-02:00:29.20858337=f3d1223e-3e35-40f0-bce4-74fce8ba64365797=210=182
20250411-02:00:29.337970000 : 8=FIXT.1.19=28935=X49=Coinbase56=24ab46f784d1b20db435b852086e325034=9850=TEST52=20250411-02:00:29.210354369=45262=38b76e38-5a27-4fa7-8aa2-3c519fd2251e268=1279=2269=1278=f3d1223e-3e35-40f0-bce4-74fce8ba643683=159758210055=BTC-USD270=3.26271=0.0000000060=20250411-02:00:29.20858358=FILLED10=246
20250411-02:00:29.388461000 : 8=FIXT.1.19=28335=X49=Coinbase56=24ab46f784d1b20db435b852086e325034=9950=TEST52=20250411-02:00:29.265287369=45262=38b76e38-5a27-4fa7-8aa2-3c519fd2251e268=1279=0269=083=159758210155=BTC-USD270=3.84271=0.6197183160=20250411-02:00:29.26402940=237=2b7f4d30-692b-477d-b3bc-c840f48094d610=019
20250411-02:00:29.389045000 : 8=FIXT.1.19=32735=X49=Coinbase56=24ab46f784d1b20db435b852086e325034=10050=TEST52=20250411-02:00:29.265294369=45262=38b76e38-5a27-4fa7-8aa2-3c519fd2251e268=1279=0269=2278=c5b88ea9-605d-4595-ac52-f7c3f08523ba83=159758210255=BTC-USD270=3.55271=0.6197183160=20250411-02:00:29.26402937=2b7f4d30-692b-477d-b3bc-c840f48094d65797=110=002
20250411-02:00:29.389262000 : 8=FIXT.1.19=29035=X49=Coinbase56=24ab46f784d1b20db435b852086e325034=10150=TEST52=20250411-02:00:29.265299369=45262=38b76e38-5a27-4fa7-8aa2-3c519fd2251e268=1279=2269=0278=2b7f4d30-692b-477d-b3bc-c840f48094d683=159758210355=BTC-USD270=3.84271=0.0000000060=20250411-02:00:29.26402958=FILLED10=210
20250411-02:00:29.441435000 : 8=FIXT.1.19=28435=X49=Coinbase56=24ab46f784d1b20db435b852086e325034=10250=TEST52=20250411-02:00:29.325210369=45262=38b76e38-5a27-4fa7-8aa2-3c519fd2251e268=1279=0269=183=159758210455=BTC-USD270=3.35271=0.6197183160=20250411-02:00:29.32388540=237=5cff4017-c61f-4333-83ee-bed5d76f367410=096
20250411-02:00:29.441972000 : 8=FIXT.1.19=32735=X49=Coinbase56=24ab46f784d1b20db435b852086e325034=10350=TEST52=20250411-02:00:29.325218369=45262=38b76e38-5a27-4fa7-8aa2-3c519fd2251e268=1279=0269=2278=4d60a78e-b39b-420e-b830-bc0f3f4fdde283=159758210555=BTC-USD270=3.53271=0.6197183160=20250411-02:00:29.32388537=5cff4017-c61f-4333-83ee-bed5d76f36745797=210=188
20250411-02:00:29.442997000 : 8=FIXT.1.19=29035=X49=Coinbase56=24ab46f784d1b20db435b852086e325034=10450=TEST52=20250411-02:00:29.325223369=45262=38b76e38-5a27-4fa7-8aa2-3c519fd2251e268=1279=2269=1278=5cff4017-c61f-4333-83ee-bed5d76f367483=159758210655=BTC-USD270=3.35271=0.0000000060=20250411-02:00:29.32388558=FILLED10=001
20250411-02:00:29.443281000 : 8=FIXT.1.19=28435=X49=Coinbase56=24ab46f784d1b20db435b852086e325034=10550=TEST52=20250411-02:00:29.325227369=45262=38b76e38-5a27-4fa7-8aa2-3c519fd2251e268=1279=0269=183=159758210755=BTC-USD270=3.26271=0.6197183160=20250411-02:00:29.32388540=237=9cac39cd-6f78-4490-8c10-23899925845a10=189
20250411-02:00:29.443515000 : 8=FIXT.1.19=32735=X49=Coinbase56=24ab46f784d1b20db435b852086e325034=10650=TEST52=20250411-02:00:29.325231369=45262=38b76e38-5a27-4fa7-8aa2-3c519fd2251e268=1279=0269=2278=4d60a78e-b39b-420e-b830-bc0f3f4fdde283=159758210855=BTC-USD270=3.53271=0.6197183160=20250411-02:00:29.32388537=9cac39cd-6f78-4490-8c10-23899925845a5797=210=012
20250411-02:00:29.443787000 : 8=FIXT.1.19=29035=X49=Coinbase56=24ab46f784d1b20db435b852086e325034=10750=TEST52=20250411-02:00:29.325235369=45262=38b76e38-5a27-4fa7-8aa2-3c519fd2251e268=1279=2269=1278=9cac39cd-6f78-4490-8c10-23899925845a83=159758210955=BTC-USD270=3.26271=0.0000000060=20250411-02:00:29.32388558=FILLED10=089
20250411-02:00:29.458392000 : 8=FIXT.1.19=28435=X49=Coinbase56=24ab46f784d1b20db435b852086e325034=10850=TEST52=20250411-02:00:29.341798369=45262=38b76e38-5a27-4fa7-8aa2-3c519fd2251e268=1279=0269=083=159758211055=BTC-USD270=3.91271=0.6197183160=20250411-02:00:29.34034240=237=af0ce9ec-0fcc-4ad6-9d5d-d74f0f91ab2c10=171
20250411-02:00:29.463899000 : 8=FIXT.1.19=32735=X49=Coinbase56=24ab46f784d1b20db435b852086e325034=10950=TEST52=20250411-02:00:29.341806369=45262=38b76e38-5a27-4fa7-8aa2-3c519fd2251e268=1279=0269=2278=c5b88ea9-605d-4595-ac52-f7c3f08523ba83=159758211155=BTC-USD270=3.55271=0.6197183160=20250411-02:00:29.34034237=af0ce9ec-0fcc-4ad6-9d5d-d74f0f91ab2c5797=110=117
20250411-02:00:29.464358000 : 8=FIXT.1.19=29035=X49=Coinbase56=24ab46f784d1b20db435b852086e325034=11050=TEST52=20250411-02:00:29.341811369=45262=38b76e38-5a27-4fa7-8aa2-3c519fd2251e268=1279=2269=0278=af0ce9ec-0fcc-4ad6-9d5d-d74f0f91ab2c83=159758211255=BTC-USD270=3.91271=0.0000000060=20250411-02:00:29.34034258=FILLED10=049
20250411-02:00:29.556319000 : 8=FIXT.1.19=28435=X49=Coinbase56=24ab46f784d1b20db435b852086e325034=11150=TEST52=20250411-02:00:29.439126369=45262=38b76e38-5a27-4fa7-8aa2-3c519fd2251e268=1279=0269=083=159758211355=BTC-USD270=3.75271=0.6197183160=20250411-02:00:29.43695040=237=3528aa63-1306-41b5-946d-632cdafd89aa10=042
20250411-02:00:29.556867000 : 8=FIXT.1.19=32735=X49=Coinbase56=24ab46f784d1b20db435b852086e325034=11250=TEST52=20250411-02:00:29.439132369=45262=38b76e38-5a27-4fa7-8aa2-3c519fd2251e268=1279=0269=2278=c5b88ea9-605d-4595-ac52-f7c3f08523ba83=159758211455=BTC-USD270=3.55271=0.6197183160=20250411-02:00:29.43695037=3528aa63-1306-41b5-946d-632cdafd89aa5797=110=249
20250411-02:00:29.557048000 : 8=FIXT.1.19=29035=X49=Coinbase56=24ab46f784d1b20db435b852086e325034=11350=TEST52=20250411-02:00:29.439136369=45262=38b76e38-5a27-4fa7-8aa2-3c519fd2251e268=1279=2269=0278=3528aa63-1306-41b5-946d-632cdafd89aa83=159758211555=BTC-USD270=3.75271=0.0000000060=20250411-02:00:29.43695058=FILLED10=200
20250411-02:00:29.557309000 : 8=FIXT.1.19=28435=X49=Coinbase56=24ab46f784d1b20db435b852086e325034=11450=TEST52=20250411-02:00:29.439140369=45262=38b76e38-5a27-4fa7-8aa2-3c519fd2251e268=1279=0269=083=159758211655=BTC-USD270=3.81271=0.6197183160=20250411-02:00:29.43695040=237=3e543c92-7a63-4132-865c-1c0c224a510010=088
20250411-02:00:29.558191000 : 8=FIXT.1.19=32735=X49=Coinbase56=24ab46f784d1b20db435b852086e325034=11550=TEST52=20250411-02:00:29.439144369=45262=38b76e38-5a27-4fa7-8aa2-3c519fd2251e268=1279=0269=2278=c5b88ea9-605d-4595-ac52-f7c3f08523ba83=159758211755=BTC-USD270=3.55271=0.6197183160=20250411-02:00:29.43695037=3e543c92-7a63-4132-865c-1c0c224a51005797=110=049
20250411-02:00:29.558350000 : 8=FIXT.1.19=29035=X49=Coinbase56=24ab46f784d1b20db435b852086e325034=11650=TEST52=20250411-02:00:29.439148369=45262=38b76e38-5a27-4fa7-8aa2-3c519fd2251e268=1279=2269=0278=3e543c92-7a63-4132-865c-1c0c224a510083=159758211855=BTC-USD270=3.81271=0.0000000060=20250411-02:00:29.43695058=FILLED10=253
20250411-02:00:29.566800000 : 8=FIXT.1.19=29235=X49=Coinbase56=24ab46f784d1b20db435b852086e325034=11750=TEST52=20250411-02:00:29.450080369=45262=38b76e38-5a27-4fa7-8aa2-3c519fd2251e268=1279=2269=0278=fdbc7e1d-ccf4-462b-8ff6-948d3376718883=159758211955=BTC-USD270=3.51271=0.6232294660=20250411-02:00:29.44884858=CANCELED10=239
20250411-02:00:30.424197000 : 8=FIXT.1.19=29235=X49=Coinbase56=24ab46f784d1b20db435b852086e325034=11850=TEST52=20250411-02:00:30.308042369=45262=38b76e38-5a27-4fa7-8aa2-3c519fd2251e268=1279=2269=1278=cdf1353d-a3bb-4f74-95ad-759d60d356a083=159758212055=BTC-USD270=3.57271=0.6232294660=20250411-02:00:30.30629858=CANCELED10=186
20250411-02:00:30.697619000 : 8=FIXT.1.19=30335=X49=Coinbase56=24ab46f784d1b20db435b852086e325034=11950=TEST52=20250411-02:00:30.581214369=45262=38b76e38-5a27-4fa7-8aa2-3c519fd2251e268=1279=0269=183=159758212155=BTC-USD270=3.32271=0.5835694029004=2.059999982060=20250411-02:00:30.58008040=237=aef976c9-a641-46e0-91ed-bfadebb005d610=189
20250411-02:00:30.698475000 : 8=FIXT.1.19=32735=X49=Coinbase56=24ab46f784d1b20db435b852086e325034=12050=TEST52=20250411-02:00:30.581225369=45262=38b76e38-5a27-4fa7-8aa2-3c519fd2251e268=1279=0269=2278=4d60a78e-b39b-420e-b830-bc0f3f4fdde283=159758212255=BTC-USD270=3.53271=0.5835694060=20250411-02:00:30.58008037=aef976c9-a641-46e0-91ed-bfadebb005d65797=210=092
20250411-02:00:30.698786000 : 8=FIXT.1.19=28135=X49=Coinbase56=24ab46f784d1b20db435b852086e325034=12150=TEST52=20250411-02:00:30.581230369=45262=38b76e38-5a27-4fa7-8aa2-3c519fd2251e268=1279=2269=1278=aef976c9-a641-46e0-91ed-bfadebb005d683=159758212355=BTC-USD270=3.32271=060=20250411-02:00:30.58008058=FILLED10=236
20250411-02:00:30.755417000 : 8=FIXT.1.19=28435=X49=Coinbase56=24ab46f784d1b20db435b852086e325034=12250=TEST52=20250411-02:00:30.639039369=45262=38b76e38-5a27-4fa7-8aa2-3c519fd2251e268=1279=0269=083=159758212455=BTC-USD270=3.84271=0.6197183160=20250411-02:00:30.63768440=237=0d7bf6e0-184c-4706-a4cb-26a4d145cab810=130
20250411-02:00:30.756115000 : 8=FIXT.1.19=32735=X49=Coinbase56=24ab46f784d1b20db435b852086e325034=12350=TEST52=20250411-02:00:30.639050369=45262=38b76e38-5a27-4fa7-8aa2-3c519fd2251e268=1279=0269=2278=c5b88ea9-605d-4595-ac52-f7c3f08523ba83=159758212555=BTC-USD270=3.55271=0.6197183160=20250411-02:00:30.63768437=0d7bf6e0-184c-4706-a4cb-26a4d145cab85797=110=077
20250411-02:00:30.756351000 : 8=FIXT.1.19=29035=X49=Coinbase56=24ab46f784d1b20db435b852086e325034=12450=TEST52=20250411-02:00:30.639054369=45262=38b76e38-5a27-4fa7-8aa2-3c519fd2251e268=1279=2269=0278=0d7bf6e0-184c-4706-a4cb-26a4d145cab883=159758212655=BTC-USD270=3.84271=0.0000000060=20250411-02:00:30.63768458=FILLED10=028
20250411-02:00:30.814242000 : 8=FIXT.1.19=28435=X49=Coinbase56=24ab46f784d1b20db435b852086e325034=12550=TEST52=20250411-02:00:30.698391369=45262=38b76e38-5a27-4fa7-8aa2-3c519fd2251e268=1279=0269=083=159758212755=BTC-USD270=3.85271=0.6197183160=20250411-02:00:30.69735740=237=b8dc7bc7-1812-402c-b0ed-db901592554c10=101
20250411-02:00:30.814736000 : 8=FIXT.1.19=32735=X49=Coinbase56=24ab46f784d1b20db435b852086e325034=12650=TEST52=20250411-02:00:30.698397369=45262=38b76e38-5a27-4fa7-8aa2-3c519fd2251e268=1279=0269=2278=c5b88ea9-605d-4595-ac52-f7c3f08523ba83=159758212855=BTC-USD270=3.55271=0.6197183160=20250411-02:00:30.69735737=b8dc7bc7-1812-402c-b0ed-db901592554c5797=110=060
20250411-02:00:30.815036000 : 8=FIXT.1.19=29035=X49=Coinbase56=24ab46f784d1b20db435b852086e325034=12750=TEST52=20250411-02:00:30.698402369=45262=38b76e38-5a27-4fa7-8aa2-3c519fd2251e268=1279=2269=0278=b8dc7bc7-1812-402c-b0ed-db901592554c83=159758212955=BTC-USD270=3.85271=0.0000000060=20250411-02:00:30.69735758=FILLED10=251
20250411-02:00:30.868481000 : 8=FIXT.1.19=28435=X49=Coinbase56=24ab46f784d1b20db435b852086e325034=12850=TEST52=20250411-02:00:30.752570369=45262=38b76e38-5a27-4fa7-8aa2-3c519fd2251e268=1279=0269=183=159758213055=BTC-USD270=3.21271=0.6197183160=20250411-02:00:30.75112240=237=be31c155-2bbe-4f75-a296-ef72b07670a110=063
20250411-02:00:30.869001000 : 8=FIXT.1.19=32735=X49=Coinbase56=24ab46f784d1b20db435b852086e325034=12950=TEST52=20250411-02:00:30.752578369=45262=38b76e38-5a27-4fa7-8aa2-3c519fd2251e268=1279=0269=2278=4d60a78e-b39b-420e-b830-bc0f3f4fdde283=159758213155=BTC-USD270=3.53271=0.6197183160=20250411-02:00:30.75112237=be31c155-2bbe-4f75-a296-ef72b07670a15797=210=160
20250411-02:00:30.870022000 : 8=FIXT.1.19=29035=X49=Coinbase56=24ab46f784d1b20db435b852086e325034=13050=TEST52=20250411-02:00:30.752583369=45262=38b76e38-5a27-4fa7-8aa2-3c519fd2251e268=1279=2269=1278=be31c155-2bbe-4f75-a296-ef72b07670a183=159758213255=BTC-USD270=3.21271=0.0000000060=20250411-02:00:30.75112258=FILLED10=215
20250411-02:00:30.933128000 : 8=FIXT.1.19=28435=X49=Coinbase56=24ab46f784d1b20db435b852086e325034=13150=TEST52=20250411-02:00:30.817430369=45262=38b76e38-5a27-4fa7-8aa2-3c519fd2251e268=1279=0269=183=159758213355=BTC-USD270=3.21271=0.6232294660=20250411-02:00:30.81602440=237=f2ffe96f-9d6b-4e49-b920-bc507f46756110=092
20250411-02:00:30.934783000 : 8=FIXT.1.19=32735=X49=Coinbase56=24ab46f784d1b20db435b852086e325034=13250=TEST52=20250411-02:00:30.817440369=45262=38b76e38-5a27-4fa7-8aa2-3c519fd2251e268=1279=0269=2278=4d60a78e-b39b-420e-b830-bc0f3f4fdde283=159758213455=BTC-USD270=3.53271=0.6232294660=20250411-02:00:30.81602437=f2ffe96f-9d6b-4e49-b920-bc507f4675615797=210=182
20250411-02:00:30.935053000 : 8=FIXT.1.19=29035=X49=Coinbase56=24ab46f784d1b20db435b852086e325034=13350=TEST52=20250411-02:00:30.817444369=45262=38b76e38-5a27-4fa7-8aa2-3c519fd2251e268=1279=2269=1278=f2ffe96f-9d6b-4e49-b920-bc507f46756183=159758213555=BTC-USD270=3.21271=0.0000000060=20250411-02:00:30.81602458=FILLED10=000
20250411-02:00:30.984063000 : 8=FIXT.1.19=28435=X49=Coinbase56=24ab46f784d1b20db435b852086e325034=13450=TEST52=20250411-02:00:30.868603369=45262=38b76e38-5a27-4fa7-8aa2-3c519fd2251e268=1279=0269=083=159758213655=BTC-USD270=3.79271=0.6232294660=20250411-02:00:30.86725340=237=a4069218-79ba-4160-bf81-2417d4818b2c10=162
20250411-02:00:30.985537000 : 8=FIXT.1.19=8435=534=4649=24ab46f784d1b20db435b852086e325052=20250411-02:00:30.98456=Coinbase10=166
20250411-02:00:30.985736000 : 8=FIXT.1.19=32735=X49=Coinbase56=24ab46f784d1b20db435b852086e325034=13550=TEST52=20250411-02:00:30.868614369=45262=38b76e38-5a27-4fa7-8aa2-3c519fd2251e268=1279=0269=2278=c5b88ea9-605d-4595-ac52-f7c3f08523ba83=159758213755=BTC-USD270=3.55271=0.6232294660=20250411-02:00:30.86725337=a4069218-79ba-4160-bf81-2417d4818b2c5797=110=114
20250411-02:00:30.986101000 : 8=FIXT.1.19=29035=X49=Coinbase56=24ab46f784d1b20db435b852086e325034=13650=TEST52=20250411-02:00:30.868618369=45262=38b76e38-5a27-4fa7-8aa2-3c519fd2251e268=1279=2269=0278=a4069218-79ba-4160-bf81-2417d4818b2c83=159758213855=BTC-USD270=3.79271=0.0000000060=20250411-02:00:30.86725358=FILLED10=071
20250411-02:06:36.145757000 : 8=FIXT.1.19=21535=A34=149=24ab46f784d1b20db435b852086e325052=20250411-02:06:36.13856=Coinbase95=4496=ZIZsHQKZSE/QcaIvEyd1koaUjXKMo2oMMlPLZ09KsRc=98=0108=30141=Y553=24ab46f784d1b20db435b852086e3250554=akmwnltyfgb1137=910=031
20250411-02:06:36.399254000 : 8=FIXT.1.19=12535=A49=Coinbase56=24ab46f784d1b20db435b852086e325034=150=TEST52=20250411-02:06:36.279278369=198=0108=30141=Y1137=910=204
20250411-02:06:37.715806000 : 8=FIXT.1.19=17835=V34=249=24ab46f784d1b20db435b852086e325052=20250411-02:06:37.71456=Coinbase1128=9146=155=BTC-USD262=ecae6588-1a56-49ad-9a18-1bac314fe7a4263=1264=0267=2269=0269=110=157
20250411-02:06:38.112810000 : 8=FIXT.1.19=27635=X49=Coinbase56=24ab46f784d1b20db435b852086e325034=250=TEST52=20250411-02:06:37.992220369=2262=ecae6588-1a56-49ad-9a18-1bac314fe7a4268=1279=0269=083=159758957755=BTC-USD29004=2.208895519560=20250411-02:06:37.99037440=137=c24ab721-ea91-43c6-855e-53bb7f44f77f10=178
20250411-02:06:38.113716000 : 8=FIXT.1.19=32435=X49=Coinbase56=24ab46f784d1b20db435b852086e325034=350=TEST52=20250411-02:06:37.992226369=2262=ecae6588-1a56-49ad-9a18-1bac314fe7a4268=1279=0269=2278=c5b88ea9-605d-4595-ac52-f7c3f08523ba83=159758957855=BTC-USD270=3.55271=0.6222240960=20250411-02:06:37.99037437=c24ab721-ea91-43c6-855e-53bb7f44f77f5797=110=075
20250411-02:06:38.115050000 : 8=FIXT.1.19=26335=X49=Coinbase56=24ab46f784d1b20db435b852086e325034=450=TEST52=20250411-02:06:37.992230369=2262=ecae6588-1a56-49ad-9a18-1bac314fe7a4268=1279=2269=0278=c24ab721-ea91-43c6-855e-53bb7f44f77f83=159758957955=BTC-USD60=20250411-02:06:37.99037458=FILLED10=195
20250411-02:06:38.139876000 : 8=FIXT.1.19=27235=X49=Coinbase56=24ab46f784d1b20db435b852086e325034=550=TEST52=20250411-02:06:38.021005369=2262=ecae6588-1a56-49ad-9a18-1bac314fe7a4268=1279=0269=183=159758958055=BTC-USD271=0.6197183160=20250411-02:06:38.01942240=137=536be686-4e46-4a69-ae4d-fb34444eeaec10=029
20250411-02:06:38.140439000 : 8=FIXT.1.19=32435=X49=Coinbase56=24ab46f784d1b20db435b852086e325034=650=TEST52=20250411-02:06:38.021015369=2262=ecae6588-1a56-49ad-9a18-1bac314fe7a4268=1279=0269=2278=4d60a78e-b39b-420e-b830-bc0f3f4fdde283=159758958155=BTC-USD270=3.53271=0.6197183160=20250411-02:06:38.01942237=536be686-4e46-4a69-ae4d-fb34444eeaec5797=210=019
20250411-02:06:38.140871000 : 8=FIXT.1.19=27835=X49=Coinbase56=24ab46f784d1b20db435b852086e325034=750=TEST52=20250411-02:06:38.021111369=2262=ecae6588-1a56-49ad-9a18-1bac314fe7a4268=1279=2269=1278=536be686-4e46-4a69-ae4d-fb34444eeaec83=159758958255=BTC-USD271=0.0000000060=20250411-02:06:38.01942258=FILLED10=194
20250411-02:06:38.454209000 : 8=FIXT.1.19=27635=X49=Coinbase56=24ab46f784d1b20db435b852086e325034=850=TEST52=20250411-02:06:38.334373369=2262=ecae6588-1a56-49ad-9a18-1bac314fe7a4268=1279=0269=083=159758958355=BTC-USD29004=2.208895519560=20250411-02:06:38.33325340=137=ec1b8e57-cfe5-4e07-9121-9556c5e82da110=171
20250411-02:06:38.454737000 : 8=FIXT.1.19=32435=X49=Coinbase56=24ab46f784d1b20db435b852086e325034=950=TEST52=20250411-02:06:38.334378369=2262=ecae6588-1a56-49ad-9a18-1bac314fe7a4268=1279=0269=2278=c5b88ea9-605d-4595-ac52-f7c3f08523ba83=159758958455=BTC-USD270=3.55271=0.6222240960=20250411-02:06:38.33325337=ec1b8e57-cfe5-4e07-9121-9556c5e82da15797=110=067
20250411-02:06:38.454914000 : 8=FIXT.1.19=26435=X49=Coinbase56=24ab46f784d1b20db435b852086e325034=1050=TEST52=20250411-02:06:38.334382369=2262=ecae6588-1a56-49ad-9a18-1bac314fe7a4268=1279=2269=0278=ec1b8e57-cfe5-4e07-9121-9556c5e82da183=159758958555=BTC-USD60=20250411-02:06:38.33325358=FILLED10=227
20250411-02:06:38.469022000 : 8=FIXT.1.19=28235=X49=Coinbase56=24ab46f784d1b20db435b852086e325034=1150=TEST52=20250411-02:06:38.349214369=2262=ecae6588-1a56-49ad-9a18-1bac314fe7a4268=1279=0269=183=159758958655=BTC-USD270=3.18271=0.6232294660=20250411-02:06:38.34827440=237=8afd8a6d-6609-450c-a4e3-ab8b5678439d10=173
20250411-02:06:38.469163000 : 8=FIXT.1.19=32535=X49=Coinbase56=24ab46f784d1b20db435b852086e325034=1250=TEST52=20250411-02:06:38.349218369=2262=ecae6588-1a56-49ad-9a18-1bac314fe7a4268=1279=0269=2278=4d60a78e-b39b-420e-b830-bc0f3f4fdde283=159758958755=BTC-USD270=3.53271=0.6232294660=20250411-02:06:38.34827437=8afd8a6d-6609-450c-a4e3-ab8b5678439d5797=210=004
20250411-02:06:38.469315000 : 8=FIXT.1.19=28835=X49=Coinbase56=24ab46f784d1b20db435b852086e325034=1350=TEST52=20250411-02:06:38.349222369=2262=ecae6588-1a56-49ad-9a18-1bac314fe7a4268=1279=2269=1278=8afd8a6d-6609-450c-a4e3-ab8b5678439d83=159758958855=BTC-USD270=3.18271=0.0000000060=20250411-02:06:38.34827458=FILLED10=084
20250411-02:06:38.482383000 : 8=FIXT.1.19=27335=X49=Coinbase56=24ab46f784d1b20db435b852086e325034=1450=TEST52=20250411-02:06:38.363229369=2262=ecae6588-1a56-49ad-9a18-1bac314fe7a4268=1279=0269=183=159758958955=BTC-USD271=0.6232294660=20250411-02:06:38.36207740=137=ea8a5157-dbc9-4fef-995c-372b8f7b68bc10=171
20250411-02:06:38.482800000 : 8=FIXT.1.19=32535=X49=Coinbase56=24ab46f784d1b20db435b852086e325034=1550=TEST52=20250411-02:06:38.363234369=2262=ecae6588-1a56-49ad-9a18-1bac314fe7a4268=1279=0269=2278=4d60a78e-b39b-420e-b830-bc0f3f4fdde283=159758959055=BTC-USD270=3.53271=0.6232294660=20250411-02:06:38.36207737=ea8a5157-dbc9-4fef-995c-372b8f7b68bc5797=210=147
20250411-02:06:38.483098000 : 8=FIXT.1.19=27935=X49=Coinbase56=24ab46f784d1b20db435b852086e325034=1650=TEST52=20250411-02:06:38.363238369=2262=ecae6588-1a56-49ad-9a18-1bac314fe7a4268=1279=2269=1278=ea8a5157-dbc9-4fef-995c-372b8f7b68bc83=159758959155=BTC-USD271=0.0000000060=20250411-02:06:38.36207758=FILLED10=075
20250411-02:06:38.739478000 : 8=FIXT.1.19=27735=X49=Coinbase56=24ab46f784d1b20db435b852086e325034=1750=TEST52=20250411-02:06:38.620305369=2262=ecae6588-1a56-49ad-9a18-1bac314fe7a4268=1279=0269=083=159758959255=BTC-USD29004=2.208895519560=20250411-02:06:38.61914740=137=d6f7dc5b-48ea-4191-8f7d-8f570403be3d10=018
20250411-02:06:38.740026000 : 8=FIXT.1.19=32535=X49=Coinbase56=24ab46f784d1b20db435b852086e325034=1850=TEST52=20250411-02:06:38.620313369=2262=ecae6588-1a56-49ad-9a18-1bac314fe7a4268=1279=0269=2278=c5b88ea9-605d-4595-ac52-f7c3f08523ba83=159758959355=BTC-USD270=3.55271=0.6222240960=20250411-02:06:38.61914737=d6f7dc5b-48ea-4191-8f7d-8f570403be3d5797=110=164
20250411-02:06:38.740210000 : 8=FIXT.1.19=26435=X49=Coinbase56=24ab46f784d1b20db435b852086e325034=1950=TEST52=20250411-02:06:38.620317369=2262=ecae6588-1a56-49ad-9a18-1bac314fe7a4268=1279=2269=0278=d6f7dc5b-48ea-4191-8f7d-8f570403be3d83=159758959455=BTC-USD60=20250411-02:06:38.61914758=FILLED10=037
20250411-02:06:38.767795000 : 8=FIXT.1.19=27335=X49=Coinbase56=24ab46f784d1b20db435b852086e325034=2050=TEST52=20250411-02:06:38.649047369=2262=ecae6588-1a56-49ad-9a18-1bac314fe7a4268=1279=0269=183=159758959555=BTC-USD271=0.6232294660=20250411-02:06:38.64798140=137=7905edb4-093f-467f-ac4f-3f4f009f5bf310=071
20250411-02:06:38.768249000 : 8=FIXT.1.19=32535=X49=Coinbase56=24ab46f784d1b20db435b852086e325034=2150=TEST52=20250411-02:06:38.649053369=2262=ecae6588-1a56-49ad-9a18-1bac314fe7a4268=1279=0269=2278=4d60a78e-b39b-420e-b830-bc0f3f4fdde283=159758959655=BTC-USD270=3.53271=0.6232294660=20250411-02:06:38.64798137=7905edb4-093f-467f-ac4f-3f4f009f5bf35797=210=057
20250411-02:06:38.768412000 : 8=FIXT.1.19=27935=X49=Coinbase56=24ab46f784d1b20db435b852086e325034=2250=TEST52=20250411-02:06:38.649058369=2262=ecae6588-1a56-49ad-9a18-1bac314fe7a4268=1279=2269=1278=7905edb4-093f-467f-ac4f-3f4f009f5bf383=159758959755=BTC-USD271=0.0000000060=20250411-02:06:38.64798158=FILLED10=242
20250411-02:06:39.000669000 : 8=FIXT.1.19=28235=X49=Coinbase56=24ab46f784d1b20db435b852086e325034=2350=TEST52=20250411-02:06:38.880966369=2262=ecae6588-1a56-49ad-9a18-1bac314fe7a4268=1279=0269=183=159758959855=BTC-USD270=3.24271=0.6232294660=20250411-02:06:38.87916740=237=a8fb6e0a-8846-4738-82f4-ab6ed66b8f0b10=250
20250411-02:06:39.001168000 : 8=FIXT.1.19=32535=X49=Coinbase56=24ab46f784d1b20db435b852086e325034=2450=TEST52=20250411-02:06:38.880977369=2262=ecae6588-1a56-49ad-9a18-1bac314fe7a4268=1279=0269=2278=4d60a78e-b39b-420e-b830-bc0f3f4fdde283=159758959955=BTC-USD270=3.53271=0.6232294660=20250411-02:06:38.87916737=a8fb6e0a-8846-4738-82f4-ab6ed66b8f0b5797=210=082
20250411-02:06:39.001366000 : 8=FIXT.1.19=28835=X49=Coinbase56=24ab46f784d1b20db435b852086e325034=2550=TEST52=20250411-02:06:38.880981369=2262=ecae6588-1a56-49ad-9a18-1bac314fe7a4268=1279=2269=1278=a8fb6e0a-8846-4738-82f4-ab6ed66b8f0b83=159758960055=BTC-USD270=3.24271=0.0000000060=20250411-02:06:38.87916758=FILLED10=141
20250411-02:06:39.055003000 : 8=FIXT.1.19=28235=X49=Coinbase56=24ab46f784d1b20db435b852086e325034=2650=TEST52=20250411-02:06:38.936059369=2262=ecae6588-1a56-49ad-9a18-1bac314fe7a4268=1279=0269=083=159758960155=BTC-USD270=3.81271=0.6232294660=20250411-02:06:38.93530740=237=0b483823-cf0c-49c6-88a2-095cfc5beb3b10=207
20250411-02:06:39.055438000 : 8=FIXT.1.19=32535=X49=Coinbase56=24ab46f784d1b20db435b852086e325034=2750=TEST52=20250411-02:06:38.936062369=2262=ecae6588-1a56-49ad-9a18-1bac314fe7a4268=1279=0269=2278=c5b88ea9-605d-4595-ac52-f7c3f08523ba83=159758960255=BTC-USD270=3.55271=0.6232294660=20250411-02:06:38.93530737=0b483823-cf0c-49c6-88a2-095cfc5beb3b5797=110=158
20250411-02:06:39.055737000 : 8=FIXT.1.19=28835=X49=Coinbase56=24ab46f784d1b20db435b852086e325034=2850=TEST52=20250411-02:06:38.936065369=2262=ecae6588-1a56-49ad-9a18-1bac314fe7a4268=1279=2269=0278=0b483823-cf0c-49c6-88a2-095cfc5beb3b83=159758960355=BTC-USD270=3.81271=0.0000000060=20250411-02:06:38.93530758=FILLED10=116
20250411-02:06:39.083457000 : 8=FIXT.1.19=27735=X49=Coinbase56=24ab46f784d1b20db435b852086e325034=2950=TEST52=20250411-02:06:38.964715369=2262=ecae6588-1a56-49ad-9a18-1bac314fe7a4268=1279=0269=083=159758960455=BTC-USD29004=2.208895519560=20250411-02:06:38.96346740=137=06a9133e-4beb-4011-87f8-a168bcf43d4310=177
20250411-02:06:39.083716000 : 8=FIXT.1.19=32535=X49=Coinbase56=24ab46f784d1b20db435b852086e325034=3050=TEST52=20250411-02:06:38.964720369=2262=ecae6588-1a56-49ad-9a18-1bac314fe7a4268=1279=0269=2278=c5b88ea9-605d-4595-ac52-f7c3f08523ba83=159758960555=BTC-USD270=3.55271=0.6222240960=20250411-02:06:38.96346737=06a9133e-4beb-4011-87f8-a168bcf43d435797=110=055
20250411-02:06:39.083882000 : 8=FIXT.1.19=26435=X49=Coinbase56=24ab46f784d1b20db435b852086e325034=3150=TEST52=20250411-02:06:38.964724369=2262=ecae6588-1a56-49ad-9a18-1bac314fe7a4268=1279=2269=0278=06a9133e-4beb-4011-87f8-a168bcf43d4383=159758960655=BTC-USD60=20250411-02:06:38.96346758=FILLED10=184
20250411-02:06:39.111009000 : 8=FIXT.1.19=27335=X49=Coinbase56=24ab46f784d1b20db435b852086e325034=3250=TEST52=20250411-02:06:38.991989369=2262=ecae6588-1a56-49ad-9a18-1bac314fe7a4268=1279=0269=183=159758960755=BTC-USD271=0.6232294660=20250411-02:06:38.99026740=137=9c4894c9-1882-4e00-8c21-7125a162f3ab10=084
20250411-02:06:39.111464000 : 8=FIXT.1.19=32535=X49=Coinbase56=24ab46f784d1b20db435b852086e325034=3350=TEST52=20250411-02:06:38.991995369=2262=ecae6588-1a56-49ad-9a18-1bac314fe7a4268=1279=0269=2278=4d60a78e-b39b-420e-b830-bc0f3f4fdde283=159758960855=BTC-USD270=3.53271=0.6232294660=20250411-02:06:38.99026737=9c4894c9-1882-4e00-8c21-7125a162f3ab5797=210=070
20250411-02:06:39.111632000 : 8=FIXT.1.19=27935=X49=Coinbase56=24ab46f784d1b20db435b852086e325034=3450=TEST52=20250411-02:06:38.991999369=2262=ecae6588-1a56-49ad-9a18-1bac314fe7a4268=1279=2269=1278=9c4894c9-1882-4e00-8c21-7125a162f3ab83=159758960955=BTC-USD271=0.0000000060=20250411-02:06:38.99026758=FILLED10=254
20250411-02:06:39.115660000 : 8=FIXT.1.19=28135=X49=Coinbase56=24ab46f784d1b20db435b852086e325034=3550=TEST52=20250411-02:06:38.995756369=2262=ecae6588-1a56-49ad-9a18-1bac314fe7a4268=1279=0269=183=159758961055=BTC-USD270=3.3271=0.6197183160=20250411-02:06:38.99426240=237=9b0e41a4-876b-48c6-a524-7d250aba2fb010=107
20250411-02:06:39.116337000 : 8=FIXT.1.19=32535=X49=Coinbase56=24ab46f784d1b20db435b852086e325034=3650=TEST52=20250411-02:06:38.995761369=2262=ecae6588-1a56-49ad-9a18-1bac314fe7a4268=1279=0269=2278=4d60a78e-b39b-420e-b830-bc0f3f4fdde283=159758961155=BTC-USD270=3.53271=0.6197183160=20250411-02:06:38.99426237=9b0e41a4-876b-48c6-a524-7d250aba2fb05797=210=241
20250411-02:06:39.116527000 : 8=FIXT.1.19=28735=X49=Coinbase56=24ab46f784d1b20db435b852086e325034=3750=TEST52=20250411-02:06:38.995765369=2262=ecae6588-1a56-49ad-9a18-1bac314fe7a4268=1279=2269=1278=9b0e41a4-876b-48c6-a524-7d250aba2fb083=159758961255=BTC-USD270=3.3271=0.0000000060=20250411-02:06:38.99426258=FILLED10=017
20250411-02:06:39.169125000 : 8=FIXT.1.19=28235=X49=Coinbase56=24ab46f784d1b20db435b852086e325034=3850=TEST52=20250411-02:06:39.049581369=2262=ecae6588-1a56-49ad-9a18-1bac314fe7a4268=1279=0269=083=159758961355=BTC-USD270=3.77271=0.6197183160=20250411-02:06:39.04893340=237=b5da2070-5d9d-4cad-9b6b-0df8c47522e110=002
20250411-02:06:39.169500000 : 8=FIXT.1.19=32535=X49=Coinbase56=24ab46f784d1b20db435b852086e325034=3950=TEST52=20250411-02:06:39.049672369=2262=ecae6588-1a56-49ad-9a18-1bac314fe7a4268=1279=0269=2278=c5b88ea9-605d-4595-ac52-f7c3f08523ba83=159758961455=BTC-USD270=3.55271=0.6197183160=20250411-02:06:39.04893337=b5da2070-5d9d-4cad-9b6b-0df8c47522e15797=110=211
20250411-02:06:39.169768000 : 8=FIXT.1.19=28835=X49=Coinbase56=24ab46f784d1b20db435b852086e325034=4050=TEST52=20250411-02:06:39.049676369=2262=ecae6588-1a56-49ad-9a18-1bac314fe7a4268=1279=2269=0278=b5da2070-5d9d-4cad-9b6b-0df8c47522e183=159758961555=BTC-USD270=3.77271=0.0000000060=20250411-02:06:39.04893358=FILLED10=164
20250411-02:06:39.371537000 : 8=FIXT.1.19=27735=X49=Coinbase56=24ab46f784d1b20db435b852086e325034=4150=TEST52=20250411-02:06:39.250587369=2262=ecae6588-1a56-49ad-9a18-1bac314fe7a4268=1279=0269=083=159758961655=BTC-USD29004=2.208895519560=20250411-02:06:39.24888740=137=276e4fa7-5ead-4bfb-b36e-0209d43b1a5010=054
20250411-02:06:39.371908000 : 8=FIXT.1.19=32535=X49=Coinbase56=24ab46f784d1b20db435b852086e325034=4250=TEST52=20250411-02:06:39.250597369=2262=ecae6588-1a56-49ad-9a18-1bac314fe7a4268=1279=0269=2278=c5b88ea9-605d-4595-ac52-f7c3f08523ba83=159758961755=BTC-USD270=3.55271=0.6222240960=20250411-02:06:39.24888737=276e4fa7-5ead-4bfb-b36e-0209d43b1a505797=110=202
20250411-02:06:39.372046000 : 8=FIXT.1.19=26435=X49=Coinbase56=24ab46f784d1b20db435b852086e325034=4350=TEST52=20250411-02:06:39.250602369=2262=ecae6588-1a56-49ad-9a18-1bac314fe7a4268=1279=2269=0278=276e4fa7-5ead-4bfb-b36e-0209d43b1a5083=159758961855=BTC-USD60=20250411-02:06:39.24888758=FILLED10=058
20250411-02:06:39.397503000 : 8=FIXT.1.19=27335=X49=Coinbase56=24ab46f784d1b20db435b852086e325034=4450=TEST52=20250411-02:06:39.278059369=2262=ecae6588-1a56-49ad-9a18-1bac314fe7a4268=1279=0269=183=159758961955=BTC-USD271=0.6197183160=20250411-02:06:39.27665740=137=62a4c4bd-e2ea-4791-a17b-ca78c384ce0410=104
20250411-02:06:39.397875000 : 8=FIXT.1.19=32535=X49=Coinbase56=24ab46f784d1b20db435b852086e325034=4550=TEST52=20250411-02:06:39.278065369=2262=ecae6588-1a56-49ad-9a18-1bac314fe7a4268=1279=0269=2278=4d60a78e-b39b-420e-b830-bc0f3f4fdde283=159758962055=BTC-USD270=3.53271=0.6197183160=20250411-02:06:39.27665737=62a4c4bd-e2ea-4791-a17b-ca78c384ce045797=210=081
20250411-02:06:39.398047000 : 8=FIXT.1.19=27935=X49=Coinbase56=24ab46f784d1b20db435b852086e325034=4650=TEST52=20250411-02:06:39.278069369=2262=ecae6588-1a56-49ad-9a18-1bac314fe7a4268=1279=2269=1278=62a4c4bd-e2ea-4791-a17b-ca78c384ce0483=159758962155=BTC-USD271=0.0000000060=20250411-02:06:39.27665758=FILLED10=007
20250411-02:06:39.427196000 : 8=FIXT.1.19=27735=X49=Coinbase56=24ab46f784d1b20db435b852086e325034=4750=TEST52=20250411-02:06:39.306547369=2262=ecae6588-1a56-49ad-9a18-1bac314fe7a4268=1279=0269=083=159758962255=BTC-USD29004=2.208895519560=20250411-02:06:39.30562840=137=07aaf33f-83c7-4fbd-bbc7-cdbf12ef6e1910=248
20250411-02:06:39.427467000 : 8=FIXT.1.19=32535=X49=Coinbase56=24ab46f784d1b20db435b852086e325034=4850=TEST52=20250411-02:06:39.306552369=2262=ecae6588-1a56-49ad-9a18-1bac314fe7a4268=1279=0269=2278=c5b88ea9-605d-4595-ac52-f7c3f08523ba83=159758962355=BTC-USD270=3.55271=0.6222240960=20250411-02:06:39.30562837=07aaf33f-83c7-4fbd-bbc7-cdbf12ef6e195797=110=135
20250411-02:06:39.427626000 : 8=FIXT.1.19=26435=X49=Coinbase56=24ab46f784d1b20db435b852086e325034=4950=TEST52=20250411-02:06:39.306555369=2262=ecae6588-1a56-49ad-9a18-1bac314fe7a4268=1279=2269=0278=07aaf33f-83c7-4fbd-bbc7-cdbf12ef6e1983=159758962455=BTC-USD60=20250411-02:06:39.30562858=FILLED10=007
20250411-02:06:39.454267000 : 8=FIXT.1.19=27335=X49=Coinbase56=24ab46f784d1b20db435b852086e325034=5050=TEST52=20250411-02:06:39.335005369=2262=ecae6588-1a56-49ad-9a18-1bac314fe7a4268=1279=0269=183=159758962555=BTC-USD271=0.6197183160=20250411-02:06:39.33358340=137=ebcfea63-38d1-449f-b384-21442086c38010=147
20250411-02:06:39.455483000 : 8=FIXT.1.19=32535=X49=Coinbase56=24ab46f784d1b20db435b852086e325034=5150=TEST52=20250411-02:06:39.335012369=2262=ecae6588-1a56-49ad-9a18-1bac314fe7a4268=1279=0269=2278=4d60a78e-b39b-420e-b830-bc0f3f4fdde283=159758962655=BTC-USD270=3.53271=0.6197183160=20250411-02:06:39.33358337=ebcfea63-38d1-449f-b384-21442086c3805797=210=134
20250411-02:06:39.456043000 : 8=FIXT.1.19=27935=X49=Coinbase56=24ab46f784d1b20db435b852086e325034=5250=TEST52=20250411-02:06:39.335016369=2262=ecae6588-1a56-49ad-9a18-1bac314fe7a4268=1279=2269=1278=ebcfea63-38d1-449f-b384-21442086c38083=159758962755=BTC-USD271=0.0000000060=20250411-02:06:39.33358358=FILLED10=060
20250411-02:06:39.456940000 : 8=FIXT.1.19=30135=X49=Coinbase56=24ab46f784d1b20db435b852086e325034=5350=TEST52=20250411-02:06:39.337918369=2262=ecae6588-1a56-49ad-9a18-1bac314fe7a4268=1279=0269=083=159758962855=BTC-USD270=3.82271=0.6672719929004=2.368815564560=20250411-02:06:39.33691840=237=2e76ce65-3cca-4a1d-ab3a-5094e608c64f10=188
20250411-02:06:39.457281000 : 8=FIXT.1.19=32535=X49=Coinbase56=24ab46f784d1b20db435b852086e325034=5450=TEST52=20250411-02:06:39.337922369=2262=ecae6588-1a56-49ad-9a18-1bac314fe7a4268=1279=0269=2278=c5b88ea9-605d-4595-ac52-f7c3f08523ba83=159758962955=BTC-USD270=3.55271=0.6672719960=20250411-02:06:39.33691837=2e76ce65-3cca-4a1d-ab3a-5094e608c64f5797=110=227
20250411-02:06:39.457496000 : 8=FIXT.1.19=27935=X49=Coinbase56=24ab46f784d1b20db435b852086e325034=5550=TEST52=20250411-02:06:39.337978369=2262=ecae6588-1a56-49ad-9a18-1bac314fe7a4268=1279=2269=0278=2e76ce65-3cca-4a1d-ab3a-5094e608c64f83=159758963055=BTC-USD270=3.82271=060=20250411-02:06:39.33691858=FILLED10=254
20250411-02:06:39.471099000 : 8=FIXT.1.19=28235=X49=Coinbase56=24ab46f784d1b20db435b852086e325034=5650=TEST52=20250411-02:06:39.352417369=2262=ecae6588-1a56-49ad-9a18-1bac314fe7a4268=1279=0269=083=159758963155=BTC-USD270=3.88271=0.6232294660=20250411-02:06:39.35118340=237=05026790-ef1b-459a-b990-6322a917926110=129
20250411-02:06:39.471643000 : 8=FIXT.1.19=32535=X49=Coinbase56=24ab46f784d1b20db435b852086e325034=5750=TEST52=20250411-02:06:39.352421369=2262=ecae6588-1a56-49ad-9a18-1bac314fe7a4268=1279=0269=2278=c5b88ea9-605d-4595-ac52-f7c3f08523ba83=159758963255=BTC-USD270=3.55271=0.6232294660=20250411-02:06:39.35118337=05026790-ef1b-459a-b990-6322a91792615797=110=074
20250411-02:06:39.471883000 : 8=FIXT.1.19=28835=X49=Coinbase56=24ab46f784d1b20db435b852086e325034=5850=TEST52=20250411-02:06:39.352425369=2262=ecae6588-1a56-49ad-9a18-1bac314fe7a4268=1279=2269=0278=05026790-ef1b-459a-b990-6322a917926183=159758963355=BTC-USD270=3.88271=0.0000000060=20250411-02:06:39.35118358=FILLED10=040
20250411-02:06:39.489057000 : 8=FIXT.1.19=27735=X49=Coinbase56=24ab46f784d1b20db435b852086e325034=5950=TEST52=20250411-02:06:39.364773369=2262=ecae6588-1a56-49ad-9a18-1bac314fe7a4268=1279=0269=083=159758963455=BTC-USD29004=2.208895519560=20250411-02:06:39.36326940=137=976b5e25-de00-4857-9ede-13367eb9bf2d10=251
20250411-02:06:39.493127000 : 8=FIXT.1.19=32535=X49=Coinbase56=24ab46f784d1b20db435b852086e325034=6050=TEST52=20250411-02:06:39.364777369=2262=ecae6588-1a56-49ad-9a18-1bac314fe7a4268=1279=0269=2278=c5b88ea9-605d-4595-ac52-f7c3f08523ba83=159758963555=BTC-USD270=3.55271=0.6222240960=20250411-02:06:39.36326937=976b5e25-de00-4857-9ede-13367eb9bf2d5797=110=137
20250411-02:06:39.493675000 : 8=FIXT.1.19=26435=X49=Coinbase56=24ab46f784d1b20db435b852086e325034=6150=TEST52=20250411-02:06:39.364781369=2262=ecae6588-1a56-49ad-9a18-1bac314fe7a4268=1279=2269=0278=976b5e25-de00-4857-9ede-13367eb9bf2d83=159758963655=BTC-USD60=20250411-02:06:39.36326958=FILLED10=001
20250411-02:06:39.511192000 : 8=FIXT.1.19=27335=X49=Coinbase56=24ab46f784d1b20db435b852086e325034=6250=TEST52=20250411-02:06:39.392074369=2262=ecae6588-1a56-49ad-9a18-1bac314fe7a4268=1279=0269=183=159758963755=BTC-USD271=0.6197183160=20250411-02:06:39.39031440=137=882da0bb-13d7-45ea-b1cf-8678e8383b6d10=054
20250411-02:06:39.511797000 : 8=FIXT.1.19=32535=X49=Coinbase56=24ab46f784d1b20db435b852086e325034=6350=TEST52=20250411-02:06:39.392079369=2262=ecae6588-1a56-49ad-9a18-1bac314fe7a4268=1279=0269=2278=4d60a78e-b39b-420e-b830-bc0f3f4fdde283=159758963855=BTC-USD270=3.53271=0.6197183160=20250411-02:06:39.39031437=882da0bb-13d7-45ea-b1cf-8678e8383b6d5797=210=048
20250411-02:06:39.511985000 : 8=FIXT.1.19=27935=X49=Coinbase56=24ab46f784d1b20db435b852086e325034=6450=TEST52=20250411-02:06:39.392083369=2262=ecae6588-1a56-49ad-9a18-1bac314fe7a4268=1279=2269=1278=882da0bb-13d7-45ea-b1cf-8678e8383b6d83=159758963955=BTC-USD271=0.0000000060=20250411-02:06:39.39031458=FILLED10=221
20250411-02:06:39.512158000 : 8=FIXT.1.19=28235=X49=Coinbase56=24ab46f784d1b20db435b852086e325034=6550=TEST52=20250411-02:06:39.392266369=2262=ecae6588-1a56-49ad-9a18-1bac314fe7a4268=1279=0269=183=159758964055=BTC-USD270=3.33271=0.6197183160=20250411-02:06:39.39157040=237=aa0cf57a-63e2-489b-b3ea-169995fd854510=178
20250411-02:06:39.512326000 : 8=FIXT.1.19=32535=X49=Coinbase56=24ab46f784d1b20db435b852086e325034=6650=TEST52=20250411-02:06:39.392270369=2262=ecae6588-1a56-49ad-9a18-1bac314fe7a4268=1279=0269=2278=4d60a78e-b39b-420e-b830-bc0f3f4fdde283=159758964155=BTC-USD270=3.53271=0.6197183160=20250411-02:06:39.39157037=aa0cf57a-63e2-489b-b3ea-169995fd85455797=210=003
20250411-02:06:39.512488000 : 8=FIXT.1.19=28835=X49=Coinbase56=24ab46f784d1b20db435b852086e325034=6750=TEST52=20250411-02:06:39.392274369=2262=ecae6588-1a56-49ad-9a18-1bac314fe7a4268=1279=2269=1278=aa0cf57a-63e2-489b-b3ea-169995fd854583=159758964255=BTC-USD270=3.33271=0.0000000060=20250411-02:06:39.39157058=FILLED10=087
20250411-02:06:39.804026000 : 8=FIXT.1.19=28235=X49=Coinbase56=24ab46f784d1b20db435b852086e325034=6850=TEST52=20250411-02:06:39.681638369=2262=ecae6588-1a56-49ad-9a18-1bac314fe7a4268=1279=0269=183=159758964355=BTC-USD270=3.31271=0.6232294660=20250411-02:06:39.68028440=237=341270a5-1d9f-41bb-80c9-7f8a61b935f810=080
20250411-02:06:39.804511000 : 8=FIXT.1.19=32535=X49=Coinbase56=24ab46f784d1b20db435b852086e325034=6950=TEST52=20250411-02:06:39.681646369=2262=ecae6588-1a56-49ad-9a18-1bac314fe7a4268=1279=0269=2278=4d60a78e-b39b-420e-b830-bc0f3f4fdde283=159758964455=BTC-USD270=3.53271=0.6232294660=20250411-02:06:39.68028437=341270a5-1d9f-41bb-80c9-7f8a61b935f85797=210=167
20250411-02:06:39.804753000 : 8=FIXT.1.19=28835=X49=Coinbase56=24ab46f784d1b20db435b852086e325034=7050=TEST52=20250411-02:06:39.681651369=2262=ecae6588-1a56-49ad-9a18-1bac314fe7a4268=1279=2269=1278=341270a5-1d9f-41bb-80c9-7f8a61b935f883=159758964555=BTC-USD270=3.31271=0.0000000060=20250411-02:06:39.68028458=FILLED10=234
20250411-02:06:39.805065000 : 8=FIXT.1.19=28235=X49=Coinbase56=24ab46f784d1b20db435b852086e325034=7150=TEST52=20250411-02:06:39.681706369=2262=ecae6588-1a56-49ad-9a18-1bac314fe7a4268=1279=0269=183=159758964655=BTC-USD270=3.34271=0.6232294660=20250411-02:06:39.68028440=237=89b48987-14a6-4b6b-814b-0ff52329754710=206
20250411-02:06:39.805238000 : 8=FIXT.1.19=32535=X49=Coinbase56=24ab46f784d1b20db435b852086e325034=7250=TEST52=20250411-02:06:39.681711369=2262=ecae6588-1a56-49ad-9a18-1bac314fe7a4268=1279=0269=2278=4d60a78e-b39b-420e-b830-bc0f3f4fdde283=159758964755=BTC-USD270=3.53271=0.6232294660=20250411-02:06:39.68028437=89b48987-14a6-4b6b-814b-0ff5232975475797=210=031
20250411-02:06:39.805391000 : 8=FIXT.1.19=28835=X49=Coinbase56=24ab46f784d1b20db435b852086e325034=7350=TEST52=20250411-02:06:39.681715369=2262=ecae6588-1a56-49ad-9a18-1bac314fe7a4268=1279=2269=1278=89b48987-14a6-4b6b-814b-0ff52329754783=159758964855=BTC-USD270=3.34271=0.0000000060=20250411-02:06:39.68028458=FILLED10=118
20250411-02:06:39.912399000 : 8=FIXT.1.19=28235=X49=Coinbase56=24ab46f784d1b20db435b852086e325034=7450=TEST52=20250411-02:06:39.793603369=2262=ecae6588-1a56-49ad-9a18-1bac314fe7a4268=1279=0269=083=159758964955=BTC-USD270=3.75271=0.6232294660=20250411-02:06:39.79217940=237=30300311-aa51-4953-b449-1d53276ab13310=120
20250411-02:06:39.912988000 : 8=FIXT.1.19=32535=X49=Coinbase56=24ab46f784d1b20db435b852086e325034=7550=TEST52=20250411-02:06:39.793611369=2262=ecae6588-1a56-49ad-9a18-1bac314fe7a4268=1279=0269=2278=c5b88ea9-605d-4595-ac52-f7c3f08523ba83=159758965055=BTC-USD270=3.55271=0.6232294660=20250411-02:06:39.79217937=30300311-aa51-4953-b449-1d53276ab1335797=110=064
20250411-02:06:39.913162000 : 8=FIXT.1.19=28835=X49=Coinbase56=24ab46f784d1b20db435b852086e325034=7650=TEST52=20250411-02:06:39.793615369=2262=ecae6588-1a56-49ad-9a18-1bac314fe7a4268=1279=2269=0278=30300311-aa51-4953-b449-1d53276ab13383=159758965155=BTC-USD270=3.75271=0.0000000060=20250411-02:06:39.79217958=FILLED10=026
20250411-02:06:39.913324000 : 8=FIXT.1.19=28235=X49=Coinbase56=24ab46f784d1b20db435b852086e325034=7750=TEST52=20250411-02:06:39.793619369=2262=ecae6588-1a56-49ad-9a18-1bac314fe7a4268=1279=0269=083=159758965255=BTC-USD270=3.82271=0.6232294660=20250411-02:06:39.79217940=237=90ef2788-d7f9-46db-b29a-58bb24f25fc810=003
20250411-02:06:39.913473000 : 8=FIXT.1.19=32535=X49=Coinbase56=24ab46f784d1b20db435b852086e325034=7850=TEST52=20250411-02:06:39.793623369=2262=ecae6588-1a56-49ad-9a18-1bac314fe7a4268=1279=0269=2278=c5b88ea9-605d-4595-ac52-f7c3f08523ba83=159758965355=BTC-USD270=3.55271=0.6232294660=20250411-02:06:39.79217937=90ef2788-d7f9-46db-b29a-58bb24f25fc85797=110=210
20250411-02:06:39.913629000 : 8=FIXT.1.19=28835=X49=Coinbase56=24ab46f784d1b20db435b852086e325034=7950=TEST52=20250411-02:06:39.793627369=2262=ecae6588-1a56-49ad-9a18-1bac314fe7a4268=1279=2269=0278=90ef2788-d7f9-46db-b29a-58bb24f25fc883=159758965455=BTC-USD270=3.82271=0.0000000060=20250411-02:06:39.79217958=FILLED10=170
20250411-02:06:40.028097000 : 8=FIXT.1.19=28235=X49=Coinbase56=24ab46f784d1b20db435b852086e325034=8050=TEST52=20250411-02:06:39.908930369=2262=ecae6588-1a56-49ad-9a18-1bac314fe7a4268=1279=0269=183=159758965555=BTC-USD270=3.24271=0.6197183160=20250411-02:06:39.90760340=237=6a1eb48d-6c70-49ef-a7d5-f42d6095125d10=173
20250411-02:06:40.029089000 : 8=FIXT.1.19=32535=X49=Coinbase56=24ab46f784d1b20db435b852086e325034=8150=TEST52=20250411-02:06:39.908939369=2262=ecae6588-1a56-49ad-9a18-1bac314fe7a4268=1279=0269=2278=4d60a78e-b39b-420e-b830-bc0f3f4fdde283=159758965655=BTC-USD270=3.53271=0.6197183160=20250411-02:06:39.90760337=6a1eb48d-6c70-49ef-a7d5-f42d6095125d5797=210=012
20250411-02:06:40.029285000 : 8=FIXT.1.19=28835=X49=Coinbase56=24ab46f784d1b20db435b852086e325034=8250=TEST52=20250411-02:06:39.908942369=2262=ecae6588-1a56-49ad-9a18-1bac314fe7a4268=1279=2269=1278=6a1eb48d-6c70-49ef-a7d5-f42d6095125d83=159758965755=BTC-USD270=3.24271=0.0000000060=20250411-02:06:39.90760358=FILLED10=086
20250411-02:06:40.082282000 : 8=FIXT.1.19=28235=X49=Coinbase56=24ab46f784d1b20db435b852086e325034=8350=TEST52=20250411-02:06:39.963674369=2262=ecae6588-1a56-49ad-9a18-1bac314fe7a4268=1279=0269=083=159758965855=BTC-USD270=3.75271=0.6197183160=20250411-02:06:39.96265440=237=ed85dfb5-6b25-48b8-a212-ad2e03c9761b10=234
20250411-02:06:40.082653000 : 8=FIXT.1.19=32535=X49=Coinbase56=24ab46f784d1b20db435b852086e325034=8450=TEST52=20250411-02:06:39.963680369=2262=ecae6588-1a56-49ad-9a18-1bac314fe7a4268=1279=0269=2278=c5b88ea9-605d-4595-ac52-f7c3f08523ba83=159758965955=BTC-USD270=3.55271=0.6197183160=20250411-02:06:39.96265437=ed85dfb5-6b25-48b8-a212-ad2e03c9761b5797=110=185
20250411-02:06:40.082854000 : 8=FIXT.1.19=28835=X49=Coinbase56=24ab46f784d1b20db435b852086e325034=8550=TEST52=20250411-02:06:39.963684369=2262=ecae6588-1a56-49ad-9a18-1bac314fe7a4268=1279=2269=0278=ed85dfb5-6b25-48b8-a212-ad2e03c9761b83=159758966055=BTC-USD270=3.75271=0.0000000060=20250411-02:06:39.96265458=FILLED10=136
20250411-02:06:40.226942000 : 8=FIXT.1.19=27735=X49=Coinbase56=24ab46f784d1b20db435b852086e325034=8650=TEST52=20250411-02:06:40.107116369=2262=ecae6588-1a56-49ad-9a18-1bac314fe7a4268=1279=0269=083=159758966155=BTC-USD29004=2.208895519560=20250411-02:06:40.10546940=137=8f479d63-fe97-4c94-9559-f01e47851da610=096
20250411-02:06:40.227536000 : 8=FIXT.1.19=32535=X49=Coinbase56=24ab46f784d1b20db435b852086e325034=8750=TEST52=20250411-02:06:40.107126369=2262=ecae6588-1a56-49ad-9a18-1bac314fe7a4268=1279=0269=2278=c5b88ea9-605d-4595-ac52-f7c3f08523ba83=159758966255=BTC-USD270=3.55271=0.6222240960=20250411-02:06:40.10546937=8f479d63-fe97-4c94-9559-f01e47851da65797=110=244
20250411-02:06:40.227734000 : 8=FIXT.1.19=26435=X49=Coinbase56=24ab46f784d1b20db435b852086e325034=8850=TEST52=20250411-02:06:40.107129369=2262=ecae6588-1a56-49ad-9a18-1bac314fe7a4268=1279=2269=0278=8f479d63-fe97-4c94-9559-f01e47851da683=159758966355=BTC-USD60=20250411-02:06:40.10546958=FILLED10=116
20250411-02:06:40.254204000 : 8=FIXT.1.19=27335=X49=Coinbase56=24ab46f784d1b20db435b852086e325034=8950=TEST52=20250411-02:06:40.135503369=2262=ecae6588-1a56-49ad-9a18-1bac314fe7a4268=1279=0269=183=159758966455=BTC-USD271=0.6197183160=20250411-02:06:40.13365840=137=c127583a-2ce2-4426-a686-5963fa69354c10=063
20250411-02:06:40.254432000 : 8=FIXT.1.19=32535=X49=Coinbase56=24ab46f784d1b20db435b852086e325034=9050=TEST52=20250411-02:06:40.135508369=2262=ecae6588-1a56-49ad-9a18-1bac314fe7a4268=1279=0269=2278=4d60a78e-b39b-420e-b830-bc0f3f4fdde283=159758966555=BTC-USD270=3.53271=0.6197183160=20250411-02:06:40.13365837=c127583a-2ce2-4426-a686-5963fa69354c5797=210=048
20250411-02:06:40.254585000 : 8=FIXT.1.19=27935=X49=Coinbase56=24ab46f784d1b20db435b852086e325034=9150=TEST52=20250411-02:06:40.135511369=2262=ecae6588-1a56-49ad-9a18-1bac314fe7a4268=1279=2269=1278=c127583a-2ce2-4426-a686-5963fa69354c83=159758966655=BTC-USD271=0.0000000060=20250411-02:06:40.13365858=FILLED10=220
20250411-02:06:40.282820000 : 8=FIXT.1.19=27735=X49=Coinbase56=24ab46f784d1b20db435b852086e325034=9250=TEST52=20250411-02:06:40.163603369=2262=ecae6588-1a56-49ad-9a18-1bac314fe7a4268=1279=0269=083=159758966755=BTC-USD29004=2.208895519560=20250411-02:06:40.16175640=137=41bbad24-d602-4659-bc8a-eed26fefc99110=096
20250411-02:06:40.283212000 : 8=FIXT.1.19=32535=X49=Coinbase56=24ab46f784d1b20db435b852086e325034=9350=TEST52=20250411-02:06:40.163607369=2262=ecae6588-1a56-49ad-9a18-1bac314fe7a4268=1279=0269=2278=c5b88ea9-605d-4595-ac52-f7c3f08523ba83=159758966855=BTC-USD270=3.55271=0.6222240960=20250411-02:06:40.16175637=41bbad24-d602-4659-bc8a-eed26fefc9915797=110=247
20250411-02:06:40.283436000 : 8=FIXT.1.19=26435=X49=Coinbase56=24ab46f784d1b20db435b852086e325034=9450=TEST52=20250411-02:06:40.163610369=2262=ecae6588-1a56-49ad-9a18-1bac314fe7a4268=1279=2269=0278=41bbad24-d602-4659-bc8a-eed26fefc99183=159758966955=BTC-USD60=20250411-02:06:40.16175658=FILLED10=110
20250411-02:06:40.311445000 : 8=FIXT.1.19=27335=X49=Coinbase56=24ab46f784d1b20db435b852086e325034=9550=TEST52=20250411-02:06:40.192228369=2262=ecae6588-1a56-49ad-9a18-1bac314fe7a4268=1279=0269=183=159758967055=BTC-USD271=0.6197183160=20250411-02:06:40.19118040=137=1fa5517a-b239-411d-b34a-a69680ff0ea510=227
20250411-02:06:40.311794000 : 8=FIXT.1.19=32535=X49=Coinbase56=24ab46f784d1b20db435b852086e325034=9650=TEST52=20250411-02:06:40.192233369=2262=ecae6588-1a56-49ad-9a18-1bac314fe7a4268=1279=0269=2278=4d60a78e-b39b-420e-b830-bc0f3f4fdde283=159758967155=BTC-USD270=3.53271=0.6197183160=20250411-02:06:40.19118037=1fa5517a-b239-411d-b34a-a69680ff0ea55797=210=212
20250411-02:06:40.311963000 : 8=FIXT.1.19=27935=X49=Coinbase56=24ab46f784d1b20db435b852086e325034=9750=TEST52=20250411-02:06:40.192236369=2262=ecae6588-1a56-49ad-9a18-1bac314fe7a4268=1279=2269=1278=1fa5517a-b239-411d-b34a-a69680ff0ea583=159758967255=BTC-USD271=0.0000000060=20250411-02:06:40.19118058=FILLED10=137
20250411-02:06:40.333876000 : 8=FIXT.1.19=28235=X49=Coinbase56=24ab46f784d1b20db435b852086e325034=9850=TEST52=20250411-02:06:40.206067369=2262=ecae6588-1a56-49ad-9a18-1bac314fe7a4268=1279=0269=183=159758967355=BTC-USD270=3.69271=0.6232294660=20250411-02:06:40.20527240=237=be0e8d6f-3669-4cc5-94f3-6b16f58194d510=128
20250411-02:06:40.337470000 : 8=FIXT.1.19=27835=X49=Coinbase56=24ab46f784d1b20db435b852086e325034=9950=TEST52=20250411-02:06:40.206072369=2262=ecae6588-1a56-49ad-9a18-1bac314fe7a4268=1279=0269=1278=be0e8d6f-3669-4cc5-94f3-6b16f58194d583=159758967455=BTC-USD270=3.69271=0.6232294660=20250411-02:06:40.20527210=230
20250411-02:06:41.216445000 : 8=FIXT.1.19=27835=X49=Coinbase56=24ab46f784d1b20db435b852086e325034=10050=TEST52=20250411-02:06:41.077373369=2262=ecae6588-1a56-49ad-9a18-1bac314fe7a4268=1279=0269=083=159758967555=BTC-USD29004=2.208895519560=20250411-02:06:41.07637740=137=d1e28a5b-6178-4d8f-a3c1-1c6582a6d49b10=004
20250411-02:06:41.216832000 : 8=FIXT.1.19=32635=X49=Coinbase56=24ab46f784d1b20db435b852086e325034=10150=TEST52=20250411-02:06:41.077381369=2262=ecae6588-1a56-49ad-9a18-1bac314fe7a4268=1279=0269=2278=c5b88ea9-605d-4595-ac52-f7c3f08523ba83=159758967655=BTC-USD270=3.55271=0.6222240960=20250411-02:06:41.07637737=d1e28a5b-6178-4d8f-a3c1-1c6582a6d49b5797=110=150
20250411-02:06:41.216991000 : 8=FIXT.1.19=26535=X49=Coinbase56=24ab46f784d1b20db435b852086e325034=10250=TEST52=20250411-02:06:41.077384369=2262=ecae6588-1a56-49ad-9a18-1bac314fe7a4268=1279=2269=0278=d1e28a5b-6178-4d8f-a3c1-1c6582a6d49b83=159758967755=BTC-USD60=20250411-02:06:41.07637758=FILLED10=022
20250411-02:06:41.226280000 : 8=FIXT.1.19=27435=X49=Coinbase56=24ab46f784d1b20db435b852086e325034=10350=TEST52=20250411-02:06:41.107075369=2262=ecae6588-1a56-49ad-9a18-1bac314fe7a4268=1279=0269=183=159758967855=BTC-USD271=0.6232294660=20250411-02:06:41.10549840=137=d288ec01-9348-4fb3-9ad6-b9a8d747623b10=002
20250411-02:06:41.226478000 : 8=FIXT.1.19=32635=X49=Coinbase56=24ab46f784d1b20db435b852086e325034=10450=TEST52=20250411-02:06:41.107079369=2262=ecae6588-1a56-49ad-9a18-1bac314fe7a4268=1279=0269=2278=4d60a78e-b39b-420e-b830-bc0f3f4fdde283=159758967955=BTC-USD270=3.53271=0.6232294660=20250411-02:06:41.10549837=d288ec01-9348-4fb3-9ad6-b9a8d747623b5797=210=251
20250411-02:06:41.226637000 : 8=FIXT.1.19=28035=X49=Coinbase56=24ab46f784d1b20db435b852086e325034=10550=TEST52=20250411-02:06:41.107089369=2262=ecae6588-1a56-49ad-9a18-1bac314fe7a4268=1279=2269=1278=d288ec01-9348-4fb3-9ad6-b9a8d747623b83=159758968055=BTC-USD271=0.0000000060=20250411-02:06:41.10549858=FILLED10=158
20250411-02:06:41.400412000 : 8=FIXT.1.19=28235=X49=Coinbase56=24ab46f784d1b20db435b852086e325034=10650=TEST52=20250411-02:06:41.279764369=2262=ecae6588-1a56-49ad-9a18-1bac314fe7a4268=1279=0269=083=159758968155=BTC-USD270=3.8271=0.6232294660=20250411-02:06:41.27875240=237=0f3b8062-ce7b-4da9-abac-71d95adfbfdd10=234
20250411-02:06:41.400758000 : 8=FIXT.1.19=32635=X49=Coinbase56=24ab46f784d1b20db435b852086e325034=10750=TEST52=20250411-02:06:41.279847369=2262=ecae6588-1a56-49ad-9a18-1bac314fe7a4268=1279=0269=2278=c5b88ea9-605d-4595-ac52-f7c3f08523ba83=159758968255=BTC-USD270=3.55271=0.6232294660=20250411-02:06:41.27875237=0f3b8062-ce7b-4da9-abac-71d95adfbfdd5797=110=243
20250411-02:06:41.400887000 : 8=FIXT.1.19=28835=X49=Coinbase56=24ab46f784d1b20db435b852086e325034=10850=TEST52=20250411-02:06:41.279854369=2262=ecae6588-1a56-49ad-9a18-1bac314fe7a4268=1279=2269=0278=0f3b8062-ce7b-4da9-abac-71d95adfbfdd83=159758968355=BTC-USD270=3.8271=0.0000000060=20250411-02:06:41.27875258=FILLED10=146
20250411-02:06:41.455758000 : 8=FIXT.1.19=28335=X49=Coinbase56=24ab46f784d1b20db435b852086e325034=10950=TEST52=20250411-02:06:41.336823369=2262=ecae6588-1a56-49ad-9a18-1bac314fe7a4268=1279=0269=183=159758968455=BTC-USD270=3.21271=0.6232294660=20250411-02:06:41.33511440=237=6f981aa8-5762-4d04-a750-252818262e0a10=202
20250411-02:06:41.456223000 : 8=FIXT.1.19=32635=X49=Coinbase56=24ab46f784d1b20db435b852086e325034=11050=TEST52=20250411-02:06:41.336833369=2262=ecae6588-1a56-49ad-9a18-1bac314fe7a4268=1279=0269=2278=4d60a78e-b39b-420e-b830-bc0f3f4fdde283=159758968555=BTC-USD270=3.53271=0.6232294660=20250411-02:06:41.33511437=6f981aa8-5762-4d04-a750-252818262e0a5797=210=027
20250411-02:06:41.456366000 : 8=FIXT.1.19=28935=X49=Coinbase56=24ab46f784d1b20db435b852086e325034=11150=TEST52=20250411-02:06:41.336838369=2262=ecae6588-1a56-49ad-9a18-1bac314fe7a4268=1279=2269=1278=6f981aa8-5762-4d04-a750-252818262e0a83=159758968655=BTC-USD270=3.21271=0.0000000060=20250411-02:06:41.33511458=FILLED10=111
20250411-02:06:41.712887000 : 8=FIXT.1.19=27835=X49=Coinbase56=24ab46f784d1b20db435b852086e325034=11250=TEST52=20250411-02:06:41.593777369=2262=ecae6588-1a56-49ad-9a18-1bac314fe7a4268=1279=0269=083=159758968755=BTC-USD29004=2.208895519560=20250411-02:06:41.59187040=137=9c2f5d1d-01e6-425e-8f79-38efe0f9c5a610=087
20250411-02:06:41.713497000 : 8=FIXT.1.19=32635=X49=Coinbase56=24ab46f784d1b20db435b852086e325034=11350=TEST52=20250411-02:06:41.593784369=2262=ecae6588-1a56-49ad-9a18-1bac314fe7a4268=1279=0269=2278=c5b88ea9-605d-4595-ac52-f7c3f08523ba83=159758968855=BTC-USD270=3.55271=0.6222240960=20250411-02:06:41.59187037=9c2f5d1d-01e6-425e-8f79-38efe0f9c5a65797=110=232
20250411-02:06:41.713677000 : 8=FIXT.1.19=26535=X49=Coinbase56=24ab46f784d1b20db435b852086e325034=11450=TEST52=20250411-02:06:41.593803369=2262=ecae6588-1a56-49ad-9a18-1bac314fe7a4268=1279=2269=0278=9c2f5d1d-01e6-425e-8f79-38efe0f9c5a683=159758968955=BTC-USD60=20250411-02:06:41.59187058=FILLED10=093
20250411-02:06:41.740101000 : 8=FIXT.1.19=27435=X49=Coinbase56=24ab46f784d1b20db435b852086e325034=11550=TEST52=20250411-02:06:41.621157369=2262=ecae6588-1a56-49ad-9a18-1bac314fe7a4268=1279=0269=183=159758969055=BTC-USD271=0.6232294660=20250411-02:06:41.61924640=137=b221f7f0-c56c-43c9-a3ba-2485511a3c4110=220
20250411-02:06:41.740416000 : 8=FIXT.1.19=32635=X49=Coinbase56=24ab46f784d1b20db435b852086e325034=11650=TEST52=20250411-02:06:41.621163369=2262=ecae6588-1a56-49ad-9a18-1bac314fe7a4268=1279=0269=2278=4d60a78e-b39b-420e-b830-bc0f3f4fdde283=159758969155=BTC-USD270=3.53271=0.6232294660=20250411-02:06:41.61924637=b221f7f0-c56c-43c9-a3ba-2485511a3c415797=210=206
20250411-02:06:41.740626000 : 8=FIXT.1.19=28035=X49=Coinbase56=24ab46f784d1b20db435b852086e325034=11750=TEST52=20250411-02:06:41.621165369=2262=ecae6588-1a56-49ad-9a18-1bac314fe7a4268=1279=2269=1278=b221f7f0-c56c-43c9-a3ba-2485511a3c4183=159758969255=BTC-USD271=0.0000000060=20250411-02:06:41.61924658=FILLED10=123
20250411-02:06:41.856912000 : 8=FIXT.1.19=28335=X49=Coinbase56=24ab46f784d1b20db435b852086e325034=11850=TEST52=20250411-02:06:41.738159369=2262=ecae6588-1a56-49ad-9a18-1bac314fe7a4268=1279=0269=083=159758969355=BTC-USD270=3.79271=0.6232294660=20250411-02:06:41.73642140=237=889c866b-7f7c-4f94-8c81-162d04305e6a10=094
20250411-02:06:41.857486000 : 8=FIXT.1.19=32635=X49=Coinbase56=24ab46f784d1b20db435b852086e325034=11950=TEST52=20250411-02:06:41.738167369=2262=ecae6588-1a56-49ad-9a18-1bac314fe7a4268=1279=0269=2278=c5b88ea9-605d-4595-ac52-f7c3f08523ba83=159758969455=BTC-USD270=3.55271=0.6232294660=20250411-02:06:41.73642137=889c866b-7f7c-4f94-8c81-162d04305e6a5797=110=043
20250411-02:06:41.857785000 : 8=FIXT.1.19=28935=X49=Coinbase56=24ab46f784d1b20db435b852086e325034=12050=TEST52=20250411-02:06:41.738169369=2262=ecae6588-1a56-49ad-9a18-1bac314fe7a4268=1279=2269=0278=889c866b-7f7c-4f94-8c81-162d04305e6a83=159758969555=BTC-USD270=3.79271=0.0000000060=20250411-02:06:41.73642158=FILLED10=254
20250411-02:06:41.913199000 : 8=FIXT.1.19=28235=X49=Coinbase56=24ab46f784d1b20db435b852086e325034=12150=TEST52=20250411-02:06:41.794138369=2262=ecae6588-1a56-49ad-9a18-1bac314fe7a4268=1279=0269=183=159758969655=BTC-USD270=3.2271=0.6232294660=20250411-02:06:41.79276640=237=a7b485b2-c312-42f3-9951-907bf0660fca10=062
20250411-02:06:41.915341000 : 8=FIXT.1.19=32635=X49=Coinbase56=24ab46f784d1b20db435b852086e325034=12250=TEST52=20250411-02:06:41.794146369=2262=ecae6588-1a56-49ad-9a18-1bac314fe7a4268=1279=0269=2278=4d60a78e-b39b-420e-b830-bc0f3f4fdde283=159758969755=BTC-USD270=3.53271=0.6232294660=20250411-02:06:41.79276637=a7b485b2-c312-42f3-9951-907bf0660fca5797=210=200
20250411-02:06:41.915544000 : 8=FIXT.1.19=28835=X49=Coinbase56=24ab46f784d1b20db435b852086e325034=12350=TEST52=20250411-02:06:41.794149369=2262=ecae6588-1a56-49ad-9a18-1bac314fe7a4268=1279=2269=1278=a7b485b2-c312-42f3-9951-907bf0660fca83=159758969855=BTC-USD270=3.2271=0.0000000060=20250411-02:06:41.79276658=FILLED10=232
20250411-02:06:42.054391000 : 8=FIXT.1.19=27835=X49=Coinbase56=24ab46f784d1b20db435b852086e325034=12450=TEST52=20250411-02:06:41.935164369=2262=ecae6588-1a56-49ad-9a18-1bac314fe7a4268=1279=0269=083=159758969955=BTC-USD29004=2.208895519560=20250411-02:06:41.93394540=137=449cdc68-69a8-40fd-ac7a-108d1d7c2e9a10=121
20250411-02:06:42.055238000 : 8=FIXT.1.19=32635=X49=Coinbase56=24ab46f784d1b20db435b852086e325034=12550=TEST52=20250411-02:06:41.935175369=2262=ecae6588-1a56-49ad-9a18-1bac314fe7a4268=1279=0269=2278=c5b88ea9-605d-4595-ac52-f7c3f08523ba83=159758970055=BTC-USD270=3.55271=0.6222240960=20250411-02:06:41.93394537=449cdc68-69a8-40fd-ac7a-108d1d7c2e9a5797=110=252
20250411-02:06:42.055436000 : 8=FIXT.1.19=26535=X49=Coinbase56=24ab46f784d1b20db435b852086e325034=12650=TEST52=20250411-02:06:41.935178369=2262=ecae6588-1a56-49ad-9a18-1bac314fe7a4268=1279=2269=0278=449cdc68-69a8-40fd-ac7a-108d1d7c2e9a83=159758970155=BTC-USD60=20250411-02:06:41.93394558=FILLED10=124
20250411-02:06:42.082710000 : 8=FIXT.1.19=27435=X49=Coinbase56=24ab46f784d1b20db435b852086e325034=12750=TEST52=20250411-02:06:41.963544369=2262=ecae6588-1a56-49ad-9a18-1bac314fe7a4268=1279=0269=183=159758970255=BTC-USD271=0.6232294660=20250411-02:06:41.96217040=137=188a6323-2f93-4767-89bf-ccfff50583d010=218
20250411-02:06:42.083167000 : 8=FIXT.1.19=32635=X49=Coinbase56=24ab46f784d1b20db435b852086e325034=12850=TEST52=20250411-02:06:41.963552369=2262=ecae6588-1a56-49ad-9a18-1bac314fe7a4268=1279=0269=2278=4d60a78e-b39b-420e-b830-bc0f3f4fdde283=159758970355=BTC-USD270=3.53271=0.6232294660=20250411-02:06:41.96217037=188a6323-2f93-4767-89bf-ccfff50583d05797=210=206
20250411-02:06:42.083357000 : 8=FIXT.1.19=28035=X49=Coinbase56=24ab46f784d1b20db435b852086e325034=12950=TEST52=20250411-02:06:41.963555369=2262=ecae6588-1a56-49ad-9a18-1bac314fe7a4268=1279=2269=1278=188a6323-2f93-4767-89bf-ccfff50583d083=159758970455=BTC-USD271=0.0000000060=20250411-02:06:41.96217058=FILLED10=124
20250411-02:06:42.156131000 : 8=FIXT.1.19=28335=X49=Coinbase56=24ab46f784d1b20db435b852086e325034=13050=TEST52=20250411-02:06:42.036022369=2262=ecae6588-1a56-49ad-9a18-1bac314fe7a4268=1279=0269=183=159758970555=BTC-USD270=3.62271=0.6232294660=20250411-02:06:42.03444240=237=4623b8cd-ec9c-4818-9c21-abce854b641f10=225
20250411-02:06:42.156701000 : 8=FIXT.1.19=27935=X49=Coinbase56=24ab46f784d1b20db435b852086e325034=13150=TEST52=20250411-02:06:42.036027369=2262=ecae6588-1a56-49ad-9a18-1bac314fe7a4268=1279=0269=1278=4623b8cd-ec9c-4818-9c21-abce854b641f83=159758970655=BTC-USD270=3.62271=0.6232294660=20250411-02:06:42.03444210=080
20250411-02:06:42.342365000 : 8=FIXT.1.19=27835=X49=Coinbase56=24ab46f784d1b20db435b852086e325034=13250=TEST52=20250411-02:06:42.220357369=2262=ecae6588-1a56-49ad-9a18-1bac314fe7a4268=1279=0269=083=159758970755=BTC-USD29004=2.208895519560=20250411-02:06:42.21902440=137=961d42b9-9ff1-4784-a903-3a6b5535611910=014
20250411-02:06:42.342939000 : 8=FIXT.1.19=32635=X49=Coinbase56=24ab46f784d1b20db435b852086e325034=13350=TEST52=20250411-02:06:42.220365369=2262=ecae6588-1a56-49ad-9a18-1bac314fe7a4268=1279=0269=2278=c5b88ea9-605d-4595-ac52-f7c3f08523ba83=159758970855=BTC-USD270=3.55271=0.6222240960=20250411-02:06:42.21902437=961d42b9-9ff1-4784-a903-3a6b553561195797=110=160
20250411-02:06:42.343213000 : 8=FIXT.1.19=26535=X49=Coinbase56=24ab46f784d1b20db435b852086e325034=13450=TEST52=20250411-02:06:42.220369369=2262=ecae6588-1a56-49ad-9a18-1bac314fe7a4268=1279=2269=0278=961d42b9-9ff1-4784-a903-3a6b5535611983=159758970955=BTC-USD60=20250411-02:06:42.21902458=FILLED10=033
20250411-02:06:42.369805000 : 8=FIXT.1.19=27435=X49=Coinbase56=24ab46f784d1b20db435b852086e325034=13550=TEST52=20250411-02:06:42.250440369=2262=ecae6588-1a56-49ad-9a18-1bac314fe7a4268=1279=0269=183=159758971055=BTC-USD271=0.6232294660=20250411-02:06:42.24882540=137=51cf73d3-bfb2-4ef3-a11a-905d9cce19d010=158
20250411-02:06:42.370366000 : 8=FIXT.1.19=32635=X49=Coinbase56=24ab46f784d1b20db435b852086e325034=13650=TEST52=20250411-02:06:42.250448369=2262=ecae6588-1a56-49ad-9a18-1bac314fe7a4268=1279=0269=2278=4d60a78e-b39b-420e-b830-bc0f3f4fdde283=159758971155=BTC-USD270=3.53271=0.6232294660=20250411-02:06:42.24882537=51cf73d3-bfb2-4ef3-a11a-905d9cce19d05797=210=155
20250411-02:06:42.370532000 : 8=FIXT.1.19=28035=X49=Coinbase56=24ab46f784d1b20db435b852086e325034=13750=TEST52=20250411-02:06:42.250452369=2262=ecae6588-1a56-49ad-9a18-1bac314fe7a4268=1279=2269=1278=51cf73d3-bfb2-4ef3-a11a-905d9cce19d083=159758971255=BTC-USD271=0.0000000060=20250411-02:06:42.24882558=FILLED10=065
20250411-02:06:42.751087000 : 8=FIXT.1.19=28335=X49=Coinbase56=24ab46f784d1b20db435b852086e325034=13850=TEST52=20250411-02:06:42.536600369=2262=ecae6588-1a56-49ad-9a18-1bac314fe7a4268=1279=0269=183=159758971355=BTC-USD270=3.23271=0.6232294660=20250411-02:06:42.53551340=237=4a0db00f-e14a-4911-bc1e-4f1d046cf20110=197
20250411-02:06:42.751732000 : 8=FIXT.1.19=32635=X49=Coinbase56=24ab46f784d1b20db435b852086e325034=13950=TEST52=20250411-02:06:42.536608369=2262=ecae6588-1a56-49ad-9a18-1bac314fe7a4268=1279=0269=2278=4d60a78e-b39b-420e-b830-bc0f3f4fdde283=159758971455=BTC-USD270=3.53271=0.6232294660=20250411-02:06:42.53551337=4a0db00f-e14a-4911-bc1e-4f1d046cf2015797=210=036
20250411-02:06:42.751926000 : 8=FIXT.1.19=28935=X49=Coinbase56=24ab46f784d1b20db435b852086e325034=14050=TEST52=20250411-02:06:42.536649369=2262=ecae6588-1a56-49ad-9a18-1bac314fe7a4268=1279=2269=1278=4a0db00f-e14a-4911-bc1e-4f1d046cf20183=159758971555=BTC-USD270=3.23271=0.0000000060=20250411-02:06:42.53551358=FILLED10=113
20250411-02:06:42.752104000 : 8=FIXT.1.19=28335=X49=Coinbase56=24ab46f784d1b20db435b852086e325034=14150=TEST52=20250411-02:06:42.592135369=2262=ecae6588-1a56-49ad-9a18-1bac314fe7a4268=1279=0269=083=159758971655=BTC-USD270=3.88271=0.6232294660=20250411-02:06:42.59107340=237=771f11e0-3fda-4b5a-98ee-b597b8f2783510=218
20250411-02:06:42.752260000 : 8=FIXT.1.19=32635=X49=Coinbase56=24ab46f784d1b20db435b852086e325034=14250=TEST52=20250411-02:06:42.592144369=2262=ecae6588-1a56-49ad-9a18-1bac314fe7a4268=1279=0269=2278=c5b88ea9-605d-4595-ac52-f7c3f08523ba83=159758971755=BTC-USD270=3.55271=0.6232294660=20250411-02:06:42.59107337=771f11e0-3fda-4b5a-98ee-b597b8f278355797=110=168
20250411-02:06:42.752473000 : 8=FIXT.1.19=28935=X49=Coinbase56=24ab46f784d1b20db435b852086e325034=14350=TEST52=20250411-02:06:42.592147369=2262=ecae6588-1a56-49ad-9a18-1bac314fe7a4268=1279=2269=0278=771f11e0-3fda-4b5a-98ee-b597b8f2783583=159758971855=BTC-USD270=3.88271=0.0000000060=20250411-02:06:42.59107358=FILLED10=133
20250411-02:06:42.856039000 : 8=FIXT.1.19=27835=X49=Coinbase56=24ab46f784d1b20db435b852086e325034=14450=TEST52=20250411-02:06:42.735327369=2262=ecae6588-1a56-49ad-9a18-1bac314fe7a4268=1279=0269=083=159758971955=BTC-USD29004=2.208895519560=20250411-02:06:42.73408040=137=85f24923-7aa1-4176-af86-df846dcaf25210=221
20250411-02:06:42.856723000 : 8=FIXT.1.19=32635=X49=Coinbase56=24ab46f784d1b20db435b852086e325034=14550=TEST52=20250411-02:06:42.735335369=2262=ecae6588-1a56-49ad-9a18-1bac314fe7a4268=1279=0269=2278=c5b88ea9-605d-4595-ac52-f7c3f08523ba83=159758972055=BTC-USD270=3.55271=0.6222240960=20250411-02:06:42.73408037=85f24923-7aa1-4176-af86-df846dcaf2525797=110=102
20250411-02:06:42.856999000 : 8=FIXT.1.19=26535=X49=Coinbase56=24ab46f784d1b20db435b852086e325034=14650=TEST52=20250411-02:06:42.735338369=2262=ecae6588-1a56-49ad-9a18-1bac314fe7a4268=1279=2269=0278=85f24923-7aa1-4176-af86-df846dcaf25283=159758972155=BTC-USD60=20250411-02:06:42.73408058=FILLED10=230
20250411-02:06:42.883565000 : 8=FIXT.1.19=27435=X49=Coinbase56=24ab46f784d1b20db435b852086e325034=14750=TEST52=20250411-02:06:42.763523369=2262=ecae6588-1a56-49ad-9a18-1bac314fe7a4268=1279=0269=183=159758972255=BTC-USD271=0.6197183160=20250411-02:06:42.76209640=137=919296d8-5c99-4f49-a0cb-9e1985a479cb10=242
20250411-02:06:42.884017000 : 8=FIXT.1.19=32635=X49=Coinbase56=24ab46f784d1b20db435b852086e325034=14850=TEST52=20250411-02:06:42.763533369=2262=ecae6588-1a56-49ad-9a18-1bac314fe7a4268=1279=0269=2278=4d60a78e-b39b-420e-b830-bc0f3f4fdde283=159758972355=BTC-USD270=3.53271=0.6197183160=20250411-02:06:42.76209637=919296d8-5c99-4f49-a0cb-9e1985a479cb5797=210=232
20250411-02:06:42.884213000 : 8=FIXT.1.19=28035=X49=Coinbase56=24ab46f784d1b20db435b852086e325034=14950=TEST52=20250411-02:06:42.763537369=2262=ecae6588-1a56-49ad-9a18-1bac314fe7a4268=1279=2269=1278=919296d8-5c99-4f49-a0cb-9e1985a479cb83=159758972455=BTC-USD271=0.0000000060=20250411-02:06:42.76209658=FILLED10=149
20250411-02:06:42.955662000 : 8=FIXT.1.19=91835=W49=Coinbase56=24ab46f784d1b20db435b852086e325034=15050=TEST52=20250411-02:06:42.836730369=2262=ecae6588-1a56-49ad-9a18-1bac314fe7a483=1597589724893=N55=BTC-USD1682=full_trading268=10269=0278=4d60a78e-b39b-420e-b830-bc0f3f4fdde2270=3.53271=254848.24856783269=0278=9d9353ab-229f-423a-89a3-c52a46543bc9270=3.53271=18127.30103418269=0278=52ec2402-f9eb-4d3c-bb2c-2989c3dbef3d270=3.52271=0.62322946269=0278=6ebd3f80-f4ad-47ff-997e-59fd299d54e3270=3.49271=0.61971831269=0278=f5fc5e68-a52c-44d3-87ef-3785312f4782270=3.48271=0.29310888269=0278=639a9412-904d-4153-b3cd-d1bc31abf55e270=3.48271=0.61971831269=0278=dcccb470-c535-433a-9198-4e2b4c26d99d270=3.47271=0.29311495269=0278=f05d9766-970d-44ca-aa4d-e8b2720bbda8270=3.46271=0.29026870269=0278=f47d23a4-1e65-48fa-a4d4-5a58ad6fe368270=3.45271=0.62322946269=0278=2c4d7d5a-33aa-4058-b546-480b6a2168a4270=3.44271=0.2982857710=026
20250411-02:06:42.958432000 : 8=FIXT.1.19=14135=334=349=24ab46f784d1b20db435b852086e325052=20250411-02:06:42.95856=Coinbase45=15058=Tag appears more than once371=269372=W373=1310=254
20250411-02:06:42.958585000 : 8=FIXT.1.19=90935=W49=Coinbase56=24ab46f784d1b20db435b852086e325034=15150=TEST52=20250411-02:06:42.836972369=2262=ecae6588-1a56-49ad-9a18-1bac314fe7a483=1597589724893=N55=BTC-USD1682=full_trading268=10269=0278=161a934f-49f1-47a8-adc9-3a05e681c4cd270=3.44271=0.61971831269=0278=3b351cd8-be89-4ead-a9a9-f237840e05cc270=3.44271=0.62322946269=0278=f364a6bb-935a-4143-95a3-2c59ee41a411270=3.44271=0.61971831269=0278=dbf49fc5-5a5a-4eb7-9f01-46216b5b888b270=3.43271=0.62322946269=0278=37dbcf16-0b3d-4f67-bc90-e36268b99e0e270=3.42271=0.30270947269=0278=4c63c0b7-30e0-4ef1-931f-0090359f978e270=3.41271=0.32158962269=0278=d6b4aa4e-d588-4c96-83aa-8e8d8accb1a4270=3.41271=0.30121104269=0278=e8b3d8da-1663-413c-b7fb-6aba23b01440270=3.39271=0.31006477269=0278=bcbe17c3-9059-4c38-8ab8-8e78f1ef9062270=3.38271=0.32617981269=0278=57bb77fd-337f-49bc-a56f-a4e2dff851ee270=3.37271=0.3107167610=101
20250411-02:06:42.959407000 : 8=FIXT.1.19=14135=334=449=24ab46f784d1b20db435b852086e325052=20250411-02:06:42.95956=Coinbase45=15158=Tag appears more than once371=269372=W373=1310=001
20250411-02:06:42.959492000 : 8=FIXT.1.19=90935=W49=Coinbase56=24ab46f784d1b20db435b852086e325034=15250=TEST52=20250411-02:06:42.837222369=2262=ecae6588-1a56-49ad-9a18-1bac314fe7a483=1597589724893=N55=BTC-USD1682=full_trading268=10269=0278=ded4b51d-349f-4726-8379-6761a3576bb6270=3.33271=0.31560513269=0278=ff7aff09-38de-47ac-a3cb-9beacb0b9ad8270=3.33271=0.30682342269=0278=d1da558a-e9d2-4e11-b26e-1eb80a1a34c5270=3.32271=0.31700685269=0278=9ee34527-d4d8-4659-b2ea-cdff3dc4a8fa270=3.32271=0.32181951269=0278=7abf2220-0421-460f-9dbb-14c41564e41a270=3.32271=0.31308436269=0278=69634ec5-f71a-4990-b56d-13c3069a455a270=3.31271=0.32329458269=0278=2f333c17-a386-4d52-8ff1-eadcb99bc22f270=3.31271=0.31999220269=0278=f02efc37-0b1e-470b-99ef-e31012887d73270=3.30271=0.32771570269=0278=6d430950-8078-4987-8995-e581564e368d270=3.29271=0.30702763269=0278=841f895a-cd2d-4082-9a37-b50fc19e35bf270=3.28271=0.3261080110=137
20250411-02:06:42.960390000 : 8=FIXT.1.19=14135=334=549=24ab46f784d1b20db435b852086e325052=20250411-02:06:42.95956=Coinbase45=15258=Tag appears more than once371=269372=W373=1310=003
20250411-02:06:42.960547000 : 8=FIXT.1.19=90935=W49=Coinbase56=24ab46f784d1b20db435b852086e325034=15350=TEST52=20250411-02:06:42.837472369=2262=ecae6588-1a56-49ad-9a18-1bac314fe7a483=1597589724893=N55=BTC-USD1682=full_trading268=10269=0278=3cf93093-e42b-4c24-95ea-c367d96427fe270=3.27271=0.33588654269=0278=f29c94bc-d1c2-4145-97b0-ecb77d81a8bf270=3.27271=0.31661408269=0278=d208c4fb-56c6-4911-85c9-77b68a5ba6ab270=3.25271=0.30961623269=0278=e88796ff-68c8-4463-914b-46e09fbaf639270=3.25271=0.33589845269=0278=06f345fb-0292-45fc-8237-9ad1a84b541c270=3.24271=0.31528507269=0278=fa20c2c7-df80-4941-9a9c-a6ef2e579480270=3.23271=0.33432448269=0278=a833d230-a749-4bf4-823e-93adc40b773d270=3.23271=0.31165878269=0278=2abb6e15-b9cd-415b-8c9b-99a61c750310270=3.22271=0.32048714269=0278=ec44a6d8-ae5f-4809-89d7-0f7a3adac547270=3.21271=0.33230954269=0278=9cf61c67-c4fc-4bac-92fd-d4e2b56248aa270=3.21271=0.3358395110=116
20250411-02:06:42.961184000 : 8=FIXT.1.19=14135=334=649=24ab46f784d1b20db435b852086e325052=20250411-02:06:42.96056=Coinbase45=15358=Tag appears more than once371=269372=W373=1310=253
20250411-02:06:42.961275000 : 8=FIXT.1.19=90935=W49=Coinbase56=24ab46f784d1b20db435b852086e325034=15450=TEST52=20250411-02:06:42.837722369=2262=ecae6588-1a56-49ad-9a18-1bac314fe7a483=1597589724893=N55=BTC-USD1682=full_trading268=10269=0278=210b2518-bb42-461a-9c7e-b4e04c5ffcc6270=3.21271=0.32669007269=0278=2e3fa1b2-20f1-4694-9be4-322040b75152270=3.21271=0.32907979269=0278=05dd5607-92c9-4296-8cdc-27cdff004dea270=3.21271=0.32776075269=0278=87944de7-a5f1-4033-a3d8-cbc10f3a5232270=3.20271=0.32225170269=0278=30f6bb59-2469-4e6d-8fa5-13666373901f270=3.19271=0.31386496269=0278=6a5d2852-7ddc-456e-acb5-bfadcc0c1360270=3.19271=0.32157390269=0278=5d00d8a2-5aea-4836-ba19-74fe67116df8270=3.18271=0.32651049269=0278=acc71746-3591-4dde-a7e2-c2795d0ad125270=3.17271=0.31577131269=0278=13982796-c2a8-4740-95e2-5aca0fdfd8bb270=3.16271=0.33021170269=0278=9f2f0737-661e-43d7-89f9-959ed5e08306270=3.16271=0.3308207510=087
20250411-02:06:42.961857000 : 8=FIXT.1.19=14135=334=749=24ab46f784d1b20db435b852086e325052=20250411-02:06:42.96156=Coinbase45=15458=Tag appears more than once371=269372=W373=1310=000
20250411-02:06:42.961949000 : 8=FIXT.1.19=91035=W49=Coinbase56=24ab46f784d1b20db435b852086e325034=15550=TEST52=20250411-02:06:42.837972369=2262=ecae6588-1a56-49ad-9a18-1bac314fe7a483=1597589724893=N55=BTC-USD1682=full_trading268=10269=0278=7e0e2d14-fa77-4978-8cae-d9660fd13e6d270=3.16271=0.32014975269=0278=82826a7d-848c-4516-a7b6-5ec6881609a8270=2.00271=10.00000000269=0278=590048d5-ee44-49dc-b66d-1a692e055133270=1.94271=0.51546392269=0278=22bdda11-16cd-488b-9fa9-da098dad543e270=1.94271=0.51546392269=0278=d356ef8b-596e-47e7-bf90-cc015b85fc57270=1.93271=0.52331606269=0278=aa8d48bc-97fb-4d00-b923-66d37cc8c66a270=1.93271=0.52331606269=0278=7d51dcb4-a7f8-4cca-b2d0-e902403d1b9f270=1.93271=0.52331606269=0278=f7680950-3af2-4723-a6e4-5cbd528ca900270=1.93271=0.52331606269=0278=fdeff994-4866-47af-9dde-a25947a26606270=1.93271=0.52331606269=0278=65e7e2bb-023d-4936-bb4e-ff7625ba7264270=1.93271=0.5233160610=071
20250411-02:06:42.962654000 : 8=FIXT.1.19=14135=334=849=24ab46f784d1b20db435b852086e325052=20250411-02:06:42.96256=Coinbase45=15558=Tag appears more than once371=269372=W373=1310=003
20250411-02:06:42.962738000 : 8=FIXT.1.19=90935=W49=Coinbase56=24ab46f784d1b20db435b852086e325034=15650=TEST52=20250411-02:06:42.838222369=2262=ecae6588-1a56-49ad-9a18-1bac314fe7a483=1597589724893=N55=BTC-USD1682=full_trading268=10269=0278=53732639-572c-4cd5-b61e-e4f534d1d540270=1.93271=0.52331606269=0278=24da8927-1dd1-468b-9437-ff366f5bfa11270=1.93271=0.52331606269=0278=baa5862c-41e8-458c-83d3-c095bb68ed17270=1.93271=0.52331606269=0278=92a3c3e3-7afe-4d02-a0d8-96f512b63bb7270=1.93271=0.52331606269=0278=9d2a564e-f178-4966-9baf-5814a1c1686b270=1.93271=0.52331606269=0278=f9e6b978-87f6-4397-8d82-07cf698c123f270=1.93271=0.52331606269=0278=3e64b388-13d3-441d-b241-aa8dd6fe55e6270=1.93271=0.52331606269=0278=60300433-87b0-4031-bb1e-12cf9d773d3f270=1.93271=0.52331606269=0278=1bdd5f5a-1d99-4eed-af09-c187bcbbd2d8270=1.93271=0.52331606269=0278=4ed6f6b9-77fb-4255-a188-f243dd0cdb3c270=1.93271=0.5233160610=072
20250411-02:06:42.963525000 : 8=FIXT.1.19=14135=334=949=24ab46f784d1b20db435b852086e325052=20250411-02:06:42.96356=Coinbase45=15658=Tag appears more than once371=269372=W373=1310=006
20250411-02:06:42.963625000 : 8=FIXT.1.19=90935=W49=Coinbase56=24ab46f784d1b20db435b852086e325034=15750=TEST52=20250411-02:06:42.838472369=2262=ecae6588-1a56-49ad-9a18-1bac314fe7a483=1597589724893=N55=BTC-USD1682=full_trading268=10269=0278=9ad1fc18-5a38-4edb-ac5c-6ac826a8a846270=1.93271=0.52331606269=0278=1c218c8c-baea-4a1f-838e-4a3a94b468e1270=1.93271=0.52331606269=0278=fd70f5e2-d2c9-472a-ab40-a775afafd73d270=1.93271=0.52331606269=0278=96f5e3a5-1c2a-4db6-a3fb-fd1f13d5d559270=1.93271=0.52331606269=0278=4a015a4c-490a-4c40-974f-9dfb7feb335d270=1.93271=0.52331606269=0278=d919363e-2c54-404f-bc0b-063e2f12bec4270=1.93271=0.52331606269=0278=d4636d6c-85c6-4ac9-9afb-70ca636f4ad4270=1.93271=0.52331606269=0278=bda09690-f345-4c33-ae8b-e8c78da11b5a270=1.93271=0.52331606269=0278=1a81ae10-b700-42a0-89a3-7d7a3eea0ebb270=1.93271=0.52331606269=0278=1ace5afa-e550-4abf-a458-52e46e1b54f0270=1.93271=0.5233160610=120
20250411-02:06:42.964801000 : 8=FIXT.1.19=14235=334=1049=24ab46f784d1b20db435b852086e325052=20250411-02:06:42.96456=Coinbase45=15758=Tag appears more than once371=269372=W373=1310=049
20250411-02:06:42.975066000 : 8=FIXT.1.19=90935=W49=Coinbase56=24ab46f784d1b20db435b852086e325034=15850=TEST52=20250411-02:06:42.838722369=2262=ecae6588-1a56-49ad-9a18-1bac314fe7a483=1597589724893=N55=BTC-USD1682=full_trading268=10269=0278=2332d1c9-67e7-457a-abfe-f5e9a8c2ea05270=1.93271=0.52331606269=0278=6afa1f19-0ec5-49fd-8b74-06a12a6c5ca9270=1.93271=0.52331606269=0278=3fa3413d-c26c-472f-9cc5-da1c48935c63270=1.93271=0.52331606269=0278=3f9e43c4-2e62-4d51-b4cb-ad207c693331270=1.93271=0.52331606269=0278=29e8bfcf-c764-4f7e-997d-09abf72bbc00270=1.93271=0.52331606269=0278=cf3e8b26-09ae-4dfb-9b84-b12a7e199a5a270=1.93271=0.52331606269=0278=08db3e51-e927-47d3-a9dd-2f887c58dc85270=1.93271=0.52331606269=0278=353ae741-9473-4cc5-9ab7-7e5de8ae55d0270=1.93271=0.52331606269=0278=4d037208-2072-480f-98ac-7be9c24f18f4270=1.93271=0.52331606269=0278=b598f678-da6e-4c01-90ed-d702c42f8a65270=1.93271=0.5233160610=254
20250411-02:06:42.975925000 : 8=FIXT.1.19=14235=334=1149=24ab46f784d1b20db435b852086e325052=20250411-02:06:42.97556=Coinbase45=15858=Tag appears more than once371=269372=W373=1310=053
20250411-02:06:42.976019000 : 8=FIXT.1.19=90935=W49=Coinbase56=24ab46f784d1b20db435b852086e325034=15950=TEST52=20250411-02:06:42.838972369=2262=ecae6588-1a56-49ad-9a18-1bac314fe7a483=1597589724893=N55=BTC-USD1682=full_trading268=10269=0278=5f69b1a0-b5d1-4715-9be1-9bdf008d97d7270=1.93271=0.52331606269=0278=ef063d15-248a-4eae-97f4-278be5106d80270=1.93271=0.52331606269=0278=f8b20207-84bc-44e9-a2fe-9ad775e2ecb1270=1.93271=0.52331606269=0278=75bce2b7-bc58-4479-8bfb-144f88f2262b270=1.93271=0.52331606269=0278=1f6e2a79-8b10-4a7f-89de-0f1fa03692c7270=1.93271=0.52331606269=0278=d1b80bf5-9b17-44b4-9577-6fe71170b578270=1.93271=0.52331606269=0278=b891e26a-c20c-4fce-ba1c-487fe139a4cc270=1.93271=0.52331606269=0278=5d06d3f6-3189-4394-b3c5-6a2bda14b6d1270=1.93271=0.52331606269=0278=e5791c0f-3937-4a66-9b98-26f79a3891be270=1.93271=0.52331606269=0278=c62591c6-7dfa-46a7-8f20-6a5f22804999270=1.93271=0.5233160610=013
20250411-02:06:42.976992000 : 8=FIXT.1.19=14235=334=1249=24ab46f784d1b20db435b852086e325052=20250411-02:06:42.97656=Coinbase45=15958=Tag appears more than once371=269372=W373=1310=056
20250411-02:06:42.977079000 : 8=FIXT.1.19=90935=W49=Coinbase56=24ab46f784d1b20db435b852086e325034=16050=TEST52=20250411-02:06:42.839222369=2262=ecae6588-1a56-49ad-9a18-1bac314fe7a483=1597589724893=N55=BTC-USD1682=full_trading268=10269=0278=7c503558-c0b8-457b-8c46-71ece3f7fc8a270=1.93271=0.52331606269=0278=f763bb56-2f21-4a9b-bd48-f84dc1bd5ee5270=1.93271=0.52331606269=0278=42214b03-1fc2-46b3-9e83-91b23a510e5a270=1.93271=0.52331606269=0278=1c7c52ed-7d39-4326-b3b8-98f05a9b3ef0270=1.93271=0.52331606269=0278=3313309e-45e7-4e7b-8c55-4f9a8ec1b351270=1.93271=0.52331606269=0278=78801ffb-ec5a-4c74-9d08-3e86fd9db4dd270=1.93271=0.52331606269=0278=abe6eea4-1d9c-47d7-847f-2f44aa561b3f270=1.93271=0.52331606269=0278=6a6eb56d-2010-43e2-b78e-5f098081bb64270=1.93271=0.52331606269=0278=b53c01ff-f450-4b05-8ad1-e7894b45e0e0270=1.93271=0.52331606269=0278=4747863e-c0a6-4ef5-8faf-e8934bca4f8b270=1.93271=0.5233160610=125
20250411-02:06:42.977713000 : 8=FIXT.1.19=14235=334=1349=24ab46f784d1b20db435b852086e325052=20250411-02:06:42.97756=Coinbase45=16058=Tag appears more than once371=269372=W373=1310=050
20250411-02:06:42.977823000 : 8=FIXT.1.19=90935=W49=Coinbase56=24ab46f784d1b20db435b852086e325034=16150=TEST52=20250411-02:06:42.839472369=2262=ecae6588-1a56-49ad-9a18-1bac314fe7a483=1597589724893=N55=BTC-USD1682=full_trading268=10269=0278=81a8a629-57f4-4e3a-ac25-2e9ee1f357c2270=1.93271=0.52331606269=0278=1e239259-7be4-476a-845d-1b92fd951d8b270=1.93271=0.52331606269=0278=189eb272-48f9-4915-b7e1-a86dcc505c4a270=1.93271=0.52331606269=0278=0562b9f7-aae3-4961-bd97-f5b8cde0ec34270=1.93271=0.52331606269=0278=5103331b-7300-487b-bc2c-a6032bf4be7e270=1.93271=0.52331606269=0278=78ac85ac-2478-4991-a084-7286982b77cc270=1.93271=0.52331606269=0278=6993b26d-d6dc-4f99-8a53-9500ae5b4ff1270=1.93271=0.52331606269=0278=1c96ab9d-04a6-465a-87e5-3ed33970178f270=1.93271=0.52331606269=0278=6fc0282b-d538-4aa3-8982-bda02bb1b054270=1.93271=0.52331606269=0278=80870aa3-04a2-4d2a-8669-93215130ffee270=1.93271=0.5233160610=186
20250411-02:06:42.978643000 : 8=FIXT.1.19=14235=334=1449=24ab46f784d1b20db435b852086e325052=20250411-02:06:42.97856=Coinbase45=16158=Tag appears more than once371=269372=W373=1310=053
20250411-02:06:42.978815000 : 8=FIXT.1.19=92435=W49=Coinbase56=24ab46f784d1b20db435b852086e325034=16250=TEST52=20250411-02:06:42.839722369=2262=ecae6588-1a56-49ad-9a18-1bac314fe7a483=1597589724893=N55=BTC-USD1682=full_trading268=10269=0278=b274e872-6923-45fd-b48a-68e685e769cb270=1.93271=0.52331606269=0278=2d4364c0-239c-4f4b-8ce4-2acfe0bb343d270=1.12271=1.00000000269=0278=8fa16a4f-377f-4deb-9a8e-1020aed9edf4270=1.00271=1.00000000269=1278=c5b88ea9-605d-4595-ac52-f7c3f08523ba270=3.55271=4823.39861081269=1278=81523bd3-8912-4789-8761-89a9ee42794b270=3.55271=0.30518966269=1278=60fc75ca-0052-40b7-9f18-a6aad9d31b84270=3.56271=18037.00000000269=1278=ad00e2cd-d925-46a4-9e7e-941c6faed2c7270=3.57271=18027.00000000269=1278=fec191b5-64da-4a15-ab4b-36a0d3d10750270=3.57271=0.29025301269=1278=02a780aa-8154-4638-a5ca-53b8198cc724270=3.58271=16937.00000000269=1278=911349fb-1960-4904-9a38-0e2497fb7ccb270=3.58271=0.2989631210=180
20250411-02:06:42.979822000 : 8=FIXT.1.19=14235=334=1549=24ab46f784d1b20db435b852086e325052=20250411-02:06:42.97956=Coinbase45=16258=Tag appears more than once371=269372=W373=1310=056
20250411-02:06:42.979938000 : 8=FIXT.1.19=92535=W49=Coinbase56=24ab46f784d1b20db435b852086e325034=16350=TEST52=20250411-02:06:42.839972369=2262=ecae6588-1a56-49ad-9a18-1bac314fe7a483=1597589724893=N55=BTC-USD1682=full_trading268=10269=1278=57f29423-12f1-4812-9459-8f1cdf5cff84270=3.58271=0.62322946269=1278=d91e89d4-ac5c-4853-9879-ec8ff5e00a71270=3.59271=17163.00000000269=1278=9fe891e0-4e70-4c0c-9827-8b661f335613270=3.59271=0.62395543269=1278=341d0ad8-6c15-4b5e-aebb-e3caa5af575c270=3.60271=17926.00000000269=1278=9d239e03-1215-4cc7-ad44-3f4097ee70ea270=3.61271=18058.08928020269=1278=dbb0f332-4189-4df5-879b-e55860b13def270=3.62271=0.28062774269=1278=f7639c39-7e8b-44d1-a2f2-9807e2a3228c270=3.62271=0.27709851269=1278=83be9389-2099-4173-a322-b0933bc99358270=3.62271=19973.00000000269=1278=c08a87b4-a419-4d6d-8fab-8aaa9ea5345d270=3.62271=0.61971831269=1278=4623b8cd-ec9c-4818-9c21-abce854b641f270=3.62271=0.6232294610=252
20250411-02:06:42.980711000 : 8=FIXT.1.19=14235=334=1649=24ab46f784d1b20db435b852086e325052=20250411-02:06:42.98056=Coinbase45=16358=Tag appears more than once371=269372=W373=1310=050
20250411-02:06:42.980815000 : 8=FIXT.1.19=91735=W49=Coinbase56=24ab46f784d1b20db435b852086e325034=16450=TEST52=20250411-02:06:42.840222369=2262=ecae6588-1a56-49ad-9a18-1bac314fe7a483=1597589724893=N55=BTC-USD1682=full_trading268=10269=1278=b89abc22-6b6c-4474-b3fc-ffe21f05cd4e270=3.63271=20016.00000000269=1278=ce0af8a3-149c-4603-905a-be65625fe014270=3.64271=0.27806002269=1278=94b8615f-6fa7-4dc9-bbfa-435fe535bebc270=3.64271=22352.63489459269=1278=90461834-a863-4b3b-9b1e-da4405a1b98a270=3.65271=0.61971831269=1278=4982f17e-7a62-4e9b-b36d-9cff38bbc099270=3.68271=0.61971831269=1278=cae3885d-f5b2-4de1-830c-0085e27bbb69270=3.69271=0.27722678269=1278=df5c768a-bc8c-4091-9dcb-dd992f2f2e4c270=3.69271=0.61971831269=1278=fceb36ae-5214-497f-ac35-2570d600fd6e270=3.69271=0.61971831269=1278=c65c25c1-d008-4acb-beef-194abaaa6492270=3.69271=0.62322946269=1278=be0e8d6f-3669-4cc5-94f3-6b16f58194d5270=3.69271=0.6232294610=123
20250411-02:06:42.981682000 : 8=FIXT.1.19=14235=334=1749=24ab46f784d1b20db435b852086e325052=20250411-02:06:42.98156=Coinbase45=16458=Tag appears more than once371=269372=W373=1310=053
20250411-02:06:42.981778000 : 8=FIXT.1.19=90935=W49=Coinbase56=24ab46f784d1b20db435b852086e325034=16550=TEST52=20250411-02:06:42.840472369=2262=ecae6588-1a56-49ad-9a18-1bac314fe7a483=1597589724893=N55=BTC-USD1682=full_trading268=10269=1278=b9732128-11b1-44fd-bea3-94da9fc853fb270=3.71271=0.28488329269=1278=613e565a-3da1-495d-adde-3c7f9675c01a270=3.72271=0.61971831269=1278=818b83a4-e14e-4ad5-b094-6733f0504003270=3.75271=0.27930225269=1278=3e6990a0-8ef4-4968-8ee8-89b7346c197d270=3.76271=0.28131365269=1278=342794c8-a9d2-4aa5-9886-a819398d69c6270=3.88271=0.27719712269=1278=2839680b-48b3-4f53-86b1-9269987275e7270=3.91271=0.26621275269=1278=fd7b5361-29f8-4b35-bae5-232a64f657b4270=3.95271=0.26131406269=1278=5edaeed0-fae9-4f36-8c77-6fbedf61eefc270=4.02271=0.25091227269=1278=fdbbfd04-ba67-4b23-bbc1-f87f929e7e81270=4.07271=0.24812642269=1278=534b2a85-0852-420d-928b-70cdb6ba2457270=4.10271=0.2696196810=223
20250411-02:06:42.982453000 : 8=FIXT.1.19=14235=334=1849=24ab46f784d1b20db435b852086e325052=20250411-02:06:42.98256=Coinbase45=16558=Tag appears more than once371=269372=W373=1310=056
20250411-02:06:43.085999000 : 8=FIXT.1.19=92735=W49=Coinbase56=24ab46f784d1b20db435b852086e325034=16650=TEST52=20250411-02:06:42.840722369=2262=ecae6588-1a56-49ad-9a18-1bac314fe7a483=1597589724893=N55=BTC-USD1682=full_trading268=10269=1278=b009f8a1-4a39-493b-b96e-d783e981c915270=4.26271=0.25019574269=1278=729a899c-ac2d-4541-b0a2-cbdd5df9bf98270=10.00271=10.00000000269=1278=eb1e5d45-d081-4ef8-a83e-1f5348fbda96270=10.00271=10.00000000269=1278=0cd67977-85eb-45fa-ae72-d45b92ca24f4270=10.00271=10.00000000269=1278=5d931559-6758-4b75-9d6d-6438d25b497f270=10.00271=10.00000000269=1278=57e43d1d-644a-493e-acd3-69dc5e64dcde270=10.00271=10.00000000269=1278=c1566121-2b63-494d-ac2d-973e9f0115c0270=10.00271=10.00000000269=1278=d0c4a771-9035-4db9-ae7b-ad2d1db5646d270=10.00271=10.00000000269=1278=52c644ea-628a-4576-8e7e-27ec4c90398b270=10.00271=10.00000000269=1278=c3483f66-d8ce-489a-90b9-2bce69e054ee270=10.00271=10.0000000010=049
20250411-02:06:43.086958000 : 8=FIXT.1.19=14235=334=1949=24ab46f784d1b20db435b852086e325052=20250411-02:06:43.08656=Coinbase45=16658=Tag appears more than once371=269372=W373=1310=054
20250411-02:06:43.087074000 : 8=FIXT.1.19=93335=W49=Coinbase56=24ab46f784d1b20db435b852086e325034=16750=TEST52=20250411-02:06:42.840972369=2262=ecae6588-1a56-49ad-9a18-1bac314fe7a483=1597589724893=N55=BTC-USD1682=full_trading268=10269=1278=55992a5c-cbcd-464a-8f8d-8b58e81e5c0b270=10.00271=10.00000000269=1278=19077009-6f26-4e2d-9dab-04a28231b752270=10.00271=10.00000000269=1278=692097d1-c978-4024-95e9-2bf348b64bbd270=10.00271=10.00000000269=1278=99a92935-11b7-4f21-a64c-c746b53d1777270=10.00271=10.00000000269=1278=dc024b0b-0337-4215-9669-5e5636834397270=10.00271=10.00000000269=1278=c90fcc3a-a36c-4c14-b57f-6db78762e017270=10.00271=10.00000000269=1278=7841891a-bb7c-4034-97c1-41164185edc7270=1000.00271=3.10000000269=1278=381c9fa7-1add-4dd2-9233-f41e2c8821fe270=1000.00271=3.10000000269=1278=928e65c2-7e2d-478b-9310-414fb77f5aae270=1000.00271=3.10000000269=1278=ad4bd3ac-9276-40d5-90f9-e47b1d8ee953270=1000.00271=3.1000000010=167
20250411-02:06:43.087649000 : 8=FIXT.1.19=14235=334=2049=24ab46f784d1b20db435b852086e325052=20250411-02:06:43.08756=Coinbase45=16758=Tag appears more than once371=269372=W373=1310=048
20250411-02:06:43.087733000 : 8=FIXT.1.19=93935=W49=Coinbase56=24ab46f784d1b20db435b852086e325034=16850=TEST52=20250411-02:06:42.841222369=2262=ecae6588-1a56-49ad-9a18-1bac314fe7a483=1597589724893=N55=BTC-USD1682=full_trading268=10269=1278=79e799dc-4a3d-4922-ad1a-f74eb7eff789270=1000.00271=3.10000000269=1278=04f642b7-750f-4967-b786-0d48eea0f158270=1000.00271=3.10000000269=1278=d0ad653d-3272-4a3b-ba7a-a52029a67a92270=1000.00271=3.10000000269=1278=cad40464-4c62-4bf3-8444-c487fcc8dd01270=1000.00271=3.10000000269=1278=426c6428-d481-4ff7-9de3-f00ff219d654270=1000.00271=3.10000000269=1278=1ed1152d-8c1a-4b29-acdd-bbd1a5c5f35f270=1000.00271=3.10000000269=1278=66526051-b5cb-442f-af90-c609be0a9796270=1000.00271=3.10000000269=1278=f68e4659-5785-4ee9-ac24-3186640a2752270=1000.00271=3.10000000269=1278=38070d38-80a9-4898-8ef7-a0a9da5a4123270=1000.00271=3.10000000269=1278=e4d2d308-ed11-49db-850e-3cbd8258395d270=1000.00271=3.1000000010=167
20250411-02:06:43.088283000 : 8=FIXT.1.19=14235=334=2149=24ab46f784d1b20db435b852086e325052=20250411-02:06:43.08756=Coinbase45=16858=Tag appears more than once371=269372=W373=1310=050
20250411-02:06:43.109947000 : 8=FIXT.1.19=93935=W49=Coinbase56=24ab46f784d1b20db435b852086e325034=16950=TEST52=20250411-02:06:42.841472369=2262=ecae6588-1a56-49ad-9a18-1bac314fe7a483=1597589724893=N55=BTC-USD1682=full_trading268=10269=1278=d6cfaadc-97ea-43c1-898d-40faea9c1477270=1000.00271=3.10000000269=1278=36876bea-9e3a-4018-b0ac-b75cb8c16953270=1000.00271=3.10000000269=1278=eb244bc5-49e8-4aa3-af8b-3d1a67c90a08270=1000.00271=3.10000000269=1278=3efba776-29ad-4aeb-82d8-0824f161471e270=1000.00271=3.10000000269=1278=de0ddebd-0ca8-4eca-9985-77c10c8629a9270=1000.00271=3.10000000269=1278=dde4408a-fb6b-441c-a7f3-7b8b23ffdb1f270=1000.00271=3.10000000269=1278=3ebd6434-070f-4b4d-8cf3-00368112466d270=1000.00271=3.10000000269=1278=7aa98e13-65f3-4058-9f91-c1f452d02710270=1000.00271=3.10000000269=1278=e86a1fec-3610-460d-8d85-4e1e222ee159270=1000.00271=3.10000000269=1278=6dfac057-72b1-4f2c-b110-03766dea0d31270=1000.00271=3.1000000010=255
20250411-02:06:43.110983000 : 8=FIXT.1.19=14235=334=2249=24ab46f784d1b20db435b852086e325052=20250411-02:06:43.11056=Coinbase45=16958=Tag appears more than once371=269372=W373=1310=039
20250411-02:06:43.111141000 : 8=FIXT.1.19=93935=W49=Coinbase56=24ab46f784d1b20db435b852086e325034=17050=TEST52=20250411-02:06:42.841722369=2262=ecae6588-1a56-49ad-9a18-1bac314fe7a483=1597589724893=N55=BTC-USD1682=full_trading268=10269=1278=bbb7d0ea-d251-4612-b53e-e528cc0a24ab270=1000.00271=3.10000000269=1278=0782ca37-48cf-4ff3-a74a-35674661586c270=1000.00271=3.10000000269=1278=aead437d-4b62-457f-ac83-62c7cc329fd1270=1000.00271=3.10000000269=1278=af5d47bc-a008-4567-b24f-b0298f250471270=1000.00271=3.10000000269=1278=4c260f58-c427-4a9a-969a-44024ae0c714270=1000.00271=3.10000000269=1278=8c7672e5-7ee8-4fbd-8fdf-7e74e9a77db7270=1000.00271=3.10000000269=1278=b53ec3cc-9abe-4570-b903-34d52148073e270=1000.00271=3.10000000269=1278=37ce984a-0387-4ac9-9094-b83f722036ba270=1000.00271=3.10000000269=1278=0d383649-dc6c-4df2-b821-aa0018f132c7270=1000.00271=3.10000000269=1278=e39ae0ce-9e7f-4f0d-a765-5308d473bb61270=1000.00271=3.1000000010=055
20250411-02:06:43.111780000 : 8=FIXT.1.19=14235=334=2349=24ab46f784d1b20db435b852086e325052=20250411-02:06:43.11156=Coinbase45=17058=Tag appears more than once371=269372=W373=1310=033
20250411-02:06:43.111853000 : 8=FIXT.1.19=93935=W49=Coinbase56=24ab46f784d1b20db435b852086e325034=17150=TEST52=20250411-02:06:42.841973369=2262=ecae6588-1a56-49ad-9a18-1bac314fe7a483=1597589724893=N55=BTC-USD1682=full_trading268=10269=1278=4882324e-3b5c-4b7a-b096-e8c6d9888671270=1000.00271=3.10000000269=1278=6e5c7dbd-a2cc-401f-a5b2-3902088f4ab2270=1000.00271=3.10000000269=1278=10ffac08-946a-4a30-b57a-0d78450345d9270=1000.00271=3.10000000269=1278=67784af5-72bf-4d16-a6b3-25336e2c1843270=1000.00271=3.10000000269=1278=4d8b3bbc-0dc2-4044-875c-c079ec538136270=1000.00271=3.10000000269=1278=dfba5f1e-21f5-48e3-adce-b8b6bfe71467270=1000.00271=3.10000000269=1278=e51b4e33-5eaa-46ef-936b-a74a890397e8270=1000.00271=3.10000000269=1278=8cf5dfa8-858b-48a3-9d94-78522c257473270=1000.00271=3.10000000269=1278=a153b9d2-993d-4f03-a974-b8a081e128e8270=1000.00271=3.10000000269=1278=1eebe866-0f6e-4d4a-a28b-78f4e3368b0a270=1000.00271=3.1000000010=062
20250411-02:06:43.112384000 : 8=FIXT.1.19=14235=334=2449=24ab46f784d1b20db435b852086e325052=20250411-02:06:43.11256=Coinbase45=17158=Tag appears more than once371=269372=W373=1310=036
20250411-02:06:43.189839000 : 8=FIXT.1.19=93935=W49=Coinbase56=24ab46f784d1b20db435b852086e325034=17250=TEST52=20250411-02:06:42.842222369=2262=ecae6588-1a56-49ad-9a18-1bac314fe7a483=1597589724893=N55=BTC-USD1682=full_trading268=10269=1278=300132d8-113f-4bf7-ba0c-4d93a272f55b270=1000.00271=3.10000000269=1278=757f3122-27d2-4f32-90b8-ead1eef9b936270=1000.00271=3.10000000269=1278=2b68b5de-4153-4cac-ace3-102e4fa788fd270=1000.00271=3.10000000269=1278=b01f252a-1657-4df0-a122-58a23109a7c2270=1000.00271=3.10000000269=1278=dbc57e4e-6abd-4d66-8d18-bd13caaa77b1270=1000.00271=3.10000000269=1278=948b05dc-a481-409f-b8ad-a502eb595906270=1000.00271=3.10000000269=1278=e00f9703-6e16-4237-a2c6-701829d11bf1270=1000.00271=3.10000000269=1278=fd52f47a-3f11-47bc-9952-9708617d0ecd270=1000.00271=3.10000000269=1278=f7f75b14-27c3-469c-89fb-6a98b43c61bf270=1000.00271=3.10000000269=1278=25dbeb09-7901-4280-b0c3-720d7ed03d7d270=1000.00271=3.1000000010=252
20250411-02:06:43.190909000 : 8=FIXT.1.19=14235=334=2549=24ab46f784d1b20db435b852086e325052=20250411-02:06:43.19056=Coinbase45=17258=Tag appears more than once371=269372=W373=1310=044
20250411-02:06:43.191105000 : 8=FIXT.1.19=93935=W49=Coinbase56=24ab46f784d1b20db435b852086e325034=17350=TEST52=20250411-02:06:42.842472369=2262=ecae6588-1a56-49ad-9a18-1bac314fe7a483=1597589724893=N55=BTC-USD1682=full_trading268=10269=1278=52164a1f-599f-4c43-a9ed-f93403506e67270=1000.00271=3.10000000269=1278=c71c35ea-f60f-4a41-b43a-4947bbcbafad270=1000.00271=3.10000000269=1278=2de342bc-a1be-46f3-9fc6-731297726934270=1000.00271=3.10000000269=1278=7ff4c5fc-bc9b-4845-940b-4837a672e13a270=1000.00271=3.10000000269=1278=2d270775-33eb-4328-8dad-7d206612f9f6270=1000.00271=3.10000000269=1278=c4754378-f787-4100-81af-564443a86a91270=1000.00271=3.10000000269=1278=59e16255-05eb-4fdc-8be1-3c4f83fc094e270=1000.00271=3.10000000269=1278=041b2f98-1185-49cb-964a-f0456b71e692270=1000.00271=3.10000000269=1278=9a2f3529-481e-4e50-a123-7a2095fe6b2c270=1000.00271=3.10000000269=1278=9ed552a3-3295-4878-85dd-87b7b5590212270=1000.00271=3.1000000010=164
20250411-02:06:43.191724000 : 8=FIXT.1.19=14235=334=2649=24ab46f784d1b20db435b852086e325052=20250411-02:06:43.19156=Coinbase45=17358=Tag appears more than once371=269372=W373=1310=047
20250411-02:06:43.191802000 : 8=FIXT.1.19=93935=W49=Coinbase56=24ab46f784d1b20db435b852086e325034=17450=TEST52=20250411-02:06:42.842723369=2262=ecae6588-1a56-49ad-9a18-1bac314fe7a483=1597589724893=N55=BTC-USD1682=full_trading268=10269=1278=54bec5c2-bafd-4d7d-851d-59e3553a053f270=1000.00271=3.10000000269=1278=543c1acf-52f2-442b-a893-f7aa9a5dfbd1270=1000.00271=3.10000000269=1278=fec999be-cbd0-42ef-b9c3-82ca92ef0b58270=1000.00271=3.10000000269=1278=24528176-3fc6-45b2-b2f3-9f784c01495a270=1000.00271=3.10000000269=1278=12081678-66a6-4435-a3d7-b65f959cf2ac270=1000.00271=3.10000000269=1278=e7fb6165-8f1a-4b5e-b095-e232b83ee951270=1000.00271=3.10000000269=1278=83ce6582-410a-40bf-9831-8f3d20e3a629270=1000.00271=3.10000000269=1278=bc3a930b-0567-46ba-86a4-712f76466b0b270=1000.00271=3.10000000269=1278=15704973-f5ff-457d-ab31-8f99bb76bf7e270=1000.00271=3.10000000269=1278=7159045b-cbd5-458f-b91f-9fa5241b14b5270=1000.00271=3.1000000010=145
20250411-02:06:43.192384000 : 8=FIXT.1.19=14235=334=2749=24ab46f784d1b20db435b852086e325052=20250411-02:06:43.19256=Coinbase45=17458=Tag appears more than once371=269372=W373=1310=050
20250411-02:06:43.193131000 : 8=FIXT.1.19=93935=W49=Coinbase56=24ab46f784d1b20db435b852086e325034=17550=TEST52=20250411-02:06:42.842973369=2262=ecae6588-1a56-49ad-9a18-1bac314fe7a483=1597589724893=N55=BTC-USD1682=full_trading268=10269=1278=9fa52a90-f03f-4940-b5ee-39ab937b86f1270=1000.00271=3.10000000269=1278=220f55cd-a279-4bf0-9c80-1dca086d85dc270=1000.00271=3.10000000269=1278=2b1eb468-6bcd-4117-a7c0-214d643ddad4270=1000.00271=3.10000000269=1278=cc23185d-e72e-42cb-8210-61bab29cd778270=1000.00271=3.10000000269=1278=69bb228b-973b-4176-8708-3231cc40102a270=1000.00271=3.10000000269=1278=2ec8035d-7962-4195-8388-c9fbad52ac8a270=1000.00271=3.10000000269=1278=7d39e416-0b7b-471f-a9ac-455ab1bce5a7270=1000.00271=3.10000000269=1278=7067378d-2a65-41f2-acb0-ef30ddbc3e5a270=1000.00271=3.10000000269=1278=bf3fde78-6cff-4477-b381-4b5d2e68f36f270=1000.00271=3.10000000269=1278=93a2a8a3-61d4-410c-9446-8eabaafc5f29270=1000.00271=3.1000000010=122
20250411-02:06:43.197223000 : 8=FIXT.1.19=14235=334=2849=24ab46f784d1b20db435b852086e325052=20250411-02:06:43.19656=Coinbase45=17558=Tag appears more than once371=269372=W373=1310=056
20250411-02:06:43.197408000 : 8=FIXT.1.19=93935=W49=Coinbase56=24ab46f784d1b20db435b852086e325034=17650=TEST52=20250411-02:06:42.843223369=2262=ecae6588-1a56-49ad-9a18-1bac314fe7a483=1597589724893=N55=BTC-USD1682=full_trading268=10269=1278=5afddb61-63ab-417b-a28a-41c4c03a6612270=1000.00271=3.10000000269=1278=a4280417-189c-4f76-9d2e-6ec652010bf5270=1000.00271=3.10000000269=1278=ddeb78a2-e110-4828-ba3d-c9b4837e7dd7270=1000.00271=3.10000000269=1278=fcec6c90-441a-4f4a-a94e-9003355657ef270=1000.00271=3.10000000269=1278=6db15389-dfb3-4156-8a4e-ce2ac80f2b15270=1000.00271=3.10000000269=1278=47dfefc3-6f05-4b57-8aec-2bf3e6c70c2d270=1000.00271=3.10000000269=1278=fb9fd019-4b4f-4880-82bb-3df6d1ef468a270=1000.00271=3.10000000269=1278=2cff9acd-42cb-43a5-8d50-51e676b7e763270=1000.00271=3.10000000269=1278=6e6eeb59-4728-4811-9a44-c857df6aca42270=1000.00271=3.10000000269=1278=81798560-263f-4819-a528-5f3fbbc7b042270=1000.00271=3.1000000010=158
20250411-02:06:43.198534000 : 8=FIXT.1.19=14235=334=2949=24ab46f784d1b20db435b852086e325052=20250411-02:06:43.19856=Coinbase45=17658=Tag appears more than once371=269372=W373=1310=060
20250411-02:06:43.198746000 : 8=FIXT.1.19=93935=W49=Coinbase56=24ab46f784d1b20db435b852086e325034=17750=TEST52=20250411-02:06:42.843473369=2262=ecae6588-1a56-49ad-9a18-1bac314fe7a483=1597589724893=N55=BTC-USD1682=full_trading268=10269=1278=81fbf9a8-82f4-4fe4-9fa5-3773b212ebf4270=1000.00271=3.10000000269=1278=5d3b9566-276d-47fe-a111-12c17f53f501270=1000.00271=3.10000000269=1278=8eb1b3b3-c813-48b1-b839-993672108d91270=1000.00271=3.10000000269=1278=4feb6e93-6149-481b-8d58-e1c8e6c5cda1270=1000.00271=3.10000000269=1278=f8611e72-4056-4b7c-9779-4d54cd151d44270=1000.00271=3.10000000269=1278=7a129f7c-d9ba-4ea3-a267-b7d82b2e07d9270=1000.00271=3.10000000269=1278=01f359f0-c38f-416b-af00-183907218793270=1000.00271=3.10000000269=1278=11741cec-9c08-4a20-99dc-6b9f63130b0e270=1000.00271=3.10000000269=1278=08db2574-ad52-4520-ab5b-c3c7591eb781270=1000.00271=3.10000000269=1278=b06f2249-179c-4a15-8e98-7b76083b808b270=1000.00271=3.1000000010=199
20250411-02:06:43.199409000 : 8=FIXT.1.19=14235=334=3049=24ab46f784d1b20db435b852086e325052=20250411-02:06:43.19956=Coinbase45=17758=Tag appears more than once371=269372=W373=1310=054
20250411-02:06:43.199485000 : 8=FIXT.1.19=93935=W49=Coinbase56=24ab46f784d1b20db435b852086e325034=17850=TEST52=20250411-02:06:42.843723369=2262=ecae6588-1a56-49ad-9a18-1bac314fe7a483=1597589724893=N55=BTC-USD1682=full_trading268=10269=1278=9e88fede-6d19-4c1f-863b-5a7d66781436270=1000.00271=3.10000000269=1278=75e1d8b4-7201-41fe-a687-7d93420af323270=1000.00271=3.10000000269=1278=d00aa7dd-ce7f-4f8b-9a2e-880c1ea30845270=1000.00271=3.10000000269=1278=584a483f-23bf-4d8b-809f-69cf3c110f60270=1000.00271=3.10000000269=1278=dc98524e-27e2-4863-99e4-7a0097a6ee90270=1000.00271=3.10000000269=1278=82a11ac9-4f46-44b7-a0bc-a5a4cfe686e0270=1000.00271=3.10000000269=1278=f946bb05-900c-41fc-9908-41489e97ff20270=1000.00271=3.10000000269=1278=1f9186d6-0312-4677-ba96-fdb014cdff2c270=1000.00271=3.10000000269=1278=c3b67be7-2b63-4884-b311-80f28496c2c4270=1000.00271=3.10000000269=1278=6576c7f8-a4e2-4417-b854-5fef0e705fbe270=1000.00271=3.1000000010=161
20250411-02:06:43.200039000 : 8=FIXT.1.19=14235=334=3149=24ab46f784d1b20db435b852086e325052=20250411-02:06:43.19956=Coinbase45=17858=Tag appears more than once371=269372=W373=1310=056
20250411-02:06:43.200122000 : 8=FIXT.1.19=93935=W49=Coinbase56=24ab46f784d1b20db435b852086e325034=17950=TEST52=20250411-02:06:42.843973369=2262=ecae6588-1a56-49ad-9a18-1bac314fe7a483=1597589724893=N55=BTC-USD1682=full_trading268=10269=1278=c2102c71-62f0-4eee-ae60-0777ed26a8e6270=1000.00271=3.10000000269=1278=c823a2b6-849e-4839-a2fd-cd9f459cae6c270=1000.00271=3.10000000269=1278=a051e195-4472-4a8a-8591-08a2c04a33c4270=1000.00271=3.10000000269=1278=ec81b8c4-b703-4afd-a701-ce34011f60f6270=1000.00271=3.10000000269=1278=b1172677-f493-4f32-a200-0710cf8c397f270=1000.00271=3.10000000269=1278=b1a58a75-5fca-43db-b9c6-a26920e8f66e270=1000.00271=3.10000000269=1278=038bea41-b91d-4884-b992-3e5431ef9857270=1000.00271=3.10000000269=1278=55063782-f2ea-4c84-9491-8e8e89d1dfd1270=1000.00271=3.10000000269=1278=bb2011e8-d05d-40ac-9e9c-3b720422e38d270=1000.00271=3.10000000269=1278=64dd3b4a-ce8a-4b63-9937-266e832c0f21270=1000.00271=3.1000000010=085
20250411-02:06:43.200836000 : 8=FIXT.1.19=14235=334=3249=24ab46f784d1b20db435b852086e325052=20250411-02:06:43.20056=Coinbase45=17958=Tag appears more than once371=269372=W373=1310=041
20250411-02:06:43.201079000 : 8=FIXT.1.19=93935=W49=Coinbase56=24ab46f784d1b20db435b852086e325034=18050=TEST52=20250411-02:06:42.844223369=2262=ecae6588-1a56-49ad-9a18-1bac314fe7a483=1597589724893=N55=BTC-USD1682=full_trading268=10269=1278=d64f7d2a-aa83-486c-92a8-3314c4eddd58270=1000.00271=3.10000000269=1278=0df9641b-d89d-4222-a8ea-bcddf0d555f5270=1000.00271=3.10000000269=1278=7a315b16-a05f-408d-b8c1-2704af9bf767270=1000.00271=3.10000000269=1278=0e9712a8-d00f-4864-a478-f7f591718f91270=1000.00271=3.10000000269=1278=94db025d-eada-49e3-b13c-b667ca07f829270=1000.00271=3.10000000269=1278=a88ccd1f-8f8d-46af-8fb6-20adba35f7d1270=1000.00271=3.10000000269=1278=99d4e235-c8ec-4efc-938c-9a1923eafc96270=1000.00271=3.10000000269=1278=a4fc7173-7583-4f8b-b256-2921bef83c84270=1000.00271=3.10000000269=1278=18f8afd4-8bbc-4ffa-8e8f-0c1834d74472270=1000.00271=3.10000000269=1278=21fc8cb6-f894-4d09-884e-810b8ebf2ef3270=1000.00271=3.1000000010=005
20250411-02:06:43.202170000 : 8=FIXT.1.19=14235=334=3349=24ab46f784d1b20db435b852086e325052=20250411-02:06:43.20156=Coinbase45=18058=Tag appears more than once371=269372=W373=1310=035
20250411-02:06:43.202501000 : 8=FIXT.1.19=93935=W49=Coinbase56=24ab46f784d1b20db435b852086e325034=18150=TEST52=20250411-02:06:42.844473369=2262=ecae6588-1a56-49ad-9a18-1bac314fe7a483=1597589724893=N55=BTC-USD1682=full_trading268=10269=1278=0c13b9e6-6797-4b3e-90ce-a1885b26ba53270=1000.00271=3.10000000269=1278=6d8da581-3998-4fc0-99b6-3c5edbd514cb270=1000.00271=3.10000000269=1278=67a70307-be50-4065-872b-47e0de473bc4270=1000.00271=3.10000000269=1278=8ce7be0b-98de-46d0-b1b6-307a4bec36e2270=1000.00271=3.10000000269=1278=856b22f8-5884-4739-adc0-bdd851c5c07d270=1000.00271=3.10000000269=1278=c00ae651-a76b-4bfd-be16-3672b345fe29270=1000.00271=3.10000000269=1278=cae248f9-16fc-44ea-9b79-1dacfc285db6270=1000.00271=3.10000000269=1278=42bb223c-88c6-4a18-8ff3-4fd8d9efda8d270=1000.00271=3.10000000269=1278=d7188b01-22b6-4837-a720-077601f7f483270=1000.00271=3.10000000269=1278=5d85a0a6-ddd9-4e0e-9a1a-7f418ef588e5270=1000.00271=3.1000000010=190
20250411-02:06:43.210591000 : 8=FIXT.1.19=14235=334=3449=24ab46f784d1b20db435b852086e325052=20250411-02:06:43.20856=Coinbase45=18158=Tag appears more than once371=269372=W373=1310=044
20250411-02:06:43.212278000 : 8=FIXT.1.19=93935=W49=Coinbase56=24ab46f784d1b20db435b852086e325034=18250=TEST52=20250411-02:06:42.844723369=2262=ecae6588-1a56-49ad-9a18-1bac314fe7a483=1597589724893=N55=BTC-USD1682=full_trading268=10269=1278=bff4c39f-7a80-42ce-a178-b1221792e445270=1000.00271=3.10000000269=1278=9ea3d263-b5ab-46c5-bf27-8c0e3e0e5e9e270=1000.00271=3.10000000269=1278=b93347df-d2ab-48ec-b326-4454e64f1d4e270=1000.00271=3.10000000269=1278=57acc40d-8478-444a-990f-067a8e8e846e270=1000.00271=3.10000000269=1278=34419ae2-2c16-427b-a290-845419760fd5270=1000.00271=3.10000000269=1278=ab41de2d-5def-4986-b56e-243d2f99a57c270=1000.00271=3.10000000269=1278=9025524c-03a9-407a-a58a-5258c4ea0a0b270=1000.00271=3.10000000269=1278=60766318-112b-4d83-a384-55693de75519270=1000.00271=3.10000000269=1278=c19b6a2c-086b-4fc1-8dfe-51cb2dc12c1d270=1000.00271=3.10000000269=1278=11126433-0f9c-4450-a35a-39b878e85e68270=1000.00271=3.1000000010=199
20250411-02:06:43.216506000 : 8=FIXT.1.19=14235=334=3549=24ab46f784d1b20db435b852086e325052=20250411-02:06:43.21556=Coinbase45=18258=Tag appears more than once371=269372=W373=1310=044
20250411-02:06:43.216668000 : 8=FIXT.1.19=93935=W49=Coinbase56=24ab46f784d1b20db435b852086e325034=18350=TEST52=20250411-02:06:42.844973369=2262=ecae6588-1a56-49ad-9a18-1bac314fe7a483=1597589724893=N55=BTC-USD1682=full_trading268=10269=1278=e2e620ee-44fb-4630-a890-d331ba5b2fae270=1000.00271=3.10000000269=1278=9ccf6d4b-a6ca-4a1f-a7bb-77f400ace0c8270=1000.00271=3.10000000269=1278=0e8d6c10-8421-4f19-97dc-d70e715d9033270=1000.00271=3.10000000269=1278=f31ecd5d-8231-44ea-a5c2-0fcc5a699401270=1000.00271=3.10000000269=1278=37fbb559-dc52-48fe-ab65-24910edc338a270=1000.00271=3.10000000269=1278=bc1435c5-c59c-4017-9e59-f1073f04c7e2270=1000.00271=3.10000000269=1278=9c8e1397-0cee-4b05-a66f-5594040791c4270=1000.00271=3.10000000269=1278=248b6703-f829-42bb-a551-4be3075c381e270=1000.00271=3.10000000269=1278=16d257b0-bc92-44f0-822d-3eba61af4bda270=1000.00271=3.10000000269=1278=06257aa1-4043-4cdb-9286-4342b8e59108270=1000.00271=3.1000000010=004
20250411-02:06:43.217580000 : 8=FIXT.1.19=14235=334=3649=24ab46f784d1b20db435b852086e325052=20250411-02:06:43.21756=Coinbase45=18358=Tag appears more than once371=269372=W373=1310=048
20250411-02:06:43.217687000 : 8=FIXT.1.19=93935=W49=Coinbase56=24ab46f784d1b20db435b852086e325034=18450=TEST52=20250411-02:06:42.845223369=2262=ecae6588-1a56-49ad-9a18-1bac314fe7a483=1597589724893=N55=BTC-USD1682=full_trading268=10269=1278=210ec210-1443-47dc-9e43-9c9ea720a6c3270=1000.00271=3.10000000269=1278=8b79da5d-b78c-4011-b55f-b35c16dc3724270=1000.00271=3.10000000269=1278=076c3703-1104-4e15-a38a-d95bf133f0c5270=1000.00271=3.10000000269=1278=f5a3155c-e449-4102-870d-ab8c8dd24c3d270=1000.00271=3.10000000269=1278=1af2681f-2dec-4d25-aaeb-89b8867b4a3c270=1000.00271=3.10000000269=1278=65c3088d-192a-4213-85a3-7257aa8b20a3270=1000.00271=3.10000000269=1278=2aa7989b-5601-4899-8143-01dda3255e4f270=1000.00271=3.10000000269=1278=099b432c-fa2e-4fd7-952e-22f6debf6877270=1000.00271=3.10000000269=1278=2e71cc31-1235-4b7b-a728-e3335631fe5a270=1000.00271=3.10000000269=1278=ce471ffc-1e26-4afe-afab-27ee5ac8debe270=1000.00271=3.1000000010=101
20250411-02:06:43.218267000 : 8=FIXT.1.19=14235=334=3749=24ab46f784d1b20db435b852086e325052=20250411-02:06:43.21756=Coinbase45=18458=Tag appears more than once371=269372=W373=1310=050
20250411-02:06:43.218395000 : 8=FIXT.1.19=93935=W49=Coinbase56=24ab46f784d1b20db435b852086e325034=18550=TEST52=20250411-02:06:42.845473369=2262=ecae6588-1a56-49ad-9a18-1bac314fe7a483=1597589724893=N55=BTC-USD1682=full_trading268=10269=1278=113b7fc6-8574-40eb-8682-d077245b84f2270=1000.00271=3.10000000269=1278=bcebce2c-eda8-4b85-841d-27ede39fc5a1270=1000.00271=3.10000000269=1278=0aedaae5-6cc6-4a34-8e48-5e67a5ccc148270=1000.00271=3.10000000269=1278=206e10a5-1173-4860-87b5-7c88afe061f6270=1000.00271=3.10000000269=1278=5c32d94b-696a-4d9b-afa0-665970356008270=1000.00271=3.10000000269=1278=0b7da819-cc1e-4525-a382-ce5b90dc485c270=1000.00271=3.10000000269=1278=2241b3bf-cbbe-44f2-ac75-8032f6283aa8270=1000.00271=3.10000000269=1278=88cada69-adb1-466a-afcd-66e063ad27c0270=1000.00271=3.10000000269=1278=34a52ef5-31c1-4c63-9230-21c85a9a6ba3270=1000.00271=3.10000000269=1278=e109c2c8-fb1d-4ef9-a640-368381323507270=1000.00271=3.1000000010=171
20250411-02:06:43.218946000 : 8=FIXT.1.19=14235=334=3849=24ab46f784d1b20db435b852086e325052=20250411-02:06:43.21856=Coinbase45=18558=Tag appears more than once371=269372=W373=1310=053
20250411-02:06:43.219123000 : 8=FIXT.1.19=93935=W49=Coinbase56=24ab46f784d1b20db435b852086e325034=18650=TEST52=20250411-02:06:42.845723369=2262=ecae6588-1a56-49ad-9a18-1bac314fe7a483=1597589724893=N55=BTC-USD1682=full_trading268=10269=1278=38fd36c4-4c62-4b4c-8f24-1fe39be94fa1270=1000.00271=3.10000000269=1278=f83f64c8-7d33-472d-a516-9b664ff9c966270=1000.00271=3.10000000269=1278=3411c368-380b-42e6-b656-8552d92904d5270=1000.00271=3.10000000269=1278=4803796e-79f3-4aa4-a8cb-37f13899bf01270=1000.00271=3.10000000269=1278=823f8fbf-7e6d-4ae3-adb9-3a822ff6d09a270=1000.00271=3.10000000269=1278=135624df-a204-490f-a68b-63d74ee09908270=1000.00271=3.10000000269=1278=47cfdedf-22b9-402c-93bd-f311103fd3e0270=1000.00271=3.10000000269=1278=f9173d5e-d872-4661-93f6-28f527e931f7270=1000.00271=3.10000000269=1278=06ab1365-fd39-4701-bd7f-1915ad3c7602270=1000.00271=3.10000000269=1278=012a7c59-5ae4-4da5-97ba-2e3254c889fb270=1000.00271=3.1000000010=020
20250411-02:06:43.220140000 : 8=FIXT.1.19=14235=334=3949=24ab46f784d1b20db435b852086e325052=20250411-02:06:43.21956=Coinbase45=18658=Tag appears more than once371=269372=W373=1310=056
20250411-02:06:43.220323000 : 8=FIXT.1.19=93935=W49=Coinbase56=24ab46f784d1b20db435b852086e325034=18750=TEST52=20250411-02:06:42.845973369=2262=ecae6588-1a56-49ad-9a18-1bac314fe7a483=1597589724893=N55=BTC-USD1682=full_trading268=10269=1278=a9a0d42f-ad9e-4ea9-8bf0-d5a441fded40270=1000.00271=3.10000000269=1278=f3f3930e-be0e-40b4-a97d-d19501a54885270=1000.00271=3.10000000269=1278=261922d0-5c81-4ab6-832f-4eff45f64890270=1000.00271=3.10000000269=1278=3af4e45f-56f6-4c69-894d-d56a14894a98270=1000.00271=3.10000000269=1278=1c1dd248-49e4-44aa-9e69-323b0f41fa0e270=1000.00271=3.10000000269=1278=b16b002d-1cd6-4869-9c1b-f15c758611bf270=1000.00271=3.10000000269=1278=a0520e61-28ad-448d-87c1-49f0c7358628270=1000.00271=3.10000000269=1278=152d0b57-086f-48cc-80b3-ff14ee9375ed270=1000.00271=3.10000000269=1278=c55fc264-67d2-4e9c-8cce-6c834feff648270=1000.00271=3.10000000269=1278=27361968-189a-4fa6-a3a2-eead03c640d6270=1000.00271=3.1000000010=079
20250411-02:06:43.221231000 : 8=FIXT.1.19=14235=334=4049=24ab46f784d1b20db435b852086e325052=20250411-02:06:43.22056=Coinbase45=18758=Tag appears more than once371=269372=W373=1310=041
20250411-02:06:43.221410000 : 8=FIXT.1.19=93935=W49=Coinbase56=24ab46f784d1b20db435b852086e325034=18850=TEST52=20250411-02:06:42.846223369=2262=ecae6588-1a56-49ad-9a18-1bac314fe7a483=1597589724893=N55=BTC-USD1682=full_trading268=10269=1278=f5b01c67-f98f-44b9-a511-7f07f8883d9e270=1000.00271=3.10000000269=1278=75a5c14f-8434-4533-a10e-0bf6e92e1000270=1000.00271=3.10000000269=1278=a9b0a826-3659-4105-9ecc-21bcd27b736f270=1000.00271=3.10000000269=1278=1b1bab77-5c52-459b-98e3-e27ff6f8cd04270=1000.00271=3.10000000269=1278=346695f1-fe03-4364-8fc5-006796c8f82f270=1000.00271=3.10000000269=1278=cbbaa36d-2a03-45a2-a230-bd5845d832cd270=1000.00271=3.10000000269=1278=745d4fc0-6710-4c5c-97c3-7b29c4e06839270=1000.00271=3.10000000269=1278=e95fdfba-5db2-4461-8e9c-7bfdf8a9238c270=1000.00271=3.10000000269=1278=33611b39-1fbf-45cc-bf5e-a02bc1f84736270=1000.00271=3.10000000269=1278=51f77b2d-1a69-432d-934b-234eb9e1dfac270=1000.00271=3.1000000010=133
20250411-02:06:43.224009000 : 8=FIXT.1.19=14235=334=4149=24ab46f784d1b20db435b852086e325052=20250411-02:06:43.22156=Coinbase45=18858=Tag appears more than once371=269372=W373=1310=044
20250411-02:06:43.224163000 : 8=FIXT.1.19=93935=W49=Coinbase56=24ab46f784d1b20db435b852086e325034=18950=TEST52=20250411-02:06:42.846473369=2262=ecae6588-1a56-49ad-9a18-1bac314fe7a483=1597589724893=N55=BTC-USD1682=full_trading268=10269=1278=ab09fdc3-8d50-432f-ab0f-97e8627eac24270=1000.00271=3.10000000269=1278=dde04213-6104-44c5-a811-15834c27b515270=1000.00271=3.10000000269=1278=9af2b85c-4997-4e1b-9147-7d400f059b01270=1000.00271=3.10000000269=1278=40870860-7a8a-4419-a117-e511f779abfa270=1000.00271=3.10000000269=1278=3e8fa7bd-dde0-4fe4-bb2e-e6279841b019270=1000.00271=3.10000000269=1278=4dde1422-98d8-405b-88df-bf245291ad7a270=1000.00271=3.10000000269=1278=6ee8b5a8-bc2f-4a0a-9ae4-7ff1b5dae941270=1000.00271=3.10000000269=1278=3ebc1f7a-2bb5-4ef0-a82f-844b9540f6e8270=1000.00271=3.10000000269=1278=a82d5bb9-1f1a-4575-b580-8d9b60863b10270=1000.00271=3.10000000269=1278=14f89bd5-0233-435c-b608-2e19131b8f6c270=1000.00271=3.1000000010=052
20250411-02:06:43.225062000 : 8=FIXT.1.19=14235=334=4249=24ab46f784d1b20db435b852086e325052=20250411-02:06:43.22456=Coinbase45=18958=Tag appears more than once371=269372=W373=1310=049
20250411-02:06:43.225153000 : 8=FIXT.1.19=93935=W49=Coinbase56=24ab46f784d1b20db435b852086e325034=19050=TEST52=20250411-02:06:42.846723369=2262=ecae6588-1a56-49ad-9a18-1bac314fe7a483=1597589724893=N55=BTC-USD1682=full_trading268=10269=1278=a2e319e5-aab7-41d4-9d19-98d771a3f1d3270=1000.00271=3.10000000269=1278=dc965e0b-075a-4ba4-a498-02c96d1664ba270=1000.00271=3.10000000269=1278=67b6e68f-ac11-4c05-a54a-2adb555b0123270=1000.00271=3.10000000269=1278=866f52a1-dad9-49d7-ac4a-9da3075407a3270=1000.00271=3.10000000269=1278=0e38234d-a010-40f6-9c6f-a0d574e773cf270=1000.00271=3.10000000269=1278=d6af6749-e3c8-4938-8741-1d5f177cf8e1270=1000.00271=3.10000000269=1278=45ff5e59-2c4d-45ac-9fde-403662dfd1ca270=1000.00271=3.10000000269=1278=dcac314e-c54f-44e3-b96d-ef71539766ed270=1000.00271=3.10000000269=1278=dd6d14ea-760f-4884-a546-1d3c40ebdd7c270=1000.00271=3.10000000269=1278=4f3da0c6-46eb-4b64-b973-cc43e24abccb270=1000.00271=3.1000000010=122
20250411-02:06:43.225856000 : 8=FIXT.1.19=14235=334=4349=24ab46f784d1b20db435b852086e325052=20250411-02:06:43.22556=Coinbase45=19058=Tag appears more than once371=269372=W373=1310=043
20250411-02:06:43.225946000 : 8=FIXT.1.19=95135=W49=Coinbase56=24ab46f784d1b20db435b852086e325034=19150=TEST52=20250411-02:06:42.846973369=2262=ecae6588-1a56-49ad-9a18-1bac314fe7a483=1597589724893=N55=BTC-USD1682=full_trading268=10269=1278=aa40cda8-4abd-4f52-999a-1a90ed5bf41a270=1000.00271=3.10000000269=1278=687ee4fc-f626-4e4f-abee-1f0ee5af3f72270=1000.00271=3.10000000269=1278=b1ad1135-67ec-4c96-99cb-a626137f3f16270=10000.00271=1.00000000269=1278=e9320f5f-80ae-41ab-af7a-86518d456fb0270=10000.00271=1.00000000269=1278=cd95aff0-36fa-4804-887f-2c3fce3cdc86270=10000.00271=1.00000000269=1278=fbdbcee1-8c29-4478-97df-358d209d8808270=10000.00271=1.00000000269=1278=140f39da-834b-4e42-8e15-6e25287df1f0270=900000.00271=0.00011111269=1278=49f064c5-76fe-4b38-bede-48b60a0a5aec270=900000.00271=0.00011111269=1278=681cf73b-9d37-4101-b940-9da9b1ff61ed270=900000.00271=0.00011111269=1278=3dea1587-e474-4258-b6e8-485c21b56670270=900000.00271=0.0001111110=066
20250411-02:06:43.226659000 : 8=FIXT.1.19=14235=334=4449=24ab46f784d1b20db435b852086e325052=20250411-02:06:43.22656=Coinbase45=19158=Tag appears more than once371=269372=W373=1310=046
20250411-02:06:43.226846000 : 8=FIXT.1.19=95935=W49=Coinbase56=24ab46f784d1b20db435b852086e325034=19250=TEST52=20250411-02:06:42.847223369=2262=ecae6588-1a56-49ad-9a18-1bac314fe7a483=1597589724893=N55=BTC-USD1682=full_trading268=10269=1278=afd96a7b-3d48-459e-b810-e4ee88353a31270=900000.00271=0.00011111269=1278=a68ae029-b920-4ae7-a775-ccdb800fc252270=900000.00271=0.00001111269=1278=d44508b7-1c9f-4b4f-acb8-99c93d2b99e8270=900000.00271=0.00001111269=1278=304ff106-de40-4381-89c5-c93f7f3e32ae270=900000.00271=0.00001111269=1278=08a0fef8-fcbb-4857-8463-2599cf331386270=900000.00271=0.00011111269=1278=07b2856d-f899-417c-82d5-886f0d85125e270=900000.00271=0.00011111269=1278=12ecb45e-6af8-4804-a942-5c997b9d1502270=900000.00271=0.00011111269=1278=98676c5f-b851-473c-817a-b29243092a25270=900000.00271=0.00001111269=1278=09afe685-e71f-4ea0-b164-c27737db126d270=900000.00271=0.00001111269=1278=e71ee98f-c329-428d-9893-629b53015ff6270=900000.00271=0.0000111110=188
20250411-02:06:43.227522000 : 8=FIXT.1.19=14235=334=4549=24ab46f784d1b20db435b852086e325052=20250411-02:06:43.22756=Coinbase45=19258=Tag appears more than once371=269372=W373=1310=049
