20250411-01:58:31.149855000 : 8=FIXT.1.19=29035=X49=Coinbase56=24ab46f784d1b20db435b852086e325034=38550=TEST52=20250411-01:58:31.033231369=46262=9476afd5-fdba-42be-bb0c-485d57b711d5268=1279=2269=1278=ebd04cc3-cb9b-4dea-afd8-21428afe3f9c83=159757967255=BTC-USD270=3.34271=0.0000000060=20250411-01:58:31.03198058=FILLED10=016
20250411-01:58:31.176844000 : 8=FIXT.1.19=27935=X49=Coinbase56=24ab46f784d1b20db435b852086e325034=38650=TEST52=20250411-01:58:31.061697369=46262=9476afd5-fdba-42be-bb0c-485d57b711d5268=1279=0269=083=159757967355=BTC-USD29004=2.208895519560=20250411-01:58:31.06024940=137=e3c51d91-179c-4455-b025-5e47b442813510=137
20250411-01:58:31.177304000 : 8=FIXT.1.19=32735=X49=Coinbase56=24ab46f784d1b20db435b852086e325034=38750=TEST52=20250411-01:58:31.061706369=46262=9476afd5-fdba-42be-bb0c-485d57b711d5268=1279=0269=2278=c5b88ea9-605d-4595-ac52-f7c3f08523ba83=159757967455=BTC-USD270=3.55271=0.6222240960=20250411-01:58:31.06024937=e3c51d91-179c-4455-b025-5e47b44281355797=110=019
20250411-01:58:31.177491000 : 8=FIXT.1.19=26635=X49=Coinbase56=24ab46f784d1b20db435b852086e325034=38850=TEST52=20250411-01:58:31.061711369=46262=9476afd5-fdba-42be-bb0c-485d57b711d5268=1279=2269=0278=e3c51d91-179c-4455-b025-5e47b442813583=159757967555=BTC-USD60=20250411-01:58:31.06024958=FILLED10=140
20250411-01:58:31.205599000 : 8=FIXT.1.19=27535=X49=Coinbase56=24ab46f784d1b20db435b852086e325034=38950=TEST52=20250411-01:58:31.090278369=46262=9476afd5-fdba-42be-bb0c-485d57b711d5268=1279=0269=183=159757967655=BTC-USD271=0.6197183160=20250411-01:58:31.08880640=137=348d33b4-7b96-4c53-b7ef-3359f82c400710=039
20250411-01:58:31.206046000 : 8=FIXT.1.19=32735=X49=Coinbase56=24ab46f784d1b20db435b852086e325034=39050=TEST52=20250411-01:58:31.090284369=46262=9476afd5-fdba-42be-bb0c-485d57b711d5268=1279=0269=2278=4d60a78e-b39b-420e-b830-bc0f3f4fdde283=159757967755=BTC-USD270=3.53271=0.6197183160=20250411-01:58:31.08880637=348d33b4-7b96-4c53-b7ef-3359f82c40075797=210=016
20250411-01:58:31.206266000 : 8=FIXT.1.19=28135=X49=Coinbase56=24ab46f784d1b20db435b852086e325034=39150=TEST52=20250411-01:58:31.090288369=46262=9476afd5-fdba-42be-bb0c-485d57b711d5268=1279=2269=1278=348d33b4-7b96-4c53-b7ef-3359f82c400783=159757967855=BTC-USD271=0.0000000060=20250411-01:58:31.08880658=FILLED10=189
20250411-01:58:31.458513000 : 8=FIXT.1.19=28435=X49=Coinbase56=24ab46f784d1b20db435b852086e325034=39250=TEST52=20250411-01:58:31.342553369=46262=9476afd5-fdba-42be-bb0c-485d57b711d5268=1279=0269=083=159757967955=BTC-USD270=3.88271=0.6232294660=20250411-01:58:31.34119340=237=1124c5b9-560c-4dc9-b319-23f4d69d911110=175
20250411-01:58:31.459106000 : 8=FIXT.1.19=32735=X49=Coinbase56=24ab46f784d1b20db435b852086e325034=39350=TEST52=20250411-01:58:31.342605369=46262=9476afd5-fdba-42be-bb0c-485d57b711d5268=1279=0269=2278=c5b88ea9-605d-4595-ac52-f7c3f08523ba83=159757968055=BTC-USD270=3.55271=0.6232294660=20250411-01:58:31.34119337=1124c5b9-560c-4dc9-b319-23f4d69d91115797=110=114
20250411-01:58:31.459284000 : 8=FIXT.1.19=29035=X49=Coinbase56=24ab46f784d1b20db435b852086e325034=39450=TEST52=20250411-01:58:31.342609369=46262=9476afd5-fdba-42be-bb0c-485d57b711d5268=1279=2269=0278=1124c5b9-560c-4dc9-b319-23f4d69d911183=159757968155=BTC-USD270=3.88271=0.0000000060=20250411-01:58:31.34119358=FILLED10=071
20250411-01:58:31.936986000 : 8=FIXT.1.19=27935=X49=Coinbase56=24ab46f784d1b20db435b852086e325034=39550=TEST52=20250411-01:58:31.805506369=46262=9476afd5-fdba-42be-bb0c-485d57b711d5268=1279=0269=083=159757968255=BTC-USD29004=2.208895519560=20250411-01:58:31.80388740=137=a84e6aa5-44f8-4538-b56c-fca39d4431fa10=183
20250411-01:58:31.937938000 : 8=FIXT.1.19=32735=X49=Coinbase56=24ab46f784d1b20db435b852086e325034=39650=TEST52=20250411-01:58:31.805517369=46262=9476afd5-fdba-42be-bb0c-485d57b711d5268=1279=0269=2278=c5b88ea9-605d-4595-ac52-f7c3f08523ba83=159757968355=BTC-USD270=3.55271=0.6222240960=20250411-01:58:31.80388737=a84e6aa5-44f8-4538-b56c-fca39d4431fa5797=110=076
20250411-01:58:31.938121000 : 8=FIXT.1.19=26635=X49=Coinbase56=24ab46f784d1b20db435b852086e325034=39750=TEST52=20250411-01:58:31.805520369=46262=9476afd5-fdba-42be-bb0c-485d57b711d5268=1279=2269=0278=a84e6aa5-44f8-4538-b56c-fca39d4431fa83=159757968455=BTC-USD60=20250411-01:58:31.80388758=FILLED10=195
20250411-01:58:31.947322000 : 8=FIXT.1.19=27535=X49=Coinbase56=24ab46f784d1b20db435b852086e325034=39850=TEST52=20250411-01:58:31.831890369=46262=9476afd5-fdba-42be-bb0c-485d57b711d5268=1279=0269=183=159757968555=BTC-USD271=0.6197183160=20250411-01:58:31.83076440=137=8a527013-a7c6-43d6-9f33-3b90c3c7a0c310=067
20250411-01:58:31.947500000 : 8=FIXT.1.19=32735=X49=Coinbase56=24ab46f784d1b20db435b852086e325034=39950=TEST52=20250411-01:58:31.831900369=46262=9476afd5-fdba-42be-bb0c-485d57b711d5268=1279=0269=2278=4d60a78e-b39b-420e-b830-bc0f3f4fdde283=159757968655=BTC-USD270=3.53271=0.6197183160=20250411-01:58:31.83076437=8a527013-a7c6-43d6-9f33-3b90c3c7a0c35797=210=048
20250411-01:58:31.947720000 : 8=FIXT.1.19=28135=X49=Coinbase56=24ab46f784d1b20db435b852086e325034=40050=TEST52=20250411-01:58:31.831947369=46262=9476afd5-fdba-42be-bb0c-485d57b711d5268=1279=2269=1278=8a527013-a7c6-43d6-9f33-3b90c3c7a0c383=159757968755=BTC-USD271=0.0000000060=20250411-01:58:31.83076458=FILLED10=210
20250411-01:58:32.598383000 : 8=FIXT.1.19=31035=X49=Coinbase56=24ab46f784d1b20db435b852086e325034=40150=TEST52=20250411-01:58:32.482590369=46262=9476afd5-fdba-42be-bb0c-485d57b711d5268=1279=1269=1278=582969d2-8318-4a7d-b8bb-01d0f62df42083=159757968855=BTC-USD270=3.67271=0.3994022660=20250411-01:58:32.48124558=CHANGE_REASON_MODIFY_ORDER10=184
20250411-01:58:32.883841000 : 8=FIXT.1.19=30935=X49=Coinbase56=24ab46f784d1b20db435b852086e325034=40250=TEST52=20250411-01:58:32.768401369=46262=9476afd5-fdba-42be-bb0c-485d57b711d5268=1279=1269=0278=53df6705-3c5d-4895-881d-6a43ab91b73e83=159757968955=BTC-USD270=3.4271=0.4201016860=20250411-01:58:32.76710458=CHANGE_REASON_MODIFY_ORDER10=134
20250411-01:58:32.891169000 : 8=FIXT.1.19=27935=X49=Coinbase56=24ab46f784d1b20db435b852086e325034=40350=TEST52=20250411-01:58:32.775420369=46262=9476afd5-fdba-42be-bb0c-485d57b711d5268=1279=0269=083=159757969055=BTC-USD29004=2.208895519560=20250411-01:58:32.77387540=137=548c76c7-4dc4-4045-9854-48ffa297ac7210=005
20250411-01:58:32.891418000 : 8=FIXT.1.19=32735=X49=Coinbase56=24ab46f784d1b20db435b852086e325034=40450=TEST52=20250411-01:58:32.775480369=46262=9476afd5-fdba-42be-bb0c-485d57b711d5268=1279=0269=2278=c5b88ea9-605d-4595-ac52-f7c3f08523ba83=159757969155=BTC-USD270=3.55271=0.6222240960=20250411-01:58:32.77387537=548c76c7-4dc4-4045-9854-48ffa297ac725797=110=158
20250411-01:58:32.891632000 : 8=FIXT.1.19=26635=X49=Coinbase56=24ab46f784d1b20db435b852086e325034=40550=TEST52=20250411-01:58:32.775487369=46262=9476afd5-fdba-42be-bb0c-485d57b711d5268=1279=2269=0278=548c76c7-4dc4-4045-9854-48ffa297ac7283=159757969255=BTC-USD60=20250411-01:58:32.77387558=FILLED10=034
20250411-01:58:32.920609000 : 8=FIXT.1.19=27535=X49=Coinbase56=24ab46f784d1b20db435b852086e325034=40650=TEST52=20250411-01:58:32.804833369=46262=9476afd5-fdba-42be-bb0c-485d57b711d5268=1279=0269=183=159757969355=BTC-USD271=0.6232294660=20250411-01:58:32.80291540=137=b8520925-f325-4f54-ba31-bfd55a3e702710=053
20250411-01:58:32.920853000 : 8=FIXT.1.19=32735=X49=Coinbase56=24ab46f784d1b20db435b852086e325034=40750=TEST52=20250411-01:58:32.804840369=46262=9476afd5-fdba-42be-bb0c-485d57b711d5268=1279=0269=2278=4d60a78e-b39b-420e-b830-bc0f3f4fdde283=159757969455=BTC-USD270=3.53271=0.6232294660=20250411-01:58:32.80291537=b8520925-f325-4f54-ba31-bfd55a3e70275797=210=040
20250411-01:58:32.921089000 : 8=FIXT.1.19=28135=X49=Coinbase56=24ab46f784d1b20db435b852086e325034=40850=TEST52=20250411-01:58:32.804843369=46262=9476afd5-fdba-42be-bb0c-485d57b711d5268=1279=2269=1278=b8520925-f325-4f54-ba31-bfd55a3e702783=159757969555=BTC-USD271=0.0000000060=20250411-01:58:32.80291558=FILLED10=214
20250411-01:58:33.005100000 : 8=FIXT.1.19=27935=X49=Coinbase56=24ab46f784d1b20db435b852086e325034=40950=TEST52=20250411-01:58:32.889381369=46262=9476afd5-fdba-42be-bb0c-485d57b711d5268=1279=0269=083=159757969655=BTC-USD29004=2.208895519560=20250411-01:58:32.88811240=137=cf59c6aa-15fc-4f2c-942a-e3e5fb2d83c010=073
20250411-01:58:33.005405000 : 8=FIXT.1.19=32735=X49=Coinbase56=24ab46f784d1b20db435b852086e325034=41050=TEST52=20250411-01:58:32.889386369=46262=9476afd5-fdba-42be-bb0c-485d57b711d5268=1279=0269=2278=c5b88ea9-605d-4595-ac52-f7c3f08523ba83=159757969755=BTC-USD270=3.55271=0.6222240960=20250411-01:58:32.88811237=cf59c6aa-15fc-4f2c-942a-e3e5fb2d83c05797=110=216
20250411-01:58:33.005636000 : 8=FIXT.1.19=26635=X49=Coinbase56=24ab46f784d1b20db435b852086e325034=41150=TEST52=20250411-01:58:32.889390369=46262=9476afd5-fdba-42be-bb0c-485d57b711d5268=1279=2269=0278=cf59c6aa-15fc-4f2c-942a-e3e5fb2d83c083=159757969855=BTC-USD60=20250411-01:58:32.88811258=FILLED10=080
20250411-01:58:33.035195000 : 8=FIXT.1.19=27535=X49=Coinbase56=24ab46f784d1b20db435b852086e325034=41250=TEST52=20250411-01:58:32.919040369=46262=9476afd5-fdba-42be-bb0c-485d57b711d5268=1279=0269=183=159757969955=BTC-USD271=0.6232294660=20250411-01:58:32.91686240=137=ccda4f30-3c1c-495e-9aea-002a576d830610=197
20250411-01:58:33.036258000 : 8=FIXT.1.19=32735=X49=Coinbase56=24ab46f784d1b20db435b852086e325034=41350=TEST52=20250411-01:58:32.919048369=46262=9476afd5-fdba-42be-bb0c-485d57b711d5268=1279=0269=2278=4d60a78e-b39b-420e-b830-bc0f3f4fdde283=159757970055=BTC-USD270=3.53271=0.6232294660=20250411-01:58:32.91686237=ccda4f30-3c1c-495e-9aea-002a576d83065797=210=176
20250411-01:58:33.037028000 : 8=FIXT.1.19=28135=X49=Coinbase56=24ab46f784d1b20db435b852086e325034=41450=TEST52=20250411-01:58:32.919050369=46262=9476afd5-fdba-42be-bb0c-485d57b711d5268=1279=2269=1278=ccda4f30-3c1c-495e-9aea-002a576d830683=159757970155=BTC-USD271=0.0000000060=20250411-01:58:32.91686258=FILLED10=084
20250411-01:58:33.119541000 : 8=FIXT.1.19=27935=X49=Coinbase56=24ab46f784d1b20db435b852086e325034=41550=TEST52=20250411-01:58:33.003598369=46262=9476afd5-fdba-42be-bb0c-485d57b711d5268=1279=0269=083=159757970255=BTC-USD29004=2.208895519560=20250411-01:58:33.00264740=137=4dc87e47-7d6b-4d52-af9d-1d8721328dd410=121
20250411-01:58:33.120270000 : 8=FIXT.1.19=32735=X49=Coinbase56=24ab46f784d1b20db435b852086e325034=41650=TEST52=20250411-01:58:33.003606369=46262=9476afd5-fdba-42be-bb0c-485d57b711d5268=1279=0269=2278=c5b88ea9-605d-4595-ac52-f7c3f08523ba83=159757970355=BTC-USD270=3.55271=0.6222240960=20250411-01:58:33.00264737=4dc87e47-7d6b-4d52-af9d-1d8721328dd45797=110=002
20250411-01:58:33.120588000 : 8=FIXT.1.19=26635=X49=Coinbase56=24ab46f784d1b20db435b852086e325034=41750=TEST52=20250411-01:58:33.003609369=46262=9476afd5-fdba-42be-bb0c-485d57b711d5268=1279=2269=0278=4dc87e47-7d6b-4d52-af9d-1d8721328dd483=159757970455=BTC-USD60=20250411-01:58:33.00264758=FILLED10=130
20250411-01:58:33.148042000 : 8=FIXT.1.19=27535=X49=Coinbase56=24ab46f784d1b20db435b852086e325034=41850=TEST52=20250411-01:58:33.031990369=46262=9476afd5-fdba-42be-bb0c-485d57b711d5268=1279=0269=183=159757970555=BTC-USD271=0.6232294660=20250411-01:58:33.03076940=137=d52dc3ef-ee48-4522-b0b4-f557def880b110=250
20250411-01:58:33.148485000 : 8=FIXT.1.19=32735=X49=Coinbase56=24ab46f784d1b20db435b852086e325034=41950=TEST52=20250411-01:58:33.032124369=46262=9476afd5-fdba-42be-bb0c-485d57b711d5268=1279=0269=2278=4d60a78e-b39b-420e-b830-bc0f3f4fdde283=159757970655=BTC-USD270=3.53271=0.6232294660=20250411-01:58:33.03076937=d52dc3ef-ee48-4522-b0b4-f557def880b15797=210=229
20250411-01:58:33.148707000 : 8=FIXT.1.19=28135=X49=Coinbase56=24ab46f784d1b20db435b852086e325034=42050=TEST52=20250411-01:58:33.032127369=46262=9476afd5-fdba-42be-bb0c-485d57b711d5268=1279=2269=1278=d52dc3ef-ee48-4522-b0b4-f557def880b183=159757970755=BTC-USD271=0.0000000060=20250411-01:58:33.03076958=FILLED10=138
20250411-01:58:33.171029000 : 8=FIXT.1.19=31035=X49=Coinbase56=24ab46f784d1b20db435b852086e325034=42150=TEST52=20250411-01:58:33.055150369=46262=9476afd5-fdba-42be-bb0c-485d57b711d5268=1279=1269=0278=4e6f389b-e251-4fa6-833c-4d41ac01f9cc83=159757970855=BTC-USD270=3.46271=0.4111309360=20250411-01:58:33.05309158=CHANGE_REASON_MODIFY_ORDER10=033
20250411-01:58:33.292537000 : 8=FIXT.1.19=27935=X49=Coinbase56=24ab46f784d1b20db435b852086e325034=42250=TEST52=20250411-01:58:33.177083369=46262=9476afd5-fdba-42be-bb0c-485d57b711d5268=1279=0269=083=159757970955=BTC-USD29004=2.208895519560=20250411-01:58:33.17525640=137=71fd83e2-8ef0-407b-aecc-71e087d43a1310=162
20250411-01:58:33.293035000 : 8=FIXT.1.19=32735=X49=Coinbase56=24ab46f784d1b20db435b852086e325034=42350=TEST52=20250411-01:58:33.177091369=46262=9476afd5-fdba-42be-bb0c-485d57b711d5268=1279=0269=2278=c5b88ea9-605d-4595-ac52-f7c3f08523ba83=159757971055=BTC-USD270=3.55271=0.6222240960=20250411-01:58:33.17525637=71fd83e2-8ef0-407b-aecc-71e087d43a135797=110=043
20250411-01:58:33.293193000 : 8=FIXT.1.19=26635=X49=Coinbase56=24ab46f784d1b20db435b852086e325034=42450=TEST52=20250411-01:58:33.177107369=46262=9476afd5-fdba-42be-bb0c-485d57b711d5268=1279=2269=0278=71fd83e2-8ef0-407b-aecc-71e087d43a1383=159757971155=BTC-USD60=20250411-01:58:33.17525658=FILLED10=166
20250411-01:58:33.319991000 : 8=FIXT.1.19=27535=X49=Coinbase56=24ab46f784d1b20db435b852086e325034=42550=TEST52=20250411-01:58:33.204418369=46262=9476afd5-fdba-42be-bb0c-485d57b711d5268=1279=0269=183=159757971255=BTC-USD271=0.6232294660=20250411-01:58:33.20253440=137=e191aa5d-9e6d-46cf-b7ef-da97f8d64f6510=098
20250411-01:58:33.320378000 : 8=FIXT.1.19=32735=X49=Coinbase56=24ab46f784d1b20db435b852086e325034=42650=TEST52=20250411-01:58:33.204478369=46262=9476afd5-fdba-42be-bb0c-485d57b711d5268=1279=0269=2278=4d60a78e-b39b-420e-b830-bc0f3f4fdde283=159757971355=BTC-USD270=3.53271=0.6232294660=20250411-01:58:33.20253437=e191aa5d-9e6d-46cf-b7ef-da97f8d64f655797=210=093
20250411-01:58:33.320583000 : 8=FIXT.1.19=28135=X49=Coinbase56=24ab46f784d1b20db435b852086e325034=42750=TEST52=20250411-01:58:33.204483369=46262=9476afd5-fdba-42be-bb0c-485d57b711d5268=1279=2269=1278=e191aa5d-9e6d-46cf-b7ef-da97f8d64f6583=159757971455=BTC-USD271=0.0000000060=20250411-01:58:33.20253458=FILLED10=004
20250411-01:58:33.457283000 : 8=FIXT.1.19=31035=X49=Coinbase56=24ab46f784d1b20db435b852086e325034=42850=TEST52=20250411-01:58:33.341401369=46262=9476afd5-fdba-42be-bb0c-485d57b711d5268=1279=1269=1278=0168d414-071e-4176-8910-3b2fad61ee2083=159757971555=BTC-USD270=3.55271=0.5017110360=20250411-01:58:33.33937958=CHANGE_REASON_MODIFY_ORDER10=049
20250411-01:58:33.551266000 : 8=FIXT.1.19=28435=X49=Coinbase56=24ab46f784d1b20db435b852086e325034=42950=TEST52=20250411-01:58:33.435256369=46262=9476afd5-fdba-42be-bb0c-485d57b711d5268=1279=0269=183=159757971655=BTC-USD270=3.33271=0.6232294660=20250411-01:58:33.43375540=237=d4df9e3e-7acf-42d0-85f3-a42a61a6a43e10=202
20250411-01:58:33.551996000 : 8=FIXT.1.19=32735=X49=Coinbase56=24ab46f784d1b20db435b852086e325034=43050=TEST52=20250411-01:58:33.435349369=46262=9476afd5-fdba-42be-bb0c-485d57b711d5268=1279=0269=2278=4d60a78e-b39b-420e-b830-bc0f3f4fdde283=159757971755=BTC-USD270=3.53271=0.6232294660=20250411-01:58:33.43375537=d4df9e3e-7acf-42d0-85f3-a42a61a6a43e5797=210=026
20250411-01:58:33.552342000 : 8=FIXT.1.19=29035=X49=Coinbase56=24ab46f784d1b20db435b852086e325034=43150=TEST52=20250411-01:58:33.435401369=46262=9476afd5-fdba-42be-bb0c-485d57b711d5268=1279=2269=1278=d4df9e3e-7acf-42d0-85f3-a42a61a6a43e83=159757971855=BTC-USD270=3.33271=0.0000000060=20250411-01:58:33.43375558=FILLED10=088
20250411-01:58:33.563891000 : 8=FIXT.1.19=29235=X49=Coinbase56=24ab46f784d1b20db435b852086e325034=43250=TEST52=20250411-01:58:33.448771369=46262=9476afd5-fdba-42be-bb0c-485d57b711d5268=1279=2269=1278=6937c912-4891-4676-9841-7b686b517ade83=159757971955=BTC-USD270=3.59271=0.6232294660=20250411-01:58:33.44684358=CANCELED10=138
20250411-01:58:33.605415000 : 8=FIXT.1.19=28435=X49=Coinbase56=24ab46f784d1b20db435b852086e325034=43350=TEST52=20250411-01:58:33.489959369=46262=9476afd5-fdba-42be-bb0c-485d57b711d5268=1279=0269=083=159757972055=BTC-USD270=3.81271=0.6232294660=20250411-01:58:33.48826040=237=c7dc21c7-6404-44bd-8b4c-ca061168a0b610=056
20250411-01:58:33.605939000 : 8=FIXT.1.19=32735=X49=Coinbase56=24ab46f784d1b20db435b852086e325034=43450=TEST52=20250411-01:58:33.489968369=46262=9476afd5-fdba-42be-bb0c-485d57b711d5268=1279=0269=2278=c5b88ea9-605d-4595-ac52-f7c3f08523ba83=159757972155=BTC-USD270=3.55271=0.6232294660=20250411-01:58:33.48826037=c7dc21c7-6404-44bd-8b4c-ca061168a0b65797=110=013
20250411-01:58:33.606158000 : 8=FIXT.1.19=29035=X49=Coinbase56=24ab46f784d1b20db435b852086e325034=43550=TEST52=20250411-01:58:33.489971369=46262=9476afd5-fdba-42be-bb0c-485d57b711d5268=1279=2269=0278=c7dc21c7-6404-44bd-8b4c-ca061168a0b683=159757972255=BTC-USD270=3.81271=0.0000000060=20250411-01:58:33.48826058=FILLED10=209
20250411-01:58:33.664266000 : 8=FIXT.1.19=28435=X49=Coinbase56=24ab46f784d1b20db435b852086e325034=43650=TEST52=20250411-01:58:33.548128369=46262=9476afd5-fdba-42be-bb0c-485d57b711d5268=1279=0269=083=159757972355=BTC-USD270=3.77271=0.6197183160=20250411-01:58:33.54714840=237=d3597d17-8843-44e8-b80b-15ca9735cf5c10=251
20250411-01:58:33.664788000 : 8=FIXT.1.19=32735=X49=Coinbase56=24ab46f784d1b20db435b852086e325034=43750=TEST52=20250411-01:58:33.548136369=46262=9476afd5-fdba-42be-bb0c-485d57b711d5268=1279=0269=2278=c5b88ea9-605d-4595-ac52-f7c3f08523ba83=159757972455=BTC-USD270=3.55271=0.6197183160=20250411-01:58:33.54714837=d3597d17-8843-44e8-b80b-15ca9735cf5c5797=110=202
20250411-01:58:33.664999000 : 8=FIXT.1.19=29035=X49=Coinbase56=24ab46f784d1b20db435b852086e325034=43850=TEST52=20250411-01:58:33.548186369=46262=9476afd5-fdba-42be-bb0c-485d57b711d5268=1279=2269=0278=d3597d17-8843-44e8-b80b-15ca9735cf5c83=159757972555=BTC-USD270=3.77271=0.0000000060=20250411-01:58:33.54714858=FILLED10=156
20250411-01:58:33.718752000 : 8=FIXT.1.19=28435=X49=Coinbase56=24ab46f784d1b20db435b852086e325034=43950=TEST52=20250411-01:58:33.602800369=46262=9476afd5-fdba-42be-bb0c-485d57b711d5268=1279=0269=183=159757972655=BTC-USD270=3.27271=0.6197183160=20250411-01:58:33.60188340=237=ab5eaf49-7136-4eb9-b708-ab49bc05922610=063
20250411-01:58:33.719138000 : 8=FIXT.1.19=32735=X49=Coinbase56=24ab46f784d1b20db435b852086e325034=44050=TEST52=20250411-01:58:33.602807369=46262=9476afd5-fdba-42be-bb0c-485d57b711d5268=1279=0269=2278=4d60a78e-b39b-420e-b830-bc0f3f4fdde283=159757972755=BTC-USD270=3.53271=0.6197183160=20250411-01:58:33.60188337=ab5eaf49-7136-4eb9-b708-ab49bc0592265797=210=144
20250411-01:58:33.719318000 : 8=FIXT.1.19=29035=X49=Coinbase56=24ab46f784d1b20db435b852086e325034=44150=TEST52=20250411-01:58:33.602810369=46262=9476afd5-fdba-42be-bb0c-485d57b711d5268=1279=2269=1278=ab5eaf49-7136-4eb9-b708-ab49bc05922683=159757972855=BTC-USD270=3.27271=0.0000000060=20250411-01:58:33.60188358=FILLED10=212
20250411-01:58:33.741610000 : 8=FIXT.1.19=31035=X49=Coinbase56=24ab46f784d1b20db435b852086e325034=44250=TEST52=20250411-01:58:33.626025369=46262=9476afd5-fdba-42be-bb0c-485d57b711d5268=1279=1269=0278=b6a1c1a8-fe07-415a-8303-2782e7a5887483=159757972955=BTC-USD270=3.36271=0.4933069960=20250411-01:58:33.62491758=CHANGE_REASON_MODIFY_ORDER10=140
20250411-01:58:33.849344000 : 8=FIXT.1.19=29235=X49=Coinbase56=24ab46f784d1b20db435b852086e325034=44350=TEST52=20250411-01:58:33.733954369=46262=9476afd5-fdba-42be-bb0c-485d57b711d5268=1279=2269=0278=5372b158-73b4-47ff-9c24-1c8df9ea18c383=159757973055=BTC-USD270=3.46271=0.6232294660=20250411-01:58:33.73289358=CANCELED10=096
20250411-01:58:33.892533000 : 8=FIXT.1.19=28335=X49=Coinbase56=24ab46f784d1b20db435b852086e325034=44450=TEST52=20250411-01:58:33.777443369=46262=9476afd5-fdba-42be-bb0c-485d57b711d5268=1279=0269=183=159757973155=BTC-USD270=3.2271=0.6232294660=20250411-01:58:33.77573740=237=b76cad09-2e99-4bf2-bd14-b7bbafa2775910=168
20250411-01:58:33.892755000 : 8=FIXT.1.19=32735=X49=Coinbase56=24ab46f784d1b20db435b852086e325034=44550=TEST52=20250411-01:58:33.777491369=46262=9476afd5-fdba-42be-bb0c-485d57b711d5268=1279=0269=2278=4d60a78e-b39b-420e-b830-bc0f3f4fdde283=159757973255=BTC-USD270=3.53271=0.6232294660=20250411-01:58:33.77573737=b76cad09-2e99-4bf2-bd14-b7bbafa277595797=210=054
20250411-01:58:33.893079000 : 8=FIXT.1.19=28935=X49=Coinbase56=24ab46f784d1b20db435b852086e325034=44650=TEST52=20250411-01:58:33.777497369=46262=9476afd5-fdba-42be-bb0c-485d57b711d5268=1279=2269=1278=b76cad09-2e99-4bf2-bd14-b7bbafa2775983=159757973355=BTC-USD270=3.2271=0.0000000060=20250411-01:58:33.77573758=FILLED10=089
20250411-01:58:33.948822000 : 8=FIXT.1.19=28435=X49=Coinbase56=24ab46f784d1b20db435b852086e325034=44750=TEST52=20250411-01:58:33.832762369=46262=9476afd5-fdba-42be-bb0c-485d57b711d5268=1279=0269=083=159757973455=BTC-USD270=3.73271=0.6232294660=20250411-01:58:33.83131140=237=f85a4cd3-7957-4615-b361-dc9a8e1111dd10=014
20250411-01:58:33.949454000 : 8=FIXT.1.19=32735=X49=Coinbase56=24ab46f784d1b20db435b852086e325034=44850=TEST52=20250411-01:58:33.832773369=46262=9476afd5-fdba-42be-bb0c-485d57b711d5268=1279=0269=2278=c5b88ea9-605d-4595-ac52-f7c3f08523ba83=159757973555=BTC-USD270=3.55271=0.6232294660=20250411-01:58:33.83131137=f85a4cd3-7957-4615-b361-dc9a8e1111dd5797=110=228
20250411-01:58:33.949670000 : 8=FIXT.1.19=29035=X49=Coinbase56=24ab46f784d1b20db435b852086e325034=44950=TEST52=20250411-01:58:33.832776369=46262=9476afd5-fdba-42be-bb0c-485d57b711d5268=1279=2269=0278=f85a4cd3-7957-4615-b361-dc9a8e1111dd83=159757973655=BTC-USD270=3.73271=0.0000000060=20250411-01:58:33.83131158=FILLED10=178
20250411-01:58:34.136539000 : 8=FIXT.1.19=29235=X49=Coinbase56=24ab46f784d1b20db435b852086e325034=45050=TEST52=20250411-01:58:34.020366369=46262=9476afd5-fdba-42be-bb0c-485d57b711d5268=1279=2269=0278=3daa45cc-1b85-4a14-be19-fc8c8f23ff6683=159757973755=BTC-USD270=3.39271=0.6232294660=20250411-01:58:34.01848358=CANCELED10=007
20250411-01:58:34.321285000 : 8=FIXT.1.19=27935=X49=Coinbase56=24ab46f784d1b20db435b852086e325034=45150=TEST52=20250411-01:58:34.204874369=46262=9476afd5-fdba-42be-bb0c-485d57b711d5268=1279=0269=083=159757973855=BTC-USD29004=2.208895519560=20250411-01:58:34.20298540=137=51f4a9f4-9f15-4c2f-8f53-92f727d53a7d10=098
20250411-01:58:34.321818000 : 8=FIXT.1.19=32735=X49=Coinbase56=24ab46f784d1b20db435b852086e325034=45250=TEST52=20250411-01:58:34.204937369=46262=9476afd5-fdba-42be-bb0c-485d57b711d5268=1279=0269=2278=c5b88ea9-605d-4595-ac52-f7c3f08523ba83=159757973955=BTC-USD270=3.55271=0.6222240960=20250411-01:58:34.20298537=51f4a9f4-9f15-4c2f-8f53-92f727d53a7d5797=110=245
20250411-01:58:34.322029000 : 8=FIXT.1.19=26635=X49=Coinbase56=24ab46f784d1b20db435b852086e325034=45350=TEST52=20250411-01:58:34.204952369=46262=9476afd5-fdba-42be-bb0c-485d57b711d5268=1279=2269=0278=51f4a9f4-9f15-4c2f-8f53-92f727d53a7d83=159757974055=BTC-USD60=20250411-01:58:34.20298558=FILLED10=102
20250411-01:58:34.348685000 : 8=FIXT.1.19=27535=X49=Coinbase56=24ab46f784d1b20db435b852086e325034=45450=TEST52=20250411-01:58:34.232288369=46262=9476afd5-fdba-42be-bb0c-485d57b711d5268=1279=0269=183=159757974155=BTC-USD271=0.6197183160=20250411-01:58:34.23085840=137=73478919-cf09-4f4d-8774-95ea1f67e04a10=046
20250411-01:58:34.349131000 : 8=FIXT.1.19=32735=X49=Coinbase56=24ab46f784d1b20db435b852086e325034=45550=TEST52=20250411-01:58:34.232379369=46262=9476afd5-fdba-42be-bb0c-485d57b711d5268=1279=0269=2278=4d60a78e-b39b-420e-b830-bc0f3f4fdde283=159757974255=BTC-USD270=3.53271=0.6197183160=20250411-01:58:34.23085837=73478919-cf09-4f4d-8774-95ea1f67e04a5797=210=036
20250411-01:58:34.349318000 : 8=FIXT.1.19=28135=X49=Coinbase56=24ab46f784d1b20db435b852086e325034=45650=TEST52=20250411-01:58:34.232382369=46262=9476afd5-fdba-42be-bb0c-485d57b711d5268=1279=2269=1278=73478919-cf09-4f4d-8774-95ea1f67e04a83=159757974355=BTC-USD271=0.0000000060=20250411-01:58:34.23085858=FILLED10=199
20250411-01:58:34.468747000 : 8=FIXT.1.19=28435=X49=Coinbase56=24ab46f784d1b20db435b852086e325034=45750=TEST52=20250411-01:58:34.352201369=46262=9476afd5-fdba-42be-bb0c-485d57b711d5268=1279=0269=183=159757974455=BTC-USD270=3.19271=0.6232294660=20250411-01:58:34.35067240=237=6e158ce0-ee97-440f-b6cc-211a18611ad610=046
20250411-01:58:34.469088000 : 8=FIXT.1.19=32735=X49=Coinbase56=24ab46f784d1b20db435b852086e325034=45850=TEST52=20250411-01:58:34.352266369=46262=9476afd5-fdba-42be-bb0c-485d57b711d5268=1279=0269=2278=4d60a78e-b39b-420e-b830-bc0f3f4fdde283=159757974555=BTC-USD270=3.53271=0.6232294660=20250411-01:58:34.35067237=6e158ce0-ee97-440f-b6cc-211a18611ad65797=210=139
20250411-01:58:34.469249000 : 8=FIXT.1.19=29035=X49=Coinbase56=24ab46f784d1b20db435b852086e325034=45950=TEST52=20250411-01:58:34.352273369=46262=9476afd5-fdba-42be-bb0c-485d57b711d5268=1279=2269=1278=6e158ce0-ee97-440f-b6cc-211a18611ad683=159757974655=BTC-USD270=3.19271=0.0000000060=20250411-01:58:34.35067258=FILLED10=214
20250411-01:58:34.520898000 : 8=FIXT.1.19=28435=X49=Coinbase56=24ab46f784d1b20db435b852086e325034=46050=TEST52=20250411-01:58:34.404454369=46262=9476afd5-fdba-42be-bb0c-485d57b711d5268=1279=0269=083=159757974755=BTC-USD270=3.86271=0.6232294660=20250411-01:58:34.40265240=237=473c31c0-2d2b-4229-89e8-663294e18ca710=130
20250411-01:58:34.521545000 : 8=FIXT.1.19=32735=X49=Coinbase56=24ab46f784d1b20db435b852086e325034=46150=TEST52=20250411-01:58:34.404463369=46262=9476afd5-fdba-42be-bb0c-485d57b711d5268=1279=0269=2278=c5b88ea9-605d-4595-ac52-f7c3f08523ba83=159757974855=BTC-USD270=3.55271=0.6232294660=20250411-01:58:34.40265237=473c31c0-2d2b-4229-89e8-663294e18ca75797=110=082
20250411-01:58:34.521773000 : 8=FIXT.1.19=29035=X49=Coinbase56=24ab46f784d1b20db435b852086e325034=46250=TEST52=20250411-01:58:34.404467369=46262=9476afd5-fdba-42be-bb0c-485d57b711d5268=1279=2269=0278=473c31c0-2d2b-4229-89e8-663294e18ca783=159757974955=BTC-USD270=3.86271=0.0000000060=20250411-01:58:34.40265258=FILLED10=037
20250411-01:58:34.712621000 : 8=FIXT.1.19=29235=X49=Coinbase56=24ab46f784d1b20db435b852086e325034=46350=TEST52=20250411-01:58:34.591437369=46262=9476afd5-fdba-42be-bb0c-485d57b711d5268=1279=2269=0278=6ca5464b-b3e2-4bc0-a38e-f2b71d50129c83=159757975055=BTC-USD270=3.39271=0.6232294660=20250411-01:58:34.58967958=CANCELED10=179
20250411-01:58:34.777148000 : 8=FIXT.1.19=27935=X49=Coinbase56=24ab46f784d1b20db435b852086e325034=46450=TEST52=20250411-01:58:34.661752369=46262=9476afd5-fdba-42be-bb0c-485d57b711d5268=1279=0269=083=159757975155=BTC-USD29004=2.208895519560=20250411-01:58:34.65982840=137=ddf4a50e-5288-457c-9fbf-418564c00ed110=143
20250411-01:58:34.777659000 : 8=FIXT.1.19=32735=X49=Coinbase56=24ab46f784d1b20db435b852086e325034=46550=TEST52=20250411-01:58:34.661769369=46262=9476afd5-fdba-42be-bb0c-485d57b711d5268=1279=0269=2278=c5b88ea9-605d-4595-ac52-f7c3f08523ba83=159757975255=BTC-USD270=3.55271=0.6222240960=20250411-01:58:34.65982837=ddf4a50e-5288-457c-9fbf-418564c00ed15797=110=042
20250411-01:58:34.778459000 : 8=FIXT.1.19=26635=X49=Coinbase56=24ab46f784d1b20db435b852086e325034=46650=TEST52=20250411-01:58:34.661772369=46262=9476afd5-fdba-42be-bb0c-485d57b711d5268=1279=2269=0278=ddf4a50e-5288-457c-9fbf-418564c00ed183=159757975355=BTC-USD60=20250411-01:58:34.65982858=FILLED10=161
20250411-01:58:34.805018000 : 8=FIXT.1.19=27535=X49=Coinbase56=24ab46f784d1b20db435b852086e325034=46750=TEST52=20250411-01:58:34.689199369=46262=9476afd5-fdba-42be-bb0c-485d57b711d5268=1279=0269=183=159757975455=BTC-USD271=0.6197183160=20250411-01:58:34.68803840=137=fe80217a-37c6-4454-9560-7480c38d523310=166
20250411-01:58:34.805697000 : 8=FIXT.1.19=32735=X49=Coinbase56=24ab46f784d1b20db435b852086e325034=46850=TEST52=20250411-01:58:34.689207369=46262=9476afd5-fdba-42be-bb0c-485d57b711d5268=1279=0269=2278=4d60a78e-b39b-420e-b830-bc0f3f4fdde283=159757975555=BTC-USD270=3.53271=0.6197183160=20250411-01:58:34.68803837=fe80217a-37c6-4454-9560-7480c38d52335797=210=145
20250411-01:58:34.806026000 : 8=FIXT.1.19=28135=X49=Coinbase56=24ab46f784d1b20db435b852086e325034=46950=TEST52=20250411-01:58:34.689210369=46262=9476afd5-fdba-42be-bb0c-485d57b711d5268=1279=2269=1278=fe80217a-37c6-4454-9560-7480c38d523383=159757975655=BTC-USD271=0.0000000060=20250411-01:58:34.68803858=FILLED10=052
20250411-01:58:34.950239000 : 8=FIXT.1.19=27935=X49=Coinbase56=24ab46f784d1b20db435b852086e325034=47050=TEST52=20250411-01:58:34.833620369=46262=9476afd5-fdba-42be-bb0c-485d57b711d5268=1279=0269=083=159757975755=BTC-USD29004=2.208895519560=20250411-01:58:34.83185140=137=d7ecb0b0-d82e-4203-9095-8252786c236710=191
20250411-01:58:34.950943000 : 8=FIXT.1.19=32735=X49=Coinbase56=24ab46f784d1b20db435b852086e325034=47150=TEST52=20250411-01:58:34.833628369=46262=9476afd5-fdba-42be-bb0c-485d57b711d5268=1279=0269=2278=c5b88ea9-605d-4595-ac52-f7c3f08523ba83=159757975855=BTC-USD270=3.55271=0.6222240960=20250411-01:58:34.83185137=d7ecb0b0-d82e-4203-9095-8252786c23675797=110=090
20250411-01:58:34.951235000 : 8=FIXT.1.19=26635=X49=Coinbase56=24ab46f784d1b20db435b852086e325034=47250=TEST52=20250411-01:58:34.833630369=46262=9476afd5-fdba-42be-bb0c-485d57b711d5268=1279=2269=0278=d7ecb0b0-d82e-4203-9095-8252786c236783=159757975955=BTC-USD60=20250411-01:58:34.83185158=FILLED10=208
20250411-01:58:34.980812000 : 8=FIXT.1.19=27535=X49=Coinbase56=24ab46f784d1b20db435b852086e325034=47350=TEST52=20250411-01:58:34.861136369=46262=9476afd5-fdba-42be-bb0c-485d57b711d5268=1279=0269=183=159757976055=BTC-USD271=0.6232294660=20250411-01:58:34.85982440=137=2e8cd7ed-439b-4cfc-8b7a-feeb84b06c0910=164
20250411-01:58:34.981601000 : 8=FIXT.1.19=32735=X49=Coinbase56=24ab46f784d1b20db435b852086e325034=47450=TEST52=20250411-01:58:34.861148369=46262=9476afd5-fdba-42be-bb0c-485d57b711d5268=1279=0269=2278=4d60a78e-b39b-420e-b830-bc0f3f4fdde283=159757976155=BTC-USD270=3.53271=0.6232294660=20250411-01:58:34.85982437=2e8cd7ed-439b-4cfc-8b7a-feeb84b06c095797=210=156
20250411-01:58:34.981786000 : 8=FIXT.1.19=28135=X49=Coinbase56=24ab46f784d1b20db435b852086e325034=47550=TEST52=20250411-01:58:34.861150369=46262=9476afd5-fdba-42be-bb0c-485d57b711d5268=1279=2269=1278=2e8cd7ed-439b-4cfc-8b7a-feeb84b06c0983=159757976255=BTC-USD271=0.0000000060=20250411-01:58:34.85982458=FILLED10=064
20250411-01:58:34.993222000 : 8=FIXT.1.19=29235=X49=Coinbase56=24ab46f784d1b20db435b852086e325034=47650=TEST52=20250411-01:58:34.876557369=46262=9476afd5-fdba-42be-bb0c-485d57b711d5268=1279=2269=1278=878ac31a-dec5-40fb-aaf7-0b605934daf983=159757976355=BTC-USD270=3.57271=0.6232294660=20250411-01:58:34.87531158=CANCELED10=032
20250411-01:58:35.234302000 : 8=FIXT.1.19=27935=X49=Coinbase56=24ab46f784d1b20db435b852086e325034=47750=TEST52=20250411-01:58:35.118549369=46262=9476afd5-fdba-42be-bb0c-485d57b711d5268=1279=0269=083=159757976455=BTC-USD29004=2.208895519560=20250411-01:58:35.11703340=137=fcce5a4e-d0a5-48e3-8a93-a3afbb8adf2710=154
20250411-01:58:35.234950000 : 8=FIXT.1.19=32735=X49=Coinbase56=24ab46f784d1b20db435b852086e325034=47850=TEST52=20250411-01:58:35.118612369=46262=9476afd5-fdba-42be-bb0c-485d57b711d5268=1279=0269=2278=c5b88ea9-605d-4595-ac52-f7c3f08523ba83=159757976555=BTC-USD270=3.55271=0.6222240960=20250411-01:58:35.11703337=fcce5a4e-d0a5-48e3-8a93-a3afbb8adf275797=110=036
20250411-01:58:35.235184000 : 8=FIXT.1.19=26635=X49=Coinbase56=24ab46f784d1b20db435b852086e325034=47950=TEST52=20250411-01:58:35.118620369=46262=9476afd5-fdba-42be-bb0c-485d57b711d5268=1279=2269=0278=fcce5a4e-d0a5-48e3-8a93-a3afbb8adf2783=159757976655=BTC-USD60=20250411-01:58:35.11703358=FILLED10=160
20250411-01:58:35.262405000 : 8=FIXT.1.19=27535=X49=Coinbase56=24ab46f784d1b20db435b852086e325034=48050=TEST52=20250411-01:58:35.146829369=46262=9476afd5-fdba-42be-bb0c-485d57b711d5268=1279=0269=183=159757976755=BTC-USD271=0.6232294660=20250411-01:58:35.14579240=137=cdfdae5d-69a8-46bd-8bff-7366b5c7687b10=136
20250411-01:58:35.262864000 : 8=FIXT.1.19=32735=X49=Coinbase56=24ab46f784d1b20db435b852086e325034=48150=TEST52=20250411-01:58:35.146841369=46262=9476afd5-fdba-42be-bb0c-485d57b711d5268=1279=0269=2278=4d60a78e-b39b-420e-b830-bc0f3f4fdde283=159757976855=BTC-USD270=3.53271=0.6232294660=20250411-01:58:35.14579237=cdfdae5d-69a8-46bd-8bff-7366b5c7687b5797=210=119
20250411-01:58:35.263499000 : 8=FIXT.1.19=28135=X49=Coinbase56=24ab46f784d1b20db435b852086e325034=48250=TEST52=20250411-01:58:35.146844369=46262=9476afd5-fdba-42be-bb0c-485d57b711d5268=1279=2269=1278=cdfdae5d-69a8-46bd-8bff-7366b5c7687b83=159757976955=BTC-USD271=0.0000000060=20250411-01:58:35.14579258=FILLED10=037
20250411-01:58:35.277783000 : 8=FIXT.1.19=29135=X49=Coinbase56=24ab46f784d1b20db435b852086e325034=48350=TEST52=20250411-01:58:35.162365369=46262=9476afd5-fdba-42be-bb0c-485d57b711d5268=1279=2269=0278=51f0c849-b2bc-470d-b4f7-ec6a9e92d15983=159757977055=BTC-USD270=3.5271=0.6232294660=20250411-01:58:35.16144058=CANCELED10=122
20250411-01:58:35.349085000 : 8=FIXT.1.19=27935=X49=Coinbase56=24ab46f784d1b20db435b852086e325034=48450=TEST52=20250411-01:58:35.233105369=46262=9476afd5-fdba-42be-bb0c-485d57b711d5268=1279=0269=083=159757977155=BTC-USD29004=2.208895519560=20250411-01:58:35.23180740=137=6018fc9c-2f81-45df-ab9e-47ebc449969110=136
20250411-01:58:35.349882000 : 8=FIXT.1.19=32735=X49=Coinbase56=24ab46f784d1b20db435b852086e325034=48550=TEST52=20250411-01:58:35.233120369=46262=9476afd5-fdba-42be-bb0c-485d57b711d5268=1279=0269=2278=c5b88ea9-605d-4595-ac52-f7c3f08523ba83=159757977255=BTC-USD270=3.55271=0.6222240960=20250411-01:58:35.23180737=6018fc9c-2f81-45df-ab9e-47ebc44996915797=110=024
20250411-01:58:35.350064000 : 8=FIXT.1.19=26635=X49=Coinbase56=24ab46f784d1b20db435b852086e325034=48650=TEST52=20250411-01:58:35.233124369=46262=9476afd5-fdba-42be-bb0c-485d57b711d5268=1279=2269=0278=6018fc9c-2f81-45df-ab9e-47ebc449969183=159757977355=BTC-USD60=20250411-01:58:35.23180758=FILLED10=153
20250411-01:58:35.377202000 : 8=FIXT.1.19=27535=X49=Coinbase56=24ab46f784d1b20db435b852086e325034=48750=TEST52=20250411-01:58:35.261532369=46262=9476afd5-fdba-42be-bb0c-485d57b711d5268=1279=0269=183=159757977455=BTC-USD271=0.6232294660=20250411-01:58:35.25959640=137=3ea00aa1-92fb-4abc-918e-2c9bf0fe2c0d10=136
20250411-01:58:35.377464000 : 8=FIXT.1.19=32735=X49=Coinbase56=24ab46f784d1b20db435b852086e325034=48850=TEST52=20250411-01:58:35.261539369=46262=9476afd5-fdba-42be-bb0c-485d57b711d5268=1279=0269=2278=4d60a78e-b39b-420e-b830-bc0f3f4fdde283=159757977555=BTC-USD270=3.53271=0.6232294660=20250411-01:58:35.25959637=3ea00aa1-92fb-4abc-918e-2c9bf0fe2c0d5797=210=132
20250411-01:58:35.377649000 : 8=FIXT.1.19=28135=X49=Coinbase56=24ab46f784d1b20db435b852086e325034=48950=TEST52=20250411-01:58:35.261543369=46262=9476afd5-fdba-42be-bb0c-485d57b711d5268=1279=2269=1278=3ea00aa1-92fb-4abc-918e-2c9bf0fe2c0d83=159757977655=BTC-USD271=0.0000000060=20250411-01:58:35.25959658=FILLED10=042
20250411-01:58:35.565028000 : 8=FIXT.1.19=29235=X49=Coinbase56=24ab46f784d1b20db435b852086e325034=49050=TEST52=20250411-01:58:35.448658369=46262=9476afd5-fdba-42be-bb0c-485d57b711d5268=1279=2269=0278=beb774f7-441b-4c7e-8847-e548ba1f47ce83=159757977755=BTC-USD270=3.39271=0.6214689360=20250411-01:58:35.44715958=CANCELED10=224
20250411-01:58:35.695084000 : 8=FIXT.1.19=8435=534=4749=24ab46f784d1b20db435b852086e325052=20250411-01:58:35.69156=Coinbase10=179
20250411-01:58:35.695455000 : 8=FIXT.1.19=27935=X49=Coinbase56=24ab46f784d1b20db435b852086e325034=49150=TEST52=20250411-01:58:35.576029369=46262=9476afd5-fdba-42be-bb0c-485d57b711d5268=1279=0269=083=159757977855=BTC-USD29004=2.208895519560=20250411-01:58:35.57482040=137=00c14a3b-a8a7-4a16-ba9f-b8422f8802ad10=165
20250411-01:58:35.698649000 : 8=FIXT.1.19=32735=X49=Coinbase56=24ab46f784d1b20db435b852086e325034=49250=TEST52=20250411-01:58:35.576040369=46262=9476afd5-fdba-42be-bb0c-485d57b711d5268=1279=0269=2278=c5b88ea9-605d-4595-ac52-f7c3f08523ba83=159757977955=BTC-USD270=3.55271=0.6222240960=20250411-01:58:35.57482037=00c14a3b-a8a7-4a16-ba9f-b8422f8802ad5797=110=049
20250411-01:58:35.703729000 : 8=FIXT.1.19=26635=X49=Coinbase56=24ab46f784d1b20db435b852086e325034=49350=TEST52=20250411-01:58:35.576042369=46262=9476afd5-fdba-42be-bb0c-485d57b711d5268=1279=2269=0278=00c14a3b-a8a7-4a16-ba9f-b8422f8802ad83=159757978055=BTC-USD60=20250411-01:58:35.57482058=FILLED10=167
20250411-01:58:35.720161000 : 8=FIXT.1.19=27535=X49=Coinbase56=24ab46f784d1b20db435b852086e325034=49450=TEST52=20250411-01:58:35.604495369=46262=9476afd5-fdba-42be-bb0c-485d57b711d5268=1279=0269=183=159757978155=BTC-USD271=0.6232294660=20250411-01:58:35.60290740=137=4f5b0319-cfdb-4c2b-8827-d3ffe4e8616410=226
20250411-01:58:35.721100000 : 8=FIXT.1.19=32735=X49=Coinbase56=24ab46f784d1b20db435b852086e325034=49550=TEST52=20250411-01:58:35.604501369=46262=9476afd5-fdba-42be-bb0c-485d57b711d5268=1279=0269=2278=4d60a78e-b39b-420e-b830-bc0f3f4fdde283=159757978255=BTC-USD270=3.53271=0.6232294660=20250411-01:58:35.60290737=4f5b0319-cfdb-4c2b-8827-d3ffe4e861645797=210=203
20250411-01:58:35.721404000 : 8=FIXT.1.19=28135=X49=Coinbase56=24ab46f784d1b20db435b852086e325034=49650=TEST52=20250411-01:58:35.604505369=46262=9476afd5-fdba-42be-bb0c-485d57b711d5268=1279=2269=1278=4f5b0319-cfdb-4c2b-8827-d3ffe4e8616483=159757978355=BTC-USD271=0.0000000060=20250411-01:58:35.60290758=FILLED10=122
20250411-01:58:35.722693000 : 8=FIXT.1.19=28435=X49=Coinbase56=24ab46f784d1b20db435b852086e325034=49750=TEST52=20250411-01:58:35.604611369=46262=9476afd5-fdba-42be-bb0c-485d57b711d5268=1279=0269=083=159757978455=BTC-USD270=3.89271=0.6197183160=20250411-01:58:35.60356940=237=5e3907e4-8982-413d-95a7-39672e48621f10=081
20250411-01:58:35.722910000 : 8=FIXT.1.19=32735=X49=Coinbase56=24ab46f784d1b20db435b852086e325034=49850=TEST52=20250411-01:58:35.604617369=46262=9476afd5-fdba-42be-bb0c-485d57b711d5268=1279=0269=2278=c5b88ea9-605d-4595-ac52-f7c3f08523ba83=159757978555=BTC-USD270=3.55271=0.6197183160=20250411-01:58:35.60356937=5e3907e4-8982-413d-95a7-39672e48621f5797=110=036
20250411-01:58:35.723270000 : 8=FIXT.1.19=29035=X49=Coinbase56=24ab46f784d1b20db435b852086e325034=49950=TEST52=20250411-01:58:35.604620369=46262=9476afd5-fdba-42be-bb0c-485d57b711d5268=1279=2269=0278=5e3907e4-8982-413d-95a7-39672e48621f83=159757978655=BTC-USD270=3.89271=0.0000000060=20250411-01:58:35.60356958=FILLED10=238
20250411-01:58:35.776217000 : 8=FIXT.1.19=30335=X49=Coinbase56=24ab46f784d1b20db435b852086e325034=50050=TEST52=20250411-01:58:35.660302369=46262=9476afd5-fdba-42be-bb0c-485d57b711d5268=1279=0269=183=159757978755=BTC-USD270=3.23271=0.5665722329004=1.999999971960=20250411-01:58:35.65933840=237=0c170111-6370-4b11-86ed-d44a55d3b04210=039
20250411-01:58:35.776783000 : 8=FIXT.1.19=32735=X49=Coinbase56=24ab46f784d1b20db435b852086e325034=50150=TEST52=20250411-01:58:35.660309369=46262=9476afd5-fdba-42be-bb0c-485d57b711d5268=1279=0269=2278=4d60a78e-b39b-420e-b830-bc0f3f4fdde283=159757978855=BTC-USD270=3.53271=0.5665722360=20250411-01:58:35.65933837=0c170111-6370-4b11-86ed-d44a55d3b0425797=210=193
20250411-01:58:35.777972000 : 8=FIXT.1.19=28135=X49=Coinbase56=24ab46f784d1b20db435b852086e325034=50250=TEST52=20250411-01:58:35.660348369=46262=9476afd5-fdba-42be-bb0c-485d57b711d5268=1279=2269=1278=0c170111-6370-4b11-86ed-d44a55d3b04283=159757978955=BTC-USD270=3.23271=060=20250411-01:58:35.65933858=FILLED10=092
20250411-01:59:51.886649000 : 8=FIXT.1.19=21535=A34=149=24ab46f784d1b20db435b852086e325052=20250411-01:59:51.87956=Coinbase95=4496=xH+Sq1eAp3YiWpgPUasXc0kkxRGv07uqSzavw2WZJow=98=0108=30141=Y553=24ab46f784d1b20db435b852086e3250554=akmwnltyfgb1137=910=022
20250411-01:59:52.220419000 : 8=FIXT.1.19=12535=A49=Coinbase56=24ab46f784d1b20db435b852086e325034=150=TEST52=20250411-01:59:52.024729369=198=0108=30141=Y1137=910=198
20250411-01:59:53.618025000 : 8=FIXT.1.19=17835=V34=249=24ab46f784d1b20db435b852086e325052=20250411-01:59:53.61656=Coinbase1128=9146=155=BTC-USD262=1c4ca071-c1b7-4b32-a10d-aab5f1327380263=1264=0267=2269=0269=110=027
20250411-01:59:54.036311000 : 8=FIXT.1.19=30735=X49=Coinbase56=24ab46f784d1b20db435b852086e325034=250=TEST52=20250411-01:59:53.913151369=2262=1c4ca071-c1b7-4b32-a10d-aab5f1327380268=1279=1269=0278=1427699a-fe0c-4a1f-8735-bd2913dcabdc83=159758145255=BTC-USD270=3.41271=0.5702231160=20250411-01:59:53.91188658=CHANGE_REASON_MODIFY_ORDER10=008
20250411-01:59:54.072229000 : 8=FIXT.1.19=27635=X49=Coinbase56=24ab46f784d1b20db435b852086e325034=350=TEST52=20250411-01:59:53.952830369=2262=1c4ca071-c1b7-4b32-a10d-aab5f1327380268=1279=0269=083=159758145355=BTC-USD29004=2.208895519560=20250411-01:59:53.95080840=137=fe86e07b-125b-4d74-94ac-e0b861edbf1510=129
20250411-01:59:54.072788000 : 8=FIXT.1.19=32435=X49=Coinbase56=24ab46f784d1b20db435b852086e325034=450=TEST52=20250411-01:59:53.952838369=2262=1c4ca071-c1b7-4b32-a10d-aab5f1327380268=1279=0269=2278=c5b88ea9-605d-4595-ac52-f7c3f08523ba83=159758145455=BTC-USD270=3.55271=0.6222240960=20250411-01:59:53.95080837=fe86e07b-125b-4d74-94ac-e0b861edbf155797=110=028
20250411-01:59:54.072981000 : 8=FIXT.1.19=26335=X49=Coinbase56=24ab46f784d1b20db435b852086e325034=550=TEST52=20250411-01:59:53.952841369=2262=1c4ca071-c1b7-4b32-a10d-aab5f1327380268=1279=2269=0278=fe86e07b-125b-4d74-94ac-e0b861edbf1583=159758145555=BTC-USD60=20250411-01:59:53.95080858=FILLED10=147
20250411-01:59:54.097866000 : 8=FIXT.1.19=27235=X49=Coinbase56=24ab46f784d1b20db435b852086e325034=650=TEST52=20250411-01:59:53.978076369=2262=1c4ca071-c1b7-4b32-a10d-aab5f1327380268=1279=0269=183=159758145655=BTC-USD271=0.6232294660=20250411-01:59:53.97660340=137=b97418a1-d99d-4c16-8282-95388e1cbce010=005
20250411-01:59:54.098359000 : 8=FIXT.1.19=32435=X49=Coinbase56=24ab46f784d1b20db435b852086e325034=750=TEST52=20250411-01:59:53.978111369=2262=1c4ca071-c1b7-4b32-a10d-aab5f1327380268=1279=0269=2278=4d60a78e-b39b-420e-b830-bc0f3f4fdde283=159758145755=BTC-USD270=3.53271=0.6232294660=20250411-01:59:53.97660337=b97418a1-d99d-4c16-8282-95388e1cbce05797=210=240
20250411-01:59:54.098567000 : 8=FIXT.1.19=27835=X49=Coinbase56=24ab46f784d1b20db435b852086e325034=850=TEST52=20250411-01:59:53.978115369=2262=1c4ca071-c1b7-4b32-a10d-aab5f1327380268=1279=2269=1278=b97418a1-d99d-4c16-8282-95388e1cbce083=159758145855=BTC-USD271=0.0000000060=20250411-01:59:53.97660358=FILLED10=168
20250411-01:59:54.240758000 : 8=FIXT.1.19=27635=X49=Coinbase56=24ab46f784d1b20db435b852086e325034=950=TEST52=20250411-01:59:54.122089369=2262=1c4ca071-c1b7-4b32-a10d-aab5f1327380268=1279=0269=083=159758145955=BTC-USD29004=2.208895519560=20250411-01:59:54.12073540=137=4c63c861-d4f0-4c0d-adc7-4f8f9270029810=243
20250411-01:59:54.241504000 : 8=FIXT.1.19=32535=X49=Coinbase56=24ab46f784d1b20db435b852086e325034=1050=TEST52=20250411-01:59:54.122110369=2262=1c4ca071-c1b7-4b32-a10d-aab5f1327380268=1279=0269=2278=c5b88ea9-605d-4595-ac52-f7c3f08523ba83=159758146055=BTC-USD270=3.55271=0.6222240960=20250411-01:59:54.12073537=4c63c861-d4f0-4c0d-adc7-4f8f927002985797=110=150
20250411-01:59:54.241808000 : 8=FIXT.1.19=26435=X49=Coinbase56=24ab46f784d1b20db435b852086e325034=1150=TEST52=20250411-01:59:54.122112369=2262=1c4ca071-c1b7-4b32-a10d-aab5f1327380268=1279=2269=0278=4c63c861-d4f0-4c0d-adc7-4f8f9270029883=159758146155=BTC-USD60=20250411-01:59:54.12073558=FILLED10=021
20250411-01:59:54.269308000 : 8=FIXT.1.19=27335=X49=Coinbase56=24ab46f784d1b20db435b852086e325034=1250=TEST52=20250411-01:59:54.150292369=2262=1c4ca071-c1b7-4b32-a10d-aab5f1327380268=1279=0269=183=159758146255=BTC-USD271=0.6232294660=20250411-01:59:54.14862940=137=2e6356fd-9f7d-4c26-b965-0b27fb2a91e210=121
20250411-01:59:54.270321000 : 8=FIXT.1.19=32535=X49=Coinbase56=24ab46f784d1b20db435b852086e325034=1350=TEST52=20250411-01:59:54.150345369=2262=1c4ca071-c1b7-4b32-a10d-aab5f1327380268=1279=0269=2278=4d60a78e-b39b-420e-b830-bc0f3f4fdde283=159758146355=BTC-USD270=3.53271=0.6232294660=20250411-01:59:54.14862937=2e6356fd-9f7d-4c26-b965-0b27fb2a91e25797=210=109
20250411-01:59:54.270505000 : 8=FIXT.1.19=27935=X49=Coinbase56=24ab46f784d1b20db435b852086e325034=1450=TEST52=20250411-01:59:54.150348369=2262=1c4ca071-c1b7-4b32-a10d-aab5f1327380268=1279=2269=1278=2e6356fd-9f7d-4c26-b965-0b27fb2a91e283=159758146455=BTC-USD271=0.0000000060=20250411-01:59:54.14862958=FILLED10=036
20250411-01:59:54.327478000 : 8=FIXT.1.19=30835=X49=Coinbase56=24ab46f784d1b20db435b852086e325034=1550=TEST52=20250411-01:59:54.198604369=2262=1c4ca071-c1b7-4b32-a10d-aab5f1327380268=1279=1269=1278=d68d2389-fda4-456e-a285-3787e94c7c8883=159758146555=BTC-USD270=3.59271=0.6229315960=20250411-01:59:54.19728858=CHANGE_REASON_MODIFY_ORDER10=208
20250411-01:59:54.357649000 : 8=FIXT.1.19=27735=X49=Coinbase56=24ab46f784d1b20db435b852086e325034=1650=TEST52=20250411-01:59:54.234891369=2262=1c4ca071-c1b7-4b32-a10d-aab5f1327380268=1279=0269=083=159758146655=BTC-USD29004=2.208895519560=20250411-01:59:54.23379440=137=09adedd7-3ff9-472a-9201-3db91eb2f13410=134
20250411-01:59:54.385495000 : 8=FIXT.1.19=32535=X49=Coinbase56=24ab46f784d1b20db435b852086e325034=1750=TEST52=20250411-01:59:54.235025369=2262=1c4ca071-c1b7-4b32-a10d-aab5f1327380268=1279=0269=2278=c5b88ea9-605d-4595-ac52-f7c3f08523ba83=159758146755=BTC-USD270=3.55271=0.6222240960=20250411-01:59:54.23379437=09adedd7-3ff9-472a-9201-3db91eb2f1345797=110=015
20250411-01:59:54.401409000 : 8=FIXT.1.19=26435=X49=Coinbase56=24ab46f784d1b20db435b852086e325034=1850=TEST52=20250411-01:59:54.235082369=2262=1c4ca071-c1b7-4b32-a10d-aab5f1327380268=1279=2269=0278=09adedd7-3ff9-472a-9201-3db91eb2f13483=159758146855=BTC-USD60=20250411-01:59:54.23379458=FILLED10=143
20250411-01:59:54.459263000 : 8=FIXT.1.19=27335=X49=Coinbase56=24ab46f784d1b20db435b852086e325034=1950=TEST52=20250411-01:59:54.264608369=2262=1c4ca071-c1b7-4b32-a10d-aab5f1327380268=1279=0269=183=159758146955=BTC-USD271=0.6232294660=20250411-01:59:54.26337140=137=2c78cf35-0c89-41c8-87bb-1dcc6d3c960610=135
20250411-01:59:54.465799000 : 8=FIXT.1.19=32535=X49=Coinbase56=24ab46f784d1b20db435b852086e325034=2050=TEST52=20250411-01:59:54.264626369=2262=1c4ca071-c1b7-4b32-a10d-aab5f1327380268=1279=0269=2278=4d60a78e-b39b-420e-b830-bc0f3f4fdde283=159758147055=BTC-USD270=3.53271=0.6232294660=20250411-01:59:54.26337137=2c78cf35-0c89-41c8-87bb-1dcc6d3c96065797=210=106
20250411-01:59:54.479365000 : 8=FIXT.1.19=27935=X49=Coinbase56=24ab46f784d1b20db435b852086e325034=2150=TEST52=20250411-01:59:54.264631369=2262=1c4ca071-c1b7-4b32-a10d-aab5f1327380268=1279=2269=1278=2c78cf35-0c89-41c8-87bb-1dcc6d3c960683=159758147155=BTC-USD271=0.0000000060=20250411-01:59:54.26337158=FILLED10=026
20250411-01:59:54.604698000 : 8=FIXT.1.19=30735=X49=Coinbase56=24ab46f784d1b20db435b852086e325034=2250=TEST52=20250411-01:59:54.485142369=2262=1c4ca071-c1b7-4b32-a10d-aab5f1327380268=1279=1269=1278=b175a3bc-9391-4e0a-b8f2-4c919d3a4f1883=159758147255=BTC-USD270=3.6271=0.6228674860=20250411-01:59:54.48391658=CHANGE_REASON_MODIFY_ORDER10=201
20250411-01:59:54.889697000 : 8=FIXT.1.19=32535=X49=Coinbase56=24ab46f784d1b20db435b852086e325034=2350=TEST52=20250411-01:59:54.770255369=2262=1c4ca071-c1b7-4b32-a10d-aab5f1327380268=1279=0269=2278=c5b88ea9-605d-4595-ac52-f7c3f08523ba83=159758147355=BTC-USD270=3.55271=0.6055507860=20250411-01:59:54.76903437=a0c52f26-89e3-464f-8fe6-aa36cf7329de5797=110=047
20250411-01:59:54.893233000 : 8=FIXT.1.19=28735=X49=Coinbase56=24ab46f784d1b20db435b852086e325034=2450=TEST52=20250411-01:59:54.770297369=2262=1c4ca071-c1b7-4b32-a10d-aab5f1327380268=1279=2269=0278=a0c52f26-89e3-464f-8fe6-aa36cf7329de83=159758147455=BTC-USD270=3.7271=0.0000000060=20250411-01:59:54.76903458=FILLED10=211
20250411-01:59:55.155750000 : 8=FIXT.1.19=27735=X49=Coinbase56=24ab46f784d1b20db435b852086e325034=2550=TEST52=20250411-01:59:55.036124369=2262=1c4ca071-c1b7-4b32-a10d-aab5f1327380268=1279=0269=083=159758147555=BTC-USD29004=2.208895519560=20250411-01:59:55.03486640=137=f77756dd-53ed-43db-84f7-91048fd711e810=057
20250411-01:59:55.156568000 : 8=FIXT.1.19=32535=X49=Coinbase56=24ab46f784d1b20db435b852086e325034=2650=TEST52=20250411-01:59:55.036133369=2262=1c4ca071-c1b7-4b32-a10d-aab5f1327380268=1279=0269=2278=c5b88ea9-605d-4595-ac52-f7c3f08523ba83=159758147655=BTC-USD270=3.55271=0.6222240960=20250411-01:59:55.03486637=f77756dd-53ed-43db-84f7-91048fd711e85797=110=204
20250411-01:59:55.156855000 : 8=FIXT.1.19=26435=X49=Coinbase56=24ab46f784d1b20db435b852086e325034=2750=TEST52=20250411-01:59:55.036135369=2262=1c4ca071-c1b7-4b32-a10d-aab5f1327380268=1279=2269=0278=f77756dd-53ed-43db-84f7-91048fd711e883=159758147755=BTC-USD60=20250411-01:59:55.03486658=FILLED10=075
20250411-01:59:55.184483000 : 8=FIXT.1.19=27335=X49=Coinbase56=24ab46f784d1b20db435b852086e325034=2850=TEST52=20250411-01:59:55.065310369=2262=1c4ca071-c1b7-4b32-a10d-aab5f1327380268=1279=0269=183=159758147855=BTC-USD271=0.6197183160=20250411-01:59:55.06377440=137=558c4be0-b651-471b-9f71-06442d584a7c10=236
20250411-01:59:55.184792000 : 8=FIXT.1.19=32535=X49=Coinbase56=24ab46f784d1b20db435b852086e325034=2950=TEST52=20250411-01:59:55.065319369=2262=1c4ca071-c1b7-4b32-a10d-aab5f1327380268=1279=0269=2278=4d60a78e-b39b-420e-b830-bc0f3f4fdde283=159758147955=BTC-USD270=3.53271=0.6197183160=20250411-01:59:55.06377437=558c4be0-b651-471b-9f71-06442d584a7c5797=210=234
20250411-01:59:55.184980000 : 8=FIXT.1.19=27935=X49=Coinbase56=24ab46f784d1b20db435b852086e325034=3050=TEST52=20250411-01:59:55.065322369=2262=1c4ca071-c1b7-4b32-a10d-aab5f1327380268=1279=2269=1278=558c4be0-b651-471b-9f71-06442d584a7c83=159758148055=BTC-USD271=0.0000000060=20250411-01:59:55.06377458=FILLED10=132
20250411-01:59:55.288513000 : 8=FIXT.1.19=28135=X49=Coinbase56=24ab46f784d1b20db435b852086e325034=3150=TEST52=20250411-01:59:55.168858369=2262=1c4ca071-c1b7-4b32-a10d-aab5f1327380268=1279=0269=183=159758148155=BTC-USD270=3.6271=0.6232294660=20250411-01:59:55.16689240=237=19f17d37-d517-4a55-bfc5-9d93c206d1ba10=245
20250411-01:59:55.291282000 : 8=FIXT.1.19=27735=X49=Coinbase56=24ab46f784d1b20db435b852086e325034=3250=TEST52=20250411-01:59:55.168866369=2262=1c4ca071-c1b7-4b32-a10d-aab5f1327380268=1279=0269=1278=19f17d37-d517-4a55-bfc5-9d93c206d1ba83=159758148255=BTC-USD270=3.6271=0.6232294660=20250411-01:59:55.16689210=094
20250411-01:59:55.670417000 : 8=FIXT.1.19=27735=X49=Coinbase56=24ab46f784d1b20db435b852086e325034=3350=TEST52=20250411-01:59:55.551343369=2262=1c4ca071-c1b7-4b32-a10d-aab5f1327380268=1279=0269=083=159758148355=BTC-USD29004=2.208895519560=20250411-01:59:55.54972640=137=d0ddbf32-830c-4e72-9811-ed5a9960126810=251
20250411-01:59:55.671374000 : 8=FIXT.1.19=32535=X49=Coinbase56=24ab46f784d1b20db435b852086e325034=3450=TEST52=20250411-01:59:55.551400369=2262=1c4ca071-c1b7-4b32-a10d-aab5f1327380268=1279=0269=2278=c5b88ea9-605d-4595-ac52-f7c3f08523ba83=159758148455=BTC-USD270=3.55271=0.6222240960=20250411-01:59:55.54972637=d0ddbf32-830c-4e72-9811-ed5a996012685797=110=136
20250411-01:59:55.671642000 : 8=FIXT.1.19=26435=X49=Coinbase56=24ab46f784d1b20db435b852086e325034=3550=TEST52=20250411-01:59:55.551406369=2262=1c4ca071-c1b7-4b32-a10d-aab5f1327380268=1279=2269=0278=d0ddbf32-830c-4e72-9811-ed5a9960126883=159758148555=BTC-USD60=20250411-01:59:55.54972658=FILLED10=011
20250411-01:59:55.698811000 : 8=FIXT.1.19=27335=X49=Coinbase56=24ab46f784d1b20db435b852086e325034=3650=TEST52=20250411-01:59:55.578638369=2262=1c4ca071-c1b7-4b32-a10d-aab5f1327380268=1279=0269=183=159758148655=BTC-USD271=0.6232294660=20250411-01:59:55.57661240=137=a702666a-2eab-4204-8f02-9f0de7ece55610=136
20250411-01:59:55.699385000 : 8=FIXT.1.19=32535=X49=Coinbase56=24ab46f784d1b20db435b852086e325034=3750=TEST52=20250411-01:59:55.578647369=2262=1c4ca071-c1b7-4b32-a10d-aab5f1327380268=1279=0269=2278=4d60a78e-b39b-420e-b830-bc0f3f4fdde283=159758148755=BTC-USD270=3.53271=0.6232294660=20250411-01:59:55.57661237=a702666a-2eab-4204-8f02-9f0de7ece5565797=210=125
20250411-01:59:55.699612000 : 8=FIXT.1.19=27935=X49=Coinbase56=24ab46f784d1b20db435b852086e325034=3850=TEST52=20250411-01:59:55.578650369=2262=1c4ca071-c1b7-4b32-a10d-aab5f1327380268=1279=2269=1278=a702666a-2eab-4204-8f02-9f0de7ece55683=159758148855=BTC-USD271=0.0000000060=20250411-01:59:55.57661258=FILLED10=043
20250411-01:59:56.925918000 : 8=FIXT.1.19=27735=X49=Coinbase56=24ab46f784d1b20db435b852086e325034=3950=TEST52=20250411-01:59:56.806885369=2262=1c4ca071-c1b7-4b32-a10d-aab5f1327380268=1279=0269=083=159758148955=BTC-USD29004=2.208895519560=20250411-01:59:56.80566040=137=b1a16501-da59-4269-a386-3cf6d307f29c10=010
20250411-01:59:56.926879000 : 8=FIXT.1.19=32535=X49=Coinbase56=24ab46f784d1b20db435b852086e325034=4050=TEST52=20250411-01:59:56.806895369=2262=1c4ca071-c1b7-4b32-a10d-aab5f1327380268=1279=0269=2278=c5b88ea9-605d-4595-ac52-f7c3f08523ba83=159758149055=BTC-USD270=3.55271=0.6222240960=20250411-01:59:56.80566037=b1a16501-da59-4269-a386-3cf6d307f29c5797=110=140
20250411-01:59:56.927056000 : 8=FIXT.1.19=26435=X49=Coinbase56=24ab46f784d1b20db435b852086e325034=4150=TEST52=20250411-01:59:56.806898369=2262=1c4ca071-c1b7-4b32-a10d-aab5f1327380268=1279=2269=0278=b1a16501-da59-4269-a386-3cf6d307f29c83=159758149155=BTC-USD60=20250411-01:59:56.80566058=FILLED10=012
20250411-01:59:56.930232000 : 8=FIXT.1.19=28235=X49=Coinbase56=24ab46f784d1b20db435b852086e325034=4250=TEST52=20250411-01:59:56.809502369=2262=1c4ca071-c1b7-4b32-a10d-aab5f1327380268=1279=0269=183=159758149255=BTC-USD270=3.24271=0.6232294660=20250411-01:59:56.80782040=237=95398b2c-da34-4c1f-9bf3-b7ef0b9d202b10=119
20250411-01:59:56.930475000 : 8=FIXT.1.19=32535=X49=Coinbase56=24ab46f784d1b20db435b852086e325034=4350=TEST52=20250411-01:59:56.809507369=2262=1c4ca071-c1b7-4b32-a10d-aab5f1327380268=1279=0269=2278=4d60a78e-b39b-420e-b830-bc0f3f4fdde283=159758149355=BTC-USD270=3.53271=0.6232294660=20250411-01:59:56.80782037=95398b2c-da34-4c1f-9bf3-b7ef0b9d202b5797=210=210
20250411-01:59:56.930851000 : 8=FIXT.1.19=28835=X49=Coinbase56=24ab46f784d1b20db435b852086e325034=4450=TEST52=20250411-01:59:56.809510369=2262=1c4ca071-c1b7-4b32-a10d-aab5f1327380268=1279=2269=1278=95398b2c-da34-4c1f-9bf3-b7ef0b9d202b83=159758149455=BTC-USD270=3.24271=0.0000000060=20250411-01:59:56.80782058=FILLED10=030
20250411-01:59:56.957092000 : 8=FIXT.1.19=27335=X49=Coinbase56=24ab46f784d1b20db435b852086e325034=4550=TEST52=20250411-01:59:56.836927369=2262=1c4ca071-c1b7-4b32-a10d-aab5f1327380268=1279=0269=183=159758149555=BTC-USD271=0.6232294660=20250411-01:59:56.83502340=137=d79adec0-6fd1-4ac6-bb05-33659ba634b910=227
20250411-01:59:56.957382000 : 8=FIXT.1.19=32535=X49=Coinbase56=24ab46f784d1b20db435b852086e325034=4650=TEST52=20250411-01:59:56.836935369=2262=1c4ca071-c1b7-4b32-a10d-aab5f1327380268=1279=0269=2278=4d60a78e-b39b-420e-b830-bc0f3f4fdde283=159758149655=BTC-USD270=3.53271=0.6232294660=20250411-01:59:56.83502337=d79adec0-6fd1-4ac6-bb05-33659ba634b95797=210=215
20250411-01:59:56.957559000 : 8=FIXT.1.19=27935=X49=Coinbase56=24ab46f784d1b20db435b852086e325034=4750=TEST52=20250411-01:59:56.836938369=2262=1c4ca071-c1b7-4b32-a10d-aab5f1327380268=1279=2269=1278=d79adec0-6fd1-4ac6-bb05-33659ba634b983=159758149755=BTC-USD271=0.0000000060=20250411-01:59:56.83502358=FILLED10=142
20250411-01:59:56.984492000 : 8=FIXT.1.19=28235=X49=Coinbase56=24ab46f784d1b20db435b852086e325034=4850=TEST52=20250411-01:59:56.864254369=2262=1c4ca071-c1b7-4b32-a10d-aab5f1327380268=1279=0269=083=159758149855=BTC-USD270=3.75271=0.6232294660=20250411-01:59:56.86289740=237=b3af02b8-f613-4c8e-8e16-27cdccca58c410=202
20250411-01:59:56.984690000 : 8=FIXT.1.19=32535=X49=Coinbase56=24ab46f784d1b20db435b852086e325034=4950=TEST52=20250411-01:59:56.864261369=2262=1c4ca071-c1b7-4b32-a10d-aab5f1327380268=1279=0269=2278=c5b88ea9-605d-4595-ac52-f7c3f08523ba83=159758149955=BTC-USD270=3.55271=0.6232294660=20250411-01:59:56.86289737=b3af02b8-f613-4c8e-8e16-27cdccca58c45797=110=154
20250411-01:59:56.986253000 : 8=FIXT.1.19=28835=X49=Coinbase56=24ab46f784d1b20db435b852086e325034=5050=TEST52=20250411-01:59:56.864263369=2262=1c4ca071-c1b7-4b32-a10d-aab5f1327380268=1279=2269=0278=b3af02b8-f613-4c8e-8e16-27cdccca58c483=159758150055=BTC-USD270=3.75271=0.0000000060=20250411-01:59:56.86289758=FILLED10=087
20250411-01:59:57.097002000 : 8=FIXT.1.19=27735=X49=Coinbase56=24ab46f784d1b20db435b852086e325034=5150=TEST52=20250411-01:59:56.978436369=2262=1c4ca071-c1b7-4b32-a10d-aab5f1327380268=1279=0269=083=159758150155=BTC-USD29004=2.208895519560=20250411-01:59:56.97685540=137=6cbb488f-2a19-462f-8978-3398cd4b4a5310=030
20250411-01:59:57.097523000 : 8=FIXT.1.19=32535=X49=Coinbase56=24ab46f784d1b20db435b852086e325034=5250=TEST52=20250411-01:59:56.978498369=2262=1c4ca071-c1b7-4b32-a10d-aab5f1327380268=1279=0269=2278=c5b88ea9-605d-4595-ac52-f7c3f08523ba83=159758150255=BTC-USD270=3.55271=0.6222240960=20250411-01:59:56.97685537=6cbb488f-2a19-462f-8978-3398cd4b4a535797=110=185
20250411-01:59:57.097701000 : 8=FIXT.1.19=26435=X49=Coinbase56=24ab46f784d1b20db435b852086e325034=5350=TEST52=20250411-01:59:56.978542369=2262=1c4ca071-c1b7-4b32-a10d-aab5f1327380268=1279=2269=0278=6cbb488f-2a19-462f-8978-3398cd4b4a5383=159758150355=BTC-USD60=20250411-01:59:56.97685558=FILLED10=044
20250411-01:59:57.126524000 : 8=FIXT.1.19=27335=X49=Coinbase56=24ab46f784d1b20db435b852086e325034=5450=TEST52=20250411-01:59:57.007292369=2262=1c4ca071-c1b7-4b32-a10d-aab5f1327380268=1279=0269=183=159758150455=BTC-USD271=0.6197183160=20250411-01:59:57.00634240=137=9a700687-702b-41dd-82b7-6a18099bc98010=180
20250411-01:59:57.127189000 : 8=FIXT.1.19=32535=X49=Coinbase56=24ab46f784d1b20db435b852086e325034=5550=TEST52=20250411-01:59:57.007300369=2262=1c4ca071-c1b7-4b32-a10d-aab5f1327380268=1279=0269=2278=4d60a78e-b39b-420e-b830-bc0f3f4fdde283=159758150555=BTC-USD270=3.53271=0.6197183160=20250411-01:59:57.00634237=9a700687-702b-41dd-82b7-6a18099bc9805797=210=159
20250411-01:59:57.127352000 : 8=FIXT.1.19=27935=X49=Coinbase56=24ab46f784d1b20db435b852086e325034=5650=TEST52=20250411-01:59:57.007357369=2262=1c4ca071-c1b7-4b32-a10d-aab5f1327380268=1279=2269=1278=9a700687-702b-41dd-82b7-6a18099bc98083=159758150655=BTC-USD271=0.0000000060=20250411-01:59:57.00634258=FILLED10=093
20250411-01:59:57.157774000 : 8=FIXT.1.19=30135=X49=Coinbase56=24ab46f784d1b20db435b852086e325034=5750=TEST52=20250411-01:59:57.039126369=2262=1c4ca071-c1b7-4b32-a10d-aab5f1327380268=1279=0269=183=159758150755=BTC-USD270=3.28271=0.5779036829004=2.039999990460=20250411-01:59:57.03713640=237=4165951f-11e4-4761-8593-1fbd82671b8710=198
20250411-01:59:57.158015000 : 8=FIXT.1.19=32535=X49=Coinbase56=24ab46f784d1b20db435b852086e325034=5850=TEST52=20250411-01:59:57.039135369=2262=1c4ca071-c1b7-4b32-a10d-aab5f1327380268=1279=0269=2278=4d60a78e-b39b-420e-b830-bc0f3f4fdde283=159758150855=BTC-USD270=3.53271=0.5779036860=20250411-01:59:57.03713637=4165951f-11e4-4761-8593-1fbd82671b875797=210=102
20250411-01:59:57.158376000 : 8=FIXT.1.19=27935=X49=Coinbase56=24ab46f784d1b20db435b852086e325034=5950=TEST52=20250411-01:59:57.039137369=2262=1c4ca071-c1b7-4b32-a10d-aab5f1327380268=1279=2269=1278=4165951f-11e4-4761-8593-1fbd82671b8783=159758150955=BTC-USD270=3.28271=060=20250411-01:59:57.03713658=FILLED10=005
20250411-01:59:57.213300000 : 8=FIXT.1.19=28235=X49=Coinbase56=24ab46f784d1b20db435b852086e325034=6050=TEST52=20250411-01:59:57.094466369=2262=1c4ca071-c1b7-4b32-a10d-aab5f1327380268=1279=0269=083=159758151055=BTC-USD270=3.81271=0.6232294660=20250411-01:59:57.09282340=237=e9643fc0-eb03-493a-8db3-f7c30b951a0e10=064
20250411-01:59:57.213524000 : 8=FIXT.1.19=32535=X49=Coinbase56=24ab46f784d1b20db435b852086e325034=6150=TEST52=20250411-01:59:57.094478369=2262=1c4ca071-c1b7-4b32-a10d-aab5f1327380268=1279=0269=2278=c5b88ea9-605d-4595-ac52-f7c3f08523ba83=159758151155=BTC-USD270=3.55271=0.6232294660=20250411-01:59:57.09282337=e9643fc0-eb03-493a-8db3-f7c30b951a0e5797=110=024
20250411-01:59:57.215431000 : 8=FIXT.1.19=28835=X49=Coinbase56=24ab46f784d1b20db435b852086e325034=6250=TEST52=20250411-01:59:57.094481369=2262=1c4ca071-c1b7-4b32-a10d-aab5f1327380268=1279=2269=0278=e9643fc0-eb03-493a-8db3-f7c30b951a0e83=159758151255=BTC-USD270=3.81271=0.0000000060=20250411-01:59:57.09282358=FILLED10=229
20250411-01:59:57.740046000 : 8=FIXT.1.19=28135=X49=Coinbase56=24ab46f784d1b20db435b852086e325034=6350=TEST52=20250411-01:59:57.619047369=2262=1c4ca071-c1b7-4b32-a10d-aab5f1327380268=1279=0269=183=159758151355=BTC-USD270=3.2271=0.6197183160=20250411-01:59:57.61736940=237=5b68d618-ecd8-4dd3-baf5-64d41caf76af10=183
20250411-01:59:57.743524000 : 8=FIXT.1.19=32535=X49=Coinbase56=24ab46f784d1b20db435b852086e325034=6450=TEST52=20250411-01:59:57.619124369=2262=1c4ca071-c1b7-4b32-a10d-aab5f1327380268=1279=0269=2278=4d60a78e-b39b-420e-b830-bc0f3f4fdde283=159758151455=BTC-USD270=3.53271=0.6197183160=20250411-01:59:57.61736937=5b68d618-ecd8-4dd3-baf5-64d41caf76af5797=210=062
20250411-01:59:57.743751000 : 8=FIXT.1.19=28735=X49=Coinbase56=24ab46f784d1b20db435b852086e325034=6550=TEST52=20250411-01:59:57.619127369=2262=1c4ca071-c1b7-4b32-a10d-aab5f1327380268=1279=2269=1278=5b68d618-ecd8-4dd3-baf5-64d41caf76af83=159758151555=BTC-USD270=3.2271=0.0000000060=20250411-01:59:57.61736958=FILLED10=092
20250411-01:59:57.783858000 : 8=FIXT.1.19=28235=X49=Coinbase56=24ab46f784d1b20db435b852086e325034=6650=TEST52=20250411-01:59:57.664887369=2262=1c4ca071-c1b7-4b32-a10d-aab5f1327380268=1279=0269=083=159758151655=BTC-USD270=3.79271=0.6197183160=20250411-01:59:57.66371540=237=26f29162-0822-418b-92a3-d336da129ad810=115
20250411-01:59:57.784436000 : 8=FIXT.1.19=32535=X49=Coinbase56=24ab46f784d1b20db435b852086e325034=6750=TEST52=20250411-01:59:57.664935369=2262=1c4ca071-c1b7-4b32-a10d-aab5f1327380268=1279=0269=2278=c5b88ea9-605d-4595-ac52-f7c3f08523ba83=159758151755=BTC-USD270=3.55271=0.6197183160=20250411-01:59:57.66371537=26f29162-0822-418b-92a3-d336da129ad85797=110=059
20250411-01:59:57.784615000 : 8=FIXT.1.19=28835=X49=Coinbase56=24ab46f784d1b20db435b852086e325034=6850=TEST52=20250411-01:59:57.664941369=2262=1c4ca071-c1b7-4b32-a10d-aab5f1327380268=1279=2269=0278=26f29162-0822-418b-92a3-d336da129ad883=159758151855=BTC-USD270=3.79271=0.0000000060=20250411-01:59:57.66371558=FILLED10=016
20250411-01:59:57.841025000 : 8=FIXT.1.19=27735=X49=Coinbase56=24ab46f784d1b20db435b852086e325034=6950=TEST52=20250411-01:59:57.721487369=2262=1c4ca071-c1b7-4b32-a10d-aab5f1327380268=1279=0269=083=159758151955=BTC-USD29004=2.208895519560=20250411-01:59:57.71950640=137=4c005176-5588-43c3-96a6-e2148b84fecb10=224
20250411-01:59:57.841535000 : 8=FIXT.1.19=32535=X49=Coinbase56=24ab46f784d1b20db435b852086e325034=7050=TEST52=20250411-01:59:57.721495369=2262=1c4ca071-c1b7-4b32-a10d-aab5f1327380268=1279=0269=2278=c5b88ea9-605d-4595-ac52-f7c3f08523ba83=159758152055=BTC-USD270=3.55271=0.6222240960=20250411-01:59:57.71950637=4c005176-5588-43c3-96a6-e2148b84fecb5797=110=096
20250411-01:59:57.841715000 : 8=FIXT.1.19=26435=X49=Coinbase56=24ab46f784d1b20db435b852086e325034=7150=TEST52=20250411-01:59:57.721498369=2262=1c4ca071-c1b7-4b32-a10d-aab5f1327380268=1279=2269=0278=4c005176-5588-43c3-96a6-e2148b84fecb83=159758152155=BTC-USD60=20250411-01:59:57.71950658=FILLED10=224
20250411-01:59:57.869265000 : 8=FIXT.1.19=27335=X49=Coinbase56=24ab46f784d1b20db435b852086e325034=7250=TEST52=20250411-01:59:57.750159369=2262=1c4ca071-c1b7-4b32-a10d-aab5f1327380268=1279=0269=183=159758152255=BTC-USD271=0.6197183160=20250411-01:59:57.74892640=137=e3a5dcc7-0a39-4d59-8931-b74e5331014f10=039
20250411-01:59:57.869539000 : 8=FIXT.1.19=32535=X49=Coinbase56=24ab46f784d1b20db435b852086e325034=7350=TEST52=20250411-01:59:57.750165369=2262=1c4ca071-c1b7-4b32-a10d-aab5f1327380268=1279=0269=2278=4d60a78e-b39b-420e-b830-bc0f3f4fdde283=159758152355=BTC-USD270=3.53271=0.6197183160=20250411-01:59:57.74892637=e3a5dcc7-0a39-4d59-8931-b74e5331014f5797=210=025
20250411-01:59:57.871219000 : 8=FIXT.1.19=27935=X49=Coinbase56=24ab46f784d1b20db435b852086e325034=7450=TEST52=20250411-01:59:57.750167369=2262=1c4ca071-c1b7-4b32-a10d-aab5f1327380268=1279=2269=1278=e3a5dcc7-0a39-4d59-8931-b74e5331014f83=159758152455=BTC-USD271=0.0000000060=20250411-01:59:57.74892658=FILLED10=205
20250411-01:59:57.897696000 : 8=FIXT.1.19=27735=X49=Coinbase56=24ab46f784d1b20db435b852086e325034=7550=TEST52=20250411-01:59:57.778605369=2262=1c4ca071-c1b7-4b32-a10d-aab5f1327380268=1279=0269=083=159758152555=BTC-USD29004=2.208895519560=20250411-01:59:57.77711840=137=69eb3c7a-e871-4ef8-82c6-b4a121f4ba3210=152
20250411-01:59:57.897899000 : 8=FIXT.1.19=32535=X49=Coinbase56=24ab46f784d1b20db435b852086e325034=7650=TEST52=20250411-01:59:57.778610369=2262=1c4ca071-c1b7-4b32-a10d-aab5f1327380268=1279=0269=2278=c5b88ea9-605d-4595-ac52-f7c3f08523ba83=159758152655=BTC-USD270=3.55271=0.6222240960=20250411-01:59:57.77711837=69eb3c7a-e871-4ef8-82c6-b4a121f4ba325797=110=039
20250411-01:59:57.901406000 : 8=FIXT.1.19=26435=X49=Coinbase56=24ab46f784d1b20db435b852086e325034=7750=TEST52=20250411-01:59:57.778614369=2262=1c4ca071-c1b7-4b32-a10d-aab5f1327380268=1279=2269=0278=69eb3c7a-e871-4ef8-82c6-b4a121f4ba3283=159758152755=BTC-USD60=20250411-01:59:57.77711858=FILLED10=168
20250411-01:59:57.927858000 : 8=FIXT.1.19=27335=X49=Coinbase56=24ab46f784d1b20db435b852086e325034=7850=TEST52=20250411-01:59:57.808132369=2262=1c4ca071-c1b7-4b32-a10d-aab5f1327380268=1279=0269=183=159758152855=BTC-USD271=0.6197183160=20250411-01:59:57.80622340=137=91b0ffb2-c52a-4250-8e65-34a484957f0810=244
20250411-01:59:57.928316000 : 8=FIXT.1.19=32535=X49=Coinbase56=24ab46f784d1b20db435b852086e325034=7950=TEST52=20250411-01:59:57.808142369=2262=1c4ca071-c1b7-4b32-a10d-aab5f1327380268=1279=0269=2278=4d60a78e-b39b-420e-b830-bc0f3f4fdde283=159758152955=BTC-USD270=3.53271=0.6197183160=20250411-01:59:57.80622337=91b0ffb2-c52a-4250-8e65-34a484957f085797=210=234
20250411-01:59:57.928515000 : 8=FIXT.1.19=27935=X49=Coinbase56=24ab46f784d1b20db435b852086e325034=8050=TEST52=20250411-01:59:57.808157369=2262=1c4ca071-c1b7-4b32-a10d-aab5f1327380268=1279=2269=1278=91b0ffb2-c52a-4250-8e65-34a484957f0883=159758153055=BTC-USD271=0.0000000060=20250411-01:59:57.80622358=FILLED10=144
20250411-01:59:58.073367000 : 8=FIXT.1.19=27735=X49=Coinbase56=24ab46f784d1b20db435b852086e325034=8150=TEST52=20250411-01:59:57.949828369=2262=1c4ca071-c1b7-4b32-a10d-aab5f1327380268=1279=0269=083=159758153155=BTC-USD29004=2.208895519560=20250411-01:59:57.94834940=137=83a3ab85-e1b7-4273-afc8-9f18c09e331b10=113
20250411-01:59:58.074201000 : 8=FIXT.1.19=32535=X49=Coinbase56=24ab46f784d1b20db435b852086e325034=8250=TEST52=20250411-01:59:57.949909369=2262=1c4ca071-c1b7-4b32-a10d-aab5f1327380268=1279=0269=2278=c5b88ea9-605d-4595-ac52-f7c3f08523ba83=159758153255=BTC-USD270=3.55271=0.6222240960=20250411-01:59:57.94834937=83a3ab85-e1b7-4273-afc8-9f18c09e331b5797=110=004
20250411-01:59:58.074429000 : 8=FIXT.1.19=26435=X49=Coinbase56=24ab46f784d1b20db435b852086e325034=8350=TEST52=20250411-01:59:57.949915369=2262=1c4ca071-c1b7-4b32-a10d-aab5f1327380268=1279=2269=0278=83a3ab85-e1b7-4273-afc8-9f18c09e331b83=159758153355=BTC-USD60=20250411-01:59:57.94834958=FILLED10=126
20250411-01:59:58.077471000 : 8=FIXT.1.19=28235=X49=Coinbase56=24ab46f784d1b20db435b852086e325034=8450=TEST52=20250411-01:59:57.953367369=2262=1c4ca071-c1b7-4b32-a10d-aab5f1327380268=1279=0269=083=159758153455=BTC-USD270=3.85271=0.6232294660=20250411-01:59:57.95186440=237=38378f35-1840-47e8-8742-c32f9ba78edc10=189
20250411-01:59:58.077594000 : 8=FIXT.1.19=32535=X49=Coinbase56=24ab46f784d1b20db435b852086e325034=8550=TEST52=20250411-01:59:57.953371369=2262=1c4ca071-c1b7-4b32-a10d-aab5f1327380268=1279=0269=2278=c5b88ea9-605d-4595-ac52-f7c3f08523ba83=159758153555=BTC-USD270=3.55271=0.6232294660=20250411-01:59:57.95186437=38378f35-1840-47e8-8742-c32f9ba78edc5797=110=137
20250411-01:59:58.077797000 : 8=FIXT.1.19=28835=X49=Coinbase56=24ab46f784d1b20db435b852086e325034=8650=TEST52=20250411-01:59:57.953373369=2262=1c4ca071-c1b7-4b32-a10d-aab5f1327380268=1279=2269=0278=38378f35-1840-47e8-8742-c32f9ba78edc83=159758153655=BTC-USD270=3.85271=0.0000000060=20250411-01:59:57.95186458=FILLED10=098
20250411-01:59:58.098551000 : 8=FIXT.1.19=27335=X49=Coinbase56=24ab46f784d1b20db435b852086e325034=8750=TEST52=20250411-01:59:57.978689369=2262=1c4ca071-c1b7-4b32-a10d-aab5f1327380268=1279=0269=183=159758153755=BTC-USD271=0.6232294660=20250411-01:59:57.97700340=137=999cf3a3-18ef-4c8f-a2af-bafa8229952c10=059
20250411-01:59:58.098923000 : 8=FIXT.1.19=32535=X49=Coinbase56=24ab46f784d1b20db435b852086e325034=8850=TEST52=20250411-01:59:57.978694369=2262=1c4ca071-c1b7-4b32-a10d-aab5f1327380268=1279=0269=2278=4d60a78e-b39b-420e-b830-bc0f3f4fdde283=159758153855=BTC-USD270=3.53271=0.6232294660=20250411-01:59:57.97700337=999cf3a3-18ef-4c8f-a2af-bafa8229952c5797=210=044
20250411-01:59:58.099080000 : 8=FIXT.1.19=27935=X49=Coinbase56=24ab46f784d1b20db435b852086e325034=8950=TEST52=20250411-01:59:57.978697369=2262=1c4ca071-c1b7-4b32-a10d-aab5f1327380268=1279=2269=1278=999cf3a3-18ef-4c8f-a2af-bafa8229952c83=159758153955=BTC-USD271=0.0000000060=20250411-01:59:57.97700358=FILLED10=227
20250411-01:59:58.130960000 : 8=FIXT.1.19=28135=X49=Coinbase56=24ab46f784d1b20db435b852086e325034=9050=TEST52=20250411-01:59:58.007267369=2262=1c4ca071-c1b7-4b32-a10d-aab5f1327380268=1279=0269=183=159758154055=BTC-USD270=3.2271=0.6232294660=20250411-01:59:58.00643840=237=e8ff269b-22a6-4c92-9fd1-1d75e3508b1b10=229
20250411-01:59:58.132960000 : 8=FIXT.1.19=32535=X49=Coinbase56=24ab46f784d1b20db435b852086e325034=9150=TEST52=20250411-01:59:58.007272369=2262=1c4ca071-c1b7-4b32-a10d-aab5f1327380268=1279=0269=2278=4d60a78e-b39b-420e-b830-bc0f3f4fdde283=159758154155=BTC-USD270=3.53271=0.6232294660=20250411-01:59:58.00643837=e8ff269b-22a6-4c92-9fd1-1d75e3508b1b5797=210=108
20250411-01:59:58.133137000 : 8=FIXT.1.19=28735=X49=Coinbase56=24ab46f784d1b20db435b852086e325034=9250=TEST52=20250411-01:59:58.007380369=2262=1c4ca071-c1b7-4b32-a10d-aab5f1327380268=1279=2269=1278=e8ff269b-22a6-4c92-9fd1-1d75e3508b1b83=159758154255=BTC-USD270=3.2271=0.0000000060=20250411-01:59:58.00643858=FILLED10=137
20250411-01:59:58.354818000 : 8=FIXT.1.19=27735=X49=Coinbase56=24ab46f784d1b20db435b852086e325034=9350=TEST52=20250411-01:59:58.235483369=2262=1c4ca071-c1b7-4b32-a10d-aab5f1327380268=1279=0269=083=159758154355=BTC-USD29004=2.208895519560=20250411-01:59:58.23436640=137=18825b1a-07e8-4e52-b47c-711cb9f9726010=208
20250411-01:59:58.355420000 : 8=FIXT.1.19=32535=X49=Coinbase56=24ab46f784d1b20db435b852086e325034=9450=TEST52=20250411-01:59:58.235491369=2262=1c4ca071-c1b7-4b32-a10d-aab5f1327380268=1279=0269=2278=c5b88ea9-605d-4595-ac52-f7c3f08523ba83=159758154455=BTC-USD270=3.55271=0.6222240960=20250411-01:59:58.23436637=18825b1a-07e8-4e52-b47c-711cb9f972605797=110=098
20250411-01:59:58.357616000 : 8=FIXT.1.19=26435=X49=Coinbase56=24ab46f784d1b20db435b852086e325034=9550=TEST52=20250411-01:59:58.235507369=2262=1c4ca071-c1b7-4b32-a10d-aab5f1327380268=1279=2269=0278=18825b1a-07e8-4e52-b47c-711cb9f9726083=159758154555=BTC-USD60=20250411-01:59:58.23436658=FILLED10=221
20250411-01:59:58.382965000 : 8=FIXT.1.19=27335=X49=Coinbase56=24ab46f784d1b20db435b852086e325034=9650=TEST52=20250411-01:59:58.264285369=2262=1c4ca071-c1b7-4b32-a10d-aab5f1327380268=1279=0269=183=159758154655=BTC-USD271=0.6232294660=20250411-01:59:58.26252440=137=7b5415ec-3e8a-4497-b064-9fbf9ffe847910=166
20250411-01:59:58.383267000 : 8=FIXT.1.19=32535=X49=Coinbase56=24ab46f784d1b20db435b852086e325034=9750=TEST52=20250411-01:59:58.264336369=2262=1c4ca071-c1b7-4b32-a10d-aab5f1327380268=1279=0269=2278=4d60a78e-b39b-420e-b830-bc0f3f4fdde283=159758154755=BTC-USD270=3.53271=0.6232294660=20250411-01:59:58.26252437=7b5415ec-3e8a-4497-b064-9fbf9ffe84795797=210=152
20250411-01:59:58.383530000 : 8=FIXT.1.19=27935=X49=Coinbase56=24ab46f784d1b20db435b852086e325034=9850=TEST52=20250411-01:59:58.264392369=2262=1c4ca071-c1b7-4b32-a10d-aab5f1327380268=1279=2269=1278=7b5415ec-3e8a-4497-b064-9fbf9ffe847983=159758154855=BTC-USD271=0.0000000060=20250411-01:59:58.26252458=FILLED10=078
20250411-01:59:58.528665000 : 8=FIXT.1.19=28235=X49=Coinbase56=24ab46f784d1b20db435b852086e325034=9950=TEST52=20250411-01:59:58.409260369=2262=1c4ca071-c1b7-4b32-a10d-aab5f1327380268=1279=0269=083=159758154955=BTC-USD270=3.83271=0.6232294660=20250411-01:59:58.40830940=237=7da6d52f-b5bd-4e34-8a1a-b974cad19a8b10=232
20250411-01:59:58.529082000 : 8=FIXT.1.19=32635=X49=Coinbase56=24ab46f784d1b20db435b852086e325034=10050=TEST52=20250411-01:59:58.409322369=2262=1c4ca071-c1b7-4b32-a10d-aab5f1327380268=1279=0269=2278=c5b88ea9-605d-4595-ac52-f7c3f08523ba83=159758155055=BTC-USD270=3.55271=0.6232294660=20250411-01:59:58.40830937=7da6d52f-b5bd-4e34-8a1a-b974cad19a8b5797=110=208
20250411-01:59:58.529260000 : 8=FIXT.1.19=28935=X49=Coinbase56=24ab46f784d1b20db435b852086e325034=10150=TEST52=20250411-01:59:58.409325369=2262=1c4ca071-c1b7-4b32-a10d-aab5f1327380268=1279=2269=0278=7da6d52f-b5bd-4e34-8a1a-b974cad19a8b83=159758155155=BTC-USD270=3.83271=0.0000000060=20250411-01:59:58.40830958=FILLED10=168
20250411-01:59:58.583645000 : 8=FIXT.1.19=28335=X49=Coinbase56=24ab46f784d1b20db435b852086e325034=10250=TEST52=20250411-01:59:58.464489369=2262=1c4ca071-c1b7-4b32-a10d-aab5f1327380268=1279=0269=183=159758155255=BTC-USD270=3.22271=0.6232294660=20250411-01:59:58.46273640=237=c17cd63b-728e-4ccb-8f93-f7ea0779dca110=238
20250411-01:59:58.585949000 : 8=FIXT.1.19=32635=X49=Coinbase56=24ab46f784d1b20db435b852086e325034=10350=TEST52=20250411-01:59:58.464508369=2262=1c4ca071-c1b7-4b32-a10d-aab5f1327380268=1279=0269=2278=4d60a78e-b39b-420e-b830-bc0f3f4fdde283=159758155355=BTC-USD270=3.53271=0.6232294660=20250411-01:59:58.46273637=c17cd63b-728e-4ccb-8f93-f7ea0779dca15797=210=062
20250411-01:59:58.586158000 : 8=FIXT.1.19=28935=X49=Coinbase56=24ab46f784d1b20db435b852086e325034=10450=TEST52=20250411-01:59:58.464528369=2262=1c4ca071-c1b7-4b32-a10d-aab5f1327380268=1279=2269=1278=c17cd63b-728e-4ccb-8f93-f7ea0779dca183=159758155455=BTC-USD270=3.22271=0.0000000060=20250411-01:59:58.46273658=FILLED10=144
20250411-01:59:58.761598000 : 8=FIXT.1.19=28335=X49=Coinbase56=24ab46f784d1b20db435b852086e325034=10550=TEST52=20250411-01:59:58.638594369=2262=1c4ca071-c1b7-4b32-a10d-aab5f1327380268=1279=0269=183=159758155555=BTC-USD270=3.23271=0.6232294660=20250411-01:59:58.63683340=237=51bc1298-b184-43eb-8702-8d812ec4391e10=204
20250411-01:59:58.765901000 : 8=FIXT.1.19=32635=X49=Coinbase56=24ab46f784d1b20db435b852086e325034=10650=TEST52=20250411-01:59:58.638603369=2262=1c4ca071-c1b7-4b32-a10d-aab5f1327380268=1279=0269=2278=4d60a78e-b39b-420e-b830-bc0f3f4fdde283=159758155655=BTC-USD270=3.53271=0.6232294660=20250411-01:59:58.63683337=51bc1298-b184-43eb-8702-8d812ec4391e5797=210=026
20250411-01:59:58.766496000 : 8=FIXT.1.19=28935=X49=Coinbase56=24ab46f784d1b20db435b852086e325034=10750=TEST52=20250411-01:59:58.638605369=2262=1c4ca071-c1b7-4b32-a10d-aab5f1327380268=1279=2269=1278=51bc1298-b184-43eb-8702-8d812ec4391e83=159758155755=BTC-USD270=3.23271=0.0000000060=20250411-01:59:58.63683358=FILLED10=109
20250411-01:59:58.813694000 : 8=FIXT.1.19=28235=X49=Coinbase56=24ab46f784d1b20db435b852086e325034=10850=TEST52=20250411-01:59:58.693047369=2262=1c4ca071-c1b7-4b32-a10d-aab5f1327380268=1279=0269=083=159758155855=BTC-USD270=3.8271=0.6232294660=20250411-01:59:58.69161640=237=407f8ad7-aece-4be6-8e65-ec7475785a6a10=162
20250411-01:59:58.814728000 : 8=FIXT.1.19=32635=X49=Coinbase56=24ab46f784d1b20db435b852086e325034=10950=TEST52=20250411-01:59:58.693054369=2262=1c4ca071-c1b7-4b32-a10d-aab5f1327380268=1279=0269=2278=c5b88ea9-605d-4595-ac52-f7c3f08523ba83=159758155955=BTC-USD270=3.55271=0.6232294660=20250411-01:59:58.69161637=407f8ad7-aece-4be6-8e65-ec7475785a6a5797=110=167
20250411-01:59:58.815045000 : 8=FIXT.1.19=28835=X49=Coinbase56=24ab46f784d1b20db435b852086e325034=11050=TEST52=20250411-01:59:58.693058369=2262=1c4ca071-c1b7-4b32-a10d-aab5f1327380268=1279=2269=0278=407f8ad7-aece-4be6-8e65-ec7475785a6a83=159758156055=BTC-USD270=3.8271=0.0000000060=20250411-01:59:58.69161658=FILLED10=058
20250411-01:59:58.858704000 : 8=FIXT.1.19=91835=W49=Coinbase56=24ab46f784d1b20db435b852086e325034=11150=TEST52=20250411-01:59:58.739841369=2262=1c4ca071-c1b7-4b32-a10d-aab5f132738083=1597581557893=N55=BTC-USD1682=full_trading268=10269=0278=4d60a78e-b39b-420e-b830-bc0f3f4fdde2270=3.53271=255648.31857975269=0278=9d9353ab-229f-423a-89a3-c52a46543bc9270=3.53271=18127.30103418269=0278=fdbc7e1d-ccf4-462b-8ff6-948d33767188270=3.51271=0.62322946269=0278=f5fc5e68-a52c-44d3-87ef-3785312f4782270=3.48271=0.29310888269=0278=dcccb470-c535-433a-9198-4e2b4c26d99d270=3.47271=0.29311495269=0278=f05d9766-970d-44ca-aa4d-e8b2720bbda8270=3.46271=0.29026870269=0278=2c4d7d5a-33aa-4058-b546-480b6a2168a4270=3.44271=0.29828577269=0278=37dbcf16-0b3d-4f67-bc90-e36268b99e0e270=3.42271=0.30270947269=0278=be5191de-eb81-4170-aece-43cb79ec15b8270=3.42271=0.62322946269=0278=4c63c0b7-30e0-4ef1-931f-0090359f978e270=3.41271=0.3215896210=159
20250411-01:59:58.863428000 : 8=FIXT.1.19=14135=334=349=24ab46f784d1b20db435b852086e325052=20250411-01:59:58.86256=Coinbase45=11158=Tag appears more than once371=269372=W373=1310=003
20250411-01:59:58.863607000 : 8=FIXT.1.19=90935=W49=Coinbase56=24ab46f784d1b20db435b852086e325034=11250=TEST52=20250411-01:59:58.740082369=2262=1c4ca071-c1b7-4b32-a10d-aab5f132738083=1597581557893=N55=BTC-USD1682=full_trading268=10269=0278=d6b4aa4e-d588-4c96-83aa-8e8d8accb1a4270=3.41271=0.30121104269=0278=1427699a-fe0c-4a1f-8735-bd2913dcabdc270=3.41271=0.57022311269=0278=e8b3d8da-1663-413c-b7fb-6aba23b01440270=3.39271=0.31006477269=0278=bcbe17c3-9059-4c38-8ab8-8e78f1ef9062270=3.38271=0.32617981269=0278=b9eb1261-8bf8-4e3c-af53-33aa2b72067b270=3.38271=0.62322946269=0278=57bb77fd-337f-49bc-a56f-a4e2dff851ee270=3.37271=0.31071676269=0278=b7a2004c-41b5-42c2-80e8-60bb80b63a11270=3.36271=0.62322946269=0278=ded4b51d-349f-4726-8379-6761a3576bb6270=3.33271=0.31560513269=0278=ff7aff09-38de-47ac-a3cb-9beacb0b9ad8270=3.33271=0.30682342269=0278=d1da558a-e9d2-4e11-b26e-1eb80a1a34c5270=3.32271=0.3170068510=033
20250411-01:59:58.864295000 : 8=FIXT.1.19=14135=334=449=24ab46f784d1b20db435b852086e325052=20250411-01:59:58.86356=Coinbase45=11258=Tag appears more than once371=269372=W373=1310=006
20250411-01:59:58.864392000 : 8=FIXT.1.19=90935=W49=Coinbase56=24ab46f784d1b20db435b852086e325034=11350=TEST52=20250411-01:59:58.740329369=2262=1c4ca071-c1b7-4b32-a10d-aab5f132738083=1597581557893=N55=BTC-USD1682=full_trading268=10269=0278=9ee34527-d4d8-4659-b2ea-cdff3dc4a8fa270=3.32271=0.32181951269=0278=7abf2220-0421-460f-9dbb-14c41564e41a270=3.32271=0.31308436269=0278=69634ec5-f71a-4990-b56d-13c3069a455a270=3.31271=0.32329458269=0278=2f333c17-a386-4d52-8ff1-eadcb99bc22f270=3.31271=0.31999220269=0278=f02efc37-0b1e-470b-99ef-e31012887d73270=3.30271=0.32771570269=0278=6d430950-8078-4987-8995-e581564e368d270=3.29271=0.30702763269=0278=841f895a-cd2d-4082-9a37-b50fc19e35bf270=3.28271=0.32610801269=0278=3cf93093-e42b-4c24-95ea-c367d96427fe270=3.27271=0.33588654269=0278=f29c94bc-d1c2-4145-97b0-ecb77d81a8bf270=3.27271=0.31661408269=0278=d208c4fb-56c6-4911-85c9-77b68a5ba6ab270=3.25271=0.3096162310=030
20250411-01:59:58.865037000 : 8=FIXT.1.19=14135=334=549=24ab46f784d1b20db435b852086e325052=20250411-01:59:58.86456=Coinbase45=11358=Tag appears more than once371=269372=W373=1310=009
20250411-01:59:58.865220000 : 8=FIXT.1.19=90935=W49=Coinbase56=24ab46f784d1b20db435b852086e325034=11450=TEST52=20250411-01:59:58.740579369=2262=1c4ca071-c1b7-4b32-a10d-aab5f132738083=1597581557893=N55=BTC-USD1682=full_trading268=10269=0278=e88796ff-68c8-4463-914b-46e09fbaf639270=3.25271=0.33589845269=0278=06f345fb-0292-45fc-8237-9ad1a84b541c270=3.24271=0.31528507269=0278=fa20c2c7-df80-4941-9a9c-a6ef2e579480270=3.23271=0.33432448269=0278=a833d230-a749-4bf4-823e-93adc40b773d270=3.23271=0.31165878269=0278=2abb6e15-b9cd-415b-8c9b-99a61c750310270=3.22271=0.32048714269=0278=ec44a6d8-ae5f-4809-89d7-0f7a3adac547270=3.21271=0.33230954269=0278=9cf61c67-c4fc-4bac-92fd-d4e2b56248aa270=3.21271=0.33583951269=0278=210b2518-bb42-461a-9c7e-b4e04c5ffcc6270=3.21271=0.32669007269=0278=2e3fa1b2-20f1-4694-9be4-322040b75152270=3.21271=0.32907979269=0278=05dd5607-92c9-4296-8cdc-27cdff004dea270=3.21271=0.3277607510=040
20250411-01:59:58.865798000 : 8=FIXT.1.19=14135=334=649=24ab46f784d1b20db435b852086e325052=20250411-01:59:58.86556=Coinbase45=11458=Tag appears more than once371=269372=W373=1310=012
20250411-01:59:58.865886000 : 8=FIXT.1.19=91035=W49=Coinbase56=24ab46f784d1b20db435b852086e325034=11550=TEST52=20250411-01:59:58.740829369=2262=1c4ca071-c1b7-4b32-a10d-aab5f132738083=1597581557893=N55=BTC-USD1682=full_trading268=10269=0278=87944de7-a5f1-4033-a3d8-cbc10f3a5232270=3.20271=0.32225170269=0278=30f6bb59-2469-4e6d-8fa5-13666373901f270=3.19271=0.31386496269=0278=6a5d2852-7ddc-456e-acb5-bfadcc0c1360270=3.19271=0.32157390269=0278=5d00d8a2-5aea-4836-ba19-74fe67116df8270=3.18271=0.32651049269=0278=acc71746-3591-4dde-a7e2-c2795d0ad125270=3.17271=0.31577131269=0278=13982796-c2a8-4740-95e2-5aca0fdfd8bb270=3.16271=0.33021170269=0278=9f2f0737-661e-43d7-89f9-959ed5e08306270=3.16271=0.33082075269=0278=7e0e2d14-fa77-4978-8cae-d9660fd13e6d270=3.16271=0.32014975269=0278=82826a7d-848c-4516-a7b6-5ec6881609a8270=2.00271=10.00000000269=0278=590048d5-ee44-49dc-b66d-1a692e055133270=1.94271=0.5154639210=099
20250411-01:59:58.866529000 : 8=FIXT.1.19=14135=334=749=24ab46f784d1b20db435b852086e325052=20250411-01:59:58.86656=Coinbase45=11558=Tag appears more than once371=269372=W373=1310=015
20250411-01:59:58.866667000 : 8=FIXT.1.19=90935=W49=Coinbase56=24ab46f784d1b20db435b852086e325034=11650=TEST52=20250411-01:59:58.741079369=2262=1c4ca071-c1b7-4b32-a10d-aab5f132738083=1597581557893=N55=BTC-USD1682=full_trading268=10269=0278=22bdda11-16cd-488b-9fa9-da098dad543e270=1.94271=0.51546392269=0278=d356ef8b-596e-47e7-bf90-cc015b85fc57270=1.93271=0.52331606269=0278=aa8d48bc-97fb-4d00-b923-66d37cc8c66a270=1.93271=0.52331606269=0278=7d51dcb4-a7f8-4cca-b2d0-e902403d1b9f270=1.93271=0.52331606269=0278=f7680950-3af2-4723-a6e4-5cbd528ca900270=1.93271=0.52331606269=0278=fdeff994-4866-47af-9dde-a25947a26606270=1.93271=0.52331606269=0278=65e7e2bb-023d-4936-bb4e-ff7625ba7264270=1.93271=0.52331606269=0278=53732639-572c-4cd5-b61e-e4f534d1d540270=1.93271=0.52331606269=0278=24da8927-1dd1-468b-9437-ff366f5bfa11270=1.93271=0.52331606269=0278=baa5862c-41e8-458c-83d3-c095bb68ed17270=1.93271=0.5233160610=242
20250411-01:59:58.867216000 : 8=FIXT.1.19=14135=334=849=24ab46f784d1b20db435b852086e325052=20250411-01:59:58.86656=Coinbase45=11658=Tag appears more than once371=269372=W373=1310=017
20250411-01:59:58.867293000 : 8=FIXT.1.19=90935=W49=Coinbase56=24ab46f784d1b20db435b852086e325034=11750=TEST52=20250411-01:59:58.741329369=2262=1c4ca071-c1b7-4b32-a10d-aab5f132738083=1597581557893=N55=BTC-USD1682=full_trading268=10269=0278=92a3c3e3-7afe-4d02-a0d8-96f512b63bb7270=1.93271=0.52331606269=0278=9d2a564e-f178-4966-9baf-5814a1c1686b270=1.93271=0.52331606269=0278=f9e6b978-87f6-4397-8d82-07cf698c123f270=1.93271=0.52331606269=0278=3e64b388-13d3-441d-b241-aa8dd6fe55e6270=1.93271=0.52331606269=0278=60300433-87b0-4031-bb1e-12cf9d773d3f270=1.93271=0.52331606269=0278=1bdd5f5a-1d99-4eed-af09-c187bcbbd2d8270=1.93271=0.52331606269=0278=4ed6f6b9-77fb-4255-a188-f243dd0cdb3c270=1.93271=0.52331606269=0278=9ad1fc18-5a38-4edb-ac5c-6ac826a8a846270=1.93271=0.52331606269=0278=1c218c8c-baea-4a1f-838e-4a3a94b468e1270=1.93271=0.52331606269=0278=fd70f5e2-d2c9-472a-ab40-a775afafd73d270=1.93271=0.5233160610=030
20250411-01:59:58.867811000 : 8=FIXT.1.19=14135=334=949=24ab46f784d1b20db435b852086e325052=20250411-01:59:58.86756=Coinbase45=11758=Tag appears more than once371=269372=W373=1310=020
20250411-01:59:58.867887000 : 8=FIXT.1.19=90935=W49=Coinbase56=24ab46f784d1b20db435b852086e325034=11850=TEST52=20250411-01:59:58.741579369=2262=1c4ca071-c1b7-4b32-a10d-aab5f132738083=1597581557893=N55=BTC-USD1682=full_trading268=10269=0278=96f5e3a5-1c2a-4db6-a3fb-fd1f13d5d559270=1.93271=0.52331606269=0278=4a015a4c-490a-4c40-974f-9dfb7feb335d270=1.93271=0.52331606269=0278=d919363e-2c54-404f-bc0b-063e2f12bec4270=1.93271=0.52331606269=0278=d4636d6c-85c6-4ac9-9afb-70ca636f4ad4270=1.93271=0.52331606269=0278=bda09690-f345-4c33-ae8b-e8c78da11b5a270=1.93271=0.52331606269=0278=1a81ae10-b700-42a0-89a3-7d7a3eea0ebb270=1.93271=0.52331606269=0278=1ace5afa-e550-4abf-a458-52e46e1b54f0270=1.93271=0.52331606269=0278=2332d1c9-67e7-457a-abfe-f5e9a8c2ea05270=1.93271=0.52331606269=0278=6afa1f19-0ec5-49fd-8b74-06a12a6c5ca9270=1.93271=0.52331606269=0278=3fa3413d-c26c-472f-9cc5-da1c48935c63270=1.93271=0.5233160610=016
20250411-01:59:58.868357000 : 8=FIXT.1.19=14235=334=1049=24ab46f784d1b20db435b852086e325052=20250411-01:59:58.86856=Coinbase45=11858=Tag appears more than once371=269372=W373=1310=063
20250411-01:59:58.868429000 : 8=FIXT.1.19=90935=W49=Coinbase56=24ab46f784d1b20db435b852086e325034=11950=TEST52=20250411-01:59:58.741829369=2262=1c4ca071-c1b7-4b32-a10d-aab5f132738083=1597581557893=N55=BTC-USD1682=full_trading268=10269=0278=3f9e43c4-2e62-4d51-b4cb-ad207c693331270=1.93271=0.52331606269=0278=29e8bfcf-c764-4f7e-997d-09abf72bbc00270=1.93271=0.52331606269=0278=cf3e8b26-09ae-4dfb-9b84-b12a7e199a5a270=1.93271=0.52331606269=0278=08db3e51-e927-47d3-a9dd-2f887c58dc85270=1.93271=0.52331606269=0278=353ae741-9473-4cc5-9ab7-7e5de8ae55d0270=1.93271=0.52331606269=0278=4d037208-2072-480f-98ac-7be9c24f18f4270=1.93271=0.52331606269=0278=b598f678-da6e-4c01-90ed-d702c42f8a65270=1.93271=0.52331606269=0278=5f69b1a0-b5d1-4715-9be1-9bdf008d97d7270=1.93271=0.52331606269=0278=ef063d15-248a-4eae-97f4-278be5106d80270=1.93271=0.52331606269=0278=f8b20207-84bc-44e9-a2fe-9ad775e2ecb1270=1.93271=0.5233160610=252
20250411-01:59:58.868906000 : 8=FIXT.1.19=14235=334=1149=24ab46f784d1b20db435b852086e325052=20250411-01:59:58.86856=Coinbase45=11958=Tag appears more than once371=269372=W373=1310=065
20250411-01:59:58.868975000 : 8=FIXT.1.19=90935=W49=Coinbase56=24ab46f784d1b20db435b852086e325034=12050=TEST52=20250411-01:59:58.742079369=2262=1c4ca071-c1b7-4b32-a10d-aab5f132738083=1597581557893=N55=BTC-USD1682=full_trading268=10269=0278=75bce2b7-bc58-4479-8bfb-144f88f2262b270=1.93271=0.52331606269=0278=1f6e2a79-8b10-4a7f-89de-0f1fa03692c7270=1.93271=0.52331606269=0278=d1b80bf5-9b17-44b4-9577-6fe71170b578270=1.93271=0.52331606269=0278=b891e26a-c20c-4fce-ba1c-487fe139a4cc270=1.93271=0.52331606269=0278=5d06d3f6-3189-4394-b3c5-6a2bda14b6d1270=1.93271=0.52331606269=0278=e5791c0f-3937-4a66-9b98-26f79a3891be270=1.93271=0.52331606269=0278=c62591c6-7dfa-46a7-8f20-6a5f22804999270=1.93271=0.52331606269=0278=7c503558-c0b8-457b-8c46-71ece3f7fc8a270=1.93271=0.52331606269=0278=f763bb56-2f21-4a9b-bd48-f84dc1bd5ee5270=1.93271=0.52331606269=0278=42214b03-1fc2-46b3-9e83-91b23a510e5a270=1.93271=0.5233160610=056
20250411-01:59:58.869431000 : 8=FIXT.1.19=14235=334=1249=24ab46f784d1b20db435b852086e325052=20250411-01:59:58.86956=Coinbase45=12058=Tag appears more than once371=269372=W373=1310=059
20250411-01:59:58.869551000 : 8=FIXT.1.19=90935=W49=Coinbase56=24ab46f784d1b20db435b852086e325034=12150=TEST52=20250411-01:59:58.742329369=2262=1c4ca071-c1b7-4b32-a10d-aab5f132738083=1597581557893=N55=BTC-USD1682=full_trading268=10269=0278=1c7c52ed-7d39-4326-b3b8-98f05a9b3ef0270=1.93271=0.52331606269=0278=3313309e-45e7-4e7b-8c55-4f9a8ec1b351270=1.93271=0.52331606269=0278=78801ffb-ec5a-4c74-9d08-3e86fd9db4dd270=1.93271=0.52331606269=0278=abe6eea4-1d9c-47d7-847f-2f44aa561b3f270=1.93271=0.52331606269=0278=6a6eb56d-2010-43e2-b78e-5f098081bb64270=1.93271=0.52331606269=0278=b53c01ff-f450-4b05-8ad1-e7894b45e0e0270=1.93271=0.52331606269=0278=4747863e-c0a6-4ef5-8faf-e8934bca4f8b270=1.93271=0.52331606269=0278=81a8a629-57f4-4e3a-ac25-2e9ee1f357c2270=1.93271=0.52331606269=0278=1e239259-7be4-476a-845d-1b92fd951d8b270=1.93271=0.52331606269=0278=189eb272-48f9-4915-b7e1-a86dcc505c4a270=1.93271=0.5233160610=148
20250411-01:59:58.869988000 : 8=FIXT.1.19=14235=334=1349=24ab46f784d1b20db435b852086e325052=20250411-01:59:58.86956=Coinbase45=12158=Tag appears more than once371=269372=W373=1310=061
20250411-01:59:58.870050000 : 8=FIXT.1.19=90935=W49=Coinbase56=24ab46f784d1b20db435b852086e325034=12250=TEST52=20250411-01:59:58.742579369=2262=1c4ca071-c1b7-4b32-a10d-aab5f132738083=1597581557893=N55=BTC-USD1682=full_trading268=10269=0278=0562b9f7-aae3-4961-bd97-f5b8cde0ec34270=1.93271=0.52331606269=0278=5103331b-7300-487b-bc2c-a6032bf4be7e270=1.93271=0.52331606269=0278=78ac85ac-2478-4991-a084-7286982b77cc270=1.93271=0.52331606269=0278=6993b26d-d6dc-4f99-8a53-9500ae5b4ff1270=1.93271=0.52331606269=0278=1c96ab9d-04a6-465a-87e5-3ed33970178f270=1.93271=0.52331606269=0278=6fc0282b-d538-4aa3-8982-bda02bb1b054270=1.93271=0.52331606269=0278=80870aa3-04a2-4d2a-8669-93215130ffee270=1.93271=0.52331606269=0278=b274e872-6923-45fd-b48a-68e685e769cb270=1.93271=0.52331606269=0278=2d4364c0-239c-4f4b-8ce4-2acfe0bb343d270=1.12271=1.00000000269=0278=8fa16a4f-377f-4deb-9a8e-1020aed9edf4270=1.00271=1.0000000010=056
20250411-01:59:58.870837000 : 8=FIXT.1.19=14235=334=1449=24ab46f784d1b20db435b852086e325052=20250411-01:59:58.87056=Coinbase45=12258=Tag appears more than once371=269372=W373=1310=055
20250411-01:59:58.870932000 : 8=FIXT.1.19=92835=W49=Coinbase56=24ab46f784d1b20db435b852086e325034=12350=TEST52=20250411-01:59:58.742829369=2262=1c4ca071-c1b7-4b32-a10d-aab5f132738083=1597581557893=N55=BTC-USD1682=full_trading268=10269=1278=c5b88ea9-605d-4595-ac52-f7c3f08523ba270=3.55271=5624.82164548269=1278=81523bd3-8912-4789-8761-89a9ee42794b270=3.55271=0.30518966269=1278=60fc75ca-0052-40b7-9f18-a6aad9d31b84270=3.56271=18037.00000000269=1278=ad00e2cd-d925-46a4-9e7e-941c6faed2c7270=3.57271=18027.00000000269=1278=fec191b5-64da-4a15-ab4b-36a0d3d10750270=3.57271=0.29025301269=1278=792fa54a-2068-4c20-ba3f-6579c5d1b042270=3.57271=0.62184873269=1278=0d43f23a-5517-46ec-8191-7b19b0c83f70270=3.57271=0.62322946269=1278=02a780aa-8154-4638-a5ca-53b8198cc724270=3.58271=16937.00000000269=1278=911349fb-1960-4904-9a38-0e2497fb7ccb270=3.58271=0.29896312269=1278=d91e89d4-ac5c-4853-9879-ec8ff5e00a71270=3.59271=17163.0000000010=161
20250411-01:59:58.871785000 : 8=FIXT.1.19=14235=334=1549=24ab46f784d1b20db435b852086e325052=20250411-01:59:58.87156=Coinbase45=12358=Tag appears more than once371=269372=W373=1310=058
20250411-01:59:58.987963000 : 8=FIXT.1.19=92535=W49=Coinbase56=24ab46f784d1b20db435b852086e325034=12450=TEST52=20250411-01:59:58.743079369=2262=1c4ca071-c1b7-4b32-a10d-aab5f132738083=1597581557893=N55=BTC-USD1682=full_trading268=10269=1278=d68d2389-fda4-456e-a285-3787e94c7c88270=3.59271=0.62293159269=1278=341d0ad8-6c15-4b5e-aebb-e3caa5af575c270=3.60271=17926.00000000269=1278=b175a3bc-9391-4e0a-b8f2-4c919d3a4f18270=3.60271=0.62286748269=1278=19f17d37-d517-4a55-bfc5-9d93c206d1ba270=3.60271=0.62322946269=1278=9d239e03-1215-4cc7-ad44-3f4097ee70ea270=3.61271=18058.08928020269=1278=dbb0f332-4189-4df5-879b-e55860b13def270=3.62271=0.28062774269=1278=f7639c39-7e8b-44d1-a2f2-9807e2a3228c270=3.62271=0.27709851269=1278=83be9389-2099-4173-a322-b0933bc99358270=3.62271=19973.00000000269=1278=b89abc22-6b6c-4474-b3fc-ffe21f05cd4e270=3.63271=20016.00000000269=1278=ce0af8a3-149c-4603-905a-be65625fe014270=3.64271=0.2780600210=237
20250411-01:59:58.989323000 : 8=FIXT.1.19=14235=334=1649=24ab46f784d1b20db435b852086e325052=20250411-01:59:58.98856=Coinbase45=12458=Tag appears more than once371=269372=W373=1310=069
20250411-01:59:58.989447000 : 8=FIXT.1.19=91335=W49=Coinbase56=24ab46f784d1b20db435b852086e325034=12550=TEST52=20250411-01:59:58.743330369=2262=1c4ca071-c1b7-4b32-a10d-aab5f132738083=1597581557893=N55=BTC-USD1682=full_trading268=10269=1278=94b8615f-6fa7-4dc9-bbfa-435fe535bebc270=3.64271=22352.63489459269=1278=cae3885d-f5b2-4de1-830c-0085e27bbb69270=3.69271=0.27722678269=1278=98b269f7-e916-4d1c-936f-585d9d9b2a38270=3.70271=0.62322946269=1278=b9732128-11b1-44fd-bea3-94da9fc853fb270=3.71271=0.28488329269=1278=818b83a4-e14e-4ad5-b094-6733f0504003270=3.75271=0.27930225269=1278=3e6990a0-8ef4-4968-8ee8-89b7346c197d270=3.76271=0.28131365269=1278=342794c8-a9d2-4aa5-9886-a819398d69c6270=3.88271=0.27719712269=1278=2839680b-48b3-4f53-86b1-9269987275e7270=3.91271=0.26621275269=1278=fd7b5361-29f8-4b35-bae5-232a64f657b4270=3.95271=0.26131406269=1278=5edaeed0-fae9-4f36-8c77-6fbedf61eefc270=4.02271=0.2509122710=156
20250411-01:59:58.990332000 : 8=FIXT.1.19=14235=334=1749=24ab46f784d1b20db435b852086e325052=20250411-01:59:58.98956=Coinbase45=12558=Tag appears more than once371=269372=W373=1310=072
20250411-01:59:59.040413000 : 8=FIXT.1.19=92335=W49=Coinbase56=24ab46f784d1b20db435b852086e325034=12650=TEST52=20250411-01:59:58.743580369=2262=1c4ca071-c1b7-4b32-a10d-aab5f132738083=1597581557893=N55=BTC-USD1682=full_trading268=10269=1278=fdbbfd04-ba67-4b23-bbc1-f87f929e7e81270=4.07271=0.24812642269=1278=534b2a85-0852-420d-928b-70cdb6ba2457270=4.10271=0.26961968269=1278=b009f8a1-4a39-493b-b96e-d783e981c915270=4.26271=0.25019574269=1278=729a899c-ac2d-4541-b0a2-cbdd5df9bf98270=10.00271=10.00000000269=1278=eb1e5d45-d081-4ef8-a83e-1f5348fbda96270=10.00271=10.00000000269=1278=0cd67977-85eb-45fa-ae72-d45b92ca24f4270=10.00271=10.00000000269=1278=5d931559-6758-4b75-9d6d-6438d25b497f270=10.00271=10.00000000269=1278=57e43d1d-644a-493e-acd3-69dc5e64dcde270=10.00271=10.00000000269=1278=c1566121-2b63-494d-ac2d-973e9f0115c0270=10.00271=10.00000000269=1278=d0c4a771-9035-4db9-ae7b-ad2d1db5646d270=10.00271=10.0000000010=121
20250411-01:59:59.041134000 : 8=FIXT.1.19=14235=334=1849=24ab46f784d1b20db435b852086e325052=20250411-01:59:59.04056=Coinbase45=12658=Tag appears more than once371=269372=W373=1310=053
20250411-01:59:59.041228000 : 8=FIXT.1.19=93135=W49=Coinbase56=24ab46f784d1b20db435b852086e325034=12750=TEST52=20250411-01:59:58.743831369=2262=1c4ca071-c1b7-4b32-a10d-aab5f132738083=1597581557893=N55=BTC-USD1682=full_trading268=10269=1278=52c644ea-628a-4576-8e7e-27ec4c90398b270=10.00271=10.00000000269=1278=c3483f66-d8ce-489a-90b9-2bce69e054ee270=10.00271=10.00000000269=1278=55992a5c-cbcd-464a-8f8d-8b58e81e5c0b270=10.00271=10.00000000269=1278=19077009-6f26-4e2d-9dab-04a28231b752270=10.00271=10.00000000269=1278=692097d1-c978-4024-95e9-2bf348b64bbd270=10.00271=10.00000000269=1278=99a92935-11b7-4f21-a64c-c746b53d1777270=10.00271=10.00000000269=1278=dc024b0b-0337-4215-9669-5e5636834397270=10.00271=10.00000000269=1278=c90fcc3a-a36c-4c14-b57f-6db78762e017270=10.00271=10.00000000269=1278=7841891a-bb7c-4034-97c1-41164185edc7270=1000.00271=3.10000000269=1278=381c9fa7-1add-4dd2-9233-f41e2c8821fe270=1000.00271=3.1000000010=156
20250411-01:59:59.042219000 : 8=FIXT.1.19=14235=334=1949=24ab46f784d1b20db435b852086e325052=20250411-01:59:59.04156=Coinbase45=12758=Tag appears more than once371=269372=W373=1310=056
20250411-01:59:59.042409000 : 8=FIXT.1.19=93935=W49=Coinbase56=24ab46f784d1b20db435b852086e325034=12850=TEST52=20250411-01:59:58.744079369=2262=1c4ca071-c1b7-4b32-a10d-aab5f132738083=1597581557893=N55=BTC-USD1682=full_trading268=10269=1278=928e65c2-7e2d-478b-9310-414fb77f5aae270=1000.00271=3.10000000269=1278=ad4bd3ac-9276-40d5-90f9-e47b1d8ee953270=1000.00271=3.10000000269=1278=79e799dc-4a3d-4922-ad1a-f74eb7eff789270=1000.00271=3.10000000269=1278=04f642b7-750f-4967-b786-0d48eea0f158270=1000.00271=3.10000000269=1278=d0ad653d-3272-4a3b-ba7a-a52029a67a92270=1000.00271=3.10000000269=1278=cad40464-4c62-4bf3-8444-c487fcc8dd01270=1000.00271=3.10000000269=1278=426c6428-d481-4ff7-9de3-f00ff219d654270=1000.00271=3.10000000269=1278=1ed1152d-8c1a-4b29-acdd-bbd1a5c5f35f270=1000.00271=3.10000000269=1278=66526051-b5cb-442f-af90-c609be0a9796270=1000.00271=3.10000000269=1278=f68e4659-5785-4ee9-ac24-3186640a2752270=1000.00271=3.1000000010=203
20250411-01:59:59.043025000 : 8=FIXT.1.19=14235=334=2049=24ab46f784d1b20db435b852086e325052=20250411-01:59:59.04256=Coinbase45=12858=Tag appears more than once371=269372=W373=1310=050
20250411-01:59:59.088356000 : 8=FIXT.1.19=93935=W49=Coinbase56=24ab46f784d1b20db435b852086e325034=12950=TEST52=20250411-01:59:58.744329369=2262=1c4ca071-c1b7-4b32-a10d-aab5f132738083=1597581557893=N55=BTC-USD1682=full_trading268=10269=1278=38070d38-80a9-4898-8ef7-a0a9da5a4123270=1000.00271=3.10000000269=1278=e4d2d308-ed11-49db-850e-3cbd8258395d270=1000.00271=3.10000000269=1278=d6cfaadc-97ea-43c1-898d-40faea9c1477270=1000.00271=3.10000000269=1278=36876bea-9e3a-4018-b0ac-b75cb8c16953270=1000.00271=3.10000000269=1278=eb244bc5-49e8-4aa3-af8b-3d1a67c90a08270=1000.00271=3.10000000269=1278=3efba776-29ad-4aeb-82d8-0824f161471e270=1000.00271=3.10000000269=1278=de0ddebd-0ca8-4eca-9985-77c10c8629a9270=1000.00271=3.10000000269=1278=dde4408a-fb6b-441c-a7f3-7b8b23ffdb1f270=1000.00271=3.10000000269=1278=3ebd6434-070f-4b4d-8cf3-00368112466d270=1000.00271=3.10000000269=1278=7aa98e13-65f3-4058-9f91-c1f452d02710270=1000.00271=3.1000000010=071
20250411-01:59:59.088925000 : 8=FIXT.1.19=14235=334=2149=24ab46f784d1b20db435b852086e325052=20250411-01:59:59.08856=Coinbase45=12958=Tag appears more than once371=269372=W373=1310=062
20250411-01:59:59.089005000 : 8=FIXT.1.19=93935=W49=Coinbase56=24ab46f784d1b20db435b852086e325034=13050=TEST52=20250411-01:59:58.744581369=2262=1c4ca071-c1b7-4b32-a10d-aab5f132738083=1597581557893=N55=BTC-USD1682=full_trading268=10269=1278=e86a1fec-3610-460d-8d85-4e1e222ee159270=1000.00271=3.10000000269=1278=6dfac057-72b1-4f2c-b110-03766dea0d31270=1000.00271=3.10000000269=1278=bbb7d0ea-d251-4612-b53e-e528cc0a24ab270=1000.00271=3.10000000269=1278=0782ca37-48cf-4ff3-a74a-35674661586c270=1000.00271=3.10000000269=1278=aead437d-4b62-457f-ac83-62c7cc329fd1270=1000.00271=3.10000000269=1278=af5d47bc-a008-4567-b24f-b0298f250471270=1000.00271=3.10000000269=1278=4c260f58-c427-4a9a-969a-44024ae0c714270=1000.00271=3.10000000269=1278=8c7672e5-7ee8-4fbd-8fdf-7e74e9a77db7270=1000.00271=3.10000000269=1278=b53ec3cc-9abe-4570-b903-34d52148073e270=1000.00271=3.10000000269=1278=37ce984a-0387-4ac9-9094-b83f722036ba270=1000.00271=3.1000000010=120
20250411-01:59:59.089492000 : 8=FIXT.1.19=14235=334=2249=24ab46f784d1b20db435b852086e325052=20250411-01:59:59.08956=Coinbase45=13058=Tag appears more than once371=269372=W373=1310=056
20250411-01:59:59.089564000 : 8=FIXT.1.19=93935=W49=Coinbase56=24ab46f784d1b20db435b852086e325034=13150=TEST52=20250411-01:59:58.744829369=2262=1c4ca071-c1b7-4b32-a10d-aab5f132738083=1597581557893=N55=BTC-USD1682=full_trading268=10269=1278=0d383649-dc6c-4df2-b821-aa0018f132c7270=1000.00271=3.10000000269=1278=e39ae0ce-9e7f-4f0d-a765-5308d473bb61270=1000.00271=3.10000000269=1278=4882324e-3b5c-4b7a-b096-e8c6d9888671270=1000.00271=3.10000000269=1278=6e5c7dbd-a2cc-401f-a5b2-3902088f4ab2270=1000.00271=3.10000000269=1278=10ffac08-946a-4a30-b57a-0d78450345d9270=1000.00271=3.10000000269=1278=67784af5-72bf-4d16-a6b3-25336e2c1843270=1000.00271=3.10000000269=1278=4d8b3bbc-0dc2-4044-875c-c079ec538136270=1000.00271=3.10000000269=1278=dfba5f1e-21f5-48e3-adce-b8b6bfe71467270=1000.00271=3.10000000269=1278=e51b4e33-5eaa-46ef-936b-a74a890397e8270=1000.00271=3.10000000269=1278=8cf5dfa8-858b-48a3-9d94-78522c257473270=1000.00271=3.1000000010=172
20250411-01:59:59.090157000 : 8=FIXT.1.19=14235=334=2349=24ab46f784d1b20db435b852086e325052=20250411-01:59:59.08956=Coinbase45=13158=Tag appears more than once371=269372=W373=1310=058
20250411-01:59:59.090228000 : 8=FIXT.1.19=93935=W49=Coinbase56=24ab46f784d1b20db435b852086e325034=13250=TEST52=20250411-01:59:58.745080369=2262=1c4ca071-c1b7-4b32-a10d-aab5f132738083=1597581557893=N55=BTC-USD1682=full_trading268=10269=1278=a153b9d2-993d-4f03-a974-b8a081e128e8270=1000.00271=3.10000000269=1278=1eebe866-0f6e-4d4a-a28b-78f4e3368b0a270=1000.00271=3.10000000269=1278=300132d8-113f-4bf7-ba0c-4d93a272f55b270=1000.00271=3.10000000269=1278=757f3122-27d2-4f32-90b8-ead1eef9b936270=1000.00271=3.10000000269=1278=2b68b5de-4153-4cac-ace3-102e4fa788fd270=1000.00271=3.10000000269=1278=b01f252a-1657-4df0-a122-58a23109a7c2270=1000.00271=3.10000000269=1278=dbc57e4e-6abd-4d66-8d18-bd13caaa77b1270=1000.00271=3.10000000269=1278=948b05dc-a481-409f-b8ad-a502eb595906270=1000.00271=3.10000000269=1278=e00f9703-6e16-4237-a2c6-701829d11bf1270=1000.00271=3.10000000269=1278=fd52f47a-3f11-47bc-9952-9708617d0ecd270=1000.00271=3.1000000010=177
20250411-01:59:59.090761000 : 8=FIXT.1.19=14235=334=2449=24ab46f784d1b20db435b852086e325052=20250411-01:59:59.09056=Coinbase45=13258=Tag appears more than once371=269372=W373=1310=052
20250411-01:59:59.090830000 : 8=FIXT.1.19=93935=W49=Coinbase56=24ab46f784d1b20db435b852086e325034=13350=TEST52=20250411-01:59:58.745330369=2262=1c4ca071-c1b7-4b32-a10d-aab5f132738083=1597581557893=N55=BTC-USD1682=full_trading268=10269=1278=f7f75b14-27c3-469c-89fb-6a98b43c61bf270=1000.00271=3.10000000269=1278=25dbeb09-7901-4280-b0c3-720d7ed03d7d270=1000.00271=3.10000000269=1278=52164a1f-599f-4c43-a9ed-f93403506e67270=1000.00271=3.10000000269=1278=c71c35ea-f60f-4a41-b43a-4947bbcbafad270=1000.00271=3.10000000269=1278=2de342bc-a1be-46f3-9fc6-731297726934270=1000.00271=3.10000000269=1278=7ff4c5fc-bc9b-4845-940b-4837a672e13a270=1000.00271=3.10000000269=1278=2d270775-33eb-4328-8dad-7d206612f9f6270=1000.00271=3.10000000269=1278=c4754378-f787-4100-81af-564443a86a91270=1000.00271=3.10000000269=1278=59e16255-05eb-4fdc-8be1-3c4f83fc094e270=1000.00271=3.10000000269=1278=041b2f98-1185-49cb-964a-f0456b71e692270=1000.00271=3.1000000010=052
20250411-01:59:59.091368000 : 8=FIXT.1.19=14235=334=2549=24ab46f784d1b20db435b852086e325052=20250411-01:59:59.09156=Coinbase45=13358=Tag appears more than once371=269372=W373=1310=055
20250411-01:59:59.091438000 : 8=FIXT.1.19=93935=W49=Coinbase56=24ab46f784d1b20db435b852086e325034=13450=TEST52=20250411-01:59:58.745580369=2262=1c4ca071-c1b7-4b32-a10d-aab5f132738083=1597581557893=N55=BTC-USD1682=full_trading268=10269=1278=9a2f3529-481e-4e50-a123-7a2095fe6b2c270=1000.00271=3.10000000269=1278=9ed552a3-3295-4878-85dd-87b7b5590212270=1000.00271=3.10000000269=1278=54bec5c2-bafd-4d7d-851d-59e3553a053f270=1000.00271=3.10000000269=1278=543c1acf-52f2-442b-a893-f7aa9a5dfbd1270=1000.00271=3.10000000269=1278=fec999be-cbd0-42ef-b9c3-82ca92ef0b58270=1000.00271=3.10000000269=1278=24528176-3fc6-45b2-b2f3-9f784c01495a270=1000.00271=3.10000000269=1278=12081678-66a6-4435-a3d7-b65f959cf2ac270=1000.00271=3.10000000269=1278=e7fb6165-8f1a-4b5e-b095-e232b83ee951270=1000.00271=3.10000000269=1278=83ce6582-410a-40bf-9831-8f3d20e3a629270=1000.00271=3.10000000269=1278=bc3a930b-0567-46ba-86a4-712f76466b0b270=1000.00271=3.1000000010=232
20250411-01:59:59.092175000 : 8=FIXT.1.19=14235=334=2649=24ab46f784d1b20db435b852086e325052=20250411-01:59:59.09156=Coinbase45=13458=Tag appears more than once371=269372=W373=1310=057
20250411-01:59:59.092232000 : 8=FIXT.1.19=93935=W49=Coinbase56=24ab46f784d1b20db435b852086e325034=13550=TEST52=20250411-01:59:58.745829369=2262=1c4ca071-c1b7-4b32-a10d-aab5f132738083=1597581557893=N55=BTC-USD1682=full_trading268=10269=1278=15704973-f5ff-457d-ab31-8f99bb76bf7e270=1000.00271=3.10000000269=1278=7159045b-cbd5-458f-b91f-9fa5241b14b5270=1000.00271=3.10000000269=1278=9fa52a90-f03f-4940-b5ee-39ab937b86f1270=1000.00271=3.10000000269=1278=220f55cd-a279-4bf0-9c80-1dca086d85dc270=1000.00271=3.10000000269=1278=2b1eb468-6bcd-4117-a7c0-214d643ddad4270=1000.00271=3.10000000269=1278=cc23185d-e72e-42cb-8210-61bab29cd778270=1000.00271=3.10000000269=1278=69bb228b-973b-4176-8708-3231cc40102a270=1000.00271=3.10000000269=1278=2ec8035d-7962-4195-8388-c9fbad52ac8a270=1000.00271=3.10000000269=1278=7d39e416-0b7b-471f-a9ac-455ab1bce5a7270=1000.00271=3.10000000269=1278=7067378d-2a65-41f2-acb0-ef30ddbc3e5a270=1000.00271=3.1000000010=065
20250411-01:59:59.092649000 : 8=FIXT.1.19=14235=334=2749=24ab46f784d1b20db435b852086e325052=20250411-01:59:59.09256=Coinbase45=13558=Tag appears more than once371=269372=W373=1310=060
20250411-01:59:59.092715000 : 8=FIXT.1.19=93935=W49=Coinbase56=24ab46f784d1b20db435b852086e325034=13650=TEST52=20250411-01:59:58.746080369=2262=1c4ca071-c1b7-4b32-a10d-aab5f132738083=1597581557893=N55=BTC-USD1682=full_trading268=10269=1278=bf3fde78-6cff-4477-b381-4b5d2e68f36f270=1000.00271=3.10000000269=1278=93a2a8a3-61d4-410c-9446-8eabaafc5f29270=1000.00271=3.10000000269=1278=5afddb61-63ab-417b-a28a-41c4c03a6612270=1000.00271=3.10000000269=1278=a4280417-189c-4f76-9d2e-6ec652010bf5270=1000.00271=3.10000000269=1278=ddeb78a2-e110-4828-ba3d-c9b4837e7dd7270=1000.00271=3.10000000269=1278=fcec6c90-441a-4f4a-a94e-9003355657ef270=1000.00271=3.10000000269=1278=6db15389-dfb3-4156-8a4e-ce2ac80f2b15270=1000.00271=3.10000000269=1278=47dfefc3-6f05-4b57-8aec-2bf3e6c70c2d270=1000.00271=3.10000000269=1278=fb9fd019-4b4f-4880-82bb-3df6d1ef468a270=1000.00271=3.10000000269=1278=2cff9acd-42cb-43a5-8d50-51e676b7e763270=1000.00271=3.1000000010=150
20250411-01:59:59.093152000 : 8=FIXT.1.19=14235=334=2849=24ab46f784d1b20db435b852086e325052=20250411-01:59:59.09256=Coinbase45=13658=Tag appears more than once371=269372=W373=1310=062
20250411-01:59:59.093214000 : 8=FIXT.1.19=93935=W49=Coinbase56=24ab46f784d1b20db435b852086e325034=13750=TEST52=20250411-01:59:58.746330369=2262=1c4ca071-c1b7-4b32-a10d-aab5f132738083=1597581557893=N55=BTC-USD1682=full_trading268=10269=1278=6e6eeb59-4728-4811-9a44-c857df6aca42270=1000.00271=3.10000000269=1278=81798560-263f-4819-a528-5f3fbbc7b042270=1000.00271=3.10000000269=1278=81fbf9a8-82f4-4fe4-9fa5-3773b212ebf4270=1000.00271=3.10000000269=1278=5d3b9566-276d-47fe-a111-12c17f53f501270=1000.00271=3.10000000269=1278=8eb1b3b3-c813-48b1-b839-993672108d91270=1000.00271=3.10000000269=1278=4feb6e93-6149-481b-8d58-e1c8e6c5cda1270=1000.00271=3.10000000269=1278=f8611e72-4056-4b7c-9779-4d54cd151d44270=1000.00271=3.10000000269=1278=7a129f7c-d9ba-4ea3-a267-b7d82b2e07d9270=1000.00271=3.10000000269=1278=01f359f0-c38f-416b-af00-183907218793270=1000.00271=3.10000000269=1278=11741cec-9c08-4a20-99dc-6b9f63130b0e270=1000.00271=3.1000000010=086
20250411-01:59:59.093639000 : 8=FIXT.1.19=14235=334=2949=24ab46f784d1b20db435b852086e325052=20250411-01:59:59.09356=Coinbase45=13758=Tag appears more than once371=269372=W373=1310=065
20250411-01:59:59.093696000 : 8=FIXT.1.19=93935=W49=Coinbase56=24ab46f784d1b20db435b852086e325034=13850=TEST52=20250411-01:59:58.746580369=2262=1c4ca071-c1b7-4b32-a10d-aab5f132738083=1597581557893=N55=BTC-USD1682=full_trading268=10269=1278=08db2574-ad52-4520-ab5b-c3c7591eb781270=1000.00271=3.10000000269=1278=b06f2249-179c-4a15-8e98-7b76083b808b270=1000.00271=3.10000000269=1278=9e88fede-6d19-4c1f-863b-5a7d66781436270=1000.00271=3.10000000269=1278=75e1d8b4-7201-41fe-a687-7d93420af323270=1000.00271=3.10000000269=1278=d00aa7dd-ce7f-4f8b-9a2e-880c1ea30845270=1000.00271=3.10000000269=1278=584a483f-23bf-4d8b-809f-69cf3c110f60270=1000.00271=3.10000000269=1278=dc98524e-27e2-4863-99e4-7a0097a6ee90270=1000.00271=3.10000000269=1278=82a11ac9-4f46-44b7-a0bc-a5a4cfe686e0270=1000.00271=3.10000000269=1278=f946bb05-900c-41fc-9908-41489e97ff20270=1000.00271=3.10000000269=1278=1f9186d6-0312-4677-ba96-fdb014cdff2c270=1000.00271=3.1000000010=177
20250411-01:59:59.094221000 : 8=FIXT.1.19=14235=334=3049=24ab46f784d1b20db435b852086e325052=20250411-01:59:59.09456=Coinbase45=13858=Tag appears more than once371=269372=W373=1310=059
20250411-01:59:59.094285000 : 8=FIXT.1.19=93935=W49=Coinbase56=24ab46f784d1b20db435b852086e325034=13950=TEST52=20250411-01:59:58.746830369=2262=1c4ca071-c1b7-4b32-a10d-aab5f132738083=1597581557893=N55=BTC-USD1682=full_trading268=10269=1278=c3b67be7-2b63-4884-b311-80f28496c2c4270=1000.00271=3.10000000269=1278=6576c7f8-a4e2-4417-b854-5fef0e705fbe270=1000.00271=3.10000000269=1278=c2102c71-62f0-4eee-ae60-0777ed26a8e6270=1000.00271=3.10000000269=1278=c823a2b6-849e-4839-a2fd-cd9f459cae6c270=1000.00271=3.10000000269=1278=a051e195-4472-4a8a-8591-08a2c04a33c4270=1000.00271=3.10000000269=1278=ec81b8c4-b703-4afd-a701-ce34011f60f6270=1000.00271=3.10000000269=1278=b1172677-f493-4f32-a200-0710cf8c397f270=1000.00271=3.10000000269=1278=b1a58a75-5fca-43db-b9c6-a26920e8f66e270=1000.00271=3.10000000269=1278=038bea41-b91d-4884-b992-3e5431ef9857270=1000.00271=3.10000000269=1278=55063782-f2ea-4c84-9491-8e8e89d1dfd1270=1000.00271=3.1000000010=148
20250411-01:59:59.094737000 : 8=FIXT.1.19=14235=334=3149=24ab46f784d1b20db435b852086e325052=20250411-01:59:59.09456=Coinbase45=13958=Tag appears more than once371=269372=W373=1310=061
20250411-01:59:59.094818000 : 8=FIXT.1.19=93935=W49=Coinbase56=24ab46f784d1b20db435b852086e325034=14050=TEST52=20250411-01:59:58.747080369=2262=1c4ca071-c1b7-4b32-a10d-aab5f132738083=1597581557893=N55=BTC-USD1682=full_trading268=10269=1278=bb2011e8-d05d-40ac-9e9c-3b720422e38d270=1000.00271=3.10000000269=1278=64dd3b4a-ce8a-4b63-9937-266e832c0f21270=1000.00271=3.10000000269=1278=d64f7d2a-aa83-486c-92a8-3314c4eddd58270=1000.00271=3.10000000269=1278=0df9641b-d89d-4222-a8ea-bcddf0d555f5270=1000.00271=3.10000000269=1278=7a315b16-a05f-408d-b8c1-2704af9bf767270=1000.00271=3.10000000269=1278=0e9712a8-d00f-4864-a478-f7f591718f91270=1000.00271=3.10000000269=1278=94db025d-eada-49e3-b13c-b667ca07f829270=1000.00271=3.10000000269=1278=a88ccd1f-8f8d-46af-8fb6-20adba35f7d1270=1000.00271=3.10000000269=1278=99d4e235-c8ec-4efc-938c-9a1923eafc96270=1000.00271=3.10000000269=1278=a4fc7173-7583-4f8b-b256-2921bef83c84270=1000.00271=3.1000000010=148
20250411-01:59:59.095232000 : 8=FIXT.1.19=14235=334=3249=24ab46f784d1b20db435b852086e325052=20250411-01:59:59.09456=Coinbase45=14058=Tag appears more than once371=269372=W373=1310=054
20250411-01:59:59.095298000 : 8=FIXT.1.19=93935=W49=Coinbase56=24ab46f784d1b20db435b852086e325034=14150=TEST52=20250411-01:59:58.747333369=2262=1c4ca071-c1b7-4b32-a10d-aab5f132738083=1597581557893=N55=BTC-USD1682=full_trading268=10269=1278=18f8afd4-8bbc-4ffa-8e8f-0c1834d74472270=1000.00271=3.10000000269=1278=21fc8cb6-f894-4d09-884e-810b8ebf2ef3270=1000.00271=3.10000000269=1278=0c13b9e6-6797-4b3e-90ce-a1885b26ba53270=1000.00271=3.10000000269=1278=6d8da581-3998-4fc0-99b6-3c5edbd514cb270=1000.00271=3.10000000269=1278=67a70307-be50-4065-872b-47e0de473bc4270=1000.00271=3.10000000269=1278=8ce7be0b-98de-46d0-b1b6-307a4bec36e2270=1000.00271=3.10000000269=1278=856b22f8-5884-4739-adc0-bdd851c5c07d270=1000.00271=3.10000000269=1278=c00ae651-a76b-4bfd-be16-3672b345fe29270=1000.00271=3.10000000269=1278=cae248f9-16fc-44ea-9b79-1dacfc285db6270=1000.00271=3.10000000269=1278=42bb223c-88c6-4a18-8ff3-4fd8d9efda8d270=1000.00271=3.1000000010=154
20250411-01:59:59.095941000 : 8=FIXT.1.19=14235=334=3349=24ab46f784d1b20db435b852086e325052=20250411-01:59:59.09556=Coinbase45=14158=Tag appears more than once371=269372=W373=1310=057
20250411-01:59:59.096023000 : 8=FIXT.1.19=93935=W49=Coinbase56=24ab46f784d1b20db435b852086e325034=14250=TEST52=20250411-01:59:58.747580369=2262=1c4ca071-c1b7-4b32-a10d-aab5f132738083=1597581557893=N55=BTC-USD1682=full_trading268=10269=1278=d7188b01-22b6-4837-a720-077601f7f483270=1000.00271=3.10000000269=1278=5d85a0a6-ddd9-4e0e-9a1a-7f418ef588e5270=1000.00271=3.10000000269=1278=bff4c39f-7a80-42ce-a178-b1221792e445270=1000.00271=3.10000000269=1278=9ea3d263-b5ab-46c5-bf27-8c0e3e0e5e9e270=1000.00271=3.10000000269=1278=b93347df-d2ab-48ec-b326-4454e64f1d4e270=1000.00271=3.10000000269=1278=57acc40d-8478-444a-990f-067a8e8e846e270=1000.00271=3.10000000269=1278=34419ae2-2c16-427b-a290-845419760fd5270=1000.00271=3.10000000269=1278=ab41de2d-5def-4986-b56e-243d2f99a57c270=1000.00271=3.10000000269=1278=9025524c-03a9-407a-a58a-5258c4ea0a0b270=1000.00271=3.10000000269=1278=60766318-112b-4d83-a384-55693de75519270=1000.00271=3.1000000010=212
20250411-01:59:59.096536000 : 8=FIXT.1.19=14235=334=3449=24ab46f784d1b20db435b852086e325052=20250411-01:59:59.09656=Coinbase45=14258=Tag appears more than once371=269372=W373=1310=060
20250411-01:59:59.096608000 : 8=FIXT.1.19=93935=W49=Coinbase56=24ab46f784d1b20db435b852086e325034=14350=TEST52=20250411-01:59:58.747830369=2262=1c4ca071-c1b7-4b32-a10d-aab5f132738083=1597581557893=N55=BTC-USD1682=full_trading268=10269=1278=c19b6a2c-086b-4fc1-8dfe-51cb2dc12c1d270=1000.00271=3.10000000269=1278=11126433-0f9c-4450-a35a-39b878e85e68270=1000.00271=3.10000000269=1278=e2e620ee-44fb-4630-a890-d331ba5b2fae270=1000.00271=3.10000000269=1278=9ccf6d4b-a6ca-4a1f-a7bb-77f400ace0c8270=1000.00271=3.10000000269=1278=0e8d6c10-8421-4f19-97dc-d70e715d9033270=1000.00271=3.10000000269=1278=f31ecd5d-8231-44ea-a5c2-0fcc5a699401270=1000.00271=3.10000000269=1278=37fbb559-dc52-48fe-ab65-24910edc338a270=1000.00271=3.10000000269=1278=bc1435c5-c59c-4017-9e59-f1073f04c7e2270=1000.00271=3.10000000269=1278=9c8e1397-0cee-4b05-a66f-5594040791c4270=1000.00271=3.10000000269=1278=248b6703-f829-42bb-a551-4be3075c381e270=1000.00271=3.1000000010=235
20250411-01:59:59.097046000 : 8=FIXT.1.19=14235=334=3549=24ab46f784d1b20db435b852086e325052=20250411-01:59:59.09656=Coinbase45=14358=Tag appears more than once371=269372=W373=1310=062
20250411-01:59:59.097117000 : 8=FIXT.1.19=93935=W49=Coinbase56=24ab46f784d1b20db435b852086e325034=14450=TEST52=20250411-01:59:58.748080369=2262=1c4ca071-c1b7-4b32-a10d-aab5f132738083=1597581557893=N55=BTC-USD1682=full_trading268=10269=1278=16d257b0-bc92-44f0-822d-3eba61af4bda270=1000.00271=3.10000000269=1278=06257aa1-4043-4cdb-9286-4342b8e59108270=1000.00271=3.10000000269=1278=210ec210-1443-47dc-9e43-9c9ea720a6c3270=1000.00271=3.10000000269=1278=8b79da5d-b78c-4011-b55f-b35c16dc3724270=1000.00271=3.10000000269=1278=076c3703-1104-4e15-a38a-d95bf133f0c5270=1000.00271=3.10000000269=1278=f5a3155c-e449-4102-870d-ab8c8dd24c3d270=1000.00271=3.10000000269=1278=1af2681f-2dec-4d25-aaeb-89b8867b4a3c270=1000.00271=3.10000000269=1278=65c3088d-192a-4213-85a3-7257aa8b20a3270=1000.00271=3.10000000269=1278=2aa7989b-5601-4899-8143-01dda3255e4f270=1000.00271=3.10000000269=1278=099b432c-fa2e-4fd7-952e-22f6debf6877270=1000.00271=3.1000000010=252
20250411-01:59:59.097609000 : 8=FIXT.1.19=14235=334=3649=24ab46f784d1b20db435b852086e325052=20250411-01:59:59.09756=Coinbase45=14458=Tag appears more than once371=269372=W373=1310=065
20250411-01:59:59.097689000 : 8=FIXT.1.19=93935=W49=Coinbase56=24ab46f784d1b20db435b852086e325034=14550=TEST52=20250411-01:59:58.748330369=2262=1c4ca071-c1b7-4b32-a10d-aab5f132738083=1597581557893=N55=BTC-USD1682=full_trading268=10269=1278=2e71cc31-1235-4b7b-a728-e3335631fe5a270=1000.00271=3.10000000269=1278=ce471ffc-1e26-4afe-afab-27ee5ac8debe270=1000.00271=3.10000000269=1278=113b7fc6-8574-40eb-8682-d077245b84f2270=1000.00271=3.10000000269=1278=bcebce2c-eda8-4b85-841d-27ede39fc5a1270=1000.00271=3.10000000269=1278=0aedaae5-6cc6-4a34-8e48-5e67a5ccc148270=1000.00271=3.10000000269=1278=206e10a5-1173-4860-87b5-7c88afe061f6270=1000.00271=3.10000000269=1278=5c32d94b-696a-4d9b-afa0-665970356008270=1000.00271=3.10000000269=1278=0b7da819-cc1e-4525-a382-ce5b90dc485c270=1000.00271=3.10000000269=1278=2241b3bf-cbbe-44f2-ac75-8032f6283aa8270=1000.00271=3.10000000269=1278=88cada69-adb1-466a-afcd-66e063ad27c0270=1000.00271=3.1000000010=102
20250411-01:59:59.098485000 : 8=FIXT.1.19=14235=334=3749=24ab46f784d1b20db435b852086e325052=20250411-01:59:59.09856=Coinbase45=14558=Tag appears more than once371=269372=W373=1310=068
20250411-01:59:59.098581000 : 8=FIXT.1.19=93935=W49=Coinbase56=24ab46f784d1b20db435b852086e325034=14650=TEST52=20250411-01:59:58.748580369=2262=1c4ca071-c1b7-4b32-a10d-aab5f132738083=1597581557893=N55=BTC-USD1682=full_trading268=10269=1278=34a52ef5-31c1-4c63-9230-21c85a9a6ba3270=1000.00271=3.10000000269=1278=e109c2c8-fb1d-4ef9-a640-368381323507270=1000.00271=3.10000000269=1278=38fd36c4-4c62-4b4c-8f24-1fe39be94fa1270=1000.00271=3.10000000269=1278=f83f64c8-7d33-472d-a516-9b664ff9c966270=1000.00271=3.10000000269=1278=3411c368-380b-42e6-b656-8552d92904d5270=1000.00271=3.10000000269=1278=4803796e-79f3-4aa4-a8cb-37f13899bf01270=1000.00271=3.10000000269=1278=823f8fbf-7e6d-4ae3-adb9-3a822ff6d09a270=1000.00271=3.10000000269=1278=135624df-a204-490f-a68b-63d74ee09908270=1000.00271=3.10000000269=1278=47cfdedf-22b9-402c-93bd-f311103fd3e0270=1000.00271=3.10000000269=1278=f9173d5e-d872-4661-93f6-28f527e931f7270=1000.00271=3.1000000010=248
20250411-01:59:59.099196000 : 8=FIXT.1.19=14235=334=3849=24ab46f784d1b20db435b852086e325052=20250411-01:59:59.09856=Coinbase45=14658=Tag appears more than once371=269372=W373=1310=070
20250411-01:59:59.099290000 : 8=FIXT.1.19=93935=W49=Coinbase56=24ab46f784d1b20db435b852086e325034=14750=TEST52=20250411-01:59:58.748830369=2262=1c4ca071-c1b7-4b32-a10d-aab5f132738083=1597581557893=N55=BTC-USD1682=full_trading268=10269=1278=06ab1365-fd39-4701-bd7f-1915ad3c7602270=1000.00271=3.10000000269=1278=012a7c59-5ae4-4da5-97ba-2e3254c889fb270=1000.00271=3.10000000269=1278=a9a0d42f-ad9e-4ea9-8bf0-d5a441fded40270=1000.00271=3.10000000269=1278=f3f3930e-be0e-40b4-a97d-d19501a54885270=1000.00271=3.10000000269=1278=261922d0-5c81-4ab6-832f-4eff45f64890270=1000.00271=3.10000000269=1278=3af4e45f-56f6-4c69-894d-d56a14894a98270=1000.00271=3.10000000269=1278=1c1dd248-49e4-44aa-9e69-323b0f41fa0e270=1000.00271=3.10000000269=1278=b16b002d-1cd6-4869-9c1b-f15c758611bf270=1000.00271=3.10000000269=1278=a0520e61-28ad-448d-87c1-49f0c7358628270=1000.00271=3.10000000269=1278=152d0b57-086f-48cc-80b3-ff14ee9375ed270=1000.00271=3.1000000010=023
20250411-01:59:59.099876000 : 8=FIXT.1.19=14235=334=3949=24ab46f784d1b20db435b852086e325052=20250411-01:59:59.09956=Coinbase45=14758=Tag appears more than once371=269372=W373=1310=073
20250411-01:59:59.099963000 : 8=FIXT.1.19=93935=W49=Coinbase56=24ab46f784d1b20db435b852086e325034=14850=TEST52=20250411-01:59:58.749080369=2262=1c4ca071-c1b7-4b32-a10d-aab5f132738083=1597581557893=N55=BTC-USD1682=full_trading268=10269=1278=c55fc264-67d2-4e9c-8cce-6c834feff648270=1000.00271=3.10000000269=1278=27361968-189a-4fa6-a3a2-eead03c640d6270=1000.00271=3.10000000269=1278=f5b01c67-f98f-44b9-a511-7f07f8883d9e270=1000.00271=3.10000000269=1278=75a5c14f-8434-4533-a10e-0bf6e92e1000270=1000.00271=3.10000000269=1278=a9b0a826-3659-4105-9ecc-21bcd27b736f270=1000.00271=3.10000000269=1278=1b1bab77-5c52-459b-98e3-e27ff6f8cd04270=1000.00271=3.10000000269=1278=346695f1-fe03-4364-8fc5-006796c8f82f270=1000.00271=3.10000000269=1278=cbbaa36d-2a03-45a2-a230-bd5845d832cd270=1000.00271=3.10000000269=1278=745d4fc0-6710-4c5c-97c3-7b29c4e06839270=1000.00271=3.10000000269=1278=e95fdfba-5db2-4461-8e9c-7bfdf8a9238c270=1000.00271=3.1000000010=252
20250411-01:59:59.100679000 : 8=FIXT.1.19=14235=334=4049=24ab46f784d1b20db435b852086e325052=20250411-01:59:59.10056=Coinbase45=14858=Tag appears more than once371=269372=W373=1310=049
20250411-01:59:59.100773000 : 8=FIXT.1.19=93935=W49=Coinbase56=24ab46f784d1b20db435b852086e325034=14950=TEST52=20250411-01:59:58.749330369=2262=1c4ca071-c1b7-4b32-a10d-aab5f132738083=1597581557893=N55=BTC-USD1682=full_trading268=10269=1278=33611b39-1fbf-45cc-bf5e-a02bc1f84736270=1000.00271=3.10000000269=1278=51f77b2d-1a69-432d-934b-234eb9e1dfac270=1000.00271=3.10000000269=1278=ab09fdc3-8d50-432f-ab0f-97e8627eac24270=1000.00271=3.10000000269=1278=dde04213-6104-44c5-a811-15834c27b515270=1000.00271=3.10000000269=1278=9af2b85c-4997-4e1b-9147-7d400f059b01270=1000.00271=3.10000000269=1278=40870860-7a8a-4419-a117-e511f779abfa270=1000.00271=3.10000000269=1278=3e8fa7bd-dde0-4fe4-bb2e-e6279841b019270=1000.00271=3.10000000269=1278=4dde1422-98d8-405b-88df-bf245291ad7a270=1000.00271=3.10000000269=1278=6ee8b5a8-bc2f-4a0a-9ae4-7ff1b5dae941270=1000.00271=3.10000000269=1278=3ebc1f7a-2bb5-4ef0-a82f-844b9540f6e8270=1000.00271=3.1000000010=246
20250411-01:59:59.101333000 : 8=FIXT.1.19=14235=334=4149=24ab46f784d1b20db435b852086e325052=20250411-01:59:59.10156=Coinbase45=14958=Tag appears more than once371=269372=W373=1310=052
20250411-01:59:59.101414000 : 8=FIXT.1.19=93935=W49=Coinbase56=24ab46f784d1b20db435b852086e325034=15050=TEST52=20250411-01:59:58.749580369=2262=1c4ca071-c1b7-4b32-a10d-aab5f132738083=1597581557893=N55=BTC-USD1682=full_trading268=10269=1278=a82d5bb9-1f1a-4575-b580-8d9b60863b10270=1000.00271=3.10000000269=1278=14f89bd5-0233-435c-b608-2e19131b8f6c270=1000.00271=3.10000000269=1278=a2e319e5-aab7-41d4-9d19-98d771a3f1d3270=1000.00271=3.10000000269=1278=dc965e0b-075a-4ba4-a498-02c96d1664ba270=1000.00271=3.10000000269=1278=67b6e68f-ac11-4c05-a54a-2adb555b0123270=1000.00271=3.10000000269=1278=866f52a1-dad9-49d7-ac4a-9da3075407a3270=1000.00271=3.10000000269=1278=0e38234d-a010-40f6-9c6f-a0d574e773cf270=1000.00271=3.10000000269=1278=d6af6749-e3c8-4938-8741-1d5f177cf8e1270=1000.00271=3.10000000269=1278=45ff5e59-2c4d-45ac-9fde-403662dfd1ca270=1000.00271=3.10000000269=1278=dcac314e-c54f-44e3-b96d-ef71539766ed270=1000.00271=3.1000000010=243
20250411-01:59:59.101945000 : 8=FIXT.1.19=14235=334=4249=24ab46f784d1b20db435b852086e325052=20250411-01:59:59.10156=Coinbase45=15058=Tag appears more than once371=269372=W373=1310=045
20250411-01:59:59.102025000 : 8=FIXT.1.19=94735=W49=Coinbase56=24ab46f784d1b20db435b852086e325034=15150=TEST52=20250411-01:59:58.749830369=2262=1c4ca071-c1b7-4b32-a10d-aab5f132738083=1597581557893=N55=BTC-USD1682=full_trading268=10269=1278=dd6d14ea-760f-4884-a546-1d3c40ebdd7c270=1000.00271=3.10000000269=1278=4f3da0c6-46eb-4b64-b973-cc43e24abccb270=1000.00271=3.10000000269=1278=aa40cda8-4abd-4f52-999a-1a90ed5bf41a270=1000.00271=3.10000000269=1278=687ee4fc-f626-4e4f-abee-1f0ee5af3f72270=1000.00271=3.10000000269=1278=b1ad1135-67ec-4c96-99cb-a626137f3f16270=10000.00271=1.00000000269=1278=e9320f5f-80ae-41ab-af7a-86518d456fb0270=10000.00271=1.00000000269=1278=cd95aff0-36fa-4804-887f-2c3fce3cdc86270=10000.00271=1.00000000269=1278=fbdbcee1-8c29-4478-97df-358d209d8808270=10000.00271=1.00000000269=1278=140f39da-834b-4e42-8e15-6e25287df1f0270=900000.00271=0.00011111269=1278=49f064c5-76fe-4b38-bede-48b60a0a5aec270=900000.00271=0.0001111110=172
20250411-01:59:59.102653000 : 8=FIXT.1.19=14235=334=4349=24ab46f784d1b20db435b852086e325052=20250411-01:59:59.10256=Coinbase45=15158=Tag appears more than once371=269372=W373=1310=048
20250411-01:59:59.102820000 : 8=FIXT.1.19=95935=W49=Coinbase56=24ab46f784d1b20db435b852086e325034=15250=TEST52=20250411-01:59:58.750080369=2262=1c4ca071-c1b7-4b32-a10d-aab5f132738083=1597581557893=N55=BTC-USD1682=full_trading268=10269=1278=681cf73b-9d37-4101-b940-9da9b1ff61ed270=900000.00271=0.00011111269=1278=3dea1587-e474-4258-b6e8-485c21b56670270=900000.00271=0.00011111269=1278=afd96a7b-3d48-459e-b810-e4ee88353a31270=900000.00271=0.00011111269=1278=a68ae029-b920-4ae7-a775-ccdb800fc252270=900000.00271=0.00001111269=1278=d44508b7-1c9f-4b4f-acb8-99c93d2b99e8270=900000.00271=0.00001111269=1278=304ff106-de40-4381-89c5-c93f7f3e32ae270=900000.00271=0.00001111269=1278=08a0fef8-fcbb-4857-8463-2599cf331386270=900000.00271=0.00011111269=1278=07b2856d-f899-417c-82d5-886f0d85125e270=900000.00271=0.00011111269=1278=12ecb45e-6af8-4804-a942-5c997b9d1502270=900000.00271=0.00011111269=1278=98676c5f-b851-473c-817a-b29243092a25270=900000.00271=0.0000111110=248
20250411-01:59:59.103423000 : 8=FIXT.1.19=14235=334=4449=24ab46f784d1b20db435b852086e325052=20250411-01:59:59.10356=Coinbase45=15258=Tag appears more than once371=269372=W373=1310=051
20250411-01:59:59.103502000 : 8=FIXT.1.19=73435=W49=Coinbase56=24ab46f784d1b20db435b852086e325034=15350=TEST52=20250411-01:59:58.750331369=2262=1c4ca071-c1b7-4b32-a10d-aab5f132738083=1597581557893=Y55=BTC-USD1682=full_trading268=7269=1278=09afe685-e71f-4ea0-b164-c27737db126d270=900000.00271=0.00001111269=1278=e71ee98f-c329-428d-9893-629b53015ff6270=900000.00271=0.00001111269=1278=124e6fc1-6dde-452b-be03-c00113c8ebdb270=900000.00271=0.00011111269=1278=b71cc7f5-d7c6-4fc0-a0de-59b0eb7fd063270=1000000.00271=1.00000000269=1278=afec127b-a98c-49cb-893f-e385a7e35d32270=1000000.00271=1.00000000269=1278=06df7c57-366d-4d2c-acc2-e6c26d60e9c3270=1000000.00271=1.00000000269=1278=b1c4eb2b-90df-44e0-ae4f-515df4086a9d270=9999999.00271=0.0000100010=061
20250411-01:59:59.104047000 : 8=FIXT.1.19=14235=334=4549=24ab46f784d1b20db435b852086e325052=20250411-01:59:59.10356=Coinbase45=15358=Tag appears more than once371=269372=W373=1310=053
20250411-01:59:59.104124000 : 8=FIXT.1.19=30935=X49=Coinbase56=24ab46f784d1b20db435b852086e325034=15450=TEST52=20250411-01:59:58.770819369=2262=1c4ca071-c1b7-4b32-a10d-aab5f1327380268=1279=1269=0278=1427699a-fe0c-4a1f-8735-bd2913dcabdc83=159758156155=BTC-USD270=3.41271=0.5634108860=20250411-01:59:58.76922958=CHANGE_REASON_MODIFY_ORDER10=153
20250411-01:59:59.104348000 : 8=FIXT.1.19=28335=X49=Coinbase56=24ab46f784d1b20db435b852086e325034=15550=TEST52=20250411-01:59:58.868278369=2262=1c4ca071-c1b7-4b32-a10d-aab5f1327380268=1279=0269=083=159758156255=BTC-USD270=3.86271=0.6197183160=20250411-01:59:58.86661040=237=12bf97ea-bba5-45fd-a39e-ff49c0052cb410=037
20250411-01:59:59.104598000 : 8=FIXT.1.19=32635=X49=Coinbase56=24ab46f784d1b20db435b852086e325034=15650=TEST52=20250411-01:59:58.868287369=2262=1c4ca071-c1b7-4b32-a10d-aab5f1327380268=1279=0269=2278=c5b88ea9-605d-4595-ac52-f7c3f08523ba83=159758156355=BTC-USD270=3.55271=0.6197183160=20250411-01:59:58.86661037=12bf97ea-bba5-45fd-a39e-ff49c0052cb45797=110=245
20250411-01:59:59.106761000 : 8=FIXT.1.19=28935=X49=Coinbase56=24ab46f784d1b20db435b852086e325034=15750=TEST52=20250411-01:59:58.868290369=2262=1c4ca071-c1b7-4b32-a10d-aab5f1327380268=1279=2269=0278=12bf97ea-bba5-45fd-a39e-ff49c0052cb483=159758156455=BTC-USD270=3.86271=0.0000000060=20250411-01:59:58.86661058=FILLED10=197
20250411-01:59:59.106974000 : 8=FIXT.1.19=28335=X49=Coinbase56=24ab46f784d1b20db435b852086e325034=15850=TEST52=20250411-01:59:58.922296369=2262=1c4ca071-c1b7-4b32-a10d-aab5f1327380268=1279=0269=183=159758156555=BTC-USD270=3.24271=0.6197183160=20250411-01:59:58.92149240=237=1b4cd0cb-4d11-469f-93a5-fe3b2471338d10=087
20250411-01:59:59.107203000 : 8=FIXT.1.19=32635=X49=Coinbase56=24ab46f784d1b20db435b852086e325034=15950=TEST52=20250411-01:59:58.922300369=2262=1c4ca071-c1b7-4b32-a10d-aab5f1327380268=1279=0269=2278=4d60a78e-b39b-420e-b830-bc0f3f4fdde283=159758156655=BTC-USD270=3.53271=0.6197183160=20250411-01:59:58.92149237=1b4cd0cb-4d11-469f-93a5-fe3b2471338d5797=210=159
20250411-01:59:59.107585000 : 8=FIXT.1.19=28935=X49=Coinbase56=24ab46f784d1b20db435b852086e325034=16050=TEST52=20250411-01:59:58.922356369=2262=1c4ca071-c1b7-4b32-a10d-aab5f1327380268=1279=2269=1278=1b4cd0cb-4d11-469f-93a5-fe3b2471338d83=159758156755=BTC-USD270=3.24271=0.0000000060=20250411-01:59:58.92149258=FILLED10=241
20250411-01:59:59.156435000 : 8=FIXT.1.19=27935=X49=Coinbase56=24ab46f784d1b20db435b852086e325034=16150=TEST52=20250411-01:59:59.035623369=15262=1c4ca071-c1b7-4b32-a10d-aab5f1327380268=1279=0269=083=159758156855=BTC-USD29004=2.208895519560=20250411-01:59:59.03436640=137=31339245-d114-40e1-b27a-62481fd91cd410=240
20250411-01:59:59.156681000 : 8=FIXT.1.19=32735=X49=Coinbase56=24ab46f784d1b20db435b852086e325034=16250=TEST52=20250411-01:59:59.035688369=15262=1c4ca071-c1b7-4b32-a10d-aab5f1327380268=1279=0269=2278=c5b88ea9-605d-4595-ac52-f7c3f08523ba83=159758156955=BTC-USD270=3.55271=0.6222240960=20250411-01:59:59.03436637=31339245-d114-40e1-b27a-62481fd91cd45797=110=142
20250411-01:59:59.156814000 : 8=FIXT.1.19=26635=X49=Coinbase56=24ab46f784d1b20db435b852086e325034=16350=TEST52=20250411-01:59:59.035695369=15262=1c4ca071-c1b7-4b32-a10d-aab5f1327380268=1279=2269=0278=31339245-d114-40e1-b27a-62481fd91cd483=159758157055=BTC-USD60=20250411-01:59:59.03436658=FILLED10=000
20250411-01:59:59.175864000 : 8=FIXT.1.19=30935=X49=Coinbase56=24ab46f784d1b20db435b852086e325034=16450=TEST52=20250411-01:59:59.056518369=15262=1c4ca071-c1b7-4b32-a10d-aab5f1327380268=1279=1269=1278=d68d2389-fda4-456e-a285-3787e94c7c8883=159758157155=BTC-USD270=3.59271=0.572992160=20250411-01:59:59.05461558=CHANGE_REASON_MODIFY_ORDER10=255
20250411-01:59:59.182730000 : 8=FIXT.1.19=27535=X49=Coinbase56=24ab46f784d1b20db435b852086e325034=16550=TEST52=20250411-01:59:59.063728369=15262=1c4ca071-c1b7-4b32-a10d-aab5f1327380268=1279=0269=183=159758157255=BTC-USD271=0.6232294660=20250411-01:59:59.06257840=137=fed8b559-0afc-4c1a-b562-cdb840346c3910=077
20250411-01:59:59.182973000 : 8=FIXT.1.19=32735=X49=Coinbase56=24ab46f784d1b20db435b852086e325034=16650=TEST52=20250411-01:59:59.063812369=15262=1c4ca071-c1b7-4b32-a10d-aab5f1327380268=1279=0269=2278=4d60a78e-b39b-420e-b830-bc0f3f4fdde283=159758157355=BTC-USD270=3.53271=0.6232294660=20250411-01:59:59.06257837=fed8b559-0afc-4c1a-b562-cdb840346c395797=210=060
20250411-01:59:59.183133000 : 8=FIXT.1.19=28135=X49=Coinbase56=24ab46f784d1b20db435b852086e325034=16750=TEST52=20250411-01:59:59.063815369=15262=1c4ca071-c1b7-4b32-a10d-aab5f1327380268=1279=2269=1278=fed8b559-0afc-4c1a-b562-cdb840346c3983=159758157455=BTC-USD271=0.0000000060=20250411-01:59:59.06257858=FILLED10=234
20250411-01:59:59.214989000 : 8=FIXT.1.19=28435=X49=Coinbase56=24ab46f784d1b20db435b852086e325034=16850=TEST52=20250411-01:59:59.095912369=15262=1c4ca071-c1b7-4b32-a10d-aab5f1327380268=1279=0269=183=159758157555=BTC-USD270=3.26271=0.6232294660=20250411-01:59:59.09423640=237=ecfc99ef-e9ae-4a94-b1f4-f73bea74100610=092
20250411-01:59:59.216551000 : 8=FIXT.1.19=32735=X49=Coinbase56=24ab46f784d1b20db435b852086e325034=16950=TEST52=20250411-01:59:59.095919369=15262=1c4ca071-c1b7-4b32-a10d-aab5f1327380268=1279=0269=2278=4d60a78e-b39b-420e-b830-bc0f3f4fdde283=159758157655=BTC-USD270=3.53271=0.6232294660=20250411-01:59:59.09423637=ecfc99ef-e9ae-4a94-b1f4-f73bea7410065797=210=183
20250411-01:59:59.216728000 : 8=FIXT.1.19=29035=X49=Coinbase56=24ab46f784d1b20db435b852086e325034=17050=TEST52=20250411-01:59:59.095921369=15262=1c4ca071-c1b7-4b32-a10d-aab5f1327380268=1279=2269=1278=ecfc99ef-e9ae-4a94-b1f4-f73bea74100683=159758157755=BTC-USD270=3.26271=0.0000000060=20250411-01:59:59.09423658=FILLED10=242
20250411-01:59:59.270599000 : 8=FIXT.1.19=28435=X49=Coinbase56=24ab46f784d1b20db435b852086e325034=17150=TEST52=20250411-01:59:59.151143369=17262=1c4ca071-c1b7-4b32-a10d-aab5f1327380268=1279=0269=083=159758157855=BTC-USD270=3.88271=0.6232294660=20250411-01:59:59.15010540=237=0f1993cb-a573-4e19-a9c7-3dae411dc3e810=178
20250411-01:59:59.271150000 : 8=FIXT.1.19=32735=X49=Coinbase56=24ab46f784d1b20db435b852086e325034=17250=TEST52=20250411-01:59:59.151153369=17262=1c4ca071-c1b7-4b32-a10d-aab5f1327380268=1279=0269=2278=c5b88ea9-605d-4595-ac52-f7c3f08523ba83=159758157955=BTC-USD270=3.55271=0.6232294660=20250411-01:59:59.15010537=0f1993cb-a573-4e19-a9c7-3dae411dc3e85797=110=129
20250411-01:59:59.273198000 : 8=FIXT.1.19=29035=X49=Coinbase56=24ab46f784d1b20db435b852086e325034=17350=TEST52=20250411-01:59:59.151156369=17262=1c4ca071-c1b7-4b32-a10d-aab5f1327380268=1279=2269=0278=0f1993cb-a573-4e19-a9c7-3dae411dc3e883=159758158055=BTC-USD270=3.88271=0.0000000060=20250411-01:59:59.15010558=FILLED10=076
20250411-01:59:59.459936000 : 8=FIXT.1.19=30835=X49=Coinbase56=24ab46f784d1b20db435b852086e325034=17450=TEST52=20250411-01:59:59.341015369=45262=1c4ca071-c1b7-4b32-a10d-aab5f1327380268=1279=1269=1278=b175a3bc-9391-4e0a-b8f2-4c919d3a4f1883=159758158155=BTC-USD270=3.6271=0.568309360=20250411-01:59:59.33997358=CHANGE_REASON_MODIFY_ORDER10=004
20250411-01:59:59.497676000 : 8=FIXT.1.19=27935=X49=Coinbase56=24ab46f784d1b20db435b852086e325034=17550=TEST52=20250411-01:59:59.378420369=45262=1c4ca071-c1b7-4b32-a10d-aab5f1327380268=1279=0269=083=159758158255=BTC-USD29004=2.208895519560=20250411-01:59:59.37666140=137=b6c714bf-76fd-407c-9b5a-323a3be7763c10=000
20250411-01:59:59.497966000 : 8=FIXT.1.19=32735=X49=Coinbase56=24ab46f784d1b20db435b852086e325034=17650=TEST52=20250411-01:59:59.378493369=45262=1c4ca071-c1b7-4b32-a10d-aab5f1327380268=1279=0269=2278=c5b88ea9-605d-4595-ac52-f7c3f08523ba83=159758158355=BTC-USD270=3.55271=0.6222240960=20250411-01:59:59.37666137=b6c714bf-76fd-407c-9b5a-323a3be7763c5797=110=157
20250411-01:59:59.501266000 : 8=FIXT.1.19=26635=X49=Coinbase56=24ab46f784d1b20db435b852086e325034=17750=TEST52=20250411-01:59:59.378501369=45262=1c4ca071-c1b7-4b32-a10d-aab5f1327380268=1279=2269=0278=b6c714bf-76fd-407c-9b5a-323a3be7763c83=159758158455=BTC-USD60=20250411-01:59:59.37666158=FILLED10=016
20250411-01:59:59.527147000 : 8=FIXT.1.19=27535=X49=Coinbase56=24ab46f784d1b20db435b852086e325034=17850=TEST52=20250411-01:59:59.408046369=45262=1c4ca071-c1b7-4b32-a10d-aab5f1327380268=1279=0269=183=159758158555=BTC-USD271=0.6197183160=20250411-01:59:59.40629440=137=4f437bc8-2b68-4cf8-b0e6-6b8136d5691a10=209
20250411-01:59:59.527409000 : 8=FIXT.1.19=32735=X49=Coinbase56=24ab46f784d1b20db435b852086e325034=17950=TEST52=20250411-01:59:59.408057369=45262=1c4ca071-c1b7-4b32-a10d-aab5f1327380268=1279=0269=2278=4d60a78e-b39b-420e-b830-bc0f3f4fdde283=159758158655=BTC-USD270=3.53271=0.6197183160=20250411-01:59:59.40629437=4f437bc8-2b68-4cf8-b0e6-6b8136d5691a5797=210=200
20250411-01:59:59.527558000 : 8=FIXT.1.19=28135=X49=Coinbase56=24ab46f784d1b20db435b852086e325034=18050=TEST52=20250411-01:59:59.408059369=45262=1c4ca071-c1b7-4b32-a10d-aab5f1327380268=1279=2269=1278=4f437bc8-2b68-4cf8-b0e6-6b8136d5691a83=159758158755=BTC-USD271=0.0000000060=20250411-01:59:59.40629458=FILLED10=106
20250411-01:59:59.556679000 : 8=FIXT.1.19=27935=X49=Coinbase56=24ab46f784d1b20db435b852086e325034=18150=TEST52=20250411-01:59:59.436645369=45262=1c4ca071-c1b7-4b32-a10d-aab5f1327380268=1279=0269=083=159758158855=BTC-USD29004=2.208895519560=20250411-01:59:59.43477740=137=92b2f709-38b6-49b4-8b14-b3cd7ec0647a10=175
20250411-01:59:59.556915000 : 8=FIXT.1.19=32735=X49=Coinbase56=24ab46f784d1b20db435b852086e325034=18250=TEST52=20250411-01:59:59.436652369=45262=1c4ca071-c1b7-4b32-a10d-aab5f1327380268=1279=0269=2278=c5b88ea9-605d-4595-ac52-f7c3f08523ba83=159758158955=BTC-USD270=3.55271=0.6222240960=20250411-01:59:59.43477737=92b2f709-38b6-49b4-8b14-b3cd7ec0647a5797=110=064
20250411-01:59:59.558466000 : 8=FIXT.1.19=26635=X49=Coinbase56=24ab46f784d1b20db435b852086e325034=18350=TEST52=20250411-01:59:59.436662369=45262=1c4ca071-c1b7-4b32-a10d-aab5f1327380268=1279=2269=0278=92b2f709-38b6-49b4-8b14-b3cd7ec0647a83=159758159055=BTC-USD60=20250411-01:59:59.43477758=FILLED10=181
20250411-01:59:59.558663000 : 8=FIXT.1.19=28435=X49=Coinbase56=24ab46f784d1b20db435b852086e325034=18450=TEST52=20250411-01:59:59.438122369=45262=1c4ca071-c1b7-4b32-a10d-aab5f1327380268=1279=0269=083=159758159155=BTC-USD270=3.82271=0.6232294660=20250411-01:59:59.43723040=237=034e7764-1c06-4a6b-9012-43ba2f67bcca10=069
20250411-01:59:59.558915000 : 8=FIXT.1.19=32735=X49=Coinbase56=24ab46f784d1b20db435b852086e325034=18550=TEST52=20250411-01:59:59.438220369=45262=1c4ca071-c1b7-4b32-a10d-aab5f1327380268=1279=0269=2278=c5b88ea9-605d-4595-ac52-f7c3f08523ba83=159758159255=BTC-USD270=3.55271=0.6232294660=20250411-01:59:59.43723037=034e7764-1c06-4a6b-9012-43ba2f67bcca5797=110=024
20250411-01:59:59.559210000 : 8=FIXT.1.19=29035=X49=Coinbase56=24ab46f784d1b20db435b852086e325034=18650=TEST52=20250411-01:59:59.438223369=45262=1c4ca071-c1b7-4b32-a10d-aab5f1327380268=1279=2269=0278=034e7764-1c06-4a6b-9012-43ba2f67bcca83=159758159355=BTC-USD270=3.82271=0.0000000060=20250411-01:59:59.43723058=FILLED10=230
20250411-01:59:59.584546000 : 8=FIXT.1.19=27535=X49=Coinbase56=24ab46f784d1b20db435b852086e325034=18750=TEST52=20250411-01:59:59.464726369=45262=1c4ca071-c1b7-4b32-a10d-aab5f1327380268=1279=0269=183=159758159455=BTC-USD271=0.6197183160=20250411-01:59:59.46347940=137=da76bbf0-f352-46f0-82f4-f57bd02d4fac10=143
20250411-01:59:59.584924000 : 8=FIXT.1.19=32735=X49=Coinbase56=24ab46f784d1b20db435b852086e325034=18850=TEST52=20250411-01:59:59.464732369=45262=1c4ca071-c1b7-4b32-a10d-aab5f1327380268=1279=0269=2278=4d60a78e-b39b-420e-b830-bc0f3f4fdde283=159758159555=BTC-USD270=3.53271=0.6197183160=20250411-01:59:59.46347937=da76bbf0-f352-46f0-82f4-f57bd02d4fac5797=210=129
20250411-01:59:59.585097000 : 8=FIXT.1.19=28135=X49=Coinbase56=24ab46f784d1b20db435b852086e325034=18950=TEST52=20250411-01:59:59.464736369=45262=1c4ca071-c1b7-4b32-a10d-aab5f1327380268=1279=2269=1278=da76bbf0-f352-46f0-82f4-f57bd02d4fac83=159758159655=BTC-USD271=0.0000000060=20250411-01:59:59.46347958=FILLED10=046
20250411-01:59:59.612934000 : 8=FIXT.1.19=28435=X49=Coinbase56=24ab46f784d1b20db435b852086e325034=19050=TEST52=20250411-01:59:59.493280369=45262=1c4ca071-c1b7-4b32-a10d-aab5f1327380268=1279=0269=183=159758159755=BTC-USD270=3.31271=0.6232294660=20250411-01:59:59.49152640=237=698a0d2a-ad0e-4a5f-b467-4ce970d54e0410=192
20250411-01:59:59.615578000 : 8=FIXT.1.19=32735=X49=Coinbase56=24ab46f784d1b20db435b852086e325034=19150=TEST52=20250411-01:59:59.493286369=45262=1c4ca071-c1b7-4b32-a10d-aab5f1327380268=1279=0269=2278=4d60a78e-b39b-420e-b830-bc0f3f4fdde283=159758159855=BTC-USD270=3.53271=0.6232294660=20250411-01:59:59.49152637=698a0d2a-ad0e-4a5f-b467-4ce970d54e045797=210=030
20250411-01:59:59.615789000 : 8=FIXT.1.19=29035=X49=Coinbase56=24ab46f784d1b20db435b852086e325034=19250=TEST52=20250411-01:59:59.493336369=45262=1c4ca071-c1b7-4b32-a10d-aab5f1327380268=1279=2269=1278=698a0d2a-ad0e-4a5f-b467-4ce970d54e0483=159758159955=BTC-USD270=3.31271=0.0000000060=20250411-01:59:59.49152658=FILLED10=097
20250411-01:59:59.749418000 : 8=FIXT.1.19=31035=X49=Coinbase56=24ab46f784d1b20db435b852086e325034=19350=TEST52=20250411-01:59:59.629810369=45262=1c4ca071-c1b7-4b32-a10d-aab5f1327380268=1279=1269=0278=1427699a-fe0c-4a1f-8735-bd2913dcabdc83=159758160055=BTC-USD270=3.41271=0.5471833160=20250411-01:59:59.62774058=CHANGE_REASON_MODIFY_ORDER10=181
20250411-01:59:59.841290000 : 8=FIXT.1.19=27935=X49=Coinbase56=24ab46f784d1b20db435b852086e325034=19450=TEST52=20250411-01:59:59.722237369=45262=1c4ca071-c1b7-4b32-a10d-aab5f1327380268=1279=0269=083=159758160155=BTC-USD29004=2.208895519560=20250411-01:59:59.72052240=137=cb339dbd-6cba-440f-a7ca-957f1ffe7e7b10=225
20250411-01:59:59.841955000 : 8=FIXT.1.19=32735=X49=Coinbase56=24ab46f784d1b20db435b852086e325034=19550=TEST52=20250411-01:59:59.722246369=45262=1c4ca071-c1b7-4b32-a10d-aab5f1327380268=1279=0269=2278=c5b88ea9-605d-4595-ac52-f7c3f08523ba83=159758160255=BTC-USD270=3.55271=0.6222240960=20250411-01:59:59.72052237=cb339dbd-6cba-440f-a7ca-957f1ffe7e7b5797=110=116
20250411-01:59:59.842142000 : 8=FIXT.1.19=26635=X49=Coinbase56=24ab46f784d1b20db435b852086e325034=19650=TEST52=20250411-01:59:59.722249369=45262=1c4ca071-c1b7-4b32-a10d-aab5f1327380268=1279=2269=0278=cb339dbd-6cba-440f-a7ca-957f1ffe7e7b83=159758160355=BTC-USD60=20250411-01:59:59.72052258=FILLED10=244
20250411-01:59:59.861179000 : 8=FIXT.1.19=28435=X49=Coinbase56=24ab46f784d1b20db435b852086e325034=19750=TEST52=20250411-01:59:59.742614369=45262=1c4ca071-c1b7-4b32-a10d-aab5f1327380268=1279=0269=083=159758160455=BTC-USD270=3.51271=0.6197183160=20250411-01:59:59.74063740=237=65110251-0da3-4a57-bb61-db1ad80b91a910=066
20250411-01:59:59.861374000 : 8=FIXT.1.19=28035=X49=Coinbase56=24ab46f784d1b20db435b852086e325034=19850=TEST52=20250411-01:59:59.742664369=45262=1c4ca071-c1b7-4b32-a10d-aab5f1327380268=1279=0269=0278=65110251-0da3-4a57-bb61-db1ad80b91a983=159758160555=BTC-USD270=3.51271=0.6197183160=20250411-01:59:59.74063710=168
20250411-01:59:59.869629000 : 8=FIXT.1.19=27535=X49=Coinbase56=24ab46f784d1b20db435b852086e325034=19950=TEST52=20250411-01:59:59.750648369=45262=1c4ca071-c1b7-4b32-a10d-aab5f1327380268=1279=0269=183=159758160655=BTC-USD271=0.6232294660=20250411-01:59:59.74899340=137=a15dfa3c-93e1-4288-8218-7660b519c32910=078
20250411-01:59:59.870101000 : 8=FIXT.1.19=32735=X49=Coinbase56=24ab46f784d1b20db435b852086e325034=20050=TEST52=20250411-01:59:59.750656369=45262=1c4ca071-c1b7-4b32-a10d-aab5f1327380268=1279=0269=2278=4d60a78e-b39b-420e-b830-bc0f3f4fdde283=159758160755=BTC-USD270=3.53271=0.6232294660=20250411-01:59:59.74899337=a15dfa3c-93e1-4288-8218-7660b519c3295797=210=048
20250411-01:59:59.870282000 : 8=FIXT.1.19=28135=X49=Coinbase56=24ab46f784d1b20db435b852086e325034=20150=TEST52=20250411-01:59:59.750659369=45262=1c4ca071-c1b7-4b32-a10d-aab5f1327380268=1279=2269=1278=a15dfa3c-93e1-4288-8218-7660b519c32983=159758160855=BTC-USD271=0.0000000060=20250411-01:59:59.74899358=FILLED10=222
20250411-01:59:59.956337000 : 8=FIXT.1.19=27935=X49=Coinbase56=24ab46f784d1b20db435b852086e325034=20250=TEST52=20250411-01:59:59.836043369=45262=1c4ca071-c1b7-4b32-a10d-aab5f1327380268=1279=0269=083=159758160955=BTC-USD29004=2.208895519560=20250411-01:59:59.83459240=137=df4e5b35-ac8e-45c4-bf43-41a8e161137f10=245
20250411-01:59:59.956614000 : 8=FIXT.1.19=32735=X49=Coinbase56=24ab46f784d1b20db435b852086e325034=20350=TEST52=20250411-01:59:59.836051369=45262=1c4ca071-c1b7-4b32-a10d-aab5f1327380268=1279=0269=2278=c5b88ea9-605d-4595-ac52-f7c3f08523ba83=159758161055=BTC-USD270=3.55271=0.6222240960=20250411-01:59:59.83459237=df4e5b35-ac8e-45c4-bf43-41a8e161137f5797=110=126
20250411-01:59:59.956765000 : 8=FIXT.1.19=26635=X49=Coinbase56=24ab46f784d1b20db435b852086e325034=20450=TEST52=20250411-01:59:59.836054369=45262=1c4ca071-c1b7-4b32-a10d-aab5f1327380268=1279=2269=0278=df4e5b35-ac8e-45c4-bf43-41a8e161137f83=159758161155=BTC-USD60=20250411-01:59:59.83459258=FILLED10=254
20250411-01:59:59.982667000 : 8=FIXT.1.19=27535=X49=Coinbase56=24ab46f784d1b20db435b852086e325034=20550=TEST52=20250411-01:59:59.864296369=45262=1c4ca071-c1b7-4b32-a10d-aab5f1327380268=1279=0269=183=159758161255=BTC-USD271=0.6232294660=20250411-01:59:59.86282840=137=da61fcb9-6a61-4cae-a325-5d840f7a62d110=076
20250411-01:59:59.983039000 : 8=FIXT.1.19=32735=X49=Coinbase56=24ab46f784d1b20db435b852086e325034=20650=TEST52=20250411-01:59:59.864304369=45262=1c4ca071-c1b7-4b32-a10d-aab5f1327380268=1279=0269=2278=4d60a78e-b39b-420e-b830-bc0f3f4fdde283=159758161355=BTC-USD270=3.53271=0.6232294660=20250411-01:59:59.86282837=da61fcb9-6a61-4cae-a325-5d840f7a62d15797=210=055
20250411-01:59:59.983287000 : 8=FIXT.1.19=28135=X49=Coinbase56=24ab46f784d1b20db435b852086e325034=20750=TEST52=20250411-01:59:59.864309369=45262=1c4ca071-c1b7-4b32-a10d-aab5f1327380268=1279=2269=1278=da61fcb9-6a61-4cae-a325-5d840f7a62d183=159758161455=BTC-USD271=0.0000000060=20250411-01:59:59.86282858=FILLED10=231
20250411-02:00:00.037766000 : 8=FIXT.1.19=31035=X49=Coinbase56=24ab46f784d1b20db435b852086e325034=20850=TEST52=20250411-01:59:59.913917369=45262=1c4ca071-c1b7-4b32-a10d-aab5f1327380268=1279=1269=1278=d68d2389-fda4-456e-a285-3787e94c7c8883=159758161555=BTC-USD270=3.59271=0.5676385660=20250411-01:59:59.91207958=CHANGE_REASON_MODIFY_ORDER10=063
20250411-02:00:00.320181000 : 8=FIXT.1.19=30735=X49=Coinbase56=24ab46f784d1b20db435b852086e325034=20950=TEST52=20250411-02:00:00.199434369=45262=1c4ca071-c1b7-4b32-a10d-aab5f1327380268=1279=1269=1278=b175a3bc-9391-4e0a-b8f2-4c919d3a4f1883=159758161655=BTC-USD270=3.6271=0.51421360=20250411-02:00:00.19789258=CHANGE_REASON_MODIFY_ORDER10=155
20250411-02:00:00.357574000 : 8=FIXT.1.19=28435=X49=Coinbase56=24ab46f784d1b20db435b852086e325034=21050=TEST52=20250411-02:00:00.238375369=45262=1c4ca071-c1b7-4b32-a10d-aab5f1327380268=1279=0269=083=159758161755=BTC-USD270=3.84271=0.6232294660=20250411-02:00:00.23655040=237=69b47383-c35a-4a94-93c4-00057db41cd210=188
20250411-02:00:00.357996000 : 8=FIXT.1.19=32735=X49=Coinbase56=24ab46f784d1b20db435b852086e325034=21150=TEST52=20250411-02:00:00.238384369=45262=1c4ca071-c1b7-4b32-a10d-aab5f1327380268=1279=0269=2278=c5b88ea9-605d-4595-ac52-f7c3f08523ba83=159758161855=BTC-USD270=3.55271=0.6232294660=20250411-02:00:00.23655037=69b47383-c35a-4a94-93c4-00057db41cd25797=110=142
20250411-02:00:00.358272000 : 8=FIXT.1.19=29035=X49=Coinbase56=24ab46f784d1b20db435b852086e325034=21250=TEST52=20250411-02:00:00.238386369=45262=1c4ca071-c1b7-4b32-a10d-aab5f1327380268=1279=2269=0278=69b47383-c35a-4a94-93c4-00057db41cd283=159758161955=BTC-USD270=3.84271=0.0000000060=20250411-02:00:00.23655058=FILLED10=093
20250411-02:00:00.411938000 : 8=FIXT.1.19=28435=X49=Coinbase56=24ab46f784d1b20db435b852086e325034=21350=TEST52=20250411-02:00:00.293087369=45262=1c4ca071-c1b7-4b32-a10d-aab5f1327380268=1279=0269=183=159758162055=BTC-USD270=3.29271=0.6232294660=20250411-02:00:00.29176140=237=0bda92e6-0a7d-471e-902d-152f6c0f83d410=077
20250411-02:00:00.414350000 : 8=FIXT.1.19=32735=X49=Coinbase56=24ab46f784d1b20db435b852086e325034=21450=TEST52=20250411-02:00:00.293091369=45262=1c4ca071-c1b7-4b32-a10d-aab5f1327380268=1279=0269=2278=4d60a78e-b39b-420e-b830-bc0f3f4fdde283=159758162155=BTC-USD270=3.53271=0.6232294660=20250411-02:00:00.29176137=0bda92e6-0a7d-471e-902d-152f6c0f83d45797=210=153
20250411-02:00:00.414554000 : 8=FIXT.1.19=29035=X49=Coinbase56=24ab46f784d1b20db435b852086e325034=21550=TEST52=20250411-02:00:00.293093369=45262=1c4ca071-c1b7-4b32-a10d-aab5f1327380268=1279=2269=1278=0bda92e6-0a7d-471e-902d-152f6c0f83d483=159758162255=BTC-USD270=3.29271=0.0000000060=20250411-02:00:00.29176158=FILLED10=233
20250411-02:00:00.528230000 : 8=FIXT.1.19=27935=X49=Coinbase56=24ab46f784d1b20db435b852086e325034=21650=TEST52=20250411-02:00:00.407274369=45262=1c4ca071-c1b7-4b32-a10d-aab5f1327380268=1279=0269=083=159758162355=BTC-USD29004=2.208895519560=20250411-02:00:00.40573440=137=c0174929-1689-4dd1-879b-84e41f15e84010=175
20250411-02:00:00.528656000 : 8=FIXT.1.19=32735=X49=Coinbase56=24ab46f784d1b20db435b852086e325034=21750=TEST52=20250411-02:00:00.407283369=45262=1c4ca071-c1b7-4b32-a10d-aab5f1327380268=1279=0269=2278=c5b88ea9-605d-4595-ac52-f7c3f08523ba83=159758162455=BTC-USD270=3.55271=0.6222240960=20250411-02:00:00.40573437=c0174929-1689-4dd1-879b-84e41f15e8405797=110=066
20250411-02:00:00.528830000 : 8=FIXT.1.19=26635=X49=Coinbase56=24ab46f784d1b20db435b852086e325034=21850=TEST52=20250411-02:00:00.407285369=45262=1c4ca071-c1b7-4b32-a10d-aab5f1327380268=1279=2269=0278=c0174929-1689-4dd1-879b-84e41f15e84083=159758162555=BTC-USD60=20250411-02:00:00.40573458=FILLED10=193
20250411-02:00:00.556185000 : 8=FIXT.1.19=27535=X49=Coinbase56=24ab46f784d1b20db435b852086e325034=21950=TEST52=20250411-02:00:00.437793369=45262=1c4ca071-c1b7-4b32-a10d-aab5f1327380268=1279=0269=183=159758162655=BTC-USD271=0.6232294660=20250411-02:00:00.43584740=137=3d706395-1363-4fd2-ac8e-466e352d616a10=057
20250411-02:00:00.556363000 : 8=FIXT.1.19=32735=X49=Coinbase56=24ab46f784d1b20db435b852086e325034=22050=TEST52=20250411-02:00:00.437802369=45262=1c4ca071-c1b7-4b32-a10d-aab5f1327380268=1279=0269=2278=4d60a78e-b39b-420e-b830-bc0f3f4fdde283=159758162755=BTC-USD270=3.53271=0.6232294660=20250411-02:00:00.43584737=3d706395-1363-4fd2-ac8e-466e352d616a5797=210=028
20250411-02:00:00.556485000 : 8=FIXT.1.19=28135=X49=Coinbase56=24ab46f784d1b20db435b852086e325034=22150=TEST52=20250411-02:00:00.437804369=45262=1c4ca071-c1b7-4b32-a10d-aab5f1327380268=1279=2269=1278=3d706395-1363-4fd2-ac8e-466e352d616a83=159758162855=BTC-USD271=0.0000000060=20250411-02:00:00.43584758=FILLED10=201
20250411-02:00:01.613035000 : 8=FIXT.1.19=27935=X49=Coinbase56=24ab46f784d1b20db435b852086e325034=22250=TEST52=20250411-02:00:01.493657369=45262=1c4ca071-c1b7-4b32-a10d-aab5f1327380268=1279=0269=083=159758162955=BTC-USD29004=2.208895519560=20250411-02:00:01.49219340=137=32d0d951-f902-44b0-bb4b-5b0f85ae069410=098
20250411-02:00:01.614257000 : 8=FIXT.1.19=32735=X49=Coinbase56=24ab46f784d1b20db435b852086e325034=22350=TEST52=20250411-02:00:01.493668369=45262=1c4ca071-c1b7-4b32-a10d-aab5f1327380268=1279=0269=2278=c5b88ea9-605d-4595-ac52-f7c3f08523ba83=159758163055=BTC-USD270=3.55271=0.6222240960=20250411-02:00:01.49219337=32d0d951-f902-44b0-bb4b-5b0f85ae06945797=110=238
20250411-02:00:01.614445000 : 8=FIXT.1.19=26635=X49=Coinbase56=24ab46f784d1b20db435b852086e325034=22450=TEST52=20250411-02:00:01.493697369=45262=1c4ca071-c1b7-4b32-a10d-aab5f1327380268=1279=2269=0278=32d0d951-f902-44b0-bb4b-5b0f85ae069483=159758163155=BTC-USD60=20250411-02:00:01.49219358=FILLED10=109
20250411-02:00:01.641866000 : 8=FIXT.1.19=27535=X49=Coinbase56=24ab46f784d1b20db435b852086e325034=22550=TEST52=20250411-02:00:01.522199369=45262=1c4ca071-c1b7-4b32-a10d-aab5f1327380268=1279=0269=183=159758163255=BTC-USD271=0.6232294660=20250411-02:00:01.52097740=137=4d8cdd57-4ead-4838-a32e-85d19a02934410=148
20250411-02:00:01.642621000 : 8=FIXT.1.19=32735=X49=Coinbase56=24ab46f784d1b20db435b852086e325034=22650=TEST52=20250411-02:00:01.522208369=45262=1c4ca071-c1b7-4b32-a10d-aab5f1327380268=1279=0269=2278=4d60a78e-b39b-420e-b830-bc0f3f4fdde283=159758163355=BTC-USD270=3.53271=0.6232294660=20250411-02:00:01.52097737=4d8cdd57-4ead-4838-a32e-85d19a0293445797=210=128
20250411-02:00:01.642826000 : 8=FIXT.1.19=28135=X49=Coinbase56=24ab46f784d1b20db435b852086e325034=22750=TEST52=20250411-02:00:01.522212369=45262=1c4ca071-c1b7-4b32-a10d-aab5f1327380268=1279=2269=1278=4d8cdd57-4ead-4838-a32e-85d19a02934483=159758163455=BTC-USD271=0.0000000060=20250411-02:00:01.52097758=FILLED10=038
20250411-02:00:01.897956000 : 8=FIXT.1.19=27935=X49=Coinbase56=24ab46f784d1b20db435b852086e325034=22850=TEST52=20250411-02:00:01.778770369=45262=1c4ca071-c1b7-4b32-a10d-aab5f1327380268=1279=0269=083=159758163555=BTC-USD29004=2.208895519560=20250411-02:00:01.77754240=137=7e73476e-a094-436d-8211-e3c5529d593510=200
20250411-02:00:01.898857000 : 8=FIXT.1.19=32735=X49=Coinbase56=24ab46f784d1b20db435b852086e325034=22950=TEST52=20250411-02:00:01.778779369=45262=1c4ca071-c1b7-4b32-a10d-aab5f1327380268=1279=0269=2278=c5b88ea9-605d-4595-ac52-f7c3f08523ba83=159758163655=BTC-USD270=3.55271=0.6222240960=20250411-02:00:01.77754237=7e73476e-a094-436d-8211-e3c5529d59355797=110=100
20250411-02:00:01.899105000 : 8=FIXT.1.19=26635=X49=Coinbase56=24ab46f784d1b20db435b852086e325034=23050=TEST52=20250411-02:00:01.778782369=45262=1c4ca071-c1b7-4b32-a10d-aab5f1327380268=1279=2269=0278=7e73476e-a094-436d-8211-e3c5529d593583=159758163755=BTC-USD60=20250411-02:00:01.77754258=FILLED10=210
20250411-02:00:01.925935000 : 8=FIXT.1.19=27535=X49=Coinbase56=24ab46f784d1b20db435b852086e325034=23150=TEST52=20250411-02:00:01.807141369=45262=1c4ca071-c1b7-4b32-a10d-aab5f1327380268=1279=0269=183=159758163855=BTC-USD271=0.6232294660=20250411-02:00:01.80536340=137=023273e2-f1ec-4b3b-a5ca-ad5be1bd6ee010=134
20250411-02:00:01.926264000 : 8=FIXT.1.19=32735=X49=Coinbase56=24ab46f784d1b20db435b852086e325034=23250=TEST52=20250411-02:00:01.807232369=45262=1c4ca071-c1b7-4b32-a10d-aab5f1327380268=1279=0269=2278=4d60a78e-b39b-420e-b830-bc0f3f4fdde283=159758163955=BTC-USD270=3.53271=0.6232294660=20250411-02:00:01.80536337=023273e2-f1ec-4b3b-a5ca-ad5be1bd6ee05797=210=124
20250411-02:00:01.926422000 : 8=FIXT.1.19=28135=X49=Coinbase56=24ab46f784d1b20db435b852086e325034=23350=TEST52=20250411-02:00:01.807285369=45262=1c4ca071-c1b7-4b32-a10d-aab5f1327380268=1279=2269=1278=023273e2-f1ec-4b3b-a5ca-ad5be1bd6ee083=159758164055=BTC-USD271=0.0000000060=20250411-02:00:01.80536358=FILLED10=038
20250411-02:00:02.070971000 : 8=FIXT.1.19=28435=X49=Coinbase56=24ab46f784d1b20db435b852086e325034=23450=TEST52=20250411-02:00:01.952118369=45262=1c4ca071-c1b7-4b32-a10d-aab5f1327380268=1279=0269=083=159758164155=BTC-USD270=3.86271=0.6232294660=20250411-02:00:01.95074640=237=8e274abb-1392-4272-9549-cacb33a5799b10=008
20250411-02:00:02.071700000 : 8=FIXT.1.19=32735=X49=Coinbase56=24ab46f784d1b20db435b852086e325034=23550=TEST52=20250411-02:00:01.952128369=45262=1c4ca071-c1b7-4b32-a10d-aab5f1327380268=1279=0269=2278=c5b88ea9-605d-4595-ac52-f7c3f08523ba83=159758164255=BTC-USD270=3.55271=0.6232294660=20250411-02:00:01.95074637=8e274abb-1392-4272-9549-cacb33a5799b5797=110=217
20250411-02:00:02.071870000 : 8=FIXT.1.19=29035=X49=Coinbase56=24ab46f784d1b20db435b852086e325034=23650=TEST52=20250411-02:00:01.952135369=45262=1c4ca071-c1b7-4b32-a10d-aab5f1327380268=1279=2269=0278=8e274abb-1392-4272-9549-cacb33a5799b83=159758164355=BTC-USD270=3.86271=0.0000000060=20250411-02:00:01.95074658=FILLED10=166
20250411-02:00:02.130220000 : 8=FIXT.1.19=28435=X49=Coinbase56=24ab46f784d1b20db435b852086e325034=23750=TEST52=20250411-02:00:02.007763369=45262=1c4ca071-c1b7-4b32-a10d-aab5f1327380268=1279=0269=183=159758164455=BTC-USD270=3.26271=0.6232294660=20250411-02:00:02.00655340=237=d52e3540-278f-4580-a8b6-8cc4012a02a110=179
20250411-02:00:02.139016000 : 8=FIXT.1.19=32735=X49=Coinbase56=24ab46f784d1b20db435b852086e325034=23850=TEST52=20250411-02:00:02.007819369=45262=1c4ca071-c1b7-4b32-a10d-aab5f1327380268=1279=0269=2278=4d60a78e-b39b-420e-b830-bc0f3f4fdde283=159758164555=BTC-USD270=3.53271=0.6232294660=20250411-02:00:02.00655337=d52e3540-278f-4580-a8b6-8cc4012a02a15797=210=009
20250411-02:00:02.140708000 : 8=FIXT.1.19=29035=X49=Coinbase56=24ab46f784d1b20db435b852086e325034=23950=TEST52=20250411-02:00:02.007827369=45262=1c4ca071-c1b7-4b32-a10d-aab5f1327380268=1279=2269=1278=d52e3540-278f-4580-a8b6-8cc4012a02a183=159758164655=BTC-USD270=3.26271=0.0000000060=20250411-02:00:02.00655358=FILLED10=083
20250411-02:00:02.298713000 : 8=FIXT.1.19=27935=X49=Coinbase56=24ab46f784d1b20db435b852086e325034=24050=TEST52=20250411-02:00:02.178995369=45262=1c4ca071-c1b7-4b32-a10d-aab5f1327380268=1279=0269=083=159758164755=BTC-USD29004=2.208895519560=20250411-02:00:02.17743840=137=5ed3c444-62af-40a0-9b99-163cd873b84310=076
20250411-02:00:02.299326000 : 8=FIXT.1.19=32735=X49=Coinbase56=24ab46f784d1b20db435b852086e325034=24150=TEST52=20250411-02:00:02.179006369=45262=1c4ca071-c1b7-4b32-a10d-aab5f1327380268=1279=0269=2278=c5b88ea9-605d-4595-ac52-f7c3f08523ba83=159758164855=BTC-USD270=3.55271=0.6222240960=20250411-02:00:02.17743837=5ed3c444-62af-40a0-9b99-163cd873b8435797=110=207
20250411-02:00:02.299534000 : 8=FIXT.1.19=26635=X49=Coinbase56=24ab46f784d1b20db435b852086e325034=24250=TEST52=20250411-02:00:02.179008369=45262=1c4ca071-c1b7-4b32-a10d-aab5f1327380268=1279=2269=0278=5ed3c444-62af-40a0-9b99-163cd873b84383=159758164955=BTC-USD60=20250411-02:00:02.17743858=FILLED10=078
20250411-02:00:02.327448000 : 8=FIXT.1.19=27535=X49=Coinbase56=24ab46f784d1b20db435b852086e325034=24350=TEST52=20250411-02:00:02.208255369=45262=1c4ca071-c1b7-4b32-a10d-aab5f1327380268=1279=0269=183=159758165055=BTC-USD271=0.6232294660=20250411-02:00:02.20613540=137=3e5c13dc-d67a-4ae8-b0b3-86516d5e857a10=221
20250411-02:00:02.328010000 : 8=FIXT.1.19=32735=X49=Coinbase56=24ab46f784d1b20db435b852086e325034=24450=TEST52=20250411-02:00:02.208326369=45262=1c4ca071-c1b7-4b32-a10d-aab5f1327380268=1279=0269=2278=4d60a78e-b39b-420e-b830-bc0f3f4fdde283=159758165155=BTC-USD270=3.53271=0.6232294660=20250411-02:00:02.20613537=3e5c13dc-d67a-4ae8-b0b3-86516d5e857a5797=210=209
20250411-02:00:02.328216000 : 8=FIXT.1.19=28135=X49=Coinbase56=24ab46f784d1b20db435b852086e325034=24550=TEST52=20250411-02:00:02.208329369=45262=1c4ca071-c1b7-4b32-a10d-aab5f1327380268=1279=2269=1278=3e5c13dc-d67a-4ae8-b0b3-86516d5e857a83=159758165255=BTC-USD271=0.0000000060=20250411-02:00:02.20613558=FILLED10=127
20250411-02:00:02.411917000 : 8=FIXT.1.19=27935=X49=Coinbase56=24ab46f784d1b20db435b852086e325034=24650=TEST52=20250411-02:00:02.293347369=45262=1c4ca071-c1b7-4b32-a10d-aab5f1327380268=1279=0269=083=159758165355=BTC-USD29004=2.208895519560=20250411-02:00:02.29209440=137=c963c9d1-6d22-4188-a960-55dd670d5d2a10=067
20250411-02:00:02.412493000 : 8=FIXT.1.19=32735=X49=Coinbase56=24ab46f784d1b20db435b852086e325034=24750=TEST52=20250411-02:00:02.293353369=45262=1c4ca071-c1b7-4b32-a10d-aab5f1327380268=1279=0269=2278=c5b88ea9-605d-4595-ac52-f7c3f08523ba83=159758165455=BTC-USD270=3.55271=0.6222240960=20250411-02:00:02.29209437=c963c9d1-6d22-4188-a960-55dd670d5d2a5797=110=211
20250411-02:00:02.412646000 : 8=FIXT.1.19=26635=X49=Coinbase56=24ab46f784d1b20db435b852086e325034=24850=TEST52=20250411-02:00:02.293355369=45262=1c4ca071-c1b7-4b32-a10d-aab5f1327380268=1279=2269=0278=c963c9d1-6d22-4188-a960-55dd670d5d2a83=159758165555=BTC-USD60=20250411-02:00:02.29209458=FILLED10=082
20250411-02:00:02.441687000 : 8=FIXT.1.19=27535=X49=Coinbase56=24ab46f784d1b20db435b852086e325034=24950=TEST52=20250411-02:00:02.321402369=45262=1c4ca071-c1b7-4b32-a10d-aab5f1327380268=1279=0269=183=159758165655=BTC-USD271=0.6232294660=20250411-02:00:02.32023240=137=f1dc5ebb-1e42-44e5-9ba2-98636ccde4cf10=107
20250411-02:00:02.441896000 : 8=FIXT.1.19=32735=X49=Coinbase56=24ab46f784d1b20db435b852086e325034=25050=TEST52=20250411-02:00:02.321475369=45262=1c4ca071-c1b7-4b32-a10d-aab5f1327380268=1279=0269=2278=4d60a78e-b39b-420e-b830-bc0f3f4fdde283=159758165755=BTC-USD270=3.53271=0.6232294660=20250411-02:00:02.32023237=f1dc5ebb-1e42-44e5-9ba2-98636ccde4cf5797=210=097
20250411-02:00:02.442046000 : 8=FIXT.1.19=28135=X49=Coinbase56=24ab46f784d1b20db435b852086e325034=25150=TEST52=20250411-02:00:02.321478369=45262=1c4ca071-c1b7-4b32-a10d-aab5f1327380268=1279=2269=1278=f1dc5ebb-1e42-44e5-9ba2-98636ccde4cf83=159758165855=BTC-USD271=0.0000000060=20250411-02:00:02.32023258=FILLED10=015
20250411-02:00:02.926903000 : 8=FIXT.1.19=27935=X49=Coinbase56=24ab46f784d1b20db435b852086e325034=25250=TEST52=20250411-02:00:02.807371369=45262=1c4ca071-c1b7-4b32-a10d-aab5f1327380268=1279=0269=083=159758165955=BTC-USD29004=2.208895519560=20250411-02:00:02.80587340=137=87fd2bb0-1d6b-48c7-a2ad-250a538e0a0110=186
20250411-02:00:02.927583000 : 8=FIXT.1.19=32735=X49=Coinbase56=24ab46f784d1b20db435b852086e325034=25350=TEST52=20250411-02:00:02.807382369=45262=1c4ca071-c1b7-4b32-a10d-aab5f1327380268=1279=0269=2278=c5b88ea9-605d-4595-ac52-f7c3f08523ba83=159758166055=BTC-USD270=3.55271=0.6222240960=20250411-02:00:02.80587337=87fd2bb0-1d6b-48c7-a2ad-250a538e0a015797=110=070
20250411-02:00:02.927768000 : 8=FIXT.1.19=26635=X49=Coinbase56=24ab46f784d1b20db435b852086e325034=25450=TEST52=20250411-02:00:02.807384369=45262=1c4ca071-c1b7-4b32-a10d-aab5f1327380268=1279=2269=0278=87fd2bb0-1d6b-48c7-a2ad-250a538e0a0183=159758166155=BTC-USD60=20250411-02:00:02.80587358=FILLED10=197
20250411-02:00:02.955369000 : 8=FIXT.1.19=27535=X49=Coinbase56=24ab46f784d1b20db435b852086e325034=25550=TEST52=20250411-02:00:02.835941369=45262=1c4ca071-c1b7-4b32-a10d-aab5f1327380268=1279=0269=183=159758166255=BTC-USD271=0.6232294660=20250411-02:00:02.83442640=137=980cf7e4-9009-4da3-95c9-d536773e7cea10=172
20250411-02:00:02.955902000 : 8=FIXT.1.19=32735=X49=Coinbase56=24ab46f784d1b20db435b852086e325034=25650=TEST52=20250411-02:00:02.835948369=45262=1c4ca071-c1b7-4b32-a10d-aab5f1327380268=1279=0269=2278=4d60a78e-b39b-420e-b830-bc0f3f4fdde283=159758166355=BTC-USD270=3.53271=0.6232294660=20250411-02:00:02.83442637=980cf7e4-9009-4da3-95c9-d536773e7cea5797=210=168
20250411-02:00:02.956102000 : 8=FIXT.1.19=28135=X49=Coinbase56=24ab46f784d1b20db435b852086e325034=25750=TEST52=20250411-02:00:02.835950369=45262=1c4ca071-c1b7-4b32-a10d-aab5f1327380268=1279=2269=1278=980cf7e4-9009-4da3-95c9-d536773e7cea83=159758166455=BTC-USD271=0.0000000060=20250411-02:00:02.83442658=FILLED10=076
20250411-02:00:03.098253000 : 8=FIXT.1.19=27935=X49=Coinbase56=24ab46f784d1b20db435b852086e325034=25850=TEST52=20250411-02:00:02.978490369=45262=1c4ca071-c1b7-4b32-a10d-aab5f1327380268=1279=0269=083=159758166555=BTC-USD29004=2.208895519560=20250411-02:00:02.97673440=137=54b68582-284d-4169-937b-099dcc4301b610=211
20250411-02:00:03.098923000 : 8=FIXT.1.19=32735=X49=Coinbase56=24ab46f784d1b20db435b852086e325034=25950=TEST52=20250411-02:00:02.978569369=45262=1c4ca071-c1b7-4b32-a10d-aab5f1327380268=1279=0269=2278=c5b88ea9-605d-4595-ac52-f7c3f08523ba83=159758166655=BTC-USD270=3.55271=0.6222240960=20250411-02:00:02.97673437=54b68582-284d-4169-937b-099dcc4301b65797=110=109
20250411-02:00:03.099089000 : 8=FIXT.1.19=26635=X49=Coinbase56=24ab46f784d1b20db435b852086e325034=26050=TEST52=20250411-02:00:02.978571369=45262=1c4ca071-c1b7-4b32-a10d-aab5f1327380268=1279=2269=0278=54b68582-284d-4169-937b-099dcc4301b683=159758166755=BTC-USD60=20250411-02:00:02.97673458=FILLED10=218
20250411-02:00:03.125669000 : 8=FIXT.1.19=27535=X49=Coinbase56=24ab46f784d1b20db435b852086e325034=26150=TEST52=20250411-02:00:03.006513369=45262=1c4ca071-c1b7-4b32-a10d-aab5f1327380268=1279=0269=183=159758166855=BTC-USD271=0.6232294660=20250411-02:00:03.00528340=137=772d8669-0807-483e-90c9-2fd56266512810=125
20250411-02:00:03.126078000 : 8=FIXT.1.19=32735=X49=Coinbase56=24ab46f784d1b20db435b852086e325034=26250=TEST52=20250411-02:00:03.006569369=45262=1c4ca071-c1b7-4b32-a10d-aab5f1327380268=1279=0269=2278=4d60a78e-b39b-420e-b830-bc0f3f4fdde283=159758166955=BTC-USD270=3.53271=0.6232294660=20250411-02:00:03.00528337=772d8669-0807-483e-90c9-2fd5626651285797=210=125
20250411-02:00:03.126273000 : 8=FIXT.1.19=28135=X49=Coinbase56=24ab46f784d1b20db435b852086e325034=26350=TEST52=20250411-02:00:03.006577369=45262=1c4ca071-c1b7-4b32-a10d-aab5f1327380268=1279=2269=1278=772d8669-0807-483e-90c9-2fd56266512883=159758167055=BTC-USD271=0.0000000060=20250411-02:00:03.00528358=FILLED10=030
20250411-02:00:03.213819000 : 8=FIXT.1.19=27935=X49=Coinbase56=24ab46f784d1b20db435b852086e325034=26450=TEST52=20250411-02:00:03.094744369=45262=1c4ca071-c1b7-4b32-a10d-aab5f1327380268=1279=0269=083=159758167155=BTC-USD29004=2.208895519560=20250411-02:00:03.09270140=137=4795e7fa-beb6-434c-ba18-93fdece0eb1310=089
20250411-02:00:03.214094000 : 8=FIXT.1.19=32735=X49=Coinbase56=24ab46f784d1b20db435b852086e325034=26550=TEST52=20250411-02:00:03.094749369=45262=1c4ca071-c1b7-4b32-a10d-aab5f1327380268=1279=0269=2278=c5b88ea9-605d-4595-ac52-f7c3f08523ba83=159758167255=BTC-USD270=3.55271=0.6222240960=20250411-02:00:03.09270137=4795e7fa-beb6-434c-ba18-93fdece0eb135797=110=241
20250411-02:00:03.214223000 : 8=FIXT.1.19=26635=X49=Coinbase56=24ab46f784d1b20db435b852086e325034=26650=TEST52=20250411-02:00:03.094751369=45262=1c4ca071-c1b7-4b32-a10d-aab5f1327380268=1279=2269=0278=4795e7fa-beb6-434c-ba18-93fdece0eb1383=159758167355=BTC-USD60=20250411-02:00:03.09270158=FILLED10=103
20250411-02:00:03.242442000 : 8=FIXT.1.19=27535=X49=Coinbase56=24ab46f784d1b20db435b852086e325034=26750=TEST52=20250411-02:00:03.122058369=45262=1c4ca071-c1b7-4b32-a10d-aab5f1327380268=1279=0269=183=159758167455=BTC-USD271=0.6232294660=20250411-02:00:03.12038740=137=923b03db-df50-4d5f-a864-12bc12dcf47710=224
20250411-02:00:03.242683000 : 8=FIXT.1.19=32735=X49=Coinbase56=24ab46f784d1b20db435b852086e325034=26850=TEST52=20250411-02:00:03.122063369=45262=1c4ca071-c1b7-4b32-a10d-aab5f1327380268=1279=0269=2278=4d60a78e-b39b-420e-b830-bc0f3f4fdde283=159758167555=BTC-USD270=3.53271=0.6232294660=20250411-02:00:03.12038737=923b03db-df50-4d5f-a864-12bc12dcf4775797=210=209
20250411-02:00:03.242806000 : 8=FIXT.1.19=28135=X49=Coinbase56=24ab46f784d1b20db435b852086e325034=26950=TEST52=20250411-02:00:03.122067369=45262=1c4ca071-c1b7-4b32-a10d-aab5f1327380268=1279=2269=1278=923b03db-df50-4d5f-a864-12bc12dcf47783=159758167655=BTC-USD271=0.0000000060=20250411-02:00:03.12038758=FILLED10=128
20250411-02:00:03.442137000 : 8=FIXT.1.19=27935=X49=Coinbase56=24ab46f784d1b20db435b852086e325034=27050=TEST52=20250411-02:00:03.321932369=45262=1c4ca071-c1b7-4b32-a10d-aab5f1327380268=1279=0269=083=159758167755=BTC-USD29004=2.208895519560=20250411-02:00:03.32074740=137=1a5bba3f-2e22-43e6-a5fa-707a32f7173310=131
20250411-02:00:03.443173000 : 8=FIXT.1.19=32735=X49=Coinbase56=24ab46f784d1b20db435b852086e325034=27150=TEST52=20250411-02:00:03.321942369=45262=1c4ca071-c1b7-4b32-a10d-aab5f1327380268=1279=0269=2278=c5b88ea9-605d-4595-ac52-f7c3f08523ba83=159758167855=BTC-USD270=3.55271=0.6222240960=20250411-02:00:03.32074737=1a5bba3f-2e22-43e6-a5fa-707a32f717335797=110=023
20250411-02:00:03.443522000 : 8=FIXT.1.19=26635=X49=Coinbase56=24ab46f784d1b20db435b852086e325034=27250=TEST52=20250411-02:00:03.321996369=45262=1c4ca071-c1b7-4b32-a10d-aab5f1327380268=1279=2269=0278=1a5bba3f-2e22-43e6-a5fa-707a32f7173383=159758167955=BTC-USD60=20250411-02:00:03.32074758=FILLED10=157
20250411-02:00:03.468923000 : 8=FIXT.1.19=27535=X49=Coinbase56=24ab46f784d1b20db435b852086e325034=27350=TEST52=20250411-02:00:03.350145369=45262=1c4ca071-c1b7-4b32-a10d-aab5f1327380268=1279=0269=183=159758168055=BTC-USD271=0.6232294660=20250411-02:00:03.34881440=137=37bff501-115d-4b9c-9f3e-1894df29673710=109
20250411-02:00:03.469445000 : 8=FIXT.1.19=32735=X49=Coinbase56=24ab46f784d1b20db435b852086e325034=27450=TEST52=20250411-02:00:03.350204369=45262=1c4ca071-c1b7-4b32-a10d-aab5f1327380268=1279=0269=2278=4d60a78e-b39b-420e-b830-bc0f3f4fdde283=159758168155=BTC-USD270=3.53271=0.6232294660=20250411-02:00:03.34881437=37bff501-115d-4b9c-9f3e-1894df2967375797=210=094
20250411-02:00:03.469630000 : 8=FIXT.1.19=28135=X49=Coinbase56=24ab46f784d1b20db435b852086e325034=27550=TEST52=20250411-02:00:03.350211369=45262=1c4ca071-c1b7-4b32-a10d-aab5f1327380268=1279=2269=1278=37bff501-115d-4b9c-9f3e-1894df29673783=159758168255=BTC-USD271=0.0000000060=20250411-02:00:03.34881458=FILLED10=007
20250411-02:00:04.246110000 : 8=FIXT.1.19=28435=X49=Coinbase56=24ab46f784d1b20db435b852086e325034=27650=TEST52=20250411-02:00:04.124451369=45262=1c4ca071-c1b7-4b32-a10d-aab5f1327380268=1279=0269=183=159758168355=BTC-USD270=3.19271=0.6232294660=20250411-02:00:04.12315140=237=d1daf2a9-ff74-4829-9ed1-03a1d65d493a10=138
20250411-02:00:04.252633000 : 8=FIXT.1.19=32735=X49=Coinbase56=24ab46f784d1b20db435b852086e325034=27750=TEST52=20250411-02:00:04.124461369=45262=1c4ca071-c1b7-4b32-a10d-aab5f1327380268=1279=0269=2278=4d60a78e-b39b-420e-b830-bc0f3f4fdde283=159758168455=BTC-USD270=3.53271=0.6232294660=20250411-02:00:04.12315137=d1daf2a9-ff74-4829-9ed1-03a1d65d493a5797=210=221
20250411-02:00:04.253831000 : 8=FIXT.1.19=29035=X49=Coinbase56=24ab46f784d1b20db435b852086e325034=27850=TEST52=20250411-02:00:04.124464369=45262=1c4ca071-c1b7-4b32-a10d-aab5f1327380268=1279=2269=1278=d1daf2a9-ff74-4829-9ed1-03a1d65d493a83=159758168555=BTC-USD270=3.19271=0.0000000060=20250411-02:00:04.12315158=FILLED10=045
20250411-02:00:04.307063000 : 8=FIXT.1.19=28435=X49=Coinbase56=24ab46f784d1b20db435b852086e325034=27950=TEST52=20250411-02:00:04.180072369=45262=1c4ca071-c1b7-4b32-a10d-aab5f1327380268=1279=0269=083=159758168655=BTC-USD270=3.75271=0.6232294660=20250411-02:00:04.17798440=237=1b1c4708-ff6c-4ca7-a211-f900bbc0cfbb10=025
20250411-02:00:04.308660000 : 8=FIXT.1.19=8435=534=4649=24ab46f784d1b20db435b852086e325052=20250411-02:00:04.30856=Coinbase10=157
20250411-02:00:04.308868000 : 8=FIXT.1.19=32735=X49=Coinbase56=24ab46f784d1b20db435b852086e325034=28050=TEST52=20250411-02:00:04.180080369=45262=1c4ca071-c1b7-4b32-a10d-aab5f1327380268=1279=0269=2278=c5b88ea9-605d-4595-ac52-f7c3f08523ba83=159758168755=BTC-USD270=3.55271=0.6232294660=20250411-02:00:04.17798437=1b1c4708-ff6c-4ca7-a211-f900bbc0cfbb5797=110=225
20250411-02:00:04.309177000 : 8=FIXT.1.19=29035=X49=Coinbase56=24ab46f784d1b20db435b852086e325034=28150=TEST52=20250411-02:00:04.180084369=45262=1c4ca071-c1b7-4b32-a10d-aab5f1327380268=1279=2269=0278=1b1c4708-ff6c-4ca7-a211-f900bbc0cfbb83=159758168855=BTC-USD270=3.75271=0.0000000060=20250411-02:00:04.17798458=FILLED10=178
20250411-02:00:04.311440000 : 8=FIXT.1.19=27935=X49=Coinbase56=24ab46f784d1b20db435b852086e325034=28250=TEST52=20250411-02:00:04.180167369=45262=1c4ca071-c1b7-4b32-a10d-aab5f1327380268=1279=0269=083=159758168955=BTC-USD29004=2.208895519560=20250411-02:00:04.17799140=137=495d1def-ac22-4b58-81e3-9968292b314810=044
20250411-02:00:04.311675000 : 8=FIXT.1.19=32735=X49=Coinbase56=24ab46f784d1b20db435b852086e325034=28350=TEST52=20250411-02:00:04.180178369=45262=1c4ca071-c1b7-4b32-a10d-aab5f1327380268=1279=0269=2278=c5b88ea9-605d-4595-ac52-f7c3f08523ba83=159758169055=BTC-USD270=3.55271=0.6222240960=20250411-02:00:04.17799137=495d1def-ac22-4b58-81e3-9968292b31485797=110=184
20250411-02:00:04.312077000 : 8=FIXT.1.19=26635=X49=Coinbase56=24ab46f784d1b20db435b852086e325034=28450=TEST52=20250411-02:00:04.180181369=45262=1c4ca071-c1b7-4b32-a10d-aab5f1327380268=1279=2269=0278=495d1def-ac22-4b58-81e3-9968292b314883=159758169155=BTC-USD60=20250411-02:00:04.17799158=FILLED10=047
20250411-02:00:04.328989000 : 8=FIXT.1.19=27535=X49=Coinbase56=24ab46f784d1b20db435b852086e325034=28550=TEST52=20250411-02:00:04.208250369=45262=1c4ca071-c1b7-4b32-a10d-aab5f1327380268=1279=0269=183=159758169255=BTC-USD271=0.6232294660=20250411-02:00:04.20624540=137=e3038406-a6f1-4e25-8bc4-705c7aa55c7a10=128
20250411-02:00:04.329495000 : 8=FIXT.1.19=32735=X49=Coinbase56=24ab46f784d1b20db435b852086e325034=28650=TEST52=20250411-02:00:04.208257369=45262=1c4ca071-c1b7-4b32-a10d-aab5f1327380268=1279=0269=2278=4d60a78e-b39b-420e-b830-bc0f3f4fdde283=159758169355=BTC-USD270=3.53271=0.6232294660=20250411-02:00:04.20624537=e3038406-a6f1-4e25-8bc4-705c7aa55c7a5797=210=124
20250411-02:00:04.329711000 : 8=FIXT.1.19=28135=X49=Coinbase56=24ab46f784d1b20db435b852086e325034=28750=TEST52=20250411-02:00:04.208259369=45262=1c4ca071-c1b7-4b32-a10d-aab5f1327380268=1279=2269=1278=e3038406-a6f1-4e25-8bc4-705c7aa55c7a83=159758169455=BTC-USD271=0.0000000060=20250411-02:00:04.20624558=FILLED10=041
20250411-02:00:04.434780000 : 8=FIXT.1.19=28435=X49=Coinbase56=24ab46f784d1b20db435b852086e325034=28850=TEST52=20250411-02:00:04.314189369=45262=1c4ca071-c1b7-4b32-a10d-aab5f1327380268=1279=0269=083=159758169555=BTC-USD270=3.46271=0.6232294660=20250411-02:00:04.31228140=237=419f53df-b462-4085-8a46-f2ef475be2f310=067
20250411-02:00:04.435191000 : 8=FIXT.1.19=28035=X49=Coinbase56=24ab46f784d1b20db435b852086e325034=28950=TEST52=20250411-02:00:04.314194369=45262=1c4ca071-c1b7-4b32-a10d-aab5f1327380268=1279=0269=0278=419f53df-b462-4085-8a46-f2ef475be2f383=159758169655=BTC-USD270=3.46271=0.6232294660=20250411-02:00:04.31228110=160
20250411-02:00:20.649719000 : 8=FIXT.1.19=21535=A34=149=24ab46f784d1b20db435b852086e325052=20250411-02:00:20.64356=Coinbase95=4496=cYDnZXUZwQ89l3HDXG25Zzh81H6Uv/uvUMs1jUt7VQk=98=0108=30141=Y553=24ab46f784d1b20db435b852086e3250554=akmwnltyfgb1137=910=168
20250411-02:00:20.906998000 : 8=FIXT.1.19=12535=A49=Coinbase56=24ab46f784d1b20db435b852086e325034=150=TEST52=20250411-02:00:20.788266369=198=0108=30141=Y1137=910=193
20250411-02:00:21.936056000 : 8=FIXT.1.19=17835=V34=249=24ab46f784d1b20db435b852086e325052=20250411-02:00:21.93456=Coinbase1128=9146=155=BTC-USD262=38b76e38-5a27-4fa7-8aa2-3c519fd2251e263=1264=0267=2269=0269=110=008
20250411-02:00:23.728566000 : 8=FIXT.1.19=28135=X49=Coinbase56=24ab46f784d1b20db435b852086e325034=250=TEST52=20250411-02:00:23.611104369=2262=38b76e38-5a27-4fa7-8aa2-3c519fd2251e268=1279=0269=183=159758204755=BTC-USD270=3.31271=0.6232294660=20250411-02:00:23.60968640=237=bebf049c-16b5-4ba9-b2e6-bbd8c2820b3c10=101
20250411-02:00:23.729700000 : 8=FIXT.1.19=32435=X49=Coinbase56=24ab46f784d1b20db435b852086e325034=350=TEST52=20250411-02:00:23.611157369=2262=38b76e38-5a27-4fa7-8aa2-3c519fd2251e268=1279=0269=2278=4d60a78e-b39b-420e-b830-bc0f3f4fdde283=159758204855=BTC-USD270=3.53271=0.6232294660=20250411-02:00:23.60968637=bebf049c-16b5-4ba9-b2e6-bbd8c2820b3c5797=210=197
20250411-02:00:23.731944000 : 8=FIXT.1.19=28735=X49=Coinbase56=24ab46f784d1b20db435b852086e325034=450=TEST52=20250411-02:00:23.611162369=2262=38b76e38-5a27-4fa7-8aa2-3c519fd2251e268=1279=2269=1278=bebf049c-16b5-4ba9-b2e6-bbd8c2820b3c83=159758204955=BTC-USD270=3.31271=0.0000000060=20250411-02:00:23.60968658=FILLED10=017
20250411-02:00:23.782599000 : 8=FIXT.1.19=30035=X49=Coinbase56=24ab46f784d1b20db435b852086e325034=550=TEST52=20250411-02:00:23.666163369=2262=38b76e38-5a27-4fa7-8aa2-3c519fd2251e268=1279=0269=083=159758205055=BTC-USD270=3.82271=0.6700874929004=2.378810589560=20250411-02:00:23.66493440=237=9b88fe6d-fb2f-4204-a22d-34a79e9c41b210=167
20250411-02:00:23.782828000 : 8=FIXT.1.19=32435=X49=Coinbase56=24ab46f784d1b20db435b852086e325034=650=TEST52=20250411-02:00:23.666169369=2262=38b76e38-5a27-4fa7-8aa2-3c519fd2251e268=1279=0269=2278=c5b88ea9-605d-4595-ac52-f7c3f08523ba83=159758205155=BTC-USD270=3.55271=0.6700874960=20250411-02:00:23.66493437=9b88fe6d-fb2f-4204-a22d-34a79e9c41b25797=110=214
20250411-02:00:23.782956000 : 8=FIXT.1.19=27835=X49=Coinbase56=24ab46f784d1b20db435b852086e325034=750=TEST52=20250411-02:00:23.666173369=2262=38b76e38-5a27-4fa7-8aa2-3c519fd2251e268=1279=2269=0278=9b88fe6d-fb2f-4204-a22d-34a79e9c41b283=159758205255=BTC-USD270=3.82271=060=20250411-02:00:23.66493458=FILLED10=240
20250411-02:00:25.326539000 : 8=FIXT.1.19=28135=X49=Coinbase56=24ab46f784d1b20db435b852086e325034=850=TEST52=20250411-02:00:25.210655369=2262=38b76e38-5a27-4fa7-8aa2-3c519fd2251e268=1279=0269=083=159758205355=BTC-USD270=3.81271=0.6197183160=20250411-02:00:25.20861040=237=418886e8-1e5f-4a84-a994-4fa886d2540110=013
20250411-02:00:25.327175000 : 8=FIXT.1.19=32435=X49=Coinbase56=24ab46f784d1b20db435b852086e325034=950=TEST52=20250411-02:00:25.210660369=2262=38b76e38-5a27-4fa7-8aa2-3c519fd2251e268=1279=0269=2278=c5b88ea9-605d-4595-ac52-f7c3f08523ba83=159758205455=BTC-USD270=3.55271=0.6197183160=20250411-02:00:25.20861037=418886e8-1e5f-4a84-a994-4fa886d254015797=110=222
20250411-02:00:25.327397000 : 8=FIXT.1.19=28835=X49=Coinbase56=24ab46f784d1b20db435b852086e325034=1050=TEST52=20250411-02:00:25.210665369=2262=38b76e38-5a27-4fa7-8aa2-3c519fd2251e268=1279=2269=0278=418886e8-1e5f-4a84-a994-4fa886d2540183=159758205555=BTC-USD270=3.81271=0.0000000060=20250411-02:00:25.20861058=FILLED10=220
20250411-02:00:25.380620000 : 8=FIXT.1.19=28235=X49=Coinbase56=24ab46f784d1b20db435b852086e325034=1150=TEST52=20250411-02:00:25.264996369=2262=38b76e38-5a27-4fa7-8aa2-3c519fd2251e268=1279=0269=183=159758205655=BTC-USD270=3.26271=0.6197183160=20250411-02:00:25.26381240=237=72f1fbd2-f5e2-47b1-9c4a-6bfcd072b93010=082
20250411-02:00:25.381150000 : 8=FIXT.1.19=32535=X49=Coinbase56=24ab46f784d1b20db435b852086e325034=1250=TEST52=20250411-02:00:25.265002369=2262=38b76e38-5a27-4fa7-8aa2-3c519fd2251e268=1279=0269=2278=4d60a78e-b39b-420e-b830-bc0f3f4fdde283=159758205755=BTC-USD270=3.53271=0.6197183160=20250411-02:00:25.26381237=72f1fbd2-f5e2-47b1-9c4a-6bfcd072b9305797=210=145
20250411-02:00:25.382338000 : 8=FIXT.1.19=28835=X49=Coinbase56=24ab46f784d1b20db435b852086e325034=1350=TEST52=20250411-02:00:25.265005369=2262=38b76e38-5a27-4fa7-8aa2-3c519fd2251e268=1279=2269=1278=72f1fbd2-f5e2-47b1-9c4a-6bfcd072b93083=159758205855=BTC-USD270=3.26271=0.0000000060=20250411-02:00:25.26381258=FILLED10=230
20250411-02:00:26.831928000 : 8=FIXT.1.19=28235=X49=Coinbase56=24ab46f784d1b20db435b852086e325034=1450=TEST52=20250411-02:00:26.695374369=2262=38b76e38-5a27-4fa7-8aa2-3c519fd2251e268=1279=0269=083=159758205955=BTC-USD270=3.87271=0.6232294660=20250411-02:00:26.69411740=237=e0d3044e-9f03-47a9-8ee1-6dbd036ae44410=005
20250411-02:00:26.833333000 : 8=FIXT.1.19=32535=X49=Coinbase56=24ab46f784d1b20db435b852086e325034=1550=TEST52=20250411-02:00:26.695382369=2262=38b76e38-5a27-4fa7-8aa2-3c519fd2251e268=1279=0269=2278=c5b88ea9-605d-4595-ac52-f7c3f08523ba83=159758206055=BTC-USD270=3.55271=0.6232294660=20250411-02:00:26.69411737=e0d3044e-9f03-47a9-8ee1-6dbd036ae4445797=110=202
20250411-02:00:26.833557000 : 8=FIXT.1.19=28835=X49=Coinbase56=24ab46f784d1b20db435b852086e325034=1650=TEST52=20250411-02:00:26.695386369=2262=38b76e38-5a27-4fa7-8aa2-3c519fd2251e268=1279=2269=0278=e0d3044e-9f03-47a9-8ee1-6dbd036ae44483=159758206155=BTC-USD270=3.87271=0.0000000060=20250411-02:00:26.69411758=FILLED10=167
20250411-02:00:26.868351000 : 8=FIXT.1.19=28235=X49=Coinbase56=24ab46f784d1b20db435b852086e325034=1750=TEST52=20250411-02:00:26.750881369=2262=38b76e38-5a27-4fa7-8aa2-3c519fd2251e268=1279=0269=183=159758206255=BTC-USD270=3.25271=0.6232294660=20250411-02:00:26.74948440=237=9f275026-bf56-45fa-894a-829bfef969be10=035
20250411-02:00:26.869082000 : 8=FIXT.1.19=32535=X49=Coinbase56=24ab46f784d1b20db435b852086e325034=1850=TEST52=20250411-02:00:26.750886369=2262=38b76e38-5a27-4fa7-8aa2-3c519fd2251e268=1279=0269=2278=4d60a78e-b39b-420e-b830-bc0f3f4fdde283=159758206355=BTC-USD270=3.53271=0.6232294660=20250411-02:00:26.74948437=9f275026-bf56-45fa-894a-829bfef969be5797=210=125
20250411-02:00:26.870853000 : 8=FIXT.1.19=28835=X49=Coinbase56=24ab46f784d1b20db435b852086e325034=1950=TEST52=20250411-02:00:26.750890369=2262=38b76e38-5a27-4fa7-8aa2-3c519fd2251e268=1279=2269=1278=9f275026-bf56-45fa-894a-829bfef969be83=159758206455=BTC-USD270=3.25271=0.0000000060=20250411-02:00:26.74948458=FILLED10=203
20250411-02:00:26.927081000 : 8=FIXT.1.19=28235=X49=Coinbase56=24ab46f784d1b20db435b852086e325034=2050=TEST52=20250411-02:00:26.810821369=2262=38b76e38-5a27-4fa7-8aa2-3c519fd2251e268=1279=0269=083=159758206555=BTC-USD270=3.86271=0.6232294660=20250411-02:00:26.80955340=237=12b72626-bcf3-43b1-9129-54c9c8f1d6e710=154
20250411-02:00:26.927589000 : 8=FIXT.1.19=32535=X49=Coinbase56=24ab46f784d1b20db435b852086e325034=2150=TEST52=20250411-02:00:26.810829369=2262=38b76e38-5a27-4fa7-8aa2-3c519fd2251e268=1279=0269=2278=c5b88ea9-605d-4595-ac52-f7c3f08523ba83=159758206655=BTC-USD270=3.55271=0.6232294660=20250411-02:00:26.80955337=12b72626-bcf3-43b1-9129-54c9c8f1d6e75797=110=114
20250411-02:00:26.927922000 : 8=FIXT.1.19=28835=X49=Coinbase56=24ab46f784d1b20db435b852086e325034=2250=TEST52=20250411-02:00:26.810833369=2262=38b76e38-5a27-4fa7-8aa2-3c519fd2251e268=1279=2269=0278=12b72626-bcf3-43b1-9129-54c9c8f1d6e783=159758206755=BTC-USD270=3.86271=0.0000000060=20250411-02:00:26.80955358=FILLED10=069
20250411-02:00:26.982127000 : 8=FIXT.1.19=28235=X49=Coinbase56=24ab46f784d1b20db435b852086e325034=2350=TEST52=20250411-02:00:26.866643369=2262=38b76e38-5a27-4fa7-8aa2-3c519fd2251e268=1279=0269=183=159758206855=BTC-USD270=3.23271=0.6232294660=20250411-02:00:26.86466940=237=33dc5bfe-858d-46de-a074-ccc0affd457c10=252
20250411-02:00:26.982638000 : 8=FIXT.1.19=32535=X49=Coinbase56=24ab46f784d1b20db435b852086e325034=2450=TEST52=20250411-02:00:26.866650369=2262=38b76e38-5a27-4fa7-8aa2-3c519fd2251e268=1279=0269=2278=4d60a78e-b39b-420e-b830-bc0f3f4fdde283=159758206955=BTC-USD270=3.53271=0.6232294660=20250411-02:00:26.86466937=33dc5bfe-858d-46de-a074-ccc0affd457c5797=210=081
20250411-02:00:26.983734000 : 8=FIXT.1.19=28835=X49=Coinbase56=24ab46f784d1b20db435b852086e325034=2550=TEST52=20250411-02:00:26.866654369=2262=38b76e38-5a27-4fa7-8aa2-3c519fd2251e268=1279=2269=1278=33dc5bfe-858d-46de-a074-ccc0affd457c83=159758207055=BTC-USD270=3.23271=0.0000000060=20250411-02:00:26.86466958=FILLED10=157
20250411-02:00:26.996430000 : 8=FIXT.1.19=29035=X49=Coinbase56=24ab46f784d1b20db435b852086e325034=2650=TEST52=20250411-02:00:26.878716369=2262=38b76e38-5a27-4fa7-8aa2-3c519fd2251e268=1279=2269=0278=65110251-0da3-4a57-bb61-db1ad80b91a983=159758207155=BTC-USD270=3.51271=0.6197183160=20250411-02:00:26.87715658=CANCELED10=247
20250411-02:00:27.178609000 : 8=FIXT.1.19=91735=W49=Coinbase56=24ab46f784d1b20db435b852086e325034=2750=TEST52=20250411-02:00:27.059432369=2262=38b76e38-5a27-4fa7-8aa2-3c519fd2251e83=1597582071893=N55=BTC-USD1682=full_trading268=10269=0278=4d60a78e-b39b-420e-b830-bc0f3f4fdde2270=3.53271=255597.27345358269=0278=9d9353ab-229f-423a-89a3-c52a46543bc9270=3.53271=18127.30103418269=0278=fdbc7e1d-ccf4-462b-8ff6-948d33767188270=3.51271=0.62322946269=0278=f5fc5e68-a52c-44d3-87ef-3785312f4782270=3.48271=0.29310888269=0278=dcccb470-c535-433a-9198-4e2b4c26d99d270=3.47271=0.29311495269=0278=f05d9766-970d-44ca-aa4d-e8b2720bbda8270=3.46271=0.29026870269=0278=419f53df-b462-4085-8a46-f2ef475be2f3270=3.46271=0.62322946269=0278=2c4d7d5a-33aa-4058-b546-480b6a2168a4270=3.44271=0.29828577269=0278=37dbcf16-0b3d-4f67-bc90-e36268b99e0e270=3.42271=0.30270947269=0278=be5191de-eb81-4170-aece-43cb79ec15b8270=3.42271=0.6232294610=181
20250411-02:00:27.181653000 : 8=FIXT.1.19=14035=334=349=24ab46f784d1b20db435b852086e325052=20250411-02:00:27.18156=Coinbase45=2758=Tag appears more than once371=269372=W373=1310=193
20250411-02:00:27.181848000 : 8=FIXT.1.19=90835=W49=Coinbase56=24ab46f784d1b20db435b852086e325034=2850=TEST52=20250411-02:00:27.059671369=2262=38b76e38-5a27-4fa7-8aa2-3c519fd2251e83=1597582071893=N55=BTC-USD1682=full_trading268=10269=0278=4c63c0b7-30e0-4ef1-931f-0090359f978e270=3.41271=0.32158962269=0278=d6b4aa4e-d588-4c96-83aa-8e8d8accb1a4270=3.41271=0.30121104269=0278=e8b3d8da-1663-413c-b7fb-6aba23b01440270=3.39271=0.31006477269=0278=bcbe17c3-9059-4c38-8ab8-8e78f1ef9062270=3.38271=0.32617981269=0278=b9eb1261-8bf8-4e3c-af53-33aa2b72067b270=3.38271=0.62322946269=0278=57bb77fd-337f-49bc-a56f-a4e2dff851ee270=3.37271=0.31071676269=0278=b7a2004c-41b5-42c2-80e8-60bb80b63a11270=3.36271=0.62322946269=0278=ded4b51d-349f-4726-8379-6761a3576bb6270=3.33271=0.31560513269=0278=ff7aff09-38de-47ac-a3cb-9beacb0b9ad8270=3.33271=0.30682342269=0278=d1da558a-e9d2-4e11-b26e-1eb80a1a34c5270=3.32271=0.3170068510=005
20250411-02:00:27.182612000 : 8=FIXT.1.19=14035=334=449=24ab46f784d1b20db435b852086e325052=20250411-02:00:27.18256=Coinbase45=2858=Tag appears more than once371=269372=W373=1310=196
20250411-02:00:27.182697000 : 8=FIXT.1.19=90835=W49=Coinbase56=24ab46f784d1b20db435b852086e325034=2950=TEST52=20250411-02:00:27.059921369=2262=38b76e38-5a27-4fa7-8aa2-3c519fd2251e83=1597582071893=N55=BTC-USD1682=full_trading268=10269=0278=9ee34527-d4d8-4659-b2ea-cdff3dc4a8fa270=3.32271=0.32181951269=0278=7abf2220-0421-460f-9dbb-14c41564e41a270=3.32271=0.31308436269=0278=69634ec5-f71a-4990-b56d-13c3069a455a270=3.31271=0.32329458269=0278=2f333c17-a386-4d52-8ff1-eadcb99bc22f270=3.31271=0.31999220269=0278=f02efc37-0b1e-470b-99ef-e31012887d73270=3.30271=0.32771570269=0278=6d430950-8078-4987-8995-e581564e368d270=3.29271=0.30702763269=0278=841f895a-cd2d-4082-9a37-b50fc19e35bf270=3.28271=0.32610801269=0278=3cf93093-e42b-4c24-95ea-c367d96427fe270=3.27271=0.33588654269=0278=f29c94bc-d1c2-4145-97b0-ecb77d81a8bf270=3.27271=0.31661408269=0278=d208c4fb-56c6-4911-85c9-77b68a5ba6ab270=3.25271=0.3096162310=215
20250411-02:00:27.183338000 : 8=FIXT.1.19=14035=334=549=24ab46f784d1b20db435b852086e325052=20250411-02:00:27.18356=Coinbase45=2958=Tag appears more than once371=269372=W373=1310=199
20250411-02:00:27.183415000 : 8=FIXT.1.19=90835=W49=Coinbase56=24ab46f784d1b20db435b852086e325034=3050=TEST52=20250411-02:00:27.060170369=2262=38b76e38-5a27-4fa7-8aa2-3c519fd2251e83=1597582071893=N55=BTC-USD1682=full_trading268=10269=0278=e88796ff-68c8-4463-914b-46e09fbaf639270=3.25271=0.33589845269=0278=06f345fb-0292-45fc-8237-9ad1a84b541c270=3.24271=0.31528507269=0278=fa20c2c7-df80-4941-9a9c-a6ef2e579480270=3.23271=0.33432448269=0278=a833d230-a749-4bf4-823e-93adc40b773d270=3.23271=0.31165878269=0278=2abb6e15-b9cd-415b-8c9b-99a61c750310270=3.22271=0.32048714269=0278=ec44a6d8-ae5f-4809-89d7-0f7a3adac547270=3.21271=0.33230954269=0278=9cf61c67-c4fc-4bac-92fd-d4e2b56248aa270=3.21271=0.33583951269=0278=210b2518-bb42-461a-9c7e-b4e04c5ffcc6270=3.21271=0.32669007269=0278=2e3fa1b2-20f1-4694-9be4-322040b75152270=3.21271=0.32907979269=0278=05dd5607-92c9-4296-8cdc-27cdff004dea270=3.21271=0.3277607510=197
20250411-02:00:27.184369000 : 8=FIXT.1.19=14035=334=649=24ab46f784d1b20db435b852086e325052=20250411-02:00:27.18356=Coinbase45=3058=Tag appears more than once371=269372=W373=1310=192
20250411-02:00:27.184503000 : 8=FIXT.1.19=90935=W49=Coinbase56=24ab46f784d1b20db435b852086e325034=3150=TEST52=20250411-02:00:27.060421369=2262=38b76e38-5a27-4fa7-8aa2-3c519fd2251e83=1597582071893=N55=BTC-USD1682=full_trading268=10269=0278=87944de7-a5f1-4033-a3d8-cbc10f3a5232270=3.20271=0.32225170269=0278=30f6bb59-2469-4e6d-8fa5-13666373901f270=3.19271=0.31386496269=0278=6a5d2852-7ddc-456e-acb5-bfadcc0c1360270=3.19271=0.32157390269=0278=5d00d8a2-5aea-4836-ba19-74fe67116df8270=3.18271=0.32651049269=0278=acc71746-3591-4dde-a7e2-c2795d0ad125270=3.17271=0.31577131269=0278=13982796-c2a8-4740-95e2-5aca0fdfd8bb270=3.16271=0.33021170269=0278=9f2f0737-661e-43d7-89f9-959ed5e08306270=3.16271=0.33082075269=0278=7e0e2d14-fa77-4978-8cae-d9660fd13e6d270=3.16271=0.32014975269=0278=82826a7d-848c-4516-a7b6-5ec6881609a8270=2.00271=10.00000000269=0278=590048d5-ee44-49dc-b66d-1a692e055133270=1.94271=0.5154639210=010
20250411-02:00:27.185137000 : 8=FIXT.1.19=14035=334=749=24ab46f784d1b20db435b852086e325052=20250411-02:00:27.18456=Coinbase45=3158=Tag appears more than once371=269372=W373=1310=195
20250411-02:00:27.185225000 : 8=FIXT.1.19=90835=W49=Coinbase56=24ab46f784d1b20db435b852086e325034=3250=TEST52=20250411-02:00:27.060671369=2262=38b76e38-5a27-4fa7-8aa2-3c519fd2251e83=1597582071893=N55=BTC-USD1682=full_trading268=10269=0278=22bdda11-16cd-488b-9fa9-da098dad543e270=1.94271=0.51546392269=0278=d356ef8b-596e-47e7-bf90-cc015b85fc57270=1.93271=0.52331606269=0278=aa8d48bc-97fb-4d00-b923-66d37cc8c66a270=1.93271=0.52331606269=0278=7d51dcb4-a7f8-4cca-b2d0-e902403d1b9f270=1.93271=0.52331606269=0278=f7680950-3af2-4723-a6e4-5cbd528ca900270=1.93271=0.52331606269=0278=fdeff994-4866-47af-9dde-a25947a26606270=1.93271=0.52331606269=0278=65e7e2bb-023d-4936-bb4e-ff7625ba7264270=1.93271=0.52331606269=0278=53732639-572c-4cd5-b61e-e4f534d1d540270=1.93271=0.52331606269=0278=24da8927-1dd1-468b-9437-ff366f5bfa11270=1.93271=0.52331606269=0278=baa5862c-41e8-458c-83d3-c095bb68ed17270=1.93271=0.5233160610=153
20250411-02:00:27.185877000 : 8=FIXT.1.19=14035=334=849=24ab46f784d1b20db435b852086e325052=20250411-02:00:27.18556=Coinbase45=3258=Tag appears more than once371=269372=W373=1310=198
20250411-02:00:27.185981000 : 8=FIXT.1.19=90835=W49=Coinbase56=24ab46f784d1b20db435b852086e325034=3350=TEST52=20250411-02:00:27.060921369=2262=38b76e38-5a27-4fa7-8aa2-3c519fd2251e83=1597582071893=N55=BTC-USD1682=full_trading268=10269=0278=92a3c3e3-7afe-4d02-a0d8-96f512b63bb7270=1.93271=0.52331606269=0278=9d2a564e-f178-4966-9baf-5814a1c1686b270=1.93271=0.52331606269=0278=f9e6b978-87f6-4397-8d82-07cf698c123f270=1.93271=0.52331606269=0278=3e64b388-13d3-441d-b241-aa8dd6fe55e6270=1.93271=0.52331606269=0278=60300433-87b0-4031-bb1e-12cf9d773d3f270=1.93271=0.52331606269=0278=1bdd5f5a-1d99-4eed-af09-c187bcbbd2d8270=1.93271=0.52331606269=0278=4ed6f6b9-77fb-4255-a188-f243dd0cdb3c270=1.93271=0.52331606269=0278=9ad1fc18-5a38-4edb-ac5c-6ac826a8a846270=1.93271=0.52331606269=0278=1c218c8c-baea-4a1f-838e-4a3a94b468e1270=1.93271=0.52331606269=0278=fd70f5e2-d2c9-472a-ab40-a775afafd73d270=1.93271=0.5233160610=197
20250411-02:00:27.187030000 : 8=FIXT.1.19=14035=334=949=24ab46f784d1b20db435b852086e325052=20250411-02:00:27.18656=Coinbase45=3358=Tag appears more than once371=269372=W373=1310=201
20250411-02:00:27.187130000 : 8=FIXT.1.19=90835=W49=Coinbase56=24ab46f784d1b20db435b852086e325034=3450=TEST52=20250411-02:00:27.061171369=2262=38b76e38-5a27-4fa7-8aa2-3c519fd2251e83=1597582071893=N55=BTC-USD1682=full_trading268=10269=0278=96f5e3a5-1c2a-4db6-a3fb-fd1f13d5d559270=1.93271=0.52331606269=0278=4a015a4c-490a-4c40-974f-9dfb7feb335d270=1.93271=0.52331606269=0278=d919363e-2c54-404f-bc0b-063e2f12bec4270=1.93271=0.52331606269=0278=d4636d6c-85c6-4ac9-9afb-70ca636f4ad4270=1.93271=0.52331606269=0278=bda09690-f345-4c33-ae8b-e8c78da11b5a270=1.93271=0.52331606269=0278=1a81ae10-b700-42a0-89a3-7d7a3eea0ebb270=1.93271=0.52331606269=0278=1ace5afa-e550-4abf-a458-52e46e1b54f0270=1.93271=0.52331606269=0278=2332d1c9-67e7-457a-abfe-f5e9a8c2ea05270=1.93271=0.52331606269=0278=6afa1f19-0ec5-49fd-8b74-06a12a6c5ca9270=1.93271=0.52331606269=0278=3fa3413d-c26c-472f-9cc5-da1c48935c63270=1.93271=0.5233160610=174
20250411-02:00:27.187908000 : 8=FIXT.1.19=14135=334=1049=24ab46f784d1b20db435b852086e325052=20250411-02:00:27.18756=Coinbase45=3458=Tag appears more than once371=269372=W373=1310=244
20250411-02:00:27.187998000 : 8=FIXT.1.19=90835=W49=Coinbase56=24ab46f784d1b20db435b852086e325034=3550=TEST52=20250411-02:00:27.061421369=2262=38b76e38-5a27-4fa7-8aa2-3c519fd2251e83=1597582071893=N55=BTC-USD1682=full_trading268=10269=0278=3f9e43c4-2e62-4d51-b4cb-ad207c693331270=1.93271=0.52331606269=0278=29e8bfcf-c764-4f7e-997d-09abf72bbc00270=1.93271=0.52331606269=0278=cf3e8b26-09ae-4dfb-9b84-b12a7e199a5a270=1.93271=0.52331606269=0278=08db3e51-e927-47d3-a9dd-2f887c58dc85270=1.93271=0.52331606269=0278=353ae741-9473-4cc5-9ab7-7e5de8ae55d0270=1.93271=0.52331606269=0278=4d037208-2072-480f-98ac-7be9c24f18f4270=1.93271=0.52331606269=0278=b598f678-da6e-4c01-90ed-d702c42f8a65270=1.93271=0.52331606269=0278=5f69b1a0-b5d1-4715-9be1-9bdf008d97d7270=1.93271=0.52331606269=0278=ef063d15-248a-4eae-97f4-278be5106d80270=1.93271=0.52331606269=0278=f8b20207-84bc-44e9-a2fe-9ad775e2ecb1270=1.93271=0.5233160610=154
20250411-02:00:27.188726000 : 8=FIXT.1.19=14135=334=1149=24ab46f784d1b20db435b852086e325052=20250411-02:00:27.18856=Coinbase45=3558=Tag appears more than once371=269372=W373=1310=247
