20250411-01:51:36.029366000 : 8=FIXT.1.19=35235=W49=Coinbase56=24ab46f784d1b20db435b852086e325034=10350=TEST52=20250411-01:51:35.460374369=2262=b7f6c79a-636c-490b-8bc5-37cb784406ba83=1597570840893=Y55=BTC-USD1682=full_trading268=2269=1278=06df7c57-366d-4d2c-acc2-e6c26d60e9c3270=1000000.00271=1.00000000269=1278=b1c4eb2b-90df-44e0-ae4f-515df4086a9d270=9999999.00271=0.0000100010=122
20250411-01:51:36.030200000 : 8=FIXT.1.19=14235=334=4649=24ab46f784d1b20db435b852086e325052=20250411-01:51:36.02956=Coinbase45=10358=Tag appears more than once371=269372=W373=1310=043
20250411-01:51:36.030342000 : 8=FIXT.1.19=29135=X49=Coinbase56=24ab46f784d1b20db435b852086e325034=10450=TEST52=20250411-01:51:35.614784369=2262=b7f6c79a-636c-490b-8bc5-37cb784406ba268=1279=2269=1278=023b725c-8b27-41a0-a7d8-91dba8c1008c83=159757084155=BTC-USD270=3.66271=0.4800529760=20250411-01:51:35.61306758=CANCELED10=101
20250411-01:51:36.031224000 : 8=FIXT.1.19=28335=X49=Coinbase56=24ab46f784d1b20db435b852086e325034=10550=TEST52=20250411-01:51:35.761433369=9262=b7f6c79a-636c-490b-8bc5-37cb784406ba268=1279=0269=083=159757084255=BTC-USD270=3.72271=0.6232294660=20250411-01:51:35.75935740=237=dee9d951-c9d3-4a40-b83f-02667d36649b10=085
20250411-01:51:36.031755000 : 8=FIXT.1.19=32635=X49=Coinbase56=24ab46f784d1b20db435b852086e325034=10650=TEST52=20250411-01:51:35.761512369=9262=b7f6c79a-636c-490b-8bc5-37cb784406ba268=1279=0269=2278=c5b88ea9-605d-4595-ac52-f7c3f08523ba83=159757084355=BTC-USD270=3.55271=0.6232294660=20250411-01:51:35.75935737=dee9d951-c9d3-4a40-b83f-02667d36649b5797=110=040
20250411-01:51:36.033841000 : 8=FIXT.1.19=28935=X49=Coinbase56=24ab46f784d1b20db435b852086e325034=10750=TEST52=20250411-01:51:35.761566369=9262=b7f6c79a-636c-490b-8bc5-37cb784406ba268=1279=2269=0278=dee9d951-c9d3-4a40-b83f-02667d36649b83=159757084455=BTC-USD270=3.72271=0.0000000060=20250411-01:51:35.75935758=FILLED10=004
20250411-01:51:36.034198000 : 8=FIXT.1.19=28335=X49=Coinbase56=24ab46f784d1b20db435b852086e325034=10850=TEST52=20250411-01:51:35.815581369=9262=b7f6c79a-636c-490b-8bc5-37cb784406ba268=1279=0269=183=159757084555=BTC-USD270=3.35271=0.6232294660=20250411-01:51:35.81391640=237=3252e341-7b91-4546-bb6a-fdfb63e698fd10=130
20250411-01:51:36.035657000 : 8=FIXT.1.19=32635=X49=Coinbase56=24ab46f784d1b20db435b852086e325034=10950=TEST52=20250411-01:51:35.815591369=9262=b7f6c79a-636c-490b-8bc5-37cb784406ba268=1279=0269=2278=4d60a78e-b39b-420e-b830-bc0f3f4fdde283=159757084655=BTC-USD270=3.53271=0.6232294660=20250411-01:51:35.81391637=3252e341-7b91-4546-bb6a-fdfb63e698fd5797=210=215
20250411-01:51:36.038925000 : 8=FIXT.1.19=28935=X49=Coinbase56=24ab46f784d1b20db435b852086e325034=11050=TEST52=20250411-01:51:35.815593369=9262=b7f6c79a-636c-490b-8bc5-37cb784406ba268=1279=2269=1278=3252e341-7b91-4546-bb6a-fdfb63e698fd83=159757084755=BTC-USD270=3.35271=0.0000000060=20250411-01:51:35.81391658=FILLED10=036
20250411-01:51:36.474030000 : 8=FIXT.1.19=28435=X49=Coinbase56=24ab46f784d1b20db435b852086e325034=11150=TEST52=20250411-01:51:36.332576369=46262=b7f6c79a-636c-490b-8bc5-37cb784406ba268=1279=0269=183=159757084855=BTC-USD270=3.18271=0.6232294660=20250411-01:51:36.33145440=237=f3ffd460-a7fe-4c14-9ecf-dda20047771810=005
20250411-01:51:36.475740000 : 8=FIXT.1.19=32735=X49=Coinbase56=24ab46f784d1b20db435b852086e325034=11250=TEST52=20250411-01:51:36.332587369=46262=b7f6c79a-636c-490b-8bc5-37cb784406ba268=1279=0269=2278=4d60a78e-b39b-420e-b830-bc0f3f4fdde283=159757084955=BTC-USD270=3.53271=0.6232294660=20250411-01:51:36.33145437=f3ffd460-a7fe-4c14-9ecf-dda2004777185797=210=090
20250411-01:51:36.476763000 : 8=FIXT.1.19=29035=X49=Coinbase56=24ab46f784d1b20db435b852086e325034=11350=TEST52=20250411-01:51:36.332590369=46262=b7f6c79a-636c-490b-8bc5-37cb784406ba268=1279=2269=1278=f3ffd460-a7fe-4c14-9ecf-dda20047771883=159757085055=BTC-USD270=3.18271=0.0000000060=20250411-01:51:36.33145458=FILLED10=151
20250411-01:51:37.528742000 : 8=FIXT.1.19=28435=X49=Coinbase56=24ab46f784d1b20db435b852086e325034=11450=TEST52=20250411-01:51:37.332582369=46262=b7f6c79a-636c-490b-8bc5-37cb784406ba268=1279=0269=083=159757085155=BTC-USD270=3.88271=0.6232294660=20250411-01:51:37.33118040=237=c38458c3-313e-47d4-a7bc-0ee66abc555110=154
20250411-01:51:37.529220000 : 8=FIXT.1.19=32735=X49=Coinbase56=24ab46f784d1b20db435b852086e325034=11550=TEST52=20250411-01:51:37.332592369=46262=b7f6c79a-636c-490b-8bc5-37cb784406ba268=1279=0269=2278=c5b88ea9-605d-4595-ac52-f7c3f08523ba83=159757085255=BTC-USD270=3.55271=0.6232294660=20250411-01:51:37.33118037=c38458c3-313e-47d4-a7bc-0ee66abc55515797=110=105
20250411-01:51:37.531485000 : 8=FIXT.1.19=29035=X49=Coinbase56=24ab46f784d1b20db435b852086e325034=11650=TEST52=20250411-01:51:37.332596369=46262=b7f6c79a-636c-490b-8bc5-37cb784406ba268=1279=2269=0278=c38458c3-313e-47d4-a7bc-0ee66abc555183=159757085355=BTC-USD270=3.88271=0.0000000060=20250411-01:51:37.33118058=FILLED10=062
20250411-01:51:37.531769000 : 8=FIXT.1.19=28435=X49=Coinbase56=24ab46f784d1b20db435b852086e325034=11750=TEST52=20250411-01:51:37.360833369=46262=b7f6c79a-636c-490b-8bc5-37cb784406ba268=1279=0269=183=159757085455=BTC-USD270=3.28271=0.6197183160=20250411-01:51:37.35881640=237=2f1818f9-f713-444e-a79e-7363fa46bc3c10=143
20250411-01:51:37.533038000 : 8=FIXT.1.19=32735=X49=Coinbase56=24ab46f784d1b20db435b852086e325034=11850=TEST52=20250411-01:51:37.360844369=46262=b7f6c79a-636c-490b-8bc5-37cb784406ba268=1279=0269=2278=4d60a78e-b39b-420e-b830-bc0f3f4fdde283=159757085555=BTC-USD270=3.53271=0.6197183160=20250411-01:51:37.35881637=2f1818f9-f713-444e-a79e-7363fa46bc3c5797=210=227
20250411-01:51:37.534456000 : 8=FIXT.1.19=29035=X49=Coinbase56=24ab46f784d1b20db435b852086e325034=11950=TEST52=20250411-01:51:37.360848369=46262=b7f6c79a-636c-490b-8bc5-37cb784406ba268=1279=2269=1278=2f1818f9-f713-444e-a79e-7363fa46bc3c83=159757085655=BTC-USD270=3.28271=0.0000000060=20250411-01:51:37.35881658=FILLED10=050
20250411-01:51:37.534720000 : 8=FIXT.1.19=28435=X49=Coinbase56=24ab46f784d1b20db435b852086e325034=12050=TEST52=20250411-01:51:37.416912369=46262=b7f6c79a-636c-490b-8bc5-37cb784406ba268=1279=0269=083=159757085755=BTC-USD270=3.77271=0.6197183160=20250411-01:51:37.41535140=237=210846c4-99a9-49f4-b512-dd535769a73c10=245
20250411-01:51:37.534899000 : 8=FIXT.1.19=32735=X49=Coinbase56=24ab46f784d1b20db435b852086e325034=12150=TEST52=20250411-01:51:37.416925369=46262=b7f6c79a-636c-490b-8bc5-37cb784406ba268=1279=0269=2278=c5b88ea9-605d-4595-ac52-f7c3f08523ba83=159757085855=BTC-USD270=3.55271=0.6197183160=20250411-01:51:37.41535137=210846c4-99a9-49f4-b512-dd535769a73c5797=110=201
20250411-01:51:37.536636000 : 8=FIXT.1.19=29035=X49=Coinbase56=24ab46f784d1b20db435b852086e325034=12250=TEST52=20250411-01:51:37.416928369=46262=b7f6c79a-636c-490b-8bc5-37cb784406ba268=1279=2269=0278=210846c4-99a9-49f4-b512-dd535769a73c83=159757085955=BTC-USD270=3.77271=0.0000000060=20250411-01:51:37.41535158=FILLED10=153
20250411-01:51:37.705087000 : 8=FIXT.1.19=30335=X49=Coinbase56=24ab46f784d1b20db435b852086e325034=12350=TEST52=20250411-01:51:37.589072369=46262=b7f6c79a-636c-490b-8bc5-37cb784406ba268=1279=0269=083=159757086055=BTC-USD270=3.86271=0.6729029829004=2.388805579060=20250411-01:51:37.58731740=237=fab33bed-b6c0-404b-bafd-bacc019cebfb10=038
20250411-01:51:37.705522000 : 8=FIXT.1.19=32735=X49=Coinbase56=24ab46f784d1b20db435b852086e325034=12450=TEST52=20250411-01:51:37.589179369=46262=b7f6c79a-636c-490b-8bc5-37cb784406ba268=1279=0269=2278=c5b88ea9-605d-4595-ac52-f7c3f08523ba83=159757086155=BTC-USD270=3.55271=0.6729029860=20250411-01:51:37.58731737=fab33bed-b6c0-404b-bafd-bacc019cebfb5797=110=084
20250411-01:51:37.707148000 : 8=FIXT.1.19=28135=X49=Coinbase56=24ab46f784d1b20db435b852086e325034=12550=TEST52=20250411-01:51:37.589182369=46262=b7f6c79a-636c-490b-8bc5-37cb784406ba268=1279=2269=0278=fab33bed-b6c0-404b-bafd-bacc019cebfb83=159757086255=BTC-USD270=3.86271=060=20250411-01:51:37.58731758=FILLED10=102
20250411-01:51:37.761596000 : 8=FIXT.1.19=28335=X49=Coinbase56=24ab46f784d1b20db435b852086e325034=12650=TEST52=20250411-01:51:37.644868369=46262=b7f6c79a-636c-490b-8bc5-37cb784406ba268=1279=0269=183=159757086355=BTC-USD270=3.2271=0.6197183160=20250411-01:51:37.64339640=237=dc67b6a2-950e-4f3d-8638-f463171c5c4310=045
20250411-01:51:37.763298000 : 8=FIXT.1.19=32735=X49=Coinbase56=24ab46f784d1b20db435b852086e325034=12750=TEST52=20250411-01:51:37.644877369=46262=b7f6c79a-636c-490b-8bc5-37cb784406ba268=1279=0269=2278=4d60a78e-b39b-420e-b830-bc0f3f4fdde283=159757086455=BTC-USD270=3.53271=0.6197183160=20250411-01:51:37.64339637=dc67b6a2-950e-4f3d-8638-f463171c5c435797=210=184
20250411-01:51:37.764320000 : 8=FIXT.1.19=28935=X49=Coinbase56=24ab46f784d1b20db435b852086e325034=12850=TEST52=20250411-01:51:37.644886369=46262=b7f6c79a-636c-490b-8bc5-37cb784406ba268=1279=2269=1278=dc67b6a2-950e-4f3d-8638-f463171c5c4383=159757086555=BTC-USD270=3.2271=0.0000000060=20250411-01:51:37.64339658=FILLED10=211
20250411-01:51:37.844612000 : 8=FIXT.1.19=28435=X49=Coinbase56=24ab46f784d1b20db435b852086e325034=12950=TEST52=20250411-01:51:37.728841369=46262=b7f6c79a-636c-490b-8bc5-37cb784406ba268=1279=0269=083=159757086655=BTC-USD270=3.36271=0.6232294660=20250411-01:51:37.72773740=237=17f7e8f0-1c8e-453f-a33a-c47e78e6cb8d10=043
20250411-01:51:37.845101000 : 8=FIXT.1.19=28035=X49=Coinbase56=24ab46f784d1b20db435b852086e325034=13050=TEST52=20250411-01:51:37.728849369=46262=b7f6c79a-636c-490b-8bc5-37cb784406ba268=1279=0269=0278=17f7e8f0-1c8e-453f-a33a-c47e78e6cb8d83=159757086755=BTC-USD270=3.36271=0.6232294660=20250411-01:51:37.72773710=139
20250411-01:51:38.392354000 : 8=FIXT.1.19=27935=X49=Coinbase56=24ab46f784d1b20db435b852086e325034=13150=TEST52=20250411-01:51:38.276492369=46262=b7f6c79a-636c-490b-8bc5-37cb784406ba268=1279=0269=083=159757086855=BTC-USD29004=2.208895519560=20250411-01:51:38.27470740=137=3be9e556-b22c-450a-b343-d6d58b62334b10=180
20250411-01:51:38.392794000 : 8=FIXT.1.19=32735=X49=Coinbase56=24ab46f784d1b20db435b852086e325034=13250=TEST52=20250411-01:51:38.276544369=46262=b7f6c79a-636c-490b-8bc5-37cb784406ba268=1279=0269=2278=c5b88ea9-605d-4595-ac52-f7c3f08523ba83=159757086955=BTC-USD270=3.55271=0.6222240960=20250411-01:51:38.27470737=3be9e556-b22c-450a-b343-d6d58b62334b5797=110=069
20250411-01:51:38.394636000 : 8=FIXT.1.19=26635=X49=Coinbase56=24ab46f784d1b20db435b852086e325034=13350=TEST52=20250411-01:51:38.276550369=46262=b7f6c79a-636c-490b-8bc5-37cb784406ba268=1279=2269=0278=3be9e556-b22c-450a-b343-d6d58b62334b83=159757087055=BTC-USD60=20250411-01:51:38.27470758=FILLED10=182
20250411-01:51:38.417936000 : 8=FIXT.1.19=28435=X49=Coinbase56=24ab46f784d1b20db435b852086e325034=13450=TEST52=20250411-01:51:38.301535369=46262=b7f6c79a-636c-490b-8bc5-37cb784406ba268=1279=0269=183=159757087155=BTC-USD270=3.68271=0.6197183160=20250411-01:51:38.30021940=237=6965e168-e9da-4b3e-b01d-be5876cdf9ef10=069
20250411-01:51:38.420027000 : 8=FIXT.1.19=28035=X49=Coinbase56=24ab46f784d1b20db435b852086e325034=13550=TEST52=20250411-01:51:38.301542369=46262=b7f6c79a-636c-490b-8bc5-37cb784406ba268=1279=0269=1278=6965e168-e9da-4b3e-b01d-be5876cdf9ef83=159757087255=BTC-USD270=3.68271=0.6197183160=20250411-01:51:38.30021910=164
20250411-01:51:38.421219000 : 8=FIXT.1.19=27535=X49=Coinbase56=24ab46f784d1b20db435b852086e325034=13650=TEST52=20250411-01:51:38.303180369=46262=b7f6c79a-636c-490b-8bc5-37cb784406ba268=1279=0269=183=159757087355=BTC-USD271=0.6232294660=20250411-01:51:38.30235240=137=348e52b8-4fb1-4eeb-9af8-4ffd2e6eabc310=239
20250411-01:51:38.421382000 : 8=FIXT.1.19=32735=X49=Coinbase56=24ab46f784d1b20db435b852086e325034=13750=TEST52=20250411-01:51:38.303187369=46262=b7f6c79a-636c-490b-8bc5-37cb784406ba268=1279=0269=2278=4d60a78e-b39b-420e-b830-bc0f3f4fdde283=159757087455=BTC-USD270=3.53271=0.6232294660=20250411-01:51:38.30235237=348e52b8-4fb1-4eeb-9af8-4ffd2e6eabc35797=210=235
20250411-01:51:38.422358000 : 8=FIXT.1.19=28135=X49=Coinbase56=24ab46f784d1b20db435b852086e325034=13850=TEST52=20250411-01:51:38.303207369=46262=b7f6c79a-636c-490b-8bc5-37cb784406ba268=1279=2269=1278=348e52b8-4fb1-4eeb-9af8-4ffd2e6eabc383=159757087555=BTC-USD271=0.0000000060=20250411-01:51:38.30235258=FILLED10=143
20250411-01:51:38.579663000 : 8=FIXT.1.19=28435=X49=Coinbase56=24ab46f784d1b20db435b852086e325034=13950=TEST52=20250411-01:51:38.388294369=46262=b7f6c79a-636c-490b-8bc5-37cb784406ba268=1279=0269=083=159757087655=BTC-USD270=3.73271=0.6232294660=20250411-01:51:38.38694940=237=360ffb5e-5188-4f14-99bd-5f1520eba85110=160
20250411-01:51:38.584502000 : 8=FIXT.1.19=32735=X49=Coinbase56=24ab46f784d1b20db435b852086e325034=14050=TEST52=20250411-01:51:38.388304369=46262=b7f6c79a-636c-490b-8bc5-37cb784406ba268=1279=0269=2278=c5b88ea9-605d-4595-ac52-f7c3f08523ba83=159757087755=BTC-USD270=3.55271=0.6232294660=20250411-01:51:38.38694937=360ffb5e-5188-4f14-99bd-5f1520eba8515797=110=099
20250411-01:51:38.584832000 : 8=FIXT.1.19=29035=X49=Coinbase56=24ab46f784d1b20db435b852086e325034=14150=TEST52=20250411-01:51:38.388307369=46262=b7f6c79a-636c-490b-8bc5-37cb784406ba268=1279=2269=0278=360ffb5e-5188-4f14-99bd-5f1520eba85183=159757087855=BTC-USD270=3.73271=0.0000000060=20250411-01:51:38.38694958=FILLED10=049
20250411-01:51:38.585138000 : 8=FIXT.1.19=28435=X49=Coinbase56=24ab46f784d1b20db435b852086e325034=14250=TEST52=20250411-01:51:38.443638369=46262=b7f6c79a-636c-490b-8bc5-37cb784406ba268=1279=0269=183=159757087955=BTC-USD270=3.23271=0.6232294660=20250411-01:51:38.44236840=237=ce07b453-a76b-467e-b807-a577125a328c10=081
20250411-01:51:38.585455000 : 8=FIXT.1.19=32735=X49=Coinbase56=24ab46f784d1b20db435b852086e325034=14350=TEST52=20250411-01:51:38.443791369=46262=b7f6c79a-636c-490b-8bc5-37cb784406ba268=1279=0269=2278=4d60a78e-b39b-420e-b830-bc0f3f4fdde283=159757088055=BTC-USD270=3.53271=0.6232294660=20250411-01:51:38.44236837=ce07b453-a76b-467e-b807-a577125a328c5797=210=159
20250411-01:51:38.587453000 : 8=FIXT.1.19=29035=X49=Coinbase56=24ab46f784d1b20db435b852086e325034=14450=TEST52=20250411-01:51:38.443839369=46262=b7f6c79a-636c-490b-8bc5-37cb784406ba268=1279=2269=1278=ce07b453-a76b-467e-b807-a577125a328c83=159757088155=BTC-USD270=3.23271=0.0000000060=20250411-01:51:38.44236858=FILLED10=234
20250411-01:51:38.701721000 : 8=FIXT.1.19=28435=X49=Coinbase56=24ab46f784d1b20db435b852086e325034=14550=TEST52=20250411-01:51:38.585138369=46262=b7f6c79a-636c-490b-8bc5-37cb784406ba268=1279=0269=083=159757088255=BTC-USD270=3.41271=0.6197183160=20250411-01:51:38.58326040=237=1a2171ae-6f8a-494f-846e-27ef406b6aa510=176
20250411-01:51:38.702240000 : 8=FIXT.1.19=28035=X49=Coinbase56=24ab46f784d1b20db435b852086e325034=14650=TEST52=20250411-01:51:38.585144369=46262=b7f6c79a-636c-490b-8bc5-37cb784406ba268=1279=0269=0278=1a2171ae-6f8a-494f-846e-27ef406b6aa583=159757088355=BTC-USD270=3.41271=0.6197183160=20250411-01:51:38.58326010=014
20250411-01:51:39.101631000 : 8=FIXT.1.19=28435=X49=Coinbase56=24ab46f784d1b20db435b852086e325034=14750=TEST52=20250411-01:51:38.960975369=46262=b7f6c79a-636c-490b-8bc5-37cb784406ba268=1279=0269=083=159757088455=BTC-USD270=3.78271=0.6232294660=20250411-01:51:38.95983540=237=db36142b-6ebc-48f1-af67-8fda3469f36510=010
20250411-01:51:39.102177000 : 8=FIXT.1.19=32735=X49=Coinbase56=24ab46f784d1b20db435b852086e325034=14850=TEST52=20250411-01:51:38.960984369=46262=b7f6c79a-636c-490b-8bc5-37cb784406ba268=1279=0269=2278=c5b88ea9-605d-4595-ac52-f7c3f08523ba83=159757088555=BTC-USD270=3.55271=0.6232294660=20250411-01:51:38.95983537=db36142b-6ebc-48f1-af67-8fda3469f3655797=110=217
20250411-01:51:39.104433000 : 8=FIXT.1.19=29035=X49=Coinbase56=24ab46f784d1b20db435b852086e325034=14950=TEST52=20250411-01:51:38.960997369=46262=b7f6c79a-636c-490b-8bc5-37cb784406ba268=1279=2269=0278=db36142b-6ebc-48f1-af67-8fda3469f36583=159757088655=BTC-USD270=3.78271=0.0000000060=20250411-01:51:38.95983558=FILLED10=173
20250411-01:51:39.131798000 : 8=FIXT.1.19=28435=X49=Coinbase56=24ab46f784d1b20db435b852086e325034=15050=TEST52=20250411-01:51:39.015623369=46262=b7f6c79a-636c-490b-8bc5-37cb784406ba268=1279=0269=183=159757088755=BTC-USD270=3.22271=0.6232294660=20250411-01:51:39.01393440=237=2d7dcc61-b59c-471f-bb85-b7eee1a8e20b10=092
20250411-01:51:39.155246000 : 8=FIXT.1.19=32735=X49=Coinbase56=24ab46f784d1b20db435b852086e325034=15150=TEST52=20250411-01:51:39.015729369=46262=b7f6c79a-636c-490b-8bc5-37cb784406ba268=1279=0269=2278=4d60a78e-b39b-420e-b830-bc0f3f4fdde283=159757088855=BTC-USD270=3.53271=0.6232294660=20250411-01:51:39.01393437=2d7dcc61-b59c-471f-bb85-b7eee1a8e20b5797=210=187
20250411-01:51:39.157925000 : 8=FIXT.1.19=29035=X49=Coinbase56=24ab46f784d1b20db435b852086e325034=15250=TEST52=20250411-01:51:39.015734369=46262=b7f6c79a-636c-490b-8bc5-37cb784406ba268=1279=2269=1278=2d7dcc61-b59c-471f-bb85-b7eee1a8e20b83=159757088955=BTC-USD270=3.22271=0.0000000060=20250411-01:51:39.01393458=FILLED10=254
20250411-01:51:39.191382000 : 8=FIXT.1.19=28435=X49=Coinbase56=24ab46f784d1b20db435b852086e325034=15350=TEST52=20250411-01:51:39.074325369=46262=b7f6c79a-636c-490b-8bc5-37cb784406ba268=1279=0269=083=159757089055=BTC-USD270=3.72271=0.6232294660=20250411-01:51:39.07261940=237=73518d13-924b-4fa6-8036-b4d70f57167a10=236
20250411-01:51:39.191789000 : 8=FIXT.1.19=32735=X49=Coinbase56=24ab46f784d1b20db435b852086e325034=15450=TEST52=20250411-01:51:39.074416369=46262=b7f6c79a-636c-490b-8bc5-37cb784406ba268=1279=0269=2278=c5b88ea9-605d-4595-ac52-f7c3f08523ba83=159757089155=BTC-USD270=3.55271=0.6232294660=20250411-01:51:39.07261937=73518d13-924b-4fa6-8036-b4d70f57167a5797=110=194
20250411-01:51:39.194339000 : 8=FIXT.1.19=29035=X49=Coinbase56=24ab46f784d1b20db435b852086e325034=15550=TEST52=20250411-01:51:39.074420369=46262=b7f6c79a-636c-490b-8bc5-37cb784406ba268=1279=2269=0278=73518d13-924b-4fa6-8036-b4d70f57167a83=159757089255=BTC-USD270=3.72271=0.0000000060=20250411-01:51:39.07261958=FILLED10=135
20250411-01:51:39.246817000 : 8=FIXT.1.19=28435=X49=Coinbase56=24ab46f784d1b20db435b852086e325034=15650=TEST52=20250411-01:51:39.130779369=46262=b7f6c79a-636c-490b-8bc5-37cb784406ba268=1279=0269=183=159757089355=BTC-USD270=3.23271=0.6232294660=20250411-01:51:39.12908840=237=5bf91bad-3f83-4110-b1bf-e8f5503b02d110=207
20250411-01:51:39.248979000 : 8=FIXT.1.19=32735=X49=Coinbase56=24ab46f784d1b20db435b852086e325034=15750=TEST52=20250411-01:51:39.130858369=46262=b7f6c79a-636c-490b-8bc5-37cb784406ba268=1279=0269=2278=4d60a78e-b39b-420e-b830-bc0f3f4fdde283=159757089455=BTC-USD270=3.53271=0.6232294660=20250411-01:51:39.12908837=5bf91bad-3f83-4110-b1bf-e8f5503b02d15797=210=036
20250411-01:51:39.250505000 : 8=FIXT.1.19=29035=X49=Coinbase56=24ab46f784d1b20db435b852086e325034=15850=TEST52=20250411-01:51:39.130861369=46262=b7f6c79a-636c-490b-8bc5-37cb784406ba268=1279=2269=1278=5bf91bad-3f83-4110-b1bf-e8f5503b02d183=159757089555=BTC-USD270=3.23271=0.0000000060=20250411-01:51:39.12908858=FILLED10=102
20250411-01:51:39.364070000 : 8=FIXT.1.19=27935=X49=Coinbase56=24ab46f784d1b20db435b852086e325034=15950=TEST52=20250411-01:51:39.247146369=46262=b7f6c79a-636c-490b-8bc5-37cb784406ba268=1279=0269=083=159757089655=BTC-USD29004=2.208895519560=20250411-01:51:39.24612340=137=1a754b96-425e-4db4-9ec6-4acd90aa8d4a10=074
20250411-01:51:39.364455000 : 8=FIXT.1.19=32735=X49=Coinbase56=24ab46f784d1b20db435b852086e325034=16050=TEST52=20250411-01:51:39.247155369=46262=b7f6c79a-636c-490b-8bc5-37cb784406ba268=1279=0269=2278=c5b88ea9-605d-4595-ac52-f7c3f08523ba83=159757089755=BTC-USD270=3.55271=0.6222240960=20250411-01:51:39.24612337=1a754b96-425e-4db4-9ec6-4acd90aa8d4a5797=110=212
20250411-01:51:39.366401000 : 8=FIXT.1.19=26635=X49=Coinbase56=24ab46f784d1b20db435b852086e325034=16150=TEST52=20250411-01:51:39.247158369=46262=b7f6c79a-636c-490b-8bc5-37cb784406ba268=1279=2269=0278=1a754b96-425e-4db4-9ec6-4acd90aa8d4a83=159757089855=BTC-USD60=20250411-01:51:39.24612358=FILLED10=084
20250411-01:51:39.393539000 : 8=FIXT.1.19=27535=X49=Coinbase56=24ab46f784d1b20db435b852086e325034=16250=TEST52=20250411-01:51:39.276589369=46262=b7f6c79a-636c-490b-8bc5-37cb784406ba268=1279=0269=183=159757089955=BTC-USD271=0.6232294660=20250411-01:51:39.27512840=137=52c21df3-6d3c-40b1-a4cd-1547a45e8ab910=064
20250411-01:51:39.393916000 : 8=FIXT.1.19=32735=X49=Coinbase56=24ab46f784d1b20db435b852086e325034=16350=TEST52=20250411-01:51:39.276608369=46262=b7f6c79a-636c-490b-8bc5-37cb784406ba268=1279=0269=2278=4d60a78e-b39b-420e-b830-bc0f3f4fdde283=159757090055=BTC-USD270=3.53271=0.6232294660=20250411-01:51:39.27512837=52c21df3-6d3c-40b1-a4cd-1547a45e8ab95797=210=027
20250411-01:51:39.395662000 : 8=FIXT.1.19=28135=X49=Coinbase56=24ab46f784d1b20db435b852086e325034=16450=TEST52=20250411-01:51:39.276611369=46262=b7f6c79a-636c-490b-8bc5-37cb784406ba268=1279=2269=1278=52c21df3-6d3c-40b1-a4cd-1547a45e8ab983=159757090155=BTC-USD271=0.0000000060=20250411-01:51:39.27512858=FILLED10=192
20250411-01:51:39.533384000 : 8=FIXT.1.19=28435=X49=Coinbase56=24ab46f784d1b20db435b852086e325034=16550=TEST52=20250411-01:51:39.417137369=46262=b7f6c79a-636c-490b-8bc5-37cb784406ba268=1279=0269=183=159757090255=BTC-USD270=3.23271=0.6232294660=20250411-01:51:39.41572140=237=f8242001-8a63-4934-b98e-f40462f8748b10=188
20250411-01:51:39.535187000 : 8=FIXT.1.19=32735=X49=Coinbase56=24ab46f784d1b20db435b852086e325034=16650=TEST52=20250411-01:51:39.417146369=46262=b7f6c79a-636c-490b-8bc5-37cb784406ba268=1279=0269=2278=4d60a78e-b39b-420e-b830-bc0f3f4fdde283=159757090355=BTC-USD270=3.53271=0.6232294660=20250411-01:51:39.41572137=f8242001-8a63-4934-b98e-f40462f8748b5797=210=019
20250411-01:51:39.536821000 : 8=FIXT.1.19=29035=X49=Coinbase56=24ab46f784d1b20db435b852086e325034=16750=TEST52=20250411-01:51:39.417150369=46262=b7f6c79a-636c-490b-8bc5-37cb784406ba268=1279=2269=1278=f8242001-8a63-4934-b98e-f40462f8748b83=159757090455=BTC-USD270=3.23271=0.0000000060=20250411-01:51:39.41572158=FILLED10=086
20250411-01:51:39.625972000 : 8=FIXT.1.19=28435=X49=Coinbase56=24ab46f784d1b20db435b852086e325034=16850=TEST52=20250411-01:51:39.472065369=46262=b7f6c79a-636c-490b-8bc5-37cb784406ba268=1279=0269=083=159757090555=BTC-USD270=3.75271=0.6232294660=20250411-01:51:39.47079940=237=506431e1-4365-4a7e-94a1-62d593bd4f6c10=044
20250411-01:51:39.626515000 : 8=FIXT.1.19=32735=X49=Coinbase56=24ab46f784d1b20db435b852086e325034=16950=TEST52=20250411-01:51:39.472084369=46262=b7f6c79a-636c-490b-8bc5-37cb784406ba268=1279=0269=2278=c5b88ea9-605d-4595-ac52-f7c3f08523ba83=159757090655=BTC-USD270=3.55271=0.6232294660=20250411-01:51:39.47079937=506431e1-4365-4a7e-94a1-62d593bd4f6c5797=110=255
20250411-01:51:39.628476000 : 8=FIXT.1.19=29035=X49=Coinbase56=24ab46f784d1b20db435b852086e325034=17050=TEST52=20250411-01:51:39.472087369=46262=b7f6c79a-636c-490b-8bc5-37cb784406ba268=1279=2269=0278=506431e1-4365-4a7e-94a1-62d593bd4f6c83=159757090755=BTC-USD270=3.75271=0.0000000060=20250411-01:51:39.47079958=FILLED10=198
20250411-01:51:40.562867000 : 8=FIXT.1.19=27935=X49=Coinbase56=24ab46f784d1b20db435b852086e325034=17150=TEST52=20250411-01:51:40.446732369=46262=b7f6c79a-636c-490b-8bc5-37cb784406ba268=1279=0269=083=159757090855=BTC-USD29004=2.208895519560=20250411-01:51:40.44582540=137=b0fcf910-056b-4a33-8405-5ca8376cab8310=160
20250411-01:51:40.563467000 : 8=FIXT.1.19=32735=X49=Coinbase56=24ab46f784d1b20db435b852086e325034=17250=TEST52=20250411-01:51:40.446876369=46262=b7f6c79a-636c-490b-8bc5-37cb784406ba268=1279=0269=2278=c5b88ea9-605d-4595-ac52-f7c3f08523ba83=159757090955=BTC-USD270=3.55271=0.6222240960=20250411-01:51:40.44582537=b0fcf910-056b-4a33-8405-5ca8376cab835797=110=060
20250411-01:51:40.565675000 : 8=FIXT.1.19=26635=X49=Coinbase56=24ab46f784d1b20db435b852086e325034=17350=TEST52=20250411-01:51:40.446879369=46262=b7f6c79a-636c-490b-8bc5-37cb784406ba268=1279=2269=0278=b0fcf910-056b-4a33-8405-5ca8376cab8383=159757091055=BTC-USD60=20250411-01:51:40.44582558=FILLED10=179
20250411-01:51:40.673639000 : 8=FIXT.1.19=27535=X49=Coinbase56=24ab46f784d1b20db435b852086e325034=17450=TEST52=20250411-01:51:40.476036369=46262=b7f6c79a-636c-490b-8bc5-37cb784406ba268=1279=0269=183=159757091155=BTC-USD271=0.6197183160=20250411-01:51:40.47450940=137=e67616d8-e1f0-4c15-a1db-ce9eeafd823410=145
20250411-01:51:40.674131000 : 8=FIXT.1.19=32735=X49=Coinbase56=24ab46f784d1b20db435b852086e325034=17550=TEST52=20250411-01:51:40.476045369=46262=b7f6c79a-636c-490b-8bc5-37cb784406ba268=1279=0269=2278=4d60a78e-b39b-420e-b830-bc0f3f4fdde283=159757091255=BTC-USD270=3.53271=0.6197183160=20250411-01:51:40.47450937=e67616d8-e1f0-4c15-a1db-ce9eeafd82345797=210=134
20250411-01:51:40.676163000 : 8=FIXT.1.19=28135=X49=Coinbase56=24ab46f784d1b20db435b852086e325034=17650=TEST52=20250411-01:51:40.476047369=46262=b7f6c79a-636c-490b-8bc5-37cb784406ba268=1279=2269=1278=e67616d8-e1f0-4c15-a1db-ce9eeafd823483=159757091355=BTC-USD271=0.0000000060=20250411-01:51:40.47450958=FILLED10=049
20250411-01:51:40.792606000 : 8=FIXT.1.19=27935=X49=Coinbase56=24ab46f784d1b20db435b852086e325034=17750=TEST52=20250411-01:51:40.675883369=46262=b7f6c79a-636c-490b-8bc5-37cb784406ba268=1279=0269=083=159757091455=BTC-USD29004=2.208895519560=20250411-01:51:40.67447340=137=cad1ec8b-3f00-401a-8621-21c5d04d95a910=213
20250411-01:51:40.794780000 : 8=FIXT.1.19=32735=X49=Coinbase56=24ab46f784d1b20db435b852086e325034=17850=TEST52=20250411-01:51:40.675895369=46262=b7f6c79a-636c-490b-8bc5-37cb784406ba268=1279=0269=2278=c5b88ea9-605d-4595-ac52-f7c3f08523ba83=159757091555=BTC-USD270=3.55271=0.6222240960=20250411-01:51:40.67447337=cad1ec8b-3f00-401a-8621-21c5d04d95a95797=110=107
20250411-01:51:40.797592000 : 8=FIXT.1.19=26635=X49=Coinbase56=24ab46f784d1b20db435b852086e325034=17950=TEST52=20250411-01:51:40.675915369=46262=b7f6c79a-636c-490b-8bc5-37cb784406ba268=1279=2269=0278=cad1ec8b-3f00-401a-8621-21c5d04d95a983=159757091655=BTC-USD60=20250411-01:51:40.67447358=FILLED10=225
20250411-01:51:40.820793000 : 8=FIXT.1.19=27535=X49=Coinbase56=24ab46f784d1b20db435b852086e325034=18050=TEST52=20250411-01:51:40.704030369=46262=b7f6c79a-636c-490b-8bc5-37cb784406ba268=1279=0269=183=159757091755=BTC-USD271=0.6232294660=20250411-01:51:40.70247640=137=aeb00a02-517c-4b18-8185-f010c22bf59f10=170
20250411-01:51:40.823655000 : 8=FIXT.1.19=32735=X49=Coinbase56=24ab46f784d1b20db435b852086e325034=18150=TEST52=20250411-01:51:40.704091369=46262=b7f6c79a-636c-490b-8bc5-37cb784406ba268=1279=0269=2278=4d60a78e-b39b-420e-b830-bc0f3f4fdde283=159757091855=BTC-USD270=3.53271=0.6232294660=20250411-01:51:40.70247637=aeb00a02-517c-4b18-8185-f010c22bf59f5797=210=166
20250411-01:51:40.826416000 : 8=FIXT.1.19=28135=X49=Coinbase56=24ab46f784d1b20db435b852086e325034=18250=TEST52=20250411-01:51:40.704158369=46262=b7f6c79a-636c-490b-8bc5-37cb784406ba268=1279=2269=1278=aeb00a02-517c-4b18-8185-f010c22bf59f83=159757091955=BTC-USD271=0.0000000060=20250411-01:51:40.70247658=FILLED10=085
20250411-01:51:40.911970000 : 8=FIXT.1.19=28335=X49=Coinbase56=24ab46f784d1b20db435b852086e325034=18350=TEST52=20250411-01:51:40.796477369=46262=b7f6c79a-636c-490b-8bc5-37cb784406ba268=1279=0269=183=159757092055=BTC-USD270=3.2271=0.6232294660=20250411-01:51:40.79518940=237=d7041ff6-b6c8-4558-8e27-2c716d61daea10=136
20250411-01:51:40.912671000 : 8=FIXT.1.19=32735=X49=Coinbase56=24ab46f784d1b20db435b852086e325034=18450=TEST52=20250411-01:51:40.796554369=46262=b7f6c79a-636c-490b-8bc5-37cb784406ba268=1279=0269=2278=4d60a78e-b39b-420e-b830-bc0f3f4fdde283=159757092155=BTC-USD270=3.53271=0.6232294660=20250411-01:51:40.79518937=d7041ff6-b6c8-4558-8e27-2c716d61daea5797=210=015
20250411-01:51:40.914239000 : 8=FIXT.1.19=28935=X49=Coinbase56=24ab46f784d1b20db435b852086e325034=18550=TEST52=20250411-01:51:40.796559369=46262=b7f6c79a-636c-490b-8bc5-37cb784406ba268=1279=2269=1278=d7041ff6-b6c8-4558-8e27-2c716d61daea83=159757092255=BTC-USD270=3.2271=0.0000000060=20250411-01:51:40.79518958=FILLED10=049
20250411-01:51:40.960286000 : 8=FIXT.1.19=28435=X49=Coinbase56=24ab46f784d1b20db435b852086e325034=18650=TEST52=20250411-01:51:40.844129369=46262=b7f6c79a-636c-490b-8bc5-37cb784406ba268=1279=0269=083=159757092355=BTC-USD270=3.82271=0.6232294660=20250411-01:51:40.84247140=237=35e35473-62e0-4aa1-be3c-be5af1c0e6fe10=036
20250411-01:51:40.960716000 : 8=FIXT.1.19=32735=X49=Coinbase56=24ab46f784d1b20db435b852086e325034=18750=TEST52=20250411-01:51:40.844228369=46262=b7f6c79a-636c-490b-8bc5-37cb784406ba268=1279=0269=2278=c5b88ea9-605d-4595-ac52-f7c3f08523ba83=159757092455=BTC-USD270=3.55271=0.6232294660=20250411-01:51:40.84247137=35e35473-62e0-4aa1-be3c-be5af1c0e6fe5797=110=248
20250411-01:51:40.962662000 : 8=FIXT.1.19=29035=X49=Coinbase56=24ab46f784d1b20db435b852086e325034=18850=TEST52=20250411-01:51:40.844230369=46262=b7f6c79a-636c-490b-8bc5-37cb784406ba268=1279=2269=0278=35e35473-62e0-4aa1-be3c-be5af1c0e6fe83=159757092555=BTC-USD270=3.82271=0.0000000060=20250411-01:51:40.84247158=FILLED10=188
20250411-01:51:40.964928000 : 8=FIXT.1.19=27935=X49=Coinbase56=24ab46f784d1b20db435b852086e325034=18950=TEST52=20250411-01:51:40.849116369=46262=b7f6c79a-636c-490b-8bc5-37cb784406ba268=1279=0269=083=159757092655=BTC-USD29004=2.208895519560=20250411-01:51:40.84717340=137=d3de2960-cd75-462b-985d-4630e2ebc8d610=244
20250411-01:51:40.965159000 : 8=FIXT.1.19=32735=X49=Coinbase56=24ab46f784d1b20db435b852086e325034=19050=TEST52=20250411-01:51:40.849122369=46262=b7f6c79a-636c-490b-8bc5-37cb784406ba268=1279=0269=2278=c5b88ea9-605d-4595-ac52-f7c3f08523ba83=159757092755=BTC-USD270=3.55271=0.6222240960=20250411-01:51:40.84717337=d3de2960-cd75-462b-985d-4630e2ebc8d65797=110=123
20250411-01:51:40.966167000 : 8=FIXT.1.19=26635=X49=Coinbase56=24ab46f784d1b20db435b852086e325034=19150=TEST52=20250411-01:51:40.849126369=46262=b7f6c79a-636c-490b-8bc5-37cb784406ba268=1279=2269=0278=d3de2960-cd75-462b-985d-4630e2ebc8d683=159757092855=BTC-USD60=20250411-01:51:40.84717358=FILLED10=252
20250411-01:51:40.995179000 : 8=FIXT.1.19=27535=X49=Coinbase56=24ab46f784d1b20db435b852086e325034=19250=TEST52=20250411-01:51:40.880032369=46262=b7f6c79a-636c-490b-8bc5-37cb784406ba268=1279=0269=183=159757092955=BTC-USD271=0.6232294660=20250411-01:51:40.87895040=137=b43270ac-d156-4df5-8bc6-df5df338738610=019
20250411-01:51:40.995679000 : 8=FIXT.1.19=32735=X49=Coinbase56=24ab46f784d1b20db435b852086e325034=19350=TEST52=20250411-01:51:40.880076369=46262=b7f6c79a-636c-490b-8bc5-37cb784406ba268=1279=0269=2278=4d60a78e-b39b-420e-b830-bc0f3f4fdde283=159757093055=BTC-USD270=3.53271=0.6232294660=20250411-01:51:40.87895037=b43270ac-d156-4df5-8bc6-df5df33873865797=210=007
20250411-01:51:40.997122000 : 8=FIXT.1.19=28135=X49=Coinbase56=24ab46f784d1b20db435b852086e325034=19450=TEST52=20250411-01:51:40.880178369=46262=b7f6c79a-636c-490b-8bc5-37cb784406ba268=1279=2269=1278=b43270ac-d156-4df5-8bc6-df5df338738683=159757093155=BTC-USD271=0.0000000060=20250411-01:51:40.87895058=FILLED10=181
20250411-01:51:41.198341000 : 8=FIXT.1.19=27935=X49=Coinbase56=24ab46f784d1b20db435b852086e325034=19550=TEST52=20250411-01:51:41.075981369=46262=b7f6c79a-636c-490b-8bc5-37cb784406ba268=1279=0269=083=159757093255=BTC-USD29004=2.208895519560=20250411-01:51:41.07430340=137=af68695c-ceac-4548-ab43-329925b8621b10=178
20250411-01:51:41.199130000 : 8=FIXT.1.19=32735=X49=Coinbase56=24ab46f784d1b20db435b852086e325034=19650=TEST52=20250411-01:51:41.075993369=46262=b7f6c79a-636c-490b-8bc5-37cb784406ba268=1279=0269=2278=c5b88ea9-605d-4595-ac52-f7c3f08523ba83=159757093355=BTC-USD270=3.55271=0.6222240960=20250411-01:51:41.07430337=af68695c-ceac-4548-ab43-329925b8621b5797=110=072
20250411-01:51:41.199362000 : 8=FIXT.1.19=26635=X49=Coinbase56=24ab46f784d1b20db435b852086e325034=19750=TEST52=20250411-01:51:41.075996369=46262=b7f6c79a-636c-490b-8bc5-37cb784406ba268=1279=2269=0278=af68695c-ceac-4548-ab43-329925b8621b83=159757093455=BTC-USD60=20250411-01:51:41.07430358=FILLED10=200
20250411-01:51:41.221946000 : 8=FIXT.1.19=27535=X49=Coinbase56=24ab46f784d1b20db435b852086e325034=19850=TEST52=20250411-01:51:41.105164369=46262=b7f6c79a-636c-490b-8bc5-37cb784406ba268=1279=0269=183=159757093555=BTC-USD271=0.6232294660=20250411-01:51:41.10345740=137=ff7d3224-6181-4c8c-aa6d-9beceaaea06c10=225
20250411-01:51:41.222493000 : 8=FIXT.1.19=32735=X49=Coinbase56=24ab46f784d1b20db435b852086e325034=19950=TEST52=20250411-01:51:41.105175369=46262=b7f6c79a-636c-490b-8bc5-37cb784406ba268=1279=0269=2278=4d60a78e-b39b-420e-b830-bc0f3f4fdde283=159757093655=BTC-USD270=3.53271=0.6232294660=20250411-01:51:41.10345737=ff7d3224-6181-4c8c-aa6d-9beceaaea06c5797=210=216
20250411-01:51:41.224364000 : 8=FIXT.1.19=28135=X49=Coinbase56=24ab46f784d1b20db435b852086e325034=20050=TEST52=20250411-01:51:41.105226369=46262=b7f6c79a-636c-490b-8bc5-37cb784406ba268=1279=2269=1278=ff7d3224-6181-4c8c-aa6d-9beceaaea06c83=159757093755=BTC-USD271=0.0000000060=20250411-01:51:41.10345758=FILLED10=110
20250411-01:51:41.362745000 : 8=FIXT.1.19=27935=X49=Coinbase56=24ab46f784d1b20db435b852086e325034=20150=TEST52=20250411-01:51:41.247347369=46262=b7f6c79a-636c-490b-8bc5-37cb784406ba268=1279=0269=083=159757093855=BTC-USD29004=2.208895519560=20250411-01:51:41.24577840=137=9550a8c0-0dd6-43e1-b434-3a10cb5aa8a410=196
20250411-01:51:41.363227000 : 8=FIXT.1.19=32735=X49=Coinbase56=24ab46f784d1b20db435b852086e325034=20250=TEST52=20250411-01:51:41.247355369=46262=b7f6c79a-636c-490b-8bc5-37cb784406ba268=1279=0269=2278=c5b88ea9-605d-4595-ac52-f7c3f08523ba83=159757093955=BTC-USD270=3.55271=0.6222240960=20250411-01:51:41.24577837=9550a8c0-0dd6-43e1-b434-3a10cb5aa8a45797=110=086
20250411-01:51:41.363459000 : 8=FIXT.1.19=26635=X49=Coinbase56=24ab46f784d1b20db435b852086e325034=20350=TEST52=20250411-01:51:41.247357369=46262=b7f6c79a-636c-490b-8bc5-37cb784406ba268=1279=2269=0278=9550a8c0-0dd6-43e1-b434-3a10cb5aa8a483=159757094055=BTC-USD60=20250411-01:51:41.24577858=FILLED10=204
20250411-01:51:41.390393000 : 8=FIXT.1.19=27535=X49=Coinbase56=24ab46f784d1b20db435b852086e325034=20450=TEST52=20250411-01:51:41.274836369=46262=b7f6c79a-636c-490b-8bc5-37cb784406ba268=1279=0269=183=159757094155=BTC-USD271=0.6232294660=20250411-01:51:41.27361940=137=a77eb9c3-fe1a-45f9-92a8-e6a70d11a50610=049
20250411-01:51:41.391782000 : 8=FIXT.1.19=32735=X49=Coinbase56=24ab46f784d1b20db435b852086e325034=20550=TEST52=20250411-01:51:41.274842369=46262=b7f6c79a-636c-490b-8bc5-37cb784406ba268=1279=0269=2278=4d60a78e-b39b-420e-b830-bc0f3f4fdde283=159757094255=BTC-USD270=3.53271=0.6232294660=20250411-01:51:41.27361937=a77eb9c3-fe1a-45f9-92a8-e6a70d11a5065797=210=035
20250411-01:51:41.393832000 : 8=FIXT.1.19=28135=X49=Coinbase56=24ab46f784d1b20db435b852086e325034=20650=TEST52=20250411-01:51:41.274846369=46262=b7f6c79a-636c-490b-8bc5-37cb784406ba268=1279=2269=1278=a77eb9c3-fe1a-45f9-92a8-e6a70d11a50683=159757094355=BTC-USD271=0.0000000060=20250411-01:51:41.27361958=FILLED10=210
20250411-01:51:41.477256000 : 8=FIXT.1.19=27935=X49=Coinbase56=24ab46f784d1b20db435b852086e325034=20750=TEST52=20250411-01:51:41.360507369=46262=b7f6c79a-636c-490b-8bc5-37cb784406ba268=1279=0269=083=159757094455=BTC-USD29004=2.208895519560=20250411-01:51:41.35924740=137=1f9ef704-4970-4937-8551-9e250c9e75fc10=056
20250411-01:51:41.477845000 : 8=FIXT.1.19=32735=X49=Coinbase56=24ab46f784d1b20db435b852086e325034=20850=TEST52=20250411-01:51:41.360513369=46262=b7f6c79a-636c-490b-8bc5-37cb784406ba268=1279=0269=2278=c5b88ea9-605d-4595-ac52-f7c3f08523ba83=159757094555=BTC-USD270=3.55271=0.6222240960=20250411-01:51:41.35924737=1f9ef704-4970-4937-8551-9e250c9e75fc5797=110=200
20250411-01:51:41.479670000 : 8=FIXT.1.19=26635=X49=Coinbase56=24ab46f784d1b20db435b852086e325034=20950=TEST52=20250411-01:51:41.360518369=46262=b7f6c79a-636c-490b-8bc5-37cb784406ba268=1279=2269=0278=1f9ef704-4970-4937-8551-9e250c9e75fc83=159757094655=BTC-USD60=20250411-01:51:41.35924758=FILLED10=074
20250411-01:51:41.506550000 : 8=FIXT.1.19=27535=X49=Coinbase56=24ab46f784d1b20db435b852086e325034=21050=TEST52=20250411-01:51:41.389884369=46262=b7f6c79a-636c-490b-8bc5-37cb784406ba268=1279=0269=183=159757094755=BTC-USD271=0.6232294660=20250411-01:51:41.38839840=137=0ea6a7ac-f641-4333-b2bd-a2074e1e5fdd10=146
20250411-01:51:41.507128000 : 8=FIXT.1.19=32735=X49=Coinbase56=24ab46f784d1b20db435b852086e325034=21150=TEST52=20250411-01:51:41.389969369=46262=b7f6c79a-636c-490b-8bc5-37cb784406ba268=1279=0269=2278=4d60a78e-b39b-420e-b830-bc0f3f4fdde283=159757094855=BTC-USD270=3.53271=0.6232294660=20250411-01:51:41.38839837=0ea6a7ac-f641-4333-b2bd-a2074e1e5fdd5797=210=139
20250411-01:51:41.509049000 : 8=FIXT.1.19=28135=X49=Coinbase56=24ab46f784d1b20db435b852086e325034=21250=TEST52=20250411-01:51:41.389972369=46262=b7f6c79a-636c-490b-8bc5-37cb784406ba268=1279=2269=1278=0ea6a7ac-f641-4333-b2bd-a2074e1e5fdd83=159757094955=BTC-USD271=0.0000000060=20250411-01:51:41.38839858=FILLED10=048
20250411-01:51:41.533550000 : 8=FIXT.1.19=27935=X49=Coinbase56=24ab46f784d1b20db435b852086e325034=21350=TEST52=20250411-01:51:41.418528369=46262=b7f6c79a-636c-490b-8bc5-37cb784406ba268=1279=0269=083=159757095055=BTC-USD29004=2.208895519560=20250411-01:51:41.41717540=137=eadc4515-2ab8-4076-af5a-bad5b45e54b510=088
20250411-01:51:41.534202000 : 8=FIXT.1.19=32735=X49=Coinbase56=24ab46f784d1b20db435b852086e325034=21450=TEST52=20250411-01:51:41.418657369=46262=b7f6c79a-636c-490b-8bc5-37cb784406ba268=1279=0269=2278=c5b88ea9-605d-4595-ac52-f7c3f08523ba83=159757095155=BTC-USD270=3.55271=0.6222240960=20250411-01:51:41.41717537=eadc4515-2ab8-4076-af5a-bad5b45e54b55797=110=238
20250411-01:51:41.534507000 : 8=FIXT.1.19=26635=X49=Coinbase56=24ab46f784d1b20db435b852086e325034=21550=TEST52=20250411-01:51:41.418660369=46262=b7f6c79a-636c-490b-8bc5-37cb784406ba268=1279=2269=0278=eadc4515-2ab8-4076-af5a-bad5b45e54b583=159757095255=BTC-USD60=20250411-01:51:41.41717558=FILLED10=101
20250411-01:51:41.562219000 : 8=FIXT.1.19=27535=X49=Coinbase56=24ab46f784d1b20db435b852086e325034=21650=TEST52=20250411-01:51:41.447150369=46262=b7f6c79a-636c-490b-8bc5-37cb784406ba268=1279=0269=183=159757095355=BTC-USD271=0.6197183160=20250411-01:51:41.44599940=137=ee4dcec3-4f4e-4b62-93a6-4cdafb431b2910=198
20250411-01:51:41.562712000 : 8=FIXT.1.19=32735=X49=Coinbase56=24ab46f784d1b20db435b852086e325034=21750=TEST52=20250411-01:51:41.447191369=46262=b7f6c79a-636c-490b-8bc5-37cb784406ba268=1279=0269=2278=4d60a78e-b39b-420e-b830-bc0f3f4fdde283=159757095455=BTC-USD270=3.53271=0.6197183160=20250411-01:51:41.44599937=ee4dcec3-4f4e-4b62-93a6-4cdafb431b295797=210=192
20250411-01:51:41.564358000 : 8=FIXT.1.19=28135=X49=Coinbase56=24ab46f784d1b20db435b852086e325034=21850=TEST52=20250411-01:51:41.447198369=46262=b7f6c79a-636c-490b-8bc5-37cb784406ba268=1279=2269=1278=ee4dcec3-4f4e-4b62-93a6-4cdafb431b2983=159757095555=BTC-USD271=0.0000000060=20250411-01:51:41.44599958=FILLED10=112
20250411-01:51:41.722717000 : 8=FIXT.1.19=27935=X49=Coinbase56=24ab46f784d1b20db435b852086e325034=21950=TEST52=20250411-01:51:41.590029369=46262=b7f6c79a-636c-490b-8bc5-37cb784406ba268=1279=0269=083=159757095655=BTC-USD29004=2.208895519560=20250411-01:51:41.58838140=137=74466a36-611d-40ae-8e09-f6e33c69731310=046
20250411-01:51:41.723403000 : 8=FIXT.1.19=32735=X49=Coinbase56=24ab46f784d1b20db435b852086e325034=22050=TEST52=20250411-01:51:41.590041369=46262=b7f6c79a-636c-490b-8bc5-37cb784406ba268=1279=0269=2278=c5b88ea9-605d-4595-ac52-f7c3f08523ba83=159757095755=BTC-USD270=3.55271=0.6222240960=20250411-01:51:41.58838137=74466a36-611d-40ae-8e09-f6e33c6973135797=110=178
20250411-01:51:41.723915000 : 8=FIXT.1.19=26635=X49=Coinbase56=24ab46f784d1b20db435b852086e325034=22150=TEST52=20250411-01:51:41.590043369=46262=b7f6c79a-636c-490b-8bc5-37cb784406ba268=1279=2269=0278=74466a36-611d-40ae-8e09-f6e33c69731383=159757095855=BTC-USD60=20250411-01:51:41.58838158=FILLED10=049
20250411-01:51:41.734702000 : 8=FIXT.1.19=27535=X49=Coinbase56=24ab46f784d1b20db435b852086e325034=22250=TEST52=20250411-01:51:41.618986369=46262=b7f6c79a-636c-490b-8bc5-37cb784406ba268=1279=0269=183=159757095955=BTC-USD271=0.6232294660=20250411-01:51:41.61783040=137=f531d227-5f7d-4f40-b3b9-1e323c332b2510=160
20250411-01:51:41.735228000 : 8=FIXT.1.19=32735=X49=Coinbase56=24ab46f784d1b20db435b852086e325034=22350=TEST52=20250411-01:51:41.618993369=46262=b7f6c79a-636c-490b-8bc5-37cb784406ba268=1279=0269=2278=4d60a78e-b39b-420e-b830-bc0f3f4fdde283=159757096055=BTC-USD270=3.53271=0.6232294660=20250411-01:51:41.61783037=f531d227-5f7d-4f40-b3b9-1e323c332b255797=210=138
20250411-01:51:41.737454000 : 8=FIXT.1.19=28135=X49=Coinbase56=24ab46f784d1b20db435b852086e325034=22450=TEST52=20250411-01:51:41.619054369=46262=b7f6c79a-636c-490b-8bc5-37cb784406ba268=1279=2269=1278=f531d227-5f7d-4f40-b3b9-1e323c332b2583=159757096155=BTC-USD271=0.0000000060=20250411-01:51:41.61783058=FILLED10=042
20250411-01:51:42.105724000 : 8=FIXT.1.19=27935=X49=Coinbase56=24ab46f784d1b20db435b852086e325034=22550=TEST52=20250411-01:51:41.990007369=46262=b7f6c79a-636c-490b-8bc5-37cb784406ba268=1279=0269=083=159757096255=BTC-USD29004=2.208895519560=20250411-01:51:41.98822040=137=ba72eb89-5761-4b3b-85a1-2db27bce0e1410=002
20250411-01:51:42.106658000 : 8=FIXT.1.19=32735=X49=Coinbase56=24ab46f784d1b20db435b852086e325034=22650=TEST52=20250411-01:51:41.990015369=46262=b7f6c79a-636c-490b-8bc5-37cb784406ba268=1279=0269=2278=c5b88ea9-605d-4595-ac52-f7c3f08523ba83=159757096355=BTC-USD270=3.55271=0.6222240960=20250411-01:51:41.98822037=ba72eb89-5761-4b3b-85a1-2db27bce0e145797=110=148
20250411-01:51:42.109138000 : 8=FIXT.1.19=26635=X49=Coinbase56=24ab46f784d1b20db435b852086e325034=22750=TEST52=20250411-01:51:41.990017369=46262=b7f6c79a-636c-490b-8bc5-37cb784406ba268=1279=2269=0278=ba72eb89-5761-4b3b-85a1-2db27bce0e1483=159757096455=BTC-USD60=20250411-01:51:41.98822058=FILLED10=019
20250411-01:51:42.139729000 : 8=FIXT.1.19=27535=X49=Coinbase56=24ab46f784d1b20db435b852086e325034=22850=TEST52=20250411-01:51:42.019217369=46262=b7f6c79a-636c-490b-8bc5-37cb784406ba268=1279=0269=183=159757096555=BTC-USD271=0.6232294660=20250411-01:51:42.01729740=137=816964c3-5d4b-49f3-adc5-d5f57ee9feba10=166
20250411-01:51:42.140289000 : 8=FIXT.1.19=32735=X49=Coinbase56=24ab46f784d1b20db435b852086e325034=22950=TEST52=20250411-01:51:42.019275369=46262=b7f6c79a-636c-490b-8bc5-37cb784406ba268=1279=0269=2278=4d60a78e-b39b-420e-b830-bc0f3f4fdde283=159757096655=BTC-USD270=3.53271=0.6232294660=20250411-01:51:42.01729737=816964c3-5d4b-49f3-adc5-d5f57ee9feba5797=210=159
20250411-01:51:42.142260000 : 8=FIXT.1.19=28135=X49=Coinbase56=24ab46f784d1b20db435b852086e325034=23050=TEST52=20250411-01:51:42.019284369=46262=b7f6c79a-636c-490b-8bc5-37cb784406ba268=1279=2269=1278=816964c3-5d4b-49f3-adc5-d5f57ee9feba83=159757096755=BTC-USD271=0.0000000060=20250411-01:51:42.01729758=FILLED10=065
20250411-01:51:42.246508000 : 8=FIXT.1.19=28435=X49=Coinbase56=24ab46f784d1b20db435b852086e325034=23150=TEST52=20250411-01:51:42.045534369=46262=b7f6c79a-636c-490b-8bc5-37cb784406ba268=1279=0269=083=159757096855=BTC-USD270=3.74271=0.6232294660=20250411-01:51:42.04426940=237=bc80bebf-5a0d-466c-8769-06c1741d3f2410=160
20250411-01:51:42.247049000 : 8=FIXT.1.19=32735=X49=Coinbase56=24ab46f784d1b20db435b852086e325034=23250=TEST52=20250411-01:51:42.045541369=46262=b7f6c79a-636c-490b-8bc5-37cb784406ba268=1279=0269=2278=c5b88ea9-605d-4595-ac52-f7c3f08523ba83=159757096955=BTC-USD270=3.55271=0.6232294660=20250411-01:51:42.04426937=bc80bebf-5a0d-466c-8769-06c1741d3f245797=110=113
20250411-01:51:42.248798000 : 8=FIXT.1.19=29035=X49=Coinbase56=24ab46f784d1b20db435b852086e325034=23350=TEST52=20250411-01:51:42.045545369=46262=b7f6c79a-636c-490b-8bc5-37cb784406ba268=1279=2269=0278=bc80bebf-5a0d-466c-8769-06c1741d3f2483=159757097055=BTC-USD270=3.74271=0.0000000060=20250411-01:51:42.04426958=FILLED10=056
20250411-01:51:42.249143000 : 8=FIXT.1.19=28435=X49=Coinbase56=24ab46f784d1b20db435b852086e325034=23450=TEST52=20250411-01:51:42.102359369=46262=b7f6c79a-636c-490b-8bc5-37cb784406ba268=1279=0269=183=159757097155=BTC-USD270=3.24271=0.6232294660=20250411-01:51:42.10035840=237=a40fb3e5-5d41-4d55-a624-9168e10d792c10=046
20250411-01:51:42.249405000 : 8=FIXT.1.19=32735=X49=Coinbase56=24ab46f784d1b20db435b852086e325034=23550=TEST52=20250411-01:51:42.102367369=46262=b7f6c79a-636c-490b-8bc5-37cb784406ba268=1279=0269=2278=4d60a78e-b39b-420e-b830-bc0f3f4fdde283=159757097255=BTC-USD270=3.53271=0.6232294660=20250411-01:51:42.10035837=a40fb3e5-5d41-4d55-a624-9168e10d792c5797=210=131
20250411-01:51:42.252181000 : 8=FIXT.1.19=29035=X49=Coinbase56=24ab46f784d1b20db435b852086e325034=23650=TEST52=20250411-01:51:42.102370369=46262=b7f6c79a-636c-490b-8bc5-37cb784406ba268=1279=2269=1278=a40fb3e5-5d41-4d55-a624-9168e10d792c83=159757097355=BTC-USD270=3.24271=0.0000000060=20250411-01:51:42.10035858=FILLED10=198
20250411-01:51:42.450372000 : 8=FIXT.1.19=28435=X49=Coinbase56=24ab46f784d1b20db435b852086e325034=23750=TEST52=20250411-01:51:42.333751369=46262=b7f6c79a-636c-490b-8bc5-37cb784406ba268=1279=0269=183=159757097455=BTC-USD270=3.18271=0.6232294660=20250411-01:51:42.33268840=237=459bc6a0-bfee-44b7-b4e6-cc7deb08066510=059
20250411-01:51:42.450919000 : 8=FIXT.1.19=32735=X49=Coinbase56=24ab46f784d1b20db435b852086e325034=23850=TEST52=20250411-01:51:42.333762369=46262=b7f6c79a-636c-490b-8bc5-37cb784406ba268=1279=0269=2278=4d60a78e-b39b-420e-b830-bc0f3f4fdde283=159757097555=BTC-USD270=3.53271=0.6232294660=20250411-01:51:42.33268837=459bc6a0-bfee-44b7-b4e6-cc7deb0806655797=210=144
20250411-01:51:42.454229000 : 8=FIXT.1.19=29035=X49=Coinbase56=24ab46f784d1b20db435b852086e325034=23950=TEST52=20250411-01:51:42.333867369=46262=b7f6c79a-636c-490b-8bc5-37cb784406ba268=1279=2269=1278=459bc6a0-bfee-44b7-b4e6-cc7deb08066583=159757097655=BTC-USD270=3.18271=0.0000000060=20250411-01:51:42.33268858=FILLED10=226
20250411-01:51:42.509093000 : 8=FIXT.1.19=27935=X49=Coinbase56=24ab46f784d1b20db435b852086e325034=24050=TEST52=20250411-01:51:42.389766369=46262=b7f6c79a-636c-490b-8bc5-37cb784406ba268=1279=0269=083=159757097755=BTC-USD29004=2.208895519560=20250411-01:51:42.38781040=137=693f9a23-6e59-4d36-b9cc-60eb47c88caf10=052
20250411-01:51:42.509671000 : 8=FIXT.1.19=32735=X49=Coinbase56=24ab46f784d1b20db435b852086e325034=24150=TEST52=20250411-01:51:42.389770369=46262=b7f6c79a-636c-490b-8bc5-37cb784406ba268=1279=0269=2278=c5b88ea9-605d-4595-ac52-f7c3f08523ba83=159757097855=BTC-USD270=3.55271=0.6222240960=20250411-01:51:42.38781037=693f9a23-6e59-4d36-b9cc-60eb47c88caf5797=110=194
20250411-01:51:42.511653000 : 8=FIXT.1.19=26635=X49=Coinbase56=24ab46f784d1b20db435b852086e325034=24250=TEST52=20250411-01:51:42.389772369=46262=b7f6c79a-636c-490b-8bc5-37cb784406ba268=1279=2269=0278=693f9a23-6e59-4d36-b9cc-60eb47c88caf83=159757097955=BTC-USD60=20250411-01:51:42.38781058=FILLED10=065
20250411-01:51:42.536087000 : 8=FIXT.1.19=27535=X49=Coinbase56=24ab46f784d1b20db435b852086e325034=24350=TEST52=20250411-01:51:42.420004369=46262=b7f6c79a-636c-490b-8bc5-37cb784406ba268=1279=0269=183=159757098055=BTC-USD271=0.6232294660=20250411-01:51:42.41822940=137=7dfcf42f-0290-4506-bc43-786917a866ef10=162
20250411-01:51:42.536567000 : 8=FIXT.1.19=32735=X49=Coinbase56=24ab46f784d1b20db435b852086e325034=24450=TEST52=20250411-01:51:42.420010369=46262=b7f6c79a-636c-490b-8bc5-37cb784406ba268=1279=0269=2278=4d60a78e-b39b-420e-b830-bc0f3f4fdde283=159757098155=BTC-USD270=3.53271=0.6232294660=20250411-01:51:42.41822937=7dfcf42f-0290-4506-bc43-786917a866ef5797=210=148
20250411-01:51:42.538505000 : 8=FIXT.1.19=28135=X49=Coinbase56=24ab46f784d1b20db435b852086e325034=24550=TEST52=20250411-01:51:42.420014369=46262=b7f6c79a-636c-490b-8bc5-37cb784406ba268=1279=2269=1278=7dfcf42f-0290-4506-bc43-786917a866ef83=159757098255=BTC-USD271=0.0000000060=20250411-01:51:42.41822958=FILLED10=067
20250411-01:51:43.145165000 : 8=FIXT.1.19=27935=X49=Coinbase56=24ab46f784d1b20db435b852086e325034=24650=TEST52=20250411-01:51:43.018255369=46262=b7f6c79a-636c-490b-8bc5-37cb784406ba268=1279=0269=083=159757098355=BTC-USD29004=2.208895519560=20250411-01:51:43.01724440=137=42acfeee-9ad8-4e55-a0f6-aaa86d3697ec10=210
20250411-01:51:43.145834000 : 8=FIXT.1.19=32735=X49=Coinbase56=24ab46f784d1b20db435b852086e325034=24750=TEST52=20250411-01:51:43.018268369=46262=b7f6c79a-636c-490b-8bc5-37cb784406ba268=1279=0269=2278=c5b88ea9-605d-4595-ac52-f7c3f08523ba83=159757098455=BTC-USD270=3.55271=0.6222240960=20250411-01:51:43.01724437=42acfeee-9ad8-4e55-a0f6-aaa86d3697ec5797=110=105
20250411-01:51:43.147731000 : 8=FIXT.1.19=26635=X49=Coinbase56=24ab46f784d1b20db435b852086e325034=24850=TEST52=20250411-01:51:43.018271369=46262=b7f6c79a-636c-490b-8bc5-37cb784406ba268=1279=2269=0278=42acfeee-9ad8-4e55-a0f6-aaa86d3697ec83=159757098555=BTC-USD60=20250411-01:51:43.01724458=FILLED10=224
20250411-01:51:43.163277000 : 8=FIXT.1.19=27535=X49=Coinbase56=24ab46f784d1b20db435b852086e325034=24950=TEST52=20250411-01:51:43.046871369=46262=b7f6c79a-636c-490b-8bc5-37cb784406ba268=1279=0269=183=159757098655=BTC-USD271=0.6232294660=20250411-01:51:43.04552340=137=3680be1f-4721-4621-87f1-f3f118be175010=068
20250411-01:51:43.163653000 : 8=FIXT.1.19=32735=X49=Coinbase56=24ab46f784d1b20db435b852086e325034=25050=TEST52=20250411-01:51:43.046877369=46262=b7f6c79a-636c-490b-8bc5-37cb784406ba268=1279=0269=2278=4d60a78e-b39b-420e-b830-bc0f3f4fdde283=159757098755=BTC-USD270=3.53271=0.6232294660=20250411-01:51:43.04552337=3680be1f-4721-4621-87f1-f3f118be17505797=210=054
20250411-01:51:43.165595000 : 8=FIXT.1.19=28135=X49=Coinbase56=24ab46f784d1b20db435b852086e325034=25150=TEST52=20250411-01:51:43.046915369=46262=b7f6c79a-636c-490b-8bc5-37cb784406ba268=1279=2269=1278=3680be1f-4721-4621-87f1-f3f118be175083=159757098855=BTC-USD271=0.0000000060=20250411-01:51:43.04552358=FILLED10=218
20250411-01:51:43.556362000 : 8=FIXT.1.19=28435=X49=Coinbase56=24ab46f784d1b20db435b852086e325034=25250=TEST52=20250411-01:51:43.334537369=46262=b7f6c79a-636c-490b-8bc5-37cb784406ba268=1279=0269=083=159757098955=BTC-USD270=3.88271=0.6232294660=20250411-01:51:43.33282140=237=3b4e2ec0-561d-4c8d-b0e4-6fd2c149945d10=218
20250411-01:51:43.557058000 : 8=FIXT.1.19=32735=X49=Coinbase56=24ab46f784d1b20db435b852086e325034=25350=TEST52=20250411-01:51:43.334683369=46262=b7f6c79a-636c-490b-8bc5-37cb784406ba268=1279=0269=2278=c5b88ea9-605d-4595-ac52-f7c3f08523ba83=159757099055=BTC-USD270=3.55271=0.6232294660=20250411-01:51:43.33282137=3b4e2ec0-561d-4c8d-b0e4-6fd2c149945d5797=110=161
20250411-01:51:43.558931000 : 8=FIXT.1.19=29035=X49=Coinbase56=24ab46f784d1b20db435b852086e325034=25450=TEST52=20250411-01:51:43.334686369=46262=b7f6c79a-636c-490b-8bc5-37cb784406ba268=1279=2269=0278=3b4e2ec0-561d-4c8d-b0e4-6fd2c149945d83=159757099155=BTC-USD270=3.88271=0.0000000060=20250411-01:51:43.33282158=FILLED10=117
20250411-01:51:43.559170000 : 8=FIXT.1.19=27935=X49=Coinbase56=24ab46f784d1b20db435b852086e325034=25550=TEST52=20250411-01:51:43.360922369=46262=b7f6c79a-636c-490b-8bc5-37cb784406ba268=1279=0269=083=159757099255=BTC-USD29004=2.208895519560=20250411-01:51:43.35931240=137=3313f95e-b608-4f55-958d-467476630b3310=209
20250411-01:51:43.559365000 : 8=FIXT.1.19=32735=X49=Coinbase56=24ab46f784d1b20db435b852086e325034=25650=TEST52=20250411-01:51:43.361024369=46262=b7f6c79a-636c-490b-8bc5-37cb784406ba268=1279=0269=2278=c5b88ea9-605d-4595-ac52-f7c3f08523ba83=159757099355=BTC-USD270=3.55271=0.6222240960=20250411-01:51:43.35931237=3313f95e-b608-4f55-958d-467476630b335797=110=094
20250411-01:51:43.559533000 : 8=FIXT.1.19=26635=X49=Coinbase56=24ab46f784d1b20db435b852086e325034=25750=TEST52=20250411-01:51:43.361028369=46262=b7f6c79a-636c-490b-8bc5-37cb784406ba268=1279=2269=0278=3313f95e-b608-4f55-958d-467476630b3383=159757099455=BTC-USD60=20250411-01:51:43.35931258=FILLED10=223
20250411-01:51:43.560642000 : 8=FIXT.1.19=27535=X49=Coinbase56=24ab46f784d1b20db435b852086e325034=25850=TEST52=20250411-01:51:43.389437369=46262=b7f6c79a-636c-490b-8bc5-37cb784406ba268=1279=0269=183=159757099555=BTC-USD271=0.6232294660=20250411-01:51:43.38766140=137=b6ce4664-991b-4d58-9161-eaa9d7fddecf10=193
20250411-01:51:43.560842000 : 8=FIXT.1.19=32735=X49=Coinbase56=24ab46f784d1b20db435b852086e325034=25950=TEST52=20250411-01:51:43.389444369=46262=b7f6c79a-636c-490b-8bc5-37cb784406ba268=1279=0269=2278=4d60a78e-b39b-420e-b830-bc0f3f4fdde283=159757099655=BTC-USD270=3.53271=0.6232294660=20250411-01:51:43.38766137=b6ce4664-991b-4d58-9161-eaa9d7fddecf5797=210=180
20250411-01:51:43.561082000 : 8=FIXT.1.19=28135=X49=Coinbase56=24ab46f784d1b20db435b852086e325034=26050=TEST52=20250411-01:51:43.389447369=46262=b7f6c79a-636c-490b-8bc5-37cb784406ba268=1279=2269=1278=b6ce4664-991b-4d58-9161-eaa9d7fddecf83=159757099755=BTC-USD271=0.0000000060=20250411-01:51:43.38766158=FILLED10=089
20250411-01:51:43.592980000 : 8=FIXT.1.19=27935=X49=Coinbase56=24ab46f784d1b20db435b852086e325034=26150=TEST52=20250411-01:51:43.476073369=46262=b7f6c79a-636c-490b-8bc5-37cb784406ba268=1279=0269=083=159757099855=BTC-USD29004=2.208895519560=20250411-01:51:43.47410840=137=3d9f285a-362f-4505-84d1-86ee363a098d10=102
20250411-01:51:43.593416000 : 8=FIXT.1.19=32735=X49=Coinbase56=24ab46f784d1b20db435b852086e325034=26250=TEST52=20250411-01:51:43.476084369=46262=b7f6c79a-636c-490b-8bc5-37cb784406ba268=1279=0269=2278=c5b88ea9-605d-4595-ac52-f7c3f08523ba83=159757099955=BTC-USD270=3.55271=0.6222240960=20250411-01:51:43.47410837=3d9f285a-362f-4505-84d1-86ee363a098d5797=110=251
20250411-01:51:43.593637000 : 8=FIXT.1.19=26635=X49=Coinbase56=24ab46f784d1b20db435b852086e325034=26350=TEST52=20250411-01:51:43.476087369=46262=b7f6c79a-636c-490b-8bc5-37cb784406ba268=1279=2269=0278=3d9f285a-362f-4505-84d1-86ee363a098d83=159757100055=BTC-USD60=20250411-01:51:43.47410858=FILLED10=096
20250411-01:51:43.620098000 : 8=FIXT.1.19=27535=X49=Coinbase56=24ab46f784d1b20db435b852086e325034=26450=TEST52=20250411-01:51:43.504484369=46262=b7f6c79a-636c-490b-8bc5-37cb784406ba268=1279=0269=183=159757100155=BTC-USD271=0.6232294660=20250411-01:51:43.50268740=137=249c0a51-f87b-4d9a-a621-b591bbb8965310=201
20250411-01:51:43.620684000 : 8=FIXT.1.19=32735=X49=Coinbase56=24ab46f784d1b20db435b852086e325034=26550=TEST52=20250411-01:51:43.504492369=46262=b7f6c79a-636c-490b-8bc5-37cb784406ba268=1279=0269=2278=4d60a78e-b39b-420e-b830-bc0f3f4fdde283=159757100255=BTC-USD270=3.53271=0.6232294660=20250411-01:51:43.50268737=249c0a51-f87b-4d9a-a621-b591bbb896535797=210=189
20250411-01:51:43.620950000 : 8=FIXT.1.19=28135=X49=Coinbase56=24ab46f784d1b20db435b852086e325034=26650=TEST52=20250411-01:51:43.504495369=46262=b7f6c79a-636c-490b-8bc5-37cb784406ba268=1279=2269=1278=249c0a51-f87b-4d9a-a621-b591bbb8965383=159757100355=BTC-USD271=0.0000000060=20250411-01:51:43.50268758=FILLED10=107
20250411-01:51:43.647997000 : 8=FIXT.1.19=28435=X49=Coinbase56=24ab46f784d1b20db435b852086e325034=26750=TEST52=20250411-01:51:43.530935369=46262=b7f6c79a-636c-490b-8bc5-37cb784406ba268=1279=0269=083=159757100455=BTC-USD270=3.74271=0.6232294660=20250411-01:51:43.52966040=237=4b184dc1-aa9e-4263-8a66-e73373adb2a810=157
20250411-01:51:43.648462000 : 8=FIXT.1.19=32735=X49=Coinbase56=24ab46f784d1b20db435b852086e325034=26850=TEST52=20250411-01:51:43.530943369=46262=b7f6c79a-636c-490b-8bc5-37cb784406ba268=1279=0269=2278=c5b88ea9-605d-4595-ac52-f7c3f08523ba83=159757100555=BTC-USD270=3.55271=0.6232294660=20250411-01:51:43.52966037=4b184dc1-aa9e-4263-8a66-e73373adb2a85797=110=111
20250411-01:51:43.648684000 : 8=FIXT.1.19=29035=X49=Coinbase56=24ab46f784d1b20db435b852086e325034=26950=TEST52=20250411-01:51:43.530946369=46262=b7f6c79a-636c-490b-8bc5-37cb784406ba268=1279=2269=0278=4b184dc1-aa9e-4263-8a66-e73373adb2a883=159757100655=BTC-USD270=3.74271=0.0000000060=20250411-01:51:43.52966058=FILLED10=062
20250411-01:51:43.704229000 : 8=FIXT.1.19=28435=X49=Coinbase56=24ab46f784d1b20db435b852086e325034=27050=TEST52=20250411-01:51:43.586876369=46262=b7f6c79a-636c-490b-8bc5-37cb784406ba268=1279=0269=183=159757100755=BTC-USD270=3.18271=0.6232294660=20250411-01:51:43.58560440=237=75ed8d59-d6d9-41b0-822c-db8f175ec9fa10=032
20250411-01:51:43.705960000 : 8=FIXT.1.19=32735=X49=Coinbase56=24ab46f784d1b20db435b852086e325034=27150=TEST52=20250411-01:51:43.586882369=46262=b7f6c79a-636c-490b-8bc5-37cb784406ba268=1279=0269=2278=4d60a78e-b39b-420e-b830-bc0f3f4fdde283=159757100855=BTC-USD270=3.53271=0.6232294660=20250411-01:51:43.58560437=75ed8d59-d6d9-41b0-822c-db8f175ec9fa5797=210=112
20250411-01:51:43.706178000 : 8=FIXT.1.19=29035=X49=Coinbase56=24ab46f784d1b20db435b852086e325034=27250=TEST52=20250411-01:51:43.586885369=46262=b7f6c79a-636c-490b-8bc5-37cb784406ba268=1279=2269=1278=75ed8d59-d6d9-41b0-822c-db8f175ec9fa83=159757100955=BTC-USD270=3.18271=0.0000000060=20250411-01:51:43.58560458=FILLED10=191
20250411-01:51:43.821674000 : 8=FIXT.1.19=27935=X49=Coinbase56=24ab46f784d1b20db435b852086e325034=27350=TEST52=20250411-01:51:43.705149369=46262=b7f6c79a-636c-490b-8bc5-37cb784406ba268=1279=0269=083=159757101055=BTC-USD29004=2.208895519560=20250411-01:51:43.70354040=137=3db9aae5-77db-4bf0-b588-da134fe103de10=133
20250411-01:51:43.822231000 : 8=FIXT.1.19=32735=X49=Coinbase56=24ab46f784d1b20db435b852086e325034=27450=TEST52=20250411-01:51:43.705188369=46262=b7f6c79a-636c-490b-8bc5-37cb784406ba268=1279=0269=2278=c5b88ea9-605d-4595-ac52-f7c3f08523ba83=159757101155=BTC-USD270=3.55271=0.6222240960=20250411-01:51:43.70354037=3db9aae5-77db-4bf0-b588-da134fe103de5797=110=027
20250411-01:51:43.822643000 : 8=FIXT.1.19=26635=X49=Coinbase56=24ab46f784d1b20db435b852086e325034=27550=TEST52=20250411-01:51:43.705194369=46262=b7f6c79a-636c-490b-8bc5-37cb784406ba268=1279=2269=0278=3db9aae5-77db-4bf0-b588-da134fe103de83=159757101255=BTC-USD60=20250411-01:51:43.70354058=FILLED10=149
20250411-01:51:43.853249000 : 8=FIXT.1.19=27535=X49=Coinbase56=24ab46f784d1b20db435b852086e325034=27650=TEST52=20250411-01:51:43.735762369=46262=b7f6c79a-636c-490b-8bc5-37cb784406ba268=1279=0269=183=159757101355=BTC-USD271=0.6232294660=20250411-01:51:43.73395840=137=10529297-3867-4d42-b612-eb3fdef8139810=089
20250411-01:51:43.853695000 : 8=FIXT.1.19=32735=X49=Coinbase56=24ab46f784d1b20db435b852086e325034=27750=TEST52=20250411-01:51:43.735819369=46262=b7f6c79a-636c-490b-8bc5-37cb784406ba268=1279=0269=2278=4d60a78e-b39b-420e-b830-bc0f3f4fdde283=159757101455=BTC-USD270=3.53271=0.6232294660=20250411-01:51:43.73395837=10529297-3867-4d42-b612-eb3fdef813985797=210=081
20250411-01:51:43.853856000 : 8=FIXT.1.19=28135=X49=Coinbase56=24ab46f784d1b20db435b852086e325034=27850=TEST52=20250411-01:51:43.735821369=46262=b7f6c79a-636c-490b-8bc5-37cb784406ba268=1279=2269=1278=10529297-3867-4d42-b612-eb3fdef8139883=159757101555=BTC-USD271=0.0000000060=20250411-01:51:43.73395858=FILLED10=245
20250411-01:51:44.132386000 : 8=FIXT.1.19=28435=X49=Coinbase56=24ab46f784d1b20db435b852086e325034=27950=TEST52=20250411-01:51:44.014749369=46262=b7f6c79a-636c-490b-8bc5-37cb784406ba268=1279=0269=183=159757101655=BTC-USD270=3.54271=0.6232294660=20250411-01:51:44.01361140=237=6502b177-70f1-4e62-8865-7f2fe0fb5c2c10=062
20250411-01:51:44.132988000 : 8=FIXT.1.19=28035=X49=Coinbase56=24ab46f784d1b20db435b852086e325034=28050=TEST52=20250411-01:51:44.014760369=46262=b7f6c79a-636c-490b-8bc5-37cb784406ba268=1279=0269=1278=6502b177-70f1-4e62-8865-7f2fe0fb5c2c83=159757101755=BTC-USD270=3.54271=0.6232294660=20250411-01:51:44.01361110=143
20250411-01:51:44.347711000 : 8=FIXT.1.19=27935=X49=Coinbase56=24ab46f784d1b20db435b852086e325034=28150=TEST52=20250411-01:51:44.218323369=46262=b7f6c79a-636c-490b-8bc5-37cb784406ba268=1279=0269=083=159757101855=BTC-USD29004=2.208895533960=20250411-01:51:44.21633840=137=1e7aab44-e30f-4c73-b9f7-0a058d14c3f310=247
20250411-01:51:44.348105000 : 8=FIXT.1.19=32735=X49=Coinbase56=24ab46f784d1b20db435b852086e325034=28250=TEST52=20250411-01:51:44.218333369=46262=b7f6c79a-636c-490b-8bc5-37cb784406ba268=1279=0269=2278=6502b177-70f1-4e62-8865-7f2fe0fb5c2c83=159757101955=BTC-USD270=3.54271=0.6232294660=20250411-01:51:44.21633837=1e7aab44-e30f-4c73-b9f7-0a058d14c3f35797=110=048
20250411-01:51:44.348275000 : 8=FIXT.1.19=29035=X49=Coinbase56=24ab46f784d1b20db435b852086e325034=28350=TEST52=20250411-01:51:44.218337369=46262=b7f6c79a-636c-490b-8bc5-37cb784406ba268=1279=2269=1278=6502b177-70f1-4e62-8865-7f2fe0fb5c2c83=159757102055=BTC-USD270=3.54271=0.0000000060=20250411-01:51:44.21633858=FILLED10=217
20250411-01:51:44.349331000 : 8=FIXT.1.19=32735=X49=Coinbase56=24ab46f784d1b20db435b852086e325034=28450=TEST52=20250411-01:51:44.218340369=46262=b7f6c79a-636c-490b-8bc5-37cb784406ba268=1279=0269=2278=c5b88ea9-605d-4595-ac52-f7c3f08523ba83=159757102155=BTC-USD270=3.55271=0.0007502160=20250411-01:51:44.21633837=1e7aab44-e30f-4c73-b9f7-0a058d14c3f35797=110=120
20250411-01:51:44.350021000 : 8=FIXT.1.19=26635=X49=Coinbase56=24ab46f784d1b20db435b852086e325034=28550=TEST52=20250411-01:51:44.218342369=46262=b7f6c79a-636c-490b-8bc5-37cb784406ba268=1279=2269=0278=1e7aab44-e30f-4c73-b9f7-0a058d14c3f383=159757102255=BTC-USD60=20250411-01:51:44.21633858=FILLED10=003
20250411-01:51:44.350200000 : 8=FIXT.1.19=28435=X49=Coinbase56=24ab46f784d1b20db435b852086e325034=28650=TEST52=20250411-01:51:44.218453369=46262=b7f6c79a-636c-490b-8bc5-37cb784406ba268=1279=0269=083=159757102355=BTC-USD270=3.72271=0.6232294660=20250411-01:51:44.21671440=237=f5e989fb-86cd-4476-b284-3091eaa487ca10=176
20250411-01:51:44.351861000 : 8=FIXT.1.19=32735=X49=Coinbase56=24ab46f784d1b20db435b852086e325034=28750=TEST52=20250411-01:51:44.218458369=46262=b7f6c79a-636c-490b-8bc5-37cb784406ba268=1279=0269=2278=c5b88ea9-605d-4595-ac52-f7c3f08523ba83=159757102455=BTC-USD270=3.55271=0.6232294660=20250411-01:51:44.21671437=f5e989fb-86cd-4476-b284-3091eaa487ca5797=110=138
20250411-01:51:44.352110000 : 8=FIXT.1.19=29035=X49=Coinbase56=24ab46f784d1b20db435b852086e325034=28850=TEST52=20250411-01:51:44.218460369=46262=b7f6c79a-636c-490b-8bc5-37cb784406ba268=1279=2269=0278=f5e989fb-86cd-4476-b284-3091eaa487ca83=159757102555=BTC-USD270=3.72271=0.0000000060=20250411-01:51:44.21671458=FILLED10=077
20250411-01:51:44.366599000 : 8=FIXT.1.19=27535=X49=Coinbase56=24ab46f784d1b20db435b852086e325034=28950=TEST52=20250411-01:51:44.250649369=46262=b7f6c79a-636c-490b-8bc5-37cb784406ba268=1279=0269=183=159757102655=BTC-USD271=0.6232294660=20250411-01:51:44.24918440=137=3f4222d8-fbc7-4b7f-b014-e60b6b33238e10=000
20250411-01:51:44.366914000 : 8=FIXT.1.19=32735=X49=Coinbase56=24ab46f784d1b20db435b852086e325034=29050=TEST52=20250411-01:51:44.250770369=46262=b7f6c79a-636c-490b-8bc5-37cb784406ba268=1279=0269=2278=4d60a78e-b39b-420e-b830-bc0f3f4fdde283=159757102755=BTC-USD270=3.53271=0.6232294660=20250411-01:51:44.24918437=3f4222d8-fbc7-4b7f-b014-e60b6b33238e5797=210=231
20250411-01:51:44.367080000 : 8=FIXT.1.19=28135=X49=Coinbase56=24ab46f784d1b20db435b852086e325034=29150=TEST52=20250411-01:51:44.250773369=46262=b7f6c79a-636c-490b-8bc5-37cb784406ba268=1279=2269=1278=3f4222d8-fbc7-4b7f-b014-e60b6b33238e83=159757102855=BTC-USD271=0.0000000060=20250411-01:51:44.24918458=FILLED10=149
20250411-01:51:44.388060000 : 8=FIXT.1.19=28335=X49=Coinbase56=24ab46f784d1b20db435b852086e325034=29250=TEST52=20250411-01:51:44.272690369=46262=b7f6c79a-636c-490b-8bc5-37cb784406ba268=1279=0269=183=159757102955=BTC-USD270=3.3271=0.6232294660=20250411-01:51:44.27138240=237=8dd1e3c6-b6a6-4db2-b45a-951cef96d2b410=252
20250411-01:51:44.388396000 : 8=FIXT.1.19=32735=X49=Coinbase56=24ab46f784d1b20db435b852086e325034=29350=TEST52=20250411-01:51:44.272800369=46262=b7f6c79a-636c-490b-8bc5-37cb784406ba268=1279=0269=2278=4d60a78e-b39b-420e-b830-bc0f3f4fdde283=159757103055=BTC-USD270=3.53271=0.6232294660=20250411-01:51:44.27138237=8dd1e3c6-b6a6-4db2-b45a-951cef96d2b45797=210=118
20250411-01:51:44.389364000 : 8=FIXT.1.19=28935=X49=Coinbase56=24ab46f784d1b20db435b852086e325034=29450=TEST52=20250411-01:51:44.272843369=46262=b7f6c79a-636c-490b-8bc5-37cb784406ba268=1279=2269=1278=8dd1e3c6-b6a6-4db2-b45a-951cef96d2b483=159757103155=BTC-USD270=3.3271=0.0000000060=20250411-01:51:44.27138258=FILLED10=155
20250411-01:51:44.428621000 : 8=FIXT.1.19=28435=X49=Coinbase56=24ab46f784d1b20db435b852086e325034=29550=TEST52=20250411-01:51:44.300263369=46262=b7f6c79a-636c-490b-8bc5-37cb784406ba268=1279=0269=083=159757103255=BTC-USD270=3.52271=0.6232294660=20250411-01:51:44.29861140=237=afde9fae-6294-4d52-9f0a-0ce7b8972fff10=106
20250411-01:51:44.431260000 : 8=FIXT.1.19=28035=X49=Coinbase56=24ab46f784d1b20db435b852086e325034=29650=TEST52=20250411-01:51:44.300269369=46262=b7f6c79a-636c-490b-8bc5-37cb784406ba268=1279=0269=0278=afde9fae-6294-4d52-9f0a-0ce7b8972fff83=159757103355=BTC-USD270=3.52271=0.6232294660=20250411-01:51:44.29861110=209
20250411-01:51:44.449141000 : 8=FIXT.1.19=28435=X49=Coinbase56=24ab46f784d1b20db435b852086e325034=29750=TEST52=20250411-01:51:44.332754369=46262=b7f6c79a-636c-490b-8bc5-37cb784406ba268=1279=0269=183=159757103455=BTC-USD270=3.25271=0.6232294660=20250411-01:51:44.33158740=237=1093d363-ae3e-4e04-acbf-6a7445a93d7310=157
20250411-01:51:44.449511000 : 8=FIXT.1.19=32735=X49=Coinbase56=24ab46f784d1b20db435b852086e325034=29850=TEST52=20250411-01:51:44.332758369=46262=b7f6c79a-636c-490b-8bc5-37cb784406ba268=1279=0269=2278=4d60a78e-b39b-420e-b830-bc0f3f4fdde283=159757103555=BTC-USD270=3.53271=0.6232294660=20250411-01:51:44.33158737=1093d363-ae3e-4e04-acbf-6a7445a93d735797=210=246
20250411-01:51:44.450631000 : 8=FIXT.1.19=29035=X49=Coinbase56=24ab46f784d1b20db435b852086e325034=29950=TEST52=20250411-01:51:44.332760369=46262=b7f6c79a-636c-490b-8bc5-37cb784406ba268=1279=2269=1278=1093d363-ae3e-4e04-acbf-6a7445a93d7383=159757103655=BTC-USD270=3.25271=0.0000000060=20250411-01:51:44.33158758=FILLED10=057
20250411-01:51:44.505123000 : 8=FIXT.1.19=28335=X49=Coinbase56=24ab46f784d1b20db435b852086e325034=30050=TEST52=20250411-01:51:44.387517369=46262=b7f6c79a-636c-490b-8bc5-37cb784406ba268=1279=0269=083=159757103755=BTC-USD270=3.8271=0.6232294660=20250411-01:51:44.38577740=237=8801bebc-d4ce-49be-80b3-541c89edabed10=104
20250411-01:51:44.505447000 : 8=FIXT.1.19=32735=X49=Coinbase56=24ab46f784d1b20db435b852086e325034=30150=TEST52=20250411-01:51:44.387522369=46262=b7f6c79a-636c-490b-8bc5-37cb784406ba268=1279=0269=2278=c5b88ea9-605d-4595-ac52-f7c3f08523ba83=159757103855=BTC-USD270=3.55271=0.6232294660=20250411-01:51:44.38577737=8801bebc-d4ce-49be-80b3-541c89edabed5797=110=107
20250411-01:51:44.505625000 : 8=FIXT.1.19=28935=X49=Coinbase56=24ab46f784d1b20db435b852086e325034=30250=TEST52=20250411-01:51:44.387525369=46262=b7f6c79a-636c-490b-8bc5-37cb784406ba268=1279=2269=0278=8801bebc-d4ce-49be-80b3-541c89edabed83=159757103955=BTC-USD270=3.8271=0.0000000060=20250411-01:51:44.38577758=FILLED10=015
20250411-01:51:44.906031000 : 8=FIXT.1.19=27935=X49=Coinbase56=24ab46f784d1b20db435b852086e325034=30350=TEST52=20250411-01:51:44.789942369=46262=b7f6c79a-636c-490b-8bc5-37cb784406ba268=1279=0269=083=159757104055=BTC-USD29004=2.208895519560=20250411-01:51:44.78870740=137=0b4a6fcf-4911-4ed6-98e5-9ea914f778cf10=052
20250411-01:51:44.906571000 : 8=FIXT.1.19=32735=X49=Coinbase56=24ab46f784d1b20db435b852086e325034=30450=TEST52=20250411-01:51:44.790032369=46262=b7f6c79a-636c-490b-8bc5-37cb784406ba268=1279=0269=2278=c5b88ea9-605d-4595-ac52-f7c3f08523ba83=159757104155=BTC-USD270=3.55271=0.6222240960=20250411-01:51:44.78870737=0b4a6fcf-4911-4ed6-98e5-9ea914f778cf5797=110=181
20250411-01:51:44.906805000 : 8=FIXT.1.19=26635=X49=Coinbase56=24ab46f784d1b20db435b852086e325034=30550=TEST52=20250411-01:51:44.790035369=46262=b7f6c79a-636c-490b-8bc5-37cb784406ba268=1279=2269=0278=0b4a6fcf-4911-4ed6-98e5-9ea914f778cf83=159757104255=BTC-USD60=20250411-01:51:44.78870758=FILLED10=053
20250411-01:51:44.936705000 : 8=FIXT.1.19=27535=X49=Coinbase56=24ab46f784d1b20db435b852086e325034=30650=TEST52=20250411-01:51:44.820725369=46262=b7f6c79a-636c-490b-8bc5-37cb784406ba268=1279=0269=183=159757104355=BTC-USD271=0.6197183160=20250411-01:51:44.81894140=137=1950ac9e-cb87-4bc0-9b11-098e3ecdaee710=146
20250411-01:51:44.937176000 : 8=FIXT.1.19=32735=X49=Coinbase56=24ab46f784d1b20db435b852086e325034=30750=TEST52=20250411-01:51:44.820730369=46262=b7f6c79a-636c-490b-8bc5-37cb784406ba268=1279=0269=2278=4d60a78e-b39b-420e-b830-bc0f3f4fdde283=159757104455=BTC-USD270=3.53271=0.6197183160=20250411-01:51:44.81894137=1950ac9e-cb87-4bc0-9b11-098e3ecdaee75797=210=131
20250411-01:51:44.937410000 : 8=FIXT.1.19=28135=X49=Coinbase56=24ab46f784d1b20db435b852086e325034=30850=TEST52=20250411-01:51:44.820734369=46262=b7f6c79a-636c-490b-8bc5-37cb784406ba268=1279=2269=1278=1950ac9e-cb87-4bc0-9b11-098e3ecdaee783=159757104555=BTC-USD271=0.0000000060=20250411-01:51:44.81894158=FILLED10=048
20250411-01:51:45.021789000 : 8=FIXT.1.19=28435=X49=Coinbase56=24ab46f784d1b20db435b852086e325034=30950=TEST52=20250411-01:51:44.903997369=46262=b7f6c79a-636c-490b-8bc5-37cb784406ba268=1279=0269=083=159757104655=BTC-USD270=3.81271=0.6232294660=20250411-01:51:44.90213540=237=8c7fab2c-895c-415f-abf5-4edb9ee0364710=068
20250411-01:51:45.022398000 : 8=FIXT.1.19=32735=X49=Coinbase56=24ab46f784d1b20db435b852086e325034=31050=TEST52=20250411-01:51:44.904004369=46262=b7f6c79a-636c-490b-8bc5-37cb784406ba268=1279=0269=2278=c5b88ea9-605d-4595-ac52-f7c3f08523ba83=159757104755=BTC-USD270=3.55271=0.6232294660=20250411-01:51:44.90213537=8c7fab2c-895c-415f-abf5-4edb9ee036475797=110=252
20250411-01:51:45.022608000 : 8=FIXT.1.19=29035=X49=Coinbase56=24ab46f784d1b20db435b852086e325034=31150=TEST52=20250411-01:51:44.904007369=46262=b7f6c79a-636c-490b-8bc5-37cb784406ba268=1279=2269=0278=8c7fab2c-895c-415f-abf5-4edb9ee0364783=159757104855=BTC-USD270=3.81271=0.0000000060=20250411-01:51:44.90213558=FILLED10=201
20250411-01:51:45.077399000 : 8=FIXT.1.19=28435=X49=Coinbase56=24ab46f784d1b20db435b852086e325034=31250=TEST52=20250411-01:51:44.957811369=46262=b7f6c79a-636c-490b-8bc5-37cb784406ba268=1279=0269=183=159757104955=BTC-USD270=3.29271=0.6232294660=20250411-01:51:44.95695340=237=4a415490-001a-41a6-bcb6-6c3e97b30a9410=061
20250411-01:51:45.077655000 : 8=FIXT.1.19=32735=X49=Coinbase56=24ab46f784d1b20db435b852086e325034=31350=TEST52=20250411-01:51:44.957816369=46262=b7f6c79a-636c-490b-8bc5-37cb784406ba268=1279=0269=2278=4d60a78e-b39b-420e-b830-bc0f3f4fdde283=159757105055=BTC-USD270=3.53271=0.6232294660=20250411-01:51:44.95695337=4a415490-001a-41a6-bcb6-6c3e97b30a945797=210=138
20250411-01:51:45.078647000 : 8=FIXT.1.19=29035=X49=Coinbase56=24ab46f784d1b20db435b852086e325034=31450=TEST52=20250411-01:51:44.957891369=46262=b7f6c79a-636c-490b-8bc5-37cb784406ba268=1279=2269=1278=4a415490-001a-41a6-bcb6-6c3e97b30a9483=159757105155=BTC-USD270=3.29271=0.0000000060=20250411-01:51:44.95695358=FILLED10=219
20250411-01:51:45.081003000 : 8=FIXT.1.19=27935=X49=Coinbase56=24ab46f784d1b20db435b852086e325034=31550=TEST52=20250411-01:51:44.960934369=46262=b7f6c79a-636c-490b-8bc5-37cb784406ba268=1279=0269=083=159757105255=BTC-USD29004=2.208895519560=20250411-01:51:44.95988940=137=f0b8ad6c-710b-4a3f-9d9e-786b30256ae310=035
20250411-01:51:45.081471000 : 8=FIXT.1.19=32735=X49=Coinbase56=24ab46f784d1b20db435b852086e325034=31650=TEST52=20250411-01:51:44.960941369=46262=b7f6c79a-636c-490b-8bc5-37cb784406ba268=1279=0269=2278=c5b88ea9-605d-4595-ac52-f7c3f08523ba83=159757105355=BTC-USD270=3.55271=0.6222240960=20250411-01:51:44.95988937=f0b8ad6c-710b-4a3f-9d9e-786b30256ae35797=110=180
20250411-01:51:45.081757000 : 8=FIXT.1.19=26635=X49=Coinbase56=24ab46f784d1b20db435b852086e325034=31750=TEST52=20250411-01:51:44.960944369=46262=b7f6c79a-636c-490b-8bc5-37cb784406ba268=1279=2269=0278=f0b8ad6c-710b-4a3f-9d9e-786b30256ae383=159757105455=BTC-USD60=20250411-01:51:44.95988958=FILLED10=052
20250411-01:51:45.107806000 : 8=FIXT.1.19=27535=X49=Coinbase56=24ab46f784d1b20db435b852086e325034=31850=TEST52=20250411-01:51:44.990633369=46262=b7f6c79a-636c-490b-8bc5-37cb784406ba268=1279=0269=183=159757105555=BTC-USD271=0.6197183160=20250411-01:51:44.98940140=137=ac154340-18cf-476a-8dab-d34d7b7fe39d10=110
20250411-01:51:45.108100000 : 8=FIXT.1.19=32735=X49=Coinbase56=24ab46f784d1b20db435b852086e325034=31950=TEST52=20250411-01:51:44.990639369=46262=b7f6c79a-636c-490b-8bc5-37cb784406ba268=1279=0269=2278=4d60a78e-b39b-420e-b830-bc0f3f4fdde283=159757105655=BTC-USD270=3.53271=0.6197183160=20250411-01:51:44.98940137=ac154340-18cf-476a-8dab-d34d7b7fe39d5797=210=105
20250411-01:51:45.108311000 : 8=FIXT.1.19=28135=X49=Coinbase56=24ab46f784d1b20db435b852086e325034=32050=TEST52=20250411-01:51:44.990643369=46262=b7f6c79a-636c-490b-8bc5-37cb784406ba268=1279=2269=1278=ac154340-18cf-476a-8dab-d34d7b7fe39d83=159757105755=BTC-USD271=0.0000000060=20250411-01:51:44.98940158=FILLED10=004
20250411-01:51:45.477255000 : 8=FIXT.1.19=28435=X49=Coinbase56=24ab46f784d1b20db435b852086e325034=32150=TEST52=20250411-01:51:45.361971369=46262=b7f6c79a-636c-490b-8bc5-37cb784406ba268=1279=0269=183=159757105855=BTC-USD270=3.35271=0.6232294660=20250411-01:51:45.35996540=237=7fd3b8cf-10a6-4fcf-815b-eb7f304bebf910=162
20250411-01:51:45.477918000 : 8=FIXT.1.19=32735=X49=Coinbase56=24ab46f784d1b20db435b852086e325034=32250=TEST52=20250411-01:51:45.362007369=46262=b7f6c79a-636c-490b-8bc5-37cb784406ba268=1279=0269=2278=4d60a78e-b39b-420e-b830-bc0f3f4fdde283=159757105955=BTC-USD270=3.53271=0.6232294660=20250411-01:51:45.35996537=7fd3b8cf-10a6-4fcf-815b-eb7f304bebf95797=210=237
20250411-01:51:45.479065000 : 8=FIXT.1.19=29035=X49=Coinbase56=24ab46f784d1b20db435b852086e325034=32350=TEST52=20250411-01:51:45.362016369=46262=b7f6c79a-636c-490b-8bc5-37cb784406ba268=1279=2269=1278=7fd3b8cf-10a6-4fcf-815b-eb7f304bebf983=159757106055=BTC-USD270=3.35271=0.0000000060=20250411-01:51:45.35996558=FILLED10=047
20250411-01:51:45.479307000 : 8=FIXT.1.19=28435=X49=Coinbase56=24ab46f784d1b20db435b852086e325034=32450=TEST52=20250411-01:51:45.362020369=46262=b7f6c79a-636c-490b-8bc5-37cb784406ba268=1279=0269=183=159757106155=BTC-USD270=3.24271=0.6232294660=20250411-01:51:45.35996540=237=f2b753b6-7c7f-4b73-9425-2a3f98ed641310=074
20250411-01:51:45.480168000 : 8=FIXT.1.19=32735=X49=Coinbase56=24ab46f784d1b20db435b852086e325034=32550=TEST52=20250411-01:51:45.362026369=46262=b7f6c79a-636c-490b-8bc5-37cb784406ba268=1279=0269=2278=4d60a78e-b39b-420e-b830-bc0f3f4fdde283=159757106255=BTC-USD270=3.53271=0.6232294660=20250411-01:51:45.35996537=f2b753b6-7c7f-4b73-9425-2a3f98ed64135797=210=166
20250411-01:51:45.481132000 : 8=FIXT.1.19=29035=X49=Coinbase56=24ab46f784d1b20db435b852086e325034=32650=TEST52=20250411-01:51:45.362030369=46262=b7f6c79a-636c-490b-8bc5-37cb784406ba268=1279=2269=1278=f2b753b6-7c7f-4b73-9425-2a3f98ed641383=159757106355=BTC-USD270=3.24271=0.0000000060=20250411-01:51:45.35996558=FILLED10=234
20250411-01:51:45.593419000 : 8=FIXT.1.19=28435=X49=Coinbase56=24ab46f784d1b20db435b852086e325034=32750=TEST52=20250411-01:51:45.473718369=46262=b7f6c79a-636c-490b-8bc5-37cb784406ba268=1279=0269=083=159757106455=BTC-USD270=3.73271=0.6232294660=20250411-01:51:45.47168340=237=121ec26c-109a-4efa-81fc-d32b9b64429110=160
20250411-01:51:45.594243000 : 8=FIXT.1.19=32735=X49=Coinbase56=24ab46f784d1b20db435b852086e325034=32850=TEST52=20250411-01:51:45.473726369=46262=b7f6c79a-636c-490b-8bc5-37cb784406ba268=1279=0269=2278=c5b88ea9-605d-4595-ac52-f7c3f08523ba83=159757106555=BTC-USD270=3.55271=0.6232294660=20250411-01:51:45.47168337=121ec26c-109a-4efa-81fc-d32b9b6442915797=110=115
20250411-01:51:45.594668000 : 8=FIXT.1.19=29035=X49=Coinbase56=24ab46f784d1b20db435b852086e325034=32950=TEST52=20250411-01:51:45.473730369=46262=b7f6c79a-636c-490b-8bc5-37cb784406ba268=1279=2269=0278=121ec26c-109a-4efa-81fc-d32b9b64429183=159757106655=BTC-USD270=3.73271=0.0000000060=20250411-01:51:45.47168358=FILLED10=057
20250411-01:51:45.596444000 : 8=FIXT.1.19=28435=X49=Coinbase56=24ab46f784d1b20db435b852086e325034=33050=TEST52=20250411-01:51:45.473732369=46262=b7f6c79a-636c-490b-8bc5-37cb784406ba268=1279=0269=083=159757106755=BTC-USD270=3.88271=0.6232294660=20250411-01:51:45.47168340=237=da1d5be4-28e9-4633-b904-36139198651810=200
20250411-01:51:45.597287000 : 8=FIXT.1.19=32735=X49=Coinbase56=24ab46f784d1b20db435b852086e325034=33150=TEST52=20250411-01:51:45.473879369=46262=b7f6c79a-636c-490b-8bc5-37cb784406ba268=1279=0269=2278=c5b88ea9-605d-4595-ac52-f7c3f08523ba83=159757106855=BTC-USD270=3.55271=0.6232294660=20250411-01:51:45.47168337=da1d5be4-28e9-4633-b904-3613919865185797=110=162
20250411-01:51:45.597705000 : 8=FIXT.1.19=29035=X49=Coinbase56=24ab46f784d1b20db435b852086e325034=33250=TEST52=20250411-01:51:45.473881369=46262=b7f6c79a-636c-490b-8bc5-37cb784406ba268=1279=2269=0278=da1d5be4-28e9-4633-b904-36139198651883=159757106955=BTC-USD270=3.88271=0.0000000060=20250411-01:51:45.47168358=FILLED10=108
20250411-01:51:45.763815000 : 8=FIXT.1.19=27935=X49=Coinbase56=24ab46f784d1b20db435b852086e325034=33350=TEST52=20250411-01:51:45.647133369=46262=b7f6c79a-636c-490b-8bc5-37cb784406ba268=1279=0269=083=159757107055=BTC-USD29004=2.208895519560=20250411-01:51:45.64533940=137=3cfd7780-cf56-4728-965a-5687be20f00710=095
20250411-01:51:45.764323000 : 8=FIXT.1.19=32735=X49=Coinbase56=24ab46f784d1b20db435b852086e325034=33450=TEST52=20250411-01:51:45.647145369=46262=b7f6c79a-636c-490b-8bc5-37cb784406ba268=1279=0269=2278=c5b88ea9-605d-4595-ac52-f7c3f08523ba83=159757107155=BTC-USD270=3.55271=0.6222240960=20250411-01:51:45.64533937=3cfd7780-cf56-4728-965a-5687be20f0075797=110=245
20250411-01:51:45.764528000 : 8=FIXT.1.19=26635=X49=Coinbase56=24ab46f784d1b20db435b852086e325034=33550=TEST52=20250411-01:51:45.647148369=46262=b7f6c79a-636c-490b-8bc5-37cb784406ba268=1279=2269=0278=3cfd7780-cf56-4728-965a-5687be20f00783=159757107255=BTC-USD60=20250411-01:51:45.64533958=FILLED10=117
20250411-01:51:45.792161000 : 8=FIXT.1.19=27535=X49=Coinbase56=24ab46f784d1b20db435b852086e325034=33650=TEST52=20250411-01:51:45.676680369=46262=b7f6c79a-636c-490b-8bc5-37cb784406ba268=1279=0269=183=159757107355=BTC-USD271=0.6197183160=20250411-01:51:45.67513040=137=32a96281-297f-493c-aab1-83fb5439476810=089
20250411-01:51:45.792539000 : 8=FIXT.1.19=32735=X49=Coinbase56=24ab46f784d1b20db435b852086e325034=33750=TEST52=20250411-01:51:45.676686369=46262=b7f6c79a-636c-490b-8bc5-37cb784406ba268=1279=0269=2278=4d60a78e-b39b-420e-b830-bc0f3f4fdde283=159757107455=BTC-USD270=3.53271=0.6197183160=20250411-01:51:45.67513037=32a96281-297f-493c-aab1-83fb543947685797=210=084
20250411-01:51:45.792734000 : 8=FIXT.1.19=28135=X49=Coinbase56=24ab46f784d1b20db435b852086e325034=33850=TEST52=20250411-01:51:45.676758369=46262=b7f6c79a-636c-490b-8bc5-37cb784406ba268=1279=2269=1278=32a96281-297f-493c-aab1-83fb5439476883=159757107555=BTC-USD271=0.0000000060=20250411-01:51:45.67513058=FILLED10=253
20250411-01:51:46.222142000 : 8=FIXT.1.19=27935=X49=Coinbase56=24ab46f784d1b20db435b852086e325034=33950=TEST52=20250411-01:51:46.103174369=46262=b7f6c79a-636c-490b-8bc5-37cb784406ba268=1279=0269=083=159757107655=BTC-USD29004=2.208895519560=20250411-01:51:46.10240840=137=bd07b88e-4fb1-408e-a347-e27248fb22dd10=003
20250411-01:51:46.222601000 : 8=FIXT.1.19=32735=X49=Coinbase56=24ab46f784d1b20db435b852086e325034=34050=TEST52=20250411-01:51:46.103313369=46262=b7f6c79a-636c-490b-8bc5-37cb784406ba268=1279=0269=2278=c5b88ea9-605d-4595-ac52-f7c3f08523ba83=159757107755=BTC-USD270=3.55271=0.6222240960=20250411-01:51:46.10240837=bd07b88e-4fb1-408e-a347-e27248fb22dd5797=110=136
20250411-01:51:46.222800000 : 8=FIXT.1.19=26635=X49=Coinbase56=24ab46f784d1b20db435b852086e325034=34150=TEST52=20250411-01:51:46.103316369=46262=b7f6c79a-636c-490b-8bc5-37cb784406ba268=1279=2269=0278=bd07b88e-4fb1-408e-a347-e27248fb22dd83=159757107855=BTC-USD60=20250411-01:51:46.10240858=FILLED10=008
20250411-01:51:46.250695000 : 8=FIXT.1.19=27535=X49=Coinbase56=24ab46f784d1b20db435b852086e325034=34250=TEST52=20250411-01:51:46.132964369=46262=b7f6c79a-636c-490b-8bc5-37cb784406ba268=1279=0269=183=159757107955=BTC-USD271=0.6232294660=20250411-01:51:46.13159540=137=f325c755-8985-41b3-965a-d52edf573d4710=142
20250411-01:51:46.251310000 : 8=FIXT.1.19=32735=X49=Coinbase56=24ab46f784d1b20db435b852086e325034=34350=TEST52=20250411-01:51:46.133088369=46262=b7f6c79a-636c-490b-8bc5-37cb784406ba268=1279=0269=2278=4d60a78e-b39b-420e-b830-bc0f3f4fdde283=159757108055=BTC-USD270=3.53271=0.6232294660=20250411-01:51:46.13159537=f325c755-8985-41b3-965a-d52edf573d475797=210=120
20250411-01:51:46.251644000 : 8=FIXT.1.19=28135=X49=Coinbase56=24ab46f784d1b20db435b852086e325034=34450=TEST52=20250411-01:51:46.133145369=46262=b7f6c79a-636c-490b-8bc5-37cb784406ba268=1279=2269=1278=f325c755-8985-41b3-965a-d52edf573d4783=159757108155=BTC-USD271=0.0000000060=20250411-01:51:46.13159558=FILLED10=029
20250411-01:51:46.831713000 : 8=FIXT.1.19=27935=X49=Coinbase56=24ab46f784d1b20db435b852086e325034=34550=TEST52=20250411-01:51:46.674780369=46262=b7f6c79a-636c-490b-8bc5-37cb784406ba268=1279=0269=083=159757108255=BTC-USD29004=2.208895519560=20250411-01:51:46.67366040=137=62f9c604-bb40-4e23-85ee-f63bab9f074b10=026
20250411-01:51:46.833160000 : 8=FIXT.1.19=8435=534=4749=24ab46f784d1b20db435b852086e325052=20250411-01:51:46.83256=Coinbase10=171
20250411-01:51:46.833337000 : 8=FIXT.1.19=32735=X49=Coinbase56=24ab46f784d1b20db435b852086e325034=34650=TEST52=20250411-01:51:46.674794369=46262=b7f6c79a-636c-490b-8bc5-37cb784406ba268=1279=0269=2278=c5b88ea9-605d-4595-ac52-f7c3f08523ba83=159757108355=BTC-USD270=3.55271=0.6222240960=20250411-01:51:46.67366037=62f9c604-bb40-4e23-85ee-f63bab9f074b5797=110=178
20250411-01:51:46.833599000 : 8=FIXT.1.19=26635=X49=Coinbase56=24ab46f784d1b20db435b852086e325034=34750=TEST52=20250411-01:51:46.674805369=46262=b7f6c79a-636c-490b-8bc5-37cb784406ba268=1279=2269=0278=62f9c604-bb40-4e23-85ee-f63bab9f074b83=159757108455=BTC-USD60=20250411-01:51:46.67366058=FILLED10=040
20250411-01:51:46.834852000 : 8=FIXT.1.19=27535=X49=Coinbase56=24ab46f784d1b20db435b852086e325034=34850=TEST52=20250411-01:51:46.704435369=46262=b7f6c79a-636c-490b-8bc5-37cb784406ba268=1279=0269=183=159757108555=BTC-USD271=0.6232294660=20250411-01:51:46.70285040=137=674fc0f2-744a-4f21-9a0a-36dd547b158710=166
20250411-01:51:46.835214000 : 8=FIXT.1.19=32735=X49=Coinbase56=24ab46f784d1b20db435b852086e325034=34950=TEST52=20250411-01:51:46.704442369=46262=b7f6c79a-636c-490b-8bc5-37cb784406ba268=1279=0269=2278=4d60a78e-b39b-420e-b830-bc0f3f4fdde283=159757108655=BTC-USD270=3.53271=0.6232294660=20250411-01:51:46.70285037=674fc0f2-744a-4f21-9a0a-36dd547b15875797=210=153
20250411-01:51:46.835406000 : 8=FIXT.1.19=28135=X49=Coinbase56=24ab46f784d1b20db435b852086e325034=35050=TEST52=20250411-01:51:46.704446369=46262=b7f6c79a-636c-490b-8bc5-37cb784406ba268=1279=2269=1278=674fc0f2-744a-4f21-9a0a-36dd547b158783=159757108755=BTC-USD271=0.0000000060=20250411-01:51:46.70285058=FILLED10=063
20250411-01:51:47.069857000 : 8=FIXT.1.19=12035=549=Coinbase56=24ab46f784d1b20db435b852086e325034=35150=TEST52=20250411-01:51:46.951716369=4658=CLIENT_LOGOUT10=112
20250411-01:51:55.648727000 : 8=FIXT.1.19=21535=A34=149=24ab46f784d1b20db435b852086e325052=20250411-01:51:55.64156=Coinbase95=4496=rmJOW5raWGMJ/7hRxFgOIbSh5+BJPfoBnUVJIEUt7R0=98=0108=30141=Y553=24ab46f784d1b20db435b852086e3250554=akmwnltyfgb1137=910=124
20250411-01:51:55.901714000 : 8=FIXT.1.19=12535=A49=Coinbase56=24ab46f784d1b20db435b852086e325034=150=TEST52=20250411-01:51:55.788770369=198=0108=30141=Y1137=910=206
20250411-01:51:57.168021000 : 8=FIXT.1.19=17835=V34=249=24ab46f784d1b20db435b852086e325052=20250411-01:51:57.16656=Coinbase1128=9146=155=BTC-USD262=f9400af7-8ea0-43b1-aa74-b3e6d6feb0f2263=1264=0267=2269=0269=110=195
20250411-01:51:57.530561000 : 8=FIXT.1.19=28135=X49=Coinbase56=24ab46f784d1b20db435b852086e325034=250=TEST52=20250411-01:51:57.418212369=2262=f9400af7-8ea0-43b1-aa74-b3e6d6feb0f2268=1279=0269=183=159757136955=BTC-USD270=3.27271=0.6232294660=20250411-01:51:57.41721440=237=b00f5e4b-a039-44f2-9800-5781c768a32410=182
20250411-01:51:57.535201000 : 8=FIXT.1.19=32435=X49=Coinbase56=24ab46f784d1b20db435b852086e325034=350=TEST52=20250411-01:51:57.418221369=2262=f9400af7-8ea0-43b1-aa74-b3e6d6feb0f2268=1279=0269=2278=4d60a78e-b39b-420e-b830-bc0f3f4fdde283=159757137055=BTC-USD270=3.53271=0.6232294660=20250411-01:51:57.41721437=b00f5e4b-a039-44f2-9800-5781c768a3245797=210=000
20250411-01:51:57.540906000 : 8=FIXT.1.19=28735=X49=Coinbase56=24ab46f784d1b20db435b852086e325034=450=TEST52=20250411-01:51:57.418224369=2262=f9400af7-8ea0-43b1-aa74-b3e6d6feb0f2268=1279=2269=1278=b00f5e4b-a039-44f2-9800-5781c768a32483=159757137155=BTC-USD270=3.27271=0.0000000060=20250411-01:51:57.41721458=FILLED10=088
20250411-01:51:57.587539000 : 8=FIXT.1.19=28135=X49=Coinbase56=24ab46f784d1b20db435b852086e325034=550=TEST52=20250411-01:51:57.473330369=2262=f9400af7-8ea0-43b1-aa74-b3e6d6feb0f2268=1279=0269=083=159757137255=BTC-USD270=3.88271=0.6232294660=20250411-01:51:57.47222140=237=6c3d745f-d708-4a96-93f1-88ff506e58b610=062
20250411-01:51:57.587947000 : 8=FIXT.1.19=32435=X49=Coinbase56=24ab46f784d1b20db435b852086e325034=650=TEST52=20250411-01:51:57.473339369=2262=f9400af7-8ea0-43b1-aa74-b3e6d6feb0f2268=1279=0269=2278=c5b88ea9-605d-4595-ac52-f7c3f08523ba83=159757137355=BTC-USD270=3.55271=0.6232294660=20250411-01:51:57.47222137=6c3d745f-d708-4a96-93f1-88ff506e58b65797=110=021
20250411-01:51:57.588098000 : 8=FIXT.1.19=28735=X49=Coinbase56=24ab46f784d1b20db435b852086e325034=750=TEST52=20250411-01:51:57.473415369=2262=f9400af7-8ea0-43b1-aa74-b3e6d6feb0f2268=1279=2269=0278=6c3d745f-d708-4a96-93f1-88ff506e58b683=159757137455=BTC-USD270=3.88271=0.0000000060=20250411-01:51:57.47222158=FILLED10=234
20250411-01:51:57.767202000 : 8=FIXT.1.19=27635=X49=Coinbase56=24ab46f784d1b20db435b852086e325034=850=TEST52=20250411-01:51:57.647393369=2262=f9400af7-8ea0-43b1-aa74-b3e6d6feb0f2268=1279=0269=083=159757137555=BTC-USD29004=2.208895519560=20250411-01:51:57.64523440=137=1d228238-6346-407f-847d-261993bcaaa610=014
20250411-01:51:57.767891000 : 8=FIXT.1.19=32435=X49=Coinbase56=24ab46f784d1b20db435b852086e325034=950=TEST52=20250411-01:51:57.647398369=2262=f9400af7-8ea0-43b1-aa74-b3e6d6feb0f2268=1279=0269=2278=c5b88ea9-605d-4595-ac52-f7c3f08523ba83=159757137655=BTC-USD270=3.55271=0.6222240960=20250411-01:51:57.64523437=1d228238-6346-407f-847d-261993bcaaa65797=110=166
20250411-01:51:57.768077000 : 8=FIXT.1.19=26435=X49=Coinbase56=24ab46f784d1b20db435b852086e325034=1050=TEST52=20250411-01:51:57.647401369=2262=f9400af7-8ea0-43b1-aa74-b3e6d6feb0f2268=1279=2269=0278=1d228238-6346-407f-847d-261993bcaaa683=159757137755=BTC-USD60=20250411-01:51:57.64523458=FILLED10=060
20250411-01:51:57.789961000 : 8=FIXT.1.19=27335=X49=Coinbase56=24ab46f784d1b20db435b852086e325034=1150=TEST52=20250411-01:51:57.675639369=2262=f9400af7-8ea0-43b1-aa74-b3e6d6feb0f2268=1279=0269=183=159757137855=BTC-USD271=0.6197183160=20250411-01:51:57.67401440=137=c82762fb-9077-44ca-91ea-4228c7352ede10=248
20250411-01:51:57.790238000 : 8=FIXT.1.19=32535=X49=Coinbase56=24ab46f784d1b20db435b852086e325034=1250=TEST52=20250411-01:51:57.675720369=2262=f9400af7-8ea0-43b1-aa74-b3e6d6feb0f2268=1279=0269=2278=4d60a78e-b39b-420e-b830-bc0f3f4fdde283=159757137955=BTC-USD270=3.53271=0.6197183160=20250411-01:51:57.67401437=c82762fb-9077-44ca-91ea-4228c7352ede5797=210=228
20250411-01:51:57.790397000 : 8=FIXT.1.19=27935=X49=Coinbase56=24ab46f784d1b20db435b852086e325034=1350=TEST52=20250411-01:51:57.675726369=2262=f9400af7-8ea0-43b1-aa74-b3e6d6feb0f2268=1279=2269=1278=c82762fb-9077-44ca-91ea-4228c7352ede83=159757138055=BTC-USD271=0.0000000060=20250411-01:51:57.67401458=FILLED10=147
20250411-01:51:57.817807000 : 8=FIXT.1.19=27735=X49=Coinbase56=24ab46f784d1b20db435b852086e325034=1450=TEST52=20250411-01:51:57.705835369=2262=f9400af7-8ea0-43b1-aa74-b3e6d6feb0f2268=1279=0269=083=159757138155=BTC-USD29004=2.208895519560=20250411-01:51:57.70393940=137=f608fdd0-b44e-4c38-9396-aecba4b345f610=095
20250411-01:51:57.818085000 : 8=FIXT.1.19=32535=X49=Coinbase56=24ab46f784d1b20db435b852086e325034=1550=TEST52=20250411-01:51:57.705840369=2262=f9400af7-8ea0-43b1-aa74-b3e6d6feb0f2268=1279=0269=2278=c5b88ea9-605d-4595-ac52-f7c3f08523ba83=159757138255=BTC-USD270=3.55271=0.6222240960=20250411-01:51:57.70393937=f608fdd0-b44e-4c38-9396-aecba4b345f65797=110=238
20250411-01:51:57.818412000 : 8=FIXT.1.19=26435=X49=Coinbase56=24ab46f784d1b20db435b852086e325034=1650=TEST52=20250411-01:51:57.705844369=2262=f9400af7-8ea0-43b1-aa74-b3e6d6feb0f2268=1279=2269=0278=f608fdd0-b44e-4c38-9396-aecba4b345f683=159757138355=BTC-USD60=20250411-01:51:57.70393958=FILLED10=111
20250411-01:51:57.844407000 : 8=FIXT.1.19=27335=X49=Coinbase56=24ab46f784d1b20db435b852086e325034=1750=TEST52=20250411-01:51:57.732721369=2262=f9400af7-8ea0-43b1-aa74-b3e6d6feb0f2268=1279=0269=183=159757138455=BTC-USD271=0.6197183160=20250411-01:51:57.73094640=137=1eefb40e-45ad-460f-ac64-540fd11cdfc010=200
20250411-01:51:57.845109000 : 8=FIXT.1.19=32535=X49=Coinbase56=24ab46f784d1b20db435b852086e325034=1850=TEST52=20250411-01:51:57.732829369=2262=f9400af7-8ea0-43b1-aa74-b3e6d6feb0f2268=1279=0269=2278=4d60a78e-b39b-420e-b830-bc0f3f4fdde283=159757138555=BTC-USD270=3.53271=0.6197183160=20250411-01:51:57.73094637=1eefb40e-45ad-460f-ac64-540fd11cdfc05797=210=198
20250411-01:51:57.845272000 : 8=FIXT.1.19=27935=X49=Coinbase56=24ab46f784d1b20db435b852086e325034=1950=TEST52=20250411-01:51:57.732890369=2262=f9400af7-8ea0-43b1-aa74-b3e6d6feb0f2268=1279=2269=1278=1eefb40e-45ad-460f-ac64-540fd11cdfc083=159757138655=BTC-USD271=0.0000000060=20250411-01:51:57.73094658=FILLED10=118
20250411-01:51:58.217039000 : 8=FIXT.1.19=27735=X49=Coinbase56=24ab46f784d1b20db435b852086e325034=2050=TEST52=20250411-01:51:58.104156369=2262=f9400af7-8ea0-43b1-aa74-b3e6d6feb0f2268=1279=0269=083=159757138755=BTC-USD29004=2.208895519560=20250411-01:51:58.10253840=137=d57991c8-314c-4281-a8c6-d610f57d2b1910=094
20250411-01:51:58.217632000 : 8=FIXT.1.19=32535=X49=Coinbase56=24ab46f784d1b20db435b852086e325034=2150=TEST52=20250411-01:51:58.104166369=2262=f9400af7-8ea0-43b1-aa74-b3e6d6feb0f2268=1279=0269=2278=c5b88ea9-605d-4595-ac52-f7c3f08523ba83=159757138855=BTC-USD270=3.55271=0.6222240960=20250411-01:51:58.10253837=d57991c8-314c-4281-a8c6-d610f57d2b195797=110=242
20250411-01:51:58.217794000 : 8=FIXT.1.19=26435=X49=Coinbase56=24ab46f784d1b20db435b852086e325034=2250=TEST52=20250411-01:51:58.104278369=2262=f9400af7-8ea0-43b1-aa74-b3e6d6feb0f2268=1279=2269=0278=d57991c8-314c-4281-a8c6-d610f57d2b1983=159757138955=BTC-USD60=20250411-01:51:58.10253858=FILLED10=115
20250411-01:51:58.219957000 : 8=FIXT.1.19=28235=X49=Coinbase56=24ab46f784d1b20db435b852086e325034=2350=TEST52=20250411-01:51:58.104280369=2262=f9400af7-8ea0-43b1-aa74-b3e6d6feb0f2268=1279=0269=183=159757139055=BTC-USD270=3.19271=0.6232294660=20250411-01:51:58.10293640=237=0c28b2da-7314-482f-990f-e71c259c592610=035
20250411-01:51:58.220168000 : 8=FIXT.1.19=32535=X49=Coinbase56=24ab46f784d1b20db435b852086e325034=2450=TEST52=20250411-01:51:58.104283369=2262=f9400af7-8ea0-43b1-aa74-b3e6d6feb0f2268=1279=0269=2278=4d60a78e-b39b-420e-b830-bc0f3f4fdde283=159757139155=BTC-USD270=3.53271=0.6232294660=20250411-01:51:58.10293637=0c28b2da-7314-482f-990f-e71c259c59265797=210=120
20250411-01:51:58.220496000 : 8=FIXT.1.19=28835=X49=Coinbase56=24ab46f784d1b20db435b852086e325034=2550=TEST52=20250411-01:51:58.104327369=2262=f9400af7-8ea0-43b1-aa74-b3e6d6feb0f2268=1279=2269=1278=0c28b2da-7314-482f-990f-e71c259c592683=159757139255=BTC-USD270=3.19271=0.0000000060=20250411-01:51:58.10293658=FILLED10=205
20250411-01:51:58.245067000 : 8=FIXT.1.19=27335=X49=Coinbase56=24ab46f784d1b20db435b852086e325034=2650=TEST52=20250411-01:51:58.132516369=2262=f9400af7-8ea0-43b1-aa74-b3e6d6feb0f2268=1279=0269=183=159757139355=BTC-USD271=0.6232294660=20250411-01:51:58.13147740=137=cd511657-99cd-4a7d-9131-b193a1ac66be10=016
20250411-01:51:58.245609000 : 8=FIXT.1.19=32535=X49=Coinbase56=24ab46f784d1b20db435b852086e325034=2750=TEST52=20250411-01:51:58.132601369=2262=f9400af7-8ea0-43b1-aa74-b3e6d6feb0f2268=1279=0269=2278=4d60a78e-b39b-420e-b830-bc0f3f4fdde283=159757139455=BTC-USD270=3.53271=0.6232294660=20250411-01:51:58.13147737=cd511657-99cd-4a7d-9131-b193a1ac66be5797=210=000
20250411-01:51:58.245866000 : 8=FIXT.1.19=27935=X49=Coinbase56=24ab46f784d1b20db435b852086e325034=2850=TEST52=20250411-01:51:58.132608369=2262=f9400af7-8ea0-43b1-aa74-b3e6d6feb0f2268=1279=2269=1278=cd511657-99cd-4a7d-9131-b193a1ac66be83=159757139555=BTC-USD271=0.0000000060=20250411-01:51:58.13147758=FILLED10=187
20250411-01:51:58.273345000 : 8=FIXT.1.19=28235=X49=Coinbase56=24ab46f784d1b20db435b852086e325034=2950=TEST52=20250411-01:51:58.160956369=2262=f9400af7-8ea0-43b1-aa74-b3e6d6feb0f2268=1279=0269=083=159757139655=BTC-USD270=3.79271=0.6232294660=20250411-01:51:58.15934840=237=bd5b973d-fe6f-4a3b-b8bf-f19da6e42c6710=204
20250411-01:51:58.273573000 : 8=FIXT.1.19=32535=X49=Coinbase56=24ab46f784d1b20db435b852086e325034=3050=TEST52=20250411-01:51:58.160965369=2262=f9400af7-8ea0-43b1-aa74-b3e6d6feb0f2268=1279=0269=2278=c5b88ea9-605d-4595-ac52-f7c3f08523ba83=159757139755=BTC-USD270=3.55271=0.6232294660=20250411-01:51:58.15934837=bd5b973d-fe6f-4a3b-b8bf-f19da6e42c675797=110=145
20250411-01:51:58.275652000 : 8=FIXT.1.19=28835=X49=Coinbase56=24ab46f784d1b20db435b852086e325034=3150=TEST52=20250411-01:51:58.160968369=2262=f9400af7-8ea0-43b1-aa74-b3e6d6feb0f2268=1279=2269=0278=bd5b973d-fe6f-4a3b-b8bf-f19da6e42c6783=159757139855=BTC-USD270=3.79271=0.0000000060=20250411-01:51:58.15934858=FILLED10=110
20250411-01:51:58.445642000 : 8=FIXT.1.19=28135=X49=Coinbase56=24ab46f784d1b20db435b852086e325034=3250=TEST52=20250411-01:51:58.333053369=2262=f9400af7-8ea0-43b1-aa74-b3e6d6feb0f2268=1279=0269=183=159757139955=BTC-USD270=3.2271=0.6197183160=20250411-01:51:58.33115840=237=e371181e-ab10-4ad9-9fc0-acd8536a0cdf10=000
20250411-01:51:58.448534000 : 8=FIXT.1.19=32535=X49=Coinbase56=24ab46f784d1b20db435b852086e325034=3350=TEST52=20250411-01:51:58.333133369=2262=f9400af7-8ea0-43b1-aa74-b3e6d6feb0f2268=1279=0269=2278=4d60a78e-b39b-420e-b830-bc0f3f4fdde283=159757140055=BTC-USD270=3.53271=0.6197183160=20250411-01:51:58.33115837=e371181e-ab10-4ad9-9fc0-acd8536a0cdf5797=210=120
20250411-01:51:58.448714000 : 8=FIXT.1.19=28735=X49=Coinbase56=24ab46f784d1b20db435b852086e325034=3450=TEST52=20250411-01:51:58.333141369=2262=f9400af7-8ea0-43b1-aa74-b3e6d6feb0f2268=1279=2269=1278=e371181e-ab10-4ad9-9fc0-acd8536a0cdf83=159757140155=BTC-USD270=3.2271=0.0000000060=20250411-01:51:58.33115858=FILLED10=146
20250411-01:51:58.504326000 : 8=FIXT.1.19=28235=X49=Coinbase56=24ab46f784d1b20db435b852086e325034=3550=TEST52=20250411-01:51:58.389471369=2262=f9400af7-8ea0-43b1-aa74-b3e6d6feb0f2268=1279=0269=083=159757140255=BTC-USD270=3.89271=0.6197183160=20250411-01:51:58.38824040=237=35e1e60b-f689-49bd-b76d-03aa0067407a10=143
20250411-01:51:58.504518000 : 8=FIXT.1.19=32535=X49=Coinbase56=24ab46f784d1b20db435b852086e325034=3650=TEST52=20250411-01:51:58.389482369=2262=f9400af7-8ea0-43b1-aa74-b3e6d6feb0f2268=1279=0269=2278=c5b88ea9-605d-4595-ac52-f7c3f08523ba83=159757140355=BTC-USD270=3.55271=0.6197183160=20250411-01:51:58.38824037=35e1e60b-f689-49bd-b76d-03aa0067407a5797=110=094
20250411-01:51:58.504642000 : 8=FIXT.1.19=28835=X49=Coinbase56=24ab46f784d1b20db435b852086e325034=3750=TEST52=20250411-01:51:58.389641369=2262=f9400af7-8ea0-43b1-aa74-b3e6d6feb0f2268=1279=2269=0278=35e1e60b-f689-49bd-b76d-03aa0067407a83=159757140455=BTC-USD270=3.89271=0.0000000060=20250411-01:51:58.38824058=FILLED10=052
20250411-01:51:58.814197000 : 8=FIXT.1.19=27735=X49=Coinbase56=24ab46f784d1b20db435b852086e325034=3850=TEST52=20250411-01:51:58.675310369=2262=f9400af7-8ea0-43b1-aa74-b3e6d6feb0f2268=1279=0269=083=159757140555=BTC-USD29004=2.208895519560=20250411-01:51:58.67427140=137=c9009c20-1084-41ba-83d6-8616891f899810=229
20250411-01:51:58.815414000 : 8=FIXT.1.19=8335=534=349=24ab46f784d1b20db435b852086e325052=20250411-01:51:58.81456=Coinbase10=117
20250411-01:51:58.815600000 : 8=FIXT.1.19=32535=X49=Coinbase56=24ab46f784d1b20db435b852086e325034=3950=TEST52=20250411-01:51:58.675383369=2262=f9400af7-8ea0-43b1-aa74-b3e6d6feb0f2268=1279=0269=2278=c5b88ea9-605d-4595-ac52-f7c3f08523ba83=159757140655=BTC-USD270=3.55271=0.6222240960=20250411-01:51:58.67427137=c9009c20-1084-41ba-83d6-8616891f89985797=110=130
20250411-01:51:58.815908000 : 8=FIXT.1.19=26435=X49=Coinbase56=24ab46f784d1b20db435b852086e325034=4050=TEST52=20250411-01:51:58.675389369=2262=f9400af7-8ea0-43b1-aa74-b3e6d6feb0f2268=1279=2269=0278=c9009c20-1084-41ba-83d6-8616891f899883=159757140755=BTC-USD60=20250411-01:51:58.67427158=FILLED10=252
20250411-01:51:58.817956000 : 8=FIXT.1.19=27335=X49=Coinbase56=24ab46f784d1b20db435b852086e325034=4150=TEST52=20250411-01:51:58.704715369=2262=f9400af7-8ea0-43b1-aa74-b3e6d6feb0f2268=1279=0269=183=159757140855=BTC-USD271=0.6197183160=20250411-01:51:58.70348740=137=3a626092-d59a-4411-a0e1-83b30e56fa7410=124
20250411-01:51:58.818205000 : 8=FIXT.1.19=32535=X49=Coinbase56=24ab46f784d1b20db435b852086e325034=4250=TEST52=20250411-01:51:58.704722369=2262=f9400af7-8ea0-43b1-aa74-b3e6d6feb0f2268=1279=0269=2278=4d60a78e-b39b-420e-b830-bc0f3f4fdde283=159757140955=BTC-USD270=3.53271=0.6197183160=20250411-01:51:58.70348737=3a626092-d59a-4411-a0e1-83b30e56fa745797=210=111
20250411-01:51:58.818449000 : 8=FIXT.1.19=27935=X49=Coinbase56=24ab46f784d1b20db435b852086e325034=4350=TEST52=20250411-01:51:58.704724369=2262=f9400af7-8ea0-43b1-aa74-b3e6d6feb0f2268=1279=2269=1278=3a626092-d59a-4411-a0e1-83b30e56fa7483=159757141055=BTC-USD271=0.0000000060=20250411-01:51:58.70348758=FILLED10=026
20250411-01:51:58.959273000 : 8=FIXT.1.19=27735=X49=Coinbase56=24ab46f784d1b20db435b852086e325034=4450=TEST52=20250411-01:51:58.846765369=2262=f9400af7-8ea0-43b1-aa74-b3e6d6feb0f2268=1279=0269=083=159757141155=BTC-USD29004=2.208895519560=20250411-01:51:58.84543540=137=c72d9f02-f424-458e-b584-6d1256e6cd9510=174
20250411-01:51:58.959716000 : 8=FIXT.1.19=32535=X49=Coinbase56=24ab46f784d1b20db435b852086e325034=4550=TEST52=20250411-01:51:58.846772369=2262=f9400af7-8ea0-43b1-aa74-b3e6d6feb0f2268=1279=0269=2278=c5b88ea9-605d-4595-ac52-f7c3f08523ba83=159757141255=BTC-USD270=3.55271=0.6222240960=20250411-01:51:58.84543537=c72d9f02-f424-458e-b584-6d1256e6cd955797=110=063
20250411-01:51:58.960000000 : 8=FIXT.1.19=26435=X49=Coinbase56=24ab46f784d1b20db435b852086e325034=4650=TEST52=20250411-01:51:58.846818369=2262=f9400af7-8ea0-43b1-aa74-b3e6d6feb0f2268=1279=2269=0278=c72d9f02-f424-458e-b584-6d1256e6cd9583=159757141355=BTC-USD60=20250411-01:51:58.84543558=FILLED10=189
20250411-01:52:15.404989000 : 8=FIXT.1.19=21535=A34=149=24ab46f784d1b20db435b852086e325052=20250411-01:52:15.39756=Coinbase95=4496=kisKx221KrqgCwwVXmpnpBpHQRsfVBvA6HjAg7l3tk0=98=0108=30141=Y553=24ab46f784d1b20db435b852086e3250554=akmwnltyfgb1137=910=189
20250411-01:52:15.658149000 : 8=FIXT.1.19=12535=A49=Coinbase56=24ab46f784d1b20db435b852086e325034=150=TEST52=20250411-01:52:15.544258369=198=0108=30141=Y1137=910=194
20250411-01:52:16.675740000 : 8=FIXT.1.19=17835=V34=249=24ab46f784d1b20db435b852086e325052=20250411-01:52:16.67456=Coinbase1128=9146=155=BTC-USD262=cc968855-34c5-4534-b7c2-dc3838cce15b263=1264=0267=2269=0269=110=026
20250411-01:52:17.347809000 : 8=FIXT.1.19=28135=X49=Coinbase56=24ab46f784d1b20db435b852086e325034=250=TEST52=20250411-01:52:17.191116369=2262=cc968855-34c5-4534-b7c2-dc3838cce15b268=1279=0269=083=159757176655=BTC-USD270=3.85271=0.6197183160=20250411-01:52:17.18963440=237=8b3098c0-15a1-43cc-ae03-c5e4b48f853e10=214
20250411-01:52:17.348649000 : 8=FIXT.1.19=32435=X49=Coinbase56=24ab46f784d1b20db435b852086e325034=350=TEST52=20250411-01:52:17.191127369=2262=cc968855-34c5-4534-b7c2-dc3838cce15b268=1279=0269=2278=c5b88ea9-605d-4595-ac52-f7c3f08523ba83=159757176755=BTC-USD270=3.55271=0.6197183160=20250411-01:52:17.18963437=8b3098c0-15a1-43cc-ae03-c5e4b48f853e5797=110=169
20250411-01:52:17.348927000 : 8=FIXT.1.19=28735=X49=Coinbase56=24ab46f784d1b20db435b852086e325034=450=TEST52=20250411-01:52:17.191131369=2262=cc968855-34c5-4534-b7c2-dc3838cce15b268=1279=2269=0278=8b3098c0-15a1-43cc-ae03-c5e4b48f853e83=159757176855=BTC-USD270=3.85271=0.0000000060=20250411-01:52:17.18963458=FILLED10=121
20250411-01:52:17.361741000 : 8=FIXT.1.19=28135=X49=Coinbase56=24ab46f784d1b20db435b852086e325034=550=TEST52=20250411-01:52:17.248299369=2262=cc968855-34c5-4534-b7c2-dc3838cce15b268=1279=0269=183=159757176955=BTC-USD270=3.26271=0.6197183160=20250411-01:52:17.24698240=237=aa0958c6-3f9b-40b1-99d4-2e323e23256110=091
20250411-01:52:17.361970000 : 8=FIXT.1.19=32435=X49=Coinbase56=24ab46f784d1b20db435b852086e325034=650=TEST52=20250411-01:52:17.248307369=2262=cc968855-34c5-4534-b7c2-dc3838cce15b268=1279=0269=2278=4d60a78e-b39b-420e-b830-bc0f3f4fdde283=159757177055=BTC-USD270=3.53271=0.6197183160=20250411-01:52:17.24698237=aa0958c6-3f9b-40b1-99d4-2e323e2325615797=210=156
20250411-01:52:17.362133000 : 8=FIXT.1.19=28735=X49=Coinbase56=24ab46f784d1b20db435b852086e325034=750=TEST52=20250411-01:52:17.248311369=2262=cc968855-34c5-4534-b7c2-dc3838cce15b268=1279=2269=1278=aa0958c6-3f9b-40b1-99d4-2e323e23256183=159757177155=BTC-USD270=3.26271=0.0000000060=20250411-01:52:17.24698258=FILLED10=233
20250411-01:52:18.703171000 : 8=FIXT.1.19=28135=X49=Coinbase56=24ab46f784d1b20db435b852086e325034=850=TEST52=20250411-01:52:18.588609369=2262=cc968855-34c5-4534-b7c2-dc3838cce15b268=1279=0269=183=159757177255=BTC-USD270=3.54271=0.6232294660=20250411-01:52:18.58653240=237=f0214296-5b89-4fe1-b3e4-77f6a43e35fd10=201
20250411-01:52:18.703801000 : 8=FIXT.1.19=27735=X49=Coinbase56=24ab46f784d1b20db435b852086e325034=950=TEST52=20250411-01:52:18.588614369=2262=cc968855-34c5-4534-b7c2-dc3838cce15b268=1279=0269=1278=f0214296-5b89-4fe1-b3e4-77f6a43e35fd83=159757177355=BTC-USD270=3.54271=0.6232294660=20250411-01:52:18.58653210=047
20250411-01:52:18.704996000 : 8=FIXT.1.19=28235=X49=Coinbase56=24ab46f784d1b20db435b852086e325034=1050=TEST52=20250411-01:52:18.588618369=2262=cc968855-34c5-4534-b7c2-dc3838cce15b268=1279=0269=183=159757177455=BTC-USD270=3.69271=0.6232294660=20250411-01:52:18.58653240=237=b2cd94d2-5541-4758-b3ac-106fb07a432610=178
20250411-01:52:18.705221000 : 8=FIXT.1.19=27835=X49=Coinbase56=24ab46f784d1b20db435b852086e325034=1150=TEST52=20250411-01:52:18.588667369=2262=cc968855-34c5-4534-b7c2-dc3838cce15b268=1279=0269=1278=b2cd94d2-5541-4758-b3ac-106fb07a432683=159757177555=BTC-USD270=3.69271=0.6232294660=20250411-01:52:18.58653210=032
20250411-01:52:19.138823000 : 8=FIXT.1.19=28235=X49=Coinbase56=24ab46f784d1b20db435b852086e325034=1250=TEST52=20250411-01:52:19.019462369=2262=cc968855-34c5-4534-b7c2-dc3838cce15b268=1279=0269=083=159757177655=BTC-USD270=3.74271=0.6232294660=20250411-01:52:19.01814240=237=0e1aff8d-2e97-4a80-b80b-a31263ad6b7510=044
20250411-01:52:19.176126000 : 8=FIXT.1.19=32535=X49=Coinbase56=24ab46f784d1b20db435b852086e325034=1350=TEST52=20250411-01:52:19.019471369=2262=cc968855-34c5-4534-b7c2-dc3838cce15b268=1279=0269=2278=f0214296-5b89-4fe1-b3e4-77f6a43e35fd83=159757177755=BTC-USD270=3.54271=0.6232294660=20250411-01:52:19.01814237=0e1aff8d-2e97-4a80-b80b-a31263ad6b755797=110=211
20250411-01:52:19.193547000 : 8=FIXT.1.19=28835=X49=Coinbase56=24ab46f784d1b20db435b852086e325034=1450=TEST52=20250411-01:52:19.019476369=2262=cc968855-34c5-4534-b7c2-dc3838cce15b268=1279=2269=1278=f0214296-5b89-4fe1-b3e4-77f6a43e35fd83=159757177855=BTC-USD270=3.54271=0.0000000060=20250411-01:52:19.01814258=FILLED10=141
20250411-01:52:19.197574000 : 8=FIXT.1.19=28835=X49=Coinbase56=24ab46f784d1b20db435b852086e325034=1550=TEST52=20250411-01:52:19.019480369=2262=cc968855-34c5-4534-b7c2-dc3838cce15b268=1279=2269=0278=0e1aff8d-2e97-4a80-b80b-a31263ad6b7583=159757177955=BTC-USD270=3.74271=0.0000000060=20250411-01:52:19.01814258=FILLED10=214
20250411-01:52:19.198838000 : 8=FIXT.1.19=28235=X49=Coinbase56=24ab46f784d1b20db435b852086e325034=1650=TEST52=20250411-01:52:19.075545369=2262=cc968855-34c5-4534-b7c2-dc3838cce15b268=1279=0269=183=159757178055=BTC-USD270=3.25271=0.6232294660=20250411-01:52:19.07363840=237=764edb3e-6838-4382-b123-336c956a405c10=085
20250411-01:52:19.199227000 : 8=FIXT.1.19=32535=X49=Coinbase56=24ab46f784d1b20db435b852086e325034=1750=TEST52=20250411-01:52:19.075555369=2262=cc968855-34c5-4534-b7c2-dc3838cce15b268=1279=0269=2278=4d60a78e-b39b-420e-b830-bc0f3f4fdde283=159757178155=BTC-USD270=3.53271=0.6232294660=20250411-01:52:19.07363837=764edb3e-6838-4382-b123-336c956a405c5797=210=171
20250411-01:52:19.199459000 : 8=FIXT.1.19=28835=X49=Coinbase56=24ab46f784d1b20db435b852086e325034=1850=TEST52=20250411-01:52:19.075559369=2262=cc968855-34c5-4534-b7c2-dc3838cce15b268=1279=2269=1278=764edb3e-6838-4382-b123-336c956a405c83=159757178255=BTC-USD270=3.25271=0.0000000060=20250411-01:52:19.07363858=FILLED10=002
20250411-01:52:19.249652000 : 8=FIXT.1.19=28235=X49=Coinbase56=24ab46f784d1b20db435b852086e325034=1950=TEST52=20250411-01:52:19.133734369=2262=cc968855-34c5-4534-b7c2-dc3838cce15b268=1279=0269=083=159757178355=BTC-USD270=3.73271=0.6232294660=20250411-01:52:19.13196040=237=5a854a4d-2f5b-4d5b-a813-13b76909a19f10=220
20250411-01:52:19.258955000 : 8=FIXT.1.19=32535=X49=Coinbase56=24ab46f784d1b20db435b852086e325034=2050=TEST52=20250411-01:52:19.133742369=2262=cc968855-34c5-4534-b7c2-dc3838cce15b268=1279=0269=2278=c5b88ea9-605d-4595-ac52-f7c3f08523ba83=159757178455=BTC-USD270=3.55271=0.6232294660=20250411-01:52:19.13196037=5a854a4d-2f5b-4d5b-a813-13b76909a19f5797=110=166
20250411-01:52:19.260260000 : 8=FIXT.1.19=28835=X49=Coinbase56=24ab46f784d1b20db435b852086e325034=2150=TEST52=20250411-01:52:19.133747369=2262=cc968855-34c5-4534-b7c2-dc3838cce15b268=1279=2269=0278=5a854a4d-2f5b-4d5b-a813-13b76909a19f83=159757178555=BTC-USD270=3.73271=0.0000000060=20250411-01:52:19.13196058=FILLED10=127
20250411-01:52:19.270759000 : 8=FIXT.1.19=28235=X49=Coinbase56=24ab46f784d1b20db435b852086e325034=2250=TEST52=20250411-01:52:19.157859369=2262=cc968855-34c5-4534-b7c2-dc3838cce15b268=1279=0269=083=159757178655=BTC-USD270=3.49271=0.6232294660=20250411-01:52:19.15673640=237=8ea247f8-3f43-4475-8af6-95bba22c9e3610=004
20250411-01:52:19.271278000 : 8=FIXT.1.19=27835=X49=Coinbase56=24ab46f784d1b20db435b852086e325034=2350=TEST52=20250411-01:52:19.157865369=2262=cc968855-34c5-4534-b7c2-dc3838cce15b268=1279=0269=0278=8ea247f8-3f43-4475-8af6-95bba22c9e3683=159757178755=BTC-USD270=3.49271=0.6232294660=20250411-01:52:19.15673610=107
20250411-01:52:19.271475000 : 8=FIXT.1.19=28235=X49=Coinbase56=24ab46f784d1b20db435b852086e325034=2450=TEST52=20250411-01:52:19.157869369=2262=cc968855-34c5-4534-b7c2-dc3838cce15b268=1279=0269=083=159757178855=BTC-USD270=3.51271=0.6232294660=20250411-01:52:19.15673640=237=b80036f8-4ea9-47c3-8196-392ee22baf7710=207
20250411-01:52:19.271667000 : 8=FIXT.1.19=27835=X49=Coinbase56=24ab46f784d1b20db435b852086e325034=2550=TEST52=20250411-01:52:19.157873369=2262=cc968855-34c5-4534-b7c2-dc3838cce15b268=1279=0269=0278=b80036f8-4ea9-47c3-8196-392ee22baf7783=159757178955=BTC-USD270=3.51271=0.6232294660=20250411-01:52:19.15673610=052
20250411-01:52:19.303289000 : 8=FIXT.1.19=28235=X49=Coinbase56=24ab46f784d1b20db435b852086e325034=2650=TEST52=20250411-01:52:19.187506369=2262=cc968855-34c5-4534-b7c2-dc3838cce15b268=1279=0269=183=159757179055=BTC-USD270=3.22271=0.6232294660=20250411-01:52:19.18609640=237=13cae475-5b7d-41b2-90cb-1050f5d0043010=148
20250411-01:52:19.303933000 : 8=FIXT.1.19=32535=X49=Coinbase56=24ab46f784d1b20db435b852086e325034=2750=TEST52=20250411-01:52:19.187515369=2262=cc968855-34c5-4534-b7c2-dc3838cce15b268=1279=0269=2278=4d60a78e-b39b-420e-b830-bc0f3f4fdde283=159757179155=BTC-USD270=3.53271=0.6232294660=20250411-01:52:19.18609637=13cae475-5b7d-41b2-90cb-1050f5d004305797=210=236
20250411-01:52:19.304963000 : 8=FIXT.1.19=28835=X49=Coinbase56=24ab46f784d1b20db435b852086e325034=2850=TEST52=20250411-01:52:19.187519369=2262=cc968855-34c5-4534-b7c2-dc3838cce15b268=1279=2269=1278=13cae475-5b7d-41b2-90cb-1050f5d0043083=159757179255=BTC-USD270=3.22271=0.0000000060=20250411-01:52:19.18609658=FILLED10=064
20250411-01:52:19.362963000 : 8=FIXT.1.19=28235=X49=Coinbase56=24ab46f784d1b20db435b852086e325034=2950=TEST52=20250411-01:52:19.249169369=2262=cc968855-34c5-4534-b7c2-dc3838cce15b268=1279=0269=083=159757179355=BTC-USD270=3.85271=0.6232294660=20250411-01:52:19.24703940=237=b480db0c-b008-4a49-90bd-f4577ee0ddd310=119
20250411-01:52:19.364125000 : 8=FIXT.1.19=32535=X49=Coinbase56=24ab46f784d1b20db435b852086e325034=3050=TEST52=20250411-01:52:19.249180369=2262=cc968855-34c5-4534-b7c2-dc3838cce15b268=1279=0269=2278=c5b88ea9-605d-4595-ac52-f7c3f08523ba83=159757179455=BTC-USD270=3.55271=0.6232294660=20250411-01:52:19.24703937=b480db0c-b008-4a49-90bd-f4577ee0ddd35797=110=056
20250411-01:52:19.364730000 : 8=FIXT.1.19=28835=X49=Coinbase56=24ab46f784d1b20db435b852086e325034=3150=TEST52=20250411-01:52:19.249184369=2262=cc968855-34c5-4534-b7c2-dc3838cce15b268=1279=2269=0278=b480db0c-b008-4a49-90bd-f4577ee0ddd383=159757179555=BTC-USD270=3.85271=0.0000000060=20250411-01:52:19.24703958=FILLED10=019
20250411-01:52:19.417619000 : 8=FIXT.1.19=28235=X49=Coinbase56=24ab46f784d1b20db435b852086e325034=3250=TEST52=20250411-01:52:19.304203369=2262=cc968855-34c5-4534-b7c2-dc3838cce15b268=1279=0269=183=159757179655=BTC-USD270=3.21271=0.6232294660=20250411-01:52:19.30226240=237=e572b54e-2c70-4170-a020-d5491453696510=209
20250411-01:52:19.418147000 : 8=FIXT.1.19=32535=X49=Coinbase56=24ab46f784d1b20db435b852086e325034=3350=TEST52=20250411-01:52:19.304209369=2262=cc968855-34c5-4534-b7c2-dc3838cce15b268=1279=0269=2278=4d60a78e-b39b-420e-b830-bc0f3f4fdde283=159757179755=BTC-USD270=3.53271=0.6232294660=20250411-01:52:19.30226237=e572b54e-2c70-4170-a020-d549145369655797=210=048
20250411-01:52:19.418344000 : 8=FIXT.1.19=28835=X49=Coinbase56=24ab46f784d1b20db435b852086e325034=3450=TEST52=20250411-01:52:19.304213369=2262=cc968855-34c5-4534-b7c2-dc3838cce15b268=1279=2269=1278=e572b54e-2c70-4170-a020-d5491453696583=159757179855=BTC-USD270=3.21271=0.0000000060=20250411-01:52:19.30226258=FILLED10=122
20250411-01:52:20.733249000 : 8=FIXT.1.19=28235=X49=Coinbase56=24ab46f784d1b20db435b852086e325034=3550=TEST52=20250411-01:52:20.619852369=2262=cc968855-34c5-4534-b7c2-dc3838cce15b268=1279=0269=183=159757179955=BTC-USD270=3.26271=0.6232294660=20250411-01:52:20.61856040=237=20c29e77-a470-4cfe-b976-5247e85d489010=149
20250411-01:52:20.736064000 : 8=FIXT.1.19=8335=534=349=24ab46f784d1b20db435b852086e325052=20250411-01:52:20.73556=Coinbase10=109
20250411-01:52:20.736298000 : 8=FIXT.1.19=32535=X49=Coinbase56=24ab46f784d1b20db435b852086e325034=3650=TEST52=20250411-01:52:20.619862369=2262=cc968855-34c5-4534-b7c2-dc3838cce15b268=1279=0269=2278=4d60a78e-b39b-420e-b830-bc0f3f4fdde283=159757180055=BTC-USD270=3.53271=0.6232294660=20250411-01:52:20.61856037=20c29e77-a470-4cfe-b976-5247e85d48905797=210=216
20250411-01:52:20.736668000 : 8=FIXT.1.19=28835=X49=Coinbase56=24ab46f784d1b20db435b852086e325034=3750=TEST52=20250411-01:52:20.619867369=2262=cc968855-34c5-4534-b7c2-dc3838cce15b268=1279=2269=1278=20c29e77-a470-4cfe-b976-5247e85d489083=159757180155=BTC-USD270=3.26271=0.0000000060=20250411-01:52:20.61856058=FILLED10=049
20250411-01:57:16.882783000 : 8=FIXT.1.19=21535=A34=149=24ab46f784d1b20db435b852086e325052=20250411-01:57:16.87656=Coinbase95=4496=LfcFl/VTf0gvsXtWCHIc6c/MVKiz0uL4pGbTRHcuuQI=98=0108=30141=Y553=24ab46f784d1b20db435b852086e3250554=akmwnltyfgb1137=910=073
20250411-01:57:17.138993000 : 8=FIXT.1.19=12535=A49=Coinbase56=24ab46f784d1b20db435b852086e325034=150=TEST52=20250411-01:57:17.024268369=198=0108=30141=Y1137=910=195
20250411-01:57:18.425946000 : 8=FIXT.1.19=17835=V34=249=24ab46f784d1b20db435b852086e325052=20250411-01:57:18.42456=Coinbase1128=9146=155=BTC-USD262=ba2ffebd-86b0-430d-b535-d9d3b46840d1263=1264=0267=2269=0269=110=149
20250411-01:57:18.830651000 : 8=FIXT.1.19=27635=X49=Coinbase56=24ab46f784d1b20db435b852086e325034=250=TEST52=20250411-01:57:18.716729369=2262=ba2ffebd-86b0-430d-b535-d9d3b46840d1268=1279=0269=083=159757828655=BTC-USD29004=2.208895519560=20250411-01:57:18.71472440=137=abd668db-cc57-4375-aca5-c093040448a610=158
20250411-01:57:18.831341000 : 8=FIXT.1.19=32435=X49=Coinbase56=24ab46f784d1b20db435b852086e325034=350=TEST52=20250411-01:57:18.716741369=2262=ba2ffebd-86b0-430d-b535-d9d3b46840d1268=1279=0269=2278=c5b88ea9-605d-4595-ac52-f7c3f08523ba83=159757828755=BTC-USD270=3.55271=0.6222240960=20250411-01:57:18.71472437=abd668db-cc57-4375-aca5-c093040448a65797=110=043
20250411-01:57:18.831563000 : 8=FIXT.1.19=26335=X49=Coinbase56=24ab46f784d1b20db435b852086e325034=450=TEST52=20250411-01:57:18.716744369=2262=ba2ffebd-86b0-430d-b535-d9d3b46840d1268=1279=2269=0278=abd668db-cc57-4375-aca5-c093040448a683=159757828855=BTC-USD60=20250411-01:57:18.71472458=FILLED10=171
20250411-01:57:18.857898000 : 8=FIXT.1.19=27235=X49=Coinbase56=24ab46f784d1b20db435b852086e325034=550=TEST52=20250411-01:57:18.744055369=2262=ba2ffebd-86b0-430d-b535-d9d3b46840d1268=1279=0269=183=159757828955=BTC-USD271=0.6232294660=20250411-01:57:18.74259340=137=f0d11707-ebe3-47eb-a120-31bd4d51a92c10=226
20250411-01:57:18.858288000 : 8=FIXT.1.19=32435=X49=Coinbase56=24ab46f784d1b20db435b852086e325034=650=TEST52=20250411-01:57:18.744062369=2262=ba2ffebd-86b0-430d-b535-d9d3b46840d1268=1279=0269=2278=4d60a78e-b39b-420e-b830-bc0f3f4fdde283=159757829055=BTC-USD270=3.53271=0.6232294660=20250411-01:57:18.74259337=f0d11707-ebe3-47eb-a120-31bd4d51a92c5797=210=204
20250411-01:57:18.858488000 : 8=FIXT.1.19=27835=X49=Coinbase56=24ab46f784d1b20db435b852086e325034=750=TEST52=20250411-01:57:18.744067369=2262=ba2ffebd-86b0-430d-b535-d9d3b46840d1268=1279=2269=1278=f0d11707-ebe3-47eb-a120-31bd4d51a92c83=159757829155=BTC-USD271=0.0000000060=20250411-01:57:18.74259358=FILLED10=133
20250411-01:57:19.000151000 : 8=FIXT.1.19=27635=X49=Coinbase56=24ab46f784d1b20db435b852086e325034=850=TEST52=20250411-01:57:18.886144369=2262=ba2ffebd-86b0-430d-b535-d9d3b46840d1268=1279=0269=083=159757829255=BTC-USD29004=2.208895519560=20250411-01:57:18.88466740=137=85d8d6cf-b57e-4f4d-b7ea-b4f2773ef83e10=142
20250411-01:57:19.000815000 : 8=FIXT.1.19=32435=X49=Coinbase56=24ab46f784d1b20db435b852086e325034=950=TEST52=20250411-01:57:18.886149369=2262=ba2ffebd-86b0-430d-b535-d9d3b46840d1268=1279=0269=2278=c5b88ea9-605d-4595-ac52-f7c3f08523ba83=159757829355=BTC-USD270=3.55271=0.6222240960=20250411-01:57:18.88466737=85d8d6cf-b57e-4f4d-b7ea-b4f2773ef83e5797=110=038
20250411-01:57:19.001030000 : 8=FIXT.1.19=26435=X49=Coinbase56=24ab46f784d1b20db435b852086e325034=1050=TEST52=20250411-01:57:18.886151369=2262=ba2ffebd-86b0-430d-b535-d9d3b46840d1268=1279=2269=0278=85d8d6cf-b57e-4f4d-b7ea-b4f2773ef83e83=159757829455=BTC-USD60=20250411-01:57:18.88466758=FILLED10=196
20250411-01:57:19.030275000 : 8=FIXT.1.19=27335=X49=Coinbase56=24ab46f784d1b20db435b852086e325034=1150=TEST52=20250411-01:57:18.914887369=2262=ba2ffebd-86b0-430d-b535-d9d3b46840d1268=1279=0269=183=159757829555=BTC-USD271=0.6232294660=20250411-01:57:18.91309340=137=e8f5eb88-cad8-40a1-b5bd-33e61bb3846c10=142
20250411-01:57:19.030580000 : 8=FIXT.1.19=32535=X49=Coinbase56=24ab46f784d1b20db435b852086e325034=1250=TEST52=20250411-01:57:18.914980369=2262=ba2ffebd-86b0-430d-b535-d9d3b46840d1268=1279=0269=2278=4d60a78e-b39b-420e-b830-bc0f3f4fdde283=159757829655=BTC-USD270=3.53271=0.6232294660=20250411-01:57:18.91309337=e8f5eb88-cad8-40a1-b5bd-33e61bb3846c5797=210=125
20250411-01:57:19.030856000 : 8=FIXT.1.19=27935=X49=Coinbase56=24ab46f784d1b20db435b852086e325034=1350=TEST52=20250411-01:57:18.914984369=2262=ba2ffebd-86b0-430d-b535-d9d3b46840d1268=1279=2269=1278=e8f5eb88-cad8-40a1-b5bd-33e61bb3846c83=159757829755=BTC-USD271=0.0000000060=20250411-01:57:18.91309358=FILLED10=053
20250411-01:57:19.115657000 : 8=FIXT.1.19=27735=X49=Coinbase56=24ab46f784d1b20db435b852086e325034=1450=TEST52=20250411-01:57:19.002017369=2262=ba2ffebd-86b0-430d-b535-d9d3b46840d1268=1279=0269=083=159757829855=BTC-USD29004=2.208895519560=20250411-01:57:19.00010740=137=4d66d5a0-7b68-4957-8f1f-f59234a1312010=254
20250411-01:57:19.116072000 : 8=FIXT.1.19=32535=X49=Coinbase56=24ab46f784d1b20db435b852086e325034=1550=TEST52=20250411-01:57:19.002022369=2262=ba2ffebd-86b0-430d-b535-d9d3b46840d1268=1279=0269=2278=c5b88ea9-605d-4595-ac52-f7c3f08523ba83=159757829955=BTC-USD270=3.55271=0.6222240960=20250411-01:57:19.00010737=4d66d5a0-7b68-4957-8f1f-f59234a131205797=110=141
20250411-01:57:19.116220000 : 8=FIXT.1.19=26435=X49=Coinbase56=24ab46f784d1b20db435b852086e325034=1650=TEST52=20250411-01:57:19.002024369=2262=ba2ffebd-86b0-430d-b535-d9d3b46840d1268=1279=2269=0278=4d66d5a0-7b68-4957-8f1f-f59234a1312083=159757830055=BTC-USD60=20250411-01:57:19.00010758=FILLED10=250
20250411-01:57:19.144143000 : 8=FIXT.1.19=27335=X49=Coinbase56=24ab46f784d1b20db435b852086e325034=1750=TEST52=20250411-01:57:19.029425369=2262=ba2ffebd-86b0-430d-b535-d9d3b46840d1268=1279=0269=183=159757830155=BTC-USD271=0.6232294660=20250411-01:57:19.02828040=137=8ec3f329-c0cd-46f2-92f0-4ff5de3d1d5d10=125
20250411-01:57:19.144387000 : 8=FIXT.1.19=32535=X49=Coinbase56=24ab46f784d1b20db435b852086e325034=1850=TEST52=20250411-01:57:19.029436369=2262=ba2ffebd-86b0-430d-b535-d9d3b46840d1268=1279=0269=2278=4d60a78e-b39b-420e-b830-bc0f3f4fdde283=159757830255=BTC-USD270=3.53271=0.6232294660=20250411-01:57:19.02828037=8ec3f329-c0cd-46f2-92f0-4ff5de3d1d5d5797=210=116
20250411-01:57:19.144553000 : 8=FIXT.1.19=27935=X49=Coinbase56=24ab46f784d1b20db435b852086e325034=1950=TEST52=20250411-01:57:19.029439369=2262=ba2ffebd-86b0-430d-b535-d9d3b46840d1268=1279=2269=1278=8ec3f329-c0cd-46f2-92f0-4ff5de3d1d5d83=159757830355=BTC-USD271=0.0000000060=20250411-01:57:19.02828058=FILLED10=043
20250411-01:57:19.857549000 : 8=FIXT.1.19=27735=X49=Coinbase56=24ab46f784d1b20db435b852086e325034=2050=TEST52=20250411-01:57:19.743498369=2262=ba2ffebd-86b0-430d-b535-d9d3b46840d1268=1279=0269=083=159757830455=BTC-USD29004=2.208895519560=20250411-01:57:19.74221940=137=bfcb0aa9-d65a-4474-8d13-69c8e01e1dd310=045
20250411-01:57:19.858221000 : 8=FIXT.1.19=32535=X49=Coinbase56=24ab46f784d1b20db435b852086e325034=2150=TEST52=20250411-01:57:19.743548369=2262=ba2ffebd-86b0-430d-b535-d9d3b46840d1268=1279=0269=2278=c5b88ea9-605d-4595-ac52-f7c3f08523ba83=159757830555=BTC-USD270=3.55271=0.6222240960=20250411-01:57:19.74221937=bfcb0aa9-d65a-4474-8d13-69c8e01e1dd35797=110=188
20250411-01:57:19.858359000 : 8=FIXT.1.19=26435=X49=Coinbase56=24ab46f784d1b20db435b852086e325034=2250=TEST52=20250411-01:57:19.743555369=2262=ba2ffebd-86b0-430d-b535-d9d3b46840d1268=1279=2269=0278=bfcb0aa9-d65a-4474-8d13-69c8e01e1dd383=159757830655=BTC-USD60=20250411-01:57:19.74221958=FILLED10=055
20250411-01:57:19.886176000 : 8=FIXT.1.19=27335=X49=Coinbase56=24ab46f784d1b20db435b852086e325034=2350=TEST52=20250411-01:57:19.771821369=2262=ba2ffebd-86b0-430d-b535-d9d3b46840d1268=1279=0269=183=159757830755=BTC-USD271=0.6232294660=20250411-01:57:19.77080040=137=3027b520-59c0-485f-94d3-f30b04bda75e10=135
20250411-01:57:19.886608000 : 8=FIXT.1.19=32535=X49=Coinbase56=24ab46f784d1b20db435b852086e325034=2450=TEST52=20250411-01:57:19.771825369=2262=ba2ffebd-86b0-430d-b535-d9d3b46840d1268=1279=0269=2278=4d60a78e-b39b-420e-b830-bc0f3f4fdde283=159757830855=BTC-USD270=3.53271=0.6232294660=20250411-01:57:19.77080037=3027b520-59c0-485f-94d3-f30b04bda75e5797=210=128
20250411-01:57:19.886852000 : 8=FIXT.1.19=27935=X49=Coinbase56=24ab46f784d1b20db435b852086e325034=2550=TEST52=20250411-01:57:19.771828369=2262=ba2ffebd-86b0-430d-b535-d9d3b46840d1268=1279=2269=1278=3027b520-59c0-485f-94d3-f30b04bda75e83=159757830955=BTC-USD271=0.0000000060=20250411-01:57:19.77080058=FILLED10=055
20250411-01:57:19.918280000 : 8=FIXT.1.19=27735=X49=Coinbase56=24ab46f784d1b20db435b852086e325034=2650=TEST52=20250411-01:57:19.804129369=2262=ba2ffebd-86b0-430d-b535-d9d3b46840d1268=1279=0269=083=159757831055=BTC-USD29004=2.208895519560=20250411-01:57:19.80089140=137=a05c2ccc-d356-49f9-8c62-d82285218c6c10=163
20250411-01:57:19.918767000 : 8=FIXT.1.19=32535=X49=Coinbase56=24ab46f784d1b20db435b852086e325034=2750=TEST52=20250411-01:57:19.804133369=2262=ba2ffebd-86b0-430d-b535-d9d3b46840d1268=1279=0269=2278=c5b88ea9-605d-4595-ac52-f7c3f08523ba83=159757831155=BTC-USD270=3.55271=0.6222240960=20250411-01:57:19.80089137=a05c2ccc-d356-49f9-8c62-d82285218c6c5797=110=049
20250411-01:57:19.918930000 : 8=FIXT.1.19=26435=X49=Coinbase56=24ab46f784d1b20db435b852086e325034=2850=TEST52=20250411-01:57:19.804135369=2262=ba2ffebd-86b0-430d-b535-d9d3b46840d1268=1279=2269=0278=a05c2ccc-d356-49f9-8c62-d82285218c6c83=159757831255=BTC-USD60=20250411-01:57:19.80089158=FILLED10=176
20250411-01:57:19.944109000 : 8=FIXT.1.19=27335=X49=Coinbase56=24ab46f784d1b20db435b852086e325034=2950=TEST52=20250411-01:57:19.830233369=2262=ba2ffebd-86b0-430d-b535-d9d3b46840d1268=1279=0269=183=159757831355=BTC-USD271=0.6197183160=20250411-01:57:19.82838640=137=465fe35e-ebc6-47e0-8015-09ed45b9838610=174
20250411-01:57:19.944506000 : 8=FIXT.1.19=32535=X49=Coinbase56=24ab46f784d1b20db435b852086e325034=3050=TEST52=20250411-01:57:19.830239369=2262=ba2ffebd-86b0-430d-b535-d9d3b46840d1268=1279=0269=2278=4d60a78e-b39b-420e-b830-bc0f3f4fdde283=159757831455=BTC-USD270=3.53271=0.6197183160=20250411-01:57:19.82838637=465fe35e-ebc6-47e0-8015-09ed45b983865797=210=160
20250411-01:57:19.944713000 : 8=FIXT.1.19=27935=X49=Coinbase56=24ab46f784d1b20db435b852086e325034=3150=TEST52=20250411-01:57:19.830327369=2262=ba2ffebd-86b0-430d-b535-d9d3b46840d1268=1279=2269=1278=465fe35e-ebc6-47e0-8015-09ed45b9838683=159757831555=BTC-USD271=0.0000000060=20250411-01:57:19.82838658=FILLED10=080
20250411-01:57:20.772699000 : 8=FIXT.1.19=27735=X49=Coinbase56=24ab46f784d1b20db435b852086e325034=3250=TEST52=20250411-01:57:20.659152369=2262=ba2ffebd-86b0-430d-b535-d9d3b46840d1268=1279=0269=083=159757831655=BTC-USD29004=2.208895519560=20250411-01:57:20.65734740=137=0c6590a6-dbe3-42c2-9ece-17ed28d45bb310=035
20250411-01:57:20.773542000 : 8=FIXT.1.19=32535=X49=Coinbase56=24ab46f784d1b20db435b852086e325034=3350=TEST52=20250411-01:57:20.659162369=2262=ba2ffebd-86b0-430d-b535-d9d3b46840d1268=1279=0269=2278=c5b88ea9-605d-4595-ac52-f7c3f08523ba83=159757831755=BTC-USD270=3.55271=0.6222240960=20250411-01:57:20.65734737=0c6590a6-dbe3-42c2-9ece-17ed28d45bb35797=110=183
20250411-01:57:20.773698000 : 8=FIXT.1.19=26435=X49=Coinbase56=24ab46f784d1b20db435b852086e325034=3450=TEST52=20250411-01:57:20.659164369=2262=ba2ffebd-86b0-430d-b535-d9d3b46840d1268=1279=2269=0278=0c6590a6-dbe3-42c2-9ece-17ed28d45bb383=159757831855=BTC-USD60=20250411-01:57:20.65734758=FILLED10=054
20250411-01:57:20.800063000 : 8=FIXT.1.19=27335=X49=Coinbase56=24ab46f784d1b20db435b852086e325034=3550=TEST52=20250411-01:57:20.686633369=2262=ba2ffebd-86b0-430d-b535-d9d3b46840d1268=1279=0269=183=159757831955=BTC-USD271=0.6232294660=20250411-01:57:20.68460240=137=f2712f5c-71cb-4b15-975b-a9e2bc14e78710=245
20250411-01:57:20.800344000 : 8=FIXT.1.19=32535=X49=Coinbase56=24ab46f784d1b20db435b852086e325034=3650=TEST52=20250411-01:57:20.686638369=2262=ba2ffebd-86b0-430d-b535-d9d3b46840d1268=1279=0269=2278=4d60a78e-b39b-420e-b830-bc0f3f4fdde283=159757832055=BTC-USD270=3.53271=0.6232294660=20250411-01:57:20.68460237=f2712f5c-71cb-4b15-975b-a9e2bc14e7875797=210=230
20250411-01:57:20.800607000 : 8=FIXT.1.19=27935=X49=Coinbase56=24ab46f784d1b20db435b852086e325034=3750=TEST52=20250411-01:57:20.686641369=2262=ba2ffebd-86b0-430d-b535-d9d3b46840d1268=1279=2269=1278=f2712f5c-71cb-4b15-975b-a9e2bc14e78783=159757832155=BTC-USD271=0.0000000060=20250411-01:57:20.68460258=FILLED10=148
20250411-01:57:20.919344000 : 8=FIXT.1.19=30035=X49=Coinbase56=24ab46f784d1b20db435b852086e325034=3850=TEST52=20250411-01:57:20.805529369=2262=ba2ffebd-86b0-430d-b535-d9d3b46840d1268=1279=0269=083=159757832255=BTC-USD270=3.8271=0.6672719929004=2.368815564560=20250411-01:57:20.80381540=237=8e0fb245-f534-412f-a3d6-ad430097283a10=163
20250411-01:57:20.919712000 : 8=FIXT.1.19=32535=X49=Coinbase56=24ab46f784d1b20db435b852086e325034=3950=TEST52=20250411-01:57:20.805583369=2262=ba2ffebd-86b0-430d-b535-d9d3b46840d1268=1279=0269=2278=c5b88ea9-605d-4595-ac52-f7c3f08523ba83=159757832355=BTC-USD270=3.55271=0.6672719960=20250411-01:57:20.80381537=8e0fb245-f534-412f-a3d6-ad430097283a5797=110=002
20250411-01:57:20.923185000 : 8=FIXT.1.19=27835=X49=Coinbase56=24ab46f784d1b20db435b852086e325034=4050=TEST52=20250411-01:57:20.805589369=2262=ba2ffebd-86b0-430d-b535-d9d3b46840d1268=1279=2269=0278=8e0fb245-f534-412f-a3d6-ad430097283a83=159757832455=BTC-USD270=3.8271=060=20250411-01:57:20.80381558=FILLED10=229
20250411-01:57:20.973910000 : 8=FIXT.1.19=28235=X49=Coinbase56=24ab46f784d1b20db435b852086e325034=4150=TEST52=20250411-01:57:20.859483369=2262=ba2ffebd-86b0-430d-b535-d9d3b46840d1268=1279=0269=183=159757832555=BTC-USD270=3.23271=0.6232294660=20250411-01:57:20.85839140=237=dee5c151-1ff4-4e87-ac1c-e4acab3e9e1610=127
20250411-01:57:20.974434000 : 8=FIXT.1.19=32535=X49=Coinbase56=24ab46f784d1b20db435b852086e325034=4250=TEST52=20250411-01:57:20.859491369=2262=ba2ffebd-86b0-430d-b535-d9d3b46840d1268=1279=0269=2278=4d60a78e-b39b-420e-b830-bc0f3f4fdde283=159757832655=BTC-USD270=3.53271=0.6232294660=20250411-01:57:20.85839137=dee5c151-1ff4-4e87-ac1c-e4acab3e9e165797=210=213
20250411-01:57:20.974631000 : 8=FIXT.1.19=28835=X49=Coinbase56=24ab46f784d1b20db435b852086e325034=4350=TEST52=20250411-01:57:20.859492369=2262=ba2ffebd-86b0-430d-b535-d9d3b46840d1268=1279=2269=1278=dee5c151-1ff4-4e87-ac1c-e4acab3e9e1683=159757832755=BTC-USD270=3.23271=0.0000000060=20250411-01:57:20.85839158=FILLED10=039
20250411-01:57:21.229395000 : 8=FIXT.1.19=27735=X49=Coinbase56=24ab46f784d1b20db435b852086e325034=4450=TEST52=20250411-01:57:21.114810369=2262=ba2ffebd-86b0-430d-b535-d9d3b46840d1268=1279=0269=083=159757832855=BTC-USD29004=2.208895519560=20250411-01:57:21.11345040=137=95d773d7-3124-423e-a364-bc2bb60e1a8d10=120
20250411-01:57:21.229986000 : 8=FIXT.1.19=32535=X49=Coinbase56=24ab46f784d1b20db435b852086e325034=4550=TEST52=20250411-01:57:21.114820369=2262=ba2ffebd-86b0-430d-b535-d9d3b46840d1268=1279=0269=2278=c5b88ea9-605d-4595-ac52-f7c3f08523ba83=159757832955=BTC-USD270=3.55271=0.6222240960=20250411-01:57:21.11345037=95d773d7-3124-423e-a364-bc2bb60e1a8d5797=110=012
20250411-01:57:21.230129000 : 8=FIXT.1.19=26435=X49=Coinbase56=24ab46f784d1b20db435b852086e325034=4650=TEST52=20250411-01:57:21.114823369=2262=ba2ffebd-86b0-430d-b535-d9d3b46840d1268=1279=2269=0278=95d773d7-3124-423e-a364-bc2bb60e1a8d83=159757833055=BTC-USD60=20250411-01:57:21.11345058=FILLED10=131
20250411-01:57:21.257719000 : 8=FIXT.1.19=27335=X49=Coinbase56=24ab46f784d1b20db435b852086e325034=4750=TEST52=20250411-01:57:21.144006369=2262=ba2ffebd-86b0-430d-b535-d9d3b46840d1268=1279=0269=183=159757833155=BTC-USD271=0.6232294660=20250411-01:57:21.14249340=137=4d785b9c-1e97-48cc-9b60-60673464856f10=058
20250411-01:57:21.258517000 : 8=FIXT.1.19=32535=X49=Coinbase56=24ab46f784d1b20db435b852086e325034=4850=TEST52=20250411-01:57:21.144015369=2262=ba2ffebd-86b0-430d-b535-d9d3b46840d1268=1279=0269=2278=4d60a78e-b39b-420e-b830-bc0f3f4fdde283=159757833255=BTC-USD270=3.53271=0.6232294660=20250411-01:57:21.14249337=4d785b9c-1e97-48cc-9b60-60673464856f5797=210=047
20250411-01:57:21.258755000 : 8=FIXT.1.19=27935=X49=Coinbase56=24ab46f784d1b20db435b852086e325034=4950=TEST52=20250411-01:57:21.144028369=2262=ba2ffebd-86b0-430d-b535-d9d3b46840d1268=1279=2269=1278=4d785b9c-1e97-48cc-9b60-60673464856f83=159757833355=BTC-USD271=0.0000000060=20250411-01:57:21.14249358=FILLED10=231
20250411-01:57:21.345436000 : 8=FIXT.1.19=27735=X49=Coinbase56=24ab46f784d1b20db435b852086e325034=5050=TEST52=20250411-01:57:21.228488369=2262=ba2ffebd-86b0-430d-b535-d9d3b46840d1268=1279=0269=083=159757833455=BTC-USD29004=2.208895519560=20250411-01:57:21.22741040=137=e6bccb21-218d-460b-906c-d5ac970017a310=171
20250411-01:57:21.345742000 : 8=FIXT.1.19=32535=X49=Coinbase56=24ab46f784d1b20db435b852086e325034=5150=TEST52=20250411-01:57:21.228493369=2262=ba2ffebd-86b0-430d-b535-d9d3b46840d1268=1279=0269=2278=c5b88ea9-605d-4595-ac52-f7c3f08523ba83=159757833555=BTC-USD270=3.55271=0.6222240960=20250411-01:57:21.22741037=e6bccb21-218d-460b-906c-d5ac970017a35797=110=058
20250411-01:57:21.345966000 : 8=FIXT.1.19=26435=X49=Coinbase56=24ab46f784d1b20db435b852086e325034=5250=TEST52=20250411-01:57:21.228496369=2262=ba2ffebd-86b0-430d-b535-d9d3b46840d1268=1279=2269=0278=e6bccb21-218d-460b-906c-d5ac970017a383=159757833655=BTC-USD60=20250411-01:57:21.22741058=FILLED10=186
20250411-01:57:21.371921000 : 8=FIXT.1.19=27335=X49=Coinbase56=24ab46f784d1b20db435b852086e325034=5350=TEST52=20250411-01:57:21.257977369=2262=ba2ffebd-86b0-430d-b535-d9d3b46840d1268=1279=0269=183=159757833755=BTC-USD271=0.6232294660=20250411-01:57:21.25621040=137=7cd6e2fd-5a9e-4e4f-84e6-afe70b04f22710=137
20250411-01:57:21.372198000 : 8=FIXT.1.19=32535=X49=Coinbase56=24ab46f784d1b20db435b852086e325034=5450=TEST52=20250411-01:57:21.257982369=2262=ba2ffebd-86b0-430d-b535-d9d3b46840d1268=1279=0269=2278=4d60a78e-b39b-420e-b830-bc0f3f4fdde283=159757833855=BTC-USD270=3.53271=0.6232294660=20250411-01:57:21.25621037=7cd6e2fd-5a9e-4e4f-84e6-afe70b04f2275797=210=122
20250411-01:57:21.372368000 : 8=FIXT.1.19=27935=X49=Coinbase56=24ab46f784d1b20db435b852086e325034=5550=TEST52=20250411-01:57:21.257984369=2262=ba2ffebd-86b0-430d-b535-d9d3b46840d1268=1279=2269=1278=7cd6e2fd-5a9e-4e4f-84e6-afe70b04f22783=159757833955=BTC-USD271=0.0000000060=20250411-01:57:21.25621058=FILLED10=048
20250411-01:57:21.606132000 : 8=FIXT.1.19=28235=X49=Coinbase56=24ab46f784d1b20db435b852086e325034=5650=TEST52=20250411-01:57:21.490611369=2262=ba2ffebd-86b0-430d-b535-d9d3b46840d1268=1279=0269=083=159757834055=BTC-USD270=3.75271=0.6232294660=20250411-01:57:21.48909740=237=b8950601-cd08-4e7f-b7d1-40d55934c9d910=063
20250411-01:57:21.606783000 : 8=FIXT.1.19=32535=X49=Coinbase56=24ab46f784d1b20db435b852086e325034=5750=TEST52=20250411-01:57:21.490667369=2262=ba2ffebd-86b0-430d-b535-d9d3b46840d1268=1279=0269=2278=c5b88ea9-605d-4595-ac52-f7c3f08523ba83=159757834155=BTC-USD270=3.55271=0.6232294660=20250411-01:57:21.48909737=b8950601-cd08-4e7f-b7d1-40d55934c9d95797=110=028
20250411-01:57:21.606915000 : 8=FIXT.1.19=28835=X49=Coinbase56=24ab46f784d1b20db435b852086e325034=5850=TEST52=20250411-01:57:21.490674369=2262=ba2ffebd-86b0-430d-b535-d9d3b46840d1268=1279=2269=0278=b8950601-cd08-4e7f-b7d1-40d55934c9d983=159757834255=BTC-USD270=3.75271=0.0000000060=20250411-01:57:21.48909758=FILLED10=240
20250411-01:57:21.659720000 : 8=FIXT.1.19=28235=X49=Coinbase56=24ab46f784d1b20db435b852086e325034=5950=TEST52=20250411-01:57:21.545052369=2262=ba2ffebd-86b0-430d-b535-d9d3b46840d1268=1279=0269=183=159757834355=BTC-USD270=3.29271=0.6232294660=20250411-01:57:21.54387340=237=c402b7c2-f4e9-4ad7-8564-e0337ebb324a10=140
20250411-01:57:21.660150000 : 8=FIXT.1.19=32535=X49=Coinbase56=24ab46f784d1b20db435b852086e325034=6050=TEST52=20250411-01:57:21.545193369=2262=ba2ffebd-86b0-430d-b535-d9d3b46840d1268=1279=0269=2278=4d60a78e-b39b-420e-b830-bc0f3f4fdde283=159757834455=BTC-USD270=3.53271=0.6232294660=20250411-01:57:21.54387337=c402b7c2-f4e9-4ad7-8564-e0337ebb324a5797=210=218
20250411-01:57:21.660351000 : 8=FIXT.1.19=28835=X49=Coinbase56=24ab46f784d1b20db435b852086e325034=6150=TEST52=20250411-01:57:21.545195369=2262=ba2ffebd-86b0-430d-b535-d9d3b46840d1268=1279=2269=1278=c402b7c2-f4e9-4ad7-8564-e0337ebb324a83=159757834555=BTC-USD270=3.29271=0.0000000060=20250411-01:57:21.54387358=FILLED10=051
20250411-01:57:21.947965000 : 8=FIXT.1.19=28235=X49=Coinbase56=24ab46f784d1b20db435b852086e325034=6250=TEST52=20250411-01:57:21.833974369=2262=ba2ffebd-86b0-430d-b535-d9d3b46840d1268=1279=0269=083=159757834655=BTC-USD270=3.72271=0.6232294660=20250411-01:57:21.83230340=237=fefb3a9e-b1ae-4211-b4c7-1dd055e5963f10=024
20250411-01:57:21.948776000 : 8=FIXT.1.19=32535=X49=Coinbase56=24ab46f784d1b20db435b852086e325034=6350=TEST52=20250411-01:57:21.833986369=2262=ba2ffebd-86b0-430d-b535-d9d3b46840d1268=1279=0269=2278=c5b88ea9-605d-4595-ac52-f7c3f08523ba83=159757834755=BTC-USD270=3.55271=0.6232294660=20250411-01:57:21.83230337=fefb3a9e-b1ae-4211-b4c7-1dd055e5963f5797=110=240
20250411-01:57:21.949089000 : 8=FIXT.1.19=28835=X49=Coinbase56=24ab46f784d1b20db435b852086e325034=6450=TEST52=20250411-01:57:21.833988369=2262=ba2ffebd-86b0-430d-b535-d9d3b46840d1268=1279=2269=0278=fefb3a9e-b1ae-4211-b4c7-1dd055e5963f83=159757834855=BTC-USD270=3.72271=0.0000000060=20250411-01:57:21.83230358=FILLED10=197
20250411-01:57:21.951128000 : 8=FIXT.1.19=28235=X49=Coinbase56=24ab46f784d1b20db435b852086e325034=6550=TEST52=20250411-01:57:21.833990369=2262=ba2ffebd-86b0-430d-b535-d9d3b46840d1268=1279=0269=083=159757834955=BTC-USD270=3.88271=0.6232294660=20250411-01:57:21.83230340=237=23a3c863-fb67-488c-8189-ff8c96f91bcc10=185
20250411-01:57:21.951276000 : 8=FIXT.1.19=32535=X49=Coinbase56=24ab46f784d1b20db435b852086e325034=6650=TEST52=20250411-01:57:21.833993369=2262=ba2ffebd-86b0-430d-b535-d9d3b46840d1268=1279=0269=2278=c5b88ea9-605d-4595-ac52-f7c3f08523ba83=159757835055=BTC-USD270=3.55271=0.6232294660=20250411-01:57:21.83230337=23a3c863-fb67-488c-8189-ff8c96f91bcc5797=110=129
20250411-01:57:21.951407000 : 8=FIXT.1.19=28835=X49=Coinbase56=24ab46f784d1b20db435b852086e325034=6750=TEST52=20250411-01:57:21.834007369=2262=ba2ffebd-86b0-430d-b535-d9d3b46840d1268=1279=2269=0278=23a3c863-fb67-488c-8189-ff8c96f91bcc83=159757835155=BTC-USD270=3.88271=0.0000000060=20250411-01:57:21.83230358=FILLED10=078
20250411-01:57:22.117505000 : 8=FIXT.1.19=28235=X49=Coinbase56=24ab46f784d1b20db435b852086e325034=6850=TEST52=20250411-01:57:22.003707369=2262=ba2ffebd-86b0-430d-b535-d9d3b46840d1268=1279=0269=183=159757835255=BTC-USD270=3.35271=0.6232294660=20250411-01:57:22.00263440=237=f7460d07-c5b0-4f1d-a16c-8f1ae76cdecd10=056
20250411-01:57:22.119388000 : 8=FIXT.1.19=32535=X49=Coinbase56=24ab46f784d1b20db435b852086e325034=6950=TEST52=20250411-01:57:22.003719369=2262=ba2ffebd-86b0-430d-b535-d9d3b46840d1268=1279=0269=2278=4d60a78e-b39b-420e-b830-bc0f3f4fdde283=159757835355=BTC-USD270=3.53271=0.6232294660=20250411-01:57:22.00263437=f7460d07-c5b0-4f1d-a16c-8f1ae76cdecd5797=210=143
20250411-01:57:22.119693000 : 8=FIXT.1.19=28835=X49=Coinbase56=24ab46f784d1b20db435b852086e325034=7050=TEST52=20250411-01:57:22.003722369=2262=ba2ffebd-86b0-430d-b535-d9d3b46840d1268=1279=2269=1278=f7460d07-c5b0-4f1d-a16c-8f1ae76cdecd83=159757835455=BTC-USD270=3.35271=0.0000000060=20250411-01:57:22.00263458=FILLED10=212
20250411-01:57:22.120138000 : 8=FIXT.1.19=28235=X49=Coinbase56=24ab46f784d1b20db435b852086e325034=7150=TEST52=20250411-01:57:22.003834369=2262=ba2ffebd-86b0-430d-b535-d9d3b46840d1268=1279=0269=183=159757835555=BTC-USD270=3.33271=0.6232294660=20250411-01:57:22.00263440=237=44594246-9587-4782-bd21-b1ddaa3323e010=183
20250411-01:57:22.120366000 : 8=FIXT.1.19=32535=X49=Coinbase56=24ab46f784d1b20db435b852086e325034=7250=TEST52=20250411-01:57:22.003838369=2262=ba2ffebd-86b0-430d-b535-d9d3b46840d1268=1279=0269=2278=4d60a78e-b39b-420e-b830-bc0f3f4fdde283=159757835655=BTC-USD270=3.53271=0.6232294660=20250411-01:57:22.00263437=44594246-9587-4782-bd21-b1ddaa3323e05797=210=017
20250411-01:57:22.120541000 : 8=FIXT.1.19=28835=X49=Coinbase56=24ab46f784d1b20db435b852086e325034=7350=TEST52=20250411-01:57:22.003841369=2262=ba2ffebd-86b0-430d-b535-d9d3b46840d1268=1279=2269=1278=44594246-9587-4782-bd21-b1ddaa3323e083=159757835755=BTC-USD270=3.33271=0.0000000060=20250411-01:57:22.00263458=FILLED10=093
20250411-01:57:22.120687000 : 8=FIXT.1.19=28235=X49=Coinbase56=24ab46f784d1b20db435b852086e325034=7450=TEST52=20250411-01:57:22.003899369=2262=ba2ffebd-86b0-430d-b535-d9d3b46840d1268=1279=0269=183=159757835855=BTC-USD270=3.24271=0.6232294660=20250411-01:57:22.00263440=237=03c17f11-d7d2-4f0c-9ab5-48d693af986d10=147
20250411-01:57:22.120949000 : 8=FIXT.1.19=32535=X49=Coinbase56=24ab46f784d1b20db435b852086e325034=7550=TEST52=20250411-01:57:22.003906369=2262=ba2ffebd-86b0-430d-b535-d9d3b46840d1268=1279=0269=2278=4d60a78e-b39b-420e-b830-bc0f3f4fdde283=159757835955=BTC-USD270=3.53271=0.6232294660=20250411-01:57:22.00263437=03c17f11-d7d2-4f0c-9ab5-48d693af986d5797=210=222
20250411-01:57:22.121219000 : 8=FIXT.1.19=28835=X49=Coinbase56=24ab46f784d1b20db435b852086e325034=7650=TEST52=20250411-01:57:22.003944369=2262=ba2ffebd-86b0-430d-b535-d9d3b46840d1268=1279=2269=1278=03c17f11-d7d2-4f0c-9ab5-48d693af986d83=159757836055=BTC-USD270=3.24271=0.0000000060=20250411-01:57:22.00263458=FILLED10=041
20250411-01:57:23.662247000 : 8=FIXT.1.19=28235=X49=Coinbase56=24ab46f784d1b20db435b852086e325034=7750=TEST52=20250411-01:57:23.548147369=2262=ba2ffebd-86b0-430d-b535-d9d3b46840d1268=1279=0269=083=159757836155=BTC-USD270=3.73271=0.6232294660=20250411-01:57:23.54630940=237=b752cc10-bd0e-45e0-8578-dffd09a7bfa110=035
20250411-01:57:23.663210000 : 8=FIXT.1.19=32535=X49=Coinbase56=24ab46f784d1b20db435b852086e325034=7850=TEST52=20250411-01:57:23.548163369=2262=ba2ffebd-86b0-430d-b535-d9d3b46840d1268=1279=0269=2278=c5b88ea9-605d-4595-ac52-f7c3f08523ba83=159757836255=BTC-USD270=3.55271=0.6232294660=20250411-01:57:23.54630937=b752cc10-bd0e-45e0-8578-dffd09a7bfa15797=110=245
20250411-01:57:23.663374000 : 8=FIXT.1.19=28835=X49=Coinbase56=24ab46f784d1b20db435b852086e325034=7950=TEST52=20250411-01:57:23.548166369=2262=ba2ffebd-86b0-430d-b535-d9d3b46840d1268=1279=2269=0278=b752cc10-bd0e-45e0-8578-dffd09a7bfa183=159757836355=BTC-USD270=3.73271=0.0000000060=20250411-01:57:23.54630958=FILLED10=204
20250411-01:57:23.665563000 : 8=FIXT.1.19=91735=W49=Coinbase56=24ab46f784d1b20db435b852086e325034=8050=TEST52=20250411-01:57:23.551696369=2262=ba2ffebd-86b0-430d-b535-d9d3b46840d183=1597578360893=N55=BTC-USD1682=full_trading268=10269=0278=4d60a78e-b39b-420e-b830-bc0f3f4fdde2270=3.53271=255951.72146893269=0278=9d9353ab-229f-423a-89a3-c52a46543bc9270=3.53271=18127.30103418269=0278=f5fc5e68-a52c-44d3-87ef-3785312f4782270=3.48271=0.29310888269=0278=995c849e-6749-48f6-b5b2-5805faadcecd270=3.48271=0.62322946269=0278=dcccb470-c535-433a-9198-4e2b4c26d99d270=3.47271=0.29311495269=0278=f05d9766-970d-44ca-aa4d-e8b2720bbda8270=3.46271=0.29026870269=0278=2c4d7d5a-33aa-4058-b546-480b6a2168a4270=3.44271=0.29828577269=0278=37dbcf16-0b3d-4f67-bc90-e36268b99e0e270=3.42271=0.30270947269=0278=7641d6ff-f76a-4784-a168-22b42ee61f37270=3.42271=0.61971831269=0278=4c63c0b7-30e0-4ef1-931f-0090359f978e270=3.41271=0.3215896210=009
20250411-01:57:23.668640000 : 8=FIXT.1.19=14035=334=349=24ab46f784d1b20db435b852086e325052=20250411-01:57:23.66856=Coinbase45=8058=Tag appears more than once371=269372=W373=1310=209
20250411-01:57:23.668849000 : 8=FIXT.1.19=90835=W49=Coinbase56=24ab46f784d1b20db435b852086e325034=8150=TEST52=20250411-01:57:23.551939369=2262=ba2ffebd-86b0-430d-b535-d9d3b46840d183=1597578360893=N55=BTC-USD1682=full_trading268=10269=0278=d6b4aa4e-d588-4c96-83aa-8e8d8accb1a4270=3.41271=0.30121104269=0278=80600718-10d2-4555-8213-0298dc869086270=3.40271=0.61971831269=0278=e8b3d8da-1663-413c-b7fb-6aba23b01440270=3.39271=0.31006477269=0278=6e802914-f632-4e90-857c-95726b9abf42270=3.39271=0.61971831269=0278=bcbe17c3-9059-4c38-8ab8-8e78f1ef9062270=3.38271=0.32617981269=0278=57bb77fd-337f-49bc-a56f-a4e2dff851ee270=3.37271=0.31071676269=0278=ded4b51d-349f-4726-8379-6761a3576bb6270=3.33271=0.31560513269=0278=ff7aff09-38de-47ac-a3cb-9beacb0b9ad8270=3.33271=0.30682342269=0278=d1da558a-e9d2-4e11-b26e-1eb80a1a34c5270=3.32271=0.31700685269=0278=9ee34527-d4d8-4659-b2ea-cdff3dc4a8fa270=3.32271=0.3218195110=240
20250411-01:57:23.669482000 : 8=FIXT.1.19=14035=334=449=24ab46f784d1b20db435b852086e325052=20250411-01:57:23.66956=Coinbase45=8158=Tag appears more than once371=269372=W373=1310=212
20250411-01:57:23.669566000 : 8=FIXT.1.19=90835=W49=Coinbase56=24ab46f784d1b20db435b852086e325034=8250=TEST52=20250411-01:57:23.552188369=2262=ba2ffebd-86b0-430d-b535-d9d3b46840d183=1597578360893=N55=BTC-USD1682=full_trading268=10269=0278=7abf2220-0421-460f-9dbb-14c41564e41a270=3.32271=0.31308436269=0278=69634ec5-f71a-4990-b56d-13c3069a455a270=3.31271=0.32329458269=0278=2f333c17-a386-4d52-8ff1-eadcb99bc22f270=3.31271=0.31999220269=0278=f02efc37-0b1e-470b-99ef-e31012887d73270=3.30271=0.32771570269=0278=6d430950-8078-4987-8995-e581564e368d270=3.29271=0.30702763269=0278=841f895a-cd2d-4082-9a37-b50fc19e35bf270=3.28271=0.32610801269=0278=3cf93093-e42b-4c24-95ea-c367d96427fe270=3.27271=0.33588654269=0278=f29c94bc-d1c2-4145-97b0-ecb77d81a8bf270=3.27271=0.31661408269=0278=d208c4fb-56c6-4911-85c9-77b68a5ba6ab270=3.25271=0.30961623269=0278=e88796ff-68c8-4463-914b-46e09fbaf639270=3.25271=0.3358984510=116
20250411-01:57:23.670096000 : 8=FIXT.1.19=14035=334=549=24ab46f784d1b20db435b852086e325052=20250411-01:57:23.66956=Coinbase45=8258=Tag appears more than once371=269372=W373=1310=214
20250411-01:57:23.670182000 : 8=FIXT.1.19=90835=W49=Coinbase56=24ab46f784d1b20db435b852086e325034=8350=TEST52=20250411-01:57:23.552437369=2262=ba2ffebd-86b0-430d-b535-d9d3b46840d183=1597578360893=N55=BTC-USD1682=full_trading268=10269=0278=06f345fb-0292-45fc-8237-9ad1a84b541c270=3.24271=0.31528507269=0278=fa20c2c7-df80-4941-9a9c-a6ef2e579480270=3.23271=0.33432448269=0278=a833d230-a749-4bf4-823e-93adc40b773d270=3.23271=0.31165878269=0278=2abb6e15-b9cd-415b-8c9b-99a61c750310270=3.22271=0.32048714269=0278=ec44a6d8-ae5f-4809-89d7-0f7a3adac547270=3.21271=0.33230954269=0278=9cf61c67-c4fc-4bac-92fd-d4e2b56248aa270=3.21271=0.33583951269=0278=210b2518-bb42-461a-9c7e-b4e04c5ffcc6270=3.21271=0.32669007269=0278=2e3fa1b2-20f1-4694-9be4-322040b75152270=3.21271=0.32907979269=0278=05dd5607-92c9-4296-8cdc-27cdff004dea270=3.21271=0.32776075269=0278=87944de7-a5f1-4033-a3d8-cbc10f3a5232270=3.20271=0.3222517010=072
20250411-01:57:23.670733000 : 8=FIXT.1.19=14035=334=649=24ab46f784d1b20db435b852086e325052=20250411-01:57:23.67056=Coinbase45=8358=Tag appears more than once371=269372=W373=1310=208
20250411-01:57:23.670818000 : 8=FIXT.1.19=90935=W49=Coinbase56=24ab46f784d1b20db435b852086e325034=8450=TEST52=20250411-01:57:23.552687369=2262=ba2ffebd-86b0-430d-b535-d9d3b46840d183=1597578360893=N55=BTC-USD1682=full_trading268=10269=0278=30f6bb59-2469-4e6d-8fa5-13666373901f270=3.19271=0.31386496269=0278=6a5d2852-7ddc-456e-acb5-bfadcc0c1360270=3.19271=0.32157390269=0278=5d00d8a2-5aea-4836-ba19-74fe67116df8270=3.18271=0.32651049269=0278=acc71746-3591-4dde-a7e2-c2795d0ad125270=3.17271=0.31577131269=0278=13982796-c2a8-4740-95e2-5aca0fdfd8bb270=3.16271=0.33021170269=0278=9f2f0737-661e-43d7-89f9-959ed5e08306270=3.16271=0.33082075269=0278=7e0e2d14-fa77-4978-8cae-d9660fd13e6d270=3.16271=0.32014975269=0278=82826a7d-848c-4516-a7b6-5ec6881609a8270=2.00271=10.00000000269=0278=590048d5-ee44-49dc-b66d-1a692e055133270=1.94271=0.51546392269=0278=22bdda11-16cd-488b-9fa9-da098dad543e270=1.94271=0.5154639210=147
20250411-01:57:23.671958000 : 8=FIXT.1.19=14035=334=749=24ab46f784d1b20db435b852086e325052=20250411-01:57:23.67156=Coinbase45=8458=Tag appears more than once371=269372=W373=1310=211
20250411-01:57:23.672087000 : 8=FIXT.1.19=90835=W49=Coinbase56=24ab46f784d1b20db435b852086e325034=8550=TEST52=20250411-01:57:23.552937369=2262=ba2ffebd-86b0-430d-b535-d9d3b46840d183=1597578360893=N55=BTC-USD1682=full_trading268=10269=0278=d356ef8b-596e-47e7-bf90-cc015b85fc57270=1.93271=0.52331606269=0278=aa8d48bc-97fb-4d00-b923-66d37cc8c66a270=1.93271=0.52331606269=0278=7d51dcb4-a7f8-4cca-b2d0-e902403d1b9f270=1.93271=0.52331606269=0278=f7680950-3af2-4723-a6e4-5cbd528ca900270=1.93271=0.52331606269=0278=fdeff994-4866-47af-9dde-a25947a26606270=1.93271=0.52331606269=0278=65e7e2bb-023d-4936-bb4e-ff7625ba7264270=1.93271=0.52331606269=0278=53732639-572c-4cd5-b61e-e4f534d1d540270=1.93271=0.52331606269=0278=24da8927-1dd1-468b-9437-ff366f5bfa11270=1.93271=0.52331606269=0278=baa5862c-41e8-458c-83d3-c095bb68ed17270=1.93271=0.52331606269=0278=92a3c3e3-7afe-4d02-a0d8-96f512b63bb7270=1.93271=0.5233160610=205
20250411-01:57:23.680523000 : 8=FIXT.1.19=14035=334=849=24ab46f784d1b20db435b852086e325052=20250411-01:57:23.67556=Coinbase45=8558=Tag appears more than once371=269372=W373=1310=217
20250411-01:57:23.680631000 : 8=FIXT.1.19=90835=W49=Coinbase56=24ab46f784d1b20db435b852086e325034=8650=TEST52=20250411-01:57:23.553187369=2262=ba2ffebd-86b0-430d-b535-d9d3b46840d183=1597578360893=N55=BTC-USD1682=full_trading268=10269=0278=9d2a564e-f178-4966-9baf-5814a1c1686b270=1.93271=0.52331606269=0278=f9e6b978-87f6-4397-8d82-07cf698c123f270=1.93271=0.52331606269=0278=3e64b388-13d3-441d-b241-aa8dd6fe55e6270=1.93271=0.52331606269=0278=60300433-87b0-4031-bb1e-12cf9d773d3f270=1.93271=0.52331606269=0278=1bdd5f5a-1d99-4eed-af09-c187bcbbd2d8270=1.93271=0.52331606269=0278=4ed6f6b9-77fb-4255-a188-f243dd0cdb3c270=1.93271=0.52331606269=0278=9ad1fc18-5a38-4edb-ac5c-6ac826a8a846270=1.93271=0.52331606269=0278=1c218c8c-baea-4a1f-838e-4a3a94b468e1270=1.93271=0.52331606269=0278=fd70f5e2-d2c9-472a-ab40-a775afafd73d270=1.93271=0.52331606269=0278=96f5e3a5-1c2a-4db6-a3fb-fd1f13d5d559270=1.93271=0.5233160610=205
20250411-01:57:23.681227000 : 8=FIXT.1.19=14035=334=949=24ab46f784d1b20db435b852086e325052=20250411-01:57:23.68056=Coinbase45=8658=Tag appears more than once371=269372=W373=1310=215
20250411-01:57:23.681315000 : 8=FIXT.1.19=90835=W49=Coinbase56=24ab46f784d1b20db435b852086e325034=8750=TEST52=20250411-01:57:23.553437369=2262=ba2ffebd-86b0-430d-b535-d9d3b46840d183=1597578360893=N55=BTC-USD1682=full_trading268=10269=0278=4a015a4c-490a-4c40-974f-9dfb7feb335d270=1.93271=0.52331606269=0278=d919363e-2c54-404f-bc0b-063e2f12bec4270=1.93271=0.52331606269=0278=d4636d6c-85c6-4ac9-9afb-70ca636f4ad4270=1.93271=0.52331606269=0278=bda09690-f345-4c33-ae8b-e8c78da11b5a270=1.93271=0.52331606269=0278=1a81ae10-b700-42a0-89a3-7d7a3eea0ebb270=1.93271=0.52331606269=0278=1ace5afa-e550-4abf-a458-52e46e1b54f0270=1.93271=0.52331606269=0278=2332d1c9-67e7-457a-abfe-f5e9a8c2ea05270=1.93271=0.52331606269=0278=6afa1f19-0ec5-49fd-8b74-06a12a6c5ca9270=1.93271=0.52331606269=0278=3fa3413d-c26c-472f-9cc5-da1c48935c63270=1.93271=0.52331606269=0278=3f9e43c4-2e62-4d51-b4cb-ad207c693331270=1.93271=0.5233160610=135
20250411-01:57:23.682848000 : 8=FIXT.1.19=14135=334=1049=24ab46f784d1b20db435b852086e325052=20250411-01:57:23.68256=Coinbase45=8758=Tag appears more than once371=269372=W373=1310=003
20250411-01:57:23.683028000 : 8=FIXT.1.19=90835=W49=Coinbase56=24ab46f784d1b20db435b852086e325034=8850=TEST52=20250411-01:57:23.553687369=2262=ba2ffebd-86b0-430d-b535-d9d3b46840d183=1597578360893=N55=BTC-USD1682=full_trading268=10269=0278=29e8bfcf-c764-4f7e-997d-09abf72bbc00270=1.93271=0.52331606269=0278=cf3e8b26-09ae-4dfb-9b84-b12a7e199a5a270=1.93271=0.52331606269=0278=08db3e51-e927-47d3-a9dd-2f887c58dc85270=1.93271=0.52331606269=0278=353ae741-9473-4cc5-9ab7-7e5de8ae55d0270=1.93271=0.52331606269=0278=4d037208-2072-480f-98ac-7be9c24f18f4270=1.93271=0.52331606269=0278=b598f678-da6e-4c01-90ed-d702c42f8a65270=1.93271=0.52331606269=0278=5f69b1a0-b5d1-4715-9be1-9bdf008d97d7270=1.93271=0.52331606269=0278=ef063d15-248a-4eae-97f4-278be5106d80270=1.93271=0.52331606269=0278=f8b20207-84bc-44e9-a2fe-9ad775e2ecb1270=1.93271=0.52331606269=0278=75bce2b7-bc58-4479-8bfb-144f88f2262b270=1.93271=0.5233160610=142
20250411-01:57:23.683707000 : 8=FIXT.1.19=14135=334=1149=24ab46f784d1b20db435b852086e325052=20250411-01:57:23.68356=Coinbase45=8858=Tag appears more than once371=269372=W373=1310=006
20250411-01:57:23.890480000 : 8=FIXT.1.19=90835=W49=Coinbase56=24ab46f784d1b20db435b852086e325034=8950=TEST52=20250411-01:57:23.553937369=2262=ba2ffebd-86b0-430d-b535-d9d3b46840d183=1597578360893=N55=BTC-USD1682=full_trading268=10269=0278=1f6e2a79-8b10-4a7f-89de-0f1fa03692c7270=1.93271=0.52331606269=0278=d1b80bf5-9b17-44b4-9577-6fe71170b578270=1.93271=0.52331606269=0278=b891e26a-c20c-4fce-ba1c-487fe139a4cc270=1.93271=0.52331606269=0278=5d06d3f6-3189-4394-b3c5-6a2bda14b6d1270=1.93271=0.52331606269=0278=e5791c0f-3937-4a66-9b98-26f79a3891be270=1.93271=0.52331606269=0278=c62591c6-7dfa-46a7-8f20-6a5f22804999270=1.93271=0.52331606269=0278=7c503558-c0b8-457b-8c46-71ece3f7fc8a270=1.93271=0.52331606269=0278=f763bb56-2f21-4a9b-bd48-f84dc1bd5ee5270=1.93271=0.52331606269=0278=42214b03-1fc2-46b3-9e83-91b23a510e5a270=1.93271=0.52331606269=0278=1c7c52ed-7d39-4326-b3b8-98f05a9b3ef0270=1.93271=0.5233160610=131
20250411-01:57:23.891566000 : 8=FIXT.1.19=14135=334=1249=24ab46f784d1b20db435b852086e325052=20250411-01:57:23.89156=Coinbase45=8958=Tag appears more than once371=269372=W373=1310=009
20250411-01:57:23.896314000 : 8=FIXT.1.19=90835=W49=Coinbase56=24ab46f784d1b20db435b852086e325034=9050=TEST52=20250411-01:57:23.554187369=2262=ba2ffebd-86b0-430d-b535-d9d3b46840d183=1597578360893=N55=BTC-USD1682=full_trading268=10269=0278=3313309e-45e7-4e7b-8c55-4f9a8ec1b351270=1.93271=0.52331606269=0278=78801ffb-ec5a-4c74-9d08-3e86fd9db4dd270=1.93271=0.52331606269=0278=abe6eea4-1d9c-47d7-847f-2f44aa561b3f270=1.93271=0.52331606269=0278=6a6eb56d-2010-43e2-b78e-5f098081bb64270=1.93271=0.52331606269=0278=b53c01ff-f450-4b05-8ad1-e7894b45e0e0270=1.93271=0.52331606269=0278=4747863e-c0a6-4ef5-8faf-e8934bca4f8b270=1.93271=0.52331606269=0278=81a8a629-57f4-4e3a-ac25-2e9ee1f357c2270=1.93271=0.52331606269=0278=1e239259-7be4-476a-845d-1b92fd951d8b270=1.93271=0.52331606269=0278=189eb272-48f9-4915-b7e1-a86dcc505c4a270=1.93271=0.52331606269=0278=0562b9f7-aae3-4961-bd97-f5b8cde0ec34270=1.93271=0.5233160610=061
20250411-01:57:23.897117000 : 8=FIXT.1.19=14135=334=1349=24ab46f784d1b20db435b852086e325052=20250411-01:57:23.89656=Coinbase45=9058=Tag appears more than once371=269372=W373=1310=007
20250411-01:57:23.897221000 : 8=FIXT.1.19=91135=W49=Coinbase56=24ab46f784d1b20db435b852086e325034=9150=TEST52=20250411-01:57:23.554437369=2262=ba2ffebd-86b0-430d-b535-d9d3b46840d183=1597578360893=N55=BTC-USD1682=full_trading268=10269=0278=5103331b-7300-487b-bc2c-a6032bf4be7e270=1.93271=0.52331606269=0278=78ac85ac-2478-4991-a084-7286982b77cc270=1.93271=0.52331606269=0278=6993b26d-d6dc-4f99-8a53-9500ae5b4ff1270=1.93271=0.52331606269=0278=1c96ab9d-04a6-465a-87e5-3ed33970178f270=1.93271=0.52331606269=0278=6fc0282b-d538-4aa3-8982-bda02bb1b054270=1.93271=0.52331606269=0278=80870aa3-04a2-4d2a-8669-93215130ffee270=1.93271=0.52331606269=0278=b274e872-6923-45fd-b48a-68e685e769cb270=1.93271=0.52331606269=0278=2d4364c0-239c-4f4b-8ce4-2acfe0bb343d270=1.12271=1.00000000269=0278=8fa16a4f-377f-4deb-9a8e-1020aed9edf4270=1.00271=1.00000000269=1278=c5b88ea9-605d-4595-ac52-f7c3f08523ba270=3.55271=5927.5854415010=191
20250411-01:57:23.897830000 : 8=FIXT.1.19=14135=334=1449=24ab46f784d1b20db435b852086e325052=20250411-01:57:23.89756=Coinbase45=9158=Tag appears more than once371=269372=W373=1310=010
20250411-01:57:23.897912000 : 8=FIXT.1.19=93235=W49=Coinbase56=24ab46f784d1b20db435b852086e325034=9250=TEST52=20250411-01:57:23.554687369=2262=ba2ffebd-86b0-430d-b535-d9d3b46840d183=1597578360893=N55=BTC-USD1682=full_trading268=10269=1278=81523bd3-8912-4789-8761-89a9ee42794b270=3.55271=0.30518966269=1278=60fc75ca-0052-40b7-9f18-a6aad9d31b84270=3.56271=18037.00000000269=1278=ad00e2cd-d925-46a4-9e7e-941c6faed2c7270=3.57271=18027.00000000269=1278=fec191b5-64da-4a15-ab4b-36a0d3d10750270=3.57271=0.29025301269=1278=02a780aa-8154-4638-a5ca-53b8198cc724270=3.58271=16937.00000000269=1278=911349fb-1960-4904-9a38-0e2497fb7ccb270=3.58271=0.29896312269=1278=d91e89d4-ac5c-4853-9879-ec8ff5e00a71270=3.59271=17163.00000000269=1278=341d0ad8-6c15-4b5e-aebb-e3caa5af575c270=3.60271=17926.00000000269=1278=9d239e03-1215-4cc7-ad44-3f4097ee70ea270=3.61271=18058.08928020269=1278=9b8bdf7c-8989-49dc-bd4c-a36b2af4bf80270=3.61271=0.6197183110=044
20250411-01:57:23.898551000 : 8=FIXT.1.19=14135=334=1549=24ab46f784d1b20db435b852086e325052=20250411-01:57:23.89856=Coinbase45=9258=Tag appears more than once371=269372=W373=1310=013
20250411-01:57:23.898650000 : 8=FIXT.1.19=92035=W49=Coinbase56=24ab46f784d1b20db435b852086e325034=9350=TEST52=20250411-01:57:23.554937369=2262=ba2ffebd-86b0-430d-b535-d9d3b46840d183=1597578360893=N55=BTC-USD1682=full_trading268=10269=1278=dbb0f332-4189-4df5-879b-e55860b13def270=3.62271=0.28062774269=1278=f7639c39-7e8b-44d1-a2f2-9807e2a3228c270=3.62271=0.27709851269=1278=83be9389-2099-4173-a322-b0933bc99358270=3.62271=19973.00000000269=1278=3a9c5528-ec08-4d9d-bf8d-88e11d72f250270=3.62271=0.61971831269=1278=b89abc22-6b6c-4474-b3fc-ffe21f05cd4e270=3.63271=20016.00000000269=1278=ce0af8a3-149c-4603-905a-be65625fe014270=3.64271=0.27806002269=1278=94b8615f-6fa7-4dc9-bbfa-435fe535bebc270=3.64271=22352.63489459269=1278=5b8fd4d3-38e7-43e9-9602-596138a316ae270=3.67271=0.62322946269=1278=cae3885d-f5b2-4de1-830c-0085e27bbb69270=3.69271=0.27722678269=1278=b9732128-11b1-44fd-bea3-94da9fc853fb270=3.71271=0.2848832910=227
20250411-01:57:23.899275000 : 8=FIXT.1.19=14135=334=1649=24ab46f784d1b20db435b852086e325052=20250411-01:57:23.89856=Coinbase45=9358=Tag appears more than once371=269372=W373=1310=015
20250411-01:57:23.899360000 : 8=FIXT.1.19=90835=W49=Coinbase56=24ab46f784d1b20db435b852086e325034=9450=TEST52=20250411-01:57:23.555188369=2262=ba2ffebd-86b0-430d-b535-d9d3b46840d183=1597578360893=N55=BTC-USD1682=full_trading268=10269=1278=709f2ace-ce1d-46a4-8b9b-b65548c7e38e270=3.73271=0.61971831269=1278=818b83a4-e14e-4ad5-b094-6733f0504003270=3.75271=0.27930225269=1278=3e6990a0-8ef4-4968-8ee8-89b7346c197d270=3.76271=0.28131365269=1278=342794c8-a9d2-4aa5-9886-a819398d69c6270=3.88271=0.27719712269=1278=2839680b-48b3-4f53-86b1-9269987275e7270=3.91271=0.26621275269=1278=fd7b5361-29f8-4b35-bae5-232a64f657b4270=3.95271=0.26131406269=1278=5edaeed0-fae9-4f36-8c77-6fbedf61eefc270=4.02271=0.25091227269=1278=fdbbfd04-ba67-4b23-bbc1-f87f929e7e81270=4.07271=0.24812642269=1278=534b2a85-0852-420d-928b-70cdb6ba2457270=4.10271=0.26961968269=1278=b009f8a1-4a39-493b-b96e-d783e981c915270=4.26271=0.2501957410=099
20250411-01:57:23.899919000 : 8=FIXT.1.19=14135=334=1749=24ab46f784d1b20db435b852086e325052=20250411-01:57:23.89956=Coinbase45=9458=Tag appears more than once371=269372=W373=1310=018
20250411-01:57:23.899998000 : 8=FIXT.1.19=92835=W49=Coinbase56=24ab46f784d1b20db435b852086e325034=9550=TEST52=20250411-01:57:23.555438369=2262=ba2ffebd-86b0-430d-b535-d9d3b46840d183=1597578360893=N55=BTC-USD1682=full_trading268=10269=1278=729a899c-ac2d-4541-b0a2-cbdd5df9bf98270=10.00271=10.00000000269=1278=eb1e5d45-d081-4ef8-a83e-1f5348fbda96270=10.00271=10.00000000269=1278=0cd67977-85eb-45fa-ae72-d45b92ca24f4270=10.00271=10.00000000269=1278=5d931559-6758-4b75-9d6d-6438d25b497f270=10.00271=10.00000000269=1278=57e43d1d-644a-493e-acd3-69dc5e64dcde270=10.00271=10.00000000269=1278=c1566121-2b63-494d-ac2d-973e9f0115c0270=10.00271=10.00000000269=1278=d0c4a771-9035-4db9-ae7b-ad2d1db5646d270=10.00271=10.00000000269=1278=52c644ea-628a-4576-8e7e-27ec4c90398b270=10.00271=10.00000000269=1278=c3483f66-d8ce-489a-90b9-2bce69e054ee270=10.00271=10.00000000269=1278=55992a5c-cbcd-464a-8f8d-8b58e81e5c0b270=10.00271=10.0000000010=240
20250411-01:57:23.900643000 : 8=FIXT.1.19=14135=334=1849=24ab46f784d1b20db435b852086e325052=20250411-01:57:23.90056=Coinbase45=9558=Tag appears more than once371=269372=W373=1310=003
20250411-01:57:23.900723000 : 8=FIXT.1.19=93335=W49=Coinbase56=24ab46f784d1b20db435b852086e325034=9650=TEST52=20250411-01:57:23.555687369=2262=ba2ffebd-86b0-430d-b535-d9d3b46840d183=1597578360893=N55=BTC-USD1682=full_trading268=10269=1278=19077009-6f26-4e2d-9dab-04a28231b752270=10.00271=10.00000000269=1278=692097d1-c978-4024-95e9-2bf348b64bbd270=10.00271=10.00000000269=1278=99a92935-11b7-4f21-a64c-c746b53d1777270=10.00271=10.00000000269=1278=dc024b0b-0337-4215-9669-5e5636834397270=10.00271=10.00000000269=1278=c90fcc3a-a36c-4c14-b57f-6db78762e017270=10.00271=10.00000000269=1278=7841891a-bb7c-4034-97c1-41164185edc7270=1000.00271=3.10000000269=1278=381c9fa7-1add-4dd2-9233-f41e2c8821fe270=1000.00271=3.10000000269=1278=928e65c2-7e2d-478b-9310-414fb77f5aae270=1000.00271=3.10000000269=1278=ad4bd3ac-9276-40d5-90f9-e47b1d8ee953270=1000.00271=3.10000000269=1278=79e799dc-4a3d-4922-ad1a-f74eb7eff789270=1000.00271=3.1000000010=182
20250411-01:57:23.901302000 : 8=FIXT.1.19=14135=334=1949=24ab46f784d1b20db435b852086e325052=20250411-01:57:23.90056=Coinbase45=9658=Tag appears more than once371=269372=W373=1310=005
20250411-01:57:23.901390000 : 8=FIXT.1.19=93835=W49=Coinbase56=24ab46f784d1b20db435b852086e325034=9750=TEST52=20250411-01:57:23.555938369=2262=ba2ffebd-86b0-430d-b535-d9d3b46840d183=1597578360893=N55=BTC-USD1682=full_trading268=10269=1278=04f642b7-750f-4967-b786-0d48eea0f158270=1000.00271=3.10000000269=1278=d0ad653d-3272-4a3b-ba7a-a52029a67a92270=1000.00271=3.10000000269=1278=cad40464-4c62-4bf3-8444-c487fcc8dd01270=1000.00271=3.10000000269=1278=426c6428-d481-4ff7-9de3-f00ff219d654270=1000.00271=3.10000000269=1278=1ed1152d-8c1a-4b29-acdd-bbd1a5c5f35f270=1000.00271=3.10000000269=1278=66526051-b5cb-442f-af90-c609be0a9796270=1000.00271=3.10000000269=1278=f68e4659-5785-4ee9-ac24-3186640a2752270=1000.00271=3.10000000269=1278=38070d38-80a9-4898-8ef7-a0a9da5a4123270=1000.00271=3.10000000269=1278=e4d2d308-ed11-49db-850e-3cbd8258395d270=1000.00271=3.10000000269=1278=d6cfaadc-97ea-43c1-898d-40faea9c1477270=1000.00271=3.1000000010=196
20250411-01:57:23.901916000 : 8=FIXT.1.19=14135=334=2049=24ab46f784d1b20db435b852086e325052=20250411-01:57:23.90156=Coinbase45=9758=Tag appears more than once371=269372=W373=1310=255
20250411-01:57:23.901998000 : 8=FIXT.1.19=93835=W49=Coinbase56=24ab46f784d1b20db435b852086e325034=9850=TEST52=20250411-01:57:23.556188369=2262=ba2ffebd-86b0-430d-b535-d9d3b46840d183=1597578360893=N55=BTC-USD1682=full_trading268=10269=1278=36876bea-9e3a-4018-b0ac-b75cb8c16953270=1000.00271=3.10000000269=1278=eb244bc5-49e8-4aa3-af8b-3d1a67c90a08270=1000.00271=3.10000000269=1278=3efba776-29ad-4aeb-82d8-0824f161471e270=1000.00271=3.10000000269=1278=de0ddebd-0ca8-4eca-9985-77c10c8629a9270=1000.00271=3.10000000269=1278=dde4408a-fb6b-441c-a7f3-7b8b23ffdb1f270=1000.00271=3.10000000269=1278=3ebd6434-070f-4b4d-8cf3-00368112466d270=1000.00271=3.10000000269=1278=7aa98e13-65f3-4058-9f91-c1f452d02710270=1000.00271=3.10000000269=1278=e86a1fec-3610-460d-8d85-4e1e222ee159270=1000.00271=3.10000000269=1278=6dfac057-72b1-4f2c-b110-03766dea0d31270=1000.00271=3.10000000269=1278=bbb7d0ea-d251-4612-b53e-e528cc0a24ab270=1000.00271=3.1000000010=115
20250411-01:57:23.902938000 : 8=FIXT.1.19=14135=334=2149=24ab46f784d1b20db435b852086e325052=20250411-01:57:23.90256=Coinbase45=9858=Tag appears more than once371=269372=W373=1310=002
20250411-01:57:23.903035000 : 8=FIXT.1.19=93835=W49=Coinbase56=24ab46f784d1b20db435b852086e325034=9950=TEST52=20250411-01:57:23.556438369=2262=ba2ffebd-86b0-430d-b535-d9d3b46840d183=1597578360893=N55=BTC-USD1682=full_trading268=10269=1278=0782ca37-48cf-4ff3-a74a-35674661586c270=1000.00271=3.10000000269=1278=aead437d-4b62-457f-ac83-62c7cc329fd1270=1000.00271=3.10000000269=1278=af5d47bc-a008-4567-b24f-b0298f250471270=1000.00271=3.10000000269=1278=4c260f58-c427-4a9a-969a-44024ae0c714270=1000.00271=3.10000000269=1278=8c7672e5-7ee8-4fbd-8fdf-7e74e9a77db7270=1000.00271=3.10000000269=1278=b53ec3cc-9abe-4570-b903-34d52148073e270=1000.00271=3.10000000269=1278=37ce984a-0387-4ac9-9094-b83f722036ba270=1000.00271=3.10000000269=1278=0d383649-dc6c-4df2-b821-aa0018f132c7270=1000.00271=3.10000000269=1278=e39ae0ce-9e7f-4f0d-a765-5308d473bb61270=1000.00271=3.10000000269=1278=4882324e-3b5c-4b7a-b096-e8c6d9888671270=1000.00271=3.1000000010=033
20250411-01:57:23.903700000 : 8=FIXT.1.19=14135=334=2249=24ab46f784d1b20db435b852086e325052=20250411-01:57:23.90356=Coinbase45=9958=Tag appears more than once371=269372=W373=1310=005
20250411-01:57:23.903797000 : 8=FIXT.1.19=93935=W49=Coinbase56=24ab46f784d1b20db435b852086e325034=10050=TEST52=20250411-01:57:23.556688369=2262=ba2ffebd-86b0-430d-b535-d9d3b46840d183=1597578360893=N55=BTC-USD1682=full_trading268=10269=1278=6e5c7dbd-a2cc-401f-a5b2-3902088f4ab2270=1000.00271=3.10000000269=1278=10ffac08-946a-4a30-b57a-0d78450345d9270=1000.00271=3.10000000269=1278=67784af5-72bf-4d16-a6b3-25336e2c1843270=1000.00271=3.10000000269=1278=4d8b3bbc-0dc2-4044-875c-c079ec538136270=1000.00271=3.10000000269=1278=dfba5f1e-21f5-48e3-adce-b8b6bfe71467270=1000.00271=3.10000000269=1278=e51b4e33-5eaa-46ef-936b-a74a890397e8270=1000.00271=3.10000000269=1278=8cf5dfa8-858b-48a3-9d94-78522c257473270=1000.00271=3.10000000269=1278=a153b9d2-993d-4f03-a974-b8a081e128e8270=1000.00271=3.10000000269=1278=1eebe866-0f6e-4d4a-a28b-78f4e3368b0a270=1000.00271=3.10000000269=1278=300132d8-113f-4bf7-ba0c-4d93a272f55b270=1000.00271=3.1000000010=098
20250411-01:57:23.904354000 : 8=FIXT.1.19=14235=334=2349=24ab46f784d1b20db435b852086e325052=20250411-01:57:23.90456=Coinbase45=10058=Tag appears more than once371=269372=W373=1310=039
20250411-01:57:23.904451000 : 8=FIXT.1.19=93935=W49=Coinbase56=24ab46f784d1b20db435b852086e325034=10150=TEST52=20250411-01:57:23.556938369=2262=ba2ffebd-86b0-430d-b535-d9d3b46840d183=1597578360893=N55=BTC-USD1682=full_trading268=10269=1278=757f3122-27d2-4f32-90b8-ead1eef9b936270=1000.00271=3.10000000269=1278=2b68b5de-4153-4cac-ace3-102e4fa788fd270=1000.00271=3.10000000269=1278=b01f252a-1657-4df0-a122-58a23109a7c2270=1000.00271=3.10000000269=1278=dbc57e4e-6abd-4d66-8d18-bd13caaa77b1270=1000.00271=3.10000000269=1278=948b05dc-a481-409f-b8ad-a502eb595906270=1000.00271=3.10000000269=1278=e00f9703-6e16-4237-a2c6-701829d11bf1270=1000.00271=3.10000000269=1278=fd52f47a-3f11-47bc-9952-9708617d0ecd270=1000.00271=3.10000000269=1278=f7f75b14-27c3-469c-89fb-6a98b43c61bf270=1000.00271=3.10000000269=1278=25dbeb09-7901-4280-b0c3-720d7ed03d7d270=1000.00271=3.10000000269=1278=52164a1f-599f-4c43-a9ed-f93403506e67270=1000.00271=3.1000000010=187
20250411-01:57:23.905138000 : 8=FIXT.1.19=14235=334=2449=24ab46f784d1b20db435b852086e325052=20250411-01:57:23.90456=Coinbase45=10158=Tag appears more than once371=269372=W373=1310=041
20250411-01:57:23.905317000 : 8=FIXT.1.19=93935=W49=Coinbase56=24ab46f784d1b20db435b852086e325034=10250=TEST52=20250411-01:57:23.557188369=2262=ba2ffebd-86b0-430d-b535-d9d3b46840d183=1597578360893=N55=BTC-USD1682=full_trading268=10269=1278=c71c35ea-f60f-4a41-b43a-4947bbcbafad270=1000.00271=3.10000000269=1278=2de342bc-a1be-46f3-9fc6-731297726934270=1000.00271=3.10000000269=1278=7ff4c5fc-bc9b-4845-940b-4837a672e13a270=1000.00271=3.10000000269=1278=2d270775-33eb-4328-8dad-7d206612f9f6270=1000.00271=3.10000000269=1278=c4754378-f787-4100-81af-564443a86a91270=1000.00271=3.10000000269=1278=59e16255-05eb-4fdc-8be1-3c4f83fc094e270=1000.00271=3.10000000269=1278=041b2f98-1185-49cb-964a-f0456b71e692270=1000.00271=3.10000000269=1278=9a2f3529-481e-4e50-a123-7a2095fe6b2c270=1000.00271=3.10000000269=1278=9ed552a3-3295-4878-85dd-87b7b5590212270=1000.00271=3.10000000269=1278=54bec5c2-bafd-4d7d-851d-59e3553a053f270=1000.00271=3.1000000010=122
20250411-01:57:23.906031000 : 8=FIXT.1.19=14235=334=2549=24ab46f784d1b20db435b852086e325052=20250411-01:57:23.90556=Coinbase45=10258=Tag appears more than once371=269372=W373=1310=044
20250411-01:57:23.906120000 : 8=FIXT.1.19=93935=W49=Coinbase56=24ab46f784d1b20db435b852086e325034=10350=TEST52=20250411-01:57:23.557438369=2262=ba2ffebd-86b0-430d-b535-d9d3b46840d183=1597578360893=N55=BTC-USD1682=full_trading268=10269=1278=543c1acf-52f2-442b-a893-f7aa9a5dfbd1270=1000.00271=3.10000000269=1278=fec999be-cbd0-42ef-b9c3-82ca92ef0b58270=1000.00271=3.10000000269=1278=24528176-3fc6-45b2-b2f3-9f784c01495a270=1000.00271=3.10000000269=1278=12081678-66a6-4435-a3d7-b65f959cf2ac270=1000.00271=3.10000000269=1278=e7fb6165-8f1a-4b5e-b095-e232b83ee951270=1000.00271=3.10000000269=1278=83ce6582-410a-40bf-9831-8f3d20e3a629270=1000.00271=3.10000000269=1278=bc3a930b-0567-46ba-86a4-712f76466b0b270=1000.00271=3.10000000269=1278=15704973-f5ff-457d-ab31-8f99bb76bf7e270=1000.00271=3.10000000269=1278=7159045b-cbd5-458f-b91f-9fa5241b14b5270=1000.00271=3.10000000269=1278=9fa52a90-f03f-4940-b5ee-39ab937b86f1270=1000.00271=3.1000000010=045
20250411-01:57:23.906956000 : 8=FIXT.1.19=14235=334=2649=24ab46f784d1b20db435b852086e325052=20250411-01:57:23.90656=Coinbase45=10358=Tag appears more than once371=269372=W373=1310=047
20250411-01:57:23.907049000 : 8=FIXT.1.19=93935=W49=Coinbase56=24ab46f784d1b20db435b852086e325034=10450=TEST52=20250411-01:57:23.557688369=2262=ba2ffebd-86b0-430d-b535-d9d3b46840d183=1597578360893=N55=BTC-USD1682=full_trading268=10269=1278=220f55cd-a279-4bf0-9c80-1dca086d85dc270=1000.00271=3.10000000269=1278=2b1eb468-6bcd-4117-a7c0-214d643ddad4270=1000.00271=3.10000000269=1278=cc23185d-e72e-42cb-8210-61bab29cd778270=1000.00271=3.10000000269=1278=69bb228b-973b-4176-8708-3231cc40102a270=1000.00271=3.10000000269=1278=2ec8035d-7962-4195-8388-c9fbad52ac8a270=1000.00271=3.10000000269=1278=7d39e416-0b7b-471f-a9ac-455ab1bce5a7270=1000.00271=3.10000000269=1278=7067378d-2a65-41f2-acb0-ef30ddbc3e5a270=1000.00271=3.10000000269=1278=bf3fde78-6cff-4477-b381-4b5d2e68f36f270=1000.00271=3.10000000269=1278=93a2a8a3-61d4-410c-9446-8eabaafc5f29270=1000.00271=3.10000000269=1278=5afddb61-63ab-417b-a28a-41c4c03a6612270=1000.00271=3.1000000010=118
20250411-01:57:23.907713000 : 8=FIXT.1.19=14235=334=2749=24ab46f784d1b20db435b852086e325052=20250411-01:57:23.90756=Coinbase45=10458=Tag appears more than once371=269372=W373=1310=050
20250411-01:57:23.907803000 : 8=FIXT.1.19=93935=W49=Coinbase56=24ab46f784d1b20db435b852086e325034=10550=TEST52=20250411-01:57:23.557938369=2262=ba2ffebd-86b0-430d-b535-d9d3b46840d183=1597578360893=N55=BTC-USD1682=full_trading268=10269=1278=a4280417-189c-4f76-9d2e-6ec652010bf5270=1000.00271=3.10000000269=1278=ddeb78a2-e110-4828-ba3d-c9b4837e7dd7270=1000.00271=3.10000000269=1278=fcec6c90-441a-4f4a-a94e-9003355657ef270=1000.00271=3.10000000269=1278=6db15389-dfb3-4156-8a4e-ce2ac80f2b15270=1000.00271=3.10000000269=1278=47dfefc3-6f05-4b57-8aec-2bf3e6c70c2d270=1000.00271=3.10000000269=1278=fb9fd019-4b4f-4880-82bb-3df6d1ef468a270=1000.00271=3.10000000269=1278=2cff9acd-42cb-43a5-8d50-51e676b7e763270=1000.00271=3.10000000269=1278=6e6eeb59-4728-4811-9a44-c857df6aca42270=1000.00271=3.10000000269=1278=81798560-263f-4819-a528-5f3fbbc7b042270=1000.00271=3.10000000269=1278=81fbf9a8-82f4-4fe4-9fa5-3773b212ebf4270=1000.00271=3.1000000010=197
20250411-01:57:23.908573000 : 8=FIXT.1.19=14235=334=2849=24ab46f784d1b20db435b852086e325052=20250411-01:57:23.90856=Coinbase45=10558=Tag appears more than once371=269372=W373=1310=053
20250411-01:57:23.908657000 : 8=FIXT.1.19=93935=W49=Coinbase56=24ab46f784d1b20db435b852086e325034=10650=TEST52=20250411-01:57:23.558188369=2262=ba2ffebd-86b0-430d-b535-d9d3b46840d183=1597578360893=N55=BTC-USD1682=full_trading268=10269=1278=5d3b9566-276d-47fe-a111-12c17f53f501270=1000.00271=3.10000000269=1278=8eb1b3b3-c813-48b1-b839-993672108d91270=1000.00271=3.10000000269=1278=4feb6e93-6149-481b-8d58-e1c8e6c5cda1270=1000.00271=3.10000000269=1278=f8611e72-4056-4b7c-9779-4d54cd151d44270=1000.00271=3.10000000269=1278=7a129f7c-d9ba-4ea3-a267-b7d82b2e07d9270=1000.00271=3.10000000269=1278=01f359f0-c38f-416b-af00-183907218793270=1000.00271=3.10000000269=1278=11741cec-9c08-4a20-99dc-6b9f63130b0e270=1000.00271=3.10000000269=1278=08db2574-ad52-4520-ab5b-c3c7591eb781270=1000.00271=3.10000000269=1278=b06f2249-179c-4a15-8e98-7b76083b808b270=1000.00271=3.10000000269=1278=9e88fede-6d19-4c1f-863b-5a7d66781436270=1000.00271=3.1000000010=105
20250411-01:57:23.909313000 : 8=FIXT.1.19=14235=334=2949=24ab46f784d1b20db435b852086e325052=20250411-01:57:23.90856=Coinbase45=10658=Tag appears more than once371=269372=W373=1310=055
20250411-01:57:23.909407000 : 8=FIXT.1.19=93935=W49=Coinbase56=24ab46f784d1b20db435b852086e325034=10750=TEST52=20250411-01:57:23.558438369=2262=ba2ffebd-86b0-430d-b535-d9d3b46840d183=1597578360893=N55=BTC-USD1682=full_trading268=10269=1278=75e1d8b4-7201-41fe-a687-7d93420af323270=1000.00271=3.10000000269=1278=d00aa7dd-ce7f-4f8b-9a2e-880c1ea30845270=1000.00271=3.10000000269=1278=584a483f-23bf-4d8b-809f-69cf3c110f60270=1000.00271=3.10000000269=1278=dc98524e-27e2-4863-99e4-7a0097a6ee90270=1000.00271=3.10000000269=1278=82a11ac9-4f46-44b7-a0bc-a5a4cfe686e0270=1000.00271=3.10000000269=1278=f946bb05-900c-41fc-9908-41489e97ff20270=1000.00271=3.10000000269=1278=1f9186d6-0312-4677-ba96-fdb014cdff2c270=1000.00271=3.10000000269=1278=c3b67be7-2b63-4884-b311-80f28496c2c4270=1000.00271=3.10000000269=1278=6576c7f8-a4e2-4417-b854-5fef0e705fbe270=1000.00271=3.10000000269=1278=c2102c71-62f0-4eee-ae60-0777ed26a8e6270=1000.00271=3.1000000010=156
20250411-01:57:23.909898000 : 8=FIXT.1.19=14235=334=3049=24ab46f784d1b20db435b852086e325052=20250411-01:57:23.90956=Coinbase45=10758=Tag appears more than once371=269372=W373=1310=049
20250411-01:57:23.909959000 : 8=FIXT.1.19=93935=W49=Coinbase56=24ab46f784d1b20db435b852086e325034=10850=TEST52=20250411-01:57:23.558688369=2262=ba2ffebd-86b0-430d-b535-d9d3b46840d183=1597578360893=N55=BTC-USD1682=full_trading268=10269=1278=c823a2b6-849e-4839-a2fd-cd9f459cae6c270=1000.00271=3.10000000269=1278=a051e195-4472-4a8a-8591-08a2c04a33c4270=1000.00271=3.10000000269=1278=ec81b8c4-b703-4afd-a701-ce34011f60f6270=1000.00271=3.10000000269=1278=b1172677-f493-4f32-a200-0710cf8c397f270=1000.00271=3.10000000269=1278=b1a58a75-5fca-43db-b9c6-a26920e8f66e270=1000.00271=3.10000000269=1278=038bea41-b91d-4884-b992-3e5431ef9857270=1000.00271=3.10000000269=1278=55063782-f2ea-4c84-9491-8e8e89d1dfd1270=1000.00271=3.10000000269=1278=bb2011e8-d05d-40ac-9e9c-3b720422e38d270=1000.00271=3.10000000269=1278=64dd3b4a-ce8a-4b63-9937-266e832c0f21270=1000.00271=3.10000000269=1278=d64f7d2a-aa83-486c-92a8-3314c4eddd58270=1000.00271=3.1000000010=133
20250411-01:57:23.910450000 : 8=FIXT.1.19=14235=334=3149=24ab46f784d1b20db435b852086e325052=20250411-01:57:23.91056=Coinbase45=10858=Tag appears more than once371=269372=W373=1310=043
20250411-01:57:23.910524000 : 8=FIXT.1.19=93935=W49=Coinbase56=24ab46f784d1b20db435b852086e325034=10950=TEST52=20250411-01:57:23.558938369=2262=ba2ffebd-86b0-430d-b535-d9d3b46840d183=1597578360893=N55=BTC-USD1682=full_trading268=10269=1278=0df9641b-d89d-4222-a8ea-bcddf0d555f5270=1000.00271=3.10000000269=1278=7a315b16-a05f-408d-b8c1-2704af9bf767270=1000.00271=3.10000000269=1278=0e9712a8-d00f-4864-a478-f7f591718f91270=1000.00271=3.10000000269=1278=94db025d-eada-49e3-b13c-b667ca07f829270=1000.00271=3.10000000269=1278=a88ccd1f-8f8d-46af-8fb6-20adba35f7d1270=1000.00271=3.10000000269=1278=99d4e235-c8ec-4efc-938c-9a1923eafc96270=1000.00271=3.10000000269=1278=a4fc7173-7583-4f8b-b256-2921bef83c84270=1000.00271=3.10000000269=1278=18f8afd4-8bbc-4ffa-8e8f-0c1834d74472270=1000.00271=3.10000000269=1278=21fc8cb6-f894-4d09-884e-810b8ebf2ef3270=1000.00271=3.10000000269=1278=0c13b9e6-6797-4b3e-90ce-a1885b26ba53270=1000.00271=3.1000000010=166
20250411-01:57:23.910946000 : 8=FIXT.1.19=14235=334=3249=24ab46f784d1b20db435b852086e325052=20250411-01:57:23.91056=Coinbase45=10958=Tag appears more than once371=269372=W373=1310=045
20250411-01:57:23.911007000 : 8=FIXT.1.19=93935=W49=Coinbase56=24ab46f784d1b20db435b852086e325034=11050=TEST52=20250411-01:57:23.559189369=2262=ba2ffebd-86b0-430d-b535-d9d3b46840d183=1597578360893=N55=BTC-USD1682=full_trading268=10269=1278=6d8da581-3998-4fc0-99b6-3c5edbd514cb270=1000.00271=3.10000000269=1278=67a70307-be50-4065-872b-47e0de473bc4270=1000.00271=3.10000000269=1278=8ce7be0b-98de-46d0-b1b6-307a4bec36e2270=1000.00271=3.10000000269=1278=856b22f8-5884-4739-adc0-bdd851c5c07d270=1000.00271=3.10000000269=1278=c00ae651-a76b-4bfd-be16-3672b345fe29270=1000.00271=3.10000000269=1278=cae248f9-16fc-44ea-9b79-1dacfc285db6270=1000.00271=3.10000000269=1278=42bb223c-88c6-4a18-8ff3-4fd8d9efda8d270=1000.00271=3.10000000269=1278=d7188b01-22b6-4837-a720-077601f7f483270=1000.00271=3.10000000269=1278=5d85a0a6-ddd9-4e0e-9a1a-7f418ef588e5270=1000.00271=3.10000000269=1278=bff4c39f-7a80-42ce-a178-b1221792e445270=1000.00271=3.1000000010=174
20250411-01:57:23.911449000 : 8=FIXT.1.19=14235=334=3349=24ab46f784d1b20db435b852086e325052=20250411-01:57:23.91156=Coinbase45=11058=Tag appears more than once371=269372=W373=1310=039
20250411-01:57:23.911542000 : 8=FIXT.1.19=93935=W49=Coinbase56=24ab46f784d1b20db435b852086e325034=11150=TEST52=20250411-01:57:23.559439369=2262=ba2ffebd-86b0-430d-b535-d9d3b46840d183=1597578360893=N55=BTC-USD1682=full_trading268=10269=1278=9ea3d263-b5ab-46c5-bf27-8c0e3e0e5e9e270=1000.00271=3.10000000269=1278=b93347df-d2ab-48ec-b326-4454e64f1d4e270=1000.00271=3.10000000269=1278=57acc40d-8478-444a-990f-067a8e8e846e270=1000.00271=3.10000000269=1278=34419ae2-2c16-427b-a290-845419760fd5270=1000.00271=3.10000000269=1278=ab41de2d-5def-4986-b56e-243d2f99a57c270=1000.00271=3.10000000269=1278=9025524c-03a9-407a-a58a-5258c4ea0a0b270=1000.00271=3.10000000269=1278=60766318-112b-4d83-a384-55693de75519270=1000.00271=3.10000000269=1278=c19b6a2c-086b-4fc1-8dfe-51cb2dc12c1d270=1000.00271=3.10000000269=1278=11126433-0f9c-4450-a35a-39b878e85e68270=1000.00271=3.10000000269=1278=e2e620ee-44fb-4630-a890-d331ba5b2fae270=1000.00271=3.1000000010=056
20250411-01:57:23.912192000 : 8=FIXT.1.19=14235=334=3449=24ab46f784d1b20db435b852086e325052=20250411-01:57:23.91156=Coinbase45=11158=Tag appears more than once371=269372=W373=1310=041
20250411-01:57:23.912285000 : 8=FIXT.1.19=93935=W49=Coinbase56=24ab46f784d1b20db435b852086e325034=11250=TEST52=20250411-01:57:23.559688369=2262=ba2ffebd-86b0-430d-b535-d9d3b46840d183=1597578360893=N55=BTC-USD1682=full_trading268=10269=1278=9ccf6d4b-a6ca-4a1f-a7bb-77f400ace0c8270=1000.00271=3.10000000269=1278=0e8d6c10-8421-4f19-97dc-d70e715d9033270=1000.00271=3.10000000269=1278=f31ecd5d-8231-44ea-a5c2-0fcc5a699401270=1000.00271=3.10000000269=1278=37fbb559-dc52-48fe-ab65-24910edc338a270=1000.00271=3.10000000269=1278=bc1435c5-c59c-4017-9e59-f1073f04c7e2270=1000.00271=3.10000000269=1278=9c8e1397-0cee-4b05-a66f-5594040791c4270=1000.00271=3.10000000269=1278=248b6703-f829-42bb-a551-4be3075c381e270=1000.00271=3.10000000269=1278=16d257b0-bc92-44f0-822d-3eba61af4bda270=1000.00271=3.10000000269=1278=06257aa1-4043-4cdb-9286-4342b8e59108270=1000.00271=3.10000000269=1278=210ec210-1443-47dc-9e43-9c9ea720a6c3270=1000.00271=3.1000000010=056
20250411-01:57:23.912980000 : 8=FIXT.1.19=14235=334=3549=24ab46f784d1b20db435b852086e325052=20250411-01:57:23.91256=Coinbase45=11258=Tag appears more than once371=269372=W373=1310=044
20250411-01:57:23.913068000 : 8=FIXT.1.19=93935=W49=Coinbase56=24ab46f784d1b20db435b852086e325034=11350=TEST52=20250411-01:57:23.559938369=2262=ba2ffebd-86b0-430d-b535-d9d3b46840d183=1597578360893=N55=BTC-USD1682=full_trading268=10269=1278=8b79da5d-b78c-4011-b55f-b35c16dc3724270=1000.00271=3.10000000269=1278=076c3703-1104-4e15-a38a-d95bf133f0c5270=1000.00271=3.10000000269=1278=f5a3155c-e449-4102-870d-ab8c8dd24c3d270=1000.00271=3.10000000269=1278=1af2681f-2dec-4d25-aaeb-89b8867b4a3c270=1000.00271=3.10000000269=1278=65c3088d-192a-4213-85a3-7257aa8b20a3270=1000.00271=3.10000000269=1278=2aa7989b-5601-4899-8143-01dda3255e4f270=1000.00271=3.10000000269=1278=099b432c-fa2e-4fd7-952e-22f6debf6877270=1000.00271=3.10000000269=1278=2e71cc31-1235-4b7b-a728-e3335631fe5a270=1000.00271=3.10000000269=1278=ce471ffc-1e26-4afe-afab-27ee5ac8debe270=1000.00271=3.10000000269=1278=113b7fc6-8574-40eb-8682-d077245b84f2270=1000.00271=3.1000000010=025
20250411-01:57:23.913628000 : 8=FIXT.1.19=14235=334=3649=24ab46f784d1b20db435b852086e325052=20250411-01:57:23.91356=Coinbase45=11358=Tag appears more than once371=269372=W373=1310=047
20250411-01:57:23.913707000 : 8=FIXT.1.19=93935=W49=Coinbase56=24ab46f784d1b20db435b852086e325034=11450=TEST52=20250411-01:57:23.560189369=2262=ba2ffebd-86b0-430d-b535-d9d3b46840d183=1597578360893=N55=BTC-USD1682=full_trading268=10269=1278=bcebce2c-eda8-4b85-841d-27ede39fc5a1270=1000.00271=3.10000000269=1278=0aedaae5-6cc6-4a34-8e48-5e67a5ccc148270=1000.00271=3.10000000269=1278=206e10a5-1173-4860-87b5-7c88afe061f6270=1000.00271=3.10000000269=1278=5c32d94b-696a-4d9b-afa0-665970356008270=1000.00271=3.10000000269=1278=0b7da819-cc1e-4525-a382-ce5b90dc485c270=1000.00271=3.10000000269=1278=2241b3bf-cbbe-44f2-ac75-8032f6283aa8270=1000.00271=3.10000000269=1278=88cada69-adb1-466a-afcd-66e063ad27c0270=1000.00271=3.10000000269=1278=34a52ef5-31c1-4c63-9230-21c85a9a6ba3270=1000.00271=3.10000000269=1278=e109c2c8-fb1d-4ef9-a640-368381323507270=1000.00271=3.10000000269=1278=38fd36c4-4c62-4b4c-8f24-1fe39be94fa1270=1000.00271=3.1000000010=131
20250411-01:57:23.914248000 : 8=FIXT.1.19=14235=334=3749=24ab46f784d1b20db435b852086e325052=20250411-01:57:23.91356=Coinbase45=11458=Tag appears more than once371=269372=W373=1310=049
20250411-01:57:23.914326000 : 8=FIXT.1.19=93935=W49=Coinbase56=24ab46f784d1b20db435b852086e325034=11550=TEST52=20250411-01:57:23.560439369=2262=ba2ffebd-86b0-430d-b535-d9d3b46840d183=1597578360893=N55=BTC-USD1682=full_trading268=10269=1278=f83f64c8-7d33-472d-a516-9b664ff9c966270=1000.00271=3.10000000269=1278=3411c368-380b-42e6-b656-8552d92904d5270=1000.00271=3.10000000269=1278=4803796e-79f3-4aa4-a8cb-37f13899bf01270=1000.00271=3.10000000269=1278=823f8fbf-7e6d-4ae3-adb9-3a822ff6d09a270=1000.00271=3.10000000269=1278=135624df-a204-490f-a68b-63d74ee09908270=1000.00271=3.10000000269=1278=47cfdedf-22b9-402c-93bd-f311103fd3e0270=1000.00271=3.10000000269=1278=f9173d5e-d872-4661-93f6-28f527e931f7270=1000.00271=3.10000000269=1278=06ab1365-fd39-4701-bd7f-1915ad3c7602270=1000.00271=3.10000000269=1278=012a7c59-5ae4-4da5-97ba-2e3254c889fb270=1000.00271=3.10000000269=1278=a9a0d42f-ad9e-4ea9-8bf0-d5a441fded40270=1000.00271=3.1000000010=176
20250411-01:57:23.914921000 : 8=FIXT.1.19=14235=334=3849=24ab46f784d1b20db435b852086e325052=20250411-01:57:23.91456=Coinbase45=11558=Tag appears more than once371=269372=W373=1310=052
20250411-01:57:24.119797000 : 8=FIXT.1.19=93935=W49=Coinbase56=24ab46f784d1b20db435b852086e325034=11650=TEST52=20250411-01:57:23.560688369=2262=ba2ffebd-86b0-430d-b535-d9d3b46840d183=1597578360893=N55=BTC-USD1682=full_trading268=10269=1278=f3f3930e-be0e-40b4-a97d-d19501a54885270=1000.00271=3.10000000269=1278=261922d0-5c81-4ab6-832f-4eff45f64890270=1000.00271=3.10000000269=1278=3af4e45f-56f6-4c69-894d-d56a14894a98270=1000.00271=3.10000000269=1278=1c1dd248-49e4-44aa-9e69-323b0f41fa0e270=1000.00271=3.10000000269=1278=b16b002d-1cd6-4869-9c1b-f15c758611bf270=1000.00271=3.10000000269=1278=a0520e61-28ad-448d-87c1-49f0c7358628270=1000.00271=3.10000000269=1278=152d0b57-086f-48cc-80b3-ff14ee9375ed270=1000.00271=3.10000000269=1278=c55fc264-67d2-4e9c-8cce-6c834feff648270=1000.00271=3.10000000269=1278=27361968-189a-4fa6-a3a2-eead03c640d6270=1000.00271=3.10000000269=1278=f5b01c67-f98f-44b9-a511-7f07f8883d9e270=1000.00271=3.1000000010=058
20250411-01:57:24.120491000 : 8=FIXT.1.19=14235=334=3949=24ab46f784d1b20db435b852086e325052=20250411-01:57:24.12056=Coinbase45=11658=Tag appears more than once371=269372=W373=1310=044
20250411-01:57:24.120571000 : 8=FIXT.1.19=93935=W49=Coinbase56=24ab46f784d1b20db435b852086e325034=11750=TEST52=20250411-01:57:23.560939369=2262=ba2ffebd-86b0-430d-b535-d9d3b46840d183=1597578360893=N55=BTC-USD1682=full_trading268=10269=1278=75a5c14f-8434-4533-a10e-0bf6e92e1000270=1000.00271=3.10000000269=1278=a9b0a826-3659-4105-9ecc-21bcd27b736f270=1000.00271=3.10000000269=1278=1b1bab77-5c52-459b-98e3-e27ff6f8cd04270=1000.00271=3.10000000269=1278=346695f1-fe03-4364-8fc5-006796c8f82f270=1000.00271=3.10000000269=1278=cbbaa36d-2a03-45a2-a230-bd5845d832cd270=1000.00271=3.10000000269=1278=745d4fc0-6710-4c5c-97c3-7b29c4e06839270=1000.00271=3.10000000269=1278=e95fdfba-5db2-4461-8e9c-7bfdf8a9238c270=1000.00271=3.10000000269=1278=33611b39-1fbf-45cc-bf5e-a02bc1f84736270=1000.00271=3.10000000269=1278=51f77b2d-1a69-432d-934b-234eb9e1dfac270=1000.00271=3.10000000269=1278=ab09fdc3-8d50-432f-ab0f-97e8627eac24270=1000.00271=3.1000000010=235
20250411-01:57:24.121327000 : 8=FIXT.1.19=14235=334=4049=24ab46f784d1b20db435b852086e325052=20250411-01:57:24.12056=Coinbase45=11758=Tag appears more than once371=269372=W373=1310=037
20250411-01:57:24.121408000 : 8=FIXT.1.19=93935=W49=Coinbase56=24ab46f784d1b20db435b852086e325034=11850=TEST52=20250411-01:57:23.561189369=2262=ba2ffebd-86b0-430d-b535-d9d3b46840d183=1597578360893=N55=BTC-USD1682=full_trading268=10269=1278=dde04213-6104-44c5-a811-15834c27b515270=1000.00271=3.10000000269=1278=9af2b85c-4997-4e1b-9147-7d400f059b01270=1000.00271=3.10000000269=1278=40870860-7a8a-4419-a117-e511f779abfa270=1000.00271=3.10000000269=1278=3e8fa7bd-dde0-4fe4-bb2e-e6279841b019270=1000.00271=3.10000000269=1278=4dde1422-98d8-405b-88df-bf245291ad7a270=1000.00271=3.10000000269=1278=6ee8b5a8-bc2f-4a0a-9ae4-7ff1b5dae941270=1000.00271=3.10000000269=1278=3ebc1f7a-2bb5-4ef0-a82f-844b9540f6e8270=1000.00271=3.10000000269=1278=a82d5bb9-1f1a-4575-b580-8d9b60863b10270=1000.00271=3.10000000269=1278=14f89bd5-0233-435c-b608-2e19131b8f6c270=1000.00271=3.10000000269=1278=a2e319e5-aab7-41d4-9d19-98d771a3f1d3270=1000.00271=3.1000000010=194
20250411-01:57:24.122102000 : 8=FIXT.1.19=14235=334=4149=24ab46f784d1b20db435b852086e325052=20250411-01:57:24.12156=Coinbase45=11858=Tag appears more than once371=269372=W373=1310=040
20250411-01:57:24.122178000 : 8=FIXT.1.19=93935=W49=Coinbase56=24ab46f784d1b20db435b852086e325034=11950=TEST52=20250411-01:57:23.561439369=2262=ba2ffebd-86b0-430d-b535-d9d3b46840d183=1597578360893=N55=BTC-USD1682=full_trading268=10269=1278=dc965e0b-075a-4ba4-a498-02c96d1664ba270=1000.00271=3.10000000269=1278=67b6e68f-ac11-4c05-a54a-2adb555b0123270=1000.00271=3.10000000269=1278=866f52a1-dad9-49d7-ac4a-9da3075407a3270=1000.00271=3.10000000269=1278=0e38234d-a010-40f6-9c6f-a0d574e773cf270=1000.00271=3.10000000269=1278=d6af6749-e3c8-4938-8741-1d5f177cf8e1270=1000.00271=3.10000000269=1278=45ff5e59-2c4d-45ac-9fde-403662dfd1ca270=1000.00271=3.10000000269=1278=dcac314e-c54f-44e3-b96d-ef71539766ed270=1000.00271=3.10000000269=1278=dd6d14ea-760f-4884-a546-1d3c40ebdd7c270=1000.00271=3.10000000269=1278=4f3da0c6-46eb-4b64-b973-cc43e24abccb270=1000.00271=3.10000000269=1278=aa40cda8-4abd-4f52-999a-1a90ed5bf41a270=1000.00271=3.1000000010=030
20250411-01:57:24.122799000 : 8=FIXT.1.19=14235=334=4249=24ab46f784d1b20db435b852086e325052=20250411-01:57:24.12256=Coinbase45=11958=Tag appears more than once371=269372=W373=1310=043
20250411-01:57:24.127043000 : 8=FIXT.1.19=95335=W49=Coinbase56=24ab46f784d1b20db435b852086e325034=12050=TEST52=20250411-01:57:23.561689369=2262=ba2ffebd-86b0-430d-b535-d9d3b46840d183=1597578360893=N55=BTC-USD1682=full_trading268=10269=1278=687ee4fc-f626-4e4f-abee-1f0ee5af3f72270=1000.00271=3.10000000269=1278=b1ad1135-67ec-4c96-99cb-a626137f3f16270=10000.00271=1.00000000269=1278=e9320f5f-80ae-41ab-af7a-86518d456fb0270=10000.00271=1.00000000269=1278=cd95aff0-36fa-4804-887f-2c3fce3cdc86270=10000.00271=1.00000000269=1278=fbdbcee1-8c29-4478-97df-358d209d8808270=10000.00271=1.00000000269=1278=140f39da-834b-4e42-8e15-6e25287df1f0270=900000.00271=0.00011111269=1278=49f064c5-76fe-4b38-bede-48b60a0a5aec270=900000.00271=0.00011111269=1278=681cf73b-9d37-4101-b940-9da9b1ff61ed270=900000.00271=0.00011111269=1278=3dea1587-e474-4258-b6e8-485c21b56670270=900000.00271=0.00011111269=1278=afd96a7b-3d48-459e-b810-e4ee88353a31270=900000.00271=0.0001111110=238
20250411-01:57:24.128200000 : 8=FIXT.1.19=14235=334=4349=24ab46f784d1b20db435b852086e325052=20250411-01:57:24.12756=Coinbase45=12058=Tag appears more than once371=269372=W373=1310=041
20250411-01:57:24.128266000 : 8=FIXT.1.19=95935=W49=Coinbase56=24ab46f784d1b20db435b852086e325034=12150=TEST52=20250411-01:57:23.561939369=2262=ba2ffebd-86b0-430d-b535-d9d3b46840d183=1597578360893=N55=BTC-USD1682=full_trading268=10269=1278=a68ae029-b920-4ae7-a775-ccdb800fc252270=900000.00271=0.00001111269=1278=d44508b7-1c9f-4b4f-acb8-99c93d2b99e8270=900000.00271=0.00001111269=1278=304ff106-de40-4381-89c5-c93f7f3e32ae270=900000.00271=0.00001111269=1278=08a0fef8-fcbb-4857-8463-2599cf331386270=900000.00271=0.00011111269=1278=07b2856d-f899-417c-82d5-886f0d85125e270=900000.00271=0.00011111269=1278=12ecb45e-6af8-4804-a942-5c997b9d1502270=900000.00271=0.00011111269=1278=98676c5f-b851-473c-817a-b29243092a25270=900000.00271=0.00001111269=1278=09afe685-e71f-4ea0-b164-c27737db126d270=900000.00271=0.00001111269=1278=e71ee98f-c329-428d-9893-629b53015ff6270=900000.00271=0.00001111269=1278=124e6fc1-6dde-452b-be03-c00113c8ebdb270=900000.00271=0.0001111110=025
20250411-01:57:24.129085000 : 8=FIXT.1.19=14235=334=4449=24ab46f784d1b20db435b852086e325052=20250411-01:57:24.12856=Coinbase45=12158=Tag appears more than once371=269372=W373=1310=044
