20250411-01:46:46.909534000 : 8=FIXT.1.19=21535=A34=149=24ab46f784d1b20db435b852086e325052=20250411-01:46:46.89956=Coinbase95=4496=tke5XG9gb0sfLrZifMnV3f6kffaKNsZYd144+qprotM=98=0108=30141=Y553=24ab46f784d1b20db435b852086e3250554=akmwnltyfgb1137=910=175
20250411-01:46:47.162312000 : 8=FIXT.1.19=12535=A49=Coinbase56=24ab46f784d1b20db435b852086e325034=150=TEST52=20250411-01:46:47.052357369=198=0108=30141=Y1137=910=196
20250411-01:46:48.471212000 : 8=FIXT.1.19=17835=V34=249=24ab46f784d1b20db435b852086e325052=20250411-01:46:48.46956=Coinbase1128=9146=155=BTC-USD262=87859126-8df1-460e-8f6d-b0b1f3c82bc3263=1264=0267=2269=0269=110=035
20250411-01:46:48.834059000 : 8=FIXT.1.19=28135=X49=Coinbase56=24ab46f784d1b20db435b852086e325034=250=TEST52=20250411-01:46:48.723029369=2262=87859126-8df1-460e-8f6d-b0b1f3c82bc3268=1279=0269=083=159756520155=BTC-USD270=3.71271=0.6232294660=20250411-01:46:48.72152440=237=1f388486-3ccb-4166-bd21-4483ecdfdc8210=215
20250411-01:46:48.835125000 : 8=FIXT.1.19=32435=X49=Coinbase56=24ab46f784d1b20db435b852086e325034=350=TEST52=20250411-01:46:48.723038369=2262=87859126-8df1-460e-8f6d-b0b1f3c82bc3268=1279=0269=2278=c5b88ea9-605d-4595-ac52-f7c3f08523ba83=159756520255=BTC-USD270=3.55271=0.6232294660=20250411-01:46:48.72152437=1f388486-3ccb-4166-bd21-4483ecdfdc825797=110=173
20250411-01:46:48.835354000 : 8=FIXT.1.19=28735=X49=Coinbase56=24ab46f784d1b20db435b852086e325034=450=TEST52=20250411-01:46:48.723044369=2262=87859126-8df1-460e-8f6d-b0b1f3c82bc3268=1279=2269=0278=1f388486-3ccb-4166-bd21-4483ecdfdc8283=159756520355=BTC-USD270=3.71271=0.0000000060=20250411-01:46:48.72152458=FILLED10=124
20250411-01:46:48.886363000 : 8=FIXT.1.19=28135=X49=Coinbase56=24ab46f784d1b20db435b852086e325034=550=TEST52=20250411-01:46:48.777569369=2262=87859126-8df1-460e-8f6d-b0b1f3c82bc3268=1279=0269=183=159756520455=BTC-USD270=3.18271=0.6232294660=20250411-01:46:48.77660740=237=3fc9428f-67f8-465f-abd1-8dc7f2c0eef210=154
20250411-01:46:48.886705000 : 8=FIXT.1.19=32435=X49=Coinbase56=24ab46f784d1b20db435b852086e325034=650=TEST52=20250411-01:46:48.777579369=2262=87859126-8df1-460e-8f6d-b0b1f3c82bc3268=1279=0269=2278=4d60a78e-b39b-420e-b830-bc0f3f4fdde283=159756520555=BTC-USD270=3.53271=0.6232294660=20250411-01:46:48.77660737=3fc9428f-67f8-465f-abd1-8dc7f2c0eef25797=210=238
20250411-01:46:48.886892000 : 8=FIXT.1.19=28735=X49=Coinbase56=24ab46f784d1b20db435b852086e325034=750=TEST52=20250411-01:46:48.777583369=2262=87859126-8df1-460e-8f6d-b0b1f3c82bc3268=1279=2269=1278=3fc9428f-67f8-465f-abd1-8dc7f2c0eef283=159756520655=BTC-USD270=3.18271=0.0000000060=20250411-01:46:48.77660758=FILLED10=062
20250411-01:46:49.033011000 : 8=FIXT.1.19=27635=X49=Coinbase56=24ab46f784d1b20db435b852086e325034=850=TEST52=20250411-01:46:48.924133369=2262=87859126-8df1-460e-8f6d-b0b1f3c82bc3268=1279=0269=083=159756520755=BTC-USD29004=2.208895519560=20250411-01:46:48.92315440=137=e436cb35-e14e-422f-8765-7a5ae92a474710=197
20250411-01:46:49.033801000 : 8=FIXT.1.19=32435=X49=Coinbase56=24ab46f784d1b20db435b852086e325034=950=TEST52=20250411-01:46:48.924139369=2262=87859126-8df1-460e-8f6d-b0b1f3c82bc3268=1279=0269=2278=c5b88ea9-605d-4595-ac52-f7c3f08523ba83=159756520855=BTC-USD270=3.55271=0.6222240960=20250411-01:46:48.92315437=e436cb35-e14e-422f-8765-7a5ae92a47475797=110=094
20250411-01:46:49.033991000 : 8=FIXT.1.19=26435=X49=Coinbase56=24ab46f784d1b20db435b852086e325034=1050=TEST52=20250411-01:46:48.924143369=2262=87859126-8df1-460e-8f6d-b0b1f3c82bc3268=1279=2269=0278=e436cb35-e14e-422f-8765-7a5ae92a474783=159756520955=BTC-USD60=20250411-01:46:48.92315458=FILLED10=254
20250411-01:46:49.071995000 : 8=FIXT.1.19=28235=X49=Coinbase56=24ab46f784d1b20db435b852086e325034=1150=TEST52=20250411-01:46:48.950452369=2262=87859126-8df1-460e-8f6d-b0b1f3c82bc3268=1279=0269=083=159756521055=BTC-USD270=3.85271=0.6197183160=20250411-01:46:48.94919540=237=60b59028-1eb8-478f-ac29-051c85c3dd2b10=234
20250411-01:46:49.074581000 : 8=FIXT.1.19=32535=X49=Coinbase56=24ab46f784d1b20db435b852086e325034=1250=TEST52=20250411-01:46:48.950459369=2262=87859126-8df1-460e-8f6d-b0b1f3c82bc3268=1279=0269=2278=c5b88ea9-605d-4595-ac52-f7c3f08523ba83=159756521155=BTC-USD270=3.55271=0.6197183160=20250411-01:46:48.94919537=60b59028-1eb8-478f-ac29-051c85c3dd2b5797=110=194
20250411-01:46:49.075516000 : 8=FIXT.1.19=28835=X49=Coinbase56=24ab46f784d1b20db435b852086e325034=1350=TEST52=20250411-01:46:48.950463369=2262=87859126-8df1-460e-8f6d-b0b1f3c82bc3268=1279=2269=0278=60b59028-1eb8-478f-ac29-051c85c3dd2b83=159756521255=BTC-USD270=3.85271=0.0000000060=20250411-01:46:48.94919558=FILLED10=146
20250411-01:46:49.076878000 : 8=FIXT.1.19=27335=X49=Coinbase56=24ab46f784d1b20db435b852086e325034=1450=TEST52=20250411-01:46:48.953062369=2262=87859126-8df1-460e-8f6d-b0b1f3c82bc3268=1279=0269=183=159756521355=BTC-USD271=0.6232294660=20250411-01:46:48.95158540=137=f4fb980e-3e9e-40e8-83e6-22bf34114aa310=120
20250411-01:46:49.077191000 : 8=FIXT.1.19=32535=X49=Coinbase56=24ab46f784d1b20db435b852086e325034=1550=TEST52=20250411-01:46:48.953066369=2262=87859126-8df1-460e-8f6d-b0b1f3c82bc3268=1279=0269=2278=4d60a78e-b39b-420e-b830-bc0f3f4fdde283=159756521455=BTC-USD270=3.53271=0.6232294660=20250411-01:46:48.95158537=f4fb980e-3e9e-40e8-83e6-22bf34114aa35797=210=113
20250411-01:46:49.077722000 : 8=FIXT.1.19=27935=X49=Coinbase56=24ab46f784d1b20db435b852086e325034=1650=TEST52=20250411-01:46:48.953142369=2262=87859126-8df1-460e-8f6d-b0b1f3c82bc3268=1279=2269=1278=f4fb980e-3e9e-40e8-83e6-22bf34114aa383=159756521555=BTC-USD271=0.0000000060=20250411-01:46:48.95158558=FILLED10=032
20250411-01:46:49.114635000 : 8=FIXT.1.19=28135=X49=Coinbase56=24ab46f784d1b20db435b852086e325034=1750=TEST52=20250411-01:46:49.006083369=2262=87859126-8df1-460e-8f6d-b0b1f3c82bc3268=1279=0269=183=159756521655=BTC-USD270=3.2271=0.6197183160=20250411-01:46:49.00519940=237=112ef416-11c3-4ad0-bc9d-9c6773c8222910=114
20250411-01:46:49.115187000 : 8=FIXT.1.19=32535=X49=Coinbase56=24ab46f784d1b20db435b852086e325034=1850=TEST52=20250411-01:46:49.006137369=2262=87859126-8df1-460e-8f6d-b0b1f3c82bc3268=1279=0269=2278=4d60a78e-b39b-420e-b830-bc0f3f4fdde283=159756521755=BTC-USD270=3.53271=0.6197183160=20250411-01:46:49.00519937=112ef416-11c3-4ad0-bc9d-9c6773c822295797=210=253
20250411-01:46:49.115379000 : 8=FIXT.1.19=28735=X49=Coinbase56=24ab46f784d1b20db435b852086e325034=1950=TEST52=20250411-01:46:49.006145369=2262=87859126-8df1-460e-8f6d-b0b1f3c82bc3268=1279=2269=1278=112ef416-11c3-4ad0-bc9d-9c6773c8222983=159756521855=BTC-USD270=3.2271=0.0000000060=20250411-01:46:49.00519958=FILLED10=023
20250411-01:46:49.605781000 : 8=FIXT.1.19=27735=X49=Coinbase56=24ab46f784d1b20db435b852086e325034=2050=TEST52=20250411-01:46:49.496165369=2262=87859126-8df1-460e-8f6d-b0b1f3c82bc3268=1279=0269=083=159756521955=BTC-USD29004=2.208895519560=20250411-01:46:49.49418240=137=d36bf88d-c313-4fd9-8916-a4998137bc9210=019
20250411-01:46:49.607843000 : 8=FIXT.1.19=32535=X49=Coinbase56=24ab46f784d1b20db435b852086e325034=2150=TEST52=20250411-01:46:49.496172369=2262=87859126-8df1-460e-8f6d-b0b1f3c82bc3268=1279=0269=2278=c5b88ea9-605d-4595-ac52-f7c3f08523ba83=159756522055=BTC-USD270=3.55271=0.6222240960=20250411-01:46:49.49418237=d36bf88d-c313-4fd9-8916-a4998137bc925797=110=155
20250411-01:46:49.608319000 : 8=FIXT.1.19=26435=X49=Coinbase56=24ab46f784d1b20db435b852086e325034=2250=TEST52=20250411-01:46:49.496177369=2262=87859126-8df1-460e-8f6d-b0b1f3c82bc3268=1279=2269=0278=d36bf88d-c313-4fd9-8916-a4998137bc9283=159756522155=BTC-USD60=20250411-01:46:49.49418258=FILLED10=029
20250411-01:46:49.641995000 : 8=FIXT.1.19=27335=X49=Coinbase56=24ab46f784d1b20db435b852086e325034=2350=TEST52=20250411-01:46:49.524399369=2262=87859126-8df1-460e-8f6d-b0b1f3c82bc3268=1279=0269=183=159756522255=BTC-USD271=0.6232294660=20250411-01:46:49.52329540=137=cc3ab4ba-63c5-4c8c-90ab-3e5d02db225f10=033
20250411-01:46:49.642306000 : 8=FIXT.1.19=32535=X49=Coinbase56=24ab46f784d1b20db435b852086e325034=2450=TEST52=20250411-01:46:49.524404369=2262=87859126-8df1-460e-8f6d-b0b1f3c82bc3268=1279=0269=2278=4d60a78e-b39b-420e-b830-bc0f3f4fdde283=159756522355=BTC-USD270=3.53271=0.6232294660=20250411-01:46:49.52329537=cc3ab4ba-63c5-4c8c-90ab-3e5d02db225f5797=210=009
20250411-01:46:49.642438000 : 8=FIXT.1.19=27935=X49=Coinbase56=24ab46f784d1b20db435b852086e325034=2550=TEST52=20250411-01:46:49.524407369=2262=87859126-8df1-460e-8f6d-b0b1f3c82bc3268=1279=2269=1278=cc3ab4ba-63c5-4c8c-90ab-3e5d02db225f83=159756522455=BTC-USD271=0.0000000060=20250411-01:46:49.52329558=FILLED10=192
20250411-01:46:50.089648000 : 8=FIXT.1.19=28235=X49=Coinbase56=24ab46f784d1b20db435b852086e325034=2650=TEST52=20250411-01:46:49.980544369=2262=87859126-8df1-460e-8f6d-b0b1f3c82bc3268=1279=0269=083=159756522555=BTC-USD270=3.71271=0.6232294660=20250411-01:46:49.97934040=237=d09ca63c-b19f-4de4-b6c4-79ed8cdaebe010=069
20250411-01:46:50.090183000 : 8=FIXT.1.19=32535=X49=Coinbase56=24ab46f784d1b20db435b852086e325034=2750=TEST52=20250411-01:46:49.980556369=2262=87859126-8df1-460e-8f6d-b0b1f3c82bc3268=1279=0269=2278=c5b88ea9-605d-4595-ac52-f7c3f08523ba83=159756522655=BTC-USD270=3.55271=0.6232294660=20250411-01:46:49.97934037=d09ca63c-b19f-4de4-b6c4-79ed8cdaebe05797=110=030
20250411-01:46:50.090369000 : 8=FIXT.1.19=28835=X49=Coinbase56=24ab46f784d1b20db435b852086e325034=2850=TEST52=20250411-01:46:49.980561369=2262=87859126-8df1-460e-8f6d-b0b1f3c82bc3268=1279=2269=0278=d09ca63c-b19f-4de4-b6c4-79ed8cdaebe083=159756522755=BTC-USD270=3.71271=0.0000000060=20250411-01:46:49.97934058=FILLED10=236
20250411-01:46:50.142976000 : 8=FIXT.1.19=28235=X49=Coinbase56=24ab46f784d1b20db435b852086e325034=2950=TEST52=20250411-01:46:50.034916369=2262=87859126-8df1-460e-8f6d-b0b1f3c82bc3268=1279=0269=183=159756522855=BTC-USD270=3.33271=0.6232294660=20250411-01:46:50.03353940=237=9da970bd-9051-4c1f-9169-d8dd9e06c2ad10=066
20250411-01:46:50.143263000 : 8=FIXT.1.19=32535=X49=Coinbase56=24ab46f784d1b20db435b852086e325034=3050=TEST52=20250411-01:46:50.034933369=2262=87859126-8df1-460e-8f6d-b0b1f3c82bc3268=1279=0269=2278=4d60a78e-b39b-420e-b830-bc0f3f4fdde283=159756522955=BTC-USD270=3.53271=0.6232294660=20250411-01:46:50.03353937=9da970bd-9051-4c1f-9169-d8dd9e06c2ad5797=210=142
20250411-01:46:50.144341000 : 8=FIXT.1.19=28835=X49=Coinbase56=24ab46f784d1b20db435b852086e325034=3150=TEST52=20250411-01:46:50.034938369=2262=87859126-8df1-460e-8f6d-b0b1f3c82bc3268=1279=2269=1278=9da970bd-9051-4c1f-9169-d8dd9e06c2ad83=159756523055=BTC-USD270=3.33271=0.0000000060=20250411-01:46:50.03353958=FILLED10=220
20250411-01:46:50.203659000 : 8=FIXT.1.19=28235=X49=Coinbase56=24ab46f784d1b20db435b852086e325034=3250=TEST52=20250411-01:46:50.095639369=2262=87859126-8df1-460e-8f6d-b0b1f3c82bc3268=1279=0269=183=159756523155=BTC-USD270=3.24271=0.6232294660=20250411-01:46:50.09375640=237=1689c668-c5d1-4708-ad40-35e682af255310=085
20250411-01:46:50.204178000 : 8=FIXT.1.19=32535=X49=Coinbase56=24ab46f784d1b20db435b852086e325034=3350=TEST52=20250411-01:46:50.095649369=2262=87859126-8df1-460e-8f6d-b0b1f3c82bc3268=1279=0269=2278=4d60a78e-b39b-420e-b830-bc0f3f4fdde283=159756523255=BTC-USD270=3.53271=0.6232294660=20250411-01:46:50.09375637=1689c668-c5d1-4708-ad40-35e682af25535797=210=172
20250411-01:46:50.204333000 : 8=FIXT.1.19=28835=X49=Coinbase56=24ab46f784d1b20db435b852086e325034=3450=TEST52=20250411-01:46:50.095656369=2262=87859126-8df1-460e-8f6d-b0b1f3c82bc3268=1279=2269=1278=1689c668-c5d1-4708-ad40-35e682af255383=159756523355=BTC-USD270=3.24271=0.0000000060=20250411-01:46:50.09375658=FILLED10=252
20250411-01:46:50.257921000 : 8=FIXT.1.19=28235=X49=Coinbase56=24ab46f784d1b20db435b852086e325034=3550=TEST52=20250411-01:46:50.149234369=2262=87859126-8df1-460e-8f6d-b0b1f3c82bc3268=1279=0269=083=159756523455=BTC-USD270=3.81271=0.6232294660=20250411-01:46:50.14819140=237=6c868d05-5150-49af-a613-68bfa11e491210=115
20250411-01:46:50.258427000 : 8=FIXT.1.19=32535=X49=Coinbase56=24ab46f784d1b20db435b852086e325034=3650=TEST52=20250411-01:46:50.149243369=2262=87859126-8df1-460e-8f6d-b0b1f3c82bc3268=1279=0269=2278=c5b88ea9-605d-4595-ac52-f7c3f08523ba83=159756523555=BTC-USD270=3.55271=0.6232294660=20250411-01:46:50.14819137=6c868d05-5150-49af-a613-68bfa11e49125797=110=072
20250411-01:46:50.258586000 : 8=FIXT.1.19=28835=X49=Coinbase56=24ab46f784d1b20db435b852086e325034=3750=TEST52=20250411-01:46:50.149248369=2262=87859126-8df1-460e-8f6d-b0b1f3c82bc3268=1279=2269=0278=6c868d05-5150-49af-a613-68bfa11e491283=159756523655=BTC-USD270=3.81271=0.0000000060=20250411-01:46:50.14819158=FILLED10=032
20250411-01:46:50.288812000 : 8=FIXT.1.19=30835=X49=Coinbase56=24ab46f784d1b20db435b852086e325034=3850=TEST52=20250411-01:46:50.179404369=2262=87859126-8df1-460e-8f6d-b0b1f3c82bc3268=1279=1269=1278=ab722d07-606d-4d61-bf2d-aaebc3dbb22483=159756523755=BTC-USD270=3.56271=0.5148309960=20250411-01:46:50.17853758=CHANGE_REASON_MODIFY_ORDER10=156
20250411-01:46:50.411686000 : 8=FIXT.1.19=27735=X49=Coinbase56=24ab46f784d1b20db435b852086e325034=3950=TEST52=20250411-01:46:50.303082369=2262=87859126-8df1-460e-8f6d-b0b1f3c82bc3268=1279=0269=083=159756523855=BTC-USD29004=2.208895519560=20250411-01:46:50.30109740=137=17790fbb-359c-4257-baf4-9caf06a6479310=023
20250411-01:46:50.412090000 : 8=FIXT.1.19=32535=X49=Coinbase56=24ab46f784d1b20db435b852086e325034=4050=TEST52=20250411-01:46:50.303101369=2262=87859126-8df1-460e-8f6d-b0b1f3c82bc3268=1279=0269=2278=c5b88ea9-605d-4595-ac52-f7c3f08523ba83=159756523955=BTC-USD270=3.55271=0.6222240960=20250411-01:46:50.30109737=17790fbb-359c-4257-baf4-9caf06a647935797=110=153
20250411-01:46:50.412331000 : 8=FIXT.1.19=26435=X49=Coinbase56=24ab46f784d1b20db435b852086e325034=4150=TEST52=20250411-01:46:50.303106369=2262=87859126-8df1-460e-8f6d-b0b1f3c82bc3268=1279=2269=0278=17790fbb-359c-4257-baf4-9caf06a6479383=159756524055=BTC-USD60=20250411-01:46:50.30109758=FILLED10=018
20250411-01:46:50.431948000 : 8=FIXT.1.19=27335=X49=Coinbase56=24ab46f784d1b20db435b852086e325034=4250=TEST52=20250411-01:46:50.323877369=2262=87859126-8df1-460e-8f6d-b0b1f3c82bc3268=1279=0269=183=159756524155=BTC-USD271=0.6197183160=20250411-01:46:50.32273040=137=080725c9-281d-429a-b301-52479999317210=234
20250411-01:46:50.432170000 : 8=FIXT.1.19=32535=X49=Coinbase56=24ab46f784d1b20db435b852086e325034=4350=TEST52=20250411-01:46:50.323885369=2262=87859126-8df1-460e-8f6d-b0b1f3c82bc3268=1279=0269=2278=4d60a78e-b39b-420e-b830-bc0f3f4fdde283=159756524255=BTC-USD270=3.53271=0.6197183160=20250411-01:46:50.32273037=080725c9-281d-429a-b301-5247999931725797=210=222
20250411-01:46:50.432307000 : 8=FIXT.1.19=27935=X49=Coinbase56=24ab46f784d1b20db435b852086e325034=4450=TEST52=20250411-01:46:50.323890369=2262=87859126-8df1-460e-8f6d-b0b1f3c82bc3268=1279=2269=1278=080725c9-281d-429a-b301-52479999317283=159756524355=BTC-USD271=0.0000000060=20250411-01:46:50.32273058=FILLED10=140
20250411-01:46:50.436419000 : 8=FIXT.1.19=28235=X49=Coinbase56=24ab46f784d1b20db435b852086e325034=4550=TEST52=20250411-01:46:50.328052369=2262=87859126-8df1-460e-8f6d-b0b1f3c82bc3268=1279=0269=083=159756524455=BTC-USD270=3.91271=0.6197183160=20250411-01:46:50.32635540=237=23ce91b1-7e6f-4ec3-bde9-a35fc8cb042210=145
20250411-01:46:50.436764000 : 8=FIXT.1.19=32535=X49=Coinbase56=24ab46f784d1b20db435b852086e325034=4650=TEST52=20250411-01:46:50.328060369=2262=87859126-8df1-460e-8f6d-b0b1f3c82bc3268=1279=0269=2278=c5b88ea9-605d-4595-ac52-f7c3f08523ba83=159756524555=BTC-USD270=3.55271=0.6197183160=20250411-01:46:50.32635537=23ce91b1-7e6f-4ec3-bde9-a35fc8cb04225797=110=100
20250411-01:46:50.437056000 : 8=FIXT.1.19=28835=X49=Coinbase56=24ab46f784d1b20db435b852086e325034=4750=TEST52=20250411-01:46:50.328064369=2262=87859126-8df1-460e-8f6d-b0b1f3c82bc3268=1279=2269=0278=23ce91b1-7e6f-4ec3-bde9-a35fc8cb042283=159756524655=BTC-USD270=3.91271=0.0000000060=20250411-01:46:50.32635558=FILLED10=058
20250411-01:46:50.576464000 : 8=FIXT.1.19=30835=X49=Coinbase56=24ab46f784d1b20db435b852086e325034=4850=TEST52=20250411-01:46:50.466816369=2262=87859126-8df1-460e-8f6d-b0b1f3c82bc3268=1279=1269=0278=f689890c-8f76-4091-8ff9-a0a99f3d766083=159756524755=BTC-USD270=3.43271=0.4349747260=20250411-01:46:50.46510658=CHANGE_REASON_MODIFY_ORDER10=141
20250411-01:46:50.577084000 : 8=FIXT.1.19=27735=X49=Coinbase56=24ab46f784d1b20db435b852086e325034=4950=TEST52=20250411-01:46:50.466825369=2262=87859126-8df1-460e-8f6d-b0b1f3c82bc3268=1279=0269=083=159756524855=BTC-USD29004=2.208895519560=20250411-01:46:50.46550240=137=5fa5d740-f2df-4a43-9ade-a619d07f54a210=173
20250411-01:46:50.577273000 : 8=FIXT.1.19=32535=X49=Coinbase56=24ab46f784d1b20db435b852086e325034=5050=TEST52=20250411-01:46:50.466842369=2262=87859126-8df1-460e-8f6d-b0b1f3c82bc3268=1279=0269=2278=c5b88ea9-605d-4595-ac52-f7c3f08523ba83=159756524955=BTC-USD270=3.55271=0.6222240960=20250411-01:46:50.46550237=5fa5d740-f2df-4a43-9ade-a619d07f54a25797=110=054
20250411-01:46:50.577450000 : 8=FIXT.1.19=26435=X49=Coinbase56=24ab46f784d1b20db435b852086e325034=5150=TEST52=20250411-01:46:50.466847369=2262=87859126-8df1-460e-8f6d-b0b1f3c82bc3268=1279=2269=0278=5fa5d740-f2df-4a43-9ade-a619d07f54a283=159756525055=BTC-USD60=20250411-01:46:50.46550258=FILLED10=175
20250411-01:46:50.603916000 : 8=FIXT.1.19=27335=X49=Coinbase56=24ab46f784d1b20db435b852086e325034=5250=TEST52=20250411-01:46:50.496210369=2262=87859126-8df1-460e-8f6d-b0b1f3c82bc3268=1279=0269=183=159756525155=BTC-USD271=0.6197183160=20250411-01:46:50.49491440=137=7dd90281-a8e1-4cfe-a2e3-7a1f41211ad710=139
20250411-01:46:50.604102000 : 8=FIXT.1.19=32535=X49=Coinbase56=24ab46f784d1b20db435b852086e325034=5350=TEST52=20250411-01:46:50.496219369=2262=87859126-8df1-460e-8f6d-b0b1f3c82bc3268=1279=0269=2278=4d60a78e-b39b-420e-b830-bc0f3f4fdde283=159756525255=BTC-USD270=3.53271=0.6197183160=20250411-01:46:50.49491437=7dd90281-a8e1-4cfe-a2e3-7a1f41211ad75797=210=137
20250411-01:46:50.604295000 : 8=FIXT.1.19=27935=X49=Coinbase56=24ab46f784d1b20db435b852086e325034=5450=TEST52=20250411-01:46:50.496224369=2262=87859126-8df1-460e-8f6d-b0b1f3c82bc3268=1279=2269=1278=7dd90281-a8e1-4cfe-a2e3-7a1f41211ad783=159756525355=BTC-USD271=0.0000000060=20250411-01:46:50.49491458=FILLED10=055
20250411-01:46:50.661012000 : 8=FIXT.1.19=28135=X49=Coinbase56=24ab46f784d1b20db435b852086e325034=5550=TEST52=20250411-01:46:50.552469369=2262=87859126-8df1-460e-8f6d-b0b1f3c82bc3268=1279=0269=183=159756525455=BTC-USD270=3.3271=0.6232294660=20250411-01:46:50.55079740=237=f3be00b7-9437-4d09-9572-4b07bb164a4a10=124
20250411-01:46:50.661327000 : 8=FIXT.1.19=32535=X49=Coinbase56=24ab46f784d1b20db435b852086e325034=5650=TEST52=20250411-01:46:50.552478369=2262=87859126-8df1-460e-8f6d-b0b1f3c82bc3268=1279=0269=2278=4d60a78e-b39b-420e-b830-bc0f3f4fdde283=159756525555=BTC-USD270=3.53271=0.6232294660=20250411-01:46:50.55079737=f3be00b7-9437-4d09-9572-4b07bb164a4a5797=210=006
20250411-01:46:50.661680000 : 8=FIXT.1.19=28735=X49=Coinbase56=24ab46f784d1b20db435b852086e325034=5750=TEST52=20250411-01:46:50.552483369=2262=87859126-8df1-460e-8f6d-b0b1f3c82bc3268=1279=2269=1278=f3be00b7-9437-4d09-9572-4b07bb164a4a83=159756525655=BTC-USD270=3.3271=0.0000000060=20250411-01:46:50.55079758=FILLED10=032
20250411-01:46:50.714236000 : 8=FIXT.1.19=28235=X49=Coinbase56=24ab46f784d1b20db435b852086e325034=5850=TEST52=20250411-01:46:50.606213369=2262=87859126-8df1-460e-8f6d-b0b1f3c82bc3268=1279=0269=083=159756525755=BTC-USD270=3.86271=0.6232294660=20250411-01:46:50.60503040=237=c4dc5e02-c22b-49ec-b047-9bb5596e394e10=056
20250411-01:46:50.714821000 : 8=FIXT.1.19=32535=X49=Coinbase56=24ab46f784d1b20db435b852086e325034=5950=TEST52=20250411-01:46:50.606222369=2262=87859126-8df1-460e-8f6d-b0b1f3c82bc3268=1279=0269=2278=c5b88ea9-605d-4595-ac52-f7c3f08523ba83=159756525855=BTC-USD270=3.55271=0.6232294660=20250411-01:46:50.60503037=c4dc5e02-c22b-49ec-b047-9bb5596e394e5797=110=008
20250411-01:46:50.714993000 : 8=FIXT.1.19=28835=X49=Coinbase56=24ab46f784d1b20db435b852086e325034=6050=TEST52=20250411-01:46:50.606228369=2262=87859126-8df1-460e-8f6d-b0b1f3c82bc3268=1279=2269=0278=c4dc5e02-c22b-49ec-b047-9bb5596e394e83=159756525955=BTC-USD270=3.86271=0.0000000060=20250411-01:46:50.60503058=FILLED10=221
20250411-01:46:50.863018000 : 8=FIXT.1.19=30835=X49=Coinbase56=24ab46f784d1b20db435b852086e325034=6150=TEST52=20250411-01:46:50.751871369=2262=87859126-8df1-460e-8f6d-b0b1f3c82bc3268=1279=1269=1278=1f8be7f0-8e9b-4e68-81dd-048971f81cf983=159756526055=BTC-USD270=3.56271=0.4716434960=20250411-01:46:50.75081158=CHANGE_REASON_MODIFY_ORDER10=010
20250411-01:46:50.920834000 : 8=FIXT.1.19=27735=X49=Coinbase56=24ab46f784d1b20db435b852086e325034=6250=TEST52=20250411-01:46:50.812482369=2262=87859126-8df1-460e-8f6d-b0b1f3c82bc3268=1279=0269=083=159756526155=BTC-USD29004=2.208895519560=20250411-01:46:50.81121940=137=6d7a5eba-4f2b-44c9-892e-f86acf57132e10=172
20250411-01:46:50.921373000 : 8=FIXT.1.19=32535=X49=Coinbase56=24ab46f784d1b20db435b852086e325034=6350=TEST52=20250411-01:46:50.812491369=2262=87859126-8df1-460e-8f6d-b0b1f3c82bc3268=1279=0269=2278=c5b88ea9-605d-4595-ac52-f7c3f08523ba83=159756526255=BTC-USD270=3.55271=0.6222240960=20250411-01:46:50.81121937=6d7a5eba-4f2b-44c9-892e-f86acf57132e5797=110=063
20250411-01:46:50.921551000 : 8=FIXT.1.19=26435=X49=Coinbase56=24ab46f784d1b20db435b852086e325034=6450=TEST52=20250411-01:46:50.812496369=2262=87859126-8df1-460e-8f6d-b0b1f3c82bc3268=1279=2269=0278=6d7a5eba-4f2b-44c9-892e-f86acf57132e83=159756526355=BTC-USD60=20250411-01:46:50.81121958=FILLED10=193
20250411-01:46:50.949280000 : 8=FIXT.1.19=27335=X49=Coinbase56=24ab46f784d1b20db435b852086e325034=6550=TEST52=20250411-01:46:50.840784369=2262=87859126-8df1-460e-8f6d-b0b1f3c82bc3268=1279=0269=183=159756526455=BTC-USD271=0.6197183160=20250411-01:46:50.83917340=137=2d58db23-ca00-4236-a49d-bbdd33cfe45210=199
20250411-01:46:50.949600000 : 8=FIXT.1.19=32535=X49=Coinbase56=24ab46f784d1b20db435b852086e325034=6650=TEST52=20250411-01:46:50.840804369=2262=87859126-8df1-460e-8f6d-b0b1f3c82bc3268=1279=0269=2278=4d60a78e-b39b-420e-b830-bc0f3f4fdde283=159756526555=BTC-USD270=3.53271=0.6197183160=20250411-01:46:50.83917337=2d58db23-ca00-4236-a49d-bbdd33cfe4525797=210=181
20250411-01:46:50.949892000 : 8=FIXT.1.19=27935=X49=Coinbase56=24ab46f784d1b20db435b852086e325034=6750=TEST52=20250411-01:46:50.840809369=2262=87859126-8df1-460e-8f6d-b0b1f3c82bc3268=1279=2269=1278=2d58db23-ca00-4236-a49d-bbdd33cfe45283=159756526655=BTC-USD271=0.0000000060=20250411-01:46:50.83917358=FILLED10=108
20250411-01:46:51.146180000 : 8=FIXT.1.19=30835=X49=Coinbase56=24ab46f784d1b20db435b852086e325034=6850=TEST52=20250411-01:46:51.037570369=2262=87859126-8df1-460e-8f6d-b0b1f3c82bc3268=1279=1269=1278=6ccc674e-1f21-41b2-bc6e-a5bd9976780c83=159756526755=BTC-USD270=3.69271=0.4409577260=20250411-01:46:51.03611258=CHANGE_REASON_MODIFY_ORDER10=034
20250411-01:46:51.146892000 : 8=FIXT.1.19=27735=X49=Coinbase56=24ab46f784d1b20db435b852086e325034=6950=TEST52=20250411-01:46:51.039144369=2262=87859126-8df1-460e-8f6d-b0b1f3c82bc3268=1279=0269=083=159756526855=BTC-USD29004=2.208895519560=20250411-01:46:51.03796840=137=ad25af30-476c-47bf-bf5e-e3cb34e4488d10=233
20250411-01:46:51.147026000 : 8=FIXT.1.19=32535=X49=Coinbase56=24ab46f784d1b20db435b852086e325034=7050=TEST52=20250411-01:46:51.039152369=2262=87859126-8df1-460e-8f6d-b0b1f3c82bc3268=1279=0269=2278=c5b88ea9-605d-4595-ac52-f7c3f08523ba83=159756526955=BTC-USD270=3.55271=0.6222240960=20250411-01:46:51.03796837=ad25af30-476c-47bf-bf5e-e3cb34e4488d5797=110=114
20250411-01:46:51.147375000 : 8=FIXT.1.19=26435=X49=Coinbase56=24ab46f784d1b20db435b852086e325034=7150=TEST52=20250411-01:46:51.039156369=2262=87859126-8df1-460e-8f6d-b0b1f3c82bc3268=1279=2269=0278=ad25af30-476c-47bf-bf5e-e3cb34e4488d83=159756527055=BTC-USD60=20250411-01:46:51.03796858=FILLED10=234
20250411-01:46:51.176528000 : 8=FIXT.1.19=27335=X49=Coinbase56=24ab46f784d1b20db435b852086e325034=7250=TEST52=20250411-01:46:51.068622369=2262=87859126-8df1-460e-8f6d-b0b1f3c82bc3268=1279=0269=183=159756527155=BTC-USD271=0.6232294660=20250411-01:46:51.06716940=137=a9bb4adc-73a2-442a-bce0-a1c76972e0eb10=024
20250411-01:46:51.176973000 : 8=FIXT.1.19=32535=X49=Coinbase56=24ab46f784d1b20db435b852086e325034=7350=TEST52=20250411-01:46:51.068631369=2262=87859126-8df1-460e-8f6d-b0b1f3c82bc3268=1279=0269=2278=4d60a78e-b39b-420e-b830-bc0f3f4fdde283=159756527255=BTC-USD270=3.53271=0.6232294660=20250411-01:46:51.06716937=a9bb4adc-73a2-442a-bce0-a1c76972e0eb5797=210=013
20250411-01:46:51.177159000 : 8=FIXT.1.19=27935=X49=Coinbase56=24ab46f784d1b20db435b852086e325034=7450=TEST52=20250411-01:46:51.068636369=2262=87859126-8df1-460e-8f6d-b0b1f3c82bc3268=1279=2269=1278=a9bb4adc-73a2-442a-bce0-a1c76972e0eb83=159756527355=BTC-USD271=0.0000000060=20250411-01:46:51.06716958=FILLED10=198
20250411-01:46:51.317289000 : 8=FIXT.1.19=27735=X49=Coinbase56=24ab46f784d1b20db435b852086e325034=7550=TEST52=20250411-01:46:51.209402369=2262=87859126-8df1-460e-8f6d-b0b1f3c82bc3268=1279=0269=083=159756527455=BTC-USD29004=2.208895519560=20250411-01:46:51.20819340=137=9f36bfc6-19a9-4c8a-bab2-6e33eda09d8910=222
20250411-01:46:51.317571000 : 8=FIXT.1.19=32535=X49=Coinbase56=24ab46f784d1b20db435b852086e325034=7650=TEST52=20250411-01:46:51.209411369=2262=87859126-8df1-460e-8f6d-b0b1f3c82bc3268=1279=0269=2278=c5b88ea9-605d-4595-ac52-f7c3f08523ba83=159756527555=BTC-USD270=3.55271=0.6222240960=20250411-01:46:51.20819337=9f36bfc6-19a9-4c8a-bab2-6e33eda09d895797=110=113
20250411-01:46:51.317728000 : 8=FIXT.1.19=26435=X49=Coinbase56=24ab46f784d1b20db435b852086e325034=7750=TEST52=20250411-01:46:51.209416369=2262=87859126-8df1-460e-8f6d-b0b1f3c82bc3268=1279=2269=0278=9f36bfc6-19a9-4c8a-bab2-6e33eda09d8983=159756527655=BTC-USD60=20250411-01:46:51.20819358=FILLED10=243
20250411-01:46:51.346954000 : 8=FIXT.1.19=27335=X49=Coinbase56=24ab46f784d1b20db435b852086e325034=7850=TEST52=20250411-01:46:51.238854369=2262=87859126-8df1-460e-8f6d-b0b1f3c82bc3268=1279=0269=183=159756527755=BTC-USD271=0.6232294660=20250411-01:46:51.23683940=137=58e0c9cb-1973-4a6d-bfa0-79a1d5d4fb5210=225
20250411-01:46:51.347236000 : 8=FIXT.1.19=32535=X49=Coinbase56=24ab46f784d1b20db435b852086e325034=7950=TEST52=20250411-01:46:51.238863369=2262=87859126-8df1-460e-8f6d-b0b1f3c82bc3268=1279=0269=2278=4d60a78e-b39b-420e-b830-bc0f3f4fdde283=159756527855=BTC-USD270=3.53271=0.6232294660=20250411-01:46:51.23683937=58e0c9cb-1973-4a6d-bfa0-79a1d5d4fb525797=210=214
20250411-01:46:51.347410000 : 8=FIXT.1.19=27935=X49=Coinbase56=24ab46f784d1b20db435b852086e325034=8050=TEST52=20250411-01:46:51.238867369=2262=87859126-8df1-460e-8f6d-b0b1f3c82bc3268=1279=2269=1278=58e0c9cb-1973-4a6d-bfa0-79a1d5d4fb5283=159756527955=BTC-USD271=0.0000000060=20250411-01:46:51.23683958=FILLED10=133
20250411-01:46:51.438042000 : 8=FIXT.1.19=28135=X49=Coinbase56=24ab46f784d1b20db435b852086e325034=8150=TEST52=20250411-01:46:51.328985369=2262=87859126-8df1-460e-8f6d-b0b1f3c82bc3268=1279=0269=183=159756528055=BTC-USD270=3.2271=0.6197183160=20250411-01:46:51.32758840=237=4802f120-62c5-403c-9fd8-327abf7e3dc110=175
20250411-01:46:51.438582000 : 8=FIXT.1.19=32535=X49=Coinbase56=24ab46f784d1b20db435b852086e325034=8250=TEST52=20250411-01:46:51.329000369=2262=87859126-8df1-460e-8f6d-b0b1f3c82bc3268=1279=0269=2278=4d60a78e-b39b-420e-b830-bc0f3f4fdde283=159756528155=BTC-USD270=3.53271=0.6197183160=20250411-01:46:51.32758837=4802f120-62c5-403c-9fd8-327abf7e3dc15797=210=037
20250411-01:46:51.438864000 : 8=FIXT.1.19=28735=X49=Coinbase56=24ab46f784d1b20db435b852086e325034=8350=TEST52=20250411-01:46:51.329004369=2262=87859126-8df1-460e-8f6d-b0b1f3c82bc3268=1279=2269=1278=4802f120-62c5-403c-9fd8-327abf7e3dc183=159756528255=BTC-USD270=3.2271=0.0000000060=20250411-01:46:51.32758858=FILLED10=068
20250411-01:46:51.489671000 : 8=FIXT.1.19=27735=X49=Coinbase56=24ab46f784d1b20db435b852086e325034=8450=TEST52=20250411-01:46:51.381609369=2262=87859126-8df1-460e-8f6d-b0b1f3c82bc3268=1279=0269=083=159756528355=BTC-USD29004=2.208895519560=20250411-01:46:51.38011840=137=35058588-4f8f-4de3-bde5-0de57270eb2e10=087
20250411-01:46:51.490072000 : 8=FIXT.1.19=32535=X49=Coinbase56=24ab46f784d1b20db435b852086e325034=8550=TEST52=20250411-01:46:51.381619369=2262=87859126-8df1-460e-8f6d-b0b1f3c82bc3268=1279=0269=2278=c5b88ea9-605d-4595-ac52-f7c3f08523ba83=159756528455=BTC-USD270=3.55271=0.6222240960=20250411-01:46:51.38011837=35058588-4f8f-4de3-bde5-0de57270eb2e5797=110=235
20250411-01:46:51.490217000 : 8=FIXT.1.19=26435=X49=Coinbase56=24ab46f784d1b20db435b852086e325034=8650=TEST52=20250411-01:46:51.381623369=2262=87859126-8df1-460e-8f6d-b0b1f3c82bc3268=1279=2269=0278=35058588-4f8f-4de3-bde5-0de57270eb2e83=159756528555=BTC-USD60=20250411-01:46:51.38011858=FILLED10=099
20250411-01:46:51.520141000 : 8=FIXT.1.19=27335=X49=Coinbase56=24ab46f784d1b20db435b852086e325034=8750=TEST52=20250411-01:46:51.411118369=2262=87859126-8df1-460e-8f6d-b0b1f3c82bc3268=1279=0269=183=159756528655=BTC-USD271=0.6232294660=20250411-01:46:51.40912740=137=8e84cbe9-a5cc-4170-9ed9-f5c5b66426b310=171
20250411-01:46:51.520690000 : 8=FIXT.1.19=32535=X49=Coinbase56=24ab46f784d1b20db435b852086e325034=8850=TEST52=20250411-01:46:51.411127369=2262=87859126-8df1-460e-8f6d-b0b1f3c82bc3268=1279=0269=2278=4d60a78e-b39b-420e-b830-bc0f3f4fdde283=159756528755=BTC-USD270=3.53271=0.6232294660=20250411-01:46:51.40912737=8e84cbe9-a5cc-4170-9ed9-f5c5b66426b35797=210=160
20250411-01:46:51.520864000 : 8=FIXT.1.19=27935=X49=Coinbase56=24ab46f784d1b20db435b852086e325034=8950=TEST52=20250411-01:46:51.411134369=2262=87859126-8df1-460e-8f6d-b0b1f3c82bc3268=1279=2269=1278=8e84cbe9-a5cc-4170-9ed9-f5c5b66426b383=159756528855=BTC-USD271=0.0000000060=20250411-01:46:51.40912758=FILLED10=082
20250411-01:46:51.574546000 : 8=FIXT.1.19=28235=X49=Coinbase56=24ab46f784d1b20db435b852086e325034=9050=TEST52=20250411-01:46:51.465763369=2262=87859126-8df1-460e-8f6d-b0b1f3c82bc3268=1279=0269=083=159756528955=BTC-USD270=3.82271=0.6232294660=20250411-01:46:51.46380340=237=5fb52edc-84d1-4ced-a531-9787e1a1262610=027
20250411-01:46:51.574953000 : 8=FIXT.1.19=32535=X49=Coinbase56=24ab46f784d1b20db435b852086e325034=9150=TEST52=20250411-01:46:51.465783369=2262=87859126-8df1-460e-8f6d-b0b1f3c82bc3268=1279=0269=2278=c5b88ea9-605d-4595-ac52-f7c3f08523ba83=159756529055=BTC-USD270=3.55271=0.6232294660=20250411-01:46:51.46380337=5fb52edc-84d1-4ced-a531-9787e1a126265797=110=232
20250411-01:46:51.575103000 : 8=FIXT.1.19=28835=X49=Coinbase56=24ab46f784d1b20db435b852086e325034=9250=TEST52=20250411-01:46:51.465800369=2262=87859126-8df1-460e-8f6d-b0b1f3c82bc3268=1279=2269=0278=5fb52edc-84d1-4ced-a531-9787e1a1262683=159756529155=BTC-USD270=3.82271=0.0000000060=20250411-01:46:51.46380358=FILLED10=178
20250411-01:46:51.629355000 : 8=FIXT.1.19=28235=X49=Coinbase56=24ab46f784d1b20db435b852086e325034=9350=TEST52=20250411-01:46:51.520872369=2262=87859126-8df1-460e-8f6d-b0b1f3c82bc3268=1279=0269=183=159756529255=BTC-USD270=3.31271=0.6232294660=20250411-01:46:51.51927840=237=4368b71a-16a0-41c0-8ab5-3bdd57e52ab410=254
20250411-01:46:51.629639000 : 8=FIXT.1.19=32535=X49=Coinbase56=24ab46f784d1b20db435b852086e325034=9450=TEST52=20250411-01:46:51.520881369=2262=87859126-8df1-460e-8f6d-b0b1f3c82bc3268=1279=0269=2278=4d60a78e-b39b-420e-b830-bc0f3f4fdde283=159756529355=BTC-USD270=3.53271=0.6232294660=20250411-01:46:51.51927837=4368b71a-16a0-41c0-8ab5-3bdd57e52ab45797=210=086
20250411-01:46:51.629798000 : 8=FIXT.1.19=28835=X49=Coinbase56=24ab46f784d1b20db435b852086e325034=9550=TEST52=20250411-01:46:51.520886369=2262=87859126-8df1-460e-8f6d-b0b1f3c82bc3268=1279=2269=1278=4368b71a-16a0-41c0-8ab5-3bdd57e52ab483=159756529455=BTC-USD270=3.31271=0.0000000060=20250411-01:46:51.51927858=FILLED10=171
20250411-01:46:51.660721000 : 8=FIXT.1.19=27735=X49=Coinbase56=24ab46f784d1b20db435b852086e325034=9650=TEST52=20250411-01:46:51.552487369=2262=87859126-8df1-460e-8f6d-b0b1f3c82bc3268=1279=0269=083=159756529555=BTC-USD29004=2.208895519560=20250411-01:46:51.55112040=137=57b1391c-2cc1-44a8-9449-952ba1d99eac10=034
20250411-01:46:51.661026000 : 8=FIXT.1.19=32535=X49=Coinbase56=24ab46f784d1b20db435b852086e325034=9750=TEST52=20250411-01:46:51.552495369=2262=87859126-8df1-460e-8f6d-b0b1f3c82bc3268=1279=0269=2278=c5b88ea9-605d-4595-ac52-f7c3f08523ba83=159756529655=BTC-USD270=3.55271=0.6222240960=20250411-01:46:51.55112037=57b1391c-2cc1-44a8-9449-952ba1d99eac5797=110=180
20250411-01:46:51.661202000 : 8=FIXT.1.19=26435=X49=Coinbase56=24ab46f784d1b20db435b852086e325034=9850=TEST52=20250411-01:46:51.552500369=2262=87859126-8df1-460e-8f6d-b0b1f3c82bc3268=1279=2269=0278=57b1391c-2cc1-44a8-9449-952ba1d99eac83=159756529755=BTC-USD60=20250411-01:46:51.55112058=FILLED10=036
20250411-01:46:51.689534000 : 8=FIXT.1.19=27335=X49=Coinbase56=24ab46f784d1b20db435b852086e325034=9950=TEST52=20250411-01:46:51.580866369=2262=87859126-8df1-460e-8f6d-b0b1f3c82bc3268=1279=0269=183=159756529855=BTC-USD271=0.6197183160=20250411-01:46:51.57959940=137=89f6e403-c63d-4b79-8bad-3bd005f701a510=152
20250411-01:46:51.690185000 : 8=FIXT.1.19=32635=X49=Coinbase56=24ab46f784d1b20db435b852086e325034=10050=TEST52=20250411-01:46:51.580874369=2262=87859126-8df1-460e-8f6d-b0b1f3c82bc3268=1279=0269=2278=4d60a78e-b39b-420e-b830-bc0f3f4fdde283=159756529955=BTC-USD270=3.53271=0.6197183160=20250411-01:46:51.57959937=89f6e403-c63d-4b79-8bad-3bd005f701a55797=210=171
20250411-01:46:51.690396000 : 8=FIXT.1.19=28035=X49=Coinbase56=24ab46f784d1b20db435b852086e325034=10150=TEST52=20250411-01:46:51.580879369=2262=87859126-8df1-460e-8f6d-b0b1f3c82bc3268=1279=2269=1278=89f6e403-c63d-4b79-8bad-3bd005f701a583=159756530055=BTC-USD271=0.0000000060=20250411-01:46:51.57959958=FILLED10=071
20250411-01:46:51.717996000 : 8=FIXT.1.19=27835=X49=Coinbase56=24ab46f784d1b20db435b852086e325034=10250=TEST52=20250411-01:46:51.609334369=2262=87859126-8df1-460e-8f6d-b0b1f3c82bc3268=1279=0269=083=159756530155=BTC-USD29004=2.208895519560=20250411-01:46:51.60811740=137=e13b8a89-47fa-45ea-a463-1ee67600f4a010=101
20250411-01:46:51.718416000 : 8=FIXT.1.19=32635=X49=Coinbase56=24ab46f784d1b20db435b852086e325034=10350=TEST52=20250411-01:46:51.609342369=2262=87859126-8df1-460e-8f6d-b0b1f3c82bc3268=1279=0269=2278=c5b88ea9-605d-4595-ac52-f7c3f08523ba83=159756530255=BTC-USD270=3.55271=0.6222240960=20250411-01:46:51.60811737=e13b8a89-47fa-45ea-a463-1ee67600f4a05797=110=247
20250411-01:46:51.718587000 : 8=FIXT.1.19=26535=X49=Coinbase56=24ab46f784d1b20db435b852086e325034=10450=TEST52=20250411-01:46:51.609347369=2262=87859126-8df1-460e-8f6d-b0b1f3c82bc3268=1279=2269=0278=e13b8a89-47fa-45ea-a463-1ee67600f4a083=159756530355=BTC-USD60=20250411-01:46:51.60811758=FILLED10=121
20250411-01:46:51.747976000 : 8=FIXT.1.19=27435=X49=Coinbase56=24ab46f784d1b20db435b852086e325034=10550=TEST52=20250411-01:46:51.639904369=2262=87859126-8df1-460e-8f6d-b0b1f3c82bc3268=1279=0269=183=159756530455=BTC-USD271=0.6197183160=20250411-01:46:51.63817240=137=e451b5e0-5102-42d5-977d-adfa5691e46610=065
20250411-01:46:51.748286000 : 8=FIXT.1.19=32635=X49=Coinbase56=24ab46f784d1b20db435b852086e325034=10650=TEST52=20250411-01:46:51.639912369=2262=87859126-8df1-460e-8f6d-b0b1f3c82bc3268=1279=0269=2278=4d60a78e-b39b-420e-b830-bc0f3f4fdde283=159756530555=BTC-USD270=3.53271=0.6197183160=20250411-01:46:51.63817237=e451b5e0-5102-42d5-977d-adfa5691e4665797=210=053
20250411-01:46:51.748448000 : 8=FIXT.1.19=28035=X49=Coinbase56=24ab46f784d1b20db435b852086e325034=10750=TEST52=20250411-01:46:51.639917369=2262=87859126-8df1-460e-8f6d-b0b1f3c82bc3268=1279=2269=1278=e451b5e0-5102-42d5-977d-adfa5691e46683=159756530655=BTC-USD271=0.0000000060=20250411-01:46:51.63817258=FILLED10=227
20250411-01:46:51.803253000 : 8=FIXT.1.19=28335=X49=Coinbase56=24ab46f784d1b20db435b852086e325034=10850=TEST52=20250411-01:46:51.695245369=2262=87859126-8df1-460e-8f6d-b0b1f3c82bc3268=1279=0269=083=159756530755=BTC-USD270=3.87271=0.6232294660=20250411-01:46:51.69362040=237=62da0344-4d92-4590-8f5f-21196096043710=254
20250411-01:46:51.803734000 : 8=FIXT.1.19=32635=X49=Coinbase56=24ab46f784d1b20db435b852086e325034=10950=TEST52=20250411-01:46:51.695253369=2262=87859126-8df1-460e-8f6d-b0b1f3c82bc3268=1279=0269=2278=c5b88ea9-605d-4595-ac52-f7c3f08523ba83=159756530855=BTC-USD270=3.55271=0.6232294660=20250411-01:46:51.69362037=62da0344-4d92-4590-8f5f-2119609604375797=110=204
20250411-01:46:51.803915000 : 8=FIXT.1.19=28935=X49=Coinbase56=24ab46f784d1b20db435b852086e325034=11050=TEST52=20250411-01:46:51.695258369=2262=87859126-8df1-460e-8f6d-b0b1f3c82bc3268=1279=2269=0278=62da0344-4d92-4590-8f5f-21196096043783=159756530955=BTC-USD270=3.87271=0.0000000060=20250411-01:46:51.69362058=FILLED10=161
20250411-01:46:51.858866000 : 8=FIXT.1.19=28335=X49=Coinbase56=24ab46f784d1b20db435b852086e325034=11150=TEST52=20250411-01:46:51.750478369=2262=87859126-8df1-460e-8f6d-b0b1f3c82bc3268=1279=0269=183=159756531055=BTC-USD270=3.33271=0.6232294660=20250411-01:46:51.74861140=237=011967cf-90fc-4aad-bcb8-b96242387c0b10=097
20250411-01:46:51.859275000 : 8=FIXT.1.19=32635=X49=Coinbase56=24ab46f784d1b20db435b852086e325034=11250=TEST52=20250411-01:46:51.750488369=2262=87859126-8df1-460e-8f6d-b0b1f3c82bc3268=1279=0269=2278=4d60a78e-b39b-420e-b830-bc0f3f4fdde283=159756531155=BTC-USD270=3.53271=0.6232294660=20250411-01:46:51.74861137=011967cf-90fc-4aad-bcb8-b96242387c0b5797=210=184
20250411-01:46:51.859432000 : 8=FIXT.1.19=28935=X49=Coinbase56=24ab46f784d1b20db435b852086e325034=11350=TEST52=20250411-01:46:51.750492369=2262=87859126-8df1-460e-8f6d-b0b1f3c82bc3268=1279=2269=1278=011967cf-90fc-4aad-bcb8-b96242387c0b83=159756531255=BTC-USD270=3.33271=0.0000000060=20250411-01:46:51.74861158=FILLED10=005
20250411-01:46:52.152635000 : 8=FIXT.1.19=8335=534=349=24ab46f784d1b20db435b852086e325052=20250411-01:46:52.15256=Coinbase10=110
20250411-01:46:52.159010000 : 8=FIXT.1.19=27835=X49=Coinbase56=24ab46f784d1b20db435b852086e325034=11450=TEST52=20250411-01:46:52.010280369=2262=87859126-8df1-460e-8f6d-b0b1f3c82bc3268=1279=0269=083=159756531355=BTC-USD29004=2.208895519560=20250411-01:46:52.00840940=137=ae02cf71-21f5-434b-ad7a-2ae031766a8910=082
20250411-01:46:52.159268000 : 8=FIXT.1.19=32635=X49=Coinbase56=24ab46f784d1b20db435b852086e325034=11550=TEST52=20250411-01:46:52.010335369=2262=87859126-8df1-460e-8f6d-b0b1f3c82bc3268=1279=0269=2278=c5b88ea9-605d-4595-ac52-f7c3f08523ba83=159756531455=BTC-USD270=3.55271=0.6222240960=20250411-01:46:52.00840937=ae02cf71-21f5-434b-ad7a-2ae031766a895797=110=230
20250411-01:46:52.159437000 : 8=FIXT.1.19=26535=X49=Coinbase56=24ab46f784d1b20db435b852086e325034=11650=TEST52=20250411-01:46:52.010344369=2262=87859126-8df1-460e-8f6d-b0b1f3c82bc3268=1279=2269=0278=ae02cf71-21f5-434b-ad7a-2ae031766a8983=159756531555=BTC-USD60=20250411-01:46:52.00840958=FILLED10=099
20250411-01:46:52.159703000 : 8=FIXT.1.19=27435=X49=Coinbase56=24ab46f784d1b20db435b852086e325034=11750=TEST52=20250411-01:46:52.038650369=2262=87859126-8df1-460e-8f6d-b0b1f3c82bc3268=1279=0269=183=159756531655=BTC-USD271=0.6232294660=20250411-01:46:52.03771540=137=f72710e4-1ea4-49ab-82aa-574217ad7daa10=186
20250411-01:46:52.159876000 : 8=FIXT.1.19=32635=X49=Coinbase56=24ab46f784d1b20db435b852086e325034=11850=TEST52=20250411-01:46:52.038656369=2262=87859126-8df1-460e-8f6d-b0b1f3c82bc3268=1279=0269=2278=4d60a78e-b39b-420e-b830-bc0f3f4fdde283=159756531755=BTC-USD270=3.53271=0.6232294660=20250411-01:46:52.03771537=f72710e4-1ea4-49ab-82aa-574217ad7daa5797=210=181
20250411-01:46:52.160354000 : 8=FIXT.1.19=28035=X49=Coinbase56=24ab46f784d1b20db435b852086e325034=11950=TEST52=20250411-01:46:52.038697369=2262=87859126-8df1-460e-8f6d-b0b1f3c82bc3268=1279=2269=1278=f72710e4-1ea4-49ab-82aa-574217ad7daa83=159756531855=BTC-USD271=0.0000000060=20250411-01:46:52.03771558=FILLED10=101
20250411-01:50:19.672755000 : 8=FIXT.1.19=21535=A34=149=24ab46f784d1b20db435b852086e325052=20250411-01:50:19.66256=Coinbase95=4496=HFPObaJ/w7dNSFZJwLUO1AGt/9KsCVzNfQK9zmhLI6s=98=0108=30141=Y553=24ab46f784d1b20db435b852086e3250554=akmwnltyfgb1137=910=155
20250411-01:50:19.928984000 : 8=FIXT.1.19=12535=A49=Coinbase56=24ab46f784d1b20db435b852086e325034=150=TEST52=20250411-01:50:19.812711369=198=0108=30141=Y1137=910=188
20250411-01:50:21.417969000 : 8=FIXT.1.19=17835=V34=249=24ab46f784d1b20db435b852086e325052=20250411-01:50:21.41656=Coinbase1128=9146=155=BTC-USD262=83671f6c-e7d6-4990-a146-dc86a70aefdc263=1264=0267=2269=0269=110=114
20250411-01:50:21.674599000 : 8=FIXT.1.19=27235=X49=Coinbase56=24ab46f784d1b20db435b852086e325034=250=TEST52=20250411-01:50:21.558906369=2262=83671f6c-e7d6-4990-a146-dc86a70aefdc268=1279=0269=183=159756937355=BTC-USD271=0.6197183160=20250411-01:50:21.55729640=137=20a36dfe-2109-48b0-bcf2-c53caf9c454310=195
20250411-01:50:21.675670000 : 8=FIXT.1.19=32435=X49=Coinbase56=24ab46f784d1b20db435b852086e325034=350=TEST52=20250411-01:50:21.558916369=2262=83671f6c-e7d6-4990-a146-dc86a70aefdc268=1279=0269=2278=4d60a78e-b39b-420e-b830-bc0f3f4fdde283=159756937455=BTC-USD270=3.53271=0.6197183160=20250411-01:50:21.55729637=20a36dfe-2109-48b0-bcf2-c53caf9c45435797=210=185
20250411-01:50:21.675884000 : 8=FIXT.1.19=27835=X49=Coinbase56=24ab46f784d1b20db435b852086e325034=450=TEST52=20250411-01:50:21.558919369=2262=83671f6c-e7d6-4990-a146-dc86a70aefdc268=1279=2269=1278=20a36dfe-2109-48b0-bcf2-c53caf9c454383=159756937555=BTC-USD271=0.0000000060=20250411-01:50:21.55729658=FILLED10=110
20250411-01:50:21.701783000 : 8=FIXT.1.19=27635=X49=Coinbase56=24ab46f784d1b20db435b852086e325034=550=TEST52=20250411-01:50:21.586825369=2262=83671f6c-e7d6-4990-a146-dc86a70aefdc268=1279=0269=083=159756937655=BTC-USD29004=2.208895519560=20250411-01:50:21.58584040=137=89dcffdd-9558-47d0-90e4-9706e65b7fd010=158
20250411-01:50:21.702025000 : 8=FIXT.1.19=32435=X49=Coinbase56=24ab46f784d1b20db435b852086e325034=650=TEST52=20250411-01:50:21.586829369=2262=83671f6c-e7d6-4990-a146-dc86a70aefdc268=1279=0269=2278=c5b88ea9-605d-4595-ac52-f7c3f08523ba83=159756937755=BTC-USD270=3.55271=0.6222240960=20250411-01:50:21.58584037=89dcffdd-9558-47d0-90e4-9706e65b7fd05797=110=053
20250411-01:50:21.702205000 : 8=FIXT.1.19=26335=X49=Coinbase56=24ab46f784d1b20db435b852086e325034=750=TEST52=20250411-01:50:21.586920369=2262=83671f6c-e7d6-4990-a146-dc86a70aefdc268=1279=2269=0278=89dcffdd-9558-47d0-90e4-9706e65b7fd083=159756937855=BTC-USD60=20250411-01:50:21.58584058=FILLED10=170
20250411-01:50:21.730224000 : 8=FIXT.1.19=27235=X49=Coinbase56=24ab46f784d1b20db435b852086e325034=850=TEST52=20250411-01:50:21.615410369=2262=83671f6c-e7d6-4990-a146-dc86a70aefdc268=1279=0269=183=159756937955=BTC-USD271=0.6197183160=20250411-01:50:21.61414040=137=fa8f2339-c025-4dd4-9a83-c38a7f40b74010=092
20250411-01:50:21.730495000 : 8=FIXT.1.19=32435=X49=Coinbase56=24ab46f784d1b20db435b852086e325034=950=TEST52=20250411-01:50:21.615423369=2262=83671f6c-e7d6-4990-a146-dc86a70aefdc268=1279=0269=2278=4d60a78e-b39b-420e-b830-bc0f3f4fdde283=159756938055=BTC-USD270=3.53271=0.6197183160=20250411-01:50:21.61414037=fa8f2339-c025-4dd4-9a83-c38a7f40b7405797=210=076
20250411-01:50:21.730646000 : 8=FIXT.1.19=27935=X49=Coinbase56=24ab46f784d1b20db435b852086e325034=1050=TEST52=20250411-01:50:21.615427369=2262=83671f6c-e7d6-4990-a146-dc86a70aefdc268=1279=2269=1278=fa8f2339-c025-4dd4-9a83-c38a7f40b74083=159756938155=BTC-USD271=0.0000000060=20250411-01:50:21.61414058=FILLED10=042
20250411-01:50:22.216874000 : 8=FIXT.1.19=27735=X49=Coinbase56=24ab46f784d1b20db435b852086e325034=1150=TEST52=20250411-01:50:22.101375369=2262=83671f6c-e7d6-4990-a146-dc86a70aefdc268=1279=0269=083=159756938255=BTC-USD29004=2.208895519560=20250411-01:50:22.10002440=137=91c7e4f8-3185-4d23-ae8e-653275f3a09610=003
20250411-01:50:22.217499000 : 8=FIXT.1.19=32535=X49=Coinbase56=24ab46f784d1b20db435b852086e325034=1250=TEST52=20250411-01:50:22.101384369=2262=83671f6c-e7d6-4990-a146-dc86a70aefdc268=1279=0269=2278=c5b88ea9-605d-4595-ac52-f7c3f08523ba83=159756938355=BTC-USD270=3.55271=0.6222240960=20250411-01:50:22.10002437=91c7e4f8-3185-4d23-ae8e-653275f3a0965797=110=150
20250411-01:50:22.217672000 : 8=FIXT.1.19=26435=X49=Coinbase56=24ab46f784d1b20db435b852086e325034=1350=TEST52=20250411-01:50:22.101387369=2262=83671f6c-e7d6-4990-a146-dc86a70aefdc268=1279=2269=0278=91c7e4f8-3185-4d23-ae8e-653275f3a09683=159756938455=BTC-USD60=20250411-01:50:22.10002458=FILLED10=022
20250411-01:50:22.248994000 : 8=FIXT.1.19=27335=X49=Coinbase56=24ab46f784d1b20db435b852086e325034=1450=TEST52=20250411-01:50:22.131574369=2262=83671f6c-e7d6-4990-a146-dc86a70aefdc268=1279=0269=183=159756938555=BTC-USD271=0.6232294660=20250411-01:50:22.13006640=137=8b7b42c8-9f5a-4dd1-b977-9305730bf73210=103
20250411-01:50:22.249162000 : 8=FIXT.1.19=32535=X49=Coinbase56=24ab46f784d1b20db435b852086e325034=1550=TEST52=20250411-01:50:22.131584369=2262=83671f6c-e7d6-4990-a146-dc86a70aefdc268=1279=0269=2278=4d60a78e-b39b-420e-b830-bc0f3f4fdde283=159756938655=BTC-USD270=3.53271=0.6232294660=20250411-01:50:22.13006637=8b7b42c8-9f5a-4dd1-b977-9305730bf7325797=210=093
20250411-01:50:22.249306000 : 8=FIXT.1.19=27935=X49=Coinbase56=24ab46f784d1b20db435b852086e325034=1650=TEST52=20250411-01:50:22.131587369=2262=83671f6c-e7d6-4990-a146-dc86a70aefdc268=1279=2269=1278=8b7b42c8-9f5a-4dd1-b977-9305730bf73283=159756938755=BTC-USD271=0.0000000060=20250411-01:50:22.13006658=FILLED10=020
20250411-01:50:22.446719000 : 8=FIXT.1.19=28235=X49=Coinbase56=24ab46f784d1b20db435b852086e325034=1750=TEST52=20250411-01:50:22.331032369=2262=83671f6c-e7d6-4990-a146-dc86a70aefdc268=1279=0269=083=159756938855=BTC-USD270=3.73271=0.6232294660=20250411-01:50:22.33024740=237=73097bb1-7f41-419e-ab0b-1c3defe7c55710=138
20250411-01:50:22.447698000 : 8=FIXT.1.19=32535=X49=Coinbase56=24ab46f784d1b20db435b852086e325034=1850=TEST52=20250411-01:50:22.331217369=2262=83671f6c-e7d6-4990-a146-dc86a70aefdc268=1279=0269=2278=c5b88ea9-605d-4595-ac52-f7c3f08523ba83=159756938955=BTC-USD270=3.55271=0.6232294660=20250411-01:50:22.33024737=73097bb1-7f41-419e-ab0b-1c3defe7c5575797=110=099
20250411-01:50:22.447902000 : 8=FIXT.1.19=28835=X49=Coinbase56=24ab46f784d1b20db435b852086e325034=1950=TEST52=20250411-01:50:22.331223369=2262=83671f6c-e7d6-4990-a146-dc86a70aefdc268=1279=2269=0278=73097bb1-7f41-419e-ab0b-1c3defe7c55783=159756939055=BTC-USD270=3.73271=0.0000000060=20250411-01:50:22.33024758=FILLED10=043
20250411-01:50:22.558511000 : 8=FIXT.1.19=28235=X49=Coinbase56=24ab46f784d1b20db435b852086e325034=2050=TEST52=20250411-01:50:22.443423369=2262=83671f6c-e7d6-4990-a146-dc86a70aefdc268=1279=0269=183=159756939155=BTC-USD270=3.31271=0.6232294660=20250411-01:50:22.44205540=237=4cff4e02-0565-43c8-8e96-865c225b4ca010=248
20250411-01:50:22.562350000 : 8=FIXT.1.19=32535=X49=Coinbase56=24ab46f784d1b20db435b852086e325034=2150=TEST52=20250411-01:50:22.443435369=2262=83671f6c-e7d6-4990-a146-dc86a70aefdc268=1279=0269=2278=4d60a78e-b39b-420e-b830-bc0f3f4fdde283=159756939255=BTC-USD270=3.53271=0.6232294660=20250411-01:50:22.44205537=4cff4e02-0565-43c8-8e96-865c225b4ca05797=210=083
20250411-01:50:22.562468000 : 8=FIXT.1.19=28835=X49=Coinbase56=24ab46f784d1b20db435b852086e325034=2250=TEST52=20250411-01:50:22.443526369=2262=83671f6c-e7d6-4990-a146-dc86a70aefdc268=1279=2269=1278=4cff4e02-0565-43c8-8e96-865c225b4ca083=159756939355=BTC-USD270=3.31271=0.0000000060=20250411-01:50:22.44205558=FILLED10=164
20250411-01:50:22.562566000 : 8=FIXT.1.19=28135=X49=Coinbase56=24ab46f784d1b20db435b852086e325034=2350=TEST52=20250411-01:50:22.443532369=2262=83671f6c-e7d6-4990-a146-dc86a70aefdc268=1279=0269=183=159756939455=BTC-USD270=3.2271=0.6232294660=20250411-01:50:22.44205540=237=476653f6-89e6-4760-b799-61bfb7b43b3510=133
20250411-01:50:22.562660000 : 8=FIXT.1.19=32535=X49=Coinbase56=24ab46f784d1b20db435b852086e325034=2450=TEST52=20250411-01:50:22.443535369=2262=83671f6c-e7d6-4990-a146-dc86a70aefdc268=1279=0269=2278=4d60a78e-b39b-420e-b830-bc0f3f4fdde283=159756939555=BTC-USD270=3.53271=0.6232294660=20250411-01:50:22.44205537=476653f6-89e6-4760-b799-61bfb7b43b355797=210=019
20250411-01:50:22.562782000 : 8=FIXT.1.19=28735=X49=Coinbase56=24ab46f784d1b20db435b852086e325034=2550=TEST52=20250411-01:50:22.443538369=2262=83671f6c-e7d6-4990-a146-dc86a70aefdc268=1279=2269=1278=476653f6-89e6-4760-b799-61bfb7b43b3583=159756939655=BTC-USD270=3.2271=0.0000000060=20250411-01:50:22.44205558=FILLED10=051
20250411-01:50:22.620290000 : 8=FIXT.1.19=27735=X49=Coinbase56=24ab46f784d1b20db435b852086e325034=2650=TEST52=20250411-01:50:22.504210369=2262=83671f6c-e7d6-4990-a146-dc86a70aefdc268=1279=0269=083=159756939755=BTC-USD29004=2.208895519560=20250411-01:50:22.50073640=137=3ae84ff2-5774-48b8-be96-02a7bf879efc10=229
20250411-01:50:22.620801000 : 8=FIXT.1.19=32535=X49=Coinbase56=24ab46f784d1b20db435b852086e325034=2750=TEST52=20250411-01:50:22.504219369=2262=83671f6c-e7d6-4990-a146-dc86a70aefdc268=1279=0269=2278=c5b88ea9-605d-4595-ac52-f7c3f08523ba83=159756939855=BTC-USD270=3.55271=0.6222240960=20250411-01:50:22.50073637=3ae84ff2-5774-48b8-be96-02a7bf879efc5797=110=129
20250411-01:50:22.620992000 : 8=FIXT.1.19=26435=X49=Coinbase56=24ab46f784d1b20db435b852086e325034=2850=TEST52=20250411-01:50:22.504222369=2262=83671f6c-e7d6-4990-a146-dc86a70aefdc268=1279=2269=0278=3ae84ff2-5774-48b8-be96-02a7bf879efc83=159756939955=BTC-USD60=20250411-01:50:22.50073658=FILLED10=248
20250411-01:50:22.645424000 : 8=FIXT.1.19=27335=X49=Coinbase56=24ab46f784d1b20db435b852086e325034=2950=TEST52=20250411-01:50:22.530692369=2262=83671f6c-e7d6-4990-a146-dc86a70aefdc268=1279=0269=183=159756940055=BTC-USD271=0.6232294660=20250411-01:50:22.52908140=137=6acd3eed-bbdd-48a4-ae88-b9b33d2257e010=174
20250411-01:50:22.645920000 : 8=FIXT.1.19=32535=X49=Coinbase56=24ab46f784d1b20db435b852086e325034=3050=TEST52=20250411-01:50:22.530700369=2262=83671f6c-e7d6-4990-a146-dc86a70aefdc268=1279=0269=2278=4d60a78e-b39b-420e-b830-bc0f3f4fdde283=159756940155=BTC-USD270=3.53271=0.6232294660=20250411-01:50:22.52908137=6acd3eed-bbdd-48a4-ae88-b9b33d2257e05797=210=144
20250411-01:50:22.646048000 : 8=FIXT.1.19=27935=X49=Coinbase56=24ab46f784d1b20db435b852086e325034=3150=TEST52=20250411-01:50:22.530722369=2262=83671f6c-e7d6-4990-a146-dc86a70aefdc268=1279=2269=1278=6acd3eed-bbdd-48a4-ae88-b9b33d2257e083=159756940255=BTC-USD271=0.0000000060=20250411-01:50:22.52908158=FILLED10=072
20250411-01:50:22.904431000 : 8=FIXT.1.19=28235=X49=Coinbase56=24ab46f784d1b20db435b852086e325034=3250=TEST52=20250411-01:50:22.787256369=2262=83671f6c-e7d6-4990-a146-dc86a70aefdc268=1279=0269=183=159756940355=BTC-USD270=3.21271=0.6232294660=20250411-01:50:22.78575840=237=00c80d40-48b2-42b5-a290-a40115c4733b10=144
20250411-01:50:22.908988000 : 8=FIXT.1.19=32535=X49=Coinbase56=24ab46f784d1b20db435b852086e325034=3350=TEST52=20250411-01:50:22.787262369=2262=83671f6c-e7d6-4990-a146-dc86a70aefdc268=1279=0269=2278=4d60a78e-b39b-420e-b830-bc0f3f4fdde283=159756940455=BTC-USD270=3.53271=0.6232294660=20250411-01:50:22.78575837=00c80d40-48b2-42b5-a290-a40115c4733b5797=210=230
20250411-01:50:22.913441000 : 8=FIXT.1.19=28835=X49=Coinbase56=24ab46f784d1b20db435b852086e325034=3450=TEST52=20250411-01:50:22.787264369=2262=83671f6c-e7d6-4990-a146-dc86a70aefdc268=1279=2269=1278=00c80d40-48b2-42b5-a290-a40115c4733b83=159756940555=BTC-USD270=3.21271=0.0000000060=20250411-01:50:22.78575858=FILLED10=055
20250411-01:50:22.958405000 : 8=FIXT.1.19=28235=X49=Coinbase56=24ab46f784d1b20db435b852086e325034=3550=TEST52=20250411-01:50:22.842345369=2262=83671f6c-e7d6-4990-a146-dc86a70aefdc268=1279=0269=083=159756940655=BTC-USD270=3.79271=0.6232294660=20250411-01:50:22.84044540=237=6ff40680-13f7-4507-bd47-c39968b43fd210=237
20250411-01:50:22.958554000 : 8=FIXT.1.19=32535=X49=Coinbase56=24ab46f784d1b20db435b852086e325034=3650=TEST52=20250411-01:50:22.842351369=2262=83671f6c-e7d6-4990-a146-dc86a70aefdc268=1279=0269=2278=c5b88ea9-605d-4595-ac52-f7c3f08523ba83=159756940755=BTC-USD270=3.55271=0.6232294660=20250411-01:50:22.84044537=6ff40680-13f7-4507-bd47-c39968b43fd25797=110=184
20250411-01:50:22.958734000 : 8=FIXT.1.19=28835=X49=Coinbase56=24ab46f784d1b20db435b852086e325034=3750=TEST52=20250411-01:50:22.842354369=2262=83671f6c-e7d6-4990-a146-dc86a70aefdc268=1279=2269=0278=6ff40680-13f7-4507-bd47-c39968b43fd283=159756940855=BTC-USD270=3.79271=0.0000000060=20250411-01:50:22.84044558=FILLED10=149
20250411-01:50:23.589984000 : 8=FIXT.1.19=28235=X49=Coinbase56=24ab46f784d1b20db435b852086e325034=3850=TEST52=20250411-01:50:23.473634369=2262=83671f6c-e7d6-4990-a146-dc86a70aefdc268=1279=0269=183=159756940955=BTC-USD270=3.36271=0.6197183160=20250411-01:50:23.47245940=237=b9216257-1138-4415-8663-fab3a4c3ee9810=189
20250411-01:50:23.590615000 : 8=FIXT.1.19=32535=X49=Coinbase56=24ab46f784d1b20db435b852086e325034=3950=TEST52=20250411-01:50:23.473692369=2262=83671f6c-e7d6-4990-a146-dc86a70aefdc268=1279=0269=2278=4d60a78e-b39b-420e-b830-bc0f3f4fdde283=159756941055=BTC-USD270=3.53271=0.6197183160=20250411-01:50:23.47245937=b9216257-1138-4415-8663-fab3a4c3ee985797=210=011
20250411-01:50:23.590795000 : 8=FIXT.1.19=28835=X49=Coinbase56=24ab46f784d1b20db435b852086e325034=4050=TEST52=20250411-01:50:23.473894369=2262=83671f6c-e7d6-4990-a146-dc86a70aefdc268=1279=2269=1278=b9216257-1138-4415-8663-fab3a4c3ee9883=159756941155=BTC-USD270=3.36271=0.0000000060=20250411-01:50:23.47245958=FILLED10=089
20250411-01:50:23.590983000 : 8=FIXT.1.19=28235=X49=Coinbase56=24ab46f784d1b20db435b852086e325034=4150=TEST52=20250411-01:50:23.473896369=2262=83671f6c-e7d6-4990-a146-dc86a70aefdc268=1279=0269=183=159756941255=BTC-USD270=3.26271=0.6197183160=20250411-01:50:23.47245940=237=cb8a720e-c0c0-4b18-83e2-2acbc924fadb10=030
20250411-01:50:23.591141000 : 8=FIXT.1.19=32535=X49=Coinbase56=24ab46f784d1b20db435b852086e325034=4250=TEST52=20250411-01:50:23.473905369=2262=83671f6c-e7d6-4990-a146-dc86a70aefdc268=1279=0269=2278=4d60a78e-b39b-420e-b830-bc0f3f4fdde283=159756941355=BTC-USD270=3.53271=0.6197183160=20250411-01:50:23.47245937=cb8a720e-c0c0-4b18-83e2-2acbc924fadb5797=210=105
20250411-01:50:23.592756000 : 8=FIXT.1.19=28835=X49=Coinbase56=24ab46f784d1b20db435b852086e325034=4350=TEST52=20250411-01:50:23.473907369=2262=83671f6c-e7d6-4990-a146-dc86a70aefdc268=1279=2269=1278=cb8a720e-c0c0-4b18-83e2-2acbc924fadb83=159756941455=BTC-USD270=3.26271=0.0000000060=20250411-01:50:23.47245958=FILLED10=189
20250411-01:50:23.701194000 : 8=FIXT.1.19=28235=X49=Coinbase56=24ab46f784d1b20db435b852086e325034=4450=TEST52=20250411-01:50:23.586418369=2262=83671f6c-e7d6-4990-a146-dc86a70aefdc268=1279=0269=083=159756941555=BTC-USD270=3.75271=0.6197183160=20250411-01:50:23.58463440=237=66a788db-9e2a-4aef-b9c1-75114e24aecd10=011
20250411-01:50:23.701609000 : 8=FIXT.1.19=32535=X49=Coinbase56=24ab46f784d1b20db435b852086e325034=4550=TEST52=20250411-01:50:23.586434369=2262=83671f6c-e7d6-4990-a146-dc86a70aefdc268=1279=0269=2278=c5b88ea9-605d-4595-ac52-f7c3f08523ba83=159756941655=BTC-USD270=3.55271=0.6197183160=20250411-01:50:23.58463437=66a788db-9e2a-4aef-b9c1-75114e24aecd5797=110=219
20250411-01:50:23.701781000 : 8=FIXT.1.19=28835=X49=Coinbase56=24ab46f784d1b20db435b852086e325034=4650=TEST52=20250411-01:50:23.586522369=2262=83671f6c-e7d6-4990-a146-dc86a70aefdc268=1279=2269=0278=66a788db-9e2a-4aef-b9c1-75114e24aecd83=159756941755=BTC-USD270=3.75271=0.0000000060=20250411-01:50:23.58463458=FILLED10=173
20250411-01:50:23.701951000 : 8=FIXT.1.19=28235=X49=Coinbase56=24ab46f784d1b20db435b852086e325034=4750=TEST52=20250411-01:50:23.586524369=2262=83671f6c-e7d6-4990-a146-dc86a70aefdc268=1279=0269=083=159756941855=BTC-USD270=3.74271=0.6197183160=20250411-01:50:23.58463440=237=53a1c820-965a-412b-9968-bdf6c6294dbb10=081
20250411-01:50:23.702109000 : 8=FIXT.1.19=32535=X49=Coinbase56=24ab46f784d1b20db435b852086e325034=4850=TEST52=20250411-01:50:23.586529369=2262=83671f6c-e7d6-4990-a146-dc86a70aefdc268=1279=0269=2278=c5b88ea9-605d-4595-ac52-f7c3f08523ba83=159756941955=BTC-USD270=3.55271=0.6197183160=20250411-01:50:23.58463437=53a1c820-965a-412b-9968-bdf6c6294dbb5797=110=041
20250411-01:50:23.702705000 : 8=FIXT.1.19=28835=X49=Coinbase56=24ab46f784d1b20db435b852086e325034=4950=TEST52=20250411-01:50:23.586569369=2262=83671f6c-e7d6-4990-a146-dc86a70aefdc268=1279=2269=0278=53a1c820-965a-412b-9968-bdf6c6294dbb83=159756942055=BTC-USD270=3.74271=0.0000000060=20250411-01:50:23.58463458=FILLED10=247
20250411-01:50:24.046042000 : 8=FIXT.1.19=28135=X49=Coinbase56=24ab46f784d1b20db435b852086e325034=5050=TEST52=20250411-01:50:23.930038369=2262=83671f6c-e7d6-4990-a146-dc86a70aefdc268=1279=0269=183=159756942155=BTC-USD270=3.3271=0.6197183160=20250411-01:50:23.92870640=237=d89721db-fc53-4687-8ddd-ec267fdfa74010=167
20250411-01:50:24.046987000 : 8=FIXT.1.19=32535=X49=Coinbase56=24ab46f784d1b20db435b852086e325034=5150=TEST52=20250411-01:50:23.930048369=2262=83671f6c-e7d6-4990-a146-dc86a70aefdc268=1279=0269=2278=4d60a78e-b39b-420e-b830-bc0f3f4fdde283=159756942255=BTC-USD270=3.53271=0.6197183160=20250411-01:50:23.92870637=d89721db-fc53-4687-8ddd-ec267fdfa7405797=210=050
20250411-01:50:24.048261000 : 8=FIXT.1.19=28735=X49=Coinbase56=24ab46f784d1b20db435b852086e325034=5250=TEST52=20250411-01:50:23.930105369=2262=83671f6c-e7d6-4990-a146-dc86a70aefdc268=1279=2269=1278=d89721db-fc53-4687-8ddd-ec267fdfa74083=159756942355=BTC-USD270=3.3271=0.0000000060=20250411-01:50:23.92870658=FILLED10=072
20250411-01:50:24.098613000 : 8=FIXT.1.19=28235=X49=Coinbase56=24ab46f784d1b20db435b852086e325034=5350=TEST52=20250411-01:50:23.984072369=2262=83671f6c-e7d6-4990-a146-dc86a70aefdc268=1279=0269=083=159756942455=BTC-USD270=3.89271=0.6197183160=20250411-01:50:23.98288340=237=22c5ba1f-7348-43d1-9ff7-3b79fbca61aa10=224
20250411-01:50:24.098929000 : 8=FIXT.1.19=32535=X49=Coinbase56=24ab46f784d1b20db435b852086e325034=5450=TEST52=20250411-01:50:23.984157369=2262=83671f6c-e7d6-4990-a146-dc86a70aefdc268=1279=0269=2278=c5b88ea9-605d-4595-ac52-f7c3f08523ba83=159756942555=BTC-USD270=3.55271=0.6197183160=20250411-01:50:23.98288337=22c5ba1f-7348-43d1-9ff7-3b79fbca61aa5797=110=177
20250411-01:50:24.099145000 : 8=FIXT.1.19=28835=X49=Coinbase56=24ab46f784d1b20db435b852086e325034=5550=TEST52=20250411-01:50:23.984167369=2262=83671f6c-e7d6-4990-a146-dc86a70aefdc268=1279=2269=0278=22c5ba1f-7348-43d1-9ff7-3b79fbca61aa83=159756942655=BTC-USD270=3.89271=0.0000000060=20250411-01:50:23.98288358=FILLED10=139
20250411-01:50:24.276279000 : 8=FIXT.1.19=27735=X49=Coinbase56=24ab46f784d1b20db435b852086e325034=5650=TEST52=20250411-01:50:24.158264369=2262=83671f6c-e7d6-4990-a146-dc86a70aefdc268=1279=0269=083=159756942755=BTC-USD29004=2.208895519560=20250411-01:50:24.15686240=137=ae988b73-f7cd-41f7-80d7-9757c58219ea10=159
20250411-01:50:24.276671000 : 8=FIXT.1.19=32535=X49=Coinbase56=24ab46f784d1b20db435b852086e325034=5750=TEST52=20250411-01:50:24.158274369=2262=83671f6c-e7d6-4990-a146-dc86a70aefdc268=1279=0269=2278=c5b88ea9-605d-4595-ac52-f7c3f08523ba83=159756942855=BTC-USD270=3.55271=0.6222240960=20250411-01:50:24.15686237=ae988b73-f7cd-41f7-80d7-9757c58219ea5797=110=051
20250411-01:50:24.276874000 : 8=FIXT.1.19=26435=X49=Coinbase56=24ab46f784d1b20db435b852086e325034=5850=TEST52=20250411-01:50:24.158288369=2262=83671f6c-e7d6-4990-a146-dc86a70aefdc268=1279=2269=0278=ae988b73-f7cd-41f7-80d7-9757c58219ea83=159756942955=BTC-USD60=20250411-01:50:24.15686258=FILLED10=181
20250411-01:50:24.303809000 : 8=FIXT.1.19=27335=X49=Coinbase56=24ab46f784d1b20db435b852086e325034=5950=TEST52=20250411-01:50:24.187784369=2262=83671f6c-e7d6-4990-a146-dc86a70aefdc268=1279=0269=183=159756943055=BTC-USD271=0.6197183160=20250411-01:50:24.18605440=137=4531eb39-0b2d-499b-b9d1-911bc714402a10=104
20250411-01:50:24.303975000 : 8=FIXT.1.19=32535=X49=Coinbase56=24ab46f784d1b20db435b852086e325034=6050=TEST52=20250411-01:50:24.187794369=2262=83671f6c-e7d6-4990-a146-dc86a70aefdc268=1279=0269=2278=4d60a78e-b39b-420e-b830-bc0f3f4fdde283=159756943155=BTC-USD270=3.53271=0.6197183160=20250411-01:50:24.18605437=4531eb39-0b2d-499b-b9d1-911bc714402a5797=210=085
20250411-01:50:24.304109000 : 8=FIXT.1.19=27935=X49=Coinbase56=24ab46f784d1b20db435b852086e325034=6150=TEST52=20250411-01:50:24.187798369=2262=83671f6c-e7d6-4990-a146-dc86a70aefdc268=1279=2269=1278=4531eb39-0b2d-499b-b9d1-911bc714402a83=159756943255=BTC-USD271=0.0000000060=20250411-01:50:24.18605458=FILLED10=011
20250411-01:50:24.559089000 : 8=FIXT.1.19=27735=X49=Coinbase56=24ab46f784d1b20db435b852086e325034=6250=TEST52=20250411-01:50:24.444217369=2262=83671f6c-e7d6-4990-a146-dc86a70aefdc268=1279=0269=083=159756943355=BTC-USD29004=2.208895519560=20250411-01:50:24.44301140=137=57ec9d3d-e05f-4a4b-9eb9-bdd3b5b2c76810=096
20250411-01:50:24.559726000 : 8=FIXT.1.19=32535=X49=Coinbase56=24ab46f784d1b20db435b852086e325034=6350=TEST52=20250411-01:50:24.444284369=2262=83671f6c-e7d6-4990-a146-dc86a70aefdc268=1279=0269=2278=c5b88ea9-605d-4595-ac52-f7c3f08523ba83=159756943455=BTC-USD270=3.55271=0.6222240960=20250411-01:50:24.44301137=57ec9d3d-e05f-4a4b-9eb9-bdd3b5b2c7685797=110=247
20250411-01:50:24.559999000 : 8=FIXT.1.19=26435=X49=Coinbase56=24ab46f784d1b20db435b852086e325034=6450=TEST52=20250411-01:50:24.444296369=2262=83671f6c-e7d6-4990-a146-dc86a70aefdc268=1279=2269=0278=57ec9d3d-e05f-4a4b-9eb9-bdd3b5b2c76883=159756943555=BTC-USD60=20250411-01:50:24.44301158=FILLED10=119
20250411-01:50:24.588599000 : 8=FIXT.1.19=27335=X49=Coinbase56=24ab46f784d1b20db435b852086e325034=6550=TEST52=20250411-01:50:24.472880369=2262=83671f6c-e7d6-4990-a146-dc86a70aefdc268=1279=0269=183=159756943655=BTC-USD271=0.6232294660=20250411-01:50:24.47124040=137=257d5c2b-58fc-4577-84d1-59fe0a636f9610=132
20250411-01:50:24.589151000 : 8=FIXT.1.19=32535=X49=Coinbase56=24ab46f784d1b20db435b852086e325034=6650=TEST52=20250411-01:50:24.472889369=2262=83671f6c-e7d6-4990-a146-dc86a70aefdc268=1279=0269=2278=4d60a78e-b39b-420e-b830-bc0f3f4fdde283=159756943755=BTC-USD270=3.53271=0.6232294660=20250411-01:50:24.47124037=257d5c2b-58fc-4577-84d1-59fe0a636f965797=210=130
20250411-01:50:24.589340000 : 8=FIXT.1.19=27935=X49=Coinbase56=24ab46f784d1b20db435b852086e325034=6750=TEST52=20250411-01:50:24.472922369=2262=83671f6c-e7d6-4990-a146-dc86a70aefdc268=1279=2269=1278=257d5c2b-58fc-4577-84d1-59fe0a636f9683=159756943855=BTC-USD271=0.0000000060=20250411-01:50:24.47124058=FILLED10=042
20250411-01:50:24.616147000 : 8=FIXT.1.19=27735=X49=Coinbase56=24ab46f784d1b20db435b852086e325034=6850=TEST52=20250411-01:50:24.501262369=2262=83671f6c-e7d6-4990-a146-dc86a70aefdc268=1279=0269=083=159756943955=BTC-USD29004=2.208895519560=20250411-01:50:24.49943840=137=1bddb020-79ca-43c5-98aa-e43483ab9dc010=005
20250411-01:50:24.616541000 : 8=FIXT.1.19=32535=X49=Coinbase56=24ab46f784d1b20db435b852086e325034=6950=TEST52=20250411-01:50:24.501268369=2262=83671f6c-e7d6-4990-a146-dc86a70aefdc268=1279=0269=2278=c5b88ea9-605d-4595-ac52-f7c3f08523ba83=159756944055=BTC-USD270=3.55271=0.6222240960=20250411-01:50:24.49943837=1bddb020-79ca-43c5-98aa-e43483ab9dc05797=110=149
20250411-01:50:24.616728000 : 8=FIXT.1.19=26435=X49=Coinbase56=24ab46f784d1b20db435b852086e325034=7050=TEST52=20250411-01:50:24.501272369=2262=83671f6c-e7d6-4990-a146-dc86a70aefdc268=1279=2269=0278=1bddb020-79ca-43c5-98aa-e43483ab9dc083=159756944155=BTC-USD60=20250411-01:50:24.49943858=FILLED10=004
20250411-01:50:24.645387000 : 8=FIXT.1.19=27335=X49=Coinbase56=24ab46f784d1b20db435b852086e325034=7150=TEST52=20250411-01:50:24.529947369=2262=83671f6c-e7d6-4990-a146-dc86a70aefdc268=1279=0269=183=159756944255=BTC-USD271=0.6197183160=20250411-01:50:24.52814040=137=ad9718ce-04b7-4973-bdc7-b963d8469c0510=180
20250411-01:50:24.645663000 : 8=FIXT.1.19=32535=X49=Coinbase56=24ab46f784d1b20db435b852086e325034=7250=TEST52=20250411-01:50:24.530042369=2262=83671f6c-e7d6-4990-a146-dc86a70aefdc268=1279=0269=2278=4d60a78e-b39b-420e-b830-bc0f3f4fdde283=159756944355=BTC-USD270=3.53271=0.6197183160=20250411-01:50:24.52814037=ad9718ce-04b7-4973-bdc7-b963d8469c055797=210=147
20250411-01:50:24.645857000 : 8=FIXT.1.19=27935=X49=Coinbase56=24ab46f784d1b20db435b852086e325034=7350=TEST52=20250411-01:50:24.530046369=2262=83671f6c-e7d6-4990-a146-dc86a70aefdc268=1279=2269=1278=ad9718ce-04b7-4973-bdc7-b963d8469c0583=159756944455=BTC-USD271=0.0000000060=20250411-01:50:24.52814058=FILLED10=073
20250411-01:50:24.845266000 : 8=FIXT.1.19=28135=X49=Coinbase56=24ab46f784d1b20db435b852086e325034=7450=TEST52=20250411-01:50:24.730342369=2262=83671f6c-e7d6-4990-a146-dc86a70aefdc268=1279=0269=183=159756944555=BTC-USD270=3.3271=0.6232294660=20250411-01:50:24.72830140=237=fdea5ffc-93c6-43d4-919d-7661a883cfbe10=213
20250411-01:50:24.845764000 : 8=FIXT.1.19=32535=X49=Coinbase56=24ab46f784d1b20db435b852086e325034=7550=TEST52=20250411-01:50:24.730474369=2262=83671f6c-e7d6-4990-a146-dc86a70aefdc268=1279=0269=2278=4d60a78e-b39b-420e-b830-bc0f3f4fdde283=159756944655=BTC-USD270=3.53271=0.6232294660=20250411-01:50:24.72830137=fdea5ffc-93c6-43d4-919d-7661a883cfbe5797=210=101
20250411-01:50:24.845925000 : 8=FIXT.1.19=28735=X49=Coinbase56=24ab46f784d1b20db435b852086e325034=7650=TEST52=20250411-01:50:24.730477369=2262=83671f6c-e7d6-4990-a146-dc86a70aefdc268=1279=2269=1278=fdea5ffc-93c6-43d4-919d-7661a883cfbe83=159756944755=BTC-USD270=3.3271=0.0000000060=20250411-01:50:24.72830158=FILLED10=134
20250411-01:50:24.899514000 : 8=FIXT.1.19=28135=X49=Coinbase56=24ab46f784d1b20db435b852086e325034=7750=TEST52=20250411-01:50:24.784186369=2262=83671f6c-e7d6-4990-a146-dc86a70aefdc268=1279=0269=083=159756944855=BTC-USD270=3.8271=0.6232294660=20250411-01:50:24.78309440=237=a31d13b0-c98b-42c2-b0b0-e7175ff2bdd010=150
20250411-01:50:24.899878000 : 8=FIXT.1.19=32535=X49=Coinbase56=24ab46f784d1b20db435b852086e325034=7850=TEST52=20250411-01:50:24.784201369=2262=83671f6c-e7d6-4990-a146-dc86a70aefdc268=1279=0269=2278=c5b88ea9-605d-4595-ac52-f7c3f08523ba83=159756944955=BTC-USD270=3.55271=0.6232294660=20250411-01:50:24.78309437=a31d13b0-c98b-42c2-b0b0-e7175ff2bdd05797=110=145
20250411-01:50:24.900049000 : 8=FIXT.1.19=28735=X49=Coinbase56=24ab46f784d1b20db435b852086e325034=7950=TEST52=20250411-01:50:24.784240369=2262=83671f6c-e7d6-4990-a146-dc86a70aefdc268=1279=2269=0278=a31d13b0-c98b-42c2-b0b0-e7175ff2bdd083=159756945055=BTC-USD270=3.8271=0.0000000060=20250411-01:50:24.78309458=FILLED10=044
20250411-01:50:24.986252000 : 8=FIXT.1.19=28235=X49=Coinbase56=24ab46f784d1b20db435b852086e325034=8050=TEST52=20250411-01:50:24.871487369=2262=83671f6c-e7d6-4990-a146-dc86a70aefdc268=1279=0269=183=159756945155=BTC-USD270=3.56271=0.6197183160=20250411-01:50:24.86953940=237=f2ed167a-0d68-4cd6-aa9a-f60d28c06d9c10=024
20250411-01:50:24.986823000 : 8=FIXT.1.19=27835=X49=Coinbase56=24ab46f784d1b20db435b852086e325034=8150=TEST52=20250411-01:50:24.871494369=2262=83671f6c-e7d6-4990-a146-dc86a70aefdc268=1279=0269=1278=f2ed167a-0d68-4cd6-aa9a-f60d28c06d9c83=159756945255=BTC-USD270=3.56271=0.6197183160=20250411-01:50:24.86953910=128
20250411-01:50:24.986994000 : 8=FIXT.1.19=28235=X49=Coinbase56=24ab46f784d1b20db435b852086e325034=8250=TEST52=20250411-01:50:24.871561369=2262=83671f6c-e7d6-4990-a146-dc86a70aefdc268=1279=0269=183=159756945355=BTC-USD270=3.61271=0.6197183160=20250411-01:50:24.86953940=237=cf1b3334-372f-4087-86ba-5c48297917a710=205
20250411-01:50:24.987144000 : 8=FIXT.1.19=27835=X49=Coinbase56=24ab46f784d1b20db435b852086e325034=8350=TEST52=20250411-01:50:24.871563369=2262=83671f6c-e7d6-4990-a146-dc86a70aefdc268=1279=0269=1278=cf1b3334-372f-4087-86ba-5c48297917a783=159756945455=BTC-USD270=3.61271=0.6197183160=20250411-01:50:24.86953910=057
20250411-01:50:25.361091000 : 8=FIXT.1.19=27735=X49=Coinbase56=24ab46f784d1b20db435b852086e325034=8450=TEST52=20250411-01:50:25.244192369=2262=83671f6c-e7d6-4990-a146-dc86a70aefdc268=1279=0269=083=159756945555=BTC-USD29004=2.208895519560=20250411-01:50:25.24303240=137=21ddb54d-7b66-4d81-9537-094cd6a97bdf10=174
20250411-01:50:25.361835000 : 8=FIXT.1.19=32535=X49=Coinbase56=24ab46f784d1b20db435b852086e325034=8550=TEST52=20250411-01:50:25.244199369=2262=83671f6c-e7d6-4990-a146-dc86a70aefdc268=1279=0269=2278=c5b88ea9-605d-4595-ac52-f7c3f08523ba83=159756945655=BTC-USD270=3.55271=0.6222240960=20250411-01:50:25.24303237=21ddb54d-7b66-4d81-9537-094cd6a97bdf5797=110=072
20250411-01:50:25.362055000 : 8=FIXT.1.19=26435=X49=Coinbase56=24ab46f784d1b20db435b852086e325034=8650=TEST52=20250411-01:50:25.244202369=2262=83671f6c-e7d6-4990-a146-dc86a70aefdc268=1279=2269=0278=21ddb54d-7b66-4d81-9537-094cd6a97bdf83=159756945755=BTC-USD60=20250411-01:50:25.24303258=FILLED10=182
20250411-01:50:25.388488000 : 8=FIXT.1.19=27335=X49=Coinbase56=24ab46f784d1b20db435b852086e325034=8750=TEST52=20250411-01:50:25.273412369=2262=83671f6c-e7d6-4990-a146-dc86a70aefdc268=1279=0269=183=159756945855=BTC-USD271=0.6197183160=20250411-01:50:25.27133640=137=47592f89-bedb-4d15-8717-f0810586e34110=035
20250411-01:50:25.388863000 : 8=FIXT.1.19=32535=X49=Coinbase56=24ab46f784d1b20db435b852086e325034=8850=TEST52=20250411-01:50:25.273419369=2262=83671f6c-e7d6-4990-a146-dc86a70aefdc268=1279=0269=2278=4d60a78e-b39b-420e-b830-bc0f3f4fdde283=159756945955=BTC-USD270=3.53271=0.6197183160=20250411-01:50:25.27133637=47592f89-bedb-4d15-8717-f0810586e3415797=210=031
20250411-01:50:25.389054000 : 8=FIXT.1.19=27935=X49=Coinbase56=24ab46f784d1b20db435b852086e325034=8950=TEST52=20250411-01:50:25.273423369=2262=83671f6c-e7d6-4990-a146-dc86a70aefdc268=1279=2269=1278=47592f89-bedb-4d15-8717-f0810586e34183=159756946055=BTC-USD271=0.0000000060=20250411-01:50:25.27133658=FILLED10=195
20250411-01:50:25.476540000 : 8=FIXT.1.19=27735=X49=Coinbase56=24ab46f784d1b20db435b852086e325034=9050=TEST52=20250411-01:50:25.360930369=2262=83671f6c-e7d6-4990-a146-dc86a70aefdc268=1279=0269=083=159756946155=BTC-USD29004=2.208895519560=20250411-01:50:25.35943340=137=d9ba8062-c393-403a-9201-40c4babddcdb10=236
20250411-01:50:25.477059000 : 8=FIXT.1.19=32535=X49=Coinbase56=24ab46f784d1b20db435b852086e325034=9150=TEST52=20250411-01:50:25.360941369=2262=83671f6c-e7d6-4990-a146-dc86a70aefdc268=1279=0269=2278=c5b88ea9-605d-4595-ac52-f7c3f08523ba83=159756946255=BTC-USD270=3.55271=0.6222240960=20250411-01:50:25.35943337=d9ba8062-c393-403a-9201-40c4babddcdb5797=110=129
20250411-01:50:25.477343000 : 8=FIXT.1.19=26435=X49=Coinbase56=24ab46f784d1b20db435b852086e325034=9250=TEST52=20250411-01:50:25.360944369=2262=83671f6c-e7d6-4990-a146-dc86a70aefdc268=1279=2269=0278=d9ba8062-c393-403a-9201-40c4babddcdb83=159756946355=BTC-USD60=20250411-01:50:25.35943358=FILLED10=001
20250411-01:50:25.502451000 : 8=FIXT.1.19=27335=X49=Coinbase56=24ab46f784d1b20db435b852086e325034=9350=TEST52=20250411-01:50:25.387440369=2262=83671f6c-e7d6-4990-a146-dc86a70aefdc268=1279=0269=183=159756946455=BTC-USD271=0.6232294660=20250411-01:50:25.38555340=137=8da114a5-fc6d-4e04-adf5-3dce63ce2a3710=140
20250411-01:50:25.502823000 : 8=FIXT.1.19=32535=X49=Coinbase56=24ab46f784d1b20db435b852086e325034=9450=TEST52=20250411-01:50:25.387452369=2262=83671f6c-e7d6-4990-a146-dc86a70aefdc268=1279=0269=2278=4d60a78e-b39b-420e-b830-bc0f3f4fdde283=159756946555=BTC-USD270=3.53271=0.6232294660=20250411-01:50:25.38555337=8da114a5-fc6d-4e04-adf5-3dce63ce2a375797=210=132
20250411-01:50:25.502998000 : 8=FIXT.1.19=27935=X49=Coinbase56=24ab46f784d1b20db435b852086e325034=9550=TEST52=20250411-01:50:25.387457369=2262=83671f6c-e7d6-4990-a146-dc86a70aefdc268=1279=2269=1278=8da114a5-fc6d-4e04-adf5-3dce63ce2a3783=159756946655=BTC-USD271=0.0000000060=20250411-01:50:25.38555358=FILLED10=061
20250411-01:50:25.530225000 : 8=FIXT.1.19=28235=X49=Coinbase56=24ab46f784d1b20db435b852086e325034=9650=TEST52=20250411-01:50:25.415160369=2262=83671f6c-e7d6-4990-a146-dc86a70aefdc268=1279=0269=083=159756946755=BTC-USD270=3.81271=0.6232294660=20250411-01:50:25.41438640=237=e88245af-b05d-4b24-a149-7448d9971c6210=238
20250411-01:50:25.530730000 : 8=FIXT.1.19=32535=X49=Coinbase56=24ab46f784d1b20db435b852086e325034=9750=TEST52=20250411-01:50:25.415167369=2262=83671f6c-e7d6-4990-a146-dc86a70aefdc268=1279=0269=2278=c5b88ea9-605d-4595-ac52-f7c3f08523ba83=159756946855=BTC-USD270=3.55271=0.6232294660=20250411-01:50:25.41438637=e88245af-b05d-4b24-a149-7448d9971c625797=110=202
20250411-01:50:25.530900000 : 8=FIXT.1.19=28835=X49=Coinbase56=24ab46f784d1b20db435b852086e325034=9850=TEST52=20250411-01:50:25.415170369=2262=83671f6c-e7d6-4990-a146-dc86a70aefdc268=1279=2269=0278=e88245af-b05d-4b24-a149-7448d9971c6283=159756946955=BTC-USD270=3.81271=0.0000000060=20250411-01:50:25.41438658=FILLED10=151
20250411-01:50:25.557710000 : 8=FIXT.1.19=28235=X49=Coinbase56=24ab46f784d1b20db435b852086e325034=9950=TEST52=20250411-01:50:25.441648369=2262=83671f6c-e7d6-4990-a146-dc86a70aefdc268=1279=0269=083=159756947055=BTC-USD270=3.52271=0.6197183160=20250411-01:50:25.44014440=237=424290d5-d568-46c5-8597-a26ebd20f14f10=234
20250411-01:50:25.557982000 : 8=FIXT.1.19=27935=X49=Coinbase56=24ab46f784d1b20db435b852086e325034=10050=TEST52=20250411-01:50:25.441656369=2262=83671f6c-e7d6-4990-a146-dc86a70aefdc268=1279=0269=0278=424290d5-d568-46c5-8597-a26ebd20f14f83=159756947155=BTC-USD270=3.52271=0.6197183160=20250411-01:50:25.44014410=114
20250411-01:50:25.558422000 : 8=FIXT.1.19=28335=X49=Coinbase56=24ab46f784d1b20db435b852086e325034=10150=TEST52=20250411-01:50:25.441658369=2262=83671f6c-e7d6-4990-a146-dc86a70aefdc268=1279=0269=083=159756947255=BTC-USD270=3.39271=0.6197183160=20250411-01:50:25.44014440=237=3f3f0f61-8f53-441f-88fa-9f381b38278f10=082
20250411-01:50:25.558697000 : 8=FIXT.1.19=27935=X49=Coinbase56=24ab46f784d1b20db435b852086e325034=10250=TEST52=20250411-01:50:25.441668369=2262=83671f6c-e7d6-4990-a146-dc86a70aefdc268=1279=0269=0278=3f3f0f61-8f53-441f-88fa-9f381b38278f83=159756947355=BTC-USD270=3.39271=0.6197183160=20250411-01:50:25.44014410=189
20250411-01:50:25.585435000 : 8=FIXT.1.19=28335=X49=Coinbase56=24ab46f784d1b20db435b852086e325034=10350=TEST52=20250411-01:50:25.470700369=2262=83671f6c-e7d6-4990-a146-dc86a70aefdc268=1279=0269=183=159756947455=BTC-USD270=3.25271=0.6232294660=20250411-01:50:25.46906740=237=b889fc1a-e247-4201-8e09-8e556c44ad1410=066
20250411-01:50:25.585730000 : 8=FIXT.1.19=32635=X49=Coinbase56=24ab46f784d1b20db435b852086e325034=10450=TEST52=20250411-01:50:25.470769369=2262=83671f6c-e7d6-4990-a146-dc86a70aefdc268=1279=0269=2278=4d60a78e-b39b-420e-b830-bc0f3f4fdde283=159756947555=BTC-USD270=3.53271=0.6232294660=20250411-01:50:25.46906737=b889fc1a-e247-4201-8e09-8e556c44ad145797=210=166
20250411-01:50:25.586489000 : 8=FIXT.1.19=28935=X49=Coinbase56=24ab46f784d1b20db435b852086e325034=10550=TEST52=20250411-01:50:25.470778369=2262=83671f6c-e7d6-4990-a146-dc86a70aefdc268=1279=2269=1278=b889fc1a-e247-4201-8e09-8e556c44ad1483=159756947655=BTC-USD270=3.25271=0.0000000060=20250411-01:50:25.46906758=FILLED10=249
20250411-01:50:25.645198000 : 8=FIXT.1.19=27835=X49=Coinbase56=24ab46f784d1b20db435b852086e325034=10650=TEST52=20250411-01:50:25.530262369=2262=83671f6c-e7d6-4990-a146-dc86a70aefdc268=1279=0269=083=159756947755=BTC-USD29004=2.208895519560=20250411-01:50:25.52829640=137=eb45509b-ceca-4f7c-9613-104aab70a4c510=045
20250411-01:50:25.645730000 : 8=FIXT.1.19=32635=X49=Coinbase56=24ab46f784d1b20db435b852086e325034=10750=TEST52=20250411-01:50:25.530354369=2262=83671f6c-e7d6-4990-a146-dc86a70aefdc268=1279=0269=2278=c5b88ea9-605d-4595-ac52-f7c3f08523ba83=159756947855=BTC-USD270=3.55271=0.6222240960=20250411-01:50:25.52829637=eb45509b-ceca-4f7c-9613-104aab70a4c55797=110=194
20250411-01:50:25.645914000 : 8=FIXT.1.19=26535=X49=Coinbase56=24ab46f784d1b20db435b852086e325034=10850=TEST52=20250411-01:50:25.530359369=2262=83671f6c-e7d6-4990-a146-dc86a70aefdc268=1279=2269=0278=eb45509b-ceca-4f7c-9613-104aab70a4c583=159756947955=BTC-USD60=20250411-01:50:25.52829658=FILLED10=068
20250411-01:50:25.672973000 : 8=FIXT.1.19=27435=X49=Coinbase56=24ab46f784d1b20db435b852086e325034=10950=TEST52=20250411-01:50:25.557716369=2262=83671f6c-e7d6-4990-a146-dc86a70aefdc268=1279=0269=183=159756948055=BTC-USD271=0.6232294660=20250411-01:50:25.55648940=137=f6407d4f-4b0a-4153-bd2f-5c516f21f2e110=002
20250411-01:50:25.673133000 : 8=FIXT.1.19=32635=X49=Coinbase56=24ab46f784d1b20db435b852086e325034=11050=TEST52=20250411-01:50:25.557724369=2262=83671f6c-e7d6-4990-a146-dc86a70aefdc268=1279=0269=2278=4d60a78e-b39b-420e-b830-bc0f3f4fdde283=159756948155=BTC-USD270=3.53271=0.6232294660=20250411-01:50:25.55648937=f6407d4f-4b0a-4153-bd2f-5c516f21f2e15797=210=237
20250411-01:50:25.673283000 : 8=FIXT.1.19=28035=X49=Coinbase56=24ab46f784d1b20db435b852086e325034=11150=TEST52=20250411-01:50:25.557727369=2262=83671f6c-e7d6-4990-a146-dc86a70aefdc268=1279=2269=1278=f6407d4f-4b0a-4153-bd2f-5c516f21f2e183=159756948255=BTC-USD271=0.0000000060=20250411-01:50:25.55648958=FILLED10=155
20250411-01:51:28.635918000 : 8=FIXT.1.19=21535=A34=149=24ab46f784d1b20db435b852086e325052=20250411-01:51:28.62756=Coinbase95=4496=RoB4oyiQY8vqBBRrZBztaeCmNHiEaNZr+jYKdtQYs1g=98=0108=30141=Y553=24ab46f784d1b20db435b852086e3250554=akmwnltyfgb1137=910=210
20250411-01:51:28.892672000 : 8=FIXT.1.19=12535=A49=Coinbase56=24ab46f784d1b20db435b852086e325034=150=TEST52=20250411-01:51:28.775963369=198=0108=30141=Y1137=910=206
20250411-01:51:30.327332000 : 8=FIXT.1.19=17835=V34=249=24ab46f784d1b20db435b852086e325052=20250411-01:51:30.32656=Coinbase1128=9146=155=BTC-USD262=b7f6c79a-636c-490b-8bc5-37cb784406ba263=1264=0267=2269=0269=110=062
20250411-01:51:30.753987000 : 8=FIXT.1.19=28135=X49=Coinbase56=24ab46f784d1b20db435b852086e325034=250=TEST52=20250411-01:51:30.587155369=2262=b7f6c79a-636c-490b-8bc5-37cb784406ba268=1279=0269=083=159757078355=BTC-USD270=3.48271=0.6197183160=20250411-01:51:30.58528340=237=d22f1cd1-1c45-4091-a4e5-9785e88e7c8c10=230
20250411-01:51:30.754710000 : 8=FIXT.1.19=27735=X49=Coinbase56=24ab46f784d1b20db435b852086e325034=350=TEST52=20250411-01:51:30.587167369=2262=b7f6c79a-636c-490b-8bc5-37cb784406ba268=1279=0269=0278=d22f1cd1-1c45-4091-a4e5-9785e88e7c8c83=159757078455=BTC-USD270=3.48271=0.6197183160=20250411-01:51:30.58528310=083
20250411-01:51:31.061399000 : 8=FIXT.1.19=28135=X49=Coinbase56=24ab46f784d1b20db435b852086e325034=450=TEST52=20250411-01:51:30.874714369=2262=b7f6c79a-636c-490b-8bc5-37cb784406ba268=1279=0269=083=159757078555=BTC-USD270=3.39271=0.6197183160=20250411-01:51:30.87241740=237=6199b7ad-4bd0-49de-b1e1-842b7b71313010=211
20250411-01:51:31.062083000 : 8=FIXT.1.19=27735=X49=Coinbase56=24ab46f784d1b20db435b852086e325034=550=TEST52=20250411-01:51:30.874722369=2262=b7f6c79a-636c-490b-8bc5-37cb784406ba268=1279=0269=0278=6199b7ad-4bd0-49de-b1e1-842b7b71313083=159757078655=BTC-USD270=3.39271=0.6197183160=20250411-01:51:30.87241710=060
20250411-01:51:31.420857000 : 8=FIXT.1.19=28135=X49=Coinbase56=24ab46f784d1b20db435b852086e325034=650=TEST52=20250411-01:51:31.302932369=2262=b7f6c79a-636c-490b-8bc5-37cb784406ba268=1279=0269=083=159757078755=BTC-USD270=3.76271=0.6197183160=20250411-01:51:31.30178640=237=ed408743-2c8f-4ab5-af10-1f385b5f824d10=002
20250411-01:51:31.422201000 : 8=FIXT.1.19=32435=X49=Coinbase56=24ab46f784d1b20db435b852086e325034=750=TEST52=20250411-01:51:31.302942369=2262=b7f6c79a-636c-490b-8bc5-37cb784406ba268=1279=0269=2278=c5b88ea9-605d-4595-ac52-f7c3f08523ba83=159757078855=BTC-USD270=3.55271=0.6197183160=20250411-01:51:31.30178637=ed408743-2c8f-4ab5-af10-1f385b5f824d5797=110=212
20250411-01:51:31.422595000 : 8=FIXT.1.19=28735=X49=Coinbase56=24ab46f784d1b20db435b852086e325034=850=TEST52=20250411-01:51:31.302946369=2262=b7f6c79a-636c-490b-8bc5-37cb784406ba268=1279=2269=0278=ed408743-2c8f-4ab5-af10-1f385b5f824d83=159757078955=BTC-USD270=3.76271=0.0000000060=20250411-01:51:31.30178658=FILLED10=173
20250411-01:51:31.477193000 : 8=FIXT.1.19=28135=X49=Coinbase56=24ab46f784d1b20db435b852086e325034=950=TEST52=20250411-01:51:31.360141369=2262=b7f6c79a-636c-490b-8bc5-37cb784406ba268=1279=0269=183=159757079055=BTC-USD270=3.25271=0.6197183160=20250411-01:51:31.35838840=237=f25ff68b-c495-4819-9ffd-637e0e2bdcbd10=168
20250411-01:51:31.477679000 : 8=FIXT.1.19=32535=X49=Coinbase56=24ab46f784d1b20db435b852086e325034=1050=TEST52=20250411-01:51:31.360153369=2262=b7f6c79a-636c-490b-8bc5-37cb784406ba268=1279=0269=2278=4d60a78e-b39b-420e-b830-bc0f3f4fdde283=159757079155=BTC-USD270=3.53271=0.6197183160=20250411-01:51:31.35838837=f25ff68b-c495-4819-9ffd-637e0e2bdcbd5797=210=040
20250411-01:51:31.479139000 : 8=FIXT.1.19=28835=X49=Coinbase56=24ab46f784d1b20db435b852086e325034=1150=TEST52=20250411-01:51:31.360158369=2262=b7f6c79a-636c-490b-8bc5-37cb784406ba268=1279=2269=1278=f25ff68b-c495-4819-9ffd-637e0e2bdcbd83=159757079255=BTC-USD270=3.25271=0.0000000060=20250411-01:51:31.35838858=FILLED10=126
20250411-01:51:31.993515000 : 8=FIXT.1.19=28235=X49=Coinbase56=24ab46f784d1b20db435b852086e325034=1250=TEST52=20250411-01:51:31.876284369=2262=b7f6c79a-636c-490b-8bc5-37cb784406ba268=1279=0269=083=159757079355=BTC-USD270=3.72271=0.6232294660=20250411-01:51:31.87436340=237=b2158320-15ce-4845-9bfd-78595b80423510=086
20250411-01:51:31.993975000 : 8=FIXT.1.19=32535=X49=Coinbase56=24ab46f784d1b20db435b852086e325034=1350=TEST52=20250411-01:51:31.876300369=2262=b7f6c79a-636c-490b-8bc5-37cb784406ba268=1279=0269=2278=c5b88ea9-605d-4595-ac52-f7c3f08523ba83=159757079455=BTC-USD270=3.55271=0.6232294660=20250411-01:51:31.87436337=b2158320-15ce-4845-9bfd-78595b8042355797=110=032
20250411-01:51:31.994167000 : 8=FIXT.1.19=28835=X49=Coinbase56=24ab46f784d1b20db435b852086e325034=1450=TEST52=20250411-01:51:31.876311369=2262=b7f6c79a-636c-490b-8bc5-37cb784406ba268=1279=2269=0278=b2158320-15ce-4845-9bfd-78595b80423583=159757079555=BTC-USD270=3.72271=0.0000000060=20250411-01:51:31.87436358=FILLED10=245
20250411-01:51:31.995410000 : 8=FIXT.1.19=28235=X49=Coinbase56=24ab46f784d1b20db435b852086e325034=1550=TEST52=20250411-01:51:31.876326369=2262=b7f6c79a-636c-490b-8bc5-37cb784406ba268=1279=0269=083=159757079655=BTC-USD270=3.71271=0.6232294660=20250411-01:51:31.87436340=237=586ab649-8c43-441e-9f02-05b0022e616b10=120
20250411-01:51:31.995620000 : 8=FIXT.1.19=32535=X49=Coinbase56=24ab46f784d1b20db435b852086e325034=1650=TEST52=20250411-01:51:31.876333369=2262=b7f6c79a-636c-490b-8bc5-37cb784406ba268=1279=0269=2278=c5b88ea9-605d-4595-ac52-f7c3f08523ba83=159757079755=BTC-USD270=3.55271=0.6232294660=20250411-01:51:31.87436337=586ab649-8c43-441e-9f02-05b0022e616b5797=110=076
20250411-01:51:31.996101000 : 8=FIXT.1.19=28835=X49=Coinbase56=24ab46f784d1b20db435b852086e325034=1750=TEST52=20250411-01:51:31.876337369=2262=b7f6c79a-636c-490b-8bc5-37cb784406ba268=1279=2269=0278=586ab649-8c43-441e-9f02-05b0022e616b83=159757079855=BTC-USD270=3.71271=0.0000000060=20250411-01:51:31.87436358=FILLED10=034
20250411-01:51:32.113673000 : 8=FIXT.1.19=28235=X49=Coinbase56=24ab46f784d1b20db435b852086e325034=1850=TEST52=20250411-01:51:31.988759369=2262=b7f6c79a-636c-490b-8bc5-37cb784406ba268=1279=0269=183=159757079955=BTC-USD270=3.32271=0.6232294660=20250411-01:51:31.98714840=237=e72e5333-b8e7-4502-a5bb-ac25d84315f110=030
20250411-01:51:32.120081000 : 8=FIXT.1.19=32535=X49=Coinbase56=24ab46f784d1b20db435b852086e325034=1950=TEST52=20250411-01:51:31.988765369=2262=b7f6c79a-636c-490b-8bc5-37cb784406ba268=1279=0269=2278=4d60a78e-b39b-420e-b830-bc0f3f4fdde283=159757080055=BTC-USD270=3.53271=0.6232294660=20250411-01:51:31.98714837=e72e5333-b8e7-4502-a5bb-ac25d84315f15797=210=096
20250411-01:51:32.152923000 : 8=FIXT.1.19=28835=X49=Coinbase56=24ab46f784d1b20db435b852086e325034=2050=TEST52=20250411-01:51:31.988891369=2262=b7f6c79a-636c-490b-8bc5-37cb784406ba268=1279=2269=1278=e72e5333-b8e7-4502-a5bb-ac25d84315f183=159757080155=BTC-USD270=3.32271=0.0000000060=20250411-01:51:31.98714858=FILLED10=168
20250411-01:51:32.154283000 : 8=FIXT.1.19=28235=X49=Coinbase56=24ab46f784d1b20db435b852086e325034=2150=TEST52=20250411-01:51:31.988895369=2262=b7f6c79a-636c-490b-8bc5-37cb784406ba268=1279=0269=183=159757080255=BTC-USD270=3.18271=0.6232294660=20250411-01:51:31.98714840=237=8aa9c514-2b9a-4af6-9fbb-4322dbf403bd10=205
20250411-01:51:32.154587000 : 8=FIXT.1.19=32535=X49=Coinbase56=24ab46f784d1b20db435b852086e325034=2250=TEST52=20250411-01:51:31.988901369=2262=b7f6c79a-636c-490b-8bc5-37cb784406ba268=1279=0269=2278=4d60a78e-b39b-420e-b830-bc0f3f4fdde283=159757080355=BTC-USD270=3.53271=0.6232294660=20250411-01:51:31.98714837=8aa9c514-2b9a-4af6-9fbb-4322dbf403bd5797=210=020
20250411-01:51:32.155817000 : 8=FIXT.1.19=28835=X49=Coinbase56=24ab46f784d1b20db435b852086e325034=2350=TEST52=20250411-01:51:31.988905369=2262=b7f6c79a-636c-490b-8bc5-37cb784406ba268=1279=2269=1278=8aa9c514-2b9a-4af6-9fbb-4322dbf403bd83=159757080455=BTC-USD270=3.18271=0.0000000060=20250411-01:51:31.98714858=FILLED10=109
20250411-01:51:32.156813000 : 8=FIXT.1.19=28235=X49=Coinbase56=24ab46f784d1b20db435b852086e325034=2450=TEST52=20250411-01:51:32.016710369=2262=b7f6c79a-636c-490b-8bc5-37cb784406ba268=1279=0269=183=159757080555=BTC-USD270=3.57271=0.6232294660=20250411-01:51:32.01552540=237=3008d95d-6e0e-48d7-975d-a1044512985d10=108
20250411-01:51:32.157094000 : 8=FIXT.1.19=27835=X49=Coinbase56=24ab46f784d1b20db435b852086e325034=2550=TEST52=20250411-01:51:32.016717369=2262=b7f6c79a-636c-490b-8bc5-37cb784406ba268=1279=0269=1278=3008d95d-6e0e-48d7-975d-a1044512985d83=159757080655=BTC-USD270=3.57271=0.6232294660=20250411-01:51:32.01552510=221
20250411-01:51:32.415245000 : 8=FIXT.1.19=28235=X49=Coinbase56=24ab46f784d1b20db435b852086e325034=2650=TEST52=20250411-01:51:32.298623369=2262=b7f6c79a-636c-490b-8bc5-37cb784406ba268=1279=0269=083=159757080755=BTC-USD270=3.49271=0.6232294660=20250411-01:51:32.29723640=237=e4e84565-c0c6-4c05-b4bc-dbfc32459be310=154
20250411-01:51:32.416116000 : 8=FIXT.1.19=27835=X49=Coinbase56=24ab46f784d1b20db435b852086e325034=2750=TEST52=20250411-01:51:32.298636369=2262=b7f6c79a-636c-490b-8bc5-37cb784406ba268=1279=0269=0278=e4e84565-c0c6-4c05-b4bc-dbfc32459be383=159757080855=BTC-USD270=3.49271=0.6232294660=20250411-01:51:32.29723610=008
20250411-01:51:33.212700000 : 8=FIXT.1.19=28235=X49=Coinbase56=24ab46f784d1b20db435b852086e325034=2850=TEST52=20250411-01:51:33.018061369=2262=b7f6c79a-636c-490b-8bc5-37cb784406ba268=1279=0269=183=159757080955=BTC-USD270=3.32271=0.6232294660=20250411-01:51:33.01661440=237=2733d29a-2a07-4574-8ec5-6e106b8ef2be10=245
20250411-01:51:33.213187000 : 8=FIXT.1.19=32535=X49=Coinbase56=24ab46f784d1b20db435b852086e325034=2950=TEST52=20250411-01:51:33.018137369=2262=b7f6c79a-636c-490b-8bc5-37cb784406ba268=1279=0269=2278=4d60a78e-b39b-420e-b830-bc0f3f4fdde283=159757081055=BTC-USD270=3.53271=0.6232294660=20250411-01:51:33.01661437=2733d29a-2a07-4574-8ec5-6e106b8ef2be5797=210=071
20250411-01:51:33.213772000 : 8=FIXT.1.19=28835=X49=Coinbase56=24ab46f784d1b20db435b852086e325034=3050=TEST52=20250411-01:51:33.018145369=2262=b7f6c79a-636c-490b-8bc5-37cb784406ba268=1279=2269=1278=2733d29a-2a07-4574-8ec5-6e106b8ef2be83=159757081155=BTC-USD270=3.32271=0.0000000060=20250411-01:51:33.01661458=FILLED10=142
20250411-01:51:33.215114000 : 8=FIXT.1.19=28235=X49=Coinbase56=24ab46f784d1b20db435b852086e325034=3150=TEST52=20250411-01:51:33.018185369=2262=b7f6c79a-636c-490b-8bc5-37cb784406ba268=1279=0269=183=159757081255=BTC-USD270=3.19271=0.6232294660=20250411-01:51:33.01661440=237=1bf2850e-307b-4e32-8fa8-2f2ee005ed8710=034
20250411-01:51:33.215346000 : 8=FIXT.1.19=32535=X49=Coinbase56=24ab46f784d1b20db435b852086e325034=3250=TEST52=20250411-01:51:33.018190369=2262=b7f6c79a-636c-490b-8bc5-37cb784406ba268=1279=0269=2278=4d60a78e-b39b-420e-b830-bc0f3f4fdde283=159757081355=BTC-USD270=3.53271=0.6232294660=20250411-01:51:33.01661437=1bf2850e-307b-4e32-8fa8-2f2ee005ed875797=210=112
20250411-01:51:33.217560000 : 8=FIXT.1.19=28835=X49=Coinbase56=24ab46f784d1b20db435b852086e325034=3350=TEST52=20250411-01:51:33.018192369=2262=b7f6c79a-636c-490b-8bc5-37cb784406ba268=1279=2269=1278=1bf2850e-307b-4e32-8fa8-2f2ee005ed8783=159757081455=BTC-USD270=3.19271=0.0000000060=20250411-01:51:33.01661458=FILLED10=200
20250411-01:51:33.333976000 : 8=FIXT.1.19=28235=X49=Coinbase56=24ab46f784d1b20db435b852086e325034=3450=TEST52=20250411-01:51:33.130858369=2262=b7f6c79a-636c-490b-8bc5-37cb784406ba268=1279=0269=083=159757081555=BTC-USD270=3.72271=0.6232294660=20250411-01:51:33.12897340=237=1255a79e-3ea1-4ecb-913a-238263ec042c10=247
20250411-01:51:33.334487000 : 8=FIXT.1.19=32535=X49=Coinbase56=24ab46f784d1b20db435b852086e325034=3550=TEST52=20250411-01:51:33.130869369=2262=b7f6c79a-636c-490b-8bc5-37cb784406ba268=1279=0269=2278=c5b88ea9-605d-4595-ac52-f7c3f08523ba83=159757081655=BTC-USD270=3.55271=0.6232294660=20250411-01:51:33.12897337=1255a79e-3ea1-4ecb-913a-238263ec042c5797=110=206
20250411-01:51:33.334666000 : 8=FIXT.1.19=28835=X49=Coinbase56=24ab46f784d1b20db435b852086e325034=3650=TEST52=20250411-01:51:33.130874369=2262=b7f6c79a-636c-490b-8bc5-37cb784406ba268=1279=2269=0278=1255a79e-3ea1-4ecb-913a-238263ec042c83=159757081755=BTC-USD270=3.72271=0.0000000060=20250411-01:51:33.12897358=FILLED10=157
20250411-01:51:33.336286000 : 8=FIXT.1.19=28235=X49=Coinbase56=24ab46f784d1b20db435b852086e325034=3750=TEST52=20250411-01:51:33.130878369=2262=b7f6c79a-636c-490b-8bc5-37cb784406ba268=1279=0269=083=159757081855=BTC-USD270=3.84271=0.6232294660=20250411-01:51:33.12897340=237=c11b677b-ccc0-4a63-9b81-08d32aa11cf410=090
20250411-01:51:33.336648000 : 8=FIXT.1.19=32535=X49=Coinbase56=24ab46f784d1b20db435b852086e325034=3850=TEST52=20250411-01:51:33.130880369=2262=b7f6c79a-636c-490b-8bc5-37cb784406ba268=1279=0269=2278=c5b88ea9-605d-4595-ac52-f7c3f08523ba83=159757081955=BTC-USD270=3.55271=0.6232294660=20250411-01:51:33.12897337=c11b677b-ccc0-4a63-9b81-08d32aa11cf45797=110=037
20250411-01:51:33.337128000 : 8=FIXT.1.19=28835=X49=Coinbase56=24ab46f784d1b20db435b852086e325034=3950=TEST52=20250411-01:51:33.130882369=2262=b7f6c79a-636c-490b-8bc5-37cb784406ba268=1279=2269=0278=c11b677b-ccc0-4a63-9b81-08d32aa11cf483=159757082055=BTC-USD270=3.84271=0.0000000060=20250411-01:51:33.12897358=FILLED10=244
20250411-01:51:33.519580000 : 8=FIXT.1.19=28235=X49=Coinbase56=24ab46f784d1b20db435b852086e325034=4050=TEST52=20250411-01:51:33.359921369=2262=b7f6c79a-636c-490b-8bc5-37cb784406ba268=1279=0269=083=159757082155=BTC-USD270=3.79271=0.6197183160=20250411-01:51:33.35886540=237=1cec2c6e-a6c2-49f7-9a2e-867d8aea030710=166
20250411-01:51:33.520267000 : 8=FIXT.1.19=32535=X49=Coinbase56=24ab46f784d1b20db435b852086e325034=4150=TEST52=20250411-01:51:33.359932369=2262=b7f6c79a-636c-490b-8bc5-37cb784406ba268=1279=0269=2278=c5b88ea9-605d-4595-ac52-f7c3f08523ba83=159757082255=BTC-USD270=3.55271=0.6197183160=20250411-01:51:33.35886537=1cec2c6e-a6c2-49f7-9a2e-867d8aea03075797=110=118
20250411-01:51:33.520512000 : 8=FIXT.1.19=28835=X49=Coinbase56=24ab46f784d1b20db435b852086e325034=4250=TEST52=20250411-01:51:33.359957369=2262=b7f6c79a-636c-490b-8bc5-37cb784406ba268=1279=2269=0278=1cec2c6e-a6c2-49f7-9a2e-867d8aea030783=159757082355=BTC-USD270=3.79271=0.0000000060=20250411-01:51:33.35886558=FILLED10=085
20250411-01:51:33.533038000 : 8=FIXT.1.19=28135=X49=Coinbase56=24ab46f784d1b20db435b852086e325034=4350=TEST52=20250411-01:51:33.417002369=2262=b7f6c79a-636c-490b-8bc5-37cb784406ba268=1279=0269=183=159757082455=BTC-USD270=3.3271=0.6197183160=20250411-01:51:33.41577440=237=ff143297-ffb2-4137-bd8b-b75d195f05df10=047
20250411-01:51:33.533299000 : 8=FIXT.1.19=32535=X49=Coinbase56=24ab46f784d1b20db435b852086e325034=4450=TEST52=20250411-01:51:33.417114369=2262=b7f6c79a-636c-490b-8bc5-37cb784406ba268=1279=0269=2278=4d60a78e-b39b-420e-b830-bc0f3f4fdde283=159757082555=BTC-USD270=3.53271=0.6197183160=20250411-01:51:33.41577437=ff143297-ffb2-4137-bd8b-b75d195f05df5797=210=189
20250411-01:51:33.534234000 : 8=FIXT.1.19=28735=X49=Coinbase56=24ab46f784d1b20db435b852086e325034=4550=TEST52=20250411-01:51:33.417170369=2262=b7f6c79a-636c-490b-8bc5-37cb784406ba268=1279=2269=1278=ff143297-ffb2-4137-bd8b-b75d195f05df83=159757082655=BTC-USD270=3.3271=0.0000000060=20250411-01:51:33.41577458=FILLED10=219
20250411-01:51:33.706771000 : 8=FIXT.1.19=28235=X49=Coinbase56=24ab46f784d1b20db435b852086e325034=4650=TEST52=20250411-01:51:33.589609369=2262=b7f6c79a-636c-490b-8bc5-37cb784406ba268=1279=0269=183=159757082755=BTC-USD270=3.21271=0.6232294660=20250411-01:51:33.58841240=237=146c543c-1330-479b-a6f7-a05707358dc710=128
20250411-01:51:33.707318000 : 8=FIXT.1.19=32535=X49=Coinbase56=24ab46f784d1b20db435b852086e325034=4750=TEST52=20250411-01:51:33.589618369=2262=b7f6c79a-636c-490b-8bc5-37cb784406ba268=1279=0269=2278=4d60a78e-b39b-420e-b830-bc0f3f4fdde283=159757082855=BTC-USD270=3.53271=0.6232294660=20250411-01:51:33.58841237=146c543c-1330-479b-a6f7-a05707358dc75797=210=217
20250411-01:51:33.710509000 : 8=FIXT.1.19=28835=X49=Coinbase56=24ab46f784d1b20db435b852086e325034=4850=TEST52=20250411-01:51:33.589622369=2262=b7f6c79a-636c-490b-8bc5-37cb784406ba268=1279=2269=1278=146c543c-1330-479b-a6f7-a05707358dc783=159757082955=BTC-USD270=3.21271=0.0000000060=20250411-01:51:33.58841258=FILLED10=035
20250411-01:51:33.761506000 : 8=FIXT.1.19=28235=X49=Coinbase56=24ab46f784d1b20db435b852086e325034=4950=TEST52=20250411-01:51:33.644116369=2262=b7f6c79a-636c-490b-8bc5-37cb784406ba268=1279=0269=083=159757083055=BTC-USD270=3.78271=0.6232294660=20250411-01:51:33.64275040=237=7c705463-0e9e-49c3-9252-05aba626da0010=156
20250411-01:51:33.762014000 : 8=FIXT.1.19=32535=X49=Coinbase56=24ab46f784d1b20db435b852086e325034=5050=TEST52=20250411-01:51:33.644125369=2262=b7f6c79a-636c-490b-8bc5-37cb784406ba268=1279=0269=2278=c5b88ea9-605d-4595-ac52-f7c3f08523ba83=159757083155=BTC-USD270=3.55271=0.6232294660=20250411-01:51:33.64275037=7c705463-0e9e-49c3-9252-05aba626da005797=110=098
20250411-01:51:33.762142000 : 8=FIXT.1.19=28835=X49=Coinbase56=24ab46f784d1b20db435b852086e325034=5150=TEST52=20250411-01:51:33.644129369=2262=b7f6c79a-636c-490b-8bc5-37cb784406ba268=1279=2269=0278=7c705463-0e9e-49c3-9252-05aba626da0083=159757083255=BTC-USD270=3.78271=0.0000000060=20250411-01:51:33.64275058=FILLED10=063
20250411-01:51:34.281406000 : 8=FIXT.1.19=28235=X49=Coinbase56=24ab46f784d1b20db435b852086e325034=5250=TEST52=20250411-01:51:34.162483369=2262=b7f6c79a-636c-490b-8bc5-37cb784406ba268=1279=0269=083=159757083355=BTC-USD270=3.74271=0.6197183160=20250411-01:51:34.16107740=237=485e585e-fc3c-45f0-97ff-22db49ae341710=069
20250411-01:51:34.282028000 : 8=FIXT.1.19=32535=X49=Coinbase56=24ab46f784d1b20db435b852086e325034=5350=TEST52=20250411-01:51:34.162494369=2262=b7f6c79a-636c-490b-8bc5-37cb784406ba268=1279=0269=2278=c5b88ea9-605d-4595-ac52-f7c3f08523ba83=159757083455=BTC-USD270=3.55271=0.6197183160=20250411-01:51:34.16107737=485e585e-fc3c-45f0-97ff-22db49ae34175797=110=026
20250411-01:51:34.282512000 : 8=FIXT.1.19=28835=X49=Coinbase56=24ab46f784d1b20db435b852086e325034=5450=TEST52=20250411-01:51:34.162496369=2262=b7f6c79a-636c-490b-8bc5-37cb784406ba268=1279=2269=0278=485e585e-fc3c-45f0-97ff-22db49ae341783=159757083555=BTC-USD270=3.74271=0.0000000060=20250411-01:51:34.16107758=FILLED10=239
20250411-01:51:34.381569000 : 8=FIXT.1.19=28135=X49=Coinbase56=24ab46f784d1b20db435b852086e325034=5550=TEST52=20250411-01:51:34.216060369=2262=b7f6c79a-636c-490b-8bc5-37cb784406ba268=1279=0269=183=159757083655=BTC-USD270=3.2271=0.6197183160=20250411-01:51:34.21473540=237=0dc96803-acdb-4041-9e88-4efea2d7002410=240
20250411-01:51:34.382026000 : 8=FIXT.1.19=32535=X49=Coinbase56=24ab46f784d1b20db435b852086e325034=5650=TEST52=20250411-01:51:34.216067369=2262=b7f6c79a-636c-490b-8bc5-37cb784406ba268=1279=0269=2278=4d60a78e-b39b-420e-b830-bc0f3f4fdde283=159757083755=BTC-USD270=3.53271=0.6197183160=20250411-01:51:34.21473537=0dc96803-acdb-4041-9e88-4efea2d700245797=210=130
20250411-01:51:34.383530000 : 8=FIXT.1.19=28735=X49=Coinbase56=24ab46f784d1b20db435b852086e325034=5750=TEST52=20250411-01:51:34.216070369=2262=b7f6c79a-636c-490b-8bc5-37cb784406ba268=1279=2269=1278=0dc96803-acdb-4041-9e88-4efea2d7002483=159757083855=BTC-USD270=3.2271=0.0000000060=20250411-01:51:34.21473558=FILLED10=151
20250411-01:51:35.272218000 : 8=FIXT.1.19=28235=X49=Coinbase56=24ab46f784d1b20db435b852086e325034=5850=TEST52=20250411-01:51:35.156601369=2262=b7f6c79a-636c-490b-8bc5-37cb784406ba268=1279=0269=083=159757083955=BTC-USD270=3.36271=0.6232294660=20250411-01:51:35.15513040=237=24440124-40d0-45da-88cc-2e3ac87474ac10=193
20250411-01:51:35.272794000 : 8=FIXT.1.19=27835=X49=Coinbase56=24ab46f784d1b20db435b852086e325034=5950=TEST52=20250411-01:51:35.156614369=2262=b7f6c79a-636c-490b-8bc5-37cb784406ba268=1279=0269=0278=24440124-40d0-45da-88cc-2e3ac87474ac83=159757084055=BTC-USD270=3.36271=0.6232294660=20250411-01:51:35.15513010=038
20250411-01:51:35.565926000 : 8=FIXT.1.19=91735=W49=Coinbase56=24ab46f784d1b20db435b852086e325034=6050=TEST52=20250411-01:51:35.449630369=2262=b7f6c79a-636c-490b-8bc5-37cb784406ba83=1597570840893=N55=BTC-USD1682=full_trading268=10269=0278=4d60a78e-b39b-420e-b830-bc0f3f4fdde2270=3.53271=256692.95930806269=0278=9d9353ab-229f-423a-89a3-c52a46543bc9270=3.53271=18127.30103418269=0278=d30cd9b9-ceb4-42d8-90a3-c2c7cf5f4d4d270=3.52271=0.62322946269=0278=e4e84565-c0c6-4c05-b4bc-dbfc32459be3270=3.49271=0.62322946269=0278=f5fc5e68-a52c-44d3-87ef-3785312f4782270=3.48271=0.29310888269=0278=80dd7f1f-21ae-4491-bbbe-cab20f4cdbe2270=3.48271=0.61971831269=0278=d22f1cd1-1c45-4091-a4e5-9785e88e7c8c270=3.48271=0.61971831269=0278=dcccb470-c535-433a-9198-4e2b4c26d99d270=3.47271=0.29311495269=0278=f05d9766-970d-44ca-aa4d-e8b2720bbda8270=3.46271=0.29026870269=0278=71784df7-d0dc-47e9-8f9a-9650c5618d15270=3.45271=0.6232294610=058
20250411-01:51:35.569201000 : 8=FIXT.1.19=14035=334=349=24ab46f784d1b20db435b852086e325052=20250411-01:51:35.56856=Coinbase45=6058=Tag appears more than once371=269372=W373=1310=203
20250411-01:51:35.569469000 : 8=FIXT.1.19=90835=W49=Coinbase56=24ab46f784d1b20db435b852086e325034=6150=TEST52=20250411-01:51:35.449872369=2262=b7f6c79a-636c-490b-8bc5-37cb784406ba83=1597570840893=N55=BTC-USD1682=full_trading268=10269=0278=2c4d7d5a-33aa-4058-b546-480b6a2168a4270=3.44271=0.29828577269=0278=37dbcf16-0b3d-4f67-bc90-e36268b99e0e270=3.42271=0.30270947269=0278=4c63c0b7-30e0-4ef1-931f-0090359f978e270=3.41271=0.32158962269=0278=d6b4aa4e-d588-4c96-83aa-8e8d8accb1a4270=3.41271=0.30121104269=0278=c2782603-d732-453b-97f2-1650e97e1b31270=3.40271=0.62322946269=0278=e8b3d8da-1663-413c-b7fb-6aba23b01440270=3.39271=0.31006477269=0278=6199b7ad-4bd0-49de-b1e1-842b7b713130270=3.39271=0.61971831269=0278=bcbe17c3-9059-4c38-8ab8-8e78f1ef9062270=3.38271=0.32617981269=0278=0122ead6-1c9f-4f0e-b787-dd85b05c103f270=3.38271=0.62322946269=0278=9cc600ef-e32c-4eec-8a0d-18e9bf00e3dd270=3.38271=0.6197183110=091
20250411-01:51:35.569899000 : 8=FIXT.1.19=14035=334=449=24ab46f784d1b20db435b852086e325052=20250411-01:51:35.56956=Coinbase45=6158=Tag appears more than once371=269372=W373=1310=206
20250411-01:51:35.569981000 : 8=FIXT.1.19=90835=W49=Coinbase56=24ab46f784d1b20db435b852086e325034=6250=TEST52=20250411-01:51:35.450122369=2262=b7f6c79a-636c-490b-8bc5-37cb784406ba83=1597570840893=N55=BTC-USD1682=full_trading268=10269=0278=57bb77fd-337f-49bc-a56f-a4e2dff851ee270=3.37271=0.31071676269=0278=24440124-40d0-45da-88cc-2e3ac87474ac270=3.36271=0.62322946269=0278=ded4b51d-349f-4726-8379-6761a3576bb6270=3.33271=0.31560513269=0278=ff7aff09-38de-47ac-a3cb-9beacb0b9ad8270=3.33271=0.30682342269=0278=d1da558a-e9d2-4e11-b26e-1eb80a1a34c5270=3.32271=0.31700685269=0278=9ee34527-d4d8-4659-b2ea-cdff3dc4a8fa270=3.32271=0.32181951269=0278=7abf2220-0421-460f-9dbb-14c41564e41a270=3.32271=0.31308436269=0278=69634ec5-f71a-4990-b56d-13c3069a455a270=3.31271=0.32329458269=0278=2f333c17-a386-4d52-8ff1-eadcb99bc22f270=3.31271=0.31999220269=0278=f02efc37-0b1e-470b-99ef-e31012887d73270=3.30271=0.3277157010=171
20250411-01:51:35.570557000 : 8=FIXT.1.19=14035=334=549=24ab46f784d1b20db435b852086e325052=20250411-01:51:35.57056=Coinbase45=6258=Tag appears more than once371=269372=W373=1310=200
20250411-01:51:35.570646000 : 8=FIXT.1.19=90835=W49=Coinbase56=24ab46f784d1b20db435b852086e325034=6350=TEST52=20250411-01:51:35.450372369=2262=b7f6c79a-636c-490b-8bc5-37cb784406ba83=1597570840893=N55=BTC-USD1682=full_trading268=10269=0278=6d430950-8078-4987-8995-e581564e368d270=3.29271=0.30702763269=0278=841f895a-cd2d-4082-9a37-b50fc19e35bf270=3.28271=0.32610801269=0278=3cf93093-e42b-4c24-95ea-c367d96427fe270=3.27271=0.33588654269=0278=f29c94bc-d1c2-4145-97b0-ecb77d81a8bf270=3.27271=0.31661408269=0278=d208c4fb-56c6-4911-85c9-77b68a5ba6ab270=3.25271=0.30961623269=0278=e88796ff-68c8-4463-914b-46e09fbaf639270=3.25271=0.33589845269=0278=06f345fb-0292-45fc-8237-9ad1a84b541c270=3.24271=0.31528507269=0278=fa20c2c7-df80-4941-9a9c-a6ef2e579480270=3.23271=0.33432448269=0278=a833d230-a749-4bf4-823e-93adc40b773d270=3.23271=0.31165878269=0278=2abb6e15-b9cd-415b-8c9b-99a61c750310270=3.22271=0.3204871410=089
20250411-01:51:35.571131000 : 8=FIXT.1.19=14035=334=649=24ab46f784d1b20db435b852086e325052=20250411-01:51:35.57056=Coinbase45=6358=Tag appears more than once371=269372=W373=1310=202
20250411-01:51:35.571282000 : 8=FIXT.1.19=90835=W49=Coinbase56=24ab46f784d1b20db435b852086e325034=6450=TEST52=20250411-01:51:35.450622369=2262=b7f6c79a-636c-490b-8bc5-37cb784406ba83=1597570840893=N55=BTC-USD1682=full_trading268=10269=0278=ec44a6d8-ae5f-4809-89d7-0f7a3adac547270=3.21271=0.33230954269=0278=9cf61c67-c4fc-4bac-92fd-d4e2b56248aa270=3.21271=0.33583951269=0278=210b2518-bb42-461a-9c7e-b4e04c5ffcc6270=3.21271=0.32669007269=0278=2e3fa1b2-20f1-4694-9be4-322040b75152270=3.21271=0.32907979269=0278=05dd5607-92c9-4296-8cdc-27cdff004dea270=3.21271=0.32776075269=0278=87944de7-a5f1-4033-a3d8-cbc10f3a5232270=3.20271=0.32225170269=0278=30f6bb59-2469-4e6d-8fa5-13666373901f270=3.19271=0.31386496269=0278=6a5d2852-7ddc-456e-acb5-bfadcc0c1360270=3.19271=0.32157390269=0278=5d00d8a2-5aea-4836-ba19-74fe67116df8270=3.18271=0.32651049269=0278=acc71746-3591-4dde-a7e2-c2795d0ad125270=3.17271=0.3157713110=140
20250411-01:51:35.571699000 : 8=FIXT.1.19=14035=334=749=24ab46f784d1b20db435b852086e325052=20250411-01:51:35.57156=Coinbase45=6458=Tag appears more than once371=269372=W373=1310=205
20250411-01:51:35.571774000 : 8=FIXT.1.19=90935=W49=Coinbase56=24ab46f784d1b20db435b852086e325034=6550=TEST52=20250411-01:51:35.450872369=2262=b7f6c79a-636c-490b-8bc5-37cb784406ba83=1597570840893=N55=BTC-USD1682=full_trading268=10269=0278=13982796-c2a8-4740-95e2-5aca0fdfd8bb270=3.16271=0.33021170269=0278=9f2f0737-661e-43d7-89f9-959ed5e08306270=3.16271=0.33082075269=0278=7e0e2d14-fa77-4978-8cae-d9660fd13e6d270=3.16271=0.32014975269=0278=82826a7d-848c-4516-a7b6-5ec6881609a8270=2.00271=10.00000000269=0278=590048d5-ee44-49dc-b66d-1a692e055133270=1.94271=0.51546392269=0278=22bdda11-16cd-488b-9fa9-da098dad543e270=1.94271=0.51546392269=0278=d356ef8b-596e-47e7-bf90-cc015b85fc57270=1.93271=0.52331606269=0278=aa8d48bc-97fb-4d00-b923-66d37cc8c66a270=1.93271=0.52331606269=0278=7d51dcb4-a7f8-4cca-b2d0-e902403d1b9f270=1.93271=0.52331606269=0278=f7680950-3af2-4723-a6e4-5cbd528ca900270=1.93271=0.5233160610=242
20250411-01:51:35.572237000 : 8=FIXT.1.19=14035=334=849=24ab46f784d1b20db435b852086e325052=20250411-01:51:35.57256=Coinbase45=6558=Tag appears more than once371=269372=W373=1310=208
20250411-01:51:35.572320000 : 8=FIXT.1.19=90835=W49=Coinbase56=24ab46f784d1b20db435b852086e325034=6650=TEST52=20250411-01:51:35.451122369=2262=b7f6c79a-636c-490b-8bc5-37cb784406ba83=1597570840893=N55=BTC-USD1682=full_trading268=10269=0278=fdeff994-4866-47af-9dde-a25947a26606270=1.93271=0.52331606269=0278=65e7e2bb-023d-4936-bb4e-ff7625ba7264270=1.93271=0.52331606269=0278=53732639-572c-4cd5-b61e-e4f534d1d540270=1.93271=0.52331606269=0278=24da8927-1dd1-468b-9437-ff366f5bfa11270=1.93271=0.52331606269=0278=baa5862c-41e8-458c-83d3-c095bb68ed17270=1.93271=0.52331606269=0278=92a3c3e3-7afe-4d02-a0d8-96f512b63bb7270=1.93271=0.52331606269=0278=9d2a564e-f178-4966-9baf-5814a1c1686b270=1.93271=0.52331606269=0278=f9e6b978-87f6-4397-8d82-07cf698c123f270=1.93271=0.52331606269=0278=3e64b388-13d3-441d-b241-aa8dd6fe55e6270=1.93271=0.52331606269=0278=60300433-87b0-4031-bb1e-12cf9d773d3f270=1.93271=0.5233160610=072
20250411-01:51:35.572774000 : 8=FIXT.1.19=14035=334=949=24ab46f784d1b20db435b852086e325052=20250411-01:51:35.57256=Coinbase45=6658=Tag appears more than once371=269372=W373=1310=210
20250411-01:51:35.796140000 : 8=FIXT.1.19=90835=W49=Coinbase56=24ab46f784d1b20db435b852086e325034=6750=TEST52=20250411-01:51:35.451372369=2262=b7f6c79a-636c-490b-8bc5-37cb784406ba83=1597570840893=N55=BTC-USD1682=full_trading268=10269=0278=1bdd5f5a-1d99-4eed-af09-c187bcbbd2d8270=1.93271=0.52331606269=0278=4ed6f6b9-77fb-4255-a188-f243dd0cdb3c270=1.93271=0.52331606269=0278=9ad1fc18-5a38-4edb-ac5c-6ac826a8a846270=1.93271=0.52331606269=0278=1c218c8c-baea-4a1f-838e-4a3a94b468e1270=1.93271=0.52331606269=0278=fd70f5e2-d2c9-472a-ab40-a775afafd73d270=1.93271=0.52331606269=0278=96f5e3a5-1c2a-4db6-a3fb-fd1f13d5d559270=1.93271=0.52331606269=0278=4a015a4c-490a-4c40-974f-9dfb7feb335d270=1.93271=0.52331606269=0278=d919363e-2c54-404f-bc0b-063e2f12bec4270=1.93271=0.52331606269=0278=d4636d6c-85c6-4ac9-9afb-70ca636f4ad4270=1.93271=0.52331606269=0278=bda09690-f345-4c33-ae8b-e8c78da11b5a270=1.93271=0.5233160610=165
20250411-01:51:35.797111000 : 8=FIXT.1.19=14135=334=1049=24ab46f784d1b20db435b852086e325052=20250411-01:51:35.79656=Coinbase45=6758=Tag appears more than once371=269372=W373=1310=004
20250411-01:51:35.797205000 : 8=FIXT.1.19=90835=W49=Coinbase56=24ab46f784d1b20db435b852086e325034=6850=TEST52=20250411-01:51:35.451622369=2262=b7f6c79a-636c-490b-8bc5-37cb784406ba83=1597570840893=N55=BTC-USD1682=full_trading268=10269=0278=1a81ae10-b700-42a0-89a3-7d7a3eea0ebb270=1.93271=0.52331606269=0278=1ace5afa-e550-4abf-a458-52e46e1b54f0270=1.93271=0.52331606269=0278=2332d1c9-67e7-457a-abfe-f5e9a8c2ea05270=1.93271=0.52331606269=0278=6afa1f19-0ec5-49fd-8b74-06a12a6c5ca9270=1.93271=0.52331606269=0278=3fa3413d-c26c-472f-9cc5-da1c48935c63270=1.93271=0.52331606269=0278=3f9e43c4-2e62-4d51-b4cb-ad207c693331270=1.93271=0.52331606269=0278=29e8bfcf-c764-4f7e-997d-09abf72bbc00270=1.93271=0.52331606269=0278=cf3e8b26-09ae-4dfb-9b84-b12a7e199a5a270=1.93271=0.52331606269=0278=08db3e51-e927-47d3-a9dd-2f887c58dc85270=1.93271=0.52331606269=0278=353ae741-9473-4cc5-9ab7-7e5de8ae55d0270=1.93271=0.5233160610=162
20250411-01:51:35.797794000 : 8=FIXT.1.19=14135=334=1149=24ab46f784d1b20db435b852086e325052=20250411-01:51:35.79756=Coinbase45=6858=Tag appears more than once371=269372=W373=1310=007
20250411-01:51:35.797948000 : 8=FIXT.1.19=90835=W49=Coinbase56=24ab46f784d1b20db435b852086e325034=6950=TEST52=20250411-01:51:35.451872369=2262=b7f6c79a-636c-490b-8bc5-37cb784406ba83=1597570840893=N55=BTC-USD1682=full_trading268=10269=0278=4d037208-2072-480f-98ac-7be9c24f18f4270=1.93271=0.52331606269=0278=b598f678-da6e-4c01-90ed-d702c42f8a65270=1.93271=0.52331606269=0278=5f69b1a0-b5d1-4715-9be1-9bdf008d97d7270=1.93271=0.52331606269=0278=ef063d15-248a-4eae-97f4-278be5106d80270=1.93271=0.52331606269=0278=f8b20207-84bc-44e9-a2fe-9ad775e2ecb1270=1.93271=0.52331606269=0278=75bce2b7-bc58-4479-8bfb-144f88f2262b270=1.93271=0.52331606269=0278=1f6e2a79-8b10-4a7f-89de-0f1fa03692c7270=1.93271=0.52331606269=0278=d1b80bf5-9b17-44b4-9577-6fe71170b578270=1.93271=0.52331606269=0278=b891e26a-c20c-4fce-ba1c-487fe139a4cc270=1.93271=0.52331606269=0278=5d06d3f6-3189-4394-b3c5-6a2bda14b6d1270=1.93271=0.5233160610=224
20250411-01:51:35.798466000 : 8=FIXT.1.19=14135=334=1249=24ab46f784d1b20db435b852086e325052=20250411-01:51:35.79856=Coinbase45=6958=Tag appears more than once371=269372=W373=1310=010
20250411-01:51:35.798540000 : 8=FIXT.1.19=90835=W49=Coinbase56=24ab46f784d1b20db435b852086e325034=7050=TEST52=20250411-01:51:35.452122369=2262=b7f6c79a-636c-490b-8bc5-37cb784406ba83=1597570840893=N55=BTC-USD1682=full_trading268=10269=0278=e5791c0f-3937-4a66-9b98-26f79a3891be270=1.93271=0.52331606269=0278=c62591c6-7dfa-46a7-8f20-6a5f22804999270=1.93271=0.52331606269=0278=7c503558-c0b8-457b-8c46-71ece3f7fc8a270=1.93271=0.52331606269=0278=f763bb56-2f21-4a9b-bd48-f84dc1bd5ee5270=1.93271=0.52331606269=0278=42214b03-1fc2-46b3-9e83-91b23a510e5a270=1.93271=0.52331606269=0278=1c7c52ed-7d39-4326-b3b8-98f05a9b3ef0270=1.93271=0.52331606269=0278=3313309e-45e7-4e7b-8c55-4f9a8ec1b351270=1.93271=0.52331606269=0278=78801ffb-ec5a-4c74-9d08-3e86fd9db4dd270=1.93271=0.52331606269=0278=abe6eea4-1d9c-47d7-847f-2f44aa561b3f270=1.93271=0.52331606269=0278=6a6eb56d-2010-43e2-b78e-5f098081bb64270=1.93271=0.5233160610=138
20250411-01:51:35.799091000 : 8=FIXT.1.19=14135=334=1349=24ab46f784d1b20db435b852086e325052=20250411-01:51:35.79856=Coinbase45=7058=Tag appears more than once371=269372=W373=1310=003
20250411-01:51:35.799247000 : 8=FIXT.1.19=90835=W49=Coinbase56=24ab46f784d1b20db435b852086e325034=7150=TEST52=20250411-01:51:35.452372369=2262=b7f6c79a-636c-490b-8bc5-37cb784406ba83=1597570840893=N55=BTC-USD1682=full_trading268=10269=0278=b53c01ff-f450-4b05-8ad1-e7894b45e0e0270=1.93271=0.52331606269=0278=4747863e-c0a6-4ef5-8faf-e8934bca4f8b270=1.93271=0.52331606269=0278=81a8a629-57f4-4e3a-ac25-2e9ee1f357c2270=1.93271=0.52331606269=0278=1e239259-7be4-476a-845d-1b92fd951d8b270=1.93271=0.52331606269=0278=189eb272-48f9-4915-b7e1-a86dcc505c4a270=1.93271=0.52331606269=0278=0562b9f7-aae3-4961-bd97-f5b8cde0ec34270=1.93271=0.52331606269=0278=5103331b-7300-487b-bc2c-a6032bf4be7e270=1.93271=0.52331606269=0278=78ac85ac-2478-4991-a084-7286982b77cc270=1.93271=0.52331606269=0278=6993b26d-d6dc-4f99-8a53-9500ae5b4ff1270=1.93271=0.52331606269=0278=1c96ab9d-04a6-465a-87e5-3ed33970178f270=1.93271=0.5233160610=054
20250411-01:51:35.799755000 : 8=FIXT.1.19=14135=334=1449=24ab46f784d1b20db435b852086e325052=20250411-01:51:35.79956=Coinbase45=7158=Tag appears more than once371=269372=W373=1310=006
20250411-01:51:35.799824000 : 8=FIXT.1.19=91935=W49=Coinbase56=24ab46f784d1b20db435b852086e325034=7250=TEST52=20250411-01:51:35.452622369=2262=b7f6c79a-636c-490b-8bc5-37cb784406ba83=1597570840893=N55=BTC-USD1682=full_trading268=10269=0278=6fc0282b-d538-4aa3-8982-bda02bb1b054270=1.93271=0.52331606269=0278=80870aa3-04a2-4d2a-8669-93215130ffee270=1.93271=0.52331606269=0278=b274e872-6923-45fd-b48a-68e685e769cb270=1.93271=0.52331606269=0278=2d4364c0-239c-4f4b-8ce4-2acfe0bb343d270=1.12271=1.00000000269=0278=8fa16a4f-377f-4deb-9a8e-1020aed9edf4270=1.00271=1.00000000269=1278=c5b88ea9-605d-4595-ac52-f7c3f08523ba270=3.55271=6669.15598770269=1278=81523bd3-8912-4789-8761-89a9ee42794b270=3.55271=0.30518966269=1278=60fc75ca-0052-40b7-9f18-a6aad9d31b84270=3.56271=18037.00000000269=1278=ad00e2cd-d925-46a4-9e7e-941c6faed2c7270=3.57271=18027.00000000269=1278=fec191b5-64da-4a15-ab4b-36a0d3d10750270=3.57271=0.2902530110=200
20250411-01:51:35.800503000 : 8=FIXT.1.19=14135=334=1549=24ab46f784d1b20db435b852086e325052=20250411-01:51:35.80056=Coinbase45=7258=Tag appears more than once371=269372=W373=1310=247
20250411-01:51:35.800561000 : 8=FIXT.1.19=92835=W49=Coinbase56=24ab46f784d1b20db435b852086e325034=7350=TEST52=20250411-01:51:35.452873369=2262=b7f6c79a-636c-490b-8bc5-37cb784406ba83=1597570840893=N55=BTC-USD1682=full_trading268=10269=1278=3008d95d-6e0e-48d7-975d-a1044512985d270=3.57271=0.62322946269=1278=02a780aa-8154-4638-a5ca-53b8198cc724270=3.58271=16937.00000000269=1278=911349fb-1960-4904-9a38-0e2497fb7ccb270=3.58271=0.29896312269=1278=d91e89d4-ac5c-4853-9879-ec8ff5e00a71270=3.59271=17163.00000000269=1278=341d0ad8-6c15-4b5e-aebb-e3caa5af575c270=3.60271=17926.00000000269=1278=1c678c80-8046-41e9-b3f2-94dee03e8bb5270=3.60271=0.62322946269=1278=9d239e03-1215-4cc7-ad44-3f4097ee70ea270=3.61271=18058.08928020269=1278=dbb0f332-4189-4df5-879b-e55860b13def270=3.62271=0.28062774269=1278=f7639c39-7e8b-44d1-a2f2-9807e2a3228c270=3.62271=0.27709851269=1278=83be9389-2099-4173-a322-b0933bc99358270=3.62271=19973.0000000010=142
20250411-01:51:35.801040000 : 8=FIXT.1.19=14135=334=1649=24ab46f784d1b20db435b852086e325052=20250411-01:51:35.80056=Coinbase45=7358=Tag appears more than once371=269372=W373=1310=249
20250411-01:51:35.801122000 : 8=FIXT.1.19=91635=W49=Coinbase56=24ab46f784d1b20db435b852086e325034=7450=TEST52=20250411-01:51:35.453123369=2262=b7f6c79a-636c-490b-8bc5-37cb784406ba83=1597570840893=N55=BTC-USD1682=full_trading268=10269=1278=b89abc22-6b6c-4474-b3fc-ffe21f05cd4e270=3.63271=20016.00000000269=1278=ce0af8a3-149c-4603-905a-be65625fe014270=3.64271=0.27806002269=1278=94b8615f-6fa7-4dc9-bbfa-435fe535bebc270=3.64271=22352.63489459269=1278=73ceb8df-80c0-45fa-93c3-d066cf4e6e11270=3.65271=0.61971831269=1278=023b725c-8b27-41a0-a7d8-91dba8c1008c270=3.66271=0.48005297269=1278=96390403-07e6-4352-9f1c-a3c4a4953a5c270=3.67271=0.62322946269=1278=8ae9190b-30e8-4f61-a8a3-76c4e9d7def9270=3.67271=0.61971831269=1278=cae3885d-f5b2-4de1-830c-0085e27bbb69270=3.69271=0.27722678269=1278=b9732128-11b1-44fd-bea3-94da9fc853fb270=3.71271=0.28488329269=1278=818b83a4-e14e-4ad5-b094-6733f0504003270=3.75271=0.2793022510=110
20250411-01:51:35.801756000 : 8=FIXT.1.19=14135=334=1749=24ab46f784d1b20db435b852086e325052=20250411-01:51:35.80156=Coinbase45=7458=Tag appears more than once371=269372=W373=1310=252
20250411-01:51:35.801838000 : 8=FIXT.1.19=91235=W49=Coinbase56=24ab46f784d1b20db435b852086e325034=7550=TEST52=20250411-01:51:35.453373369=2262=b7f6c79a-636c-490b-8bc5-37cb784406ba83=1597570840893=N55=BTC-USD1682=full_trading268=10269=1278=3e6990a0-8ef4-4968-8ee8-89b7346c197d270=3.76271=0.28131365269=1278=342794c8-a9d2-4aa5-9886-a819398d69c6270=3.88271=0.27719712269=1278=2839680b-48b3-4f53-86b1-9269987275e7270=3.91271=0.26621275269=1278=fd7b5361-29f8-4b35-bae5-232a64f657b4270=3.95271=0.26131406269=1278=5edaeed0-fae9-4f36-8c77-6fbedf61eefc270=4.02271=0.25091227269=1278=fdbbfd04-ba67-4b23-bbc1-f87f929e7e81270=4.07271=0.24812642269=1278=534b2a85-0852-420d-928b-70cdb6ba2457270=4.10271=0.26961968269=1278=b009f8a1-4a39-493b-b96e-d783e981c915270=4.26271=0.25019574269=1278=729a899c-ac2d-4541-b0a2-cbdd5df9bf98270=10.00271=10.00000000269=1278=eb1e5d45-d081-4ef8-a83e-1f5348fbda96270=10.00271=10.0000000010=203
20250411-01:51:35.802345000 : 8=FIXT.1.19=14135=334=1849=24ab46f784d1b20db435b852086e325052=20250411-01:51:35.80256=Coinbase45=7558=Tag appears more than once371=269372=W373=1310=255
20250411-01:51:35.802422000 : 8=FIXT.1.19=92835=W49=Coinbase56=24ab46f784d1b20db435b852086e325034=7650=TEST52=20250411-01:51:35.453623369=2262=b7f6c79a-636c-490b-8bc5-37cb784406ba83=1597570840893=N55=BTC-USD1682=full_trading268=10269=1278=0cd67977-85eb-45fa-ae72-d45b92ca24f4270=10.00271=10.00000000269=1278=5d931559-6758-4b75-9d6d-6438d25b497f270=10.00271=10.00000000269=1278=57e43d1d-644a-493e-acd3-69dc5e64dcde270=10.00271=10.00000000269=1278=c1566121-2b63-494d-ac2d-973e9f0115c0270=10.00271=10.00000000269=1278=d0c4a771-9035-4db9-ae7b-ad2d1db5646d270=10.00271=10.00000000269=1278=52c644ea-628a-4576-8e7e-27ec4c90398b270=10.00271=10.00000000269=1278=c3483f66-d8ce-489a-90b9-2bce69e054ee270=10.00271=10.00000000269=1278=55992a5c-cbcd-464a-8f8d-8b58e81e5c0b270=10.00271=10.00000000269=1278=19077009-6f26-4e2d-9dab-04a28231b752270=10.00271=10.00000000269=1278=692097d1-c978-4024-95e9-2bf348b64bbd270=10.00271=10.0000000010=075
20250411-01:51:35.802906000 : 8=FIXT.1.19=14135=334=1949=24ab46f784d1b20db435b852086e325052=20250411-01:51:35.80256=Coinbase45=7658=Tag appears more than once371=269372=W373=1310=001
20250411-01:51:35.802973000 : 8=FIXT.1.19=93535=W49=Coinbase56=24ab46f784d1b20db435b852086e325034=7750=TEST52=20250411-01:51:35.453873369=2262=b7f6c79a-636c-490b-8bc5-37cb784406ba83=1597570840893=N55=BTC-USD1682=full_trading268=10269=1278=99a92935-11b7-4f21-a64c-c746b53d1777270=10.00271=10.00000000269=1278=dc024b0b-0337-4215-9669-5e5636834397270=10.00271=10.00000000269=1278=c90fcc3a-a36c-4c14-b57f-6db78762e017270=10.00271=10.00000000269=1278=7841891a-bb7c-4034-97c1-41164185edc7270=1000.00271=3.10000000269=1278=381c9fa7-1add-4dd2-9233-f41e2c8821fe270=1000.00271=3.10000000269=1278=928e65c2-7e2d-478b-9310-414fb77f5aae270=1000.00271=3.10000000269=1278=ad4bd3ac-9276-40d5-90f9-e47b1d8ee953270=1000.00271=3.10000000269=1278=79e799dc-4a3d-4922-ad1a-f74eb7eff789270=1000.00271=3.10000000269=1278=04f642b7-750f-4967-b786-0d48eea0f158270=1000.00271=3.10000000269=1278=d0ad653d-3272-4a3b-ba7a-a52029a67a92270=1000.00271=3.1000000010=114
20250411-01:51:35.803397000 : 8=FIXT.1.19=14135=334=2049=24ab46f784d1b20db435b852086e325052=20250411-01:51:35.80356=Coinbase45=7758=Tag appears more than once371=269372=W373=1310=251
20250411-01:51:35.803541000 : 8=FIXT.1.19=93835=W49=Coinbase56=24ab46f784d1b20db435b852086e325034=7850=TEST52=20250411-01:51:35.454123369=2262=b7f6c79a-636c-490b-8bc5-37cb784406ba83=1597570840893=N55=BTC-USD1682=full_trading268=10269=1278=cad40464-4c62-4bf3-8444-c487fcc8dd01270=1000.00271=3.10000000269=1278=426c6428-d481-4ff7-9de3-f00ff219d654270=1000.00271=3.10000000269=1278=1ed1152d-8c1a-4b29-acdd-bbd1a5c5f35f270=1000.00271=3.10000000269=1278=66526051-b5cb-442f-af90-c609be0a9796270=1000.00271=3.10000000269=1278=f68e4659-5785-4ee9-ac24-3186640a2752270=1000.00271=3.10000000269=1278=38070d38-80a9-4898-8ef7-a0a9da5a4123270=1000.00271=3.10000000269=1278=e4d2d308-ed11-49db-850e-3cbd8258395d270=1000.00271=3.10000000269=1278=d6cfaadc-97ea-43c1-898d-40faea9c1477270=1000.00271=3.10000000269=1278=36876bea-9e3a-4018-b0ac-b75cb8c16953270=1000.00271=3.10000000269=1278=eb244bc5-49e8-4aa3-af8b-3d1a67c90a08270=1000.00271=3.1000000010=078
20250411-01:51:35.803938000 : 8=FIXT.1.19=14135=334=2149=24ab46f784d1b20db435b852086e325052=20250411-01:51:35.80356=Coinbase45=7858=Tag appears more than once371=269372=W373=1310=253
20250411-01:51:35.804016000 : 8=FIXT.1.19=93835=W49=Coinbase56=24ab46f784d1b20db435b852086e325034=7950=TEST52=20250411-01:51:35.454373369=2262=b7f6c79a-636c-490b-8bc5-37cb784406ba83=1597570840893=N55=BTC-USD1682=full_trading268=10269=1278=3efba776-29ad-4aeb-82d8-0824f161471e270=1000.00271=3.10000000269=1278=de0ddebd-0ca8-4eca-9985-77c10c8629a9270=1000.00271=3.10000000269=1278=dde4408a-fb6b-441c-a7f3-7b8b23ffdb1f270=1000.00271=3.10000000269=1278=3ebd6434-070f-4b4d-8cf3-00368112466d270=1000.00271=3.10000000269=1278=7aa98e13-65f3-4058-9f91-c1f452d02710270=1000.00271=3.10000000269=1278=e86a1fec-3610-460d-8d85-4e1e222ee159270=1000.00271=3.10000000269=1278=6dfac057-72b1-4f2c-b110-03766dea0d31270=1000.00271=3.10000000269=1278=bbb7d0ea-d251-4612-b53e-e528cc0a24ab270=1000.00271=3.10000000269=1278=0782ca37-48cf-4ff3-a74a-35674661586c270=1000.00271=3.10000000269=1278=aead437d-4b62-457f-ac83-62c7cc329fd1270=1000.00271=3.1000000010=157
20250411-01:51:35.804485000 : 8=FIXT.1.19=14135=334=2249=24ab46f784d1b20db435b852086e325052=20250411-01:51:35.80456=Coinbase45=7958=Tag appears more than once371=269372=W373=1310=000
20250411-01:51:35.804557000 : 8=FIXT.1.19=93835=W49=Coinbase56=24ab46f784d1b20db435b852086e325034=8050=TEST52=20250411-01:51:35.454623369=2262=b7f6c79a-636c-490b-8bc5-37cb784406ba83=1597570840893=N55=BTC-USD1682=full_trading268=10269=1278=af5d47bc-a008-4567-b24f-b0298f250471270=1000.00271=3.10000000269=1278=4c260f58-c427-4a9a-969a-44024ae0c714270=1000.00271=3.10000000269=1278=8c7672e5-7ee8-4fbd-8fdf-7e74e9a77db7270=1000.00271=3.10000000269=1278=b53ec3cc-9abe-4570-b903-34d52148073e270=1000.00271=3.10000000269=1278=37ce984a-0387-4ac9-9094-b83f722036ba270=1000.00271=3.10000000269=1278=0d383649-dc6c-4df2-b821-aa0018f132c7270=1000.00271=3.10000000269=1278=e39ae0ce-9e7f-4f0d-a765-5308d473bb61270=1000.00271=3.10000000269=1278=4882324e-3b5c-4b7a-b096-e8c6d9888671270=1000.00271=3.10000000269=1278=6e5c7dbd-a2cc-401f-a5b2-3902088f4ab2270=1000.00271=3.10000000269=1278=10ffac08-946a-4a30-b57a-0d78450345d9270=1000.00271=3.1000000010=195
20250411-01:51:35.805006000 : 8=FIXT.1.19=14135=334=2349=24ab46f784d1b20db435b852086e325052=20250411-01:51:35.80456=Coinbase45=8058=Tag appears more than once371=269372=W373=1310=249
20250411-01:51:35.805071000 : 8=FIXT.1.19=93835=W49=Coinbase56=24ab46f784d1b20db435b852086e325034=8150=TEST52=20250411-01:51:35.454873369=2262=b7f6c79a-636c-490b-8bc5-37cb784406ba83=1597570840893=N55=BTC-USD1682=full_trading268=10269=1278=67784af5-72bf-4d16-a6b3-25336e2c1843270=1000.00271=3.10000000269=1278=4d8b3bbc-0dc2-4044-875c-c079ec538136270=1000.00271=3.10000000269=1278=dfba5f1e-21f5-48e3-adce-b8b6bfe71467270=1000.00271=3.10000000269=1278=e51b4e33-5eaa-46ef-936b-a74a890397e8270=1000.00271=3.10000000269=1278=8cf5dfa8-858b-48a3-9d94-78522c257473270=1000.00271=3.10000000269=1278=a153b9d2-993d-4f03-a974-b8a081e128e8270=1000.00271=3.10000000269=1278=1eebe866-0f6e-4d4a-a28b-78f4e3368b0a270=1000.00271=3.10000000269=1278=300132d8-113f-4bf7-ba0c-4d93a272f55b270=1000.00271=3.10000000269=1278=757f3122-27d2-4f32-90b8-ead1eef9b936270=1000.00271=3.10000000269=1278=2b68b5de-4153-4cac-ace3-102e4fa788fd270=1000.00271=3.1000000010=090
20250411-01:51:35.805582000 : 8=FIXT.1.19=14135=334=2449=24ab46f784d1b20db435b852086e325052=20250411-01:51:35.80556=Coinbase45=8158=Tag appears more than once371=269372=W373=1310=252
20250411-01:51:35.805687000 : 8=FIXT.1.19=93835=W49=Coinbase56=24ab46f784d1b20db435b852086e325034=8250=TEST52=20250411-01:51:35.455123369=2262=b7f6c79a-636c-490b-8bc5-37cb784406ba83=1597570840893=N55=BTC-USD1682=full_trading268=10269=1278=b01f252a-1657-4df0-a122-58a23109a7c2270=1000.00271=3.10000000269=1278=dbc57e4e-6abd-4d66-8d18-bd13caaa77b1270=1000.00271=3.10000000269=1278=948b05dc-a481-409f-b8ad-a502eb595906270=1000.00271=3.10000000269=1278=e00f9703-6e16-4237-a2c6-701829d11bf1270=1000.00271=3.10000000269=1278=fd52f47a-3f11-47bc-9952-9708617d0ecd270=1000.00271=3.10000000269=1278=f7f75b14-27c3-469c-89fb-6a98b43c61bf270=1000.00271=3.10000000269=1278=25dbeb09-7901-4280-b0c3-720d7ed03d7d270=1000.00271=3.10000000269=1278=52164a1f-599f-4c43-a9ed-f93403506e67270=1000.00271=3.10000000269=1278=c71c35ea-f60f-4a41-b43a-4947bbcbafad270=1000.00271=3.10000000269=1278=2de342bc-a1be-46f3-9fc6-731297726934270=1000.00271=3.1000000010=082
20250411-01:51:35.806270000 : 8=FIXT.1.19=14135=334=2549=24ab46f784d1b20db435b852086e325052=20250411-01:51:35.80556=Coinbase45=8258=Tag appears more than once371=269372=W373=1310=254
20250411-01:51:35.806343000 : 8=FIXT.1.19=93835=W49=Coinbase56=24ab46f784d1b20db435b852086e325034=8350=TEST52=20250411-01:51:35.455373369=2262=b7f6c79a-636c-490b-8bc5-37cb784406ba83=1597570840893=N55=BTC-USD1682=full_trading268=10269=1278=7ff4c5fc-bc9b-4845-940b-4837a672e13a270=1000.00271=3.10000000269=1278=2d270775-33eb-4328-8dad-7d206612f9f6270=1000.00271=3.10000000269=1278=c4754378-f787-4100-81af-564443a86a91270=1000.00271=3.10000000269=1278=59e16255-05eb-4fdc-8be1-3c4f83fc094e270=1000.00271=3.10000000269=1278=041b2f98-1185-49cb-964a-f0456b71e692270=1000.00271=3.10000000269=1278=9a2f3529-481e-4e50-a123-7a2095fe6b2c270=1000.00271=3.10000000269=1278=9ed552a3-3295-4878-85dd-87b7b5590212270=1000.00271=3.10000000269=1278=54bec5c2-bafd-4d7d-851d-59e3553a053f270=1000.00271=3.10000000269=1278=543c1acf-52f2-442b-a893-f7aa9a5dfbd1270=1000.00271=3.10000000269=1278=fec999be-cbd0-42ef-b9c3-82ca92ef0b58270=1000.00271=3.1000000010=245
20250411-01:51:35.806795000 : 8=FIXT.1.19=14135=334=2649=24ab46f784d1b20db435b852086e325052=20250411-01:51:35.80656=Coinbase45=8358=Tag appears more than once371=269372=W373=1310=001
20250411-01:51:35.806860000 : 8=FIXT.1.19=93835=W49=Coinbase56=24ab46f784d1b20db435b852086e325034=8450=TEST52=20250411-01:51:35.455623369=2262=b7f6c79a-636c-490b-8bc5-37cb784406ba83=1597570840893=N55=BTC-USD1682=full_trading268=10269=1278=24528176-3fc6-45b2-b2f3-9f784c01495a270=1000.00271=3.10000000269=1278=12081678-66a6-4435-a3d7-b65f959cf2ac270=1000.00271=3.10000000269=1278=e7fb6165-8f1a-4b5e-b095-e232b83ee951270=1000.00271=3.10000000269=1278=83ce6582-410a-40bf-9831-8f3d20e3a629270=1000.00271=3.10000000269=1278=bc3a930b-0567-46ba-86a4-712f76466b0b270=1000.00271=3.10000000269=1278=15704973-f5ff-457d-ab31-8f99bb76bf7e270=1000.00271=3.10000000269=1278=7159045b-cbd5-458f-b91f-9fa5241b14b5270=1000.00271=3.10000000269=1278=9fa52a90-f03f-4940-b5ee-39ab937b86f1270=1000.00271=3.10000000269=1278=220f55cd-a279-4bf0-9c80-1dca086d85dc270=1000.00271=3.10000000269=1278=2b1eb468-6bcd-4117-a7c0-214d643ddad4270=1000.00271=3.1000000010=109
20250411-01:51:35.807430000 : 8=FIXT.1.19=14135=334=2749=24ab46f784d1b20db435b852086e325052=20250411-01:51:35.80756=Coinbase45=8458=Tag appears more than once371=269372=W373=1310=004
20250411-01:51:35.807598000 : 8=FIXT.1.19=93835=W49=Coinbase56=24ab46f784d1b20db435b852086e325034=8550=TEST52=20250411-01:51:35.455873369=2262=b7f6c79a-636c-490b-8bc5-37cb784406ba83=1597570840893=N55=BTC-USD1682=full_trading268=10269=1278=cc23185d-e72e-42cb-8210-61bab29cd778270=1000.00271=3.10000000269=1278=69bb228b-973b-4176-8708-3231cc40102a270=1000.00271=3.10000000269=1278=2ec8035d-7962-4195-8388-c9fbad52ac8a270=1000.00271=3.10000000269=1278=7d39e416-0b7b-471f-a9ac-455ab1bce5a7270=1000.00271=3.10000000269=1278=7067378d-2a65-41f2-acb0-ef30ddbc3e5a270=1000.00271=3.10000000269=1278=bf3fde78-6cff-4477-b381-4b5d2e68f36f270=1000.00271=3.10000000269=1278=93a2a8a3-61d4-410c-9446-8eabaafc5f29270=1000.00271=3.10000000269=1278=5afddb61-63ab-417b-a28a-41c4c03a6612270=1000.00271=3.10000000269=1278=a4280417-189c-4f76-9d2e-6ec652010bf5270=1000.00271=3.10000000269=1278=ddeb78a2-e110-4828-ba3d-c9b4837e7dd7270=1000.00271=3.1000000010=130
20250411-01:51:35.808119000 : 8=FIXT.1.19=14135=334=2849=24ab46f784d1b20db435b852086e325052=20250411-01:51:35.80756=Coinbase45=8558=Tag appears more than once371=269372=W373=1310=006
20250411-01:51:35.808246000 : 8=FIXT.1.19=93835=W49=Coinbase56=24ab46f784d1b20db435b852086e325034=8650=TEST52=20250411-01:51:35.456123369=2262=b7f6c79a-636c-490b-8bc5-37cb784406ba83=1597570840893=N55=BTC-USD1682=full_trading268=10269=1278=fcec6c90-441a-4f4a-a94e-9003355657ef270=1000.00271=3.10000000269=1278=6db15389-dfb3-4156-8a4e-ce2ac80f2b15270=1000.00271=3.10000000269=1278=47dfefc3-6f05-4b57-8aec-2bf3e6c70c2d270=1000.00271=3.10000000269=1278=fb9fd019-4b4f-4880-82bb-3df6d1ef468a270=1000.00271=3.10000000269=1278=2cff9acd-42cb-43a5-8d50-51e676b7e763270=1000.00271=3.10000000269=1278=6e6eeb59-4728-4811-9a44-c857df6aca42270=1000.00271=3.10000000269=1278=81798560-263f-4819-a528-5f3fbbc7b042270=1000.00271=3.10000000269=1278=81fbf9a8-82f4-4fe4-9fa5-3773b212ebf4270=1000.00271=3.10000000269=1278=5d3b9566-276d-47fe-a111-12c17f53f501270=1000.00271=3.10000000269=1278=8eb1b3b3-c813-48b1-b839-993672108d91270=1000.00271=3.1000000010=019
20250411-01:51:35.808688000 : 8=FIXT.1.19=14135=334=2949=24ab46f784d1b20db435b852086e325052=20250411-01:51:35.80856=Coinbase45=8658=Tag appears more than once371=269372=W373=1310=009
20250411-01:51:35.808757000 : 8=FIXT.1.19=93835=W49=Coinbase56=24ab46f784d1b20db435b852086e325034=8750=TEST52=20250411-01:51:35.456373369=2262=b7f6c79a-636c-490b-8bc5-37cb784406ba83=1597570840893=N55=BTC-USD1682=full_trading268=10269=1278=4feb6e93-6149-481b-8d58-e1c8e6c5cda1270=1000.00271=3.10000000269=1278=f8611e72-4056-4b7c-9779-4d54cd151d44270=1000.00271=3.10000000269=1278=7a129f7c-d9ba-4ea3-a267-b7d82b2e07d9270=1000.00271=3.10000000269=1278=01f359f0-c38f-416b-af00-183907218793270=1000.00271=3.10000000269=1278=11741cec-9c08-4a20-99dc-6b9f63130b0e270=1000.00271=3.10000000269=1278=08db2574-ad52-4520-ab5b-c3c7591eb781270=1000.00271=3.10000000269=1278=b06f2249-179c-4a15-8e98-7b76083b808b270=1000.00271=3.10000000269=1278=9e88fede-6d19-4c1f-863b-5a7d66781436270=1000.00271=3.10000000269=1278=75e1d8b4-7201-41fe-a687-7d93420af323270=1000.00271=3.10000000269=1278=d00aa7dd-ce7f-4f8b-9a2e-880c1ea30845270=1000.00271=3.1000000010=044
20250411-01:51:35.809334000 : 8=FIXT.1.19=14135=334=3049=24ab46f784d1b20db435b852086e325052=20250411-01:51:35.80956=Coinbase45=8758=Tag appears more than once371=269372=W373=1310=003
20250411-01:51:35.809407000 : 8=FIXT.1.19=93835=W49=Coinbase56=24ab46f784d1b20db435b852086e325034=8850=TEST52=20250411-01:51:35.456623369=2262=b7f6c79a-636c-490b-8bc5-37cb784406ba83=1597570840893=N55=BTC-USD1682=full_trading268=10269=1278=584a483f-23bf-4d8b-809f-69cf3c110f60270=1000.00271=3.10000000269=1278=dc98524e-27e2-4863-99e4-7a0097a6ee90270=1000.00271=3.10000000269=1278=82a11ac9-4f46-44b7-a0bc-a5a4cfe686e0270=1000.00271=3.10000000269=1278=f946bb05-900c-41fc-9908-41489e97ff20270=1000.00271=3.10000000269=1278=1f9186d6-0312-4677-ba96-fdb014cdff2c270=1000.00271=3.10000000269=1278=c3b67be7-2b63-4884-b311-80f28496c2c4270=1000.00271=3.10000000269=1278=6576c7f8-a4e2-4417-b854-5fef0e705fbe270=1000.00271=3.10000000269=1278=c2102c71-62f0-4eee-ae60-0777ed26a8e6270=1000.00271=3.10000000269=1278=c823a2b6-849e-4839-a2fd-cd9f459cae6c270=1000.00271=3.10000000269=1278=a051e195-4472-4a8a-8591-08a2c04a33c4270=1000.00271=3.1000000010=192
20250411-01:51:35.809909000 : 8=FIXT.1.19=14135=334=3149=24ab46f784d1b20db435b852086e325052=20250411-01:51:35.80956=Coinbase45=8858=Tag appears more than once371=269372=W373=1310=005
20250411-01:51:35.809975000 : 8=FIXT.1.19=93835=W49=Coinbase56=24ab46f784d1b20db435b852086e325034=8950=TEST52=20250411-01:51:35.456873369=2262=b7f6c79a-636c-490b-8bc5-37cb784406ba83=1597570840893=N55=BTC-USD1682=full_trading268=10269=1278=ec81b8c4-b703-4afd-a701-ce34011f60f6270=1000.00271=3.10000000269=1278=b1172677-f493-4f32-a200-0710cf8c397f270=1000.00271=3.10000000269=1278=b1a58a75-5fca-43db-b9c6-a26920e8f66e270=1000.00271=3.10000000269=1278=038bea41-b91d-4884-b992-3e5431ef9857270=1000.00271=3.10000000269=1278=55063782-f2ea-4c84-9491-8e8e89d1dfd1270=1000.00271=3.10000000269=1278=bb2011e8-d05d-40ac-9e9c-3b720422e38d270=1000.00271=3.10000000269=1278=64dd3b4a-ce8a-4b63-9937-266e832c0f21270=1000.00271=3.10000000269=1278=d64f7d2a-aa83-486c-92a8-3314c4eddd58270=1000.00271=3.10000000269=1278=0df9641b-d89d-4222-a8ea-bcddf0d555f5270=1000.00271=3.10000000269=1278=7a315b16-a05f-408d-b8c1-2704af9bf767270=1000.00271=3.1000000010=188
20250411-01:51:35.810346000 : 8=FIXT.1.19=14135=334=3249=24ab46f784d1b20db435b852086e325052=20250411-01:51:35.81056=Coinbase45=8958=Tag appears more than once371=269372=W373=1310=255
20250411-01:51:35.810415000 : 8=FIXT.1.19=93835=W49=Coinbase56=24ab46f784d1b20db435b852086e325034=9050=TEST52=20250411-01:51:35.457123369=2262=b7f6c79a-636c-490b-8bc5-37cb784406ba83=1597570840893=N55=BTC-USD1682=full_trading268=10269=1278=0e9712a8-d00f-4864-a478-f7f591718f91270=1000.00271=3.10000000269=1278=94db025d-eada-49e3-b13c-b667ca07f829270=1000.00271=3.10000000269=1278=a88ccd1f-8f8d-46af-8fb6-20adba35f7d1270=1000.00271=3.10000000269=1278=99d4e235-c8ec-4efc-938c-9a1923eafc96270=1000.00271=3.10000000269=1278=a4fc7173-7583-4f8b-b256-2921bef83c84270=1000.00271=3.10000000269=1278=18f8afd4-8bbc-4ffa-8e8f-0c1834d74472270=1000.00271=3.10000000269=1278=21fc8cb6-f894-4d09-884e-810b8ebf2ef3270=1000.00271=3.10000000269=1278=0c13b9e6-6797-4b3e-90ce-a1885b26ba53270=1000.00271=3.10000000269=1278=6d8da581-3998-4fc0-99b6-3c5edbd514cb270=1000.00271=3.10000000269=1278=67a70307-be50-4065-872b-47e0de473bc4270=1000.00271=3.1000000010=095
20250411-01:51:35.810872000 : 8=FIXT.1.19=14135=334=3349=24ab46f784d1b20db435b852086e325052=20250411-01:51:35.81056=Coinbase45=9058=Tag appears more than once371=269372=W373=1310=248
20250411-01:51:35.810964000 : 8=FIXT.1.19=93835=W49=Coinbase56=24ab46f784d1b20db435b852086e325034=9150=TEST52=20250411-01:51:35.457373369=2262=b7f6c79a-636c-490b-8bc5-37cb784406ba83=1597570840893=N55=BTC-USD1682=full_trading268=10269=1278=8ce7be0b-98de-46d0-b1b6-307a4bec36e2270=1000.00271=3.10000000269=1278=856b22f8-5884-4739-adc0-bdd851c5c07d270=1000.00271=3.10000000269=1278=c00ae651-a76b-4bfd-be16-3672b345fe29270=1000.00271=3.10000000269=1278=cae248f9-16fc-44ea-9b79-1dacfc285db6270=1000.00271=3.10000000269=1278=42bb223c-88c6-4a18-8ff3-4fd8d9efda8d270=1000.00271=3.10000000269=1278=d7188b01-22b6-4837-a720-077601f7f483270=1000.00271=3.10000000269=1278=5d85a0a6-ddd9-4e0e-9a1a-7f418ef588e5270=1000.00271=3.10000000269=1278=bff4c39f-7a80-42ce-a178-b1221792e445270=1000.00271=3.10000000269=1278=9ea3d263-b5ab-46c5-bf27-8c0e3e0e5e9e270=1000.00271=3.10000000269=1278=b93347df-d2ab-48ec-b326-4454e64f1d4e270=1000.00271=3.1000000010=065
20250411-01:51:35.811931000 : 8=FIXT.1.19=14135=334=3449=24ab46f784d1b20db435b852086e325052=20250411-01:51:35.81156=Coinbase45=9158=Tag appears more than once371=269372=W373=1310=251
20250411-01:51:35.812152000 : 8=FIXT.1.19=93835=W49=Coinbase56=24ab46f784d1b20db435b852086e325034=9250=TEST52=20250411-01:51:35.457624369=2262=b7f6c79a-636c-490b-8bc5-37cb784406ba83=1597570840893=N55=BTC-USD1682=full_trading268=10269=1278=57acc40d-8478-444a-990f-067a8e8e846e270=1000.00271=3.10000000269=1278=34419ae2-2c16-427b-a290-845419760fd5270=1000.00271=3.10000000269=1278=ab41de2d-5def-4986-b56e-243d2f99a57c270=1000.00271=3.10000000269=1278=9025524c-03a9-407a-a58a-5258c4ea0a0b270=1000.00271=3.10000000269=1278=60766318-112b-4d83-a384-55693de75519270=1000.00271=3.10000000269=1278=c19b6a2c-086b-4fc1-8dfe-51cb2dc12c1d270=1000.00271=3.10000000269=1278=11126433-0f9c-4450-a35a-39b878e85e68270=1000.00271=3.10000000269=1278=e2e620ee-44fb-4630-a890-d331ba5b2fae270=1000.00271=3.10000000269=1278=9ccf6d4b-a6ca-4a1f-a7bb-77f400ace0c8270=1000.00271=3.10000000269=1278=0e8d6c10-8421-4f19-97dc-d70e715d9033270=1000.00271=3.1000000010=118
20250411-01:51:35.813105000 : 8=FIXT.1.19=14135=334=3549=24ab46f784d1b20db435b852086e325052=20250411-01:51:35.81256=Coinbase45=9258=Tag appears more than once371=269372=W373=1310=254
20250411-01:51:35.813255000 : 8=FIXT.1.19=93835=W49=Coinbase56=24ab46f784d1b20db435b852086e325034=9350=TEST52=20250411-01:51:35.457874369=2262=b7f6c79a-636c-490b-8bc5-37cb784406ba83=1597570840893=N55=BTC-USD1682=full_trading268=10269=1278=f31ecd5d-8231-44ea-a5c2-0fcc5a699401270=1000.00271=3.10000000269=1278=37fbb559-dc52-48fe-ab65-24910edc338a270=1000.00271=3.10000000269=1278=bc1435c5-c59c-4017-9e59-f1073f04c7e2270=1000.00271=3.10000000269=1278=9c8e1397-0cee-4b05-a66f-5594040791c4270=1000.00271=3.10000000269=1278=248b6703-f829-42bb-a551-4be3075c381e270=1000.00271=3.10000000269=1278=16d257b0-bc92-44f0-822d-3eba61af4bda270=1000.00271=3.10000000269=1278=06257aa1-4043-4cdb-9286-4342b8e59108270=1000.00271=3.10000000269=1278=210ec210-1443-47dc-9e43-9c9ea720a6c3270=1000.00271=3.10000000269=1278=8b79da5d-b78c-4011-b55f-b35c16dc3724270=1000.00271=3.10000000269=1278=076c3703-1104-4e15-a38a-d95bf133f0c5270=1000.00271=3.1000000010=137
20250411-01:51:35.814093000 : 8=FIXT.1.19=14135=334=3649=24ab46f784d1b20db435b852086e325052=20250411-01:51:35.81356=Coinbase45=9358=Tag appears more than once371=269372=W373=1310=001
20250411-01:51:35.814189000 : 8=FIXT.1.19=93835=W49=Coinbase56=24ab46f784d1b20db435b852086e325034=9450=TEST52=20250411-01:51:35.458124369=2262=b7f6c79a-636c-490b-8bc5-37cb784406ba83=1597570840893=N55=BTC-USD1682=full_trading268=10269=1278=f5a3155c-e449-4102-870d-ab8c8dd24c3d270=1000.00271=3.10000000269=1278=1af2681f-2dec-4d25-aaeb-89b8867b4a3c270=1000.00271=3.10000000269=1278=65c3088d-192a-4213-85a3-7257aa8b20a3270=1000.00271=3.10000000269=1278=2aa7989b-5601-4899-8143-01dda3255e4f270=1000.00271=3.10000000269=1278=099b432c-fa2e-4fd7-952e-22f6debf6877270=1000.00271=3.10000000269=1278=2e71cc31-1235-4b7b-a728-e3335631fe5a270=1000.00271=3.10000000269=1278=ce471ffc-1e26-4afe-afab-27ee5ac8debe270=1000.00271=3.10000000269=1278=113b7fc6-8574-40eb-8682-d077245b84f2270=1000.00271=3.10000000269=1278=bcebce2c-eda8-4b85-841d-27ede39fc5a1270=1000.00271=3.10000000269=1278=0aedaae5-6cc6-4a34-8e48-5e67a5ccc148270=1000.00271=3.1000000010=226
20250411-01:51:35.814652000 : 8=FIXT.1.19=14135=334=3749=24ab46f784d1b20db435b852086e325052=20250411-01:51:35.81456=Coinbase45=9458=Tag appears more than once371=269372=W373=1310=004
20250411-01:51:35.814718000 : 8=FIXT.1.19=93835=W49=Coinbase56=24ab46f784d1b20db435b852086e325034=9550=TEST52=20250411-01:51:35.458374369=2262=b7f6c79a-636c-490b-8bc5-37cb784406ba83=1597570840893=N55=BTC-USD1682=full_trading268=10269=1278=206e10a5-1173-4860-87b5-7c88afe061f6270=1000.00271=3.10000000269=1278=5c32d94b-696a-4d9b-afa0-665970356008270=1000.00271=3.10000000269=1278=0b7da819-cc1e-4525-a382-ce5b90dc485c270=1000.00271=3.10000000269=1278=2241b3bf-cbbe-44f2-ac75-8032f6283aa8270=1000.00271=3.10000000269=1278=88cada69-adb1-466a-afcd-66e063ad27c0270=1000.00271=3.10000000269=1278=34a52ef5-31c1-4c63-9230-21c85a9a6ba3270=1000.00271=3.10000000269=1278=e109c2c8-fb1d-4ef9-a640-368381323507270=1000.00271=3.10000000269=1278=38fd36c4-4c62-4b4c-8f24-1fe39be94fa1270=1000.00271=3.10000000269=1278=f83f64c8-7d33-472d-a516-9b664ff9c966270=1000.00271=3.10000000269=1278=3411c368-380b-42e6-b656-8552d92904d5270=1000.00271=3.1000000010=000
20250411-01:51:35.815905000 : 8=FIXT.1.19=14135=334=3849=24ab46f784d1b20db435b852086e325052=20250411-01:51:35.81556=Coinbase45=9558=Tag appears more than once371=269372=W373=1310=007
20250411-01:51:35.816045000 : 8=FIXT.1.19=93835=W49=Coinbase56=24ab46f784d1b20db435b852086e325034=9650=TEST52=20250411-01:51:35.458624369=2262=b7f6c79a-636c-490b-8bc5-37cb784406ba83=1597570840893=N55=BTC-USD1682=full_trading268=10269=1278=4803796e-79f3-4aa4-a8cb-37f13899bf01270=1000.00271=3.10000000269=1278=823f8fbf-7e6d-4ae3-adb9-3a822ff6d09a270=1000.00271=3.10000000269=1278=135624df-a204-490f-a68b-63d74ee09908270=1000.00271=3.10000000269=1278=47cfdedf-22b9-402c-93bd-f311103fd3e0270=1000.00271=3.10000000269=1278=f9173d5e-d872-4661-93f6-28f527e931f7270=1000.00271=3.10000000269=1278=06ab1365-fd39-4701-bd7f-1915ad3c7602270=1000.00271=3.10000000269=1278=012a7c59-5ae4-4da5-97ba-2e3254c889fb270=1000.00271=3.10000000269=1278=a9a0d42f-ad9e-4ea9-8bf0-d5a441fded40270=1000.00271=3.10000000269=1278=f3f3930e-be0e-40b4-a97d-d19501a54885270=1000.00271=3.10000000269=1278=261922d0-5c81-4ab6-832f-4eff45f64890270=1000.00271=3.1000000010=214
20250411-01:51:35.817555000 : 8=FIXT.1.19=14135=334=3949=24ab46f784d1b20db435b852086e325052=20250411-01:51:35.81656=Coinbase45=9658=Tag appears more than once371=269372=W373=1310=010
20250411-01:51:35.818048000 : 8=FIXT.1.19=93835=W49=Coinbase56=24ab46f784d1b20db435b852086e325034=9750=TEST52=20250411-01:51:35.458874369=2262=b7f6c79a-636c-490b-8bc5-37cb784406ba83=1597570840893=N55=BTC-USD1682=full_trading268=10269=1278=3af4e45f-56f6-4c69-894d-d56a14894a98270=1000.00271=3.10000000269=1278=1c1dd248-49e4-44aa-9e69-323b0f41fa0e270=1000.00271=3.10000000269=1278=b16b002d-1cd6-4869-9c1b-f15c758611bf270=1000.00271=3.10000000269=1278=a0520e61-28ad-448d-87c1-49f0c7358628270=1000.00271=3.10000000269=1278=152d0b57-086f-48cc-80b3-ff14ee9375ed270=1000.00271=3.10000000269=1278=c55fc264-67d2-4e9c-8cce-6c834feff648270=1000.00271=3.10000000269=1278=27361968-189a-4fa6-a3a2-eead03c640d6270=1000.00271=3.10000000269=1278=f5b01c67-f98f-44b9-a511-7f07f8883d9e270=1000.00271=3.10000000269=1278=75a5c14f-8434-4533-a10e-0bf6e92e1000270=1000.00271=3.10000000269=1278=a9b0a826-3659-4105-9ecc-21bcd27b736f270=1000.00271=3.1000000010=161
20250411-01:51:35.820070000 : 8=FIXT.1.19=14135=334=4049=24ab46f784d1b20db435b852086e325052=20250411-01:51:35.81856=Coinbase45=9758=Tag appears more than once371=269372=W373=1310=005
20250411-01:51:36.024735000 : 8=FIXT.1.19=93835=W49=Coinbase56=24ab46f784d1b20db435b852086e325034=9850=TEST52=20250411-01:51:35.459124369=2262=b7f6c79a-636c-490b-8bc5-37cb784406ba83=1597570840893=N55=BTC-USD1682=full_trading268=10269=1278=1b1bab77-5c52-459b-98e3-e27ff6f8cd04270=1000.00271=3.10000000269=1278=346695f1-fe03-4364-8fc5-006796c8f82f270=1000.00271=3.10000000269=1278=cbbaa36d-2a03-45a2-a230-bd5845d832cd270=1000.00271=3.10000000269=1278=745d4fc0-6710-4c5c-97c3-7b29c4e06839270=1000.00271=3.10000000269=1278=e95fdfba-5db2-4461-8e9c-7bfdf8a9238c270=1000.00271=3.10000000269=1278=33611b39-1fbf-45cc-bf5e-a02bc1f84736270=1000.00271=3.10000000269=1278=51f77b2d-1a69-432d-934b-234eb9e1dfac270=1000.00271=3.10000000269=1278=ab09fdc3-8d50-432f-ab0f-97e8627eac24270=1000.00271=3.10000000269=1278=dde04213-6104-44c5-a811-15834c27b515270=1000.00271=3.10000000269=1278=9af2b85c-4997-4e1b-9147-7d400f059b01270=1000.00271=3.1000000010=174
20250411-01:51:36.025978000 : 8=FIXT.1.19=14135=334=4149=24ab46f784d1b20db435b852086e325052=20250411-01:51:36.02556=Coinbase45=9858=Tag appears more than once371=269372=W373=1310=254
20250411-01:51:36.026157000 : 8=FIXT.1.19=93835=W49=Coinbase56=24ab46f784d1b20db435b852086e325034=9950=TEST52=20250411-01:51:35.459374369=2262=b7f6c79a-636c-490b-8bc5-37cb784406ba83=1597570840893=N55=BTC-USD1682=full_trading268=10269=1278=40870860-7a8a-4419-a117-e511f779abfa270=1000.00271=3.10000000269=1278=3e8fa7bd-dde0-4fe4-bb2e-e6279841b019270=1000.00271=3.10000000269=1278=4dde1422-98d8-405b-88df-bf245291ad7a270=1000.00271=3.10000000269=1278=6ee8b5a8-bc2f-4a0a-9ae4-7ff1b5dae941270=1000.00271=3.10000000269=1278=3ebc1f7a-2bb5-4ef0-a82f-844b9540f6e8270=1000.00271=3.10000000269=1278=a82d5bb9-1f1a-4575-b580-8d9b60863b10270=1000.00271=3.10000000269=1278=14f89bd5-0233-435c-b608-2e19131b8f6c270=1000.00271=3.10000000269=1278=a2e319e5-aab7-41d4-9d19-98d771a3f1d3270=1000.00271=3.10000000269=1278=dc965e0b-075a-4ba4-a498-02c96d1664ba270=1000.00271=3.10000000269=1278=67b6e68f-ac11-4c05-a54a-2adb555b0123270=1000.00271=3.1000000010=187
20250411-01:51:36.027174000 : 8=FIXT.1.19=14135=334=4249=24ab46f784d1b20db435b852086e325052=20250411-01:51:36.02656=Coinbase45=9958=Tag appears more than once371=269372=W373=1310=001
20250411-01:51:36.027341000 : 8=FIXT.1.19=94035=W49=Coinbase56=24ab46f784d1b20db435b852086e325034=10050=TEST52=20250411-01:51:35.459624369=2262=b7f6c79a-636c-490b-8bc5-37cb784406ba83=1597570840893=N55=BTC-USD1682=full_trading268=10269=1278=866f52a1-dad9-49d7-ac4a-9da3075407a3270=1000.00271=3.10000000269=1278=0e38234d-a010-40f6-9c6f-a0d574e773cf270=1000.00271=3.10000000269=1278=d6af6749-e3c8-4938-8741-1d5f177cf8e1270=1000.00271=3.10000000269=1278=45ff5e59-2c4d-45ac-9fde-403662dfd1ca270=1000.00271=3.10000000269=1278=dcac314e-c54f-44e3-b96d-ef71539766ed270=1000.00271=3.10000000269=1278=dd6d14ea-760f-4884-a546-1d3c40ebdd7c270=1000.00271=3.10000000269=1278=4f3da0c6-46eb-4b64-b973-cc43e24abccb270=1000.00271=3.10000000269=1278=aa40cda8-4abd-4f52-999a-1a90ed5bf41a270=1000.00271=3.10000000269=1278=687ee4fc-f626-4e4f-abee-1f0ee5af3f72270=1000.00271=3.10000000269=1278=b1ad1135-67ec-4c96-99cb-a626137f3f16270=10000.00271=1.0000000010=211
20250411-01:51:36.027973000 : 8=FIXT.1.19=14235=334=4349=24ab46f784d1b20db435b852086e325052=20250411-01:51:36.02756=Coinbase45=10058=Tag appears more than once371=269372=W373=1310=035
20250411-01:51:36.028044000 : 8=FIXT.1.19=95635=W49=Coinbase56=24ab46f784d1b20db435b852086e325034=10150=TEST52=20250411-01:51:35.459874369=2262=b7f6c79a-636c-490b-8bc5-37cb784406ba83=1597570840893=N55=BTC-USD1682=full_trading268=10269=1278=e9320f5f-80ae-41ab-af7a-86518d456fb0270=10000.00271=1.00000000269=1278=cd95aff0-36fa-4804-887f-2c3fce3cdc86270=10000.00271=1.00000000269=1278=fbdbcee1-8c29-4478-97df-358d209d8808270=10000.00271=1.00000000269=1278=140f39da-834b-4e42-8e15-6e25287df1f0270=900000.00271=0.00011111269=1278=49f064c5-76fe-4b38-bede-48b60a0a5aec270=900000.00271=0.00011111269=1278=681cf73b-9d37-4101-b940-9da9b1ff61ed270=900000.00271=0.00011111269=1278=3dea1587-e474-4258-b6e8-485c21b56670270=900000.00271=0.00011111269=1278=afd96a7b-3d48-459e-b810-e4ee88353a31270=900000.00271=0.00011111269=1278=a68ae029-b920-4ae7-a775-ccdb800fc252270=900000.00271=0.00001111269=1278=d44508b7-1c9f-4b4f-acb8-99c93d2b99e8270=900000.00271=0.0000111110=225
20250411-01:51:36.028553000 : 8=FIXT.1.19=14235=334=4449=24ab46f784d1b20db435b852086e325052=20250411-01:51:36.02856=Coinbase45=10158=Tag appears more than once371=269372=W373=1310=038
20250411-01:51:36.028623000 : 8=FIXT.1.19=96135=W49=Coinbase56=24ab46f784d1b20db435b852086e325034=10250=TEST52=20250411-01:51:35.460124369=2262=b7f6c79a-636c-490b-8bc5-37cb784406ba83=1597570840893=N55=BTC-USD1682=full_trading268=10269=1278=304ff106-de40-4381-89c5-c93f7f3e32ae270=900000.00271=0.00001111269=1278=08a0fef8-fcbb-4857-8463-2599cf331386270=900000.00271=0.00011111269=1278=07b2856d-f899-417c-82d5-886f0d85125e270=900000.00271=0.00011111269=1278=12ecb45e-6af8-4804-a942-5c997b9d1502270=900000.00271=0.00011111269=1278=98676c5f-b851-473c-817a-b29243092a25270=900000.00271=0.00001111269=1278=09afe685-e71f-4ea0-b164-c27737db126d270=900000.00271=0.00001111269=1278=e71ee98f-c329-428d-9893-629b53015ff6270=900000.00271=0.00001111269=1278=124e6fc1-6dde-452b-be03-c00113c8ebdb270=900000.00271=0.00011111269=1278=b71cc7f5-d7c6-4fc0-a0de-59b0eb7fd063270=1000000.00271=1.00000000269=1278=afec127b-a98c-49cb-893f-e385a7e35d32270=1000000.00271=1.0000000010=177
20250411-01:51:36.029293000 : 8=FIXT.1.19=14235=334=4549=24ab46f784d1b20db435b852086e325052=20250411-01:51:36.02956=Coinbase45=10258=Tag appears more than once371=269372=W373=1310=041
