20250411-01:57:24.129148000 : 8=FIXT.1.19=50635=W49=Coinbase56=24ab46f784d1b20db435b852086e325034=12250=TEST52=20250411-01:57:23.562189369=2262=ba2ffebd-86b0-430d-b535-d9d3b46840d183=1597578360893=Y55=BTC-USD1682=full_trading268=4269=1278=b71cc7f5-d7c6-4fc0-a0de-59b0eb7fd063270=1000000.00271=1.00000000269=1278=afec127b-a98c-49cb-893f-e385a7e35d32270=1000000.00271=1.00000000269=1278=06df7c57-366d-4d2c-acc2-e6c26d60e9c3270=1000000.00271=1.00000000269=1278=b1c4eb2b-90df-44e0-ae4f-515df4086a9d270=9999999.00271=0.0000100010=166
20250411-01:57:24.139474000 : 8=FIXT.1.19=14235=334=4549=24ab46f784d1b20db435b852086e325052=20250411-01:57:24.13256=Coinbase45=12258=Tag appears more than once371=269372=W373=1310=041
20250411-01:57:24.140135000 : 8=FIXT.1.19=28335=X49=Coinbase56=24ab46f784d1b20db435b852086e325034=12350=TEST52=20250411-01:57:23.603455369=2262=ba2ffebd-86b0-430d-b535-d9d3b46840d1268=1279=0269=183=159757836455=BTC-USD270=3.34271=0.6232294660=20250411-01:57:23.60178640=237=a5334cc8-fa7b-442e-b5a0-9b80a6e0241810=176
20250411-01:57:24.142366000 : 8=FIXT.1.19=32635=X49=Coinbase56=24ab46f784d1b20db435b852086e325034=12450=TEST52=20250411-01:57:23.603468369=2262=ba2ffebd-86b0-430d-b535-d9d3b46840d1268=1279=0269=2278=4d60a78e-b39b-420e-b830-bc0f3f4fdde283=159757836555=BTC-USD270=3.53271=0.6232294660=20250411-01:57:23.60178637=a5334cc8-fa7b-442e-b5a0-9b80a6e024185797=210=009
20250411-01:57:24.143994000 : 8=FIXT.1.19=28935=X49=Coinbase56=24ab46f784d1b20db435b852086e325034=12550=TEST52=20250411-01:57:23.603472369=2262=ba2ffebd-86b0-430d-b535-d9d3b46840d1268=1279=2269=1278=a5334cc8-fa7b-442e-b5a0-9b80a6e0241883=159757836655=BTC-USD270=3.34271=0.0000000060=20250411-01:57:23.60178658=FILLED10=087
20250411-01:57:24.348663000 : 8=FIXT.1.19=28435=X49=Coinbase56=24ab46f784d1b20db435b852086e325034=12650=TEST52=20250411-01:57:24.233925369=38262=ba2ffebd-86b0-430d-b535-d9d3b46840d1268=1279=0269=183=159757836755=BTC-USD270=3.25271=0.6232294660=20250411-01:57:24.23245540=237=53f3d6be-e27a-4ea7-8d36-91cf3767f9e010=062
20250411-01:57:24.351380000 : 8=FIXT.1.19=32735=X49=Coinbase56=24ab46f784d1b20db435b852086e325034=12750=TEST52=20250411-01:57:24.233951369=38262=ba2ffebd-86b0-430d-b535-d9d3b46840d1268=1279=0269=2278=4d60a78e-b39b-420e-b830-bc0f3f4fdde283=159757836855=BTC-USD270=3.53271=0.6232294660=20250411-01:57:24.23245537=53f3d6be-e27a-4ea7-8d36-91cf3767f9e05797=210=146
20250411-01:57:24.351601000 : 8=FIXT.1.19=29035=X49=Coinbase56=24ab46f784d1b20db435b852086e325034=12850=TEST52=20250411-01:57:24.233960369=38262=ba2ffebd-86b0-430d-b535-d9d3b46840d1268=1279=2269=1278=53f3d6be-e27a-4ea7-8d36-91cf3767f9e083=159757836955=BTC-USD270=3.25271=0.0000000060=20250411-01:57:24.23245558=FILLED10=220
20250411-01:57:24.403322000 : 8=FIXT.1.19=28435=X49=Coinbase56=24ab46f784d1b20db435b852086e325034=12950=TEST52=20250411-01:57:24.287958369=45262=ba2ffebd-86b0-430d-b535-d9d3b46840d1268=1279=0269=083=159757837055=BTC-USD270=3.74271=0.6232294660=20250411-01:57:24.28652840=237=c95cd686-0aaa-412b-b2b6-74587544109010=122
20250411-01:57:24.403751000 : 8=FIXT.1.19=32735=X49=Coinbase56=24ab46f784d1b20db435b852086e325034=13050=TEST52=20250411-01:57:24.287971369=45262=ba2ffebd-86b0-430d-b535-d9d3b46840d1268=1279=0269=2278=c5b88ea9-605d-4595-ac52-f7c3f08523ba83=159757837155=BTC-USD270=3.55271=0.6232294660=20250411-01:57:24.28652837=c95cd686-0aaa-412b-b2b6-7458754410905797=110=063
20250411-01:57:24.403930000 : 8=FIXT.1.19=29035=X49=Coinbase56=24ab46f784d1b20db435b852086e325034=13150=TEST52=20250411-01:57:24.287974369=45262=ba2ffebd-86b0-430d-b535-d9d3b46840d1268=1279=2269=0278=c95cd686-0aaa-412b-b2b6-74587544109083=159757837255=BTC-USD270=3.74271=0.0000000060=20250411-01:57:24.28652858=FILLED10=014
20250411-01:57:24.461138000 : 8=FIXT.1.19=28435=X49=Coinbase56=24ab46f784d1b20db435b852086e325034=13250=TEST52=20250411-01:57:24.347296369=45262=ba2ffebd-86b0-430d-b535-d9d3b46840d1268=1279=0269=083=159757837355=BTC-USD270=3.88271=0.6197183160=20250411-01:57:24.34584240=237=835e448d-8d5f-4e7f-8939-974c2d8e707b10=212
20250411-01:57:24.461517000 : 8=FIXT.1.19=32735=X49=Coinbase56=24ab46f784d1b20db435b852086e325034=13350=TEST52=20250411-01:57:24.347306369=45262=ba2ffebd-86b0-430d-b535-d9d3b46840d1268=1279=0269=2278=c5b88ea9-605d-4595-ac52-f7c3f08523ba83=159757837455=BTC-USD270=3.55271=0.6197183160=20250411-01:57:24.34584237=835e448d-8d5f-4e7f-8939-974c2d8e707b5797=110=154
20250411-01:57:24.461675000 : 8=FIXT.1.19=29035=X49=Coinbase56=24ab46f784d1b20db435b852086e325034=13450=TEST52=20250411-01:57:24.347310369=45262=ba2ffebd-86b0-430d-b535-d9d3b46840d1268=1279=2269=0278=835e448d-8d5f-4e7f-8939-974c2d8e707b83=159757837555=BTC-USD270=3.88271=0.0000000060=20250411-01:57:24.34584258=FILLED10=100
20250411-01:57:24.517258000 : 8=FIXT.1.19=28435=X49=Coinbase56=24ab46f784d1b20db435b852086e325034=13550=TEST52=20250411-01:57:24.402398369=45262=ba2ffebd-86b0-430d-b535-d9d3b46840d1268=1279=0269=183=159757837655=BTC-USD270=3.28271=0.6197183160=20250411-01:57:24.40105640=237=9c077646-9e6d-43a9-9366-79af7653d77610=056
20250411-01:57:24.517544000 : 8=FIXT.1.19=32735=X49=Coinbase56=24ab46f784d1b20db435b852086e325034=13650=TEST52=20250411-01:57:24.402407369=45262=ba2ffebd-86b0-430d-b535-d9d3b46840d1268=1279=0269=2278=4d60a78e-b39b-420e-b830-bc0f3f4fdde283=159757837755=BTC-USD270=3.53271=0.6197183160=20250411-01:57:24.40105637=9c077646-9e6d-43a9-9366-79af7653d7765797=210=129
20250411-01:57:24.517723000 : 8=FIXT.1.19=29035=X49=Coinbase56=24ab46f784d1b20db435b852086e325034=13750=TEST52=20250411-01:57:24.402411369=45262=ba2ffebd-86b0-430d-b535-d9d3b46840d1268=1279=2269=1278=9c077646-9e6d-43a9-9366-79af7653d77683=159757837855=BTC-USD270=3.28271=0.0000000060=20250411-01:57:24.40105658=FILLED10=199
20250411-01:57:25.376097000 : 8=FIXT.1.19=28435=X49=Coinbase56=24ab46f784d1b20db435b852086e325034=13850=TEST52=20250411-01:57:25.262201369=45262=ba2ffebd-86b0-430d-b535-d9d3b46840d1268=1279=0269=083=159757837955=BTC-USD270=3.75271=0.6232294660=20250411-01:57:25.26094140=237=01fd0015-5bee-45ab-9231-37e12e95051f10=135
20250411-01:57:25.376856000 : 8=FIXT.1.19=32735=X49=Coinbase56=24ab46f784d1b20db435b852086e325034=13950=TEST52=20250411-01:57:25.262217369=45262=ba2ffebd-86b0-430d-b535-d9d3b46840d1268=1279=0269=2278=c5b88ea9-605d-4595-ac52-f7c3f08523ba83=159757838055=BTC-USD270=3.55271=0.6232294660=20250411-01:57:25.26094137=01fd0015-5bee-45ab-9231-37e12e95051f5797=110=087
20250411-01:57:25.377041000 : 8=FIXT.1.19=29035=X49=Coinbase56=24ab46f784d1b20db435b852086e325034=14050=TEST52=20250411-01:57:25.262220369=45262=ba2ffebd-86b0-430d-b535-d9d3b46840d1268=1279=2269=0278=01fd0015-5bee-45ab-9231-37e12e95051f83=159757838155=BTC-USD270=3.75271=0.0000000060=20250411-01:57:25.26094158=FILLED10=021
20250411-01:57:25.431165000 : 8=FIXT.1.19=28435=X49=Coinbase56=24ab46f784d1b20db435b852086e325034=14150=TEST52=20250411-01:57:25.317234369=45262=ba2ffebd-86b0-430d-b535-d9d3b46840d1268=1279=0269=183=159757838255=BTC-USD270=3.34271=0.6232294660=20250411-01:57:25.31590440=237=ab2c3fd5-fc1e-4b2a-afcb-df4f0a7aa7dc10=186
20250411-01:57:25.433028000 : 8=FIXT.1.19=32735=X49=Coinbase56=24ab46f784d1b20db435b852086e325034=14250=TEST52=20250411-01:57:25.317243369=45262=ba2ffebd-86b0-430d-b535-d9d3b46840d1268=1279=0269=2278=4d60a78e-b39b-420e-b830-bc0f3f4fdde283=159757838355=BTC-USD270=3.53271=0.6232294660=20250411-01:57:25.31590437=ab2c3fd5-fc1e-4b2a-afcb-df4f0a7aa7dc5797=210=015
20250411-01:57:25.433209000 : 8=FIXT.1.19=29035=X49=Coinbase56=24ab46f784d1b20db435b852086e325034=14350=TEST52=20250411-01:57:25.317249369=45262=ba2ffebd-86b0-430d-b535-d9d3b46840d1268=1279=2269=1278=ab2c3fd5-fc1e-4b2a-afcb-df4f0a7aa7dc83=159757838455=BTC-USD270=3.34271=0.0000000060=20250411-01:57:25.31590458=FILLED10=095
20250411-01:57:25.605747000 : 8=FIXT.1.19=28435=X49=Coinbase56=24ab46f784d1b20db435b852086e325034=14450=TEST52=20250411-01:57:25.489860369=45262=ba2ffebd-86b0-430d-b535-d9d3b46840d1268=1279=0269=183=159757838555=BTC-USD270=3.22271=0.6232294660=20250411-01:57:25.48832040=237=a7782c6a-23a6-4969-af3b-94594df5547010=138
20250411-01:57:25.608404000 : 8=FIXT.1.19=32735=X49=Coinbase56=24ab46f784d1b20db435b852086e325034=14550=TEST52=20250411-01:57:25.489872369=45262=ba2ffebd-86b0-430d-b535-d9d3b46840d1268=1279=0269=2278=4d60a78e-b39b-420e-b830-bc0f3f4fdde283=159757838655=BTC-USD270=3.53271=0.6232294660=20250411-01:57:25.48832037=a7782c6a-23a6-4969-af3b-94594df554705797=210=229
20250411-01:57:25.608790000 : 8=FIXT.1.19=29035=X49=Coinbase56=24ab46f784d1b20db435b852086e325034=14650=TEST52=20250411-01:57:25.489875369=45262=ba2ffebd-86b0-430d-b535-d9d3b46840d1268=1279=2269=1278=a7782c6a-23a6-4969-af3b-94594df5547083=159757838755=BTC-USD270=3.22271=0.0000000060=20250411-01:57:25.48832058=FILLED10=047
20250411-01:57:25.661608000 : 8=FIXT.1.19=30335=X49=Coinbase56=24ab46f784d1b20db435b852086e325034=14750=TEST52=20250411-01:57:25.547295369=45262=ba2ffebd-86b0-430d-b535-d9d3b46840d1268=1279=0269=083=159757838855=BTC-USD270=3.79271=0.6644565029004=2.358820575060=20250411-01:57:25.54524040=237=c20f3636-dfe0-4dac-8feb-78466989b7b610=247
20250411-01:57:25.661972000 : 8=FIXT.1.19=32735=X49=Coinbase56=24ab46f784d1b20db435b852086e325034=14850=TEST52=20250411-01:57:25.547303369=45262=ba2ffebd-86b0-430d-b535-d9d3b46840d1268=1279=0269=2278=c5b88ea9-605d-4595-ac52-f7c3f08523ba83=159757838955=BTC-USD270=3.55271=0.6644565060=20250411-01:57:25.54524037=c20f3636-dfe0-4dac-8feb-78466989b7b65797=110=027
20250411-01:57:25.662132000 : 8=FIXT.1.19=28135=X49=Coinbase56=24ab46f784d1b20db435b852086e325034=14950=TEST52=20250411-01:57:25.547360369=45262=ba2ffebd-86b0-430d-b535-d9d3b46840d1268=1279=2269=0278=c20f3636-dfe0-4dac-8feb-78466989b7b683=159757839055=BTC-USD270=3.79271=060=20250411-01:57:25.54524058=FILLED10=054
20250411-01:57:26.707404000 : 8=FIXT.1.19=28435=X49=Coinbase56=24ab46f784d1b20db435b852086e325034=15050=TEST52=20250411-01:57:26.593458369=45262=ba2ffebd-86b0-430d-b535-d9d3b46840d1268=1279=0269=183=159757839155=BTC-USD270=3.56271=0.6197183160=20250411-01:57:26.59248540=237=ec245233-8611-4fe2-a93c-14f901d9dae010=217
20250411-01:57:26.712719000 : 8=FIXT.1.19=28035=X49=Coinbase56=24ab46f784d1b20db435b852086e325034=15150=TEST52=20250411-01:57:26.593509369=45262=ba2ffebd-86b0-430d-b535-d9d3b46840d1268=1279=0269=1278=ec245233-8611-4fe2-a93c-14f901d9dae083=159757839255=BTC-USD270=3.56271=0.6197183160=20250411-01:57:26.59248510=055
20250411-01:57:26.748044000 : 8=FIXT.1.19=28435=X49=Coinbase56=24ab46f784d1b20db435b852086e325034=15250=TEST52=20250411-01:57:26.634256369=45262=ba2ffebd-86b0-430d-b535-d9d3b46840d1268=1279=0269=083=159757839355=BTC-USD270=3.75271=0.6197183160=20250411-01:57:26.63222140=237=7c77db69-eec3-4e53-8318-90c930862c1210=124
20250411-01:57:26.748395000 : 8=FIXT.1.19=32735=X49=Coinbase56=24ab46f784d1b20db435b852086e325034=15350=TEST52=20250411-01:57:26.634325369=45262=ba2ffebd-86b0-430d-b535-d9d3b46840d1268=1279=0269=2278=c5b88ea9-605d-4595-ac52-f7c3f08523ba83=159757839455=BTC-USD270=3.55271=0.6197183160=20250411-01:57:26.63222137=7c77db69-eec3-4e53-8318-90c930862c125797=110=075
20250411-01:57:26.748598000 : 8=FIXT.1.19=29035=X49=Coinbase56=24ab46f784d1b20db435b852086e325034=15450=TEST52=20250411-01:57:26.634332369=45262=ba2ffebd-86b0-430d-b535-d9d3b46840d1268=1279=2269=0278=7c77db69-eec3-4e53-8318-90c930862c1283=159757839555=BTC-USD270=3.75271=0.0000000060=20250411-01:57:26.63222158=FILLED10=020
20250411-01:57:26.804280000 : 8=FIXT.1.19=28435=X49=Coinbase56=24ab46f784d1b20db435b852086e325034=15550=TEST52=20250411-01:57:26.689379369=45262=ba2ffebd-86b0-430d-b535-d9d3b46840d1268=1279=0269=183=159757839655=BTC-USD270=3.34271=0.6197183160=20250411-01:57:26.68806440=237=2050673f-a851-40e7-b83e-b15599b3aa7410=141
20250411-01:57:26.804875000 : 8=FIXT.1.19=32735=X49=Coinbase56=24ab46f784d1b20db435b852086e325034=15650=TEST52=20250411-01:57:26.689387369=45262=ba2ffebd-86b0-430d-b535-d9d3b46840d1268=1279=0269=2278=4d60a78e-b39b-420e-b830-bc0f3f4fdde283=159757839755=BTC-USD270=3.53271=0.6197183160=20250411-01:57:26.68806437=2050673f-a851-40e7-b83e-b15599b3aa745797=210=225
20250411-01:57:26.805113000 : 8=FIXT.1.19=29035=X49=Coinbase56=24ab46f784d1b20db435b852086e325034=15750=TEST52=20250411-01:57:26.689391369=45262=ba2ffebd-86b0-430d-b535-d9d3b46840d1268=1279=2269=1278=2050673f-a851-40e7-b83e-b15599b3aa7483=159757839855=BTC-USD270=3.34271=0.0000000060=20250411-01:57:26.68806458=FILLED10=036
20250411-01:57:27.207327000 : 8=FIXT.1.19=28335=X49=Coinbase56=24ab46f784d1b20db435b852086e325034=15850=TEST52=20250411-01:57:27.090372369=45262=ba2ffebd-86b0-430d-b535-d9d3b46840d1268=1279=0269=083=159757839955=BTC-USD270=3.8271=0.6232294660=20250411-01:57:27.08899740=237=6dd32a4a-6eb2-4c18-8da2-40de5f995daa10=115
20250411-01:57:27.208379000 : 8=FIXT.1.19=32735=X49=Coinbase56=24ab46f784d1b20db435b852086e325034=15950=TEST52=20250411-01:57:27.090388369=45262=ba2ffebd-86b0-430d-b535-d9d3b46840d1268=1279=0269=2278=c5b88ea9-605d-4595-ac52-f7c3f08523ba83=159757840055=BTC-USD270=3.55271=0.6232294660=20250411-01:57:27.08899737=6dd32a4a-6eb2-4c18-8da2-40de5f995daa5797=110=111
20250411-01:57:27.208907000 : 8=FIXT.1.19=28935=X49=Coinbase56=24ab46f784d1b20db435b852086e325034=16050=TEST52=20250411-01:57:27.090468369=45262=ba2ffebd-86b0-430d-b535-d9d3b46840d1268=1279=2269=0278=6dd32a4a-6eb2-4c18-8da2-40de5f995daa83=159757840155=BTC-USD270=3.8271=0.0000000060=20250411-01:57:27.08899758=FILLED10=006
20250411-01:57:27.260347000 : 8=FIXT.1.19=28435=X49=Coinbase56=24ab46f784d1b20db435b852086e325034=16150=TEST52=20250411-01:57:27.146606369=45262=ba2ffebd-86b0-430d-b535-d9d3b46840d1268=1279=0269=183=159757840255=BTC-USD270=3.26271=0.6232294660=20250411-01:57:27.14468940=237=a0e471d4-32de-4c29-9a09-6d86cff18d7310=008
20250411-01:57:27.260791000 : 8=FIXT.1.19=32735=X49=Coinbase56=24ab46f784d1b20db435b852086e325034=16250=TEST52=20250411-01:57:27.146693369=45262=ba2ffebd-86b0-430d-b535-d9d3b46840d1268=1279=0269=2278=4d60a78e-b39b-420e-b830-bc0f3f4fdde283=159757840355=BTC-USD270=3.53271=0.6232294660=20250411-01:57:27.14468937=a0e471d4-32de-4c29-9a09-6d86cff18d735797=210=098
20250411-01:57:27.261019000 : 8=FIXT.1.19=29035=X49=Coinbase56=24ab46f784d1b20db435b852086e325034=16350=TEST52=20250411-01:57:27.146696369=45262=ba2ffebd-86b0-430d-b535-d9d3b46840d1268=1279=2269=1278=a0e471d4-32de-4c29-9a09-6d86cff18d7383=159757840455=BTC-USD270=3.26271=0.0000000060=20250411-01:57:27.14468958=FILLED10=176
20250411-01:57:28.235893000 : 8=FIXT.1.19=28435=X49=Coinbase56=24ab46f784d1b20db435b852086e325034=16450=TEST52=20250411-01:57:28.121638369=45262=ba2ffebd-86b0-430d-b535-d9d3b46840d1268=1279=0269=083=159757840555=BTC-USD270=3.81271=0.6232294660=20250411-01:57:28.11974340=237=a19f9eeb-9206-4365-93e6-dbbc058cef5c10=106
20250411-01:57:28.236953000 : 8=FIXT.1.19=32735=X49=Coinbase56=24ab46f784d1b20db435b852086e325034=16550=TEST52=20250411-01:57:28.121650369=45262=ba2ffebd-86b0-430d-b535-d9d3b46840d1268=1279=0269=2278=c5b88ea9-605d-4595-ac52-f7c3f08523ba83=159757840655=BTC-USD270=3.55271=0.6232294660=20250411-01:57:28.11974337=a19f9eeb-9206-4365-93e6-dbbc058cef5c5797=110=057
20250411-01:57:28.238804000 : 8=FIXT.1.19=29035=X49=Coinbase56=24ab46f784d1b20db435b852086e325034=16650=TEST52=20250411-01:57:28.121653369=45262=ba2ffebd-86b0-430d-b535-d9d3b46840d1268=1279=2269=0278=a19f9eeb-9206-4365-93e6-dbbc058cef5c83=159757840755=BTC-USD270=3.81271=0.0000000060=20250411-01:57:28.11974358=FILLED10=006
20250411-01:57:28.293322000 : 8=FIXT.1.19=28435=X49=Coinbase56=24ab46f784d1b20db435b852086e325034=16750=TEST52=20250411-01:57:28.177778369=45262=ba2ffebd-86b0-430d-b535-d9d3b46840d1268=1279=0269=183=159757840855=BTC-USD270=3.21271=0.6232294660=20250411-01:57:28.17650140=237=07402b19-8ec5-410c-9209-17a653c380c010=010
20250411-01:57:28.293885000 : 8=FIXT.1.19=32735=X49=Coinbase56=24ab46f784d1b20db435b852086e325034=16850=TEST52=20250411-01:57:28.177787369=45262=ba2ffebd-86b0-430d-b535-d9d3b46840d1268=1279=0269=2278=4d60a78e-b39b-420e-b830-bc0f3f4fdde283=159757840955=BTC-USD270=3.53271=0.6232294660=20250411-01:57:28.17650137=07402b19-8ec5-410c-9209-17a653c380c05797=210=099
20250411-01:57:28.294136000 : 8=FIXT.1.19=29035=X49=Coinbase56=24ab46f784d1b20db435b852086e325034=16950=TEST52=20250411-01:57:28.177791369=45262=ba2ffebd-86b0-430d-b535-d9d3b46840d1268=1279=2269=1278=07402b19-8ec5-410c-9209-17a653c380c083=159757841055=BTC-USD270=3.21271=0.0000000060=20250411-01:57:28.17650158=FILLED10=155
20250411-01:57:29.604137000 : 8=FIXT.1.19=28335=X49=Coinbase56=24ab46f784d1b20db435b852086e325034=17050=TEST52=20250411-01:57:29.490164369=45262=ba2ffebd-86b0-430d-b535-d9d3b46840d1268=1279=0269=183=159757841155=BTC-USD270=3.3271=0.6232294660=20250411-01:57:29.48886240=237=bd1c15ee-dab6-44de-a900-a8d7f2a0df8910=186
20250411-01:57:29.604855000 : 8=FIXT.1.19=32735=X49=Coinbase56=24ab46f784d1b20db435b852086e325034=17150=TEST52=20250411-01:57:29.490300369=45262=ba2ffebd-86b0-430d-b535-d9d3b46840d1268=1279=0269=2278=4d60a78e-b39b-420e-b830-bc0f3f4fdde283=159757841255=BTC-USD270=3.53271=0.6232294660=20250411-01:57:29.48886237=bd1c15ee-dab6-44de-a900-a8d7f2a0df895797=210=060
20250411-01:57:29.605369000 : 8=FIXT.1.19=28935=X49=Coinbase56=24ab46f784d1b20db435b852086e325034=17250=TEST52=20250411-01:57:29.490334369=45262=ba2ffebd-86b0-430d-b535-d9d3b46840d1268=1279=2269=1278=bd1c15ee-dab6-44de-a900-a8d7f2a0df8983=159757841355=BTC-USD270=3.3271=0.0000000060=20250411-01:57:29.48886258=FILLED10=097
20250411-01:57:29.661281000 : 8=FIXT.1.19=28435=X49=Coinbase56=24ab46f784d1b20db435b852086e325034=17350=TEST52=20250411-01:57:29.546772369=45262=ba2ffebd-86b0-430d-b535-d9d3b46840d1268=1279=0269=083=159757841455=BTC-USD270=3.81271=0.6232294660=20250411-01:57:29.54553640=237=7673cab5-f52d-493b-bc6d-223ccc0b92cb10=145
20250411-01:57:29.661708000 : 8=FIXT.1.19=32735=X49=Coinbase56=24ab46f784d1b20db435b852086e325034=17450=TEST52=20250411-01:57:29.546942369=45262=ba2ffebd-86b0-430d-b535-d9d3b46840d1268=1279=0269=2278=c5b88ea9-605d-4595-ac52-f7c3f08523ba83=159757841555=BTC-USD270=3.55271=0.6232294660=20250411-01:57:29.54553637=7673cab5-f52d-493b-bc6d-223ccc0b92cb5797=110=101
20250411-01:57:29.661900000 : 8=FIXT.1.19=29035=X49=Coinbase56=24ab46f784d1b20db435b852086e325034=17550=TEST52=20250411-01:57:29.546945369=45262=ba2ffebd-86b0-430d-b535-d9d3b46840d1268=1279=2269=0278=7673cab5-f52d-493b-bc6d-223ccc0b92cb83=159757841655=BTC-USD270=3.81271=0.0000000060=20250411-01:57:29.54553658=FILLED10=050
20250411-01:57:30.406213000 : 8=FIXT.1.19=28435=X49=Coinbase56=24ab46f784d1b20db435b852086e325034=17650=TEST52=20250411-01:57:30.291016369=45262=ba2ffebd-86b0-430d-b535-d9d3b46840d1268=1279=0269=083=159757841755=BTC-USD270=3.73271=0.6197183160=20250411-01:57:30.28951840=237=725ac49f-ec11-417e-b7e0-586f42f4c71110=208
20250411-01:57:30.407239000 : 8=FIXT.1.19=32735=X49=Coinbase56=24ab46f784d1b20db435b852086e325034=17750=TEST52=20250411-01:57:30.291084369=45262=ba2ffebd-86b0-430d-b535-d9d3b46840d1268=1279=0269=2278=c5b88ea9-605d-4595-ac52-f7c3f08523ba83=159757841855=BTC-USD270=3.55271=0.6197183160=20250411-01:57:30.28951837=725ac49f-ec11-417e-b7e0-586f42f4c7115797=110=169
20250411-01:57:30.407405000 : 8=FIXT.1.19=29035=X49=Coinbase56=24ab46f784d1b20db435b852086e325034=17850=TEST52=20250411-01:57:30.291088369=45262=ba2ffebd-86b0-430d-b535-d9d3b46840d1268=1279=2269=0278=725ac49f-ec11-417e-b7e0-586f42f4c71183=159757841955=BTC-USD270=3.73271=0.0000000060=20250411-01:57:30.28951858=FILLED10=118
20250411-01:57:30.456837000 : 8=FIXT.1.19=28435=X49=Coinbase56=24ab46f784d1b20db435b852086e325034=17950=TEST52=20250411-01:57:30.340414369=45262=ba2ffebd-86b0-430d-b535-d9d3b46840d1268=1279=0269=083=159757842055=BTC-USD270=3.91271=0.6197183160=20250411-01:57:30.33867940=237=58667b5d-724f-42c7-b286-42d9dbb0b38010=162
20250411-01:57:30.457196000 : 8=FIXT.1.19=32735=X49=Coinbase56=24ab46f784d1b20db435b852086e325034=18050=TEST52=20250411-01:57:30.340429369=45262=ba2ffebd-86b0-430d-b535-d9d3b46840d1268=1279=0269=2278=c5b88ea9-605d-4595-ac52-f7c3f08523ba83=159757842155=BTC-USD270=3.55271=0.6197183160=20250411-01:57:30.33867937=58667b5d-724f-42c7-b286-42d9dbb0b3805797=110=115
20250411-01:57:30.457578000 : 8=FIXT.1.19=29035=X49=Coinbase56=24ab46f784d1b20db435b852086e325034=18150=TEST52=20250411-01:57:30.340432369=45262=ba2ffebd-86b0-430d-b535-d9d3b46840d1268=1279=2269=0278=58667b5d-724f-42c7-b286-42d9dbb0b38083=159757842255=BTC-USD270=3.91271=0.0000000060=20250411-01:57:30.33867958=FILLED10=054
20250411-01:57:30.460692000 : 8=FIXT.1.19=28435=X49=Coinbase56=24ab46f784d1b20db435b852086e325034=18250=TEST52=20250411-01:57:30.346814369=45262=ba2ffebd-86b0-430d-b535-d9d3b46840d1268=1279=0269=183=159757842355=BTC-USD270=3.29271=0.6197183160=20250411-01:57:30.34537340=237=47b0bc22-e670-4ee6-b56d-14825f767b6010=155
20250411-01:57:30.461158000 : 8=FIXT.1.19=32735=X49=Coinbase56=24ab46f784d1b20db435b852086e325034=18350=TEST52=20250411-01:57:30.346935369=45262=ba2ffebd-86b0-430d-b535-d9d3b46840d1268=1279=0269=2278=4d60a78e-b39b-420e-b830-bc0f3f4fdde283=159757842455=BTC-USD270=3.53271=0.6197183160=20250411-01:57:30.34537337=47b0bc22-e670-4ee6-b56d-14825f767b605797=210=240
20250411-01:57:30.461440000 : 8=FIXT.1.19=29035=X49=Coinbase56=24ab46f784d1b20db435b852086e325034=18450=TEST52=20250411-01:57:30.346939369=45262=ba2ffebd-86b0-430d-b535-d9d3b46840d1268=1279=2269=1278=47b0bc22-e670-4ee6-b56d-14825f767b6083=159757842555=BTC-USD270=3.29271=0.0000000060=20250411-01:57:30.34537358=FILLED10=064
20250411-01:57:30.636436000 : 8=FIXT.1.19=28435=X49=Coinbase56=24ab46f784d1b20db435b852086e325034=18550=TEST52=20250411-01:57:30.519634369=45262=ba2ffebd-86b0-430d-b535-d9d3b46840d1268=1279=0269=083=159757842655=BTC-USD270=3.74271=0.6232294660=20250411-01:57:30.51771440=237=f7972d22-41f7-4aba-b989-e332747c32e710=173
20250411-01:57:30.637790000 : 8=FIXT.1.19=32735=X49=Coinbase56=24ab46f784d1b20db435b852086e325034=18650=TEST52=20250411-01:57:30.519647369=45262=ba2ffebd-86b0-430d-b535-d9d3b46840d1268=1279=0269=2278=c5b88ea9-605d-4595-ac52-f7c3f08523ba83=159757842755=BTC-USD270=3.55271=0.6232294660=20250411-01:57:30.51771437=f7972d22-41f7-4aba-b989-e332747c32e75797=110=132
20250411-01:57:30.638014000 : 8=FIXT.1.19=29035=X49=Coinbase56=24ab46f784d1b20db435b852086e325034=18750=TEST52=20250411-01:57:30.519650369=45262=ba2ffebd-86b0-430d-b535-d9d3b46840d1268=1279=2269=0278=f7972d22-41f7-4aba-b989-e332747c32e783=159757842855=BTC-USD270=3.74271=0.0000000060=20250411-01:57:30.51771458=FILLED10=074
20250411-01:57:30.687999000 : 8=FIXT.1.19=28435=X49=Coinbase56=24ab46f784d1b20db435b852086e325034=18850=TEST52=20250411-01:57:30.573865369=45262=ba2ffebd-86b0-430d-b535-d9d3b46840d1268=1279=0269=183=159757842955=BTC-USD270=3.21271=0.6232294660=20250411-01:57:30.57252840=237=4ec6dceb-96d8-42c1-8bc3-bd50a5ad582210=146
20250411-01:57:30.688406000 : 8=FIXT.1.19=32735=X49=Coinbase56=24ab46f784d1b20db435b852086e325034=18950=TEST52=20250411-01:57:30.573950369=45262=ba2ffebd-86b0-430d-b535-d9d3b46840d1268=1279=0269=2278=4d60a78e-b39b-420e-b830-bc0f3f4fdde283=159757843055=BTC-USD270=3.53271=0.6232294660=20250411-01:57:30.57252837=4ec6dceb-96d8-42c1-8bc3-bd50a5ad58225797=210=221
20250411-01:57:30.688828000 : 8=FIXT.1.19=29035=X49=Coinbase56=24ab46f784d1b20db435b852086e325034=19050=TEST52=20250411-01:57:30.573954369=45262=ba2ffebd-86b0-430d-b535-d9d3b46840d1268=1279=2269=1278=4ec6dceb-96d8-42c1-8bc3-bd50a5ad582283=159757843155=BTC-USD270=3.21271=0.0000000060=20250411-01:57:30.57252858=FILLED10=030
20250411-01:57:31.206681000 : 8=FIXT.1.19=28435=X49=Coinbase56=24ab46f784d1b20db435b852086e325034=19150=TEST52=20250411-01:57:31.091182369=45262=ba2ffebd-86b0-430d-b535-d9d3b46840d1268=1279=0269=083=159757843255=BTC-USD270=3.83271=0.6232294660=20250411-01:57:31.08993140=237=40b25ed3-78fa-4296-8773-211ddb6f5d7b10=208
20250411-01:57:31.207765000 : 8=FIXT.1.19=32735=X49=Coinbase56=24ab46f784d1b20db435b852086e325034=19250=TEST52=20250411-01:57:31.091206369=45262=ba2ffebd-86b0-430d-b535-d9d3b46840d1268=1279=0269=2278=c5b88ea9-605d-4595-ac52-f7c3f08523ba83=159757843355=BTC-USD270=3.55271=0.6232294660=20250411-01:57:31.08993137=40b25ed3-78fa-4296-8773-211ddb6f5d7b5797=110=160
20250411-01:57:31.208163000 : 8=FIXT.1.19=29035=X49=Coinbase56=24ab46f784d1b20db435b852086e325034=19350=TEST52=20250411-01:57:31.091265369=45262=ba2ffebd-86b0-430d-b535-d9d3b46840d1268=1279=2269=0278=40b25ed3-78fa-4296-8773-211ddb6f5d7b83=159757843455=BTC-USD270=3.83271=0.0000000060=20250411-01:57:31.08993158=FILLED10=113
20250411-01:57:31.260916000 : 8=FIXT.1.19=28435=X49=Coinbase56=24ab46f784d1b20db435b852086e325034=19450=TEST52=20250411-01:57:31.146150369=45262=ba2ffebd-86b0-430d-b535-d9d3b46840d1268=1279=0269=183=159757843555=BTC-USD270=3.32271=0.6232294660=20250411-01:57:31.14503640=237=900db37f-3962-43d7-a2b2-ec105102e2c210=114
20250411-01:57:31.261269000 : 8=FIXT.1.19=32735=X49=Coinbase56=24ab46f784d1b20db435b852086e325034=19550=TEST52=20250411-01:57:31.146160369=45262=ba2ffebd-86b0-430d-b535-d9d3b46840d1268=1279=0269=2278=4d60a78e-b39b-420e-b830-bc0f3f4fdde283=159757843655=BTC-USD270=3.53271=0.6232294660=20250411-01:57:31.14503637=900db37f-3962-43d7-a2b2-ec105102e2c25797=210=202
20250411-01:57:31.261483000 : 8=FIXT.1.19=29035=X49=Coinbase56=24ab46f784d1b20db435b852086e325034=19650=TEST52=20250411-01:57:31.146163369=45262=ba2ffebd-86b0-430d-b535-d9d3b46840d1268=1279=2269=1278=900db37f-3962-43d7-a2b2-ec105102e2c283=159757843755=BTC-USD270=3.32271=0.0000000060=20250411-01:57:31.14503658=FILLED10=021
20250411-01:57:31.456582000 : 8=FIXT.1.19=28335=X49=Coinbase56=24ab46f784d1b20db435b852086e325034=19750=TEST52=20250411-01:57:31.341879369=45262=ba2ffebd-86b0-430d-b535-d9d3b46840d1268=1279=0269=183=159757843855=BTC-USD270=3.2271=0.6197183160=20250411-01:57:31.34049040=237=4ec68f5d-a5bd-4d97-a52f-dd0040f120f010=035
20250411-01:57:31.458431000 : 8=FIXT.1.19=32735=X49=Coinbase56=24ab46f784d1b20db435b852086e325034=19850=TEST52=20250411-01:57:31.341889369=45262=ba2ffebd-86b0-430d-b535-d9d3b46840d1268=1279=0269=2278=4d60a78e-b39b-420e-b830-bc0f3f4fdde283=159757843955=BTC-USD270=3.53271=0.6197183160=20250411-01:57:31.34049037=4ec68f5d-a5bd-4d97-a52f-dd0040f120f05797=210=175
20250411-01:57:31.458868000 : 8=FIXT.1.19=28935=X49=Coinbase56=24ab46f784d1b20db435b852086e325034=19950=TEST52=20250411-01:57:31.341892369=45262=ba2ffebd-86b0-430d-b535-d9d3b46840d1268=1279=2269=1278=4ec68f5d-a5bd-4d97-a52f-dd0040f120f083=159757844055=BTC-USD270=3.2271=0.0000000060=20250411-01:57:31.34049058=FILLED10=187
20250411-01:58:09.674299000 : 8=FIXT.1.19=21535=A34=149=24ab46f784d1b20db435b852086e325052=20250411-01:58:09.66656=Coinbase95=4496=KcUw1wqye97nTPt83qeyjISk0aOS9zP/Lkvm4Jc7K3I=98=0108=30141=Y553=24ab46f784d1b20db435b852086e3250554=akmwnltyfgb1137=910=045
20250411-01:58:09.927546000 : 8=FIXT.1.19=12535=A49=Coinbase56=24ab46f784d1b20db435b852086e325034=150=TEST52=20250411-01:58:09.811930369=198=0108=30141=Y1137=910=197
20250411-01:58:10.961202000 : 8=FIXT.1.19=17835=V34=249=24ab46f784d1b20db435b852086e325052=20250411-01:58:10.95956=Coinbase1128=9146=155=BTC-USD262=9476afd5-fdba-42be-bb0c-485d57b711d5263=1264=0267=2269=0269=110=212
20250411-01:58:11.285137000 : 8=FIXT.1.19=28135=X49=Coinbase56=24ab46f784d1b20db435b852086e325034=250=TEST52=20250411-01:58:11.164223369=2262=9476afd5-fdba-42be-bb0c-485d57b711d5268=1279=0269=083=159757933355=BTC-USD270=3.39271=0.6214689360=20250411-01:58:11.16290240=237=beb774f7-441b-4c7e-8847-e548ba1f47ce10=201
20250411-01:58:11.288040000 : 8=FIXT.1.19=27735=X49=Coinbase56=24ab46f784d1b20db435b852086e325034=350=TEST52=20250411-01:58:11.164237369=2262=9476afd5-fdba-42be-bb0c-485d57b711d5268=1279=0269=0278=beb774f7-441b-4c7e-8847-e548ba1f47ce83=159757933455=BTC-USD270=3.39271=0.6214689360=20250411-01:58:11.16290210=056
20250411-01:58:13.708078000 : 8=FIXT.1.19=28135=X49=Coinbase56=24ab46f784d1b20db435b852086e325034=450=TEST52=20250411-01:58:13.550302369=2262=9476afd5-fdba-42be-bb0c-485d57b711d5268=1279=0269=183=159757933555=BTC-USD270=3.22271=0.6214689360=20250411-01:58:13.54827840=237=2006afa7-4753-4a74-a1e3-075e05b7346810=201
20250411-01:58:13.708697000 : 8=FIXT.1.19=32435=X49=Coinbase56=24ab46f784d1b20db435b852086e325034=550=TEST52=20250411-01:58:13.550317369=2262=9476afd5-fdba-42be-bb0c-485d57b711d5268=1279=0269=2278=4d60a78e-b39b-420e-b830-bc0f3f4fdde283=159757933655=BTC-USD270=3.53271=0.6214689360=20250411-01:58:13.54827837=2006afa7-4753-4a74-a1e3-075e05b734685797=210=039
20250411-01:58:13.709696000 : 8=FIXT.1.19=28735=X49=Coinbase56=24ab46f784d1b20db435b852086e325034=650=TEST52=20250411-01:58:13.550328369=2262=9476afd5-fdba-42be-bb0c-485d57b711d5268=1279=2269=1278=2006afa7-4753-4a74-a1e3-075e05b7346883=159757933755=BTC-USD270=3.22271=0.0000000060=20250411-01:58:13.54827858=FILLED10=116
20250411-01:58:13.719239000 : 8=FIXT.1.19=28135=X49=Coinbase56=24ab46f784d1b20db435b852086e325034=750=TEST52=20250411-01:58:13.604303369=2262=9476afd5-fdba-42be-bb0c-485d57b711d5268=1279=0269=083=159757933855=BTC-USD270=3.76271=0.6214689360=20250411-01:58:13.60233340=237=505ae4da-de03-4f39-935b-cfae5f6a76f510=038
20250411-01:58:13.719596000 : 8=FIXT.1.19=32435=X49=Coinbase56=24ab46f784d1b20db435b852086e325034=850=TEST52=20250411-01:58:13.604312369=2262=9476afd5-fdba-42be-bb0c-485d57b711d5268=1279=0269=2278=c5b88ea9-605d-4595-ac52-f7c3f08523ba83=159757933955=BTC-USD270=3.55271=0.6214689360=20250411-01:58:13.60233337=505ae4da-de03-4f39-935b-cfae5f6a76f55797=110=247
20250411-01:58:13.719749000 : 8=FIXT.1.19=28735=X49=Coinbase56=24ab46f784d1b20db435b852086e325034=950=TEST52=20250411-01:58:13.604315369=2262=9476afd5-fdba-42be-bb0c-485d57b711d5268=1279=2269=0278=505ae4da-de03-4f39-935b-cfae5f6a76f583=159757934055=BTC-USD270=3.76271=0.0000000060=20250411-01:58:13.60233358=FILLED10=195
20250411-01:58:13.779445000 : 8=FIXT.1.19=28235=X49=Coinbase56=24ab46f784d1b20db435b852086e325034=1050=TEST52=20250411-01:58:13.664362369=2262=9476afd5-fdba-42be-bb0c-485d57b711d5268=1279=0269=183=159757934155=BTC-USD270=3.25271=0.6197183160=20250411-01:58:13.66314040=237=a8852d5b-a655-4e87-8090-71b9428d577910=232
20250411-01:58:13.780002000 : 8=FIXT.1.19=32535=X49=Coinbase56=24ab46f784d1b20db435b852086e325034=1150=TEST52=20250411-01:58:13.664368369=2262=9476afd5-fdba-42be-bb0c-485d57b711d5268=1279=0269=2278=4d60a78e-b39b-420e-b830-bc0f3f4fdde283=159757934255=BTC-USD270=3.53271=0.6197183160=20250411-01:58:13.66314037=a8852d5b-a655-4e87-8090-71b9428d57795797=210=067
20250411-01:58:13.780200000 : 8=FIXT.1.19=28835=X49=Coinbase56=24ab46f784d1b20db435b852086e325034=1250=TEST52=20250411-01:58:13.664371369=2262=9476afd5-fdba-42be-bb0c-485d57b711d5268=1279=2269=1278=a8852d5b-a655-4e87-8090-71b9428d577983=159757934355=BTC-USD270=3.25271=0.0000000060=20250411-01:58:13.66314058=FILLED10=142
20250411-01:58:13.832659000 : 8=FIXT.1.19=28235=X49=Coinbase56=24ab46f784d1b20db435b852086e325034=1350=TEST52=20250411-01:58:13.717124369=2262=9476afd5-fdba-42be-bb0c-485d57b711d5268=1279=0269=083=159757934455=BTC-USD270=3.76271=0.6197183160=20250411-01:58:13.71588140=237=0d580049-d86e-445a-b8df-b23538a3018710=060
20250411-01:58:13.833042000 : 8=FIXT.1.19=32535=X49=Coinbase56=24ab46f784d1b20db435b852086e325034=1450=TEST52=20250411-01:58:13.717131369=2262=9476afd5-fdba-42be-bb0c-485d57b711d5268=1279=0269=2278=c5b88ea9-605d-4595-ac52-f7c3f08523ba83=159757934555=BTC-USD270=3.55271=0.6197183160=20250411-01:58:13.71588137=0d580049-d86e-445a-b8df-b23538a301875797=110=011
20250411-01:58:13.833216000 : 8=FIXT.1.19=28835=X49=Coinbase56=24ab46f784d1b20db435b852086e325034=1550=TEST52=20250411-01:58:13.717134369=2262=9476afd5-fdba-42be-bb0c-485d57b711d5268=1279=2269=0278=0d580049-d86e-445a-b8df-b23538a3018783=159757934655=BTC-USD270=3.76271=0.0000000060=20250411-01:58:13.71588158=FILLED10=227
20250411-01:58:14.701286000 : 8=FIXT.1.19=28235=X49=Coinbase56=24ab46f784d1b20db435b852086e325034=1650=TEST52=20250411-01:58:14.578467369=2262=9476afd5-fdba-42be-bb0c-485d57b711d5268=1279=0269=083=159757934755=BTC-USD270=3.81271=0.6197183160=20250411-01:58:14.57631440=237=ba9d91e3-9c7d-412f-b224-ffaa41b75cb810=103
20250411-01:58:14.701887000 : 8=FIXT.1.19=32535=X49=Coinbase56=24ab46f784d1b20db435b852086e325034=1750=TEST52=20250411-01:58:14.578478369=2262=9476afd5-fdba-42be-bb0c-485d57b711d5268=1279=0269=2278=c5b88ea9-605d-4595-ac52-f7c3f08523ba83=159757934855=BTC-USD270=3.55271=0.6197183160=20250411-01:58:14.57631437=ba9d91e3-9c7d-412f-b224-ffaa41b75cb85797=110=062
20250411-01:58:14.702102000 : 8=FIXT.1.19=28835=X49=Coinbase56=24ab46f784d1b20db435b852086e325034=1850=TEST52=20250411-01:58:14.578480369=2262=9476afd5-fdba-42be-bb0c-485d57b711d5268=1279=2269=0278=ba9d91e3-9c7d-412f-b224-ffaa41b75cb883=159757934955=BTC-USD270=3.81271=0.0000000060=20250411-01:58:14.57631458=FILLED10=008
20250411-01:58:14.748946000 : 8=FIXT.1.19=28235=X49=Coinbase56=24ab46f784d1b20db435b852086e325034=1950=TEST52=20250411-01:58:14.633442369=2262=9476afd5-fdba-42be-bb0c-485d57b711d5268=1279=0269=183=159757935055=BTC-USD270=3.34271=0.6197183160=20250411-01:58:14.63158840=237=0aaea843-9b02-4793-8fdb-bd191773726710=114
20250411-01:58:14.749409000 : 8=FIXT.1.19=32535=X49=Coinbase56=24ab46f784d1b20db435b852086e325034=2050=TEST52=20250411-01:58:14.633448369=2262=9476afd5-fdba-42be-bb0c-485d57b711d5268=1279=0269=2278=4d60a78e-b39b-420e-b830-bc0f3f4fdde283=159757935155=BTC-USD270=3.53271=0.6197183160=20250411-01:58:14.63158837=0aaea843-9b02-4793-8fdb-bd19177372675797=210=196
20250411-01:58:14.751523000 : 8=FIXT.1.19=28835=X49=Coinbase56=24ab46f784d1b20db435b852086e325034=2150=TEST52=20250411-01:58:14.633451369=2262=9476afd5-fdba-42be-bb0c-485d57b711d5268=1279=2269=1278=0aaea843-9b02-4793-8fdb-bd191773726783=159757935255=BTC-USD270=3.34271=0.0000000060=20250411-01:58:14.63158858=FILLED10=015
20250411-01:58:15.381500000 : 8=FIXT.1.19=28135=X49=Coinbase56=24ab46f784d1b20db435b852086e325034=2250=TEST52=20250411-01:58:15.262989369=2262=9476afd5-fdba-42be-bb0c-485d57b711d5268=1279=0269=083=159757935355=BTC-USD270=3.8271=0.6232294660=20250411-01:58:15.26140440=237=26e8eb8c-a3b6-4ea6-ad16-675807ecf96710=219
20250411-01:58:15.383537000 : 8=FIXT.1.19=32535=X49=Coinbase56=24ab46f784d1b20db435b852086e325034=2350=TEST52=20250411-01:58:15.263001369=2262=9476afd5-fdba-42be-bb0c-485d57b711d5268=1279=0269=2278=c5b88ea9-605d-4595-ac52-f7c3f08523ba83=159757935455=BTC-USD270=3.55271=0.6232294660=20250411-01:58:15.26140437=26e8eb8c-a3b6-4ea6-ad16-675807ecf9675797=110=202
20250411-01:58:15.383802000 : 8=FIXT.1.19=28735=X49=Coinbase56=24ab46f784d1b20db435b852086e325034=2450=TEST52=20250411-01:58:15.263004369=2262=9476afd5-fdba-42be-bb0c-485d57b711d5268=1279=2269=0278=26e8eb8c-a3b6-4ea6-ad16-675807ecf96783=159757935555=BTC-USD270=3.8271=0.0000000060=20250411-01:58:15.26140458=FILLED10=110
20250411-01:58:15.433619000 : 8=FIXT.1.19=30135=X49=Coinbase56=24ab46f784d1b20db435b852086e325034=2550=TEST52=20250411-01:58:15.317503369=2262=9476afd5-fdba-42be-bb0c-485d57b711d5268=1279=0269=183=159757935655=BTC-USD270=3.22271=0.5694050929004=2.009999967760=20250411-01:58:15.31618440=237=f609b04d-92dc-4da2-8cd1-44c3aa6374cf10=211
20250411-01:58:15.434244000 : 8=FIXT.1.19=32535=X49=Coinbase56=24ab46f784d1b20db435b852086e325034=2650=TEST52=20250411-01:58:15.317508369=2262=9476afd5-fdba-42be-bb0c-485d57b711d5268=1279=0269=2278=4d60a78e-b39b-420e-b830-bc0f3f4fdde283=159757935755=BTC-USD270=3.53271=0.5694050960=20250411-01:58:15.31618437=f609b04d-92dc-4da2-8cd1-44c3aa6374cf5797=210=122
20250411-01:58:15.434569000 : 8=FIXT.1.19=27935=X49=Coinbase56=24ab46f784d1b20db435b852086e325034=2750=TEST52=20250411-01:58:15.317564369=2262=9476afd5-fdba-42be-bb0c-485d57b711d5268=1279=2269=1278=f609b04d-92dc-4da2-8cd1-44c3aa6374cf83=159757935855=BTC-USD270=3.22271=060=20250411-01:58:15.31618458=FILLED10=026
20250411-01:58:15.494428000 : 8=FIXT.1.19=28235=X49=Coinbase56=24ab46f784d1b20db435b852086e325034=2850=TEST52=20250411-01:58:15.378718369=2262=9476afd5-fdba-42be-bb0c-485d57b711d5268=1279=0269=183=159757935955=BTC-USD270=3.27271=0.6232294660=20250411-01:58:15.37705440=237=aa9e66ba-a829-4439-ae1b-c193f609cac610=063
20250411-01:58:15.495189000 : 8=FIXT.1.19=32535=X49=Coinbase56=24ab46f784d1b20db435b852086e325034=2950=TEST52=20250411-01:58:15.378726369=2262=9476afd5-fdba-42be-bb0c-485d57b711d5268=1279=0269=2278=4d60a78e-b39b-420e-b830-bc0f3f4fdde283=159757936055=BTC-USD270=3.53271=0.6232294660=20250411-01:58:15.37705437=aa9e66ba-a829-4439-ae1b-c193f609cac65797=210=136
20250411-01:58:15.495759000 : 8=FIXT.1.19=28835=X49=Coinbase56=24ab46f784d1b20db435b852086e325034=3050=TEST52=20250411-01:58:15.378731369=2262=9476afd5-fdba-42be-bb0c-485d57b711d5268=1279=2269=1278=aa9e66ba-a829-4439-ae1b-c193f609cac683=159757936155=BTC-USD270=3.27271=0.0000000060=20250411-01:58:15.37705458=FILLED10=208
20250411-01:58:15.551556000 : 8=FIXT.1.19=28235=X49=Coinbase56=24ab46f784d1b20db435b852086e325034=3150=TEST52=20250411-01:58:15.433777369=2262=9476afd5-fdba-42be-bb0c-485d57b711d5268=1279=0269=083=159757936255=BTC-USD270=3.85271=0.6232294660=20250411-01:58:15.43261140=237=f2a38e79-7d0a-4c84-8c9b-8b40f4bb43fd10=051
20250411-01:58:15.552048000 : 8=FIXT.1.19=32535=X49=Coinbase56=24ab46f784d1b20db435b852086e325034=3250=TEST52=20250411-01:58:15.433783369=2262=9476afd5-fdba-42be-bb0c-485d57b711d5268=1279=0269=2278=c5b88ea9-605d-4595-ac52-f7c3f08523ba83=159757936355=BTC-USD270=3.55271=0.6232294660=20250411-01:58:15.43261137=f2a38e79-7d0a-4c84-8c9b-8b40f4bb43fd5797=110=001
20250411-01:58:15.552246000 : 8=FIXT.1.19=28835=X49=Coinbase56=24ab46f784d1b20db435b852086e325034=3350=TEST52=20250411-01:58:15.433786369=2262=9476afd5-fdba-42be-bb0c-485d57b711d5268=1279=2269=0278=f2a38e79-7d0a-4c84-8c9b-8b40f4bb43fd83=159757936455=BTC-USD270=3.85271=0.0000000060=20250411-01:58:15.43261158=FILLED10=219
20250411-01:58:15.836777000 : 8=FIXT.1.19=28235=X49=Coinbase56=24ab46f784d1b20db435b852086e325034=3450=TEST52=20250411-01:58:15.719647369=2262=9476afd5-fdba-42be-bb0c-485d57b711d5268=1279=0269=083=159757936555=BTC-USD270=3.75271=0.6197183160=20250411-01:58:15.71805940=237=d9dc79c5-3b34-4ae0-a53b-4081cc74b57e10=013
20250411-01:58:15.837334000 : 8=FIXT.1.19=32535=X49=Coinbase56=24ab46f784d1b20db435b852086e325034=3550=TEST52=20250411-01:58:15.719653369=2262=9476afd5-fdba-42be-bb0c-485d57b711d5268=1279=0269=2278=c5b88ea9-605d-4595-ac52-f7c3f08523ba83=159757936655=BTC-USD270=3.55271=0.6197183160=20250411-01:58:15.71805937=d9dc79c5-3b34-4ae0-a53b-4081cc74b57e5797=110=220
20250411-01:58:15.837613000 : 8=FIXT.1.19=28835=X49=Coinbase56=24ab46f784d1b20db435b852086e325034=3650=TEST52=20250411-01:58:15.719656369=2262=9476afd5-fdba-42be-bb0c-485d57b711d5268=1279=2269=0278=d9dc79c5-3b34-4ae0-a53b-4081cc74b57e83=159757936755=BTC-USD270=3.75271=0.0000000060=20250411-01:58:15.71805958=FILLED10=179
20250411-01:58:15.892134000 : 8=FIXT.1.19=28235=X49=Coinbase56=24ab46f784d1b20db435b852086e325034=3750=TEST52=20250411-01:58:15.776121369=2262=9476afd5-fdba-42be-bb0c-485d57b711d5268=1279=0269=183=159757936855=BTC-USD270=3.37271=0.6197183160=20250411-01:58:15.77496740=237=04061895-6687-4319-98dd-28dc2ef7960510=227
20250411-01:58:15.892869000 : 8=FIXT.1.19=32535=X49=Coinbase56=24ab46f784d1b20db435b852086e325034=3850=TEST52=20250411-01:58:15.776127369=2262=9476afd5-fdba-42be-bb0c-485d57b711d5268=1279=0269=2278=4d60a78e-b39b-420e-b830-bc0f3f4fdde283=159757936955=BTC-USD270=3.53271=0.6197183160=20250411-01:58:15.77496737=04061895-6687-4319-98dd-28dc2ef796055797=210=059
20250411-01:58:15.893246000 : 8=FIXT.1.19=28835=X49=Coinbase56=24ab46f784d1b20db435b852086e325034=3950=TEST52=20250411-01:58:15.776163369=2262=9476afd5-fdba-42be-bb0c-485d57b711d5268=1279=2269=1278=04061895-6687-4319-98dd-28dc2ef7960583=159757937055=BTC-USD270=3.37271=0.0000000060=20250411-01:58:15.77496758=FILLED10=134
20250411-01:58:16.179093000 : 8=FIXT.1.19=28235=X49=Coinbase56=24ab46f784d1b20db435b852086e325034=4050=TEST52=20250411-01:58:16.063401369=2262=9476afd5-fdba-42be-bb0c-485d57b711d5268=1279=0269=083=159757937155=BTC-USD270=3.87271=0.6232294660=20250411-01:58:16.06199640=237=4ff4c10c-af5b-437b-b9f5-9e7342b6897510=219
20250411-01:58:16.179855000 : 8=FIXT.1.19=32535=X49=Coinbase56=24ab46f784d1b20db435b852086e325034=4150=TEST52=20250411-01:58:16.063411369=2262=9476afd5-fdba-42be-bb0c-485d57b711d5268=1279=0269=2278=c5b88ea9-605d-4595-ac52-f7c3f08523ba83=159757937255=BTC-USD270=3.55271=0.6232294660=20250411-01:58:16.06199637=4ff4c10c-af5b-437b-b9f5-9e7342b689755797=110=171
20250411-01:58:16.180262000 : 8=FIXT.1.19=28835=X49=Coinbase56=24ab46f784d1b20db435b852086e325034=4250=TEST52=20250411-01:58:16.063414369=2262=9476afd5-fdba-42be-bb0c-485d57b711d5268=1279=2269=0278=4ff4c10c-af5b-437b-b9f5-9e7342b6897583=159757937355=BTC-USD270=3.87271=0.0000000060=20250411-01:58:16.06199658=FILLED10=135
20250411-01:58:16.195571000 : 8=FIXT.1.19=91735=W49=Coinbase56=24ab46f784d1b20db435b852086e325034=4350=TEST52=20250411-01:58:16.077687369=2262=9476afd5-fdba-42be-bb0c-485d57b711d583=1597579370893=N55=BTC-USD1682=full_trading268=10269=0278=4d60a78e-b39b-420e-b830-bc0f3f4fdde2270=3.53271=255854.97040679269=0278=9d9353ab-229f-423a-89a3-c52a46543bc9270=3.53271=18127.30103418269=0278=bf5e201a-eb8a-4b1d-984a-ecf1462585a4270=3.52271=0.62322946269=0278=ab68ad0e-c039-4714-8601-94d5a1e3daf2270=3.51271=0.62322946269=0278=51f0c849-b2bc-470d-b4f7-ec6a9e92d159270=3.50271=0.62322946269=0278=f5fc5e68-a52c-44d3-87ef-3785312f4782270=3.48271=0.29310888269=0278=dcccb470-c535-433a-9198-4e2b4c26d99d270=3.47271=0.29311495269=0278=89a50502-9ad3-4f70-9e00-a34d73b98681270=3.47271=0.62216729269=0278=f05d9766-970d-44ca-aa4d-e8b2720bbda8270=3.46271=0.29026870269=0278=4e6f389b-e251-4fa6-833c-4d41ac01f9cc270=3.46271=0.5283092710=003
20250411-01:58:16.199283000 : 8=FIXT.1.19=14035=334=349=24ab46f784d1b20db435b852086e325052=20250411-01:58:16.19856=Coinbase45=4358=Tag appears more than once371=269372=W373=1310=209
20250411-01:58:16.199483000 : 8=FIXT.1.19=90835=W49=Coinbase56=24ab46f784d1b20db435b852086e325034=4450=TEST52=20250411-01:58:16.077923369=2262=9476afd5-fdba-42be-bb0c-485d57b711d583=1597579370893=N55=BTC-USD1682=full_trading268=10269=0278=5372b158-73b4-47ff-9c24-1c8df9ea18c3270=3.46271=0.62322946269=0278=2c4d7d5a-33aa-4058-b546-480b6a2168a4270=3.44271=0.29828577269=0278=37dbcf16-0b3d-4f67-bc90-e36268b99e0e270=3.42271=0.30270947269=0278=4c63c0b7-30e0-4ef1-931f-0090359f978e270=3.41271=0.32158962269=0278=d6b4aa4e-d588-4c96-83aa-8e8d8accb1a4270=3.41271=0.30121104269=0278=53df6705-3c5d-4895-881d-6a43ab91b73e270=3.40271=0.60237902269=0278=88221fe9-68b0-48cf-acca-f9b353f912a1270=3.40271=0.62322946269=0278=e8b3d8da-1663-413c-b7fb-6aba23b01440270=3.39271=0.31006477269=0278=6ca5464b-b3e2-4bc0-a38e-f2b71d50129c270=3.39271=0.62322946269=0278=3daa45cc-1b85-4a14-be19-fc8c8f23ff66270=3.39271=0.6232294610=071
20250411-01:58:16.200423000 : 8=FIXT.1.19=14035=334=449=24ab46f784d1b20db435b852086e325052=20250411-01:58:16.19956=Coinbase45=4458=Tag appears more than once371=269372=W373=1310=212
20250411-01:58:16.200567000 : 8=FIXT.1.19=90835=W49=Coinbase56=24ab46f784d1b20db435b852086e325034=4550=TEST52=20250411-01:58:16.078174369=2262=9476afd5-fdba-42be-bb0c-485d57b711d583=1597579370893=N55=BTC-USD1682=full_trading268=10269=0278=beb774f7-441b-4c7e-8847-e548ba1f47ce270=3.39271=0.62146893269=0278=bcbe17c3-9059-4c38-8ab8-8e78f1ef9062270=3.38271=0.32617981269=0278=57bb77fd-337f-49bc-a56f-a4e2dff851ee270=3.37271=0.31071676269=0278=b6a1c1a8-fe07-415a-8303-2782e7a58874270=3.36271=0.58107172269=0278=ded4b51d-349f-4726-8379-6761a3576bb6270=3.33271=0.31560513269=0278=ff7aff09-38de-47ac-a3cb-9beacb0b9ad8270=3.33271=0.30682342269=0278=d1da558a-e9d2-4e11-b26e-1eb80a1a34c5270=3.32271=0.31700685269=0278=9ee34527-d4d8-4659-b2ea-cdff3dc4a8fa270=3.32271=0.32181951269=0278=7abf2220-0421-460f-9dbb-14c41564e41a270=3.32271=0.31308436269=0278=69634ec5-f71a-4990-b56d-13c3069a455a270=3.31271=0.3232945810=102
20250411-01:58:16.201854000 : 8=FIXT.1.19=14035=334=549=24ab46f784d1b20db435b852086e325052=20250411-01:58:16.20156=Coinbase45=4558=Tag appears more than once371=269372=W373=1310=198
20250411-01:58:16.202003000 : 8=FIXT.1.19=90835=W49=Coinbase56=24ab46f784d1b20db435b852086e325034=4650=TEST52=20250411-01:58:16.078424369=2262=9476afd5-fdba-42be-bb0c-485d57b711d583=1597579370893=N55=BTC-USD1682=full_trading268=10269=0278=2f333c17-a386-4d52-8ff1-eadcb99bc22f270=3.31271=0.31999220269=0278=f02efc37-0b1e-470b-99ef-e31012887d73270=3.30271=0.32771570269=0278=6d430950-8078-4987-8995-e581564e368d270=3.29271=0.30702763269=0278=841f895a-cd2d-4082-9a37-b50fc19e35bf270=3.28271=0.32610801269=0278=3cf93093-e42b-4c24-95ea-c367d96427fe270=3.27271=0.33588654269=0278=f29c94bc-d1c2-4145-97b0-ecb77d81a8bf270=3.27271=0.31661408269=0278=d208c4fb-56c6-4911-85c9-77b68a5ba6ab270=3.25271=0.30961623269=0278=e88796ff-68c8-4463-914b-46e09fbaf639270=3.25271=0.33589845269=0278=06f345fb-0292-45fc-8237-9ad1a84b541c270=3.24271=0.31528507269=0278=fa20c2c7-df80-4941-9a9c-a6ef2e579480270=3.23271=0.3343244810=091
20250411-01:58:16.202648000 : 8=FIXT.1.19=14035=334=649=24ab46f784d1b20db435b852086e325052=20250411-01:58:16.20256=Coinbase45=4658=Tag appears more than once371=269372=W373=1310=201
20250411-01:58:16.202723000 : 8=FIXT.1.19=90835=W49=Coinbase56=24ab46f784d1b20db435b852086e325034=4750=TEST52=20250411-01:58:16.078674369=2262=9476afd5-fdba-42be-bb0c-485d57b711d583=1597579370893=N55=BTC-USD1682=full_trading268=10269=0278=a833d230-a749-4bf4-823e-93adc40b773d270=3.23271=0.31165878269=0278=2abb6e15-b9cd-415b-8c9b-99a61c750310270=3.22271=0.32048714269=0278=ec44a6d8-ae5f-4809-89d7-0f7a3adac547270=3.21271=0.33230954269=0278=9cf61c67-c4fc-4bac-92fd-d4e2b56248aa270=3.21271=0.33583951269=0278=210b2518-bb42-461a-9c7e-b4e04c5ffcc6270=3.21271=0.32669007269=0278=2e3fa1b2-20f1-4694-9be4-322040b75152270=3.21271=0.32907979269=0278=05dd5607-92c9-4296-8cdc-27cdff004dea270=3.21271=0.32776075269=0278=87944de7-a5f1-4033-a3d8-cbc10f3a5232270=3.20271=0.32225170269=0278=30f6bb59-2469-4e6d-8fa5-13666373901f270=3.19271=0.31386496269=0278=6a5d2852-7ddc-456e-acb5-bfadcc0c1360270=3.19271=0.3215739010=245
20250411-01:58:16.203207000 : 8=FIXT.1.19=14035=334=749=24ab46f784d1b20db435b852086e325052=20250411-01:58:16.20256=Coinbase45=4758=Tag appears more than once371=269372=W373=1310=203
20250411-01:58:16.203313000 : 8=FIXT.1.19=90935=W49=Coinbase56=24ab46f784d1b20db435b852086e325034=4850=TEST52=20250411-01:58:16.078924369=2262=9476afd5-fdba-42be-bb0c-485d57b711d583=1597579370893=N55=BTC-USD1682=full_trading268=10269=0278=5d00d8a2-5aea-4836-ba19-74fe67116df8270=3.18271=0.32651049269=0278=acc71746-3591-4dde-a7e2-c2795d0ad125270=3.17271=0.31577131269=0278=13982796-c2a8-4740-95e2-5aca0fdfd8bb270=3.16271=0.33021170269=0278=9f2f0737-661e-43d7-89f9-959ed5e08306270=3.16271=0.33082075269=0278=7e0e2d14-fa77-4978-8cae-d9660fd13e6d270=3.16271=0.32014975269=0278=82826a7d-848c-4516-a7b6-5ec6881609a8270=2.00271=10.00000000269=0278=590048d5-ee44-49dc-b66d-1a692e055133270=1.94271=0.51546392269=0278=22bdda11-16cd-488b-9fa9-da098dad543e270=1.94271=0.51546392269=0278=d356ef8b-596e-47e7-bf90-cc015b85fc57270=1.93271=0.52331606269=0278=aa8d48bc-97fb-4d00-b923-66d37cc8c66a270=1.93271=0.5233160610=105
20250411-01:58:16.203910000 : 8=FIXT.1.19=14035=334=849=24ab46f784d1b20db435b852086e325052=20250411-01:58:16.20356=Coinbase45=4858=Tag appears more than once371=269372=W373=1310=206
20250411-01:58:16.204007000 : 8=FIXT.1.19=90835=W49=Coinbase56=24ab46f784d1b20db435b852086e325034=4950=TEST52=20250411-01:58:16.079174369=2262=9476afd5-fdba-42be-bb0c-485d57b711d583=1597579370893=N55=BTC-USD1682=full_trading268=10269=0278=7d51dcb4-a7f8-4cca-b2d0-e902403d1b9f270=1.93271=0.52331606269=0278=f7680950-3af2-4723-a6e4-5cbd528ca900270=1.93271=0.52331606269=0278=fdeff994-4866-47af-9dde-a25947a26606270=1.93271=0.52331606269=0278=65e7e2bb-023d-4936-bb4e-ff7625ba7264270=1.93271=0.52331606269=0278=53732639-572c-4cd5-b61e-e4f534d1d540270=1.93271=0.52331606269=0278=24da8927-1dd1-468b-9437-ff366f5bfa11270=1.93271=0.52331606269=0278=baa5862c-41e8-458c-83d3-c095bb68ed17270=1.93271=0.52331606269=0278=92a3c3e3-7afe-4d02-a0d8-96f512b63bb7270=1.93271=0.52331606269=0278=9d2a564e-f178-4966-9baf-5814a1c1686b270=1.93271=0.52331606269=0278=f9e6b978-87f6-4397-8d82-07cf698c123f270=1.93271=0.5233160610=174
20250411-01:58:16.204721000 : 8=FIXT.1.19=14035=334=949=24ab46f784d1b20db435b852086e325052=20250411-01:58:16.20456=Coinbase45=4958=Tag appears more than once371=269372=W373=1310=209
20250411-01:58:16.204826000 : 8=FIXT.1.19=90835=W49=Coinbase56=24ab46f784d1b20db435b852086e325034=5050=TEST52=20250411-01:58:16.079424369=2262=9476afd5-fdba-42be-bb0c-485d57b711d583=1597579370893=N55=BTC-USD1682=full_trading268=10269=0278=3e64b388-13d3-441d-b241-aa8dd6fe55e6270=1.93271=0.52331606269=0278=60300433-87b0-4031-bb1e-12cf9d773d3f270=1.93271=0.52331606269=0278=1bdd5f5a-1d99-4eed-af09-c187bcbbd2d8270=1.93271=0.52331606269=0278=4ed6f6b9-77fb-4255-a188-f243dd0cdb3c270=1.93271=0.52331606269=0278=9ad1fc18-5a38-4edb-ac5c-6ac826a8a846270=1.93271=0.52331606269=0278=1c218c8c-baea-4a1f-838e-4a3a94b468e1270=1.93271=0.52331606269=0278=fd70f5e2-d2c9-472a-ab40-a775afafd73d270=1.93271=0.52331606269=0278=96f5e3a5-1c2a-4db6-a3fb-fd1f13d5d559270=1.93271=0.52331606269=0278=4a015a4c-490a-4c40-974f-9dfb7feb335d270=1.93271=0.52331606269=0278=d919363e-2c54-404f-bc0b-063e2f12bec4270=1.93271=0.5233160610=202
20250411-01:58:16.205627000 : 8=FIXT.1.19=14135=334=1049=24ab46f784d1b20db435b852086e325052=20250411-01:58:16.20556=Coinbase45=5058=Tag appears more than once371=269372=W373=1310=243
20250411-01:58:16.205712000 : 8=FIXT.1.19=90835=W49=Coinbase56=24ab46f784d1b20db435b852086e325034=5150=TEST52=20250411-01:58:16.079674369=2262=9476afd5-fdba-42be-bb0c-485d57b711d583=1597579370893=N55=BTC-USD1682=full_trading268=10269=0278=d4636d6c-85c6-4ac9-9afb-70ca636f4ad4270=1.93271=0.52331606269=0278=bda09690-f345-4c33-ae8b-e8c78da11b5a270=1.93271=0.52331606269=0278=1a81ae10-b700-42a0-89a3-7d7a3eea0ebb270=1.93271=0.52331606269=0278=1ace5afa-e550-4abf-a458-52e46e1b54f0270=1.93271=0.52331606269=0278=2332d1c9-67e7-457a-abfe-f5e9a8c2ea05270=1.93271=0.52331606269=0278=6afa1f19-0ec5-49fd-8b74-06a12a6c5ca9270=1.93271=0.52331606269=0278=3fa3413d-c26c-472f-9cc5-da1c48935c63270=1.93271=0.52331606269=0278=3f9e43c4-2e62-4d51-b4cb-ad207c693331270=1.93271=0.52331606269=0278=29e8bfcf-c764-4f7e-997d-09abf72bbc00270=1.93271=0.52331606269=0278=cf3e8b26-09ae-4dfb-9b84-b12a7e199a5a270=1.93271=0.5233160610=217
20250411-01:58:16.206304000 : 8=FIXT.1.19=14135=334=1149=24ab46f784d1b20db435b852086e325052=20250411-01:58:16.20556=Coinbase45=5158=Tag appears more than once371=269372=W373=1310=245
20250411-01:58:16.206400000 : 8=FIXT.1.19=90835=W49=Coinbase56=24ab46f784d1b20db435b852086e325034=5250=TEST52=20250411-01:58:16.079924369=2262=9476afd5-fdba-42be-bb0c-485d57b711d583=1597579370893=N55=BTC-USD1682=full_trading268=10269=0278=08db3e51-e927-47d3-a9dd-2f887c58dc85270=1.93271=0.52331606269=0278=353ae741-9473-4cc5-9ab7-7e5de8ae55d0270=1.93271=0.52331606269=0278=4d037208-2072-480f-98ac-7be9c24f18f4270=1.93271=0.52331606269=0278=b598f678-da6e-4c01-90ed-d702c42f8a65270=1.93271=0.52331606269=0278=5f69b1a0-b5d1-4715-9be1-9bdf008d97d7270=1.93271=0.52331606269=0278=ef063d15-248a-4eae-97f4-278be5106d80270=1.93271=0.52331606269=0278=f8b20207-84bc-44e9-a2fe-9ad775e2ecb1270=1.93271=0.52331606269=0278=75bce2b7-bc58-4479-8bfb-144f88f2262b270=1.93271=0.52331606269=0278=1f6e2a79-8b10-4a7f-89de-0f1fa03692c7270=1.93271=0.52331606269=0278=d1b80bf5-9b17-44b4-9577-6fe71170b578270=1.93271=0.5233160610=017
20250411-01:58:16.207186000 : 8=FIXT.1.19=14135=334=1249=24ab46f784d1b20db435b852086e325052=20250411-01:58:16.20656=Coinbase45=5258=Tag appears more than once371=269372=W373=1310=248
20250411-01:58:16.403039000 : 8=FIXT.1.19=90835=W49=Coinbase56=24ab46f784d1b20db435b852086e325034=5350=TEST52=20250411-01:58:16.080174369=2262=9476afd5-fdba-42be-bb0c-485d57b711d583=1597579370893=N55=BTC-USD1682=full_trading268=10269=0278=b891e26a-c20c-4fce-ba1c-487fe139a4cc270=1.93271=0.52331606269=0278=5d06d3f6-3189-4394-b3c5-6a2bda14b6d1270=1.93271=0.52331606269=0278=e5791c0f-3937-4a66-9b98-26f79a3891be270=1.93271=0.52331606269=0278=c62591c6-7dfa-46a7-8f20-6a5f22804999270=1.93271=0.52331606269=0278=7c503558-c0b8-457b-8c46-71ece3f7fc8a270=1.93271=0.52331606269=0278=f763bb56-2f21-4a9b-bd48-f84dc1bd5ee5270=1.93271=0.52331606269=0278=42214b03-1fc2-46b3-9e83-91b23a510e5a270=1.93271=0.52331606269=0278=1c7c52ed-7d39-4326-b3b8-98f05a9b3ef0270=1.93271=0.52331606269=0278=3313309e-45e7-4e7b-8c55-4f9a8ec1b351270=1.93271=0.52331606269=0278=78801ffb-ec5a-4c74-9d08-3e86fd9db4dd270=1.93271=0.5233160610=113
20250411-01:58:16.404483000 : 8=FIXT.1.19=14135=334=1349=24ab46f784d1b20db435b852086e325052=20250411-01:58:16.40356=Coinbase45=5358=Tag appears more than once371=269372=W373=1310=249
20250411-01:58:16.422522000 : 8=FIXT.1.19=90835=W49=Coinbase56=24ab46f784d1b20db435b852086e325034=5450=TEST52=20250411-01:58:16.080424369=2262=9476afd5-fdba-42be-bb0c-485d57b711d583=1597579370893=N55=BTC-USD1682=full_trading268=10269=0278=abe6eea4-1d9c-47d7-847f-2f44aa561b3f270=1.93271=0.52331606269=0278=6a6eb56d-2010-43e2-b78e-5f098081bb64270=1.93271=0.52331606269=0278=b53c01ff-f450-4b05-8ad1-e7894b45e0e0270=1.93271=0.52331606269=0278=4747863e-c0a6-4ef5-8faf-e8934bca4f8b270=1.93271=0.52331606269=0278=81a8a629-57f4-4e3a-ac25-2e9ee1f357c2270=1.93271=0.52331606269=0278=1e239259-7be4-476a-845d-1b92fd951d8b270=1.93271=0.52331606269=0278=189eb272-48f9-4915-b7e1-a86dcc505c4a270=1.93271=0.52331606269=0278=0562b9f7-aae3-4961-bd97-f5b8cde0ec34270=1.93271=0.52331606269=0278=5103331b-7300-487b-bc2c-a6032bf4be7e270=1.93271=0.52331606269=0278=78ac85ac-2478-4991-a084-7286982b77cc270=1.93271=0.5233160610=053
20250411-01:58:16.423235000 : 8=FIXT.1.19=14135=334=1449=24ab46f784d1b20db435b852086e325052=20250411-01:58:16.42256=Coinbase45=5458=Tag appears more than once371=269372=W373=1310=252
20250411-01:58:16.423337000 : 8=FIXT.1.19=91135=W49=Coinbase56=24ab46f784d1b20db435b852086e325034=5550=TEST52=20250411-01:58:16.080674369=2262=9476afd5-fdba-42be-bb0c-485d57b711d583=1597579370893=N55=BTC-USD1682=full_trading268=10269=0278=6993b26d-d6dc-4f99-8a53-9500ae5b4ff1270=1.93271=0.52331606269=0278=1c96ab9d-04a6-465a-87e5-3ed33970178f270=1.93271=0.52331606269=0278=6fc0282b-d538-4aa3-8982-bda02bb1b054270=1.93271=0.52331606269=0278=80870aa3-04a2-4d2a-8669-93215130ffee270=1.93271=0.52331606269=0278=b274e872-6923-45fd-b48a-68e685e769cb270=1.93271=0.52331606269=0278=2d4364c0-239c-4f4b-8ce4-2acfe0bb343d270=1.12271=1.00000000269=0278=8fa16a4f-377f-4deb-9a8e-1020aed9edf4270=1.00271=1.00000000269=1278=c5b88ea9-605d-4595-ac52-f7c3f08523ba270=3.55271=5832.32147908269=1278=81523bd3-8912-4789-8761-89a9ee42794b270=3.55271=0.30518966269=1278=0168d414-071e-4176-8910-3b2fad61ee20270=3.55271=0.5772745010=050
20250411-01:58:16.424287000 : 8=FIXT.1.19=14135=334=1549=24ab46f784d1b20db435b852086e325052=20250411-01:58:16.42356=Coinbase45=5558=Tag appears more than once371=269372=W373=1310=255
20250411-01:58:16.424429000 : 8=FIXT.1.19=92435=W49=Coinbase56=24ab46f784d1b20db435b852086e325034=5650=TEST52=20250411-01:58:16.080924369=2262=9476afd5-fdba-42be-bb0c-485d57b711d583=1597579370893=N55=BTC-USD1682=full_trading268=10269=1278=60fc75ca-0052-40b7-9f18-a6aad9d31b84270=3.56271=18037.00000000269=1278=452d7507-afcf-4e82-9acb-6e7272f48089270=3.56271=0.62322946269=1278=0fc1058c-c986-4a94-b177-26d09bf5d48d270=3.56271=0.61971831269=1278=ad00e2cd-d925-46a4-9e7e-941c6faed2c7270=3.57271=18027.00000000269=1278=fec191b5-64da-4a15-ab4b-36a0d3d10750270=3.57271=0.29025301269=1278=878ac31a-dec5-40fb-aaf7-0b605934daf9270=3.57271=0.62322946269=1278=02a780aa-8154-4638-a5ca-53b8198cc724270=3.58271=16937.00000000269=1278=911349fb-1960-4904-9a38-0e2497fb7ccb270=3.58271=0.29896312269=1278=d91e89d4-ac5c-4853-9879-ec8ff5e00a71270=3.59271=17163.00000000269=1278=6937c912-4891-4676-9841-7b686b517ade270=3.59271=0.6232294610=175
20250411-01:58:16.425079000 : 8=FIXT.1.19=14135=334=1649=24ab46f784d1b20db435b852086e325052=20250411-01:58:16.42456=Coinbase45=5658=Tag appears more than once371=269372=W373=1310=002
20250411-01:58:16.425179000 : 8=FIXT.1.19=92835=W49=Coinbase56=24ab46f784d1b20db435b852086e325034=5750=TEST52=20250411-01:58:16.081175369=2262=9476afd5-fdba-42be-bb0c-485d57b711d583=1597579370893=N55=BTC-USD1682=full_trading268=10269=1278=c58dde5a-8c3f-42f2-b87e-3418a1e3dafe270=3.59271=0.62322946269=1278=341d0ad8-6c15-4b5e-aebb-e3caa5af575c270=3.60271=17926.00000000269=1278=9d239e03-1215-4cc7-ad44-3f4097ee70ea270=3.61271=18058.08928020269=1278=dbb0f332-4189-4df5-879b-e55860b13def270=3.62271=0.28062774269=1278=f7639c39-7e8b-44d1-a2f2-9807e2a3228c270=3.62271=0.27709851269=1278=83be9389-2099-4173-a322-b0933bc99358270=3.62271=19973.00000000269=1278=154b96f5-b328-4f0a-9a67-bd407ea92fad270=3.62271=0.62322946269=1278=b89abc22-6b6c-4474-b3fc-ffe21f05cd4e270=3.63271=20016.00000000269=1278=ce0af8a3-149c-4603-905a-be65625fe014270=3.64271=0.27806002269=1278=94b8615f-6fa7-4dc9-bbfa-435fe535bebc270=3.64271=22352.6348945910=064
20250411-01:58:16.425878000 : 8=FIXT.1.19=14135=334=1749=24ab46f784d1b20db435b852086e325052=20250411-01:58:16.42556=Coinbase45=5758=Tag appears more than once371=269372=W373=1310=005
20250411-01:58:16.425984000 : 8=FIXT.1.19=90835=W49=Coinbase56=24ab46f784d1b20db435b852086e325034=5850=TEST52=20250411-01:58:16.081424369=2262=9476afd5-fdba-42be-bb0c-485d57b711d583=1597579370893=N55=BTC-USD1682=full_trading268=10269=1278=582969d2-8318-4a7d-b8bb-01d0f62df420270=3.67271=0.55209819269=1278=cae3885d-f5b2-4de1-830c-0085e27bbb69270=3.69271=0.27722678269=1278=9adacb20-925e-497a-bcbf-32ea23265ab3270=3.69271=0.62146893269=1278=b9732128-11b1-44fd-bea3-94da9fc853fb270=3.71271=0.28488329269=1278=818b83a4-e14e-4ad5-b094-6733f0504003270=3.75271=0.27930225269=1278=3e6990a0-8ef4-4968-8ee8-89b7346c197d270=3.76271=0.28131365269=1278=342794c8-a9d2-4aa5-9886-a819398d69c6270=3.88271=0.27719712269=1278=2839680b-48b3-4f53-86b1-9269987275e7270=3.91271=0.26621275269=1278=fd7b5361-29f8-4b35-bae5-232a64f657b4270=3.95271=0.26131406269=1278=5edaeed0-fae9-4f36-8c77-6fbedf61eefc270=4.02271=0.2509122710=237
20250411-01:58:16.426727000 : 8=FIXT.1.19=14135=334=1849=24ab46f784d1b20db435b852086e325052=20250411-01:58:16.42656=Coinbase45=5858=Tag appears more than once371=269372=W373=1310=008
20250411-01:58:16.426854000 : 8=FIXT.1.19=92235=W49=Coinbase56=24ab46f784d1b20db435b852086e325034=5950=TEST52=20250411-01:58:16.081674369=2262=9476afd5-fdba-42be-bb0c-485d57b711d583=1597579370893=N55=BTC-USD1682=full_trading268=10269=1278=fdbbfd04-ba67-4b23-bbc1-f87f929e7e81270=4.07271=0.24812642269=1278=534b2a85-0852-420d-928b-70cdb6ba2457270=4.10271=0.26961968269=1278=b009f8a1-4a39-493b-b96e-d783e981c915270=4.26271=0.25019574269=1278=729a899c-ac2d-4541-b0a2-cbdd5df9bf98270=10.00271=10.00000000269=1278=eb1e5d45-d081-4ef8-a83e-1f5348fbda96270=10.00271=10.00000000269=1278=0cd67977-85eb-45fa-ae72-d45b92ca24f4270=10.00271=10.00000000269=1278=5d931559-6758-4b75-9d6d-6438d25b497f270=10.00271=10.00000000269=1278=57e43d1d-644a-493e-acd3-69dc5e64dcde270=10.00271=10.00000000269=1278=c1566121-2b63-494d-ac2d-973e9f0115c0270=10.00271=10.00000000269=1278=d0c4a771-9035-4db9-ae7b-ad2d1db5646d270=10.00271=10.0000000010=252
20250411-01:58:16.427711000 : 8=FIXT.1.19=14135=334=1949=24ab46f784d1b20db435b852086e325052=20250411-01:58:16.42756=Coinbase45=5958=Tag appears more than once371=269372=W373=1310=011
20250411-01:58:16.427811000 : 8=FIXT.1.19=93035=W49=Coinbase56=24ab46f784d1b20db435b852086e325034=6050=TEST52=20250411-01:58:16.081924369=2262=9476afd5-fdba-42be-bb0c-485d57b711d583=1597579370893=N55=BTC-USD1682=full_trading268=10269=1278=52c644ea-628a-4576-8e7e-27ec4c90398b270=10.00271=10.00000000269=1278=c3483f66-d8ce-489a-90b9-2bce69e054ee270=10.00271=10.00000000269=1278=55992a5c-cbcd-464a-8f8d-8b58e81e5c0b270=10.00271=10.00000000269=1278=19077009-6f26-4e2d-9dab-04a28231b752270=10.00271=10.00000000269=1278=692097d1-c978-4024-95e9-2bf348b64bbd270=10.00271=10.00000000269=1278=99a92935-11b7-4f21-a64c-c746b53d1777270=10.00271=10.00000000269=1278=dc024b0b-0337-4215-9669-5e5636834397270=10.00271=10.00000000269=1278=c90fcc3a-a36c-4c14-b57f-6db78762e017270=10.00271=10.00000000269=1278=7841891a-bb7c-4034-97c1-41164185edc7270=1000.00271=3.10000000269=1278=381c9fa7-1add-4dd2-9233-f41e2c8821fe270=1000.00271=3.1000000010=021
20250411-01:58:16.428561000 : 8=FIXT.1.19=14135=334=2049=24ab46f784d1b20db435b852086e325052=20250411-01:58:16.42856=Coinbase45=6058=Tag appears more than once371=269372=W373=1310=252
20250411-01:58:16.428655000 : 8=FIXT.1.19=93835=W49=Coinbase56=24ab46f784d1b20db435b852086e325034=6150=TEST52=20250411-01:58:16.082174369=2262=9476afd5-fdba-42be-bb0c-485d57b711d583=1597579370893=N55=BTC-USD1682=full_trading268=10269=1278=928e65c2-7e2d-478b-9310-414fb77f5aae270=1000.00271=3.10000000269=1278=ad4bd3ac-9276-40d5-90f9-e47b1d8ee953270=1000.00271=3.10000000269=1278=79e799dc-4a3d-4922-ad1a-f74eb7eff789270=1000.00271=3.10000000269=1278=04f642b7-750f-4967-b786-0d48eea0f158270=1000.00271=3.10000000269=1278=d0ad653d-3272-4a3b-ba7a-a52029a67a92270=1000.00271=3.10000000269=1278=cad40464-4c62-4bf3-8444-c487fcc8dd01270=1000.00271=3.10000000269=1278=426c6428-d481-4ff7-9de3-f00ff219d654270=1000.00271=3.10000000269=1278=1ed1152d-8c1a-4b29-acdd-bbd1a5c5f35f270=1000.00271=3.10000000269=1278=66526051-b5cb-442f-af90-c609be0a9796270=1000.00271=3.10000000269=1278=f68e4659-5785-4ee9-ac24-3186640a2752270=1000.00271=3.1000000010=061
20250411-01:58:16.429421000 : 8=FIXT.1.19=14135=334=2149=24ab46f784d1b20db435b852086e325052=20250411-01:58:16.42856=Coinbase45=6158=Tag appears more than once371=269372=W373=1310=254
20250411-01:58:16.429554000 : 8=FIXT.1.19=93835=W49=Coinbase56=24ab46f784d1b20db435b852086e325034=6250=TEST52=20250411-01:58:16.082424369=2262=9476afd5-fdba-42be-bb0c-485d57b711d583=1597579370893=N55=BTC-USD1682=full_trading268=10269=1278=38070d38-80a9-4898-8ef7-a0a9da5a4123270=1000.00271=3.10000000269=1278=e4d2d308-ed11-49db-850e-3cbd8258395d270=1000.00271=3.10000000269=1278=d6cfaadc-97ea-43c1-898d-40faea9c1477270=1000.00271=3.10000000269=1278=36876bea-9e3a-4018-b0ac-b75cb8c16953270=1000.00271=3.10000000269=1278=eb244bc5-49e8-4aa3-af8b-3d1a67c90a08270=1000.00271=3.10000000269=1278=3efba776-29ad-4aeb-82d8-0824f161471e270=1000.00271=3.10000000269=1278=de0ddebd-0ca8-4eca-9985-77c10c8629a9270=1000.00271=3.10000000269=1278=dde4408a-fb6b-441c-a7f3-7b8b23ffdb1f270=1000.00271=3.10000000269=1278=3ebd6434-070f-4b4d-8cf3-00368112466d270=1000.00271=3.10000000269=1278=7aa98e13-65f3-4058-9f91-c1f452d02710270=1000.00271=3.1000000010=185
20250411-01:58:16.430368000 : 8=FIXT.1.19=14135=334=2249=24ab46f784d1b20db435b852086e325052=20250411-01:58:16.43056=Coinbase45=6258=Tag appears more than once371=269372=W373=1310=249
20250411-01:58:16.430473000 : 8=FIXT.1.19=93835=W49=Coinbase56=24ab46f784d1b20db435b852086e325034=6350=TEST52=20250411-01:58:16.082675369=2262=9476afd5-fdba-42be-bb0c-485d57b711d583=1597579370893=N55=BTC-USD1682=full_trading268=10269=1278=e86a1fec-3610-460d-8d85-4e1e222ee159270=1000.00271=3.10000000269=1278=6dfac057-72b1-4f2c-b110-03766dea0d31270=1000.00271=3.10000000269=1278=bbb7d0ea-d251-4612-b53e-e528cc0a24ab270=1000.00271=3.10000000269=1278=0782ca37-48cf-4ff3-a74a-35674661586c270=1000.00271=3.10000000269=1278=aead437d-4b62-457f-ac83-62c7cc329fd1270=1000.00271=3.10000000269=1278=af5d47bc-a008-4567-b24f-b0298f250471270=1000.00271=3.10000000269=1278=4c260f58-c427-4a9a-969a-44024ae0c714270=1000.00271=3.10000000269=1278=8c7672e5-7ee8-4fbd-8fdf-7e74e9a77db7270=1000.00271=3.10000000269=1278=b53ec3cc-9abe-4570-b903-34d52148073e270=1000.00271=3.10000000269=1278=37ce984a-0387-4ac9-9094-b83f722036ba270=1000.00271=3.1000000010=251
20250411-01:58:16.430966000 : 8=FIXT.1.19=14135=334=2349=24ab46f784d1b20db435b852086e325052=20250411-01:58:16.43056=Coinbase45=6358=Tag appears more than once371=269372=W373=1310=251
20250411-01:58:16.431039000 : 8=FIXT.1.19=93835=W49=Coinbase56=24ab46f784d1b20db435b852086e325034=6450=TEST52=20250411-01:58:16.082924369=2262=9476afd5-fdba-42be-bb0c-485d57b711d583=1597579370893=N55=BTC-USD1682=full_trading268=10269=1278=0d383649-dc6c-4df2-b821-aa0018f132c7270=1000.00271=3.10000000269=1278=e39ae0ce-9e7f-4f0d-a765-5308d473bb61270=1000.00271=3.10000000269=1278=4882324e-3b5c-4b7a-b096-e8c6d9888671270=1000.00271=3.10000000269=1278=6e5c7dbd-a2cc-401f-a5b2-3902088f4ab2270=1000.00271=3.10000000269=1278=10ffac08-946a-4a30-b57a-0d78450345d9270=1000.00271=3.10000000269=1278=67784af5-72bf-4d16-a6b3-25336e2c1843270=1000.00271=3.10000000269=1278=4d8b3bbc-0dc2-4044-875c-c079ec538136270=1000.00271=3.10000000269=1278=dfba5f1e-21f5-48e3-adce-b8b6bfe71467270=1000.00271=3.10000000269=1278=e51b4e33-5eaa-46ef-936b-a74a890397e8270=1000.00271=3.10000000269=1278=8cf5dfa8-858b-48a3-9d94-78522c257473270=1000.00271=3.1000000010=039
20250411-01:58:16.431507000 : 8=FIXT.1.19=14135=334=2449=24ab46f784d1b20db435b852086e325052=20250411-01:58:16.43156=Coinbase45=6458=Tag appears more than once371=269372=W373=1310=254
20250411-01:58:16.431576000 : 8=FIXT.1.19=93835=W49=Coinbase56=24ab46f784d1b20db435b852086e325034=6550=TEST52=20250411-01:58:16.083175369=2262=9476afd5-fdba-42be-bb0c-485d57b711d583=1597579370893=N55=BTC-USD1682=full_trading268=10269=1278=a153b9d2-993d-4f03-a974-b8a081e128e8270=1000.00271=3.10000000269=1278=1eebe866-0f6e-4d4a-a28b-78f4e3368b0a270=1000.00271=3.10000000269=1278=300132d8-113f-4bf7-ba0c-4d93a272f55b270=1000.00271=3.10000000269=1278=757f3122-27d2-4f32-90b8-ead1eef9b936270=1000.00271=3.10000000269=1278=2b68b5de-4153-4cac-ace3-102e4fa788fd270=1000.00271=3.10000000269=1278=b01f252a-1657-4df0-a122-58a23109a7c2270=1000.00271=3.10000000269=1278=dbc57e4e-6abd-4d66-8d18-bd13caaa77b1270=1000.00271=3.10000000269=1278=948b05dc-a481-409f-b8ad-a502eb595906270=1000.00271=3.10000000269=1278=e00f9703-6e16-4237-a2c6-701829d11bf1270=1000.00271=3.10000000269=1278=fd52f47a-3f11-47bc-9952-9708617d0ecd270=1000.00271=3.1000000010=053
20250411-01:58:16.432236000 : 8=FIXT.1.19=14135=334=2549=24ab46f784d1b20db435b852086e325052=20250411-01:58:16.43156=Coinbase45=6558=Tag appears more than once371=269372=W373=1310=000
20250411-01:58:16.432295000 : 8=FIXT.1.19=93835=W49=Coinbase56=24ab46f784d1b20db435b852086e325034=6650=TEST52=20250411-01:58:16.083425369=2262=9476afd5-fdba-42be-bb0c-485d57b711d583=1597579370893=N55=BTC-USD1682=full_trading268=10269=1278=f7f75b14-27c3-469c-89fb-6a98b43c61bf270=1000.00271=3.10000000269=1278=25dbeb09-7901-4280-b0c3-720d7ed03d7d270=1000.00271=3.10000000269=1278=52164a1f-599f-4c43-a9ed-f93403506e67270=1000.00271=3.10000000269=1278=c71c35ea-f60f-4a41-b43a-4947bbcbafad270=1000.00271=3.10000000269=1278=2de342bc-a1be-46f3-9fc6-731297726934270=1000.00271=3.10000000269=1278=7ff4c5fc-bc9b-4845-940b-4837a672e13a270=1000.00271=3.10000000269=1278=2d270775-33eb-4328-8dad-7d206612f9f6270=1000.00271=3.10000000269=1278=c4754378-f787-4100-81af-564443a86a91270=1000.00271=3.10000000269=1278=59e16255-05eb-4fdc-8be1-3c4f83fc094e270=1000.00271=3.10000000269=1278=041b2f98-1185-49cb-964a-f0456b71e692270=1000.00271=3.1000000010=184
20250411-01:58:16.432895000 : 8=FIXT.1.19=14135=334=2649=24ab46f784d1b20db435b852086e325052=20250411-01:58:16.43256=Coinbase45=6658=Tag appears more than once371=269372=W373=1310=003
20250411-01:58:16.432984000 : 8=FIXT.1.19=93835=W49=Coinbase56=24ab46f784d1b20db435b852086e325034=6750=TEST52=20250411-01:58:16.083675369=2262=9476afd5-fdba-42be-bb0c-485d57b711d583=1597579370893=N55=BTC-USD1682=full_trading268=10269=1278=9a2f3529-481e-4e50-a123-7a2095fe6b2c270=1000.00271=3.10000000269=1278=9ed552a3-3295-4878-85dd-87b7b5590212270=1000.00271=3.10000000269=1278=54bec5c2-bafd-4d7d-851d-59e3553a053f270=1000.00271=3.10000000269=1278=543c1acf-52f2-442b-a893-f7aa9a5dfbd1270=1000.00271=3.10000000269=1278=fec999be-cbd0-42ef-b9c3-82ca92ef0b58270=1000.00271=3.10000000269=1278=24528176-3fc6-45b2-b2f3-9f784c01495a270=1000.00271=3.10000000269=1278=12081678-66a6-4435-a3d7-b65f959cf2ac270=1000.00271=3.10000000269=1278=e7fb6165-8f1a-4b5e-b095-e232b83ee951270=1000.00271=3.10000000269=1278=83ce6582-410a-40bf-9831-8f3d20e3a629270=1000.00271=3.10000000269=1278=bc3a930b-0567-46ba-86a4-712f76466b0b270=1000.00271=3.1000000010=108
20250411-01:58:16.433681000 : 8=FIXT.1.19=14135=334=2749=24ab46f784d1b20db435b852086e325052=20250411-01:58:16.43356=Coinbase45=6758=Tag appears more than once371=269372=W373=1310=006
20250411-01:58:16.433781000 : 8=FIXT.1.19=93835=W49=Coinbase56=24ab46f784d1b20db435b852086e325034=6850=TEST52=20250411-01:58:16.083925369=2262=9476afd5-fdba-42be-bb0c-485d57b711d583=1597579370893=N55=BTC-USD1682=full_trading268=10269=1278=15704973-f5ff-457d-ab31-8f99bb76bf7e270=1000.00271=3.10000000269=1278=7159045b-cbd5-458f-b91f-9fa5241b14b5270=1000.00271=3.10000000269=1278=9fa52a90-f03f-4940-b5ee-39ab937b86f1270=1000.00271=3.10000000269=1278=220f55cd-a279-4bf0-9c80-1dca086d85dc270=1000.00271=3.10000000269=1278=2b1eb468-6bcd-4117-a7c0-214d643ddad4270=1000.00271=3.10000000269=1278=cc23185d-e72e-42cb-8210-61bab29cd778270=1000.00271=3.10000000269=1278=69bb228b-973b-4176-8708-3231cc40102a270=1000.00271=3.10000000269=1278=2ec8035d-7962-4195-8388-c9fbad52ac8a270=1000.00271=3.10000000269=1278=7d39e416-0b7b-471f-a9ac-455ab1bce5a7270=1000.00271=3.10000000269=1278=7067378d-2a65-41f2-acb0-ef30ddbc3e5a270=1000.00271=3.1000000010=189
20250411-01:58:16.434463000 : 8=FIXT.1.19=14135=334=2849=24ab46f784d1b20db435b852086e325052=20250411-01:58:16.43456=Coinbase45=6858=Tag appears more than once371=269372=W373=1310=009
20250411-01:58:16.434618000 : 8=FIXT.1.19=93835=W49=Coinbase56=24ab46f784d1b20db435b852086e325034=6950=TEST52=20250411-01:58:16.084175369=2262=9476afd5-fdba-42be-bb0c-485d57b711d583=1597579370893=N55=BTC-USD1682=full_trading268=10269=1278=bf3fde78-6cff-4477-b381-4b5d2e68f36f270=1000.00271=3.10000000269=1278=93a2a8a3-61d4-410c-9446-8eabaafc5f29270=1000.00271=3.10000000269=1278=5afddb61-63ab-417b-a28a-41c4c03a6612270=1000.00271=3.10000000269=1278=a4280417-189c-4f76-9d2e-6ec652010bf5270=1000.00271=3.10000000269=1278=ddeb78a2-e110-4828-ba3d-c9b4837e7dd7270=1000.00271=3.10000000269=1278=fcec6c90-441a-4f4a-a94e-9003355657ef270=1000.00271=3.10000000269=1278=6db15389-dfb3-4156-8a4e-ce2ac80f2b15270=1000.00271=3.10000000269=1278=47dfefc3-6f05-4b57-8aec-2bf3e6c70c2d270=1000.00271=3.10000000269=1278=fb9fd019-4b4f-4880-82bb-3df6d1ef468a270=1000.00271=3.10000000269=1278=2cff9acd-42cb-43a5-8d50-51e676b7e763270=1000.00271=3.1000000010=026
20250411-01:58:16.435243000 : 8=FIXT.1.19=14135=334=2949=24ab46f784d1b20db435b852086e325052=20250411-01:58:16.43456=Coinbase45=6958=Tag appears more than once371=269372=W373=1310=011
20250411-01:58:16.435327000 : 8=FIXT.1.19=93835=W49=Coinbase56=24ab46f784d1b20db435b852086e325034=7050=TEST52=20250411-01:58:16.084425369=2262=9476afd5-fdba-42be-bb0c-485d57b711d583=1597579370893=N55=BTC-USD1682=full_trading268=10269=1278=6e6eeb59-4728-4811-9a44-c857df6aca42270=1000.00271=3.10000000269=1278=81798560-263f-4819-a528-5f3fbbc7b042270=1000.00271=3.10000000269=1278=81fbf9a8-82f4-4fe4-9fa5-3773b212ebf4270=1000.00271=3.10000000269=1278=5d3b9566-276d-47fe-a111-12c17f53f501270=1000.00271=3.10000000269=1278=8eb1b3b3-c813-48b1-b839-993672108d91270=1000.00271=3.10000000269=1278=4feb6e93-6149-481b-8d58-e1c8e6c5cda1270=1000.00271=3.10000000269=1278=f8611e72-4056-4b7c-9779-4d54cd151d44270=1000.00271=3.10000000269=1278=7a129f7c-d9ba-4ea3-a267-b7d82b2e07d9270=1000.00271=3.10000000269=1278=01f359f0-c38f-416b-af00-183907218793270=1000.00271=3.10000000269=1278=11741cec-9c08-4a20-99dc-6b9f63130b0e270=1000.00271=3.1000000010=209
20250411-01:58:16.435942000 : 8=FIXT.1.19=14135=334=3049=24ab46f784d1b20db435b852086e325052=20250411-01:58:16.43556=Coinbase45=7058=Tag appears more than once371=269372=W373=1310=252
20250411-01:58:16.436020000 : 8=FIXT.1.19=93835=W49=Coinbase56=24ab46f784d1b20db435b852086e325034=7150=TEST52=20250411-01:58:16.084675369=2262=9476afd5-fdba-42be-bb0c-485d57b711d583=1597579370893=N55=BTC-USD1682=full_trading268=10269=1278=08db2574-ad52-4520-ab5b-c3c7591eb781270=1000.00271=3.10000000269=1278=b06f2249-179c-4a15-8e98-7b76083b808b270=1000.00271=3.10000000269=1278=9e88fede-6d19-4c1f-863b-5a7d66781436270=1000.00271=3.10000000269=1278=75e1d8b4-7201-41fe-a687-7d93420af323270=1000.00271=3.10000000269=1278=d00aa7dd-ce7f-4f8b-9a2e-880c1ea30845270=1000.00271=3.10000000269=1278=584a483f-23bf-4d8b-809f-69cf3c110f60270=1000.00271=3.10000000269=1278=dc98524e-27e2-4863-99e4-7a0097a6ee90270=1000.00271=3.10000000269=1278=82a11ac9-4f46-44b7-a0bc-a5a4cfe686e0270=1000.00271=3.10000000269=1278=f946bb05-900c-41fc-9908-41489e97ff20270=1000.00271=3.10000000269=1278=1f9186d6-0312-4677-ba96-fdb014cdff2c270=1000.00271=3.1000000010=044
20250411-01:58:16.436560000 : 8=FIXT.1.19=14135=334=3149=24ab46f784d1b20db435b852086e325052=20250411-01:58:16.43656=Coinbase45=7158=Tag appears more than once371=269372=W373=1310=255
20250411-01:58:16.436629000 : 8=FIXT.1.19=93835=W49=Coinbase56=24ab46f784d1b20db435b852086e325034=7250=TEST52=20250411-01:58:16.084925369=2262=9476afd5-fdba-42be-bb0c-485d57b711d583=1597579370893=N55=BTC-USD1682=full_trading268=10269=1278=c3b67be7-2b63-4884-b311-80f28496c2c4270=1000.00271=3.10000000269=1278=6576c7f8-a4e2-4417-b854-5fef0e705fbe270=1000.00271=3.10000000269=1278=c2102c71-62f0-4eee-ae60-0777ed26a8e6270=1000.00271=3.10000000269=1278=c823a2b6-849e-4839-a2fd-cd9f459cae6c270=1000.00271=3.10000000269=1278=a051e195-4472-4a8a-8591-08a2c04a33c4270=1000.00271=3.10000000269=1278=ec81b8c4-b703-4afd-a701-ce34011f60f6270=1000.00271=3.10000000269=1278=b1172677-f493-4f32-a200-0710cf8c397f270=1000.00271=3.10000000269=1278=b1a58a75-5fca-43db-b9c6-a26920e8f66e270=1000.00271=3.10000000269=1278=038bea41-b91d-4884-b992-3e5431ef9857270=1000.00271=3.10000000269=1278=55063782-f2ea-4c84-9491-8e8e89d1dfd1270=1000.00271=3.1000000010=015
20250411-01:58:16.437105000 : 8=FIXT.1.19=14135=334=3249=24ab46f784d1b20db435b852086e325052=20250411-01:58:16.43656=Coinbase45=7258=Tag appears more than once371=269372=W373=1310=001
20250411-01:58:16.437172000 : 8=FIXT.1.19=93835=W49=Coinbase56=24ab46f784d1b20db435b852086e325034=7350=TEST52=20250411-01:58:16.085175369=2262=9476afd5-fdba-42be-bb0c-485d57b711d583=1597579370893=N55=BTC-USD1682=full_trading268=10269=1278=bb2011e8-d05d-40ac-9e9c-3b720422e38d270=1000.00271=3.10000000269=1278=64dd3b4a-ce8a-4b63-9937-266e832c0f21270=1000.00271=3.10000000269=1278=d64f7d2a-aa83-486c-92a8-3314c4eddd58270=1000.00271=3.10000000269=1278=0df9641b-d89d-4222-a8ea-bcddf0d555f5270=1000.00271=3.10000000269=1278=7a315b16-a05f-408d-b8c1-2704af9bf767270=1000.00271=3.10000000269=1278=0e9712a8-d00f-4864-a478-f7f591718f91270=1000.00271=3.10000000269=1278=94db025d-eada-49e3-b13c-b667ca07f829270=1000.00271=3.10000000269=1278=a88ccd1f-8f8d-46af-8fb6-20adba35f7d1270=1000.00271=3.10000000269=1278=99d4e235-c8ec-4efc-938c-9a1923eafc96270=1000.00271=3.10000000269=1278=a4fc7173-7583-4f8b-b256-2921bef83c84270=1000.00271=3.1000000010=024
20250411-01:58:16.437727000 : 8=FIXT.1.19=14135=334=3349=24ab46f784d1b20db435b852086e325052=20250411-01:58:16.43756=Coinbase45=7358=Tag appears more than once371=269372=W373=1310=004
20250411-01:58:16.437821000 : 8=FIXT.1.19=93835=W49=Coinbase56=24ab46f784d1b20db435b852086e325034=7450=TEST52=20250411-01:58:16.085425369=2262=9476afd5-fdba-42be-bb0c-485d57b711d583=1597579370893=N55=BTC-USD1682=full_trading268=10269=1278=18f8afd4-8bbc-4ffa-8e8f-0c1834d74472270=1000.00271=3.10000000269=1278=21fc8cb6-f894-4d09-884e-810b8ebf2ef3270=1000.00271=3.10000000269=1278=0c13b9e6-6797-4b3e-90ce-a1885b26ba53270=1000.00271=3.10000000269=1278=6d8da581-3998-4fc0-99b6-3c5edbd514cb270=1000.00271=3.10000000269=1278=67a70307-be50-4065-872b-47e0de473bc4270=1000.00271=3.10000000269=1278=8ce7be0b-98de-46d0-b1b6-307a4bec36e2270=1000.00271=3.10000000269=1278=856b22f8-5884-4739-adc0-bdd851c5c07d270=1000.00271=3.10000000269=1278=c00ae651-a76b-4bfd-be16-3672b345fe29270=1000.00271=3.10000000269=1278=cae248f9-16fc-44ea-9b79-1dacfc285db6270=1000.00271=3.10000000269=1278=42bb223c-88c6-4a18-8ff3-4fd8d9efda8d270=1000.00271=3.1000000010=027
20250411-01:58:16.438413000 : 8=FIXT.1.19=14135=334=3449=24ab46f784d1b20db435b852086e325052=20250411-01:58:16.43856=Coinbase45=7458=Tag appears more than once371=269372=W373=1310=007
20250411-01:58:16.438499000 : 8=FIXT.1.19=93835=W49=Coinbase56=24ab46f784d1b20db435b852086e325034=7550=TEST52=20250411-01:58:16.085675369=2262=9476afd5-fdba-42be-bb0c-485d57b711d583=1597579370893=N55=BTC-USD1682=full_trading268=10269=1278=d7188b01-22b6-4837-a720-077601f7f483270=1000.00271=3.10000000269=1278=5d85a0a6-ddd9-4e0e-9a1a-7f418ef588e5270=1000.00271=3.10000000269=1278=bff4c39f-7a80-42ce-a178-b1221792e445270=1000.00271=3.10000000269=1278=9ea3d263-b5ab-46c5-bf27-8c0e3e0e5e9e270=1000.00271=3.10000000269=1278=b93347df-d2ab-48ec-b326-4454e64f1d4e270=1000.00271=3.10000000269=1278=57acc40d-8478-444a-990f-067a8e8e846e270=1000.00271=3.10000000269=1278=34419ae2-2c16-427b-a290-845419760fd5270=1000.00271=3.10000000269=1278=ab41de2d-5def-4986-b56e-243d2f99a57c270=1000.00271=3.10000000269=1278=9025524c-03a9-407a-a58a-5258c4ea0a0b270=1000.00271=3.10000000269=1278=60766318-112b-4d83-a384-55693de75519270=1000.00271=3.1000000010=088
20250411-01:58:16.439113000 : 8=FIXT.1.19=14135=334=3549=24ab46f784d1b20db435b852086e325052=20250411-01:58:16.43856=Coinbase45=7558=Tag appears more than once371=269372=W373=1310=009
20250411-01:58:16.439279000 : 8=FIXT.1.19=93835=W49=Coinbase56=24ab46f784d1b20db435b852086e325034=7650=TEST52=20250411-01:58:16.085925369=2262=9476afd5-fdba-42be-bb0c-485d57b711d583=1597579370893=N55=BTC-USD1682=full_trading268=10269=1278=c19b6a2c-086b-4fc1-8dfe-51cb2dc12c1d270=1000.00271=3.10000000269=1278=11126433-0f9c-4450-a35a-39b878e85e68270=1000.00271=3.10000000269=1278=e2e620ee-44fb-4630-a890-d331ba5b2fae270=1000.00271=3.10000000269=1278=9ccf6d4b-a6ca-4a1f-a7bb-77f400ace0c8270=1000.00271=3.10000000269=1278=0e8d6c10-8421-4f19-97dc-d70e715d9033270=1000.00271=3.10000000269=1278=f31ecd5d-8231-44ea-a5c2-0fcc5a699401270=1000.00271=3.10000000269=1278=37fbb559-dc52-48fe-ab65-24910edc338a270=1000.00271=3.10000000269=1278=bc1435c5-c59c-4017-9e59-f1073f04c7e2270=1000.00271=3.10000000269=1278=9c8e1397-0cee-4b05-a66f-5594040791c4270=1000.00271=3.10000000269=1278=248b6703-f829-42bb-a551-4be3075c381e270=1000.00271=3.1000000010=111
20250411-01:58:16.440279000 : 8=FIXT.1.19=14135=334=3649=24ab46f784d1b20db435b852086e325052=20250411-01:58:16.43956=Coinbase45=7658=Tag appears more than once371=269372=W373=1310=012
20250411-01:58:16.440388000 : 8=FIXT.1.19=93835=W49=Coinbase56=24ab46f784d1b20db435b852086e325034=7750=TEST52=20250411-01:58:16.086175369=2262=9476afd5-fdba-42be-bb0c-485d57b711d583=1597579370893=N55=BTC-USD1682=full_trading268=10269=1278=16d257b0-bc92-44f0-822d-3eba61af4bda270=1000.00271=3.10000000269=1278=06257aa1-4043-4cdb-9286-4342b8e59108270=1000.00271=3.10000000269=1278=210ec210-1443-47dc-9e43-9c9ea720a6c3270=1000.00271=3.10000000269=1278=8b79da5d-b78c-4011-b55f-b35c16dc3724270=1000.00271=3.10000000269=1278=076c3703-1104-4e15-a38a-d95bf133f0c5270=1000.00271=3.10000000269=1278=f5a3155c-e449-4102-870d-ab8c8dd24c3d270=1000.00271=3.10000000269=1278=1af2681f-2dec-4d25-aaeb-89b8867b4a3c270=1000.00271=3.10000000269=1278=65c3088d-192a-4213-85a3-7257aa8b20a3270=1000.00271=3.10000000269=1278=2aa7989b-5601-4899-8143-01dda3255e4f270=1000.00271=3.10000000269=1278=099b432c-fa2e-4fd7-952e-22f6debf6877270=1000.00271=3.1000000010=128
20250411-01:58:16.441148000 : 8=FIXT.1.19=14135=334=3749=24ab46f784d1b20db435b852086e325052=20250411-01:58:16.44056=Coinbase45=7758=Tag appears more than once371=269372=W373=1310=006
20250411-01:58:16.441247000 : 8=FIXT.1.19=93835=W49=Coinbase56=24ab46f784d1b20db435b852086e325034=7850=TEST52=20250411-01:58:16.086425369=2262=9476afd5-fdba-42be-bb0c-485d57b711d583=1597579370893=N55=BTC-USD1682=full_trading268=10269=1278=2e71cc31-1235-4b7b-a728-e3335631fe5a270=1000.00271=3.10000000269=1278=ce471ffc-1e26-4afe-afab-27ee5ac8debe270=1000.00271=3.10000000269=1278=113b7fc6-8574-40eb-8682-d077245b84f2270=1000.00271=3.10000000269=1278=bcebce2c-eda8-4b85-841d-27ede39fc5a1270=1000.00271=3.10000000269=1278=0aedaae5-6cc6-4a34-8e48-5e67a5ccc148270=1000.00271=3.10000000269=1278=206e10a5-1173-4860-87b5-7c88afe061f6270=1000.00271=3.10000000269=1278=5c32d94b-696a-4d9b-afa0-665970356008270=1000.00271=3.10000000269=1278=0b7da819-cc1e-4525-a382-ce5b90dc485c270=1000.00271=3.10000000269=1278=2241b3bf-cbbe-44f2-ac75-8032f6283aa8270=1000.00271=3.10000000269=1278=88cada69-adb1-466a-afcd-66e063ad27c0270=1000.00271=3.1000000010=234
20250411-01:58:16.441829000 : 8=FIXT.1.19=14135=334=3849=24ab46f784d1b20db435b852086e325052=20250411-01:58:16.44156=Coinbase45=7858=Tag appears more than once371=269372=W373=1310=009
20250411-01:58:16.441898000 : 8=FIXT.1.19=93835=W49=Coinbase56=24ab46f784d1b20db435b852086e325034=7950=TEST52=20250411-01:58:16.086675369=2262=9476afd5-fdba-42be-bb0c-485d57b711d583=1597579370893=N55=BTC-USD1682=full_trading268=10269=1278=34a52ef5-31c1-4c63-9230-21c85a9a6ba3270=1000.00271=3.10000000269=1278=e109c2c8-fb1d-4ef9-a640-368381323507270=1000.00271=3.10000000269=1278=38fd36c4-4c62-4b4c-8f24-1fe39be94fa1270=1000.00271=3.10000000269=1278=f83f64c8-7d33-472d-a516-9b664ff9c966270=1000.00271=3.10000000269=1278=3411c368-380b-42e6-b656-8552d92904d5270=1000.00271=3.10000000269=1278=4803796e-79f3-4aa4-a8cb-37f13899bf01270=1000.00271=3.10000000269=1278=823f8fbf-7e6d-4ae3-adb9-3a822ff6d09a270=1000.00271=3.10000000269=1278=135624df-a204-490f-a68b-63d74ee09908270=1000.00271=3.10000000269=1278=47cfdedf-22b9-402c-93bd-f311103fd3e0270=1000.00271=3.10000000269=1278=f9173d5e-d872-4661-93f6-28f527e931f7270=1000.00271=3.1000000010=124
20250411-01:58:16.442901000 : 8=FIXT.1.19=14135=334=3949=24ab46f784d1b20db435b852086e325052=20250411-01:58:16.44256=Coinbase45=7958=Tag appears more than once371=269372=W373=1310=012
20250411-01:58:16.633353000 : 8=FIXT.1.19=93835=W49=Coinbase56=24ab46f784d1b20db435b852086e325034=8050=TEST52=20250411-01:58:16.086925369=2262=9476afd5-fdba-42be-bb0c-485d57b711d583=1597579370893=N55=BTC-USD1682=full_trading268=10269=1278=06ab1365-fd39-4701-bd7f-1915ad3c7602270=1000.00271=3.10000000269=1278=012a7c59-5ae4-4da5-97ba-2e3254c889fb270=1000.00271=3.10000000269=1278=a9a0d42f-ad9e-4ea9-8bf0-d5a441fded40270=1000.00271=3.10000000269=1278=f3f3930e-be0e-40b4-a97d-d19501a54885270=1000.00271=3.10000000269=1278=261922d0-5c81-4ab6-832f-4eff45f64890270=1000.00271=3.10000000269=1278=3af4e45f-56f6-4c69-894d-d56a14894a98270=1000.00271=3.10000000269=1278=1c1dd248-49e4-44aa-9e69-323b0f41fa0e270=1000.00271=3.10000000269=1278=b16b002d-1cd6-4869-9c1b-f15c758611bf270=1000.00271=3.10000000269=1278=a0520e61-28ad-448d-87c1-49f0c7358628270=1000.00271=3.10000000269=1278=152d0b57-086f-48cc-80b3-ff14ee9375ed270=1000.00271=3.1000000010=146
20250411-01:58:16.635971000 : 8=FIXT.1.19=14135=334=4049=24ab46f784d1b20db435b852086e325052=20250411-01:58:16.63556=Coinbase45=8058=Tag appears more than once371=269372=W373=1310=000
20250411-01:58:16.636164000 : 8=FIXT.1.19=93835=W49=Coinbase56=24ab46f784d1b20db435b852086e325034=8150=TEST52=20250411-01:58:16.087186369=2262=9476afd5-fdba-42be-bb0c-485d57b711d583=1597579370893=N55=BTC-USD1682=full_trading268=10269=1278=c55fc264-67d2-4e9c-8cce-6c834feff648270=1000.00271=3.10000000269=1278=27361968-189a-4fa6-a3a2-eead03c640d6270=1000.00271=3.10000000269=1278=f5b01c67-f98f-44b9-a511-7f07f8883d9e270=1000.00271=3.10000000269=1278=75a5c14f-8434-4533-a10e-0bf6e92e1000270=1000.00271=3.10000000269=1278=a9b0a826-3659-4105-9ecc-21bcd27b736f270=1000.00271=3.10000000269=1278=1b1bab77-5c52-459b-98e3-e27ff6f8cd04270=1000.00271=3.10000000269=1278=346695f1-fe03-4364-8fc5-006796c8f82f270=1000.00271=3.10000000269=1278=cbbaa36d-2a03-45a2-a230-bd5845d832cd270=1000.00271=3.10000000269=1278=745d4fc0-6710-4c5c-97c3-7b29c4e06839270=1000.00271=3.10000000269=1278=e95fdfba-5db2-4461-8e9c-7bfdf8a9238c270=1000.00271=3.1000000010=121
20250411-01:58:16.637038000 : 8=FIXT.1.19=14135=334=4149=24ab46f784d1b20db435b852086e325052=20250411-01:58:16.63656=Coinbase45=8158=Tag appears more than once371=269372=W373=1310=003
20250411-01:58:16.637139000 : 8=FIXT.1.19=93835=W49=Coinbase56=24ab46f784d1b20db435b852086e325034=8250=TEST52=20250411-01:58:16.087425369=2262=9476afd5-fdba-42be-bb0c-485d57b711d583=1597579370893=N55=BTC-USD1682=full_trading268=10269=1278=33611b39-1fbf-45cc-bf5e-a02bc1f84736270=1000.00271=3.10000000269=1278=51f77b2d-1a69-432d-934b-234eb9e1dfac270=1000.00271=3.10000000269=1278=ab09fdc3-8d50-432f-ab0f-97e8627eac24270=1000.00271=3.10000000269=1278=dde04213-6104-44c5-a811-15834c27b515270=1000.00271=3.10000000269=1278=9af2b85c-4997-4e1b-9147-7d400f059b01270=1000.00271=3.10000000269=1278=40870860-7a8a-4419-a117-e511f779abfa270=1000.00271=3.10000000269=1278=3e8fa7bd-dde0-4fe4-bb2e-e6279841b019270=1000.00271=3.10000000269=1278=4dde1422-98d8-405b-88df-bf245291ad7a270=1000.00271=3.10000000269=1278=6ee8b5a8-bc2f-4a0a-9ae4-7ff1b5dae941270=1000.00271=3.10000000269=1278=3ebc1f7a-2bb5-4ef0-a82f-844b9540f6e8270=1000.00271=3.1000000010=113
20250411-01:58:16.638150000 : 8=FIXT.1.19=14135=334=4249=24ab46f784d1b20db435b852086e325052=20250411-01:58:16.63756=Coinbase45=8258=Tag appears more than once371=269372=W373=1310=006
20250411-01:58:16.638277000 : 8=FIXT.1.19=93835=W49=Coinbase56=24ab46f784d1b20db435b852086e325034=8350=TEST52=20250411-01:58:16.087675369=2262=9476afd5-fdba-42be-bb0c-485d57b711d583=1597579370893=N55=BTC-USD1682=full_trading268=10269=1278=a82d5bb9-1f1a-4575-b580-8d9b60863b10270=1000.00271=3.10000000269=1278=14f89bd5-0233-435c-b608-2e19131b8f6c270=1000.00271=3.10000000269=1278=a2e319e5-aab7-41d4-9d19-98d771a3f1d3270=1000.00271=3.10000000269=1278=dc965e0b-075a-4ba4-a498-02c96d1664ba270=1000.00271=3.10000000269=1278=67b6e68f-ac11-4c05-a54a-2adb555b0123270=1000.00271=3.10000000269=1278=866f52a1-dad9-49d7-ac4a-9da3075407a3270=1000.00271=3.10000000269=1278=0e38234d-a010-40f6-9c6f-a0d574e773cf270=1000.00271=3.10000000269=1278=d6af6749-e3c8-4938-8741-1d5f177cf8e1270=1000.00271=3.10000000269=1278=45ff5e59-2c4d-45ac-9fde-403662dfd1ca270=1000.00271=3.10000000269=1278=dcac314e-c54f-44e3-b96d-ef71539766ed270=1000.00271=3.1000000010=119
20250411-01:58:16.639142000 : 8=FIXT.1.19=14135=334=4349=24ab46f784d1b20db435b852086e325052=20250411-01:58:16.63856=Coinbase45=8358=Tag appears more than once371=269372=W373=1310=009
20250411-01:58:16.648138000 : 8=FIXT.1.19=94635=W49=Coinbase56=24ab46f784d1b20db435b852086e325034=8450=TEST52=20250411-01:58:16.087926369=2262=9476afd5-fdba-42be-bb0c-485d57b711d583=1597579370893=N55=BTC-USD1682=full_trading268=10269=1278=dd6d14ea-760f-4884-a546-1d3c40ebdd7c270=1000.00271=3.10000000269=1278=4f3da0c6-46eb-4b64-b973-cc43e24abccb270=1000.00271=3.10000000269=1278=aa40cda8-4abd-4f52-999a-1a90ed5bf41a270=1000.00271=3.10000000269=1278=687ee4fc-f626-4e4f-abee-1f0ee5af3f72270=1000.00271=3.10000000269=1278=b1ad1135-67ec-4c96-99cb-a626137f3f16270=10000.00271=1.00000000269=1278=e9320f5f-80ae-41ab-af7a-86518d456fb0270=10000.00271=1.00000000269=1278=cd95aff0-36fa-4804-887f-2c3fce3cdc86270=10000.00271=1.00000000269=1278=fbdbcee1-8c29-4478-97df-358d209d8808270=10000.00271=1.00000000269=1278=140f39da-834b-4e42-8e15-6e25287df1f0270=900000.00271=0.00011111269=1278=49f064c5-76fe-4b38-bede-48b60a0a5aec270=900000.00271=0.0001111110=049
20250411-01:58:16.648980000 : 8=FIXT.1.19=14135=334=4449=24ab46f784d1b20db435b852086e325052=20250411-01:58:16.64856=Coinbase45=8458=Tag appears more than once371=269372=W373=1310=012
20250411-01:58:16.649097000 : 8=FIXT.1.19=95835=W49=Coinbase56=24ab46f784d1b20db435b852086e325034=8550=TEST52=20250411-01:58:16.088176369=2262=9476afd5-fdba-42be-bb0c-485d57b711d583=1597579370893=N55=BTC-USD1682=full_trading268=10269=1278=681cf73b-9d37-4101-b940-9da9b1ff61ed270=900000.00271=0.00011111269=1278=3dea1587-e474-4258-b6e8-485c21b56670270=900000.00271=0.00011111269=1278=afd96a7b-3d48-459e-b810-e4ee88353a31270=900000.00271=0.00011111269=1278=a68ae029-b920-4ae7-a775-ccdb800fc252270=900000.00271=0.00001111269=1278=d44508b7-1c9f-4b4f-acb8-99c93d2b99e8270=900000.00271=0.00001111269=1278=304ff106-de40-4381-89c5-c93f7f3e32ae270=900000.00271=0.00001111269=1278=08a0fef8-fcbb-4857-8463-2599cf331386270=900000.00271=0.00011111269=1278=07b2856d-f899-417c-82d5-886f0d85125e270=900000.00271=0.00011111269=1278=12ecb45e-6af8-4804-a942-5c997b9d1502270=900000.00271=0.00011111269=1278=98676c5f-b851-473c-817a-b29243092a25270=900000.00271=0.0000111110=134
20250411-01:58:16.649949000 : 8=FIXT.1.19=14135=334=4549=24ab46f784d1b20db435b852086e325052=20250411-01:58:16.64956=Coinbase45=8558=Tag appears more than once371=269372=W373=1310=015
20250411-01:58:16.650045000 : 8=FIXT.1.19=73335=W49=Coinbase56=24ab46f784d1b20db435b852086e325034=8650=TEST52=20250411-01:58:16.088427369=2262=9476afd5-fdba-42be-bb0c-485d57b711d583=1597579370893=Y55=BTC-USD1682=full_trading268=7269=1278=09afe685-e71f-4ea0-b164-c27737db126d270=900000.00271=0.00001111269=1278=e71ee98f-c329-428d-9893-629b53015ff6270=900000.00271=0.00001111269=1278=124e6fc1-6dde-452b-be03-c00113c8ebdb270=900000.00271=0.00011111269=1278=b71cc7f5-d7c6-4fc0-a0de-59b0eb7fd063270=1000000.00271=1.00000000269=1278=afec127b-a98c-49cb-893f-e385a7e35d32270=1000000.00271=1.00000000269=1278=06df7c57-366d-4d2c-acc2-e6c26d60e9c3270=1000000.00271=1.00000000269=1278=b1c4eb2b-90df-44e0-ae4f-515df4086a9d270=9999999.00271=0.0000100010=203
20250411-01:58:16.650627000 : 8=FIXT.1.19=14135=334=4649=24ab46f784d1b20db435b852086e325052=20250411-01:58:16.65056=Coinbase45=8658=Tag appears more than once371=269372=W373=1310=009
20250411-01:58:16.650755000 : 8=FIXT.1.19=28135=X49=Coinbase56=24ab46f784d1b20db435b852086e325034=8750=TEST52=20250411-01:58:16.118642369=2262=9476afd5-fdba-42be-bb0c-485d57b711d5268=1279=0269=183=159757937455=BTC-USD270=3.2271=0.6232294660=20250411-01:58:16.11749940=237=ff95a9a4-f415-4b5f-bf76-e839e12ef67510=239
20250411-01:58:16.651033000 : 8=FIXT.1.19=32535=X49=Coinbase56=24ab46f784d1b20db435b852086e325034=8850=TEST52=20250411-01:58:16.118654369=2262=9476afd5-fdba-42be-bb0c-485d57b711d5268=1279=0269=2278=4d60a78e-b39b-420e-b830-bc0f3f4fdde283=159757937555=BTC-USD270=3.53271=0.6232294660=20250411-01:58:16.11749937=ff95a9a4-f415-4b5f-bf76-e839e12ef6755797=210=125
20250411-01:58:16.652332000 : 8=FIXT.1.19=28735=X49=Coinbase56=24ab46f784d1b20db435b852086e325034=8950=TEST52=20250411-01:58:16.118657369=2262=9476afd5-fdba-42be-bb0c-485d57b711d5268=1279=2269=1278=ff95a9a4-f415-4b5f-bf76-e839e12ef67583=159757937655=BTC-USD270=3.2271=0.0000000060=20250411-01:58:16.11749958=FILLED10=157
20250411-01:58:16.652584000 : 8=FIXT.1.19=28135=X49=Coinbase56=24ab46f784d1b20db435b852086e325034=9050=TEST52=20250411-01:58:16.290661369=2262=9476afd5-fdba-42be-bb0c-485d57b711d5268=1279=0269=183=159757937755=BTC-USD270=3.2271=0.6232294660=20250411-01:58:16.28926340=237=dd53dde2-99e8-4bdf-988c-090347cdae3c10=068
20250411-01:58:16.652736000 : 8=FIXT.1.19=32535=X49=Coinbase56=24ab46f784d1b20db435b852086e325034=9150=TEST52=20250411-01:58:16.290666369=2262=9476afd5-fdba-42be-bb0c-485d57b711d5268=1279=0269=2278=4d60a78e-b39b-420e-b830-bc0f3f4fdde283=159757937855=BTC-USD270=3.53271=0.6232294660=20250411-01:58:16.28926337=dd53dde2-99e8-4bdf-988c-090347cdae3c5797=210=212
20250411-01:58:16.652878000 : 8=FIXT.1.19=28735=X49=Coinbase56=24ab46f784d1b20db435b852086e325034=9250=TEST52=20250411-01:58:16.290670369=2262=9476afd5-fdba-42be-bb0c-485d57b711d5268=1279=2269=1278=dd53dde2-99e8-4bdf-988c-090347cdae3c83=159757937955=BTC-USD270=3.2271=0.0000000060=20250411-01:58:16.28926358=FILLED10=236
20250411-01:58:16.653192000 : 8=FIXT.1.19=28335=X49=Coinbase56=24ab46f784d1b20db435b852086e325034=9350=TEST52=20250411-01:58:16.343258369=12262=9476afd5-fdba-42be-bb0c-485d57b711d5268=1279=0269=183=159757938055=BTC-USD270=3.18271=0.6232294660=20250411-01:58:16.34211140=237=84d5b40f-9b96-4fb9-8ab9-32d353f8d34310=218
20250411-01:58:16.653570000 : 8=FIXT.1.19=32635=X49=Coinbase56=24ab46f784d1b20db435b852086e325034=9450=TEST52=20250411-01:58:16.343270369=12262=9476afd5-fdba-42be-bb0c-485d57b711d5268=1279=0269=2278=4d60a78e-b39b-420e-b830-bc0f3f4fdde283=159757938155=BTC-USD270=3.53271=0.6232294660=20250411-01:58:16.34211137=84d5b40f-9b96-4fb9-8ab9-32d353f8d3435797=210=039
20250411-01:58:16.654543000 : 8=FIXT.1.19=28935=X49=Coinbase56=24ab46f784d1b20db435b852086e325034=9550=TEST52=20250411-01:58:16.343285369=12262=9476afd5-fdba-42be-bb0c-485d57b711d5268=1279=2269=1278=84d5b40f-9b96-4fb9-8ab9-32d353f8d34383=159757938255=BTC-USD270=3.18271=0.0000000060=20250411-01:58:16.34211158=FILLED10=130
20250411-01:58:16.654756000 : 8=FIXT.1.19=28335=X49=Coinbase56=24ab46f784d1b20db435b852086e325034=9650=TEST52=20250411-01:58:16.345945369=12262=9476afd5-fdba-42be-bb0c-485d57b711d5268=1279=0269=083=159757938355=BTC-USD270=3.82271=0.6232294660=20250411-01:58:16.34489240=237=4e2c57da-de2e-4c19-8f84-8517eff2341e10=082
20250411-01:58:16.656128000 : 8=FIXT.1.19=32635=X49=Coinbase56=24ab46f784d1b20db435b852086e325034=9750=TEST52=20250411-01:58:16.346063369=12262=9476afd5-fdba-42be-bb0c-485d57b711d5268=1279=0269=2278=c5b88ea9-605d-4595-ac52-f7c3f08523ba83=159757938455=BTC-USD270=3.55271=0.6232294660=20250411-01:58:16.34489237=4e2c57da-de2e-4c19-8f84-8517eff2341e5797=110=030
20250411-01:58:16.657006000 : 8=FIXT.1.19=28935=X49=Coinbase56=24ab46f784d1b20db435b852086e325034=9850=TEST52=20250411-01:58:16.346131369=12262=9476afd5-fdba-42be-bb0c-485d57b711d5268=1279=2269=0278=4e2c57da-de2e-4c19-8f84-8517eff2341e83=159757938555=BTC-USD270=3.82271=0.0000000060=20250411-01:58:16.34489258=FILLED10=238
20250411-01:58:16.659038000 : 8=FIXT.1.19=30935=X49=Coinbase56=24ab46f784d1b20db435b852086e325034=9950=TEST52=20250411-01:58:16.482067369=12262=9476afd5-fdba-42be-bb0c-485d57b711d5268=1279=1269=1278=582969d2-8318-4a7d-b8bb-01d0f62df42083=159757938655=BTC-USD270=3.67271=0.5284412860=20250411-01:58:16.48093458=CHANGE_REASON_MODIFY_ORDER10=151
20250411-01:58:16.887066000 : 8=FIXT.1.19=30935=X49=Coinbase56=24ab46f784d1b20db435b852086e325034=10050=TEST52=20250411-01:58:16.769126369=46262=9476afd5-fdba-42be-bb0c-485d57b711d5268=1279=1269=0278=53df6705-3c5d-4895-881d-6a43ab91b73e83=159757938755=BTC-USD270=3.4271=0.5433851860=20250411-01:58:16.76763558=CHANGE_REASON_MODIFY_ORDER10=157
20250411-01:58:17.172067000 : 8=FIXT.1.19=31035=X49=Coinbase56=24ab46f784d1b20db435b852086e325034=10150=TEST52=20250411-01:58:17.054863369=46262=9476afd5-fdba-42be-bb0c-485d57b711d5268=1279=1269=0278=4e6f389b-e251-4fa6-833c-4d41ac01f9cc83=159757938855=BTC-USD270=3.46271=0.5216601760=20250411-01:58:17.05376158=CHANGE_REASON_MODIFY_ORDER10=056
20250411-01:58:17.457808000 : 8=FIXT.1.19=28435=X49=Coinbase56=24ab46f784d1b20db435b852086e325034=10250=TEST52=20250411-01:58:17.341198369=46262=9476afd5-fdba-42be-bb0c-485d57b711d5268=1279=0269=083=159757938955=BTC-USD270=3.88271=0.6232294660=20250411-01:58:17.33931440=237=549f51db-f22c-449e-bbfe-4e23361c14d910=117
20250411-01:58:17.458456000 : 8=FIXT.1.19=32735=X49=Coinbase56=24ab46f784d1b20db435b852086e325034=10350=TEST52=20250411-01:58:17.341208369=46262=9476afd5-fdba-42be-bb0c-485d57b711d5268=1279=0269=2278=c5b88ea9-605d-4595-ac52-f7c3f08523ba83=159757939055=BTC-USD270=3.55271=0.6232294660=20250411-01:58:17.33931437=549f51db-f22c-449e-bbfe-4e23361c14d95797=110=050
20250411-01:58:17.458644000 : 8=FIXT.1.19=29035=X49=Coinbase56=24ab46f784d1b20db435b852086e325034=10450=TEST52=20250411-01:58:17.341212369=46262=9476afd5-fdba-42be-bb0c-485d57b711d5268=1279=2269=0278=549f51db-f22c-449e-bbfe-4e23361c14d983=159757939155=BTC-USD270=3.88271=0.0000000060=20250411-01:58:17.33931458=FILLED10=254
20250411-01:58:17.459036000 : 8=FIXT.1.19=31035=X49=Coinbase56=24ab46f784d1b20db435b852086e325034=10550=TEST52=20250411-01:58:17.341218369=46262=9476afd5-fdba-42be-bb0c-485d57b711d5268=1279=1269=1278=0168d414-071e-4176-8910-3b2fad61ee2083=159757939255=BTC-USD270=3.55271=0.5670286160=20250411-01:58:17.33965958=CHANGE_REASON_MODIFY_ORDER10=070
20250411-01:58:17.741138000 : 8=FIXT.1.19=31035=X49=Coinbase56=24ab46f784d1b20db435b852086e325034=10650=TEST52=20250411-01:58:17.625237369=46262=9476afd5-fdba-42be-bb0c-485d57b711d5268=1279=1269=0278=b6a1c1a8-fe07-415a-8303-2782e7a5887483=159757939355=BTC-USD270=3.36271=0.5589135160=20250411-01:58:17.62375758=CHANGE_REASON_MODIFY_ORDER10=137
20250411-01:58:18.031267000 : 8=FIXT.1.19=31035=X49=Coinbase56=24ab46f784d1b20db435b852086e325034=10750=TEST52=20250411-01:58:17.911798369=46262=9476afd5-fdba-42be-bb0c-485d57b711d5268=1279=1269=1278=582969d2-8318-4a7d-b8bb-01d0f62df42083=159757939455=BTC-USD270=3.67271=0.4772498460=20250411-01:58:17.91066658=CHANGE_REASON_MODIFY_ORDER10=208
20250411-01:58:18.238605000 : 8=FIXT.1.19=28435=X49=Coinbase56=24ab46f784d1b20db435b852086e325034=10850=TEST52=20250411-01:58:18.120558369=46262=9476afd5-fdba-42be-bb0c-485d57b711d5268=1279=0269=183=159757939555=BTC-USD270=3.36271=0.6197183160=20250411-01:58:18.11863140=237=9110f96a-9bee-415f-82c0-43e95e37289b10=236
20250411-01:58:18.239102000 : 8=FIXT.1.19=32735=X49=Coinbase56=24ab46f784d1b20db435b852086e325034=10950=TEST52=20250411-01:58:18.120566369=46262=9476afd5-fdba-42be-bb0c-485d57b711d5268=1279=0269=2278=4d60a78e-b39b-420e-b830-bc0f3f4fdde283=159757939655=BTC-USD270=3.53271=0.6197183160=20250411-01:58:18.11863137=9110f96a-9bee-415f-82c0-43e95e37289b5797=210=062
20250411-01:58:18.239387000 : 8=FIXT.1.19=29035=X49=Coinbase56=24ab46f784d1b20db435b852086e325034=11050=TEST52=20250411-01:58:18.120570369=46262=9476afd5-fdba-42be-bb0c-485d57b711d5268=1279=2269=1278=9110f96a-9bee-415f-82c0-43e95e37289b83=159757939755=BTC-USD270=3.36271=0.0000000060=20250411-01:58:18.11863158=FILLED10=122
20250411-01:58:18.291513000 : 8=FIXT.1.19=28435=X49=Coinbase56=24ab46f784d1b20db435b852086e325034=11150=TEST52=20250411-01:58:18.175513369=46262=9476afd5-fdba-42be-bb0c-485d57b711d5268=1279=0269=083=159757939855=BTC-USD270=3.86271=0.6197183160=20250411-01:58:18.17435540=237=485346bf-00de-4be2-8401-31870d8b40d810=172
20250411-01:58:18.292057000 : 8=FIXT.1.19=32735=X49=Coinbase56=24ab46f784d1b20db435b852086e325034=11250=TEST52=20250411-01:58:18.175523369=46262=9476afd5-fdba-42be-bb0c-485d57b711d5268=1279=0269=2278=c5b88ea9-605d-4595-ac52-f7c3f08523ba83=159757939955=BTC-USD270=3.55271=0.6197183160=20250411-01:58:18.17435537=485346bf-00de-4be2-8401-31870d8b40d85797=110=125
20250411-01:58:18.292305000 : 8=FIXT.1.19=29035=X49=Coinbase56=24ab46f784d1b20db435b852086e325034=11350=TEST52=20250411-01:58:18.175526369=46262=9476afd5-fdba-42be-bb0c-485d57b711d5268=1279=2269=0278=485346bf-00de-4be2-8401-31870d8b40d883=159757940055=BTC-USD270=3.86271=0.0000000060=20250411-01:58:18.17435558=FILLED10=059
20250411-01:58:18.312493000 : 8=FIXT.1.19=30935=X49=Coinbase56=24ab46f784d1b20db435b852086e325034=11450=TEST52=20250411-01:58:18.197326369=46262=9476afd5-fdba-42be-bb0c-485d57b711d5268=1279=1269=0278=53df6705-3c5d-4895-881d-6a43ab91b73e83=159757940155=BTC-USD270=3.4271=0.5391156160=20250411-01:58:18.19601758=CHANGE_REASON_MODIFY_ORDER10=134
20250411-01:58:18.624831000 : 8=FIXT.1.19=31035=X49=Coinbase56=24ab46f784d1b20db435b852086e325034=11550=TEST52=20250411-01:58:18.483247369=46262=9476afd5-fdba-42be-bb0c-485d57b711d5268=1279=1269=0278=4e6f389b-e251-4fa6-833c-4d41ac01f9cc83=159757940255=BTC-USD270=3.46271=0.4734566860=20250411-01:58:18.48181558=CHANGE_REASON_MODIFY_ORDER10=072
20250411-01:58:18.931624000 : 8=FIXT.1.19=31035=X49=Coinbase56=24ab46f784d1b20db435b852086e325034=11650=TEST52=20250411-01:58:18.768885369=46262=9476afd5-fdba-42be-bb0c-485d57b711d5268=1279=1269=1278=0168d414-071e-4176-8910-3b2fad61ee2083=159757940355=BTC-USD270=3.55271=0.5570194960=20250411-01:58:18.76678358=CHANGE_REASON_MODIFY_ORDER10=097
20250411-01:58:19.238851000 : 8=FIXT.1.19=31035=X49=Coinbase56=24ab46f784d1b20db435b852086e325034=11750=TEST52=20250411-01:58:19.054207369=46262=9476afd5-fdba-42be-bb0c-485d57b711d5268=1279=1269=0278=b6a1c1a8-fe07-415a-8303-2782e7a5887483=159757940455=BTC-USD270=3.36271=0.5513427460=20250411-01:58:19.05279458=CHANGE_REASON_MODIFY_ORDER10=120
20250411-01:58:19.457288000 : 8=FIXT.1.19=31035=X49=Coinbase56=24ab46f784d1b20db435b852086e325034=11850=TEST52=20250411-01:58:19.341130369=46262=9476afd5-fdba-42be-bb0c-485d57b711d5268=1279=1269=1278=582969d2-8318-4a7d-b8bb-01d0f62df42083=159757940555=BTC-USD270=3.67271=0.4575683460=20250411-01:58:19.33971358=CHANGE_REASON_MODIFY_ORDER10=179
20250411-01:58:19.609177000 : 8=FIXT.1.19=28435=X49=Coinbase56=24ab46f784d1b20db435b852086e325034=11950=TEST52=20250411-01:58:19.492942369=46262=9476afd5-fdba-42be-bb0c-485d57b711d5268=1279=0269=083=159757940655=BTC-USD270=3.77271=0.6197183160=20250411-01:58:19.49173540=237=d6f6de92-fe0d-4061-8d5f-47e21b04ee1110=126
20250411-01:58:19.609772000 : 8=FIXT.1.19=32735=X49=Coinbase56=24ab46f784d1b20db435b852086e325034=12050=TEST52=20250411-01:58:19.492953369=46262=9476afd5-fdba-42be-bb0c-485d57b711d5268=1279=0269=2278=c5b88ea9-605d-4595-ac52-f7c3f08523ba83=159757940755=BTC-USD270=3.55271=0.6197183160=20250411-01:58:19.49173537=d6f6de92-fe0d-4061-8d5f-47e21b04ee115797=110=071
20250411-01:58:19.609995000 : 8=FIXT.1.19=29035=X49=Coinbase56=24ab46f784d1b20db435b852086e325034=12150=TEST52=20250411-01:58:19.492956369=46262=9476afd5-fdba-42be-bb0c-485d57b711d5268=1279=2269=0278=d6f6de92-fe0d-4061-8d5f-47e21b04ee1183=159757940855=BTC-USD270=3.77271=0.0000000060=20250411-01:58:19.49173558=FILLED10=023
20250411-01:58:19.662307000 : 8=FIXT.1.19=28435=X49=Coinbase56=24ab46f784d1b20db435b852086e325034=12250=TEST52=20250411-01:58:19.546696369=46262=9476afd5-fdba-42be-bb0c-485d57b711d5268=1279=0269=183=159757940955=BTC-USD270=3.25271=0.6197183160=20250411-01:58:19.54539540=237=2493864e-bef3-4e14-9f52-dc514baa71d910=084
20250411-01:58:19.662683000 : 8=FIXT.1.19=32735=X49=Coinbase56=24ab46f784d1b20db435b852086e325034=12350=TEST52=20250411-01:58:19.546705369=46262=9476afd5-fdba-42be-bb0c-485d57b711d5268=1279=0269=2278=4d60a78e-b39b-420e-b830-bc0f3f4fdde283=159757941055=BTC-USD270=3.53271=0.6197183160=20250411-01:58:19.54539537=2493864e-bef3-4e14-9f52-dc514baa71d95797=210=151
20250411-01:58:19.662928000 : 8=FIXT.1.19=29035=X49=Coinbase56=24ab46f784d1b20db435b852086e325034=12450=TEST52=20250411-01:58:19.546840369=46262=9476afd5-fdba-42be-bb0c-485d57b711d5268=1279=2269=1278=2493864e-bef3-4e14-9f52-dc514baa71d983=159757941155=BTC-USD270=3.25271=0.0000000060=20250411-01:58:19.54539558=FILLED10=223
20250411-01:58:19.722049000 : 8=FIXT.1.19=28435=X49=Coinbase56=24ab46f784d1b20db435b852086e325034=12550=TEST52=20250411-01:58:19.606294369=46262=9476afd5-fdba-42be-bb0c-485d57b711d5268=1279=0269=083=159757941255=BTC-USD270=3.73271=0.6232294660=20250411-01:58:19.60510740=237=8be9c9e5-c74f-4ed0-8202-0c0886d90fd010=064
20250411-01:58:19.722551000 : 8=FIXT.1.19=32735=X49=Coinbase56=24ab46f784d1b20db435b852086e325034=12650=TEST52=20250411-01:58:19.606303369=46262=9476afd5-fdba-42be-bb0c-485d57b711d5268=1279=0269=2278=c5b88ea9-605d-4595-ac52-f7c3f08523ba83=159757941355=BTC-USD270=3.55271=0.6232294660=20250411-01:58:19.60510737=8be9c9e5-c74f-4ed0-8202-0c0886d90fd05797=110=011
20250411-01:58:19.722739000 : 8=FIXT.1.19=29035=X49=Coinbase56=24ab46f784d1b20db435b852086e325034=12750=TEST52=20250411-01:58:19.606306369=46262=9476afd5-fdba-42be-bb0c-485d57b711d5268=1279=2269=0278=8be9c9e5-c74f-4ed0-8202-0c0886d90fd083=159757941455=BTC-USD270=3.73271=0.0000000060=20250411-01:58:19.60510758=FILLED10=217
20250411-01:58:19.742477000 : 8=FIXT.1.19=30935=X49=Coinbase56=24ab46f784d1b20db435b852086e325034=12850=TEST52=20250411-01:58:19.627007369=46262=9476afd5-fdba-42be-bb0c-485d57b711d5268=1279=1269=0278=53df6705-3c5d-4895-881d-6a43ab91b73e83=159757941555=BTC-USD270=3.4271=0.5315309360=20250411-01:58:19.62576458=CHANGE_REASON_MODIFY_ORDER10=144
20250411-01:58:19.775122000 : 8=FIXT.1.19=28435=X49=Coinbase56=24ab46f784d1b20db435b852086e325034=12950=TEST52=20250411-01:58:19.659806369=46262=9476afd5-fdba-42be-bb0c-485d57b711d5268=1279=0269=183=159757941655=BTC-USD270=3.24271=0.6232294660=20250411-01:58:19.65867840=237=d71aba8b-e448-4115-87c6-2dade689c3df10=191
20250411-01:58:19.775341000 : 8=FIXT.1.19=32735=X49=Coinbase56=24ab46f784d1b20db435b852086e325034=13050=TEST52=20250411-01:58:19.659814369=46262=9476afd5-fdba-42be-bb0c-485d57b711d5268=1279=0269=2278=4d60a78e-b39b-420e-b830-bc0f3f4fdde283=159757941755=BTC-USD270=3.53271=0.6232294660=20250411-01:58:19.65867837=d71aba8b-e448-4115-87c6-2dade689c3df5797=210=011
20250411-01:58:19.776851000 : 8=FIXT.1.19=29035=X49=Coinbase56=24ab46f784d1b20db435b852086e325034=13150=TEST52=20250411-01:58:19.659818369=46262=9476afd5-fdba-42be-bb0c-485d57b711d5268=1279=2269=1278=d71aba8b-e448-4115-87c6-2dade689c3df83=159757941855=BTC-USD270=3.24271=0.0000000060=20250411-01:58:19.65867858=FILLED10=088
20250411-01:58:19.949520000 : 8=FIXT.1.19=28435=X49=Coinbase56=24ab46f784d1b20db435b852086e325034=13250=TEST52=20250411-01:58:19.834012369=46262=9476afd5-fdba-42be-bb0c-485d57b711d5268=1279=0269=083=159757941955=BTC-USD270=3.72271=0.6232294660=20250411-01:58:19.83247940=237=dafb5033-d76a-4d95-92fe-458645ca818510=030
20250411-01:58:19.950236000 : 8=FIXT.1.19=32735=X49=Coinbase56=24ab46f784d1b20db435b852086e325034=13350=TEST52=20250411-01:58:19.834020369=46262=9476afd5-fdba-42be-bb0c-485d57b711d5268=1279=0269=2278=c5b88ea9-605d-4595-ac52-f7c3f08523ba83=159757942055=BTC-USD270=3.55271=0.6232294660=20250411-01:58:19.83247937=dafb5033-d76a-4d95-92fe-458645ca81855797=110=233
20250411-01:58:19.950448000 : 8=FIXT.1.19=29035=X49=Coinbase56=24ab46f784d1b20db435b852086e325034=13450=TEST52=20250411-01:58:19.834023369=46262=9476afd5-fdba-42be-bb0c-485d57b711d5268=1279=2269=0278=dafb5033-d76a-4d95-92fe-458645ca818583=159757942155=BTC-USD270=3.72271=0.0000000060=20250411-01:58:19.83247958=FILLED10=182
20250411-01:58:20.005560000 : 8=FIXT.1.19=28435=X49=Coinbase56=24ab46f784d1b20db435b852086e325034=13550=TEST52=20250411-01:58:19.890182369=46262=9476afd5-fdba-42be-bb0c-485d57b711d5268=1279=0269=183=159757942255=BTC-USD270=3.33271=0.6232294660=20250411-01:58:19.88918940=237=1c409e0c-c98a-4472-90d7-61926182b09210=096
20250411-01:58:20.006039000 : 8=FIXT.1.19=32735=X49=Coinbase56=24ab46f784d1b20db435b852086e325034=13650=TEST52=20250411-01:58:19.890190369=46262=9476afd5-fdba-42be-bb0c-485d57b711d5268=1279=0269=2278=4d60a78e-b39b-420e-b830-bc0f3f4fdde283=159757942355=BTC-USD270=3.53271=0.6232294660=20250411-01:58:19.88918937=1c409e0c-c98a-4472-90d7-61926182b0925797=210=181
20250411-01:58:20.006231000 : 8=FIXT.1.19=29035=X49=Coinbase56=24ab46f784d1b20db435b852086e325034=13750=TEST52=20250411-01:58:19.890193369=46262=9476afd5-fdba-42be-bb0c-485d57b711d5268=1279=2269=1278=1c409e0c-c98a-4472-90d7-61926182b09283=159757942455=BTC-USD270=3.33271=0.0000000060=20250411-01:58:19.88918958=FILLED10=001
20250411-01:58:20.027215000 : 8=FIXT.1.19=31035=X49=Coinbase56=24ab46f784d1b20db435b852086e325034=13850=TEST52=20250411-01:58:19.912405369=46262=9476afd5-fdba-42be-bb0c-485d57b711d5268=1279=1269=0278=4e6f389b-e251-4fa6-833c-4d41ac01f9cc83=159757942555=BTC-USD270=3.46271=0.4649109760=20250411-01:58:19.91095758=CHANGE_REASON_MODIFY_ORDER10=078
20250411-01:58:20.312983000 : 8=FIXT.1.19=31035=X49=Coinbase56=24ab46f784d1b20db435b852086e325034=13950=TEST52=20250411-01:58:20.197204369=46262=9476afd5-fdba-42be-bb0c-485d57b711d5268=1279=1269=1278=0168d414-071e-4176-8910-3b2fad61ee2083=159757942655=BTC-USD270=3.55271=0.5370145760=20250411-01:58:20.19588558=CHANGE_REASON_MODIFY_ORDER10=065
20250411-01:58:20.599958000 : 8=FIXT.1.19=31035=X49=Coinbase56=24ab46f784d1b20db435b852086e325034=14050=TEST52=20250411-01:58:20.483380369=46262=9476afd5-fdba-42be-bb0c-485d57b711d5268=1279=1269=0278=b6a1c1a8-fe07-415a-8303-2782e7a5887483=159757942755=BTC-USD270=3.36271=0.5338246960=20250411-01:58:20.48195258=CHANGE_REASON_MODIFY_ORDER10=124
20250411-01:58:20.722428000 : 8=FIXT.1.19=28435=X49=Coinbase56=24ab46f784d1b20db435b852086e325034=14150=TEST52=20250411-01:58:20.604089369=46262=9476afd5-fdba-42be-bb0c-485d57b711d5268=1279=0269=083=159757942855=BTC-USD270=3.47271=0.6232294660=20250411-01:58:20.59301340=237=3ae68093-8005-4ce7-891d-5f7ec39489e310=185
20250411-01:58:20.722840000 : 8=FIXT.1.19=28035=X49=Coinbase56=24ab46f784d1b20db435b852086e325034=14250=TEST52=20250411-01:58:20.604106369=46262=9476afd5-fdba-42be-bb0c-485d57b711d5268=1279=0269=0278=3ae68093-8005-4ce7-891d-5f7ec39489e383=159757942955=BTC-USD270=3.47271=0.6232294660=20250411-01:58:20.59301310=016
20250411-01:58:20.866636000 : 8=FIXT.1.19=28435=X49=Coinbase56=24ab46f784d1b20db435b852086e325034=14350=TEST52=20250411-01:58:20.748466369=46262=9476afd5-fdba-42be-bb0c-485d57b711d5268=1279=0269=083=159757943055=BTC-USD270=3.88271=0.6232294660=20250411-01:58:20.74658840=237=e17952c4-446b-4633-9f60-2962bb5d252110=089
20250411-01:58:20.867193000 : 8=FIXT.1.19=32735=X49=Coinbase56=24ab46f784d1b20db435b852086e325034=14450=TEST52=20250411-01:58:20.748475369=46262=9476afd5-fdba-42be-bb0c-485d57b711d5268=1279=0269=2278=c5b88ea9-605d-4595-ac52-f7c3f08523ba83=159757943155=BTC-USD270=3.55271=0.6232294660=20250411-01:58:20.74658837=e17952c4-446b-4633-9f60-2962bb5d25215797=110=039
20250411-01:58:20.867470000 : 8=FIXT.1.19=29035=X49=Coinbase56=24ab46f784d1b20db435b852086e325034=14550=TEST52=20250411-01:58:20.748479369=46262=9476afd5-fdba-42be-bb0c-485d57b711d5268=1279=2269=0278=e17952c4-446b-4633-9f60-2962bb5d252183=159757943255=BTC-USD270=3.88271=0.0000000060=20250411-01:58:20.74658858=FILLED10=252
20250411-01:58:20.887281000 : 8=FIXT.1.19=31035=X49=Coinbase56=24ab46f784d1b20db435b852086e325034=14650=TEST52=20250411-01:58:20.771350369=46262=9476afd5-fdba-42be-bb0c-485d57b711d5268=1279=1269=1278=582969d2-8318-4a7d-b8bb-01d0f62df42083=159757943355=BTC-USD270=3.67271=0.4401874660=20250411-01:58:20.76989858=CHANGE_REASON_MODIFY_ORDER10=189
20250411-01:58:20.919416000 : 8=FIXT.1.19=28435=X49=Coinbase56=24ab46f784d1b20db435b852086e325034=14750=TEST52=20250411-01:58:20.804362369=46262=9476afd5-fdba-42be-bb0c-485d57b711d5268=1279=0269=183=159757943455=BTC-USD270=3.25271=0.6232294660=20250411-01:58:20.80313740=237=dba700d3-554f-4a79-8cd5-769d7e11192a10=001
20250411-01:58:20.919569000 : 8=FIXT.1.19=32735=X49=Coinbase56=24ab46f784d1b20db435b852086e325034=14850=TEST52=20250411-01:58:20.804428369=46262=9476afd5-fdba-42be-bb0c-485d57b711d5268=1279=0269=2278=4d60a78e-b39b-420e-b830-bc0f3f4fdde283=159757943555=BTC-USD270=3.53271=0.6232294660=20250411-01:58:20.80313737=dba700d3-554f-4a79-8cd5-769d7e11192a5797=210=089
20250411-01:58:20.921769000 : 8=FIXT.1.19=29035=X49=Coinbase56=24ab46f784d1b20db435b852086e325034=14950=TEST52=20250411-01:58:20.804436369=46262=9476afd5-fdba-42be-bb0c-485d57b711d5268=1279=2269=1278=dba700d3-554f-4a79-8cd5-769d7e11192a83=159757943655=BTC-USD270=3.25271=0.0000000060=20250411-01:58:20.80313758=FILLED10=162
20250411-01:58:20.993574000 : 8=FIXT.1.19=28435=X49=Coinbase56=24ab46f784d1b20db435b852086e325034=15050=TEST52=20250411-01:58:20.877050369=46262=9476afd5-fdba-42be-bb0c-485d57b711d5268=1279=0269=183=159757943755=BTC-USD270=3.63271=0.6232294660=20250411-01:58:20.87588740=237=0fcf51d1-2f8e-46ae-9b93-ee60b774892010=079
20250411-01:58:20.995504000 : 8=FIXT.1.19=28035=X49=Coinbase56=24ab46f784d1b20db435b852086e325034=15150=TEST52=20250411-01:58:20.877057369=46262=9476afd5-fdba-42be-bb0c-485d57b711d5268=1279=0269=1278=0fcf51d1-2f8e-46ae-9b93-ee60b774892083=159757943855=BTC-USD270=3.63271=0.6232294660=20250411-01:58:20.87588710=183
20250411-01:58:21.171422000 : 8=FIXT.1.19=30935=X49=Coinbase56=24ab46f784d1b20db435b852086e325034=15250=TEST52=20250411-01:58:21.055344369=46262=9476afd5-fdba-42be-bb0c-485d57b711d5268=1279=1269=0278=53df6705-3c5d-4895-881d-6a43ab91b73e83=159757943955=BTC-USD270=3.4271=0.4785495860=20250411-01:58:21.05364958=CHANGE_REASON_MODIFY_ORDER10=150
20250411-01:58:21.288097000 : 8=FIXT.1.19=28435=X49=Coinbase56=24ab46f784d1b20db435b852086e325034=15350=TEST52=20250411-01:58:21.172027369=46262=9476afd5-fdba-42be-bb0c-485d57b711d5268=1279=0269=083=159757944055=BTC-USD270=3.45271=0.6232294660=20250411-01:58:21.17095740=237=9747bd50-a5c9-42c4-899f-2e225a4fb93210=218
20250411-01:58:21.288736000 : 8=FIXT.1.19=28035=X49=Coinbase56=24ab46f784d1b20db435b852086e325034=15450=TEST52=20250411-01:58:21.172033369=46262=9476afd5-fdba-42be-bb0c-485d57b711d5268=1279=0269=0278=9747bd50-a5c9-42c4-899f-2e225a4fb93283=159757944155=BTC-USD270=3.45271=0.6232294660=20250411-01:58:21.17095710=056
20250411-01:58:21.437517000 : 8=FIXT.1.19=28435=X49=Coinbase56=24ab46f784d1b20db435b852086e325034=15550=TEST52=20250411-01:58:21.320383369=46262=9476afd5-fdba-42be-bb0c-485d57b711d5268=1279=0269=183=159757944255=BTC-USD270=3.33271=0.6232294660=20250411-01:58:21.31876340=237=b91da792-cb0a-454b-aef3-61fd205bab6510=170
20250411-01:58:21.439978000 : 8=FIXT.1.19=32735=X49=Coinbase56=24ab46f784d1b20db435b852086e325034=15650=TEST52=20250411-01:58:21.320393369=46262=9476afd5-fdba-42be-bb0c-485d57b711d5268=1279=0269=2278=4d60a78e-b39b-420e-b830-bc0f3f4fdde283=159757944355=BTC-USD270=3.53271=0.6232294660=20250411-01:58:21.31876337=b91da792-cb0a-454b-aef3-61fd205bab655797=210=001
20250411-01:58:21.441392000 : 8=FIXT.1.19=29035=X49=Coinbase56=24ab46f784d1b20db435b852086e325034=15750=TEST52=20250411-01:58:21.320396369=46262=9476afd5-fdba-42be-bb0c-485d57b711d5268=1279=2269=1278=b91da792-cb0a-454b-aef3-61fd205bab6583=159757944455=BTC-USD270=3.33271=0.0000000060=20250411-01:58:21.31876358=FILLED10=077
20250411-01:58:21.456008000 : 8=FIXT.1.19=31035=X49=Coinbase56=24ab46f784d1b20db435b852086e325034=15850=TEST52=20250411-01:58:21.339838369=46262=9476afd5-fdba-42be-bb0c-485d57b711d5268=1279=1269=0278=4e6f389b-e251-4fa6-833c-4d41ac01f9cc83=159757944555=BTC-USD270=3.46271=0.4406048660=20250411-01:58:21.33882558=CHANGE_REASON_MODIFY_ORDER10=071
20250411-01:58:21.491120000 : 8=FIXT.1.19=28435=X49=Coinbase56=24ab46f784d1b20db435b852086e325034=15950=TEST52=20250411-01:58:21.375819369=46262=9476afd5-fdba-42be-bb0c-485d57b711d5268=1279=0269=083=159757944655=BTC-USD270=3.79271=0.6232294660=20250411-01:58:21.37374640=237=c754f9d2-f022-4189-8af1-0b7c8f8676f810=007
20250411-01:58:21.491442000 : 8=FIXT.1.19=32735=X49=Coinbase56=24ab46f784d1b20db435b852086e325034=16050=TEST52=20250411-01:58:21.375898369=46262=9476afd5-fdba-42be-bb0c-485d57b711d5268=1279=0269=2278=c5b88ea9-605d-4595-ac52-f7c3f08523ba83=159757944755=BTC-USD270=3.55271=0.6232294660=20250411-01:58:21.37374637=c754f9d2-f022-4189-8af1-0b7c8f8676f85797=110=211
20250411-01:58:21.491588000 : 8=FIXT.1.19=29035=X49=Coinbase56=24ab46f784d1b20db435b852086e325034=16150=TEST52=20250411-01:58:21.375907369=46262=9476afd5-fdba-42be-bb0c-485d57b711d5268=1279=2269=0278=c754f9d2-f022-4189-8af1-0b7c8f8676f883=159757944855=BTC-USD270=3.79271=0.0000000060=20250411-01:58:21.37374658=FILLED10=155
20250411-01:58:21.565038000 : 8=FIXT.1.19=28335=X49=Coinbase56=24ab46f784d1b20db435b852086e325034=16250=TEST52=20250411-01:58:21.448648369=46262=9476afd5-fdba-42be-bb0c-485d57b711d5268=1279=0269=183=159757944955=BTC-USD270=3.7271=0.6232294660=20250411-01:58:21.44762040=237=af2fcd55-2b08-401e-b227-e74371c1d58210=207
20250411-01:58:21.567346000 : 8=FIXT.1.19=27935=X49=Coinbase56=24ab46f784d1b20db435b852086e325034=16350=TEST52=20250411-01:58:21.448657369=46262=9476afd5-fdba-42be-bb0c-485d57b711d5268=1279=0269=1278=af2fcd55-2b08-401e-b227-e74371c1d58283=159757945055=BTC-USD270=3.7271=0.6232294660=20250411-01:58:21.44762010=048
20250411-01:58:21.743350000 : 8=FIXT.1.19=31035=X49=Coinbase56=24ab46f784d1b20db435b852086e325034=16450=TEST52=20250411-01:58:21.626936369=46262=9476afd5-fdba-42be-bb0c-485d57b711d5268=1279=1269=1278=0168d414-071e-4176-8910-3b2fad61ee2083=159757945155=BTC-USD270=3.55271=0.5295087260=20250411-01:58:21.62496858=CHANGE_REASON_MODIFY_ORDER10=077
20250411-01:58:21.748761000 : 8=FIXT.1.19=27935=X49=Coinbase56=24ab46f784d1b20db435b852086e325034=16550=TEST52=20250411-01:58:21.632787369=46262=9476afd5-fdba-42be-bb0c-485d57b711d5268=1279=0269=083=159757945255=BTC-USD29004=2.208895519560=20250411-01:58:21.63120340=137=a819a3af-cf83-4399-b68d-9a1a2d2b1a7510=158
20250411-01:58:21.748929000 : 8=FIXT.1.19=32735=X49=Coinbase56=24ab46f784d1b20db435b852086e325034=16650=TEST52=20250411-01:58:21.632922369=46262=9476afd5-fdba-42be-bb0c-485d57b711d5268=1279=0269=2278=c5b88ea9-605d-4595-ac52-f7c3f08523ba83=159757945355=BTC-USD270=3.55271=0.6222240960=20250411-01:58:21.63120337=a819a3af-cf83-4399-b68d-9a1a2d2b1a755797=110=040
20250411-01:58:21.751993000 : 8=FIXT.1.19=26635=X49=Coinbase56=24ab46f784d1b20db435b852086e325034=16750=TEST52=20250411-01:58:21.632925369=46262=9476afd5-fdba-42be-bb0c-485d57b711d5268=1279=2269=0278=a819a3af-cf83-4399-b68d-9a1a2d2b1a7583=159757945455=BTC-USD60=20250411-01:58:21.63120358=FILLED10=168
20250411-01:58:21.776543000 : 8=FIXT.1.19=27535=X49=Coinbase56=24ab46f784d1b20db435b852086e325034=16850=TEST52=20250411-01:58:21.661347369=46262=9476afd5-fdba-42be-bb0c-485d57b711d5268=1279=0269=183=159757945555=BTC-USD271=0.6197183160=20250411-01:58:21.66009240=137=fabede3a-221d-49a6-a3aa-6f4abb198c9e10=175
20250411-01:58:21.776956000 : 8=FIXT.1.19=32735=X49=Coinbase56=24ab46f784d1b20db435b852086e325034=16950=TEST52=20250411-01:58:21.661354369=46262=9476afd5-fdba-42be-bb0c-485d57b711d5268=1279=0269=2278=4d60a78e-b39b-420e-b830-bc0f3f4fdde283=159757945655=BTC-USD270=3.53271=0.6197183160=20250411-01:58:21.66009237=fabede3a-221d-49a6-a3aa-6f4abb198c9e5797=210=162
20250411-01:58:21.777237000 : 8=FIXT.1.19=28135=X49=Coinbase56=24ab46f784d1b20db435b852086e325034=17050=TEST52=20250411-01:58:21.661358369=46262=9476afd5-fdba-42be-bb0c-485d57b711d5268=1279=2269=1278=fabede3a-221d-49a6-a3aa-6f4abb198c9e83=159757945755=BTC-USD271=0.0000000060=20250411-01:58:21.66009258=FILLED10=070
20250411-01:58:21.779266000 : 8=FIXT.1.19=28435=X49=Coinbase56=24ab46f784d1b20db435b852086e325034=17150=TEST52=20250411-01:58:21.663067369=46262=9476afd5-fdba-42be-bb0c-485d57b711d5268=1279=0269=083=159757945855=BTC-USD270=3.86271=0.6197183160=20250411-01:58:21.66167040=237=e1e3f33e-7189-4902-9d33-47aa2aee254910=232
20250411-01:58:21.779492000 : 8=FIXT.1.19=32735=X49=Coinbase56=24ab46f784d1b20db435b852086e325034=17250=TEST52=20250411-01:58:21.663074369=46262=9476afd5-fdba-42be-bb0c-485d57b711d5268=1279=0269=2278=c5b88ea9-605d-4595-ac52-f7c3f08523ba83=159757945955=BTC-USD270=3.55271=0.6197183160=20250411-01:58:21.66167037=e1e3f33e-7189-4902-9d33-47aa2aee25495797=110=182
20250411-01:58:21.781451000 : 8=FIXT.1.19=29035=X49=Coinbase56=24ab46f784d1b20db435b852086e325034=17350=TEST52=20250411-01:58:21.663077369=46262=9476afd5-fdba-42be-bb0c-485d57b711d5268=1279=2269=0278=e1e3f33e-7189-4902-9d33-47aa2aee254983=159757946055=BTC-USD270=3.86271=0.0000000060=20250411-01:58:21.66167058=FILLED10=125
20250411-01:58:21.833712000 : 8=FIXT.1.19=28435=X49=Coinbase56=24ab46f784d1b20db435b852086e325034=17450=TEST52=20250411-01:58:21.717912369=46262=9476afd5-fdba-42be-bb0c-485d57b711d5268=1279=0269=183=159757946155=BTC-USD270=3.36271=0.6197183160=20250411-01:58:21.71638240=237=820c098a-f5db-437c-b0c7-9818e4fc6c9f10=122
20250411-01:58:21.836063000 : 8=FIXT.1.19=32735=X49=Coinbase56=24ab46f784d1b20db435b852086e325034=17550=TEST52=20250411-01:58:21.717920369=46262=9476afd5-fdba-42be-bb0c-485d57b711d5268=1279=0269=2278=4d60a78e-b39b-420e-b830-bc0f3f4fdde283=159757946255=BTC-USD270=3.53271=0.6197183160=20250411-01:58:21.71638237=820c098a-f5db-437c-b0c7-9818e4fc6c9f5797=210=204
20250411-01:58:21.836265000 : 8=FIXT.1.19=29035=X49=Coinbase56=24ab46f784d1b20db435b852086e325034=17650=TEST52=20250411-01:58:21.717925369=46262=9476afd5-fdba-42be-bb0c-485d57b711d5268=1279=2269=1278=820c098a-f5db-437c-b0c7-9818e4fc6c9f83=159757946355=BTC-USD270=3.36271=0.0000000060=20250411-01:58:21.71638258=FILLED10=027
20250411-01:58:22.027591000 : 8=FIXT.1.19=31035=X49=Coinbase56=24ab46f784d1b20db435b852086e325034=17750=TEST52=20250411-01:58:21.911498369=46262=9476afd5-fdba-42be-bb0c-485d57b711d5268=1279=1269=0278=b6a1c1a8-fe07-415a-8303-2782e7a5887483=159757946455=BTC-USD270=3.36271=0.5261837660=20250411-01:58:21.91028658=CHANGE_REASON_MODIFY_ORDER10=138
20250411-01:58:22.137855000 : 8=FIXT.1.19=30335=X49=Coinbase56=24ab46f784d1b20db435b852086e325034=17850=TEST52=20250411-01:58:22.020894369=46262=9476afd5-fdba-42be-bb0c-485d57b711d5268=1279=0269=083=159757946555=BTC-USD270=3.37271=0.6228339829004=2.098950512660=20250411-01:58:22.01937040=237=c70c6409-713c-4b98-b18c-45bab47e93ee10=230
20250411-01:58:22.138382000 : 8=FIXT.1.19=28035=X49=Coinbase56=24ab46f784d1b20db435b852086e325034=17950=TEST52=20250411-01:58:22.020909369=46262=9476afd5-fdba-42be-bb0c-485d57b711d5268=1279=0269=0278=c70c6409-713c-4b98-b18c-45bab47e93ee83=159757946655=BTC-USD270=3.37271=0.6228339860=20250411-01:58:22.01937010=162
20250411-01:58:22.236048000 : 8=FIXT.1.19=28435=X49=Coinbase56=24ab46f784d1b20db435b852086e325034=18050=TEST52=20250411-01:58:22.119985369=46262=9476afd5-fdba-42be-bb0c-485d57b711d5268=1279=0269=183=159757946755=BTC-USD270=3.25271=0.6232294660=20250411-01:58:22.11861240=237=d2e7579f-4e11-4c9c-924d-2bdc2cddb07710=158
20250411-01:58:22.239121000 : 8=FIXT.1.19=32735=X49=Coinbase56=24ab46f784d1b20db435b852086e325034=18150=TEST52=20250411-01:58:22.119992369=46262=9476afd5-fdba-42be-bb0c-485d57b711d5268=1279=0269=2278=4d60a78e-b39b-420e-b830-bc0f3f4fdde283=159757946855=BTC-USD270=3.53271=0.6232294660=20250411-01:58:22.11861237=d2e7579f-4e11-4c9c-924d-2bdc2cddb0775797=210=241
20250411-01:58:22.239299000 : 8=FIXT.1.19=29035=X49=Coinbase56=24ab46f784d1b20db435b852086e325034=18250=TEST52=20250411-01:58:22.119997369=46262=9476afd5-fdba-42be-bb0c-485d57b711d5268=1279=2269=1278=d2e7579f-4e11-4c9c-924d-2bdc2cddb07783=159757946955=BTC-USD270=3.25271=0.0000000060=20250411-01:58:22.11861258=FILLED10=064
20250411-01:58:22.263706000 : 8=FIXT.1.19=27935=X49=Coinbase56=24ab46f784d1b20db435b852086e325034=18350=TEST52=20250411-01:58:22.147309369=46262=9476afd5-fdba-42be-bb0c-485d57b711d5268=1279=0269=083=159757947055=BTC-USD29004=2.208895519560=20250411-01:58:22.14584940=137=d64e9606-8f33-4512-828a-8c942844178810=065
20250411-01:58:22.263938000 : 8=FIXT.1.19=32735=X49=Coinbase56=24ab46f784d1b20db435b852086e325034=18450=TEST52=20250411-01:58:22.147324369=46262=9476afd5-fdba-42be-bb0c-485d57b711d5268=1279=0269=2278=c5b88ea9-605d-4595-ac52-f7c3f08523ba83=159757947155=BTC-USD270=3.55271=0.6222240960=20250411-01:58:22.14584937=d64e9606-8f33-4512-828a-8c94284417885797=110=209
20250411-01:58:22.265377000 : 8=FIXT.1.19=26635=X49=Coinbase56=24ab46f784d1b20db435b852086e325034=18550=TEST52=20250411-01:58:22.147340369=46262=9476afd5-fdba-42be-bb0c-485d57b711d5268=1279=2269=0278=d64e9606-8f33-4512-828a-8c942844178883=159757947255=BTC-USD60=20250411-01:58:22.14584958=FILLED10=076
20250411-01:58:22.291404000 : 8=FIXT.1.19=27535=X49=Coinbase56=24ab46f784d1b20db435b852086e325034=18650=TEST52=20250411-01:58:22.175640369=46262=9476afd5-fdba-42be-bb0c-485d57b711d5268=1279=0269=183=159757947355=BTC-USD271=0.6232294660=20250411-01:58:22.17396940=137=eafb7be9-d5a7-4053-9291-c1b0ea8370ec10=254
20250411-01:58:22.291615000 : 8=FIXT.1.19=32735=X49=Coinbase56=24ab46f784d1b20db435b852086e325034=18750=TEST52=20250411-01:58:22.175647369=46262=9476afd5-fdba-42be-bb0c-485d57b711d5268=1279=0269=2278=4d60a78e-b39b-420e-b830-bc0f3f4fdde283=159757947455=BTC-USD270=3.53271=0.6232294660=20250411-01:58:22.17396937=eafb7be9-d5a7-4053-9291-c1b0ea8370ec5797=210=250
20250411-01:58:22.291782000 : 8=FIXT.1.19=28135=X49=Coinbase56=24ab46f784d1b20db435b852086e325034=18850=TEST52=20250411-01:58:22.175651369=46262=9476afd5-fdba-42be-bb0c-485d57b711d5268=1279=2269=1278=eafb7be9-d5a7-4053-9291-c1b0ea8370ec83=159757947555=BTC-USD271=0.0000000060=20250411-01:58:22.17396958=FILLED10=160
20250411-01:58:22.293088000 : 8=FIXT.1.19=28435=X49=Coinbase56=24ab46f784d1b20db435b852086e325034=18950=TEST52=20250411-01:58:22.175719369=46262=9476afd5-fdba-42be-bb0c-485d57b711d5268=1279=0269=083=159757947655=BTC-USD270=3.71271=0.6232294660=20250411-01:58:22.17423140=237=b0ecc678-ae8f-4753-a5de-1af42c703a0510=150
20250411-01:58:22.293299000 : 8=FIXT.1.19=32735=X49=Coinbase56=24ab46f784d1b20db435b852086e325034=19050=TEST52=20250411-01:58:22.175736369=46262=9476afd5-fdba-42be-bb0c-485d57b711d5268=1279=0269=2278=c5b88ea9-605d-4595-ac52-f7c3f08523ba83=159757947755=BTC-USD270=3.55271=0.6232294660=20250411-01:58:22.17423137=b0ecc678-ae8f-4753-a5de-1af42c703a055797=110=098
20250411-01:58:22.293570000 : 8=FIXT.1.19=29035=X49=Coinbase56=24ab46f784d1b20db435b852086e325034=19150=TEST52=20250411-01:58:22.175740369=46262=9476afd5-fdba-42be-bb0c-485d57b711d5268=1279=2269=0278=b0ecc678-ae8f-4753-a5de-1af42c703a0583=159757947855=BTC-USD270=3.71271=0.0000000060=20250411-01:58:22.17423158=FILLED10=038
20250411-01:58:22.663394000 : 8=FIXT.1.19=27935=X49=Coinbase56=24ab46f784d1b20db435b852086e325034=19250=TEST52=20250411-01:58:22.547220369=46262=9476afd5-fdba-42be-bb0c-485d57b711d5268=1279=0269=083=159757947955=BTC-USD29004=2.208895519560=20250411-01:58:22.54607240=137=28055c68-9ba2-4d23-a319-697f362af46810=192
20250411-01:58:22.664547000 : 8=FIXT.1.19=32735=X49=Coinbase56=24ab46f784d1b20db435b852086e325034=19350=TEST52=20250411-01:58:22.547231369=46262=9476afd5-fdba-42be-bb0c-485d57b711d5268=1279=0269=2278=c5b88ea9-605d-4595-ac52-f7c3f08523ba83=159757948055=BTC-USD270=3.55271=0.6222240960=20250411-01:58:22.54607237=28055c68-9ba2-4d23-a319-697f362af4685797=110=076
20250411-01:58:22.664766000 : 8=FIXT.1.19=26635=X49=Coinbase56=24ab46f784d1b20db435b852086e325034=19450=TEST52=20250411-01:58:22.547234369=46262=9476afd5-fdba-42be-bb0c-485d57b711d5268=1279=2269=0278=28055c68-9ba2-4d23-a319-697f362af46883=159757948155=BTC-USD60=20250411-01:58:22.54607258=FILLED10=204
20250411-01:58:22.692377000 : 8=FIXT.1.19=27535=X49=Coinbase56=24ab46f784d1b20db435b852086e325034=19550=TEST52=20250411-01:58:22.575427369=46262=9476afd5-fdba-42be-bb0c-485d57b711d5268=1279=0269=183=159757948255=BTC-USD271=0.6197183160=20250411-01:58:22.57396540=137=2544f3d4-0936-4985-8c01-8bb2ea57e22d10=031
20250411-01:58:22.692615000 : 8=FIXT.1.19=32735=X49=Coinbase56=24ab46f784d1b20db435b852086e325034=19650=TEST52=20250411-01:58:22.575434369=46262=9476afd5-fdba-42be-bb0c-485d57b711d5268=1279=0269=2278=4d60a78e-b39b-420e-b830-bc0f3f4fdde283=159757948355=BTC-USD270=3.53271=0.6197183160=20250411-01:58:22.57396537=2544f3d4-0936-4985-8c01-8bb2ea57e22d5797=210=018
20250411-01:58:22.692741000 : 8=FIXT.1.19=28135=X49=Coinbase56=24ab46f784d1b20db435b852086e325034=19750=TEST52=20250411-01:58:22.575437369=46262=9476afd5-fdba-42be-bb0c-485d57b711d5268=1279=2269=1278=2544f3d4-0936-4985-8c01-8bb2ea57e22d83=159757948455=BTC-USD271=0.0000000060=20250411-01:58:22.57396558=FILLED10=190
20250411-01:58:23.035969000 : 8=FIXT.1.19=28435=X49=Coinbase56=24ab46f784d1b20db435b852086e325034=19850=TEST52=20250411-01:58:22.919599369=46262=9476afd5-fdba-42be-bb0c-485d57b711d5268=1279=0269=183=159757948555=BTC-USD270=3.25271=0.6232294660=20250411-01:58:22.91862140=237=2c4a44b3-6da3-45bc-b7c2-e480f16de8a910=172
20250411-01:58:23.039042000 : 8=FIXT.1.19=32735=X49=Coinbase56=24ab46f784d1b20db435b852086e325034=19950=TEST52=20250411-01:58:22.919608369=46262=9476afd5-fdba-42be-bb0c-485d57b711d5268=1279=0269=2278=4d60a78e-b39b-420e-b830-bc0f3f4fdde283=159757948655=BTC-USD270=3.53271=0.6232294660=20250411-01:58:22.91862137=2c4a44b3-6da3-45bc-b7c2-e480f16de8a95797=210=248
20250411-01:58:23.039236000 : 8=FIXT.1.19=29035=X49=Coinbase56=24ab46f784d1b20db435b852086e325034=20050=TEST52=20250411-01:58:22.919610369=46262=9476afd5-fdba-42be-bb0c-485d57b711d5268=1279=2269=1278=2c4a44b3-6da3-45bc-b7c2-e480f16de8a983=159757948755=BTC-USD270=3.25271=0.0000000060=20250411-01:58:22.91862158=FILLED10=041
20250411-01:58:23.092813000 : 8=FIXT.1.19=28435=X49=Coinbase56=24ab46f784d1b20db435b852086e325034=20150=TEST52=20250411-01:58:22.976006369=46262=9476afd5-fdba-42be-bb0c-485d57b711d5268=1279=0269=083=159757948855=BTC-USD270=3.72271=0.6232294660=20250411-01:58:22.97391240=237=b239566e-ebd9-42da-a3fc-9df505f343d410=164
20250411-01:58:23.093174000 : 8=FIXT.1.19=32735=X49=Coinbase56=24ab46f784d1b20db435b852086e325034=20250=TEST52=20250411-01:58:22.976012369=46262=9476afd5-fdba-42be-bb0c-485d57b711d5268=1279=0269=2278=c5b88ea9-605d-4595-ac52-f7c3f08523ba83=159757948955=BTC-USD270=3.55271=0.6232294660=20250411-01:58:22.97391237=b239566e-ebd9-42da-a3fc-9df505f343d45797=110=118
20250411-01:58:23.093416000 : 8=FIXT.1.19=29035=X49=Coinbase56=24ab46f784d1b20db435b852086e325034=20350=TEST52=20250411-01:58:22.976016369=46262=9476afd5-fdba-42be-bb0c-485d57b711d5268=1279=2269=0278=b239566e-ebd9-42da-a3fc-9df505f343d483=159757949055=BTC-USD270=3.72271=0.0000000060=20250411-01:58:22.97391258=FILLED10=059
20250411-01:58:23.805722000 : 8=FIXT.1.19=27935=X49=Coinbase56=24ab46f784d1b20db435b852086e325034=20450=TEST52=20250411-01:58:23.689960369=46262=9476afd5-fdba-42be-bb0c-485d57b711d5268=1279=0269=083=159757949155=BTC-USD29004=2.208895519560=20250411-01:58:23.68854640=137=b10386ad-c21c-4776-8ec3-d6514786f1dc10=091
20250411-01:58:23.806612000 : 8=FIXT.1.19=32735=X49=Coinbase56=24ab46f784d1b20db435b852086e325034=20550=TEST52=20250411-01:58:23.689971369=46262=9476afd5-fdba-42be-bb0c-485d57b711d5268=1279=0269=2278=c5b88ea9-605d-4595-ac52-f7c3f08523ba83=159757949255=BTC-USD270=3.55271=0.6222240960=20250411-01:58:23.68854637=b10386ad-c21c-4776-8ec3-d6514786f1dc5797=110=240
20250411-01:58:23.806778000 : 8=FIXT.1.19=26635=X49=Coinbase56=24ab46f784d1b20db435b852086e325034=20650=TEST52=20250411-01:58:23.689973369=46262=9476afd5-fdba-42be-bb0c-485d57b711d5268=1279=2269=0278=b10386ad-c21c-4776-8ec3-d6514786f1dc83=159757949355=BTC-USD60=20250411-01:58:23.68854658=FILLED10=111
20250411-01:58:23.833750000 : 8=FIXT.1.19=27535=X49=Coinbase56=24ab46f784d1b20db435b852086e325034=20750=TEST52=20250411-01:58:23.718223369=46262=9476afd5-fdba-42be-bb0c-485d57b711d5268=1279=0269=183=159757949455=BTC-USD271=0.6197183160=20250411-01:58:23.71687940=137=57871049-0d58-4da6-8486-9c8629f5b82510=169
20250411-01:58:23.833967000 : 8=FIXT.1.19=32735=X49=Coinbase56=24ab46f784d1b20db435b852086e325034=20850=TEST52=20250411-01:58:23.718262369=46262=9476afd5-fdba-42be-bb0c-485d57b711d5268=1279=0269=2278=4d60a78e-b39b-420e-b830-bc0f3f4fdde283=159757949555=BTC-USD270=3.53271=0.6197183160=20250411-01:58:23.71687937=57871049-0d58-4da6-8486-9c8629f5b8255797=210=161
20250411-01:58:23.835504000 : 8=FIXT.1.19=28135=X49=Coinbase56=24ab46f784d1b20db435b852086e325034=20950=TEST52=20250411-01:58:23.718316369=46262=9476afd5-fdba-42be-bb0c-485d57b711d5268=1279=2269=1278=57871049-0d58-4da6-8486-9c8629f5b82583=159757949655=BTC-USD271=0.0000000060=20250411-01:58:23.71687958=FILLED10=074
20250411-01:58:24.033776000 : 8=FIXT.1.19=27935=X49=Coinbase56=24ab46f784d1b20db435b852086e325034=21050=TEST52=20250411-01:58:23.918207369=46262=9476afd5-fdba-42be-bb0c-485d57b711d5268=1279=0269=083=159757949755=BTC-USD29004=2.208895519560=20250411-01:58:23.91668540=137=b727c14d-d5d1-4c63-8c47-898ca0024b7110=028
20250411-01:58:24.034350000 : 8=FIXT.1.19=32735=X49=Coinbase56=24ab46f784d1b20db435b852086e325034=21150=TEST52=20250411-01:58:23.918243369=46262=9476afd5-fdba-42be-bb0c-485d57b711d5268=1279=0269=2278=c5b88ea9-605d-4595-ac52-f7c3f08523ba83=159757949855=BTC-USD270=3.55271=0.6222240960=20250411-01:58:23.91668537=b727c14d-d5d1-4c63-8c47-898ca0024b715797=110=175
20250411-01:58:24.034528000 : 8=FIXT.1.19=26635=X49=Coinbase56=24ab46f784d1b20db435b852086e325034=21250=TEST52=20250411-01:58:23.918250369=46262=9476afd5-fdba-42be-bb0c-485d57b711d5268=1279=2269=0278=b727c14d-d5d1-4c63-8c47-898ca0024b7183=159757949955=BTC-USD60=20250411-01:58:23.91668558=FILLED10=042
20250411-01:58:24.063269000 : 8=FIXT.1.19=27535=X49=Coinbase56=24ab46f784d1b20db435b852086e325034=21350=TEST52=20250411-01:58:23.947833369=46262=9476afd5-fdba-42be-bb0c-485d57b711d5268=1279=0269=183=159757950055=BTC-USD271=0.6232294660=20250411-01:58:23.94591940=137=731d4a81-ae53-43e6-b444-1e04422f541c10=254
20250411-01:58:24.063489000 : 8=FIXT.1.19=32735=X49=Coinbase56=24ab46f784d1b20db435b852086e325034=21450=TEST52=20250411-01:58:23.947838369=46262=9476afd5-fdba-42be-bb0c-485d57b711d5268=1279=0269=2278=4d60a78e-b39b-420e-b830-bc0f3f4fdde283=159757950155=BTC-USD270=3.53271=0.6232294660=20250411-01:58:23.94591937=731d4a81-ae53-43e6-b444-1e04422f541c5797=210=248
20250411-01:58:24.063695000 : 8=FIXT.1.19=28135=X49=Coinbase56=24ab46f784d1b20db435b852086e325034=21550=TEST52=20250411-01:58:23.947841369=46262=9476afd5-fdba-42be-bb0c-485d57b711d5268=1279=2269=1278=731d4a81-ae53-43e6-b444-1e04422f541c83=159757950255=BTC-USD271=0.0000000060=20250411-01:58:23.94591958=FILLED10=157
20250411-01:58:24.091097000 : 8=FIXT.1.19=27935=X49=Coinbase56=24ab46f784d1b20db435b852086e325034=21650=TEST52=20250411-01:58:23.975214369=46262=9476afd5-fdba-42be-bb0c-485d57b711d5268=1279=0269=083=159757950355=BTC-USD29004=2.208895519560=20250411-01:58:23.97367540=137=328fb881-c293-46ff-8467-aebb00b696ae10=135
20250411-01:58:24.091639000 : 8=FIXT.1.19=32735=X49=Coinbase56=24ab46f784d1b20db435b852086e325034=21750=TEST52=20250411-01:58:23.975322369=46262=9476afd5-fdba-42be-bb0c-485d57b711d5268=1279=0269=2278=c5b88ea9-605d-4595-ac52-f7c3f08523ba83=159757950455=BTC-USD270=3.55271=0.6222240960=20250411-01:58:23.97367537=328fb881-c293-46ff-8467-aebb00b696ae5797=110=026
20250411-01:58:24.091822000 : 8=FIXT.1.19=26635=X49=Coinbase56=24ab46f784d1b20db435b852086e325034=21850=TEST52=20250411-01:58:23.975326369=46262=9476afd5-fdba-42be-bb0c-485d57b711d5268=1279=2269=0278=328fb881-c293-46ff-8467-aebb00b696ae83=159757950555=BTC-USD60=20250411-01:58:23.97367558=FILLED10=155
20250411-01:58:24.121024000 : 8=FIXT.1.19=27535=X49=Coinbase56=24ab46f784d1b20db435b852086e325034=21950=TEST52=20250411-01:58:24.005446369=46262=9476afd5-fdba-42be-bb0c-485d57b711d5268=1279=0269=183=159757950655=BTC-USD271=0.6197183160=20250411-01:58:24.00361140=137=8e976659-14af-4524-bc9d-a16201f8688e10=013
20250411-01:58:24.121335000 : 8=FIXT.1.19=32735=X49=Coinbase56=24ab46f784d1b20db435b852086e325034=22050=TEST52=20250411-01:58:24.005567369=46262=9476afd5-fdba-42be-bb0c-485d57b711d5268=1279=0269=2278=4d60a78e-b39b-420e-b830-bc0f3f4fdde283=159757950755=BTC-USD270=3.53271=0.6197183160=20250411-01:58:24.00361137=8e976659-14af-4524-bc9d-a16201f8688e5797=210=253
20250411-01:58:24.121531000 : 8=FIXT.1.19=28135=X49=Coinbase56=24ab46f784d1b20db435b852086e325034=22150=TEST52=20250411-01:58:24.005570369=46262=9476afd5-fdba-42be-bb0c-485d57b711d5268=1279=2269=1278=8e976659-14af-4524-bc9d-a16201f8688e83=159757950855=BTC-USD271=0.0000000060=20250411-01:58:24.00361158=FILLED10=160
20250411-01:58:24.147816000 : 8=FIXT.1.19=27935=X49=Coinbase56=24ab46f784d1b20db435b852086e325034=22250=TEST52=20250411-01:58:24.031773369=46262=9476afd5-fdba-42be-bb0c-485d57b711d5268=1279=0269=083=159757950955=BTC-USD29004=2.208895519560=20250411-01:58:24.03077340=137=4d373c47-5b9b-457c-8973-d3136b551e9910=191
20250411-01:58:24.148216000 : 8=FIXT.1.19=32735=X49=Coinbase56=24ab46f784d1b20db435b852086e325034=22350=TEST52=20250411-01:58:24.031821369=46262=9476afd5-fdba-42be-bb0c-485d57b711d5268=1279=0269=2278=c5b88ea9-605d-4595-ac52-f7c3f08523ba83=159757951055=BTC-USD270=3.55271=0.6222240960=20250411-01:58:24.03077337=4d373c47-5b9b-457c-8973-d3136b551e995797=110=067
20250411-01:58:24.148384000 : 8=FIXT.1.19=26635=X49=Coinbase56=24ab46f784d1b20db435b852086e325034=22450=TEST52=20250411-01:58:24.031853369=46262=9476afd5-fdba-42be-bb0c-485d57b711d5268=1279=2269=0278=4d373c47-5b9b-457c-8973-d3136b551e9983=159757951155=BTC-USD60=20250411-01:58:24.03077358=FILLED10=197
20250411-01:58:24.177213000 : 8=FIXT.1.19=27535=X49=Coinbase56=24ab46f784d1b20db435b852086e325034=22550=TEST52=20250411-01:58:24.061294369=46262=9476afd5-fdba-42be-bb0c-485d57b711d5268=1279=0269=183=159757951255=BTC-USD271=0.6197183160=20250411-01:58:24.05977240=137=0d8ddf91-8a20-4ea7-a4b8-89f37f62724010=112
20250411-01:58:24.177682000 : 8=FIXT.1.19=32735=X49=Coinbase56=24ab46f784d1b20db435b852086e325034=22650=TEST52=20250411-01:58:24.061300369=46262=9476afd5-fdba-42be-bb0c-485d57b711d5268=1279=0269=2278=4d60a78e-b39b-420e-b830-bc0f3f4fdde283=159757951355=BTC-USD270=3.53271=0.6197183160=20250411-01:58:24.05977237=0d8ddf91-8a20-4ea7-a4b8-89f37f6272405797=210=089
20250411-01:58:24.178132000 : 8=FIXT.1.19=28135=X49=Coinbase56=24ab46f784d1b20db435b852086e325034=22750=TEST52=20250411-01:58:24.061303369=46262=9476afd5-fdba-42be-bb0c-485d57b711d5268=1279=2269=1278=0d8ddf91-8a20-4ea7-a4b8-89f37f62724083=159757951455=BTC-USD271=0.0000000060=20250411-01:58:24.05977258=FILLED10=005
20250411-01:58:24.205610000 : 8=FIXT.1.19=27935=X49=Coinbase56=24ab46f784d1b20db435b852086e325034=22850=TEST52=20250411-01:58:24.090060369=46262=9476afd5-fdba-42be-bb0c-485d57b711d5268=1279=0269=083=159757951555=BTC-USD29004=2.208895519560=20250411-01:58:24.08879540=137=85ed6062-1a9f-40eb-8bf7-a186dc93dc0810=174
20250411-01:58:24.205790000 : 8=FIXT.1.19=32735=X49=Coinbase56=24ab46f784d1b20db435b852086e325034=22950=TEST52=20250411-01:58:24.090065369=46262=9476afd5-fdba-42be-bb0c-485d57b711d5268=1279=0269=2278=c5b88ea9-605d-4595-ac52-f7c3f08523ba83=159757951655=BTC-USD270=3.55271=0.6222240960=20250411-01:58:24.08879537=85ed6062-1a9f-40eb-8bf7-a186dc93dc085797=110=070
20250411-01:58:24.206000000 : 8=FIXT.1.19=26635=X49=Coinbase56=24ab46f784d1b20db435b852086e325034=23050=TEST52=20250411-01:58:24.090069369=46262=9476afd5-fdba-42be-bb0c-485d57b711d5268=1279=2269=0278=85ed6062-1a9f-40eb-8bf7-a186dc93dc0883=159757951755=BTC-USD60=20250411-01:58:24.08879558=FILLED10=190
20250411-01:58:24.233848000 : 8=FIXT.1.19=27535=X49=Coinbase56=24ab46f784d1b20db435b852086e325034=23150=TEST52=20250411-01:58:24.117890369=46262=9476afd5-fdba-42be-bb0c-485d57b711d5268=1279=0269=183=159757951855=BTC-USD271=0.6197183160=20250411-01:58:24.11655340=137=01cb278d-9458-4a92-b820-25d44ec5625f10=007
20250411-01:58:24.234351000 : 8=FIXT.1.19=32735=X49=Coinbase56=24ab46f784d1b20db435b852086e325034=23250=TEST52=20250411-01:58:24.117894369=46262=9476afd5-fdba-42be-bb0c-485d57b711d5268=1279=0269=2278=4d60a78e-b39b-420e-b830-bc0f3f4fdde283=159757951955=BTC-USD270=3.53271=0.6197183160=20250411-01:58:24.11655337=01cb278d-9458-4a92-b820-25d44ec5625f5797=210=000
20250411-01:58:24.234547000 : 8=FIXT.1.19=28135=X49=Coinbase56=24ab46f784d1b20db435b852086e325034=23350=TEST52=20250411-01:58:24.117896369=46262=9476afd5-fdba-42be-bb0c-485d57b711d5268=1279=2269=1278=01cb278d-9458-4a92-b820-25d44ec5625f83=159757952055=BTC-USD271=0.0000000060=20250411-01:58:24.11655358=FILLED10=162
20250411-01:58:24.892009000 : 8=FIXT.1.19=27935=X49=Coinbase56=24ab46f784d1b20db435b852086e325034=23450=TEST52=20250411-01:58:24.775882369=46262=9476afd5-fdba-42be-bb0c-485d57b711d5268=1279=0269=083=159757952155=BTC-USD29004=2.208895519560=20250411-01:58:24.77460740=137=2b57c7a0-0858-467f-8e57-14873f1f9b3610=215
20250411-01:58:24.892947000 : 8=FIXT.1.19=32735=X49=Coinbase56=24ab46f784d1b20db435b852086e325034=23550=TEST52=20250411-01:58:24.775986369=46262=9476afd5-fdba-42be-bb0c-485d57b711d5268=1279=0269=2278=c5b88ea9-605d-4595-ac52-f7c3f08523ba83=159757952255=BTC-USD270=3.55271=0.6222240960=20250411-01:58:24.77460737=2b57c7a0-0858-467f-8e57-14873f1f9b365797=110=111
20250411-01:58:24.893131000 : 8=FIXT.1.19=26635=X49=Coinbase56=24ab46f784d1b20db435b852086e325034=23650=TEST52=20250411-01:58:24.776026369=46262=9476afd5-fdba-42be-bb0c-485d57b711d5268=1279=2269=0278=2b57c7a0-0858-467f-8e57-14873f1f9b3683=159757952355=BTC-USD60=20250411-01:58:24.77460758=FILLED10=222
20250411-01:58:24.919351000 : 8=FIXT.1.19=27535=X49=Coinbase56=24ab46f784d1b20db435b852086e325034=23750=TEST52=20250411-01:58:24.803515369=46262=9476afd5-fdba-42be-bb0c-485d57b711d5268=1279=0269=183=159757952455=BTC-USD271=0.6232294660=20250411-01:58:24.80237940=137=4c5c0a5e-81b4-4ffa-bea3-bbea3083afb510=163
20250411-01:58:24.919970000 : 8=FIXT.1.19=32735=X49=Coinbase56=24ab46f784d1b20db435b852086e325034=23850=TEST52=20250411-01:58:24.803520369=46262=9476afd5-fdba-42be-bb0c-485d57b711d5268=1279=0269=2278=4d60a78e-b39b-420e-b830-bc0f3f4fdde283=159757952555=BTC-USD270=3.53271=0.6232294660=20250411-01:58:24.80237937=4c5c0a5e-81b4-4ffa-bea3-bbea3083afb55797=210=148
20250411-01:58:24.920155000 : 8=FIXT.1.19=28135=X49=Coinbase56=24ab46f784d1b20db435b852086e325034=23950=TEST52=20250411-01:58:24.803524369=46262=9476afd5-fdba-42be-bb0c-485d57b711d5268=1279=2269=1278=4c5c0a5e-81b4-4ffa-bea3-bbea3083afb583=159757952655=BTC-USD271=0.0000000060=20250411-01:58:24.80237958=FILLED10=067
20250411-01:58:25.282884000 : 8=FIXT.1.19=31035=X49=Coinbase56=24ab46f784d1b20db435b852086e325034=24050=TEST52=20250411-01:58:25.055542369=46262=9476afd5-fdba-42be-bb0c-485d57b711d5268=1279=1269=1278=582969d2-8318-4a7d-b8bb-01d0f62df42083=159757952755=BTC-USD270=3.67271=0.4256819260=20250411-01:58:25.05388058=CHANGE_REASON_MODIFY_ORDER10=176
20250411-01:58:25.283670000 : 8=FIXT.1.19=28435=X49=Coinbase56=24ab46f784d1b20db435b852086e325034=24150=TEST52=20250411-01:58:25.090355369=46262=9476afd5-fdba-42be-bb0c-485d57b711d5268=1279=0269=083=159757952855=BTC-USD270=3.87271=0.6232294660=20250411-01:58:25.08954340=237=f700cda7-6faf-4127-b41d-b7cdae21c97010=196
20250411-01:58:25.283901000 : 8=FIXT.1.19=32735=X49=Coinbase56=24ab46f784d1b20db435b852086e325034=24250=TEST52=20250411-01:58:25.090420369=46262=9476afd5-fdba-42be-bb0c-485d57b711d5268=1279=0269=2278=c5b88ea9-605d-4595-ac52-f7c3f08523ba83=159757952955=BTC-USD270=3.55271=0.6232294660=20250411-01:58:25.08954337=f700cda7-6faf-4127-b41d-b7cdae21c9705797=110=140
20250411-01:58:25.284071000 : 8=FIXT.1.19=29035=X49=Coinbase56=24ab46f784d1b20db435b852086e325034=24350=TEST52=20250411-01:58:25.090423369=46262=9476afd5-fdba-42be-bb0c-485d57b711d5268=1279=2269=0278=f700cda7-6faf-4127-b41d-b7cdae21c97083=159757953055=BTC-USD270=3.87271=0.0000000060=20250411-01:58:25.08954358=FILLED10=086
20250411-01:58:25.284231000 : 8=FIXT.1.19=27935=X49=Coinbase56=24ab46f784d1b20db435b852086e325034=24450=TEST52=20250411-01:58:25.119017369=46262=9476afd5-fdba-42be-bb0c-485d57b711d5268=1279=0269=083=159757953155=BTC-USD29004=2.208895519560=20250411-01:58:25.11749440=137=c1e64721-7b59-4504-9b61-42d3f3d6ff5010=224
20250411-01:58:25.284384000 : 8=FIXT.1.19=32735=X49=Coinbase56=24ab46f784d1b20db435b852086e325034=24550=TEST52=20250411-01:58:25.119027369=46262=9476afd5-fdba-42be-bb0c-485d57b711d5268=1279=0269=2278=c5b88ea9-605d-4595-ac52-f7c3f08523ba83=159757953255=BTC-USD270=3.55271=0.6222240960=20250411-01:58:25.11749437=c1e64721-7b59-4504-9b61-42d3f3d6ff505797=110=116
20250411-01:58:25.284534000 : 8=FIXT.1.19=26635=X49=Coinbase56=24ab46f784d1b20db435b852086e325034=24650=TEST52=20250411-01:58:25.119031369=46262=9476afd5-fdba-42be-bb0c-485d57b711d5268=1279=2269=0278=c1e64721-7b59-4504-9b61-42d3f3d6ff5083=159757953355=BTC-USD60=20250411-01:58:25.11749458=FILLED10=236
20250411-01:58:25.284722000 : 8=FIXT.1.19=28435=X49=Coinbase56=24ab46f784d1b20db435b852086e325034=24750=TEST52=20250411-01:58:25.146304369=46262=9476afd5-fdba-42be-bb0c-485d57b711d5268=1279=0269=183=159757953455=BTC-USD270=3.26271=0.6232294660=20250411-01:58:25.14455740=237=80932071-7472-4595-947a-78a87252acda10=037
20250411-01:58:25.285393000 : 8=FIXT.1.19=32735=X49=Coinbase56=24ab46f784d1b20db435b852086e325034=24850=TEST52=20250411-01:58:25.146313369=46262=9476afd5-fdba-42be-bb0c-485d57b711d5268=1279=0269=2278=4d60a78e-b39b-420e-b830-bc0f3f4fdde283=159757953555=BTC-USD270=3.53271=0.6232294660=20250411-01:58:25.14455737=80932071-7472-4595-947a-78a87252acda5797=210=121
20250411-01:58:25.285603000 : 8=FIXT.1.19=29035=X49=Coinbase56=24ab46f784d1b20db435b852086e325034=24950=TEST52=20250411-01:58:25.146316369=46262=9476afd5-fdba-42be-bb0c-485d57b711d5268=1279=2269=1278=80932071-7472-4595-947a-78a87252acda83=159757953655=BTC-USD270=3.26271=0.0000000060=20250411-01:58:25.14455758=FILLED10=199
20250411-01:58:25.286658000 : 8=FIXT.1.19=27535=X49=Coinbase56=24ab46f784d1b20db435b852086e325034=25050=TEST52=20250411-01:58:25.146434369=46262=9476afd5-fdba-42be-bb0c-485d57b711d5268=1279=0269=183=159757953755=BTC-USD271=0.6232294660=20250411-01:58:25.14546040=137=f3033283-b593-48b5-8af9-9719013492d410=127
20250411-01:58:25.287210000 : 8=FIXT.1.19=32735=X49=Coinbase56=24ab46f784d1b20db435b852086e325034=25150=TEST52=20250411-01:58:25.146440369=46262=9476afd5-fdba-42be-bb0c-485d57b711d5268=1279=0269=2278=4d60a78e-b39b-420e-b830-bc0f3f4fdde283=159757953855=BTC-USD270=3.53271=0.6232294660=20250411-01:58:25.14546037=f3033283-b593-48b5-8af9-9719013492d45797=210=113
20250411-01:58:25.287995000 : 8=FIXT.1.19=28135=X49=Coinbase56=24ab46f784d1b20db435b852086e325034=25250=TEST52=20250411-01:58:25.146443369=46262=9476afd5-fdba-42be-bb0c-485d57b711d5268=1279=2269=1278=f3033283-b593-48b5-8af9-9719013492d483=159757953955=BTC-USD271=0.0000000060=20250411-01:58:25.14546058=FILLED10=031
20250411-01:58:25.320619000 : 8=FIXT.1.19=28435=X49=Coinbase56=24ab46f784d1b20db435b852086e325034=25350=TEST52=20250411-01:58:25.205278369=46262=9476afd5-fdba-42be-bb0c-485d57b711d5268=1279=0269=183=159757954055=BTC-USD270=3.26271=0.6232294660=20250411-01:58:25.20446740=237=15c9c3a3-08c7-4005-a2fa-1d05e829b00510=189
20250411-01:58:25.321126000 : 8=FIXT.1.19=32735=X49=Coinbase56=24ab46f784d1b20db435b852086e325034=25450=TEST52=20250411-01:58:25.205283369=46262=9476afd5-fdba-42be-bb0c-485d57b711d5268=1279=0269=2278=4d60a78e-b39b-420e-b830-bc0f3f4fdde283=159757954155=BTC-USD270=3.53271=0.6232294660=20250411-01:58:25.20446737=15c9c3a3-08c7-4005-a2fa-1d05e829b0055797=210=013
20250411-01:58:25.321373000 : 8=FIXT.1.19=29035=X49=Coinbase56=24ab46f784d1b20db435b852086e325034=25550=TEST52=20250411-01:58:25.205287369=46262=9476afd5-fdba-42be-bb0c-485d57b711d5268=1279=2269=1278=15c9c3a3-08c7-4005-a2fa-1d05e829b00583=159757954255=BTC-USD270=3.26271=0.0000000060=20250411-01:58:25.20446758=FILLED10=092
20250411-01:58:25.379513000 : 8=FIXT.1.19=28435=X49=Coinbase56=24ab46f784d1b20db435b852086e325034=25650=TEST52=20250411-01:58:25.264080369=46262=9476afd5-fdba-42be-bb0c-485d57b711d5268=1279=0269=083=159757954355=BTC-USD270=3.73271=0.6232294660=20250411-01:58:25.26266040=237=94f0ce54-a34d-4034-b625-2733d8c5eec010=255
20250411-01:58:25.379947000 : 8=FIXT.1.19=32735=X49=Coinbase56=24ab46f784d1b20db435b852086e325034=25750=TEST52=20250411-01:58:25.264086369=46262=9476afd5-fdba-42be-bb0c-485d57b711d5268=1279=0269=2278=c5b88ea9-605d-4595-ac52-f7c3f08523ba83=159757954455=BTC-USD270=3.55271=0.6232294660=20250411-01:58:25.26266037=94f0ce54-a34d-4034-b625-2733d8c5eec05797=110=217
20250411-01:58:25.380119000 : 8=FIXT.1.19=29035=X49=Coinbase56=24ab46f784d1b20db435b852086e325034=25850=TEST52=20250411-01:58:25.264090369=46262=9476afd5-fdba-42be-bb0c-485d57b711d5268=1279=2269=0278=94f0ce54-a34d-4034-b625-2733d8c5eec083=159757954555=BTC-USD270=3.73271=0.0000000060=20250411-01:58:25.26266058=FILLED10=159
20250411-01:58:25.456110000 : 8=FIXT.1.19=30935=X49=Coinbase56=24ab46f784d1b20db435b852086e325034=25950=TEST52=20250411-01:58:25.340075369=46262=9476afd5-fdba-42be-bb0c-485d57b711d5268=1279=1269=0278=53df6705-3c5d-4895-881d-6a43ab91b73e83=159757954655=BTC-USD270=3.4271=0.4431809460=20250411-01:58:25.33842158=CHANGE_REASON_MODIFY_ORDER10=140
20250411-01:58:25.741165000 : 8=FIXT.1.19=31035=X49=Coinbase56=24ab46f784d1b20db435b852086e325034=26050=TEST52=20250411-01:58:25.625713369=46262=9476afd5-fdba-42be-bb0c-485d57b711d5268=1279=1269=0278=4e6f389b-e251-4fa6-833c-4d41ac01f9cc83=159757954755=BTC-USD270=3.46271=0.4402710760=20250411-01:58:25.62396858=CHANGE_REASON_MODIFY_ORDER10=064
20250411-01:58:25.749682000 : 8=FIXT.1.19=27935=X49=Coinbase56=24ab46f784d1b20db435b852086e325034=26150=TEST52=20250411-01:58:25.633807369=46262=9476afd5-fdba-42be-bb0c-485d57b711d5268=1279=0269=083=159757954855=BTC-USD29004=2.208895519560=20250411-01:58:25.63213740=137=c5241f19-dde7-4f6c-b723-3816e019fe4010=075
20250411-01:58:25.750156000 : 8=FIXT.1.19=32735=X49=Coinbase56=24ab46f784d1b20db435b852086e325034=26250=TEST52=20250411-01:58:25.633923369=46262=9476afd5-fdba-42be-bb0c-485d57b711d5268=1279=0269=2278=c5b88ea9-605d-4595-ac52-f7c3f08523ba83=159757954955=BTC-USD270=3.55271=0.6222240960=20250411-01:58:25.63213737=c5241f19-dde7-4f6c-b723-3816e019fe405797=110=221
20250411-01:58:25.750381000 : 8=FIXT.1.19=26635=X49=Coinbase56=24ab46f784d1b20db435b852086e325034=26350=TEST52=20250411-01:58:25.633926369=46262=9476afd5-fdba-42be-bb0c-485d57b711d5268=1279=2269=0278=c5241f19-dde7-4f6c-b723-3816e019fe4083=159757955055=BTC-USD60=20250411-01:58:25.63213758=FILLED10=084
20250411-01:58:25.776844000 : 8=FIXT.1.19=27535=X49=Coinbase56=24ab46f784d1b20db435b852086e325034=26450=TEST52=20250411-01:58:25.661397369=46262=9476afd5-fdba-42be-bb0c-485d57b711d5268=1279=0269=183=159757955155=BTC-USD271=0.6197183160=20250411-01:58:25.66010440=137=9203de17-9cbc-4649-8240-57e425dba8ad10=111
20250411-01:58:25.777078000 : 8=FIXT.1.19=32735=X49=Coinbase56=24ab46f784d1b20db435b852086e325034=26550=TEST52=20250411-01:58:25.661403369=46262=9476afd5-fdba-42be-bb0c-485d57b711d5268=1279=0269=2278=4d60a78e-b39b-420e-b830-bc0f3f4fdde283=159757955255=BTC-USD270=3.53271=0.6197183160=20250411-01:58:25.66010437=9203de17-9cbc-4649-8240-57e425dba8ad5797=210=088
20250411-01:58:25.777220000 : 8=FIXT.1.19=28135=X49=Coinbase56=24ab46f784d1b20db435b852086e325034=26650=TEST52=20250411-01:58:25.661443369=46262=9476afd5-fdba-42be-bb0c-485d57b711d5268=1279=2269=1278=9203de17-9cbc-4649-8240-57e425dba8ad83=159757955355=BTC-USD271=0.0000000060=20250411-01:58:25.66010458=FILLED10=005
20250411-01:58:25.984494000 : 8=FIXT.1.19=27935=X49=Coinbase56=24ab46f784d1b20db435b852086e325034=26750=TEST52=20250411-01:58:25.869118369=46262=9476afd5-fdba-42be-bb0c-485d57b711d5268=1279=0269=083=159757955455=BTC-USD29004=2.208895519560=20250411-01:58:25.86730040=137=bd49b2cd-1b1e-46d9-b357-52c0b722e41d10=166
20250411-01:58:25.985017000 : 8=FIXT.1.19=32735=X49=Coinbase56=24ab46f784d1b20db435b852086e325034=26850=TEST52=20250411-01:58:25.869128369=46262=9476afd5-fdba-42be-bb0c-485d57b711d5268=1279=0269=2278=c5b88ea9-605d-4595-ac52-f7c3f08523ba83=159757955555=BTC-USD270=3.55271=0.6222240960=20250411-01:58:25.86730037=bd49b2cd-1b1e-46d9-b357-52c0b722e41d5797=110=058
20250411-01:58:25.985256000 : 8=FIXT.1.19=26635=X49=Coinbase56=24ab46f784d1b20db435b852086e325034=26950=TEST52=20250411-01:58:25.869132369=46262=9476afd5-fdba-42be-bb0c-485d57b711d5268=1279=2269=0278=bd49b2cd-1b1e-46d9-b357-52c0b722e41d83=159757955655=BTC-USD60=20250411-01:58:25.86730058=FILLED10=178
20250411-01:58:26.007397000 : 8=FIXT.1.19=28435=X49=Coinbase56=24ab46f784d1b20db435b852086e325034=27050=TEST52=20250411-01:58:25.892117369=46262=9476afd5-fdba-42be-bb0c-485d57b711d5268=1279=0269=083=159757955755=BTC-USD270=3.89271=0.6197183160=20250411-01:58:25.89110240=237=f6276471-6d56-49d4-93fb-69edb513d3ad10=042
20250411-01:58:26.007976000 : 8=FIXT.1.19=32735=X49=Coinbase56=24ab46f784d1b20db435b852086e325034=27150=TEST52=20250411-01:58:25.892127369=46262=9476afd5-fdba-42be-bb0c-485d57b711d5268=1279=0269=2278=c5b88ea9-605d-4595-ac52-f7c3f08523ba83=159757955855=BTC-USD270=3.55271=0.6197183160=20250411-01:58:25.89110237=f6276471-6d56-49d4-93fb-69edb513d3ad5797=110=248
20250411-01:58:26.008244000 : 8=FIXT.1.19=29035=X49=Coinbase56=24ab46f784d1b20db435b852086e325034=27250=TEST52=20250411-01:58:25.892131369=46262=9476afd5-fdba-42be-bb0c-485d57b711d5268=1279=2269=0278=f6276471-6d56-49d4-93fb-69edb513d3ad83=159757955955=BTC-USD270=3.89271=0.0000000060=20250411-01:58:25.89110258=FILLED10=195
20250411-01:58:26.009250000 : 8=FIXT.1.19=27535=X49=Coinbase56=24ab46f784d1b20db435b852086e325034=27350=TEST52=20250411-01:58:25.892591369=46262=9476afd5-fdba-42be-bb0c-485d57b711d5268=1279=0269=183=159757956055=BTC-USD271=0.6232294660=20250411-01:58:25.89163540=137=e3815e1a-5d03-4363-8685-2dec81f2e90810=034
20250411-01:58:26.009548000 : 8=FIXT.1.19=32735=X49=Coinbase56=24ab46f784d1b20db435b852086e325034=27450=TEST52=20250411-01:58:25.892596369=46262=9476afd5-fdba-42be-bb0c-485d57b711d5268=1279=0269=2278=4d60a78e-b39b-420e-b830-bc0f3f4fdde283=159757956155=BTC-USD270=3.53271=0.6232294660=20250411-01:58:25.89163537=e3815e1a-5d03-4363-8685-2dec81f2e9085797=210=028
20250411-01:58:26.009750000 : 8=FIXT.1.19=28135=X49=Coinbase56=24ab46f784d1b20db435b852086e325034=27550=TEST52=20250411-01:58:25.892699369=46262=9476afd5-fdba-42be-bb0c-485d57b711d5268=1279=2269=1278=e3815e1a-5d03-4363-8685-2dec81f2e90883=159757956255=BTC-USD271=0.0000000060=20250411-01:58:25.89163558=FILLED10=203
20250411-01:58:26.027277000 : 8=FIXT.1.19=31035=X49=Coinbase56=24ab46f784d1b20db435b852086e325034=27650=TEST52=20250411-01:58:25.911305369=46262=9476afd5-fdba-42be-bb0c-485d57b711d5268=1279=1269=1278=0168d414-071e-4176-8910-3b2fad61ee2083=159757956355=BTC-USD270=3.55271=0.5103632560=20250411-01:58:25.90997758=CHANGE_REASON_MODIFY_ORDER10=073
20250411-01:58:26.063365000 : 8=FIXT.1.19=28435=X49=Coinbase56=24ab46f784d1b20db435b852086e325034=27750=TEST52=20250411-01:58:25.948131369=46262=9476afd5-fdba-42be-bb0c-485d57b711d5268=1279=0269=183=159757956455=BTC-USD270=3.29271=0.6197183160=20250411-01:58:25.94717840=237=87ef4866-ee27-4827-8f5a-e7ac7563d94f10=077
20250411-01:58:26.063812000 : 8=FIXT.1.19=32735=X49=Coinbase56=24ab46f784d1b20db435b852086e325034=27850=TEST52=20250411-01:58:25.948135369=46262=9476afd5-fdba-42be-bb0c-485d57b711d5268=1279=0269=2278=4d60a78e-b39b-420e-b830-bc0f3f4fdde283=159757956555=BTC-USD270=3.53271=0.6197183160=20250411-01:58:25.94717837=87ef4866-ee27-4827-8f5a-e7ac7563d94f5797=210=162
20250411-01:58:26.064809000 : 8=FIXT.1.19=29035=X49=Coinbase56=24ab46f784d1b20db435b852086e325034=27950=TEST52=20250411-01:58:25.948139369=46262=9476afd5-fdba-42be-bb0c-485d57b711d5268=1279=2269=1278=87ef4866-ee27-4827-8f5a-e7ac7563d94f83=159757956655=BTC-USD270=3.29271=0.0000000060=20250411-01:58:25.94717858=FILLED10=242
20250411-01:58:26.314330000 : 8=FIXT.1.19=31035=X49=Coinbase56=24ab46f784d1b20db435b852086e325034=28050=TEST52=20250411-01:58:26.197150369=46262=9476afd5-fdba-42be-bb0c-485d57b711d5268=1279=1269=0278=b6a1c1a8-fe07-415a-8303-2782e7a5887483=159757956755=BTC-USD270=3.36271=0.5168038760=20250411-01:58:26.19578258=CHANGE_REASON_MODIFY_ORDER10=144
20250411-01:58:26.465015000 : 8=FIXT.1.19=28435=X49=Coinbase56=24ab46f784d1b20db435b852086e325034=28150=TEST52=20250411-01:58:26.348728369=46262=9476afd5-fdba-42be-bb0c-485d57b711d5268=1279=0269=183=159757956855=BTC-USD270=3.21271=0.6232294660=20250411-01:58:26.34766540=237=1f33e65b-7e93-4c77-8d4a-50f1fbaea18f10=178
20250411-01:58:26.465543000 : 8=FIXT.1.19=32735=X49=Coinbase56=24ab46f784d1b20db435b852086e325034=28250=TEST52=20250411-01:58:26.348858369=46262=9476afd5-fdba-42be-bb0c-485d57b711d5268=1279=0269=2278=4d60a78e-b39b-420e-b830-bc0f3f4fdde283=159757956955=BTC-USD270=3.53271=0.6232294660=20250411-01:58:26.34766537=1f33e65b-7e93-4c77-8d4a-50f1fbaea18f5797=210=015
20250411-01:58:26.466825000 : 8=FIXT.1.19=29035=X49=Coinbase56=24ab46f784d1b20db435b852086e325034=28350=TEST52=20250411-01:58:26.348905369=46262=9476afd5-fdba-42be-bb0c-485d57b711d5268=1279=2269=1278=1f33e65b-7e93-4c77-8d4a-50f1fbaea18f83=159757957055=BTC-USD270=3.21271=0.0000000060=20250411-01:58:26.34766558=FILLED10=069
20250411-01:58:26.520271000 : 8=FIXT.1.19=28435=X49=Coinbase56=24ab46f784d1b20db435b852086e325034=28450=TEST52=20250411-01:58:26.403899369=46262=9476afd5-fdba-42be-bb0c-485d57b711d5268=1279=0269=083=159757957155=BTC-USD270=3.72271=0.6232294660=20250411-01:58:26.40265640=237=a9fecc74-9637-4b4a-afef-5b9be57af48210=026
20250411-01:58:26.520741000 : 8=FIXT.1.19=32735=X49=Coinbase56=24ab46f784d1b20db435b852086e325034=28550=TEST52=20250411-01:58:26.403909369=46262=9476afd5-fdba-42be-bb0c-485d57b711d5268=1279=0269=2278=c5b88ea9-605d-4595-ac52-f7c3f08523ba83=159757957255=BTC-USD270=3.55271=0.6232294660=20250411-01:58:26.40265637=a9fecc74-9637-4b4a-afef-5b9be57af4825797=110=231
20250411-01:58:26.520980000 : 8=FIXT.1.19=29035=X49=Coinbase56=24ab46f784d1b20db435b852086e325034=28650=TEST52=20250411-01:58:26.403911369=46262=9476afd5-fdba-42be-bb0c-485d57b711d5268=1279=2269=0278=a9fecc74-9637-4b4a-afef-5b9be57af48283=159757957355=BTC-USD270=3.72271=0.0000000060=20250411-01:58:26.40265658=FILLED10=170
20250411-01:58:27.228923000 : 8=FIXT.1.19=27935=X49=Coinbase56=24ab46f784d1b20db435b852086e325034=28750=TEST52=20250411-01:58:27.003769369=46262=9476afd5-fdba-42be-bb0c-485d57b711d5268=1279=0269=083=159757957455=BTC-USD29004=2.208895519560=20250411-01:58:27.00274440=137=7576cd44-9f63-46ad-872b-b72c9feb04a310=137
20250411-01:58:27.229469000 : 8=FIXT.1.19=32735=X49=Coinbase56=24ab46f784d1b20db435b852086e325034=28850=TEST52=20250411-01:58:27.003876369=46262=9476afd5-fdba-42be-bb0c-485d57b711d5268=1279=0269=2278=c5b88ea9-605d-4595-ac52-f7c3f08523ba83=159757957555=BTC-USD270=3.55271=0.6222240960=20250411-01:58:27.00274437=7576cd44-9f63-46ad-872b-b72c9feb04a35797=110=027
20250411-01:58:27.229695000 : 8=FIXT.1.19=26635=X49=Coinbase56=24ab46f784d1b20db435b852086e325034=28950=TEST52=20250411-01:58:27.003930369=46262=9476afd5-fdba-42be-bb0c-485d57b711d5268=1279=2269=0278=7576cd44-9f63-46ad-872b-b72c9feb04a383=159757957655=BTC-USD60=20250411-01:58:27.00274458=FILLED10=143
20250411-01:58:27.229897000 : 8=FIXT.1.19=27535=X49=Coinbase56=24ab46f784d1b20db435b852086e325034=29050=TEST52=20250411-01:58:27.033406369=46262=9476afd5-fdba-42be-bb0c-485d57b711d5268=1279=0269=183=159757957755=BTC-USD271=0.6197183160=20250411-01:58:27.03154640=137=4e5d3641-72b0-44e0-804e-a8327ef2325b10=254
20250411-01:58:27.230405000 : 8=FIXT.1.19=32735=X49=Coinbase56=24ab46f784d1b20db435b852086e325034=29150=TEST52=20250411-01:58:27.033418369=46262=9476afd5-fdba-42be-bb0c-485d57b711d5268=1279=0269=2278=4d60a78e-b39b-420e-b830-bc0f3f4fdde283=159757957855=BTC-USD270=3.53271=0.6197183160=20250411-01:58:27.03154637=4e5d3641-72b0-44e0-804e-a8327ef2325b5797=210=246
20250411-01:58:27.231303000 : 8=FIXT.1.19=28135=X49=Coinbase56=24ab46f784d1b20db435b852086e325034=29250=TEST52=20250411-01:58:27.033423369=46262=9476afd5-fdba-42be-bb0c-485d57b711d5268=1279=2269=1278=4e5d3641-72b0-44e0-804e-a8327ef2325b83=159757957955=BTC-USD271=0.0000000060=20250411-01:58:27.03154658=FILLED10=155
20250411-01:58:27.231803000 : 8=FIXT.1.19=27935=X49=Coinbase56=24ab46f784d1b20db435b852086e325034=29350=TEST52=20250411-01:58:27.061217369=46262=9476afd5-fdba-42be-bb0c-485d57b711d5268=1279=0269=083=159757958055=BTC-USD29004=2.208895519560=20250411-01:58:27.06005240=137=0ba7c3c8-7ca9-4221-b9f8-21f774234da110=052
20250411-01:58:27.232046000 : 8=FIXT.1.19=32735=X49=Coinbase56=24ab46f784d1b20db435b852086e325034=29450=TEST52=20250411-01:58:27.061225369=46262=9476afd5-fdba-42be-bb0c-485d57b711d5268=1279=0269=2278=c5b88ea9-605d-4595-ac52-f7c3f08523ba83=159757958155=BTC-USD270=3.55271=0.6222240960=20250411-01:58:27.06005237=0ba7c3c8-7ca9-4221-b9f8-21f774234da15797=110=198
20250411-01:58:27.233342000 : 8=FIXT.1.19=26635=X49=Coinbase56=24ab46f784d1b20db435b852086e325034=29550=TEST52=20250411-01:58:27.061229369=46262=9476afd5-fdba-42be-bb0c-485d57b711d5268=1279=2269=0278=0ba7c3c8-7ca9-4221-b9f8-21f774234da183=159757958255=BTC-USD60=20250411-01:58:27.06005258=FILLED10=071
20250411-01:58:27.234165000 : 8=FIXT.1.19=27535=X49=Coinbase56=24ab46f784d1b20db435b852086e325034=29650=TEST52=20250411-01:58:27.089710369=46262=9476afd5-fdba-42be-bb0c-485d57b711d5268=1279=0269=183=159757958355=BTC-USD271=0.6197183160=20250411-01:58:27.08813840=137=d684e275-ca44-4934-b5d2-1467db641e4810=038
20250411-01:58:27.234388000 : 8=FIXT.1.19=32735=X49=Coinbase56=24ab46f784d1b20db435b852086e325034=29750=TEST52=20250411-01:58:27.089718369=46262=9476afd5-fdba-42be-bb0c-485d57b711d5268=1279=0269=2278=4d60a78e-b39b-420e-b830-bc0f3f4fdde283=159757958455=BTC-USD270=3.53271=0.6197183160=20250411-01:58:27.08813837=d684e275-ca44-4934-b5d2-1467db641e485797=210=035
20250411-01:58:27.234760000 : 8=FIXT.1.19=28135=X49=Coinbase56=24ab46f784d1b20db435b852086e325034=29850=TEST52=20250411-01:58:27.089721369=46262=9476afd5-fdba-42be-bb0c-485d57b711d5268=1279=2269=1278=d684e275-ca44-4934-b5d2-1467db641e4883=159757958555=BTC-USD271=0.0000000060=20250411-01:58:27.08813858=FILLED10=198
20250411-01:58:27.348557000 : 8=FIXT.1.19=27935=X49=Coinbase56=24ab46f784d1b20db435b852086e325034=29950=TEST52=20250411-01:58:27.233147369=46262=9476afd5-fdba-42be-bb0c-485d57b711d5268=1279=0269=083=159757958655=BTC-USD29004=2.208895519560=20250411-01:58:27.23176740=137=fb56dfc1-ec40-4fca-b5ca-9027737cc6f010=064
20250411-01:58:27.349082000 : 8=FIXT.1.19=32735=X49=Coinbase56=24ab46f784d1b20db435b852086e325034=30050=TEST52=20250411-01:58:27.233158369=46262=9476afd5-fdba-42be-bb0c-485d57b711d5268=1279=0269=2278=c5b88ea9-605d-4595-ac52-f7c3f08523ba83=159757958755=BTC-USD270=3.55271=0.6222240960=20250411-01:58:27.23176737=fb56dfc1-ec40-4fca-b5ca-9027737cc6f05797=110=195
20250411-01:58:27.349285000 : 8=FIXT.1.19=26635=X49=Coinbase56=24ab46f784d1b20db435b852086e325034=30150=TEST52=20250411-01:58:27.233161369=46262=9476afd5-fdba-42be-bb0c-485d57b711d5268=1279=2269=0278=fb56dfc1-ec40-4fca-b5ca-9027737cc6f083=159757958855=BTC-USD60=20250411-01:58:27.23176758=FILLED10=058
20250411-01:58:27.378066000 : 8=FIXT.1.19=27535=X49=Coinbase56=24ab46f784d1b20db435b852086e325034=30250=TEST52=20250411-01:58:27.261326369=46262=9476afd5-fdba-42be-bb0c-485d57b711d5268=1279=0269=183=159757958955=BTC-USD271=0.6232294660=20250411-01:58:27.25937740=137=72303206-ed94-4794-a75f-ef7621a1c1b510=020
20250411-01:58:27.378368000 : 8=FIXT.1.19=32735=X49=Coinbase56=24ab46f784d1b20db435b852086e325034=30350=TEST52=20250411-01:58:27.261335369=46262=9476afd5-fdba-42be-bb0c-485d57b711d5268=1279=0269=2278=4d60a78e-b39b-420e-b830-bc0f3f4fdde283=159757959055=BTC-USD270=3.53271=0.6232294660=20250411-01:58:27.25937737=72303206-ed94-4794-a75f-ef7621a1c1b55797=210=000
20250411-01:58:27.378597000 : 8=FIXT.1.19=28135=X49=Coinbase56=24ab46f784d1b20db435b852086e325034=30450=TEST52=20250411-01:58:27.261339369=46262=9476afd5-fdba-42be-bb0c-485d57b711d5268=1279=2269=1278=72303206-ed94-4794-a75f-ef7621a1c1b583=159757959155=BTC-USD271=0.0000000060=20250411-01:58:27.25937758=FILLED10=175
20250411-01:58:27.462674000 : 8=FIXT.1.19=27935=X49=Coinbase56=24ab46f784d1b20db435b852086e325034=30550=TEST52=20250411-01:58:27.346807369=46262=9476afd5-fdba-42be-bb0c-485d57b711d5268=1279=0269=083=159757959255=BTC-USD29004=2.208895519560=20250411-01:58:27.34510640=137=275008c2-9843-49f3-b7a7-33432744a4b510=091
20250411-01:58:27.463103000 : 8=FIXT.1.19=32735=X49=Coinbase56=24ab46f784d1b20db435b852086e325034=30650=TEST52=20250411-01:58:27.346813369=46262=9476afd5-fdba-42be-bb0c-485d57b711d5268=1279=0269=2278=c5b88ea9-605d-4595-ac52-f7c3f08523ba83=159757959355=BTC-USD270=3.55271=0.6222240960=20250411-01:58:27.34510637=275008c2-9843-49f3-b7a7-33432744a4b55797=110=235
20250411-01:58:27.463320000 : 8=FIXT.1.19=26635=X49=Coinbase56=24ab46f784d1b20db435b852086e325034=30750=TEST52=20250411-01:58:27.346823369=46262=9476afd5-fdba-42be-bb0c-485d57b711d5268=1279=2269=0278=275008c2-9843-49f3-b7a7-33432744a4b583=159757959455=BTC-USD60=20250411-01:58:27.34510658=FILLED10=105
20250411-01:58:27.490462000 : 8=FIXT.1.19=27535=X49=Coinbase56=24ab46f784d1b20db435b852086e325034=30850=TEST52=20250411-01:58:27.375147369=46262=9476afd5-fdba-42be-bb0c-485d57b711d5268=1279=0269=183=159757959555=BTC-USD271=0.6232294660=20250411-01:58:27.37377940=137=d89a9e26-89cc-41f2-aa87-5ab87d3a7b4b10=032
20250411-01:58:27.490895000 : 8=FIXT.1.19=32735=X49=Coinbase56=24ab46f784d1b20db435b852086e325034=30950=TEST52=20250411-01:58:27.375155369=46262=9476afd5-fdba-42be-bb0c-485d57b711d5268=1279=0269=2278=4d60a78e-b39b-420e-b830-bc0f3f4fdde283=159757959655=BTC-USD270=3.53271=0.6232294660=20250411-01:58:27.37377937=d89a9e26-89cc-41f2-aa87-5ab87d3a7b4b5797=210=020
20250411-01:58:27.491066000 : 8=FIXT.1.19=28135=X49=Coinbase56=24ab46f784d1b20db435b852086e325034=31050=TEST52=20250411-01:58:27.375159369=46262=9476afd5-fdba-42be-bb0c-485d57b711d5268=1279=2269=1278=d89a9e26-89cc-41f2-aa87-5ab87d3a7b4b83=159757959755=BTC-USD271=0.0000000060=20250411-01:58:27.37377958=FILLED10=186
20250411-01:58:28.093539000 : 8=FIXT.1.19=27935=X49=Coinbase56=24ab46f784d1b20db435b852086e325034=31150=TEST52=20250411-01:58:27.976174369=46262=9476afd5-fdba-42be-bb0c-485d57b711d5268=1279=0269=083=159757959855=BTC-USD29004=2.208895519560=20250411-01:58:27.97502440=137=11a8d5cd-fe0b-407c-9377-2aa89183d90c10=137
20250411-01:58:28.094411000 : 8=FIXT.1.19=32735=X49=Coinbase56=24ab46f784d1b20db435b852086e325034=31250=TEST52=20250411-01:58:27.976186369=46262=9476afd5-fdba-42be-bb0c-485d57b711d5268=1279=0269=2278=c5b88ea9-605d-4595-ac52-f7c3f08523ba83=159757959955=BTC-USD270=3.55271=0.6222240960=20250411-01:58:27.97502437=11a8d5cd-fe0b-407c-9377-2aa89183d90c5797=110=031
20250411-01:58:28.094605000 : 8=FIXT.1.19=26635=X49=Coinbase56=24ab46f784d1b20db435b852086e325034=31350=TEST52=20250411-01:58:27.976191369=46262=9476afd5-fdba-42be-bb0c-485d57b711d5268=1279=2269=0278=11a8d5cd-fe0b-407c-9377-2aa89183d90c83=159757960055=BTC-USD60=20250411-01:58:27.97502458=FILLED10=134
20250411-01:58:28.119942000 : 8=FIXT.1.19=27535=X49=Coinbase56=24ab46f784d1b20db435b852086e325034=31450=TEST52=20250411-01:58:28.003987369=46262=9476afd5-fdba-42be-bb0c-485d57b711d5268=1279=0269=183=159757960155=BTC-USD271=0.6232294660=20250411-01:58:28.00253940=137=de799cdf-fb22-458f-aed6-a64052d1701410=200
20250411-01:58:28.120330000 : 8=FIXT.1.19=32735=X49=Coinbase56=24ab46f784d1b20db435b852086e325034=31550=TEST52=20250411-01:58:28.003993369=46262=9476afd5-fdba-42be-bb0c-485d57b711d5268=1279=0269=2278=4d60a78e-b39b-420e-b830-bc0f3f4fdde283=159757960255=BTC-USD270=3.53271=0.6232294660=20250411-01:58:28.00253937=de799cdf-fb22-458f-aed6-a64052d170145797=210=186
20250411-01:58:28.120552000 : 8=FIXT.1.19=28135=X49=Coinbase56=24ab46f784d1b20db435b852086e325034=31650=TEST52=20250411-01:58:28.004110369=46262=9476afd5-fdba-42be-bb0c-485d57b711d5268=1279=2269=1278=de799cdf-fb22-458f-aed6-a64052d1701483=159757960355=BTC-USD271=0.0000000060=20250411-01:58:28.00253958=FILLED10=083
20250411-01:58:28.150191000 : 8=FIXT.1.19=27935=X49=Coinbase56=24ab46f784d1b20db435b852086e325034=31750=TEST52=20250411-01:58:28.033130369=46262=9476afd5-fdba-42be-bb0c-485d57b711d5268=1279=0269=083=159757960455=BTC-USD29004=2.208895519560=20250411-01:58:28.03162440=137=4762e84f-5caa-4cc8-bd7e-8fb5f4ef9e4f10=107
20250411-01:58:28.158574000 : 8=FIXT.1.19=32735=X49=Coinbase56=24ab46f784d1b20db435b852086e325034=31850=TEST52=20250411-01:58:28.033136369=46262=9476afd5-fdba-42be-bb0c-485d57b711d5268=1279=0269=2278=c5b88ea9-605d-4595-ac52-f7c3f08523ba83=159757960555=BTC-USD270=3.55271=0.6222240960=20250411-01:58:28.03162437=4762e84f-5caa-4cc8-bd7e-8fb5f4ef9e4f5797=110=004
20250411-01:58:28.158910000 : 8=FIXT.1.19=26635=X49=Coinbase56=24ab46f784d1b20db435b852086e325034=31950=TEST52=20250411-01:58:28.033139369=46262=9476afd5-fdba-42be-bb0c-485d57b711d5268=1279=2269=0278=4762e84f-5caa-4cc8-bd7e-8fb5f4ef9e4f83=159757960655=BTC-USD60=20250411-01:58:28.03162458=FILLED10=132
20250411-01:58:28.177610000 : 8=FIXT.1.19=27535=X49=Coinbase56=24ab46f784d1b20db435b852086e325034=32050=TEST52=20250411-01:58:28.061444369=46262=9476afd5-fdba-42be-bb0c-485d57b711d5268=1279=0269=183=159757960755=BTC-USD271=0.6197183160=20250411-01:58:28.06021340=137=f21b1399-ae4c-47d8-a12d-2bdcbca1d55910=015
20250411-01:58:28.178208000 : 8=FIXT.1.19=32735=X49=Coinbase56=24ab46f784d1b20db435b852086e325034=32150=TEST52=20250411-01:58:28.061452369=46262=9476afd5-fdba-42be-bb0c-485d57b711d5268=1279=0269=2278=4d60a78e-b39b-420e-b830-bc0f3f4fdde283=159757960855=BTC-USD270=3.53271=0.6197183160=20250411-01:58:28.06021337=f21b1399-ae4c-47d8-a12d-2bdcbca1d5595797=210=003
20250411-01:58:28.178449000 : 8=FIXT.1.19=28135=X49=Coinbase56=24ab46f784d1b20db435b852086e325034=32250=TEST52=20250411-01:58:28.061455369=46262=9476afd5-fdba-42be-bb0c-485d57b711d5268=1279=2269=1278=f21b1399-ae4c-47d8-a12d-2bdcbca1d55983=159757960955=BTC-USD271=0.0000000060=20250411-01:58:28.06021358=FILLED10=175
20250411-01:58:28.179758000 : 8=FIXT.1.19=28435=X49=Coinbase56=24ab46f784d1b20db435b852086e325034=32350=TEST52=20250411-01:58:28.062324369=46262=9476afd5-fdba-42be-bb0c-485d57b711d5268=1279=0269=083=159757961055=BTC-USD270=3.83271=0.6197183160=20250411-01:58:28.06141540=237=ea87a1e9-06bb-4c26-a3ea-d257f047262a10=082
20250411-01:58:28.180071000 : 8=FIXT.1.19=32735=X49=Coinbase56=24ab46f784d1b20db435b852086e325034=32450=TEST52=20250411-01:58:28.062330369=46262=9476afd5-fdba-42be-bb0c-485d57b711d5268=1279=0269=2278=c5b88ea9-605d-4595-ac52-f7c3f08523ba83=159757961155=BTC-USD270=3.55271=0.6197183160=20250411-01:58:28.06141537=ea87a1e9-06bb-4c26-a3ea-d257f047262a5797=110=034
20250411-01:58:28.180300000 : 8=FIXT.1.19=29035=X49=Coinbase56=24ab46f784d1b20db435b852086e325034=32550=TEST52=20250411-01:58:28.062334369=46262=9476afd5-fdba-42be-bb0c-485d57b711d5268=1279=2269=0278=ea87a1e9-06bb-4c26-a3ea-d257f047262a83=159757961255=BTC-USD270=3.83271=0.0000000060=20250411-01:58:28.06141558=FILLED10=240
20250411-01:58:28.233340000 : 8=FIXT.1.19=28435=X49=Coinbase56=24ab46f784d1b20db435b852086e325034=32650=TEST52=20250411-01:58:28.117587369=46262=9476afd5-fdba-42be-bb0c-485d57b711d5268=1279=0269=183=159757961355=BTC-USD270=3.21271=0.6197183160=20250411-01:58:28.11619140=237=0492978b-0b62-4722-89bc-415f458194eb10=087
20250411-01:58:28.233993000 : 8=FIXT.1.19=32735=X49=Coinbase56=24ab46f784d1b20db435b852086e325034=32750=TEST52=20250411-01:58:28.117601369=46262=9476afd5-fdba-42be-bb0c-485d57b711d5268=1279=0269=2278=4d60a78e-b39b-420e-b830-bc0f3f4fdde283=159757961455=BTC-USD270=3.53271=0.6197183160=20250411-01:58:28.11619137=0492978b-0b62-4722-89bc-415f458194eb5797=210=163
20250411-01:58:28.234156000 : 8=FIXT.1.19=29035=X49=Coinbase56=24ab46f784d1b20db435b852086e325034=32850=TEST52=20250411-01:58:28.117612369=46262=9476afd5-fdba-42be-bb0c-485d57b711d5268=1279=2269=1278=0492978b-0b62-4722-89bc-415f458194eb83=159757961555=BTC-USD270=3.21271=0.0000000060=20250411-01:58:28.11619158=FILLED10=233
20250411-01:58:28.293931000 : 8=FIXT.1.19=28435=X49=Coinbase56=24ab46f784d1b20db435b852086e325034=32950=TEST52=20250411-01:58:28.177947369=46262=9476afd5-fdba-42be-bb0c-485d57b711d5268=1279=0269=083=159757961655=BTC-USD270=3.79271=0.6232294660=20250411-01:58:28.17662940=237=6af75534-8a51-40d8-8894-20eac9e28fcb10=058
20250411-01:58:28.294264000 : 8=FIXT.1.19=32735=X49=Coinbase56=24ab46f784d1b20db435b852086e325034=33050=TEST52=20250411-01:58:28.177958369=46262=9476afd5-fdba-42be-bb0c-485d57b711d5268=1279=0269=2278=c5b88ea9-605d-4595-ac52-f7c3f08523ba83=159757961755=BTC-USD270=3.55271=0.6232294660=20250411-01:58:28.17662937=6af75534-8a51-40d8-8894-20eac9e28fcb5797=110=001
20250411-01:58:28.294452000 : 8=FIXT.1.19=29035=X49=Coinbase56=24ab46f784d1b20db435b852086e325034=33150=TEST52=20250411-01:58:28.177963369=46262=9476afd5-fdba-42be-bb0c-485d57b711d5268=1279=2269=0278=6af75534-8a51-40d8-8894-20eac9e28fcb83=159757961855=BTC-USD270=3.79271=0.0000000060=20250411-01:58:28.17662958=FILLED10=206
20250411-01:58:28.349206000 : 8=FIXT.1.19=28435=X49=Coinbase56=24ab46f784d1b20db435b852086e325034=33250=TEST52=20250411-01:58:28.233132369=46262=9476afd5-fdba-42be-bb0c-485d57b711d5268=1279=0269=183=159757961955=BTC-USD270=3.35271=0.6232294660=20250411-01:58:28.23122040=237=67445f41-b847-47fc-bcc3-eec7c2fc2db110=187
20250411-01:58:28.349801000 : 8=FIXT.1.19=32735=X49=Coinbase56=24ab46f784d1b20db435b852086e325034=33350=TEST52=20250411-01:58:28.233222369=46262=9476afd5-fdba-42be-bb0c-485d57b711d5268=1279=0269=2278=4d60a78e-b39b-420e-b830-bc0f3f4fdde283=159757962055=BTC-USD270=3.53271=0.6232294660=20250411-01:58:28.23122037=67445f41-b847-47fc-bcc3-eec7c2fc2db15797=210=006
20250411-01:58:28.349982000 : 8=FIXT.1.19=29035=X49=Coinbase56=24ab46f784d1b20db435b852086e325034=33450=TEST52=20250411-01:58:28.233224369=46262=9476afd5-fdba-42be-bb0c-485d57b711d5268=1279=2269=1278=67445f41-b847-47fc-bcc3-eec7c2fc2db183=159757962155=BTC-USD270=3.35271=0.0000000060=20250411-01:58:28.23122058=FILLED10=083
20250411-01:58:29.283193000 : 8=FIXT.1.19=27935=X49=Coinbase56=24ab46f784d1b20db435b852086e325034=33550=TEST52=20250411-01:58:29.118581369=46262=9476afd5-fdba-42be-bb0c-485d57b711d5268=1279=0269=083=159757962255=BTC-USD29004=2.208895519560=20250411-01:58:29.11662840=137=3b0cf341-ee7f-4f9d-8fbc-8e869ef442da10=078
20250411-01:58:29.291399000 : 8=FIXT.1.19=32735=X49=Coinbase56=24ab46f784d1b20db435b852086e325034=33650=TEST52=20250411-01:58:29.118636369=46262=9476afd5-fdba-42be-bb0c-485d57b711d5268=1279=0269=2278=c5b88ea9-605d-4595-ac52-f7c3f08523ba83=159757962355=BTC-USD270=3.55271=0.6222240960=20250411-01:58:29.11662837=3b0cf341-ee7f-4f9d-8fbc-8e869ef442da5797=110=226
20250411-01:58:29.291639000 : 8=FIXT.1.19=26635=X49=Coinbase56=24ab46f784d1b20db435b852086e325034=33750=TEST52=20250411-01:58:29.118645369=46262=9476afd5-fdba-42be-bb0c-485d57b711d5268=1279=2269=0278=3b0cf341-ee7f-4f9d-8fbc-8e869ef442da83=159757962455=BTC-USD60=20250411-01:58:29.11662858=FILLED10=095
20250411-01:58:29.293241000 : 8=FIXT.1.19=27535=X49=Coinbase56=24ab46f784d1b20db435b852086e325034=33850=TEST52=20250411-01:58:29.146957369=46262=9476afd5-fdba-42be-bb0c-485d57b711d5268=1279=0269=183=159757962555=BTC-USD271=0.6232294660=20250411-01:58:29.14503940=137=6f545175-31fa-4956-a14b-edd0fe85feca10=015
20250411-01:58:29.294534000 : 8=FIXT.1.19=32735=X49=Coinbase56=24ab46f784d1b20db435b852086e325034=33950=TEST52=20250411-01:58:29.146964369=46262=9476afd5-fdba-42be-bb0c-485d57b711d5268=1279=0269=2278=4d60a78e-b39b-420e-b830-bc0f3f4fdde283=159757962655=BTC-USD270=3.53271=0.6232294660=20250411-01:58:29.14503937=6f545175-31fa-4956-a14b-edd0fe85feca5797=210=002
20250411-01:58:29.294729000 : 8=FIXT.1.19=28135=X49=Coinbase56=24ab46f784d1b20db435b852086e325034=34050=TEST52=20250411-01:58:29.146966369=46262=9476afd5-fdba-42be-bb0c-485d57b711d5268=1279=2269=1278=6f545175-31fa-4956-a14b-edd0fe85feca83=159757962755=BTC-USD271=0.0000000060=20250411-01:58:29.14503958=FILLED10=166
20250411-01:58:29.349825000 : 8=FIXT.1.19=27935=X49=Coinbase56=24ab46f784d1b20db435b852086e325034=34150=TEST52=20250411-01:58:29.232968369=46262=9476afd5-fdba-42be-bb0c-485d57b711d5268=1279=0269=083=159757962855=BTC-USD29004=2.208895519560=20250411-01:58:29.23179140=137=5279e4f1-a18e-424b-b2e6-2b15c5e21d9a10=122
20250411-01:58:29.350202000 : 8=FIXT.1.19=32735=X49=Coinbase56=24ab46f784d1b20db435b852086e325034=34250=TEST52=20250411-01:58:29.233043369=46262=9476afd5-fdba-42be-bb0c-485d57b711d5268=1279=0269=2278=c5b88ea9-605d-4595-ac52-f7c3f08523ba83=159757962955=BTC-USD270=3.55271=0.6222240960=20250411-01:58:29.23179137=5279e4f1-a18e-424b-b2e6-2b15c5e21d9a5797=110=254
20250411-01:58:29.350453000 : 8=FIXT.1.19=26635=X49=Coinbase56=24ab46f784d1b20db435b852086e325034=34350=TEST52=20250411-01:58:29.233091369=46262=9476afd5-fdba-42be-bb0c-485d57b711d5268=1279=2269=0278=5279e4f1-a18e-424b-b2e6-2b15c5e21d9a83=159757963055=BTC-USD60=20250411-01:58:29.23179158=FILLED10=117
20250411-01:58:29.377559000 : 8=FIXT.1.19=27535=X49=Coinbase56=24ab46f784d1b20db435b852086e325034=34450=TEST52=20250411-01:58:29.261875369=46262=9476afd5-fdba-42be-bb0c-485d57b711d5268=1279=0269=183=159757963155=BTC-USD271=0.6232294660=20250411-01:58:29.25984740=137=22d911c2-dc51-4c7b-a86c-33bed1492e5a10=208
20250411-01:58:29.377802000 : 8=FIXT.1.19=32735=X49=Coinbase56=24ab46f784d1b20db435b852086e325034=34550=TEST52=20250411-01:58:29.261897369=46262=9476afd5-fdba-42be-bb0c-485d57b711d5268=1279=0269=2278=4d60a78e-b39b-420e-b830-bc0f3f4fdde283=159757963255=BTC-USD270=3.53271=0.6232294660=20250411-01:58:29.25984737=22d911c2-dc51-4c7b-a86c-33bed1492e5a5797=210=201
20250411-01:58:29.377938000 : 8=FIXT.1.19=28135=X49=Coinbase56=24ab46f784d1b20db435b852086e325034=34650=TEST52=20250411-01:58:29.261901369=46262=9476afd5-fdba-42be-bb0c-485d57b711d5268=1279=2269=1278=22d911c2-dc51-4c7b-a86c-33bed1492e5a83=159757963355=BTC-USD271=0.0000000060=20250411-01:58:29.25984758=FILLED10=102
20250411-01:58:29.551173000 : 8=FIXT.1.19=28435=X49=Coinbase56=24ab46f784d1b20db435b852086e325034=34750=TEST52=20250411-01:58:29.433522369=46262=9476afd5-fdba-42be-bb0c-485d57b711d5268=1279=0269=083=159757963455=BTC-USD270=3.84271=0.6232294660=20250411-01:58:29.43198140=237=063a6fdf-46cd-4ec2-a5cf-c276240e1d9e10=210
20250411-01:58:29.551769000 : 8=FIXT.1.19=32735=X49=Coinbase56=24ab46f784d1b20db435b852086e325034=34850=TEST52=20250411-01:58:29.433532369=46262=9476afd5-fdba-42be-bb0c-485d57b711d5268=1279=0269=2278=c5b88ea9-605d-4595-ac52-f7c3f08523ba83=159757963555=BTC-USD270=3.55271=0.6232294660=20250411-01:58:29.43198137=063a6fdf-46cd-4ec2-a5cf-c276240e1d9e5797=110=165
20250411-01:58:29.551936000 : 8=FIXT.1.19=29035=X49=Coinbase56=24ab46f784d1b20db435b852086e325034=34950=TEST52=20250411-01:58:29.433535369=46262=9476afd5-fdba-42be-bb0c-485d57b711d5268=1279=2269=0278=063a6fdf-46cd-4ec2-a5cf-c276240e1d9e83=159757963655=BTC-USD270=3.84271=0.0000000060=20250411-01:58:29.43198158=FILLED10=117
20250411-01:58:29.605523000 : 8=FIXT.1.19=30335=X49=Coinbase56=24ab46f784d1b20db435b852086e325034=35050=TEST52=20250411-01:58:29.489631369=46262=9476afd5-fdba-42be-bb0c-485d57b711d5268=1279=0269=183=159757963755=BTC-USD270=3.25271=0.5750708229004=2.029999994660=20250411-01:58:29.48796940=237=c5865f0f-9756-4919-98ad-33321f7ca7a610=155
20250411-01:58:29.605687000 : 8=FIXT.1.19=32735=X49=Coinbase56=24ab46f784d1b20db435b852086e325034=35150=TEST52=20250411-01:58:29.489684369=46262=9476afd5-fdba-42be-bb0c-485d57b711d5268=1279=0269=2278=4d60a78e-b39b-420e-b830-bc0f3f4fdde283=159757963855=BTC-USD270=3.53271=0.5750708260=20250411-01:58:29.48796937=c5865f0f-9756-4919-98ad-33321f7ca7a65797=210=065
20250411-01:58:29.605832000 : 8=FIXT.1.19=28135=X49=Coinbase56=24ab46f784d1b20db435b852086e325034=35250=TEST52=20250411-01:58:29.489690369=46262=9476afd5-fdba-42be-bb0c-485d57b711d5268=1279=2269=1278=c5865f0f-9756-4919-98ad-33321f7ca7a683=159757963955=BTC-USD270=3.25271=060=20250411-01:58:29.48796958=FILLED10=218
20250411-01:58:29.807047000 : 8=FIXT.1.19=27935=X49=Coinbase56=24ab46f784d1b20db435b852086e325034=35350=TEST52=20250411-01:58:29.690461369=46262=9476afd5-fdba-42be-bb0c-485d57b711d5268=1279=0269=083=159757964055=BTC-USD29004=2.208895519560=20250411-01:58:29.68837440=137=dcb7d9f0-fedd-4773-8a4c-1195fdbd40e610=081
20250411-01:58:29.807592000 : 8=FIXT.1.19=32735=X49=Coinbase56=24ab46f784d1b20db435b852086e325034=35450=TEST52=20250411-01:58:29.690469369=46262=9476afd5-fdba-42be-bb0c-485d57b711d5268=1279=0269=2278=c5b88ea9-605d-4595-ac52-f7c3f08523ba83=159757964155=BTC-USD270=3.55271=0.6222240960=20250411-01:58:29.68837437=dcb7d9f0-fedd-4773-8a4c-1195fdbd40e65797=110=236
20250411-01:58:29.807791000 : 8=FIXT.1.19=26635=X49=Coinbase56=24ab46f784d1b20db435b852086e325034=35550=TEST52=20250411-01:58:29.690474369=46262=9476afd5-fdba-42be-bb0c-485d57b711d5268=1279=2269=0278=dcb7d9f0-fedd-4773-8a4c-1195fdbd40e683=159757964255=BTC-USD60=20250411-01:58:29.68837458=FILLED10=101
20250411-01:58:29.834913000 : 8=FIXT.1.19=27535=X49=Coinbase56=24ab46f784d1b20db435b852086e325034=35650=TEST52=20250411-01:58:29.718634369=46262=9476afd5-fdba-42be-bb0c-485d57b711d5268=1279=0269=183=159757964355=BTC-USD271=0.6232294660=20250411-01:58:29.71713040=137=83e97757-92c5-4b94-a385-13144390c88b10=155
20250411-01:58:29.835056000 : 8=FIXT.1.19=32735=X49=Coinbase56=24ab46f784d1b20db435b852086e325034=35750=TEST52=20250411-01:58:29.718645369=46262=9476afd5-fdba-42be-bb0c-485d57b711d5268=1279=0269=2278=4d60a78e-b39b-420e-b830-bc0f3f4fdde283=159757964455=BTC-USD270=3.53271=0.6232294660=20250411-01:58:29.71713037=83e97757-92c5-4b94-a385-13144390c88b5797=210=146
20250411-01:58:29.835184000 : 8=FIXT.1.19=28135=X49=Coinbase56=24ab46f784d1b20db435b852086e325034=35850=TEST52=20250411-01:58:29.718725369=46262=9476afd5-fdba-42be-bb0c-485d57b711d5268=1279=2269=1278=83e97757-92c5-4b94-a385-13144390c88b83=159757964555=BTC-USD271=0.0000000060=20250411-01:58:29.71713058=FILLED10=060
20250411-01:58:30.300792000 : 8=FIXT.1.19=27935=X49=Coinbase56=24ab46f784d1b20db435b852086e325034=35950=TEST52=20250411-01:58:30.147046369=46262=9476afd5-fdba-42be-bb0c-485d57b711d5268=1279=0269=083=159757964655=BTC-USD29004=2.208895519560=20250411-01:58:30.14579440=137=94df8d29-1d35-428b-aa5b-6470c9cf2d2f10=177
20250411-01:58:30.301214000 : 8=FIXT.1.19=32735=X49=Coinbase56=24ab46f784d1b20db435b852086e325034=36050=TEST52=20250411-01:58:30.147055369=46262=9476afd5-fdba-42be-bb0c-485d57b711d5268=1279=0269=2278=c5b88ea9-605d-4595-ac52-f7c3f08523ba83=159757964755=BTC-USD270=3.55271=0.6222240960=20250411-01:58:30.14579437=94df8d29-1d35-428b-aa5b-6470c9cf2d2f5797=110=059
20250411-01:58:30.301385000 : 8=FIXT.1.19=26635=X49=Coinbase56=24ab46f784d1b20db435b852086e325034=36150=TEST52=20250411-01:58:30.147058369=46262=9476afd5-fdba-42be-bb0c-485d57b711d5268=1279=2269=0278=94df8d29-1d35-428b-aa5b-6470c9cf2d2f83=159757964855=BTC-USD60=20250411-01:58:30.14579458=FILLED10=187
20250411-01:58:30.301577000 : 8=FIXT.1.19=27535=X49=Coinbase56=24ab46f784d1b20db435b852086e325034=36250=TEST52=20250411-01:58:30.175397369=46262=9476afd5-fdba-42be-bb0c-485d57b711d5268=1279=0269=183=159757964955=BTC-USD271=0.6232294660=20250411-01:58:30.17401440=137=0ba531b4-87c6-413e-b385-1225506ee65510=207
20250411-01:58:30.301983000 : 8=FIXT.1.19=32735=X49=Coinbase56=24ab46f784d1b20db435b852086e325034=36350=TEST52=20250411-01:58:30.175407369=46262=9476afd5-fdba-42be-bb0c-485d57b711d5268=1279=0269=2278=4d60a78e-b39b-420e-b830-bc0f3f4fdde283=159757965055=BTC-USD270=3.53271=0.6232294660=20250411-01:58:30.17401437=0ba531b4-87c6-413e-b385-1225506ee6555797=210=179
20250411-01:58:30.302131000 : 8=FIXT.1.19=28135=X49=Coinbase56=24ab46f784d1b20db435b852086e325034=36450=TEST52=20250411-01:58:30.175409369=46262=9476afd5-fdba-42be-bb0c-485d57b711d5268=1279=2269=1278=0ba531b4-87c6-413e-b385-1225506ee65583=159757965155=BTC-USD271=0.0000000060=20250411-01:58:30.17401458=FILLED10=096
20250411-01:58:30.502780000 : 8=FIXT.1.19=28435=X49=Coinbase56=24ab46f784d1b20db435b852086e325034=36550=TEST52=20250411-01:58:30.339957369=46262=9476afd5-fdba-42be-bb0c-485d57b711d5268=1279=0269=183=159757965255=BTC-USD270=3.18271=0.6232294660=20250411-01:58:30.33877440=237=35ccc2b1-9065-4be5-a220-461e8446627410=129
20250411-01:58:30.505253000 : 8=FIXT.1.19=32735=X49=Coinbase56=24ab46f784d1b20db435b852086e325034=36650=TEST52=20250411-01:58:30.339969369=46262=9476afd5-fdba-42be-bb0c-485d57b711d5268=1279=0269=2278=4d60a78e-b39b-420e-b830-bc0f3f4fdde283=159757965355=BTC-USD270=3.53271=0.6232294660=20250411-01:58:30.33877437=35ccc2b1-9065-4be5-a220-461e844662745797=210=215
20250411-01:58:30.506853000 : 8=FIXT.1.19=29035=X49=Coinbase56=24ab46f784d1b20db435b852086e325034=36750=TEST52=20250411-01:58:30.339972369=46262=9476afd5-fdba-42be-bb0c-485d57b711d5268=1279=2269=1278=35ccc2b1-9065-4be5-a220-461e8446627483=159757965455=BTC-USD270=3.18271=0.0000000060=20250411-01:58:30.33877458=FILLED10=029
20250411-01:58:30.549309000 : 8=FIXT.1.19=27935=X49=Coinbase56=24ab46f784d1b20db435b852086e325034=36850=TEST52=20250411-01:58:30.433613369=46262=9476afd5-fdba-42be-bb0c-485d57b711d5268=1279=0269=083=159757965555=BTC-USD29004=2.208895519560=20250411-01:58:30.43153540=137=50cb5b38-e95f-4822-94da-eea3acea41db10=040
20250411-01:58:30.549727000 : 8=FIXT.1.19=32735=X49=Coinbase56=24ab46f784d1b20db435b852086e325034=36950=TEST52=20250411-01:58:30.433633369=46262=9476afd5-fdba-42be-bb0c-485d57b711d5268=1279=0269=2278=c5b88ea9-605d-4595-ac52-f7c3f08523ba83=159757965655=BTC-USD270=3.55271=0.6222240960=20250411-01:58:30.43153537=50cb5b38-e95f-4822-94da-eea3acea41db5797=110=189
20250411-01:58:30.550005000 : 8=FIXT.1.19=26635=X49=Coinbase56=24ab46f784d1b20db435b852086e325034=37050=TEST52=20250411-01:58:30.433691369=46262=9476afd5-fdba-42be-bb0c-485d57b711d5268=1279=2269=0278=50cb5b38-e95f-4822-94da-eea3acea41db83=159757965755=BTC-USD60=20250411-01:58:30.43153558=FILLED10=053
20250411-01:58:30.577866000 : 8=FIXT.1.19=27535=X49=Coinbase56=24ab46f784d1b20db435b852086e325034=37150=TEST52=20250411-01:58:30.462088369=46262=9476afd5-fdba-42be-bb0c-485d57b711d5268=1279=0269=183=159757965855=BTC-USD271=0.6232294660=20250411-01:58:30.46085240=137=73cc5032-9e5e-4a48-a45d-906a756d4a1810=064
20250411-01:58:30.578199000 : 8=FIXT.1.19=32735=X49=Coinbase56=24ab46f784d1b20db435b852086e325034=37250=TEST52=20250411-01:58:30.462112369=46262=9476afd5-fdba-42be-bb0c-485d57b711d5268=1279=0269=2278=4d60a78e-b39b-420e-b830-bc0f3f4fdde283=159757965955=BTC-USD270=3.53271=0.6232294660=20250411-01:58:30.46085237=73cc5032-9e5e-4a48-a45d-906a756d4a185797=210=041
20250411-01:58:30.578364000 : 8=FIXT.1.19=28135=X49=Coinbase56=24ab46f784d1b20db435b852086e325034=37350=TEST52=20250411-01:58:30.462117369=46262=9476afd5-fdba-42be-bb0c-485d57b711d5268=1279=2269=1278=73cc5032-9e5e-4a48-a45d-906a756d4a1883=159757966055=BTC-USD271=0.0000000060=20250411-01:58:30.46085258=FILLED10=208
20250411-01:58:31.038393000 : 8=FIXT.1.19=28435=X49=Coinbase56=24ab46f784d1b20db435b852086e325034=37450=TEST52=20250411-01:58:30.922837369=46262=9476afd5-fdba-42be-bb0c-485d57b711d5268=1279=0269=083=159757966155=BTC-USD270=3.72271=0.6232294660=20250411-01:58:30.92104340=237=04a6ec59-66c8-49de-81db-91da3ea5374810=070
20250411-01:58:31.038978000 : 8=FIXT.1.19=32735=X49=Coinbase56=24ab46f784d1b20db435b852086e325034=37550=TEST52=20250411-01:58:30.922850369=46262=9476afd5-fdba-42be-bb0c-485d57b711d5268=1279=0269=2278=c5b88ea9-605d-4595-ac52-f7c3f08523ba83=159757966255=BTC-USD270=3.55271=0.6232294660=20250411-01:58:30.92104337=04a6ec59-66c8-49de-81db-91da3ea537485797=110=022
20250411-01:58:31.039145000 : 8=FIXT.1.19=29035=X49=Coinbase56=24ab46f784d1b20db435b852086e325034=37650=TEST52=20250411-01:58:30.922887369=46262=9476afd5-fdba-42be-bb0c-485d57b711d5268=1279=2269=0278=04a6ec59-66c8-49de-81db-91da3ea5374883=159757966355=BTC-USD270=3.72271=0.0000000060=20250411-01:58:30.92104358=FILLED10=234
20250411-01:58:31.039275000 : 8=FIXT.1.19=28435=X49=Coinbase56=24ab46f784d1b20db435b852086e325034=37750=TEST52=20250411-01:58:30.922892369=46262=9476afd5-fdba-42be-bb0c-485d57b711d5268=1279=0269=083=159757966455=BTC-USD270=3.74271=0.6232294660=20250411-01:58:30.92104340=237=86f685f4-cfc2-42ca-81c6-4b2fd03e2ac610=160
20250411-01:58:31.039401000 : 8=FIXT.1.19=32735=X49=Coinbase56=24ab46f784d1b20db435b852086e325034=37850=TEST52=20250411-01:58:30.922897369=46262=9476afd5-fdba-42be-bb0c-485d57b711d5268=1279=0269=2278=c5b88ea9-605d-4595-ac52-f7c3f08523ba83=159757966555=BTC-USD270=3.55271=0.6232294660=20250411-01:58:30.92104337=86f685f4-cfc2-42ca-81c6-4b2fd03e2ac65797=110=120
20250411-01:58:31.039913000 : 8=FIXT.1.19=29035=X49=Coinbase56=24ab46f784d1b20db435b852086e325034=37950=TEST52=20250411-01:58:30.922899369=46262=9476afd5-fdba-42be-bb0c-485d57b711d5268=1279=2269=0278=86f685f4-cfc2-42ca-81c6-4b2fd03e2ac683=159757966655=BTC-USD270=3.74271=0.0000000060=20250411-01:58:30.92104358=FILLED10=070
20250411-01:58:31.148909000 : 8=FIXT.1.19=28435=X49=Coinbase56=24ab46f784d1b20db435b852086e325034=38050=TEST52=20250411-01:58:31.033142369=46262=9476afd5-fdba-42be-bb0c-485d57b711d5268=1279=0269=183=159757966755=BTC-USD270=3.35271=0.6232294660=20250411-01:58:31.03198040=237=e23020fc-94b5-48c1-a81c-feb7216e69f410=044
20250411-01:58:31.149186000 : 8=FIXT.1.19=32735=X49=Coinbase56=24ab46f784d1b20db435b852086e325034=38150=TEST52=20250411-01:58:31.033205369=46262=9476afd5-fdba-42be-bb0c-485d57b711d5268=1279=0269=2278=4d60a78e-b39b-420e-b830-bc0f3f4fdde283=159757966855=BTC-USD270=3.53271=0.6232294660=20250411-01:58:31.03198037=e23020fc-94b5-48c1-a81c-feb7216e69f45797=210=128
20250411-01:58:31.149352000 : 8=FIXT.1.19=29035=X49=Coinbase56=24ab46f784d1b20db435b852086e325034=38250=TEST52=20250411-01:58:31.033213369=46262=9476afd5-fdba-42be-bb0c-485d57b711d5268=1279=2269=1278=e23020fc-94b5-48c1-a81c-feb7216e69f483=159757966955=BTC-USD270=3.35271=0.0000000060=20250411-01:58:31.03198058=FILLED10=202
20250411-01:58:31.149520000 : 8=FIXT.1.19=28435=X49=Coinbase56=24ab46f784d1b20db435b852086e325034=38350=TEST52=20250411-01:58:31.033224369=46262=9476afd5-fdba-42be-bb0c-485d57b711d5268=1279=0269=183=159757967055=BTC-USD270=3.34271=0.6232294660=20250411-01:58:31.03198040=237=ebd04cc3-cb9b-4dea-afd8-21428afe3f9c10=115
20250411-01:58:31.149652000 : 8=FIXT.1.19=32735=X49=Coinbase56=24ab46f784d1b20db435b852086e325034=38450=TEST52=20250411-01:58:31.033228369=46262=9476afd5-fdba-42be-bb0c-485d57b711d5268=1279=0269=2278=4d60a78e-b39b-420e-b830-bc0f3f4fdde283=159757967155=BTC-USD270=3.53271=0.6232294660=20250411-01:58:31.03198037=ebd04cc3-cb9b-4dea-afd8-21428afe3f9c5797=210=204
