20250410-22:59:44.352842000 : 8=FIXT.1.19=95935=W49=Coinbase56=24ab46f784d1b20db435b852086e325034=15250=TEST52=20250410-22:59:43.793579369=2262=951674d8-b877-4a40-8deb-be531852296483=1597363728893=N55=BTC-USD1682=full_trading268=10269=1278=afd96a7b-3d48-459e-b810-e4ee88353a31270=900000.00271=0.00011111269=1278=a68ae029-b920-4ae7-a775-ccdb800fc252270=900000.00271=0.00001111269=1278=d44508b7-1c9f-4b4f-acb8-99c93d2b99e8270=900000.00271=0.00001111269=1278=304ff106-de40-4381-89c5-c93f7f3e32ae270=900000.00271=0.00001111269=1278=08a0fef8-fcbb-4857-8463-2599cf331386270=900000.00271=0.00011111269=1278=07b2856d-f899-417c-82d5-886f0d85125e270=900000.00271=0.00011111269=1278=12ecb45e-6af8-4804-a942-5c997b9d1502270=900000.00271=0.00011111269=1278=98676c5f-b851-473c-817a-b29243092a25270=900000.00271=0.00001111269=1278=09afe685-e71f-4ea0-b164-c27737db126d270=900000.00271=0.00001111269=1278=e71ee98f-c329-428d-9893-629b53015ff6270=900000.00271=0.0000111110=189
20250410-22:59:44.353572000 : 8=FIXT.1.19=14235=334=4549=24ab46f784d1b20db435b852086e325052=20250410-22:59:44.35356=Coinbase45=15258=Tag appears more than once371=269372=W373=1310=055
20250410-22:59:44.353686000 : 8=FIXT.1.19=58235=W49=Coinbase56=24ab46f784d1b20db435b852086e325034=15350=TEST52=20250410-22:59:43.793830369=2262=951674d8-b877-4a40-8deb-be531852296483=1597363728893=Y55=BTC-USD1682=full_trading268=5269=1278=124e6fc1-6dde-452b-be03-c00113c8ebdb270=900000.00271=0.00011111269=1278=b71cc7f5-d7c6-4fc0-a0de-59b0eb7fd063270=1000000.00271=1.00000000269=1278=afec127b-a98c-49cb-893f-e385a7e35d32270=1000000.00271=1.00000000269=1278=06df7c57-366d-4d2c-acc2-e6c26d60e9c3270=1000000.00271=1.00000000269=1278=b1c4eb2b-90df-44e0-ae4f-515df4086a9d270=9999999.00271=0.0000100010=211
20250410-22:59:44.354360000 : 8=FIXT.1.19=14235=334=4649=24ab46f784d1b20db435b852086e325052=20250410-22:59:44.35356=Coinbase45=15358=Tag appears more than once371=269372=W373=1310=057
20250410-22:59:44.354532000 : 8=FIXT.1.19=27835=X49=Coinbase56=24ab46f784d1b20db435b852086e325034=15450=TEST52=20250410-22:59:43.954093369=2262=951674d8-b877-4a40-8deb-be5318522964268=1279=0269=083=159736372955=BTC-USD29004=2.208895536660=20250410-22:59:43.95277240=137=1a2db894-64f8-4775-b1cc-c4432c3b705910=178
20250410-22:59:44.354766000 : 8=FIXT.1.19=32635=X49=Coinbase56=24ab46f784d1b20db435b852086e325034=15550=TEST52=20250410-22:59:43.954101369=2262=951674d8-b877-4a40-8deb-be5318522964268=1279=0269=2278=b9704cf1-f180-4d92-90da-6bb364d4a71583=159736373055=BTC-USD270=3.54271=0.6239817960=20250410-22:59:43.95277237=1a2db894-64f8-4775-b1cc-c4432c3b70595797=110=008
20250410-22:59:44.355063000 : 8=FIXT.1.19=26535=X49=Coinbase56=24ab46f784d1b20db435b852086e325034=15650=TEST52=20250410-22:59:43.954108369=2262=951674d8-b877-4a40-8deb-be5318522964268=1279=2269=0278=1a2db894-64f8-4775-b1cc-c4432c3b705983=159736373155=BTC-USD60=20250410-22:59:43.95277258=FILLED10=182
20250410-22:59:44.355306000 : 8=FIXT.1.19=27435=X49=Coinbase56=24ab46f784d1b20db435b852086e325034=15750=TEST52=20250410-22:59:43.983505369=2262=951674d8-b877-4a40-8deb-be5318522964268=1279=0269=183=159736373255=BTC-USD271=0.6232294660=20250410-22:59:43.98228540=137=e4e1742a-3b94-49e8-a8ae-834921ce60e810=015
20250410-22:59:44.355498000 : 8=FIXT.1.19=32635=X49=Coinbase56=24ab46f784d1b20db435b852086e325034=15850=TEST52=20250410-22:59:43.983513369=2262=951674d8-b877-4a40-8deb-be5318522964268=1279=0269=2278=4d60a78e-b39b-420e-b830-bc0f3f4fdde283=159736373355=BTC-USD270=3.53271=0.6232294660=20250410-22:59:43.98228537=e4e1742a-3b94-49e8-a8ae-834921ce60e85797=210=003
20250410-22:59:44.355768000 : 8=FIXT.1.19=28035=X49=Coinbase56=24ab46f784d1b20db435b852086e325034=15950=TEST52=20250410-22:59:43.983518369=2262=951674d8-b877-4a40-8deb-be5318522964268=1279=2269=1278=e4e1742a-3b94-49e8-a8ae-834921ce60e883=159736373455=BTC-USD271=0.0000000060=20250410-22:59:43.98228558=FILLED10=179
20250410-22:59:44.636020000 : 8=FIXT.1.19=27935=X49=Coinbase56=24ab46f784d1b20db435b852086e325034=16050=TEST52=20250410-22:59:44.526496369=46262=951674d8-b877-4a40-8deb-be5318522964268=1279=0269=083=159736373555=BTC-USD29004=2.208895536660=20250410-22:59:44.52507540=137=24ac89fb-f5cd-4d23-995d-8c5e9261565610=039
20250410-22:59:44.636414000 : 8=FIXT.1.19=32735=X49=Coinbase56=24ab46f784d1b20db435b852086e325034=16150=TEST52=20250410-22:59:44.526503369=46262=951674d8-b877-4a40-8deb-be5318522964268=1279=0269=2278=b9704cf1-f180-4d92-90da-6bb364d4a71583=159736373655=BTC-USD270=3.54271=0.6239817960=20250410-22:59:44.52507537=24ac89fb-f5cd-4d23-995d-8c5e926156565797=110=133
20250410-22:59:44.636748000 : 8=FIXT.1.19=26635=X49=Coinbase56=24ab46f784d1b20db435b852086e325034=16250=TEST52=20250410-22:59:44.526507369=46262=951674d8-b877-4a40-8deb-be5318522964268=1279=2269=0278=24ac89fb-f5cd-4d23-995d-8c5e9261565683=159736373755=BTC-USD60=20250410-22:59:44.52507558=FILLED10=048
20250410-22:59:44.662855000 : 8=FIXT.1.19=27535=X49=Coinbase56=24ab46f784d1b20db435b852086e325034=16350=TEST52=20250410-22:59:44.555102369=46262=951674d8-b877-4a40-8deb-be5318522964268=1279=0269=183=159736373855=BTC-USD271=0.6232294660=20250410-22:59:44.55299740=137=3ec597aa-d75b-42d8-beb0-5832285a613810=057
20250410-22:59:44.663388000 : 8=FIXT.1.19=32735=X49=Coinbase56=24ab46f784d1b20db435b852086e325034=16450=TEST52=20250410-22:59:44.555108369=46262=951674d8-b877-4a40-8deb-be5318522964268=1279=0269=2278=4d60a78e-b39b-420e-b830-bc0f3f4fdde283=159736373955=BTC-USD270=3.53271=0.6232294660=20250410-22:59:44.55299737=3ec597aa-d75b-42d8-beb0-5832285a61385797=210=052
20250410-22:59:44.663641000 : 8=FIXT.1.19=28135=X49=Coinbase56=24ab46f784d1b20db435b852086e325034=16550=TEST52=20250410-22:59:44.555112369=46262=951674d8-b877-4a40-8deb-be5318522964268=1279=2269=1278=3ec597aa-d75b-42d8-beb0-5832285a613883=159736374055=BTC-USD271=0.0000000060=20250410-22:59:44.55299758=FILLED10=209
20250410-22:59:44.752693000 : 8=FIXT.1.19=27935=X49=Coinbase56=24ab46f784d1b20db435b852086e325034=16650=TEST52=20250410-22:59:44.640655369=46262=951674d8-b877-4a40-8deb-be5318522964268=1279=0269=083=159736374155=BTC-USD29004=2.208895536660=20250410-22:59:44.63947940=137=37f1a4b9-f155-4034-95f7-eea22243466e10=189
20250410-22:59:44.753852000 : 8=FIXT.1.19=8435=534=4749=24ab46f784d1b20db435b852086e325052=20250410-22:59:44.75356=Coinbase10=181
20250410-22:59:44.754053000 : 8=FIXT.1.19=32735=X49=Coinbase56=24ab46f784d1b20db435b852086e325034=16750=TEST52=20250410-22:59:44.640664369=46262=951674d8-b877-4a40-8deb-be5318522964268=1279=0269=2278=b9704cf1-f180-4d92-90da-6bb364d4a71583=159736374255=BTC-USD270=3.54271=0.6239817960=20250410-22:59:44.63947937=37f1a4b9-f155-4034-95f7-eea22243466e5797=110=038
20250410-22:59:44.754376000 : 8=FIXT.1.19=26635=X49=Coinbase56=24ab46f784d1b20db435b852086e325034=16850=TEST52=20250410-22:59:44.640668369=46262=951674d8-b877-4a40-8deb-be5318522964268=1279=2269=0278=37f1a4b9-f155-4034-95f7-eea22243466e83=159736374355=BTC-USD60=20250410-22:59:44.63947958=FILLED10=209
20250410-22:59:44.777130000 : 8=FIXT.1.19=27535=X49=Coinbase56=24ab46f784d1b20db435b852086e325034=16950=TEST52=20250410-22:59:44.669018369=46262=951674d8-b877-4a40-8deb-be5318522964268=1279=0269=183=159736374455=BTC-USD271=0.6232294660=20250410-22:59:44.66700940=137=8a1c7c95-25e7-4d1f-8218-7637562233c410=137
20250410-22:59:44.777488000 : 8=FIXT.1.19=32735=X49=Coinbase56=24ab46f784d1b20db435b852086e325034=17050=TEST52=20250410-22:59:44.669024369=46262=951674d8-b877-4a40-8deb-be5318522964268=1279=0269=2278=4d60a78e-b39b-420e-b830-bc0f3f4fdde283=159736374555=BTC-USD270=3.53271=0.6232294660=20250410-22:59:44.66700937=8a1c7c95-25e7-4d1f-8218-7637562233c45797=210=114
20250410-22:59:44.777762000 : 8=FIXT.1.19=28135=X49=Coinbase56=24ab46f784d1b20db435b852086e325034=17150=TEST52=20250410-22:59:44.669029369=46262=951674d8-b877-4a40-8deb-be5318522964268=1279=2269=1278=8a1c7c95-25e7-4d1f-8218-7637562233c483=159736374655=BTC-USD271=0.0000000060=20250410-22:59:44.66700958=FILLED10=034
20250410-22:59:44.976658000 : 8=FIXT.1.19=27935=X49=Coinbase56=24ab46f784d1b20db435b852086e325034=17250=TEST52=20250410-22:59:44.869007369=46262=951674d8-b877-4a40-8deb-be5318522964268=1279=0269=083=159736374755=BTC-USD29004=2.208895536660=20250410-22:59:44.86773940=137=39519856-a577-468e-913f-d75458849f8b10=099
20250410-22:59:44.977142000 : 8=FIXT.1.19=32735=X49=Coinbase56=24ab46f784d1b20db435b852086e325034=17350=TEST52=20250410-22:59:44.869012369=46262=951674d8-b877-4a40-8deb-be5318522964268=1279=0269=2278=b9704cf1-f180-4d92-90da-6bb364d4a71583=159736374855=BTC-USD270=3.54271=0.6239817960=20250410-22:59:44.86773937=39519856-a577-468e-913f-d75458849f8b5797=110=200
20250410-22:59:44.977518000 : 8=FIXT.1.19=26635=X49=Coinbase56=24ab46f784d1b20db435b852086e325034=17450=TEST52=20250410-22:59:44.869017369=46262=951674d8-b877-4a40-8deb-be5318522964268=1279=2269=0278=39519856-a577-468e-913f-d75458849f8b83=159736374955=BTC-USD60=20250410-22:59:44.86773958=FILLED10=116
20250410-22:59:44.984494000 : 8=FIXT.1.19=12035=549=Coinbase56=24ab46f784d1b20db435b852086e325034=17550=TEST52=20250410-22:59:44.876433369=4658=CLIENT_LOGOUT10=126
20250411-01:22:32.718035000 : 8=FIXT.1.19=21535=A34=149=24ab46f784d1b20db435b852086e325052=20250411-01:22:32.71056=Coinbase95=4496=eBgADtV5SRoPx2G5qfLlqRXuRrjIMKIIk7HC1I+mOlA=98=0108=30141=Y553=24ab46f784d1b20db435b852086e3250554=akmwnltyfgb1137=910=189
20250411-01:22:32.974670000 : 8=FIXT.1.19=12535=A49=Coinbase56=24ab46f784d1b20db435b852086e325034=150=TEST52=20250411-01:22:32.861219369=198=0108=30141=Y1137=910=189
20250411-01:22:34.352685000 : 8=FIXT.1.19=17835=V34=249=24ab46f784d1b20db435b852086e325052=20250411-01:22:34.35256=Coinbase1128=9146=155=BTC-USD262=cf88f8c2-c1ea-4dd7-ae2f-ae85b6928ae8263=1264=0267=2269=0269=110=055
20250411-01:22:34.947309000 : 8=FIXT.1.19=28035=X49=Coinbase56=24ab46f784d1b20db435b852086e325034=250=TEST52=20250411-01:22:34.833883369=2262=cf88f8c2-c1ea-4dd7-ae2f-ae85b6928ae8268=1279=0269=183=159753607755=BTC-USD270=3.7271=0.6232294660=20250411-01:22:34.83236240=237=5ea6dac6-8ac3-4774-9d9a-070553e128b210=154
20250411-01:22:34.948203000 : 8=FIXT.1.19=27635=X49=Coinbase56=24ab46f784d1b20db435b852086e325034=350=TEST52=20250411-01:22:34.833888369=2262=cf88f8c2-c1ea-4dd7-ae2f-ae85b6928ae8268=1279=0269=1278=5ea6dac6-8ac3-4774-9d9a-070553e128b283=159753607855=BTC-USD270=3.7271=0.6232294660=20250411-01:22:34.83236210=009
20250411-01:22:35.228436000 : 8=FIXT.1.19=28135=X49=Coinbase56=24ab46f784d1b20db435b852086e325034=450=TEST52=20250411-01:22:35.116250369=2262=cf88f8c2-c1ea-4dd7-ae2f-ae85b6928ae8268=1279=0269=083=159753607955=BTC-USD270=3.39271=0.6232294660=20250411-01:22:35.11537540=237=a132f93c-d846-4e22-8c32-5f393b5b1c8810=148
20250411-01:22:35.228941000 : 8=FIXT.1.19=27735=X49=Coinbase56=24ab46f784d1b20db435b852086e325034=550=TEST52=20250411-01:22:35.116255369=2262=cf88f8c2-c1ea-4dd7-ae2f-ae85b6928ae8268=1279=0269=0278=a132f93c-d846-4e22-8c32-5f393b5b1c8883=159753608055=BTC-USD270=3.39271=0.6232294660=20250411-01:22:35.11537510=250
20250411-01:22:35.406052000 : 8=FIXT.1.19=28935=X49=Coinbase56=24ab46f784d1b20db435b852086e325034=650=TEST52=20250411-01:22:35.293837369=2262=cf88f8c2-c1ea-4dd7-ae2f-ae85b6928ae8268=1279=2269=0278=0a39c338-1bad-4f14-bfbf-56f2bdfe10dd83=159753608155=BTC-USD270=3.44271=0.4816216760=20250411-01:22:35.29261458=CANCELED10=034
20250411-01:22:35.789985000 : 8=FIXT.1.19=8335=534=349=24ab46f784d1b20db435b852086e325052=20250411-01:22:35.78956=Coinbase10=121
20250411-01:22:36.019518000 : 8=FIXT.1.19=11735=549=Coinbase56=24ab46f784d1b20db435b852086e325034=750=TEST52=20250411-01:22:35.906431369=258=CLIENT_LOGOUT10=210
20250411-01:22:43.620363000 : 8=FIXT.1.19=21535=A34=149=24ab46f784d1b20db435b852086e325052=20250411-01:22:43.60956=Coinbase95=4496=Yd2ZLamCZsvhPvGqzvtqRD4mehNtvpOZZx7ivL6kpxg=98=0108=30141=Y553=24ab46f784d1b20db435b852086e3250554=akmwnltyfgb1137=910=204
20250411-01:22:43.876123000 : 8=FIXT.1.19=12535=A49=Coinbase56=24ab46f784d1b20db435b852086e325034=150=TEST52=20250411-01:22:43.763770369=198=0108=30141=Y1137=910=194
20250411-01:22:45.381317000 : 8=FIXT.1.19=17835=V34=249=24ab46f784d1b20db435b852086e325052=20250411-01:22:45.38056=Coinbase1128=9146=155=BTC-USD262=f3031983-3333-44e4-810f-7a389c7706e2263=1264=0267=2269=0269=110=030
20250411-01:22:45.803353000 : 8=FIXT.1.19=28135=X49=Coinbase56=24ab46f784d1b20db435b852086e325034=250=TEST52=20250411-01:22:45.690993369=2262=f3031983-3333-44e4-810f-7a389c7706e2268=1279=0269=183=159753629455=BTC-USD270=3.56271=0.6232294660=20250411-01:22:45.68983540=237=4d9a1222-d476-4add-bb48-0d5276ede07b10=033
20250411-01:22:45.807756000 : 8=FIXT.1.19=27735=X49=Coinbase56=24ab46f784d1b20db435b852086e325034=350=TEST52=20250411-01:22:45.691000369=2262=f3031983-3333-44e4-810f-7a389c7706e2268=1279=0269=1278=4d9a1222-d476-4add-bb48-0d5276ede07b83=159753629555=BTC-USD270=3.56271=0.6232294660=20250411-01:22:45.68983510=119
20250411-01:22:46.085769000 : 8=FIXT.1.19=28135=X49=Coinbase56=24ab46f784d1b20db435b852086e325034=450=TEST52=20250411-01:22:45.974062369=2262=f3031983-3333-44e4-810f-7a389c7706e2268=1279=0269=083=159753629655=BTC-USD270=3.36271=0.6232294660=20250411-01:22:45.97260840=237=c1c9c161-ed3a-46e4-a43f-4e821b42248710=179
20250411-01:22:46.086395000 : 8=FIXT.1.19=27735=X49=Coinbase56=24ab46f784d1b20db435b852086e325034=550=TEST52=20250411-01:22:45.974069369=2262=f3031983-3333-44e4-810f-7a389c7706e2268=1279=0269=0278=c1c9c161-ed3a-46e4-a43f-4e821b42248783=159753629755=BTC-USD270=3.36271=0.6232294660=20250411-01:22:45.97260810=036
20250411-01:22:46.480145000 : 8=FIXT.1.19=27635=X49=Coinbase56=24ab46f784d1b20db435b852086e325034=650=TEST52=20250411-01:22:46.368507369=2262=f3031983-3333-44e4-810f-7a389c7706e2268=1279=0269=083=159753629855=BTC-USD29004=2.208895519560=20250411-01:22:46.36704640=137=b2a222cd-ade5-4b4d-bbdf-65c882502a1d10=207
20250411-01:22:46.480900000 : 8=FIXT.1.19=32435=X49=Coinbase56=24ab46f784d1b20db435b852086e325034=750=TEST52=20250411-01:22:46.368518369=2262=f3031983-3333-44e4-810f-7a389c7706e2268=1279=0269=2278=c5b88ea9-605d-4595-ac52-f7c3f08523ba83=159753629955=BTC-USD270=3.55271=0.6222240960=20250411-01:22:46.36704637=b2a222cd-ade5-4b4d-bbdf-65c882502a1d5797=110=100
20250411-01:22:46.481702000 : 8=FIXT.1.19=26335=X49=Coinbase56=24ab46f784d1b20db435b852086e325034=850=TEST52=20250411-01:22:46.368523369=2262=f3031983-3333-44e4-810f-7a389c7706e2268=1279=2269=0278=b2a222cd-ade5-4b4d-bbdf-65c882502a1d83=159753630055=BTC-USD60=20250411-01:22:46.36704658=FILLED10=203
20250411-01:22:46.508877000 : 8=FIXT.1.19=27235=X49=Coinbase56=24ab46f784d1b20db435b852086e325034=950=TEST52=20250411-01:22:46.396969369=2262=f3031983-3333-44e4-810f-7a389c7706e2268=1279=0269=183=159753630155=BTC-USD271=0.6232294660=20250411-01:22:46.39567740=137=f8defda8-7de1-41a6-bde2-a5b2d0f5073a10=061
20250411-01:22:46.509538000 : 8=FIXT.1.19=32535=X49=Coinbase56=24ab46f784d1b20db435b852086e325034=1050=TEST52=20250411-01:22:46.396977369=2262=f3031983-3333-44e4-810f-7a389c7706e2268=1279=0269=2278=4d60a78e-b39b-420e-b830-bc0f3f4fdde283=159753630255=BTC-USD270=3.53271=0.6232294660=20250411-01:22:46.39567737=f8defda8-7de1-41a6-bde2-a5b2d0f5073a5797=210=089
20250411-01:22:46.510213000 : 8=FIXT.1.19=27935=X49=Coinbase56=24ab46f784d1b20db435b852086e325034=1150=TEST52=20250411-01:22:46.396981369=2262=f3031983-3333-44e4-810f-7a389c7706e2268=1279=2269=1278=f8defda8-7de1-41a6-bde2-a5b2d0f5073a83=159753630355=BTC-USD271=0.0000000060=20250411-01:22:46.39567758=FILLED10=008
20250411-01:22:47.053589000 : 8=FIXT.1.19=27735=X49=Coinbase56=24ab46f784d1b20db435b852086e325034=1250=TEST52=20250411-01:22:46.940719369=2262=f3031983-3333-44e4-810f-7a389c7706e2268=1279=0269=083=159753630455=BTC-USD29004=2.208895519560=20250411-01:22:46.93943340=137=4cebe059-5237-4567-a1c3-fc5714c2d74a10=028
20250411-01:22:47.054074000 : 8=FIXT.1.19=32535=X49=Coinbase56=24ab46f784d1b20db435b852086e325034=1350=TEST52=20250411-01:22:46.940730369=2262=f3031983-3333-44e4-810f-7a389c7706e2268=1279=0269=2278=c5b88ea9-605d-4595-ac52-f7c3f08523ba83=159753630555=BTC-USD270=3.55271=0.6222240960=20250411-01:22:46.93943337=4cebe059-5237-4567-a1c3-fc5714c2d74a5797=110=168
20250411-01:22:47.054334000 : 8=FIXT.1.19=26435=X49=Coinbase56=24ab46f784d1b20db435b852086e325034=1450=TEST52=20250411-01:22:46.940735369=2262=f3031983-3333-44e4-810f-7a389c7706e2268=1279=2269=0278=4cebe059-5237-4567-a1c3-fc5714c2d74a83=159753630655=BTC-USD60=20250411-01:22:46.93943358=FILLED10=042
20250411-01:22:47.079221000 : 8=FIXT.1.19=27335=X49=Coinbase56=24ab46f784d1b20db435b852086e325034=1550=TEST52=20250411-01:22:46.967987369=2262=f3031983-3333-44e4-810f-7a389c7706e2268=1279=0269=183=159753630755=BTC-USD271=0.6232294660=20250411-01:22:46.96678240=137=6636aeee-7420-45c5-87df-669eea7a201910=110
20250411-01:22:47.079548000 : 8=FIXT.1.19=32535=X49=Coinbase56=24ab46f784d1b20db435b852086e325034=1650=TEST52=20250411-01:22:46.967996369=2262=f3031983-3333-44e4-810f-7a389c7706e2268=1279=0269=2278=4d60a78e-b39b-420e-b830-bc0f3f4fdde283=159753630855=BTC-USD270=3.53271=0.6232294660=20250411-01:22:46.96678237=6636aeee-7420-45c5-87df-669eea7a20195797=210=099
20250411-01:22:47.079791000 : 8=FIXT.1.19=27935=X49=Coinbase56=24ab46f784d1b20db435b852086e325034=1750=TEST52=20250411-01:22:46.968000369=2262=f3031983-3333-44e4-810f-7a389c7706e2268=1279=2269=1278=6636aeee-7420-45c5-87df-669eea7a201983=159753630955=BTC-USD271=0.0000000060=20250411-01:22:46.96678258=FILLED10=000
20250411-01:22:47.280565000 : 8=FIXT.1.19=27735=X49=Coinbase56=24ab46f784d1b20db435b852086e325034=1850=TEST52=20250411-01:22:47.168403369=2262=f3031983-3333-44e4-810f-7a389c7706e2268=1279=0269=083=159753631055=BTC-USD29004=2.208895519560=20250411-01:22:47.16698840=137=0b363488-03d8-4467-a2dc-535adcd057f810=244
20250411-01:22:47.280998000 : 8=FIXT.1.19=32535=X49=Coinbase56=24ab46f784d1b20db435b852086e325034=1950=TEST52=20250411-01:22:47.168412369=2262=f3031983-3333-44e4-810f-7a389c7706e2268=1279=0269=2278=c5b88ea9-605d-4595-ac52-f7c3f08523ba83=159753631155=BTC-USD270=3.55271=0.6222240960=20250411-01:22:47.16698837=0b363488-03d8-4467-a2dc-535adcd057f85797=110=135
20250411-01:22:47.282441000 : 8=FIXT.1.19=26435=X49=Coinbase56=24ab46f784d1b20db435b852086e325034=2050=TEST52=20250411-01:22:47.168417369=2262=f3031983-3333-44e4-810f-7a389c7706e2268=1279=2269=0278=0b363488-03d8-4467-a2dc-535adcd057f883=159753631255=BTC-USD60=20250411-01:22:47.16698858=FILLED10=000
20250411-01:22:47.300385000 : 8=FIXT.1.19=28135=X49=Coinbase56=24ab46f784d1b20db435b852086e325034=2150=TEST52=20250411-01:22:47.188922369=2262=f3031983-3333-44e4-810f-7a389c7706e2268=1279=0269=183=159753631355=BTC-USD270=3.3271=0.6197183160=20250411-01:22:47.18772740=237=89a402e9-f017-4534-98af-512c26b1031210=233
20250411-01:22:47.300694000 : 8=FIXT.1.19=32535=X49=Coinbase56=24ab46f784d1b20db435b852086e325034=2250=TEST52=20250411-01:22:47.188933369=2262=f3031983-3333-44e4-810f-7a389c7706e2268=1279=0269=2278=4d60a78e-b39b-420e-b830-bc0f3f4fdde283=159753631455=BTC-USD270=3.53271=0.6197183160=20250411-01:22:47.18772737=89a402e9-f017-4534-98af-512c26b103125797=210=117
20250411-01:22:47.301278000 : 8=FIXT.1.19=28735=X49=Coinbase56=24ab46f784d1b20db435b852086e325034=2350=TEST52=20250411-01:22:47.188938369=2262=f3031983-3333-44e4-810f-7a389c7706e2268=1279=2269=1278=89a402e9-f017-4534-98af-512c26b1031283=159753631555=BTC-USD270=3.3271=0.0000000060=20250411-01:22:47.18772758=FILLED10=150
20250411-01:22:47.307695000 : 8=FIXT.1.19=27335=X49=Coinbase56=24ab46f784d1b20db435b852086e325034=2450=TEST52=20250411-01:22:47.196130369=2262=f3031983-3333-44e4-810f-7a389c7706e2268=1279=0269=183=159753631655=BTC-USD271=0.6232294660=20250411-01:22:47.19511540=137=946d4f82-bbe4-4639-a47a-7d1a2523895c10=019
20250411-01:22:47.308121000 : 8=FIXT.1.19=32535=X49=Coinbase56=24ab46f784d1b20db435b852086e325034=2550=TEST52=20250411-01:22:47.196135369=2262=f3031983-3333-44e4-810f-7a389c7706e2268=1279=0269=2278=4d60a78e-b39b-420e-b830-bc0f3f4fdde283=159753631755=BTC-USD270=3.53271=0.6232294660=20250411-01:22:47.19511537=946d4f82-bbe4-4639-a47a-7d1a2523895c5797=210=013
20250411-01:22:47.308346000 : 8=FIXT.1.19=27935=X49=Coinbase56=24ab46f784d1b20db435b852086e325034=2650=TEST52=20250411-01:22:47.196139369=2262=f3031983-3333-44e4-810f-7a389c7706e2268=1279=2269=1278=946d4f82-bbe4-4639-a47a-7d1a2523895c83=159753631855=BTC-USD271=0.0000000060=20250411-01:22:47.19511558=FILLED10=197
20250411-01:22:47.353293000 : 8=FIXT.1.19=28235=X49=Coinbase56=24ab46f784d1b20db435b852086e325034=2750=TEST52=20250411-01:22:47.241996369=2262=f3031983-3333-44e4-810f-7a389c7706e2268=1279=0269=083=159753631955=BTC-USD270=3.74271=0.6197183160=20250411-01:22:47.24010740=237=9e1abe5f-1891-4e74-b576-70d088b8c05410=194
20250411-01:22:47.353787000 : 8=FIXT.1.19=32535=X49=Coinbase56=24ab46f784d1b20db435b852086e325034=2850=TEST52=20250411-01:22:47.242002369=2262=f3031983-3333-44e4-810f-7a389c7706e2268=1279=0269=2278=c5b88ea9-605d-4595-ac52-f7c3f08523ba83=159753632055=BTC-USD270=3.55271=0.6197183160=20250411-01:22:47.24010737=9e1abe5f-1891-4e74-b576-70d088b8c0545797=110=119
20250411-01:22:47.354152000 : 8=FIXT.1.19=28835=X49=Coinbase56=24ab46f784d1b20db435b852086e325034=2950=TEST52=20250411-01:22:47.242007369=2262=f3031983-3333-44e4-810f-7a389c7706e2268=1279=2269=0278=9e1abe5f-1891-4e74-b576-70d088b8c05483=159753632155=BTC-USD270=3.74271=0.0000000060=20250411-01:22:47.24010758=FILLED10=079
20250411-01:22:48.481726000 : 8=FIXT.1.19=27735=X49=Coinbase56=24ab46f784d1b20db435b852086e325034=3050=TEST52=20250411-01:22:48.368858369=2262=f3031983-3333-44e4-810f-7a389c7706e2268=1279=0269=083=159753632255=BTC-USD29004=2.208895519560=20250411-01:22:48.36761640=137=5da31fd4-927c-463f-8754-5bb12e00d5fb10=085
20250411-01:22:48.482418000 : 8=FIXT.1.19=32535=X49=Coinbase56=24ab46f784d1b20db435b852086e325034=3150=TEST52=20250411-01:22:48.368865369=2262=f3031983-3333-44e4-810f-7a389c7706e2268=1279=0269=2278=c5b88ea9-605d-4595-ac52-f7c3f08523ba83=159753632355=BTC-USD270=3.55271=0.6222240960=20250411-01:22:48.36761637=5da31fd4-927c-463f-8754-5bb12e00d5fb5797=110=230
20250411-01:22:48.482821000 : 8=FIXT.1.19=26435=X49=Coinbase56=24ab46f784d1b20db435b852086e325034=3250=TEST52=20250411-01:22:48.368869369=2262=f3031983-3333-44e4-810f-7a389c7706e2268=1279=2269=0278=5da31fd4-927c-463f-8754-5bb12e00d5fb83=159753632455=BTC-USD60=20250411-01:22:48.36761658=FILLED10=103
20250411-01:22:48.508694000 : 8=FIXT.1.19=27335=X49=Coinbase56=24ab46f784d1b20db435b852086e325034=3350=TEST52=20250411-01:22:48.397168369=2262=f3031983-3333-44e4-810f-7a389c7706e2268=1279=0269=183=159753632555=BTC-USD271=0.6197183160=20250411-01:22:48.39526340=137=2665b512-1217-4a64-8e30-6e720a57206610=036
20250411-01:22:48.509193000 : 8=FIXT.1.19=32535=X49=Coinbase56=24ab46f784d1b20db435b852086e325034=3450=TEST52=20250411-01:22:48.397178369=2262=f3031983-3333-44e4-810f-7a389c7706e2268=1279=0269=2278=4d60a78e-b39b-420e-b830-bc0f3f4fdde283=159753632655=BTC-USD270=3.53271=0.6197183160=20250411-01:22:48.39526337=2665b512-1217-4a64-8e30-6e720a5720665797=210=026
20250411-01:22:48.509608000 : 8=FIXT.1.19=27935=X49=Coinbase56=24ab46f784d1b20db435b852086e325034=3550=TEST52=20250411-01:22:48.397182369=2262=f3031983-3333-44e4-810f-7a389c7706e2268=1279=2269=1278=2665b512-1217-4a64-8e30-6e720a57206683=159753632755=BTC-USD271=0.0000000060=20250411-01:22:48.39526358=FILLED10=199
20250411-01:22:48.659011000 : 8=FIXT.1.19=28235=X49=Coinbase56=24ab46f784d1b20db435b852086e325034=3650=TEST52=20250411-01:22:48.547137369=2262=f3031983-3333-44e4-810f-7a389c7706e2268=1279=0269=083=159753632855=BTC-USD270=3.48271=0.6232294660=20250411-01:22:48.54590840=237=453b87ac-2fb9-4b80-a79a-407cefcb928c10=138
20250411-01:22:48.659634000 : 8=FIXT.1.19=27835=X49=Coinbase56=24ab46f784d1b20db435b852086e325034=3750=TEST52=20250411-01:22:48.547145369=2262=f3031983-3333-44e4-810f-7a389c7706e2268=1279=0269=0278=453b87ac-2fb9-4b80-a79a-407cefcb928c83=159753632955=BTC-USD270=3.48271=0.6232294660=20250411-01:22:48.54590810=243
20250411-01:22:49.015383000 : 8=FIXT.1.19=28235=X49=Coinbase56=24ab46f784d1b20db435b852086e325034=3850=TEST52=20250411-01:22:48.901529369=2262=f3031983-3333-44e4-810f-7a389c7706e2268=1279=0269=083=159753633055=BTC-USD270=3.76271=0.6232294660=20250411-01:22:48.89970340=237=3a5f0c21-8a54-4602-b566-c8535840defc10=190
20250411-01:22:49.015857000 : 8=FIXT.1.19=32535=X49=Coinbase56=24ab46f784d1b20db435b852086e325034=3950=TEST52=20250411-01:22:48.901541369=2262=f3031983-3333-44e4-810f-7a389c7706e2268=1279=0269=2278=c5b88ea9-605d-4595-ac52-f7c3f08523ba83=159753633155=BTC-USD270=3.55271=0.6232294660=20250411-01:22:48.89970337=3a5f0c21-8a54-4602-b566-c8535840defc5797=110=137
20250411-01:22:49.017163000 : 8=FIXT.1.19=28835=X49=Coinbase56=24ab46f784d1b20db435b852086e325034=4050=TEST52=20250411-01:22:48.901545369=2262=f3031983-3333-44e4-810f-7a389c7706e2268=1279=2269=0278=3a5f0c21-8a54-4602-b566-c8535840defc83=159753633255=BTC-USD270=3.76271=0.0000000060=20250411-01:22:48.89970358=FILLED10=091
20250411-01:22:49.067496000 : 8=FIXT.1.19=28235=X49=Coinbase56=24ab46f784d1b20db435b852086e325034=4150=TEST52=20250411-01:22:48.956117369=2262=f3031983-3333-44e4-810f-7a389c7706e2268=1279=0269=183=159753633355=BTC-USD270=3.23271=0.6232294660=20250411-01:22:48.95420740=237=3d3c6482-186c-4069-a1ca-ac8441afa0ba10=046
20250411-01:22:49.068037000 : 8=FIXT.1.19=32535=X49=Coinbase56=24ab46f784d1b20db435b852086e325034=4250=TEST52=20250411-01:22:48.956126369=2262=f3031983-3333-44e4-810f-7a389c7706e2268=1279=0269=2278=4d60a78e-b39b-420e-b830-bc0f3f4fdde283=159753633455=BTC-USD270=3.53271=0.6232294660=20250411-01:22:48.95420737=3d3c6482-186c-4069-a1ca-ac8441afa0ba5797=210=133
20250411-01:22:49.068283000 : 8=FIXT.1.19=28835=X49=Coinbase56=24ab46f784d1b20db435b852086e325034=4350=TEST52=20250411-01:22:48.956130369=2262=f3031983-3333-44e4-810f-7a389c7706e2268=1279=2269=1278=3d3c6482-186c-4069-a1ca-ac8441afa0ba83=159753633555=BTC-USD270=3.23271=0.0000000060=20250411-01:22:48.95420758=FILLED10=209
20250411-01:22:49.222932000 : 8=FIXT.1.19=27735=X49=Coinbase56=24ab46f784d1b20db435b852086e325034=4450=TEST52=20250411-01:22:49.111427369=2262=f3031983-3333-44e4-810f-7a389c7706e2268=1279=0269=083=159753633655=BTC-USD29004=2.208895519560=20250411-01:22:49.11004640=137=728ac69f-8095-499a-bb24-0a44abdf543310=018
20250411-01:22:49.223441000 : 8=FIXT.1.19=32535=X49=Coinbase56=24ab46f784d1b20db435b852086e325034=4550=TEST52=20250411-01:22:49.111490369=2262=f3031983-3333-44e4-810f-7a389c7706e2268=1279=0269=2278=c5b88ea9-605d-4595-ac52-f7c3f08523ba83=159753633755=BTC-USD270=3.55271=0.6222240960=20250411-01:22:49.11004637=728ac69f-8095-499a-bb24-0a44abdf54335797=110=165
20250411-01:22:49.224934000 : 8=FIXT.1.19=26435=X49=Coinbase56=24ab46f784d1b20db435b852086e325034=4650=TEST52=20250411-01:22:49.111496369=2262=f3031983-3333-44e4-810f-7a389c7706e2268=1279=2269=0278=728ac69f-8095-499a-bb24-0a44abdf543383=159753633855=BTC-USD60=20250411-01:22:49.11004658=FILLED10=040
20250411-01:22:49.229125000 : 8=FIXT.1.19=28235=X49=Coinbase56=24ab46f784d1b20db435b852086e325034=4750=TEST52=20250411-01:22:49.118312369=2262=f3031983-3333-44e4-810f-7a389c7706e2268=1279=0269=183=159753633955=BTC-USD270=3.54271=0.6232294660=20250411-01:22:49.11751340=237=f7badc2b-eddc-4e47-a81a-2f6fd677458f10=011
20250411-01:22:49.229314000 : 8=FIXT.1.19=27835=X49=Coinbase56=24ab46f784d1b20db435b852086e325034=4850=TEST52=20250411-01:22:49.118318369=2262=f3031983-3333-44e4-810f-7a389c7706e2268=1279=0269=1278=f7badc2b-eddc-4e47-a81a-2f6fd677458f83=159753634055=BTC-USD270=3.54271=0.6232294660=20250411-01:22:49.11751310=114
20250411-01:22:49.251619000 : 8=FIXT.1.19=27335=X49=Coinbase56=24ab46f784d1b20db435b852086e325034=4950=TEST52=20250411-01:22:49.140073369=2262=f3031983-3333-44e4-810f-7a389c7706e2268=1279=0269=183=159753634155=BTC-USD271=0.6232294660=20250411-01:22:49.13828240=137=fb4a4b0c-6bdb-40bf-adaa-d5cd907145fa10=164
20250411-01:22:49.252000000 : 8=FIXT.1.19=32535=X49=Coinbase56=24ab46f784d1b20db435b852086e325034=5050=TEST52=20250411-01:22:49.140084369=2262=f3031983-3333-44e4-810f-7a389c7706e2268=1279=0269=2278=4d60a78e-b39b-420e-b830-bc0f3f4fdde283=159753634255=BTC-USD270=3.53271=0.6232294660=20250411-01:22:49.13828237=fb4a4b0c-6bdb-40bf-adaa-d5cd907145fa5797=210=146
20250411-01:22:49.252160000 : 8=FIXT.1.19=27935=X49=Coinbase56=24ab46f784d1b20db435b852086e325034=5150=TEST52=20250411-01:22:49.140088369=2262=f3031983-3333-44e4-810f-7a389c7706e2268=1279=2269=1278=fb4a4b0c-6bdb-40bf-adaa-d5cd907145fa83=159753634355=BTC-USD271=0.0000000060=20250411-01:22:49.13828258=FILLED10=074
20250411-01:22:49.513031000 : 8=FIXT.1.19=30135=X49=Coinbase56=24ab46f784d1b20db435b852086e325034=5250=TEST52=20250411-01:22:49.402004369=2262=f3031983-3333-44e4-810f-7a389c7706e2268=1279=0269=083=159753634455=BTC-USD270=3.41271=0.6243212629004=2.128935496660=20250411-01:22:49.40088840=237=47fc61dd-ef0a-4d3d-bd97-19672e4fc7e910=075
20250411-01:22:49.513465000 : 8=FIXT.1.19=27835=X49=Coinbase56=24ab46f784d1b20db435b852086e325034=5350=TEST52=20250411-01:22:49.402010369=2262=f3031983-3333-44e4-810f-7a389c7706e2268=1279=0269=0278=47fc61dd-ef0a-4d3d-bd97-19672e4fc7e983=159753634555=BTC-USD270=3.41271=0.6243212660=20250411-01:22:49.40088810=008
20250411-01:22:49.786467000 : 8=FIXT.1.19=8335=534=349=24ab46f784d1b20db435b852086e325052=20250411-01:22:49.78556=Coinbase10=122
20250411-01:22:50.014645000 : 8=FIXT.1.19=11835=549=Coinbase56=24ab46f784d1b20db435b852086e325034=5450=TEST52=20250411-01:22:49.903079369=258=CLIENT_LOGOUT10=015
20250411-01:23:22.664140000 : 8=FIXT.1.19=21535=A34=149=24ab46f784d1b20db435b852086e325052=20250411-01:23:22.65056=Coinbase95=4496=FgHniNPgVFP8E/GKoHKlh88lGLd6e44mZnZ1aqIBpxA=98=0108=30141=Y553=24ab46f784d1b20db435b852086e3250554=akmwnltyfgb1137=910=150
20250411-01:23:22.923887000 : 8=FIXT.1.19=12535=A49=Coinbase56=24ab46f784d1b20db435b852086e325034=150=TEST52=20250411-01:23:22.807692369=198=0108=30141=Y1137=910=194
20250411-01:23:23.945134000 : 8=FIXT.1.19=17835=V34=249=24ab46f784d1b20db435b852086e325052=20250411-01:23:23.94456=Coinbase1128=9146=155=BTC-USD262=1850cf72-9acb-441d-8b46-896f97af82d2263=1264=0267=2269=0269=110=030
20250411-01:23:24.309579000 : 8=FIXT.1.19=27635=X49=Coinbase56=24ab46f784d1b20db435b852086e325034=250=TEST52=20250411-01:23:24.199509369=2262=1850cf72-9acb-441d-8b46-896f97af82d2268=1279=0269=083=159753693855=BTC-USD29004=2.208895519560=20250411-01:23:24.19767840=137=a715e638-8f1e-42e1-b594-c0d5315e46a010=198
20250411-01:23:24.310522000 : 8=FIXT.1.19=32435=X49=Coinbase56=24ab46f784d1b20db435b852086e325034=350=TEST52=20250411-01:23:24.199570369=2262=1850cf72-9acb-441d-8b46-896f97af82d2268=1279=0269=2278=c5b88ea9-605d-4595-ac52-f7c3f08523ba83=159753693955=BTC-USD270=3.55271=0.6222240960=20250411-01:23:24.19767837=a715e638-8f1e-42e1-b594-c0d5315e46a05797=110=087
20250411-01:23:24.313316000 : 8=FIXT.1.19=26335=X49=Coinbase56=24ab46f784d1b20db435b852086e325034=450=TEST52=20250411-01:23:24.199576369=2262=1850cf72-9acb-441d-8b46-896f97af82d2268=1279=2269=0278=a715e638-8f1e-42e1-b594-c0d5315e46a083=159753694055=BTC-USD60=20250411-01:23:24.19767858=FILLED10=209
20250411-01:23:24.339581000 : 8=FIXT.1.19=27235=X49=Coinbase56=24ab46f784d1b20db435b852086e325034=550=TEST52=20250411-01:23:24.228409369=2262=1850cf72-9acb-441d-8b46-896f97af82d2268=1279=0269=183=159753694155=BTC-USD271=0.6232294660=20250411-01:23:24.22668240=137=cbe3c72d-b02a-43f7-a802-3c9a95e2c03410=086
20250411-01:23:24.340122000 : 8=FIXT.1.19=32435=X49=Coinbase56=24ab46f784d1b20db435b852086e325034=650=TEST52=20250411-01:23:24.228420369=2262=1850cf72-9acb-441d-8b46-896f97af82d2268=1279=0269=2278=4d60a78e-b39b-420e-b830-bc0f3f4fdde283=159753694255=BTC-USD270=3.53271=0.6232294660=20250411-01:23:24.22668237=cbe3c72d-b02a-43f7-a802-3c9a95e2c0345797=210=068
20250411-01:23:24.340853000 : 8=FIXT.1.19=27835=X49=Coinbase56=24ab46f784d1b20db435b852086e325034=750=TEST52=20250411-01:23:24.228423369=2262=1850cf72-9acb-441d-8b46-896f97af82d2268=1279=2269=1278=cbe3c72d-b02a-43f7-a802-3c9a95e2c03483=159753694355=BTC-USD271=0.0000000060=20250411-01:23:24.22668258=FILLED10=251
20250411-01:23:24.424038000 : 8=FIXT.1.19=27635=X49=Coinbase56=24ab46f784d1b20db435b852086e325034=850=TEST52=20250411-01:23:24.313849369=2262=1850cf72-9acb-441d-8b46-896f97af82d2268=1279=0269=083=159753694455=BTC-USD29004=2.208895519560=20250411-01:23:24.31225340=137=76db53b8-2a94-4f42-b164-7b03c6b493f710=183
20250411-01:23:24.426031000 : 8=FIXT.1.19=32435=X49=Coinbase56=24ab46f784d1b20db435b852086e325034=950=TEST52=20250411-01:23:24.313856369=2262=1850cf72-9acb-441d-8b46-896f97af82d2268=1279=0269=2278=c5b88ea9-605d-4595-ac52-f7c3f08523ba83=159753694555=BTC-USD270=3.55271=0.6222240960=20250411-01:23:24.31225337=76db53b8-2a94-4f42-b164-7b03c6b493f75797=110=072
20250411-01:23:24.426471000 : 8=FIXT.1.19=26435=X49=Coinbase56=24ab46f784d1b20db435b852086e325034=1050=TEST52=20250411-01:23:24.313859369=2262=1850cf72-9acb-441d-8b46-896f97af82d2268=1279=2269=0278=76db53b8-2a94-4f42-b164-7b03c6b493f783=159753694655=BTC-USD60=20250411-01:23:24.31225358=FILLED10=240
20250411-01:23:24.453690000 : 8=FIXT.1.19=27335=X49=Coinbase56=24ab46f784d1b20db435b852086e325034=1150=TEST52=20250411-01:23:24.342518369=2262=1850cf72-9acb-441d-8b46-896f97af82d2268=1279=0269=183=159753694755=BTC-USD271=0.6232294660=20250411-01:23:24.34068040=137=9f615b9d-a013-4fde-a00e-e57eb1c53f5d10=238
20250411-01:23:24.455745000 : 8=FIXT.1.19=32535=X49=Coinbase56=24ab46f784d1b20db435b852086e325034=1250=TEST52=20250411-01:23:24.342528369=2262=1850cf72-9acb-441d-8b46-896f97af82d2268=1279=0269=2278=4d60a78e-b39b-420e-b830-bc0f3f4fdde283=159753694855=BTC-USD270=3.53271=0.6232294660=20250411-01:23:24.34068037=9f615b9d-a013-4fde-a00e-e57eb1c53f5d5797=210=228
20250411-01:23:24.456342000 : 8=FIXT.1.19=27935=X49=Coinbase56=24ab46f784d1b20db435b852086e325034=1350=TEST52=20250411-01:23:24.342530369=2262=1850cf72-9acb-441d-8b46-896f97af82d2268=1279=2269=1278=9f615b9d-a013-4fde-a00e-e57eb1c53f5d83=159753694955=BTC-USD271=0.0000000060=20250411-01:23:24.34068058=FILLED10=145
20250411-01:23:24.728462000 : 8=FIXT.1.19=28235=X49=Coinbase56=24ab46f784d1b20db435b852086e325034=1450=TEST52=20250411-01:23:24.618422369=2262=1850cf72-9acb-441d-8b46-896f97af82d2268=1279=0269=083=159753695055=BTC-USD270=3.86271=0.6232294660=20250411-01:23:24.61663140=237=4e9e8d07-5c64-4f1a-9e35-d7694976e4b710=204
20250411-01:23:24.728963000 : 8=FIXT.1.19=32535=X49=Coinbase56=24ab46f784d1b20db435b852086e325034=1550=TEST52=20250411-01:23:24.618436369=2262=1850cf72-9acb-441d-8b46-896f97af82d2268=1279=0269=2278=c5b88ea9-605d-4595-ac52-f7c3f08523ba83=159753695155=BTC-USD270=3.55271=0.6232294660=20250411-01:23:24.61663137=4e9e8d07-5c64-4f1a-9e35-d7694976e4b75797=110=161
20250411-01:23:24.729222000 : 8=FIXT.1.19=28835=X49=Coinbase56=24ab46f784d1b20db435b852086e325034=1650=TEST52=20250411-01:23:24.618439369=2262=1850cf72-9acb-441d-8b46-896f97af82d2268=1279=2269=0278=4e9e8d07-5c64-4f1a-9e35-d7694976e4b783=159753695255=BTC-USD270=3.86271=0.0000000060=20250411-01:23:24.61663158=FILLED10=124
20250411-01:23:24.783669000 : 8=FIXT.1.19=28135=X49=Coinbase56=24ab46f784d1b20db435b852086e325034=1750=TEST52=20250411-01:23:24.673868369=2262=1850cf72-9acb-441d-8b46-896f97af82d2268=1279=0269=183=159753695355=BTC-USD270=3.2271=0.6232294660=20250411-01:23:24.67221940=237=59616a49-8353-452b-88c5-1306939ee7e010=219
20250411-01:23:24.784183000 : 8=FIXT.1.19=32535=X49=Coinbase56=24ab46f784d1b20db435b852086e325034=1850=TEST52=20250411-01:23:24.673874369=2262=1850cf72-9acb-441d-8b46-896f97af82d2268=1279=0269=2278=4d60a78e-b39b-420e-b830-bc0f3f4fdde283=159753695455=BTC-USD270=3.53271=0.6232294660=20250411-01:23:24.67221937=59616a49-8353-452b-88c5-1306939ee7e05797=210=099
20250411-01:23:24.784437000 : 8=FIXT.1.19=28735=X49=Coinbase56=24ab46f784d1b20db435b852086e325034=1950=TEST52=20250411-01:23:24.673887369=2262=1850cf72-9acb-441d-8b46-896f97af82d2268=1279=2269=1278=59616a49-8353-452b-88c5-1306939ee7e083=159753695555=BTC-USD270=3.2271=0.0000000060=20250411-01:23:24.67221958=FILLED10=132
20250411-01:23:25.115515000 : 8=FIXT.1.19=27735=X49=Coinbase56=24ab46f784d1b20db435b852086e325034=2050=TEST52=20250411-01:23:25.000310369=2262=1850cf72-9acb-441d-8b46-896f97af82d2268=1279=0269=083=159753695655=BTC-USD29004=2.208895519560=20250411-01:23:24.99874240=137=8329532b-a84d-4a88-9d8e-1fd2bf51591210=237
20250411-01:23:25.116051000 : 8=FIXT.1.19=32535=X49=Coinbase56=24ab46f784d1b20db435b852086e325034=2150=TEST52=20250411-01:23:25.000323369=2262=1850cf72-9acb-441d-8b46-896f97af82d2268=1279=0269=2278=c5b88ea9-605d-4595-ac52-f7c3f08523ba83=159753695755=BTC-USD270=3.55271=0.6222240960=20250411-01:23:24.99874237=8329532b-a84d-4a88-9d8e-1fd2bf5159125797=110=132
20250411-01:23:25.116330000 : 8=FIXT.1.19=26435=X49=Coinbase56=24ab46f784d1b20db435b852086e325034=2250=TEST52=20250411-01:23:25.000325369=2262=1850cf72-9acb-441d-8b46-896f97af82d2268=1279=2269=0278=8329532b-a84d-4a88-9d8e-1fd2bf51591283=159753695855=BTC-USD60=20250411-01:23:24.99874258=FILLED10=003
20250411-01:23:25.138334000 : 8=FIXT.1.19=27335=X49=Coinbase56=24ab46f784d1b20db435b852086e325034=2350=TEST52=20250411-01:23:25.027559369=2262=1850cf72-9acb-441d-8b46-896f97af82d2268=1279=0269=183=159753695955=BTC-USD271=0.6232294660=20250411-01:23:25.02609940=137=8facfaea-b61e-40b0-90d0-d70dfa92641010=241
20250411-01:23:25.138791000 : 8=FIXT.1.19=32535=X49=Coinbase56=24ab46f784d1b20db435b852086e325034=2450=TEST52=20250411-01:23:25.027569369=2262=1850cf72-9acb-441d-8b46-896f97af82d2268=1279=0269=2278=4d60a78e-b39b-420e-b830-bc0f3f4fdde283=159753696055=BTC-USD270=3.53271=0.6232294660=20250411-01:23:25.02609937=8facfaea-b61e-40b0-90d0-d70dfa9264105797=210=222
20250411-01:23:25.139103000 : 8=FIXT.1.19=27935=X49=Coinbase56=24ab46f784d1b20db435b852086e325034=2550=TEST52=20250411-01:23:25.027573369=2262=1850cf72-9acb-441d-8b46-896f97af82d2268=1279=2269=1278=8facfaea-b61e-40b0-90d0-d70dfa92641083=159753696155=BTC-USD271=0.0000000060=20250411-01:23:25.02609958=FILLED10=141
20250411-01:23:25.339169000 : 8=FIXT.1.19=27735=X49=Coinbase56=24ab46f784d1b20db435b852086e325034=2650=TEST52=20250411-01:23:25.228132369=2262=1850cf72-9acb-441d-8b46-896f97af82d2268=1279=0269=083=159753696255=BTC-USD29004=2.208895519560=20250411-01:23:25.22601040=137=2cfa1c8c-dbe6-4b97-ad07-7ec20fc7bc4610=035
20250411-01:23:25.340465000 : 8=FIXT.1.19=32535=X49=Coinbase56=24ab46f784d1b20db435b852086e325034=2750=TEST52=20250411-01:23:25.228140369=2262=1850cf72-9acb-441d-8b46-896f97af82d2268=1279=0269=2278=c5b88ea9-605d-4595-ac52-f7c3f08523ba83=159753696355=BTC-USD270=3.55271=0.6222240960=20250411-01:23:25.22601037=2cfa1c8c-dbe6-4b97-ad07-7ec20fc7bc465797=110=181
20250411-01:23:25.340726000 : 8=FIXT.1.19=26435=X49=Coinbase56=24ab46f784d1b20db435b852086e325034=2850=TEST52=20250411-01:23:25.228145369=2262=1850cf72-9acb-441d-8b46-896f97af82d2268=1279=2269=0278=2cfa1c8c-dbe6-4b97-ad07-7ec20fc7bc4683=159753696455=BTC-USD60=20250411-01:23:25.22601058=FILLED10=055
20250411-01:23:25.368030000 : 8=FIXT.1.19=27335=X49=Coinbase56=24ab46f784d1b20db435b852086e325034=2950=TEST52=20250411-01:23:25.257089369=2262=1850cf72-9acb-441d-8b46-896f97af82d2268=1279=0269=183=159753696555=BTC-USD271=0.6232294660=20250411-01:23:25.25553040=137=b9124c5c-e627-4a5e-92f9-a763f442116610=238
20250411-01:23:25.368458000 : 8=FIXT.1.19=32535=X49=Coinbase56=24ab46f784d1b20db435b852086e325034=3050=TEST52=20250411-01:23:25.257161369=2262=1850cf72-9acb-441d-8b46-896f97af82d2268=1279=0269=2278=4d60a78e-b39b-420e-b830-bc0f3f4fdde283=159753696655=BTC-USD270=3.53271=0.6232294660=20250411-01:23:25.25553037=b9124c5c-e627-4a5e-92f9-a763f44211665797=210=209
20250411-01:23:25.368873000 : 8=FIXT.1.19=27935=X49=Coinbase56=24ab46f784d1b20db435b852086e325034=3150=TEST52=20250411-01:23:25.257163369=2262=1850cf72-9acb-441d-8b46-896f97af82d2268=1279=2269=1278=b9124c5c-e627-4a5e-92f9-a763f442116683=159753696755=BTC-USD271=0.0000000060=20250411-01:23:25.25553058=FILLED10=135
20250411-01:23:25.798029000 : 8=FIXT.1.19=29035=X49=Coinbase56=24ab46f784d1b20db435b852086e325034=3250=TEST52=20250411-01:23:25.687650369=2262=1850cf72-9acb-441d-8b46-896f97af82d2268=1279=2269=1278=c4b888f5-6011-4465-80b6-7ef02142f38983=159753696855=BTC-USD270=3.55271=0.6232294660=20250411-01:23:25.68578458=CANCELED10=130
20250411-01:23:25.983124000 : 8=FIXT.1.19=30635=X49=Coinbase56=24ab46f784d1b20db435b852086e325034=3350=TEST52=20250411-01:23:25.872857369=2262=1850cf72-9acb-441d-8b46-896f97af82d2268=1279=1269=1278=c3f8c9d3-1e7a-4b3f-9abb-d8966560465f83=159753696955=BTC-USD270=3.6271=0.599300760=20250411-01:23:25.87077858=CHANGE_REASON_MODIFY_ORDER10=231
20250411-01:23:26.081840000 : 8=FIXT.1.19=27735=X49=Coinbase56=24ab46f784d1b20db435b852086e325034=3450=TEST52=20250411-01:23:25.970991369=2262=1850cf72-9acb-441d-8b46-896f97af82d2268=1279=0269=083=159753697055=BTC-USD29004=2.208895519560=20250411-01:23:25.96956740=137=e7d4f900-9f80-432e-a7cf-4e3be7fa2ead10=041
20250411-01:23:26.082226000 : 8=FIXT.1.19=32535=X49=Coinbase56=24ab46f784d1b20db435b852086e325034=3550=TEST52=20250411-01:23:25.971128369=2262=1850cf72-9acb-441d-8b46-896f97af82d2268=1279=0269=2278=c5b88ea9-605d-4595-ac52-f7c3f08523ba83=159753697155=BTC-USD270=3.55271=0.6222240960=20250411-01:23:25.96956737=e7d4f900-9f80-432e-a7cf-4e3be7fa2ead5797=110=181
20250411-01:23:26.082631000 : 8=FIXT.1.19=26435=X49=Coinbase56=24ab46f784d1b20db435b852086e325034=3650=TEST52=20250411-01:23:25.971131369=2262=1850cf72-9acb-441d-8b46-896f97af82d2268=1279=2269=0278=e7d4f900-9f80-432e-a7cf-4e3be7fa2ead83=159753697255=BTC-USD60=20250411-01:23:25.96956758=FILLED10=044
20250411-01:23:26.084583000 : 8=FIXT.1.19=29035=X49=Coinbase56=24ab46f784d1b20db435b852086e325034=3750=TEST52=20250411-01:23:25.973640369=2262=1850cf72-9acb-441d-8b46-896f97af82d2268=1279=2269=0278=47fc61dd-ef0a-4d3d-bd97-19672e4fc7e983=159753697355=BTC-USD270=3.41271=0.6243212660=20250411-01:23:25.97191958=CANCELED10=248
20250411-01:23:26.085791000 : 8=FIXT.1.19=28235=X49=Coinbase56=24ab46f784d1b20db435b852086e325034=3850=TEST52=20250411-01:23:25.976400369=2262=1850cf72-9acb-441d-8b46-896f97af82d2268=1279=0269=183=159753697455=BTC-USD270=3.69271=0.6232294660=20250411-01:23:25.97488740=237=de706bf6-2c13-4238-abe2-7377bd3c9ba610=093
20250411-01:23:26.086001000 : 8=FIXT.1.19=27835=X49=Coinbase56=24ab46f784d1b20db435b852086e325034=3950=TEST52=20250411-01:23:25.976406369=2262=1850cf72-9acb-441d-8b46-896f97af82d2268=1279=0269=1278=de706bf6-2c13-4238-abe2-7377bd3c9ba683=159753697555=BTC-USD270=3.69271=0.6232294660=20250411-01:23:25.97488710=205
20250411-01:23:26.126999000 : 8=FIXT.1.19=27335=X49=Coinbase56=24ab46f784d1b20db435b852086e325034=4050=TEST52=20250411-01:23:26.001695369=2262=1850cf72-9acb-441d-8b46-896f97af82d2268=1279=0269=183=159753697655=BTC-USD271=0.6232294660=20250411-01:23:25.99990440=137=92c64b96-cdfa-47ee-9c6e-99b3c13ddcfe10=130
20250411-01:23:26.139406000 : 8=FIXT.1.19=32535=X49=Coinbase56=24ab46f784d1b20db435b852086e325034=4150=TEST52=20250411-01:23:26.001708369=2262=1850cf72-9acb-441d-8b46-896f97af82d2268=1279=0269=2278=4d60a78e-b39b-420e-b830-bc0f3f4fdde283=159753697755=BTC-USD270=3.53271=0.6232294660=20250411-01:23:25.99990437=92c64b96-cdfa-47ee-9c6e-99b3c13ddcfe5797=210=114
20250411-01:23:26.140109000 : 8=FIXT.1.19=27935=X49=Coinbase56=24ab46f784d1b20db435b852086e325034=4250=TEST52=20250411-01:23:26.001713369=2262=1850cf72-9acb-441d-8b46-896f97af82d2268=1279=2269=1278=92c64b96-cdfa-47ee-9c6e-99b3c13ddcfe83=159753697855=BTC-USD271=0.0000000060=20250411-01:23:25.99990458=FILLED10=034
20250411-01:23:26.267128000 : 8=FIXT.1.19=30835=X49=Coinbase56=24ab46f784d1b20db435b852086e325034=4350=TEST52=20250411-01:23:26.156437369=2262=1850cf72-9acb-441d-8b46-896f97af82d2268=1279=1269=0278=fa3dd227-6bee-44a4-aa1e-e296b7fa77d883=159753697955=BTC-USD270=3.52271=0.6027561860=20250411-01:23:26.15334158=CHANGE_REASON_MODIFY_ORDER10=177
20250411-01:23:26.368731000 : 8=FIXT.1.19=28935=X49=Coinbase56=24ab46f784d1b20db435b852086e325034=4450=TEST52=20250411-01:23:26.258389369=2262=1850cf72-9acb-441d-8b46-896f97af82d2268=1279=2269=0278=07d64586-4cc9-4f25-aa1a-db6da053497c83=159753698055=BTC-USD270=3.4271=0.6232294660=20250411-01:23:26.25732658=CANCELED10=044
20250411-01:23:26.370450000 : 8=FIXT.1.19=28235=X49=Coinbase56=24ab46f784d1b20db435b852086e325034=4550=TEST52=20250411-01:23:26.260030369=2262=1850cf72-9acb-441d-8b46-896f97af82d2268=1279=0269=083=159753698155=BTC-USD270=3.41271=0.6232294660=20250411-01:23:26.25890440=237=080102f1-f1e9-4669-913f-f2efc20ea8f310=214
20250411-01:23:26.370795000 : 8=FIXT.1.19=27835=X49=Coinbase56=24ab46f784d1b20db435b852086e325034=4650=TEST52=20250411-01:23:26.260036369=2262=1850cf72-9acb-441d-8b46-896f97af82d2268=1279=0269=0278=080102f1-f1e9-4669-913f-f2efc20ea8f383=159753698255=BTC-USD270=3.41271=0.6232294660=20250411-01:23:26.25890410=070
20250411-01:23:26.423960000 : 8=FIXT.1.19=27735=X49=Coinbase56=24ab46f784d1b20db435b852086e325034=4750=TEST52=20250411-01:23:26.313703369=2262=1850cf72-9acb-441d-8b46-896f97af82d2268=1279=0269=083=159753698355=BTC-USD29004=2.208895519560=20250411-01:23:26.31236940=137=761d256a-c5e3-4f0f-aedd-364316343e6010=019
20250411-01:23:26.424421000 : 8=FIXT.1.19=32535=X49=Coinbase56=24ab46f784d1b20db435b852086e325034=4850=TEST52=20250411-01:23:26.313710369=2262=1850cf72-9acb-441d-8b46-896f97af82d2268=1279=0269=2278=c5b88ea9-605d-4595-ac52-f7c3f08523ba83=159753698455=BTC-USD270=3.55271=0.6222240960=20250411-01:23:26.31236937=761d256a-c5e3-4f0f-aedd-364316343e605797=110=164
20250411-01:23:26.424776000 : 8=FIXT.1.19=26435=X49=Coinbase56=24ab46f784d1b20db435b852086e325034=4950=TEST52=20250411-01:23:26.313714369=2262=1850cf72-9acb-441d-8b46-896f97af82d2268=1279=2269=0278=761d256a-c5e3-4f0f-aedd-364316343e6083=159753698555=BTC-USD60=20250411-01:23:26.31236958=FILLED10=037
20250411-01:23:26.453066000 : 8=FIXT.1.19=27335=X49=Coinbase56=24ab46f784d1b20db435b852086e325034=5050=TEST52=20250411-01:23:26.342649369=2262=1850cf72-9acb-441d-8b46-896f97af82d2268=1279=0269=183=159753698655=BTC-USD271=0.6232294660=20250411-01:23:26.34086240=137=5bcd85bb-9abf-40c9-9c49-ca96995136c410=185
20250411-01:23:26.453595000 : 8=FIXT.1.19=32535=X49=Coinbase56=24ab46f784d1b20db435b852086e325034=5150=TEST52=20250411-01:23:26.342656369=2262=1850cf72-9acb-441d-8b46-896f97af82d2268=1279=0269=2278=4d60a78e-b39b-420e-b830-bc0f3f4fdde283=159753698755=BTC-USD270=3.53271=0.6232294660=20250411-01:23:26.34086237=5bcd85bb-9abf-40c9-9c49-ca96995136c45797=210=172
20250411-01:23:26.453936000 : 8=FIXT.1.19=27935=X49=Coinbase56=24ab46f784d1b20db435b852086e325034=5250=TEST52=20250411-01:23:26.342658369=2262=1850cf72-9acb-441d-8b46-896f97af82d2268=1279=2269=1278=5bcd85bb-9abf-40c9-9c49-ca96995136c483=159753698855=BTC-USD271=0.0000000060=20250411-01:23:26.34086258=FILLED10=098
20250411-01:23:26.539019000 : 8=FIXT.1.19=27735=X49=Coinbase56=24ab46f784d1b20db435b852086e325034=5350=TEST52=20250411-01:23:26.428832369=2262=1850cf72-9acb-441d-8b46-896f97af82d2268=1279=0269=083=159753698955=BTC-USD29004=2.208895519560=20250411-01:23:26.42707640=137=3d3150a6-794f-47af-b610-588e96bbdddb10=143
20250411-01:23:26.539444000 : 8=FIXT.1.19=32535=X49=Coinbase56=24ab46f784d1b20db435b852086e325034=5450=TEST52=20250411-01:23:26.428840369=2262=1850cf72-9acb-441d-8b46-896f97af82d2268=1279=0269=2278=c5b88ea9-605d-4595-ac52-f7c3f08523ba83=159753699055=BTC-USD270=3.55271=0.6222240960=20250411-01:23:26.42707637=3d3150a6-794f-47af-b610-588e96bbdddb5797=110=024
20250411-01:23:26.539717000 : 8=FIXT.1.19=26435=X49=Coinbase56=24ab46f784d1b20db435b852086e325034=5550=TEST52=20250411-01:23:26.428843369=2262=1850cf72-9acb-441d-8b46-896f97af82d2268=1279=2269=0278=3d3150a6-794f-47af-b610-588e96bbdddb83=159753699155=BTC-USD60=20250411-01:23:26.42707658=FILLED10=152
20250411-01:23:26.567670000 : 8=FIXT.1.19=27335=X49=Coinbase56=24ab46f784d1b20db435b852086e325034=5650=TEST52=20250411-01:23:26.457202369=2262=1850cf72-9acb-441d-8b46-896f97af82d2268=1279=0269=183=159753699255=BTC-USD271=0.6232294660=20250411-01:23:26.45519140=137=d2da02d5-02f9-4349-9085-9496cad3464610=189
20250411-01:23:26.568333000 : 8=FIXT.1.19=32535=X49=Coinbase56=24ab46f784d1b20db435b852086e325034=5750=TEST52=20250411-01:23:26.457208369=2262=1850cf72-9acb-441d-8b46-896f97af82d2268=1279=0269=2278=4d60a78e-b39b-420e-b830-bc0f3f4fdde283=159753699355=BTC-USD270=3.53271=0.6232294660=20250411-01:23:26.45519137=d2da02d5-02f9-4349-9085-9496cad346465797=210=184
20250411-01:23:26.568632000 : 8=FIXT.1.19=27935=X49=Coinbase56=24ab46f784d1b20db435b852086e325034=5850=TEST52=20250411-01:23:26.457211369=2262=1850cf72-9acb-441d-8b46-896f97af82d2268=1279=2269=1278=d2da02d5-02f9-4349-9085-9496cad3464683=159753699455=BTC-USD271=0.0000000060=20250411-01:23:26.45519158=FILLED10=102
20250411-01:23:26.881703000 : 8=FIXT.1.19=27735=X49=Coinbase56=24ab46f784d1b20db435b852086e325034=5950=TEST52=20250411-01:23:26.771319369=2262=1850cf72-9acb-441d-8b46-896f97af82d2268=1279=0269=083=159753699555=BTC-USD29004=2.208895519560=20250411-01:23:26.76996840=137=3e5d1b50-e040-4065-9c52-0fab2b3cae0010=076
20250411-01:23:26.882086000 : 8=FIXT.1.19=32535=X49=Coinbase56=24ab46f784d1b20db435b852086e325034=6050=TEST52=20250411-01:23:26.771325369=2262=1850cf72-9acb-441d-8b46-896f97af82d2268=1279=0269=2278=c5b88ea9-605d-4595-ac52-f7c3f08523ba83=159753699655=BTC-USD270=3.55271=0.6222240960=20250411-01:23:26.76996837=3e5d1b50-e040-4065-9c52-0fab2b3cae005797=110=211
20250411-01:23:26.882316000 : 8=FIXT.1.19=26435=X49=Coinbase56=24ab46f784d1b20db435b852086e325034=6150=TEST52=20250411-01:23:26.771329369=2262=1850cf72-9acb-441d-8b46-896f97af82d2268=1279=2269=0278=3e5d1b50-e040-4065-9c52-0fab2b3cae0083=159753699755=BTC-USD60=20250411-01:23:26.76996858=FILLED10=084
20250411-01:23:26.910300000 : 8=FIXT.1.19=27335=X49=Coinbase56=24ab46f784d1b20db435b852086e325034=6250=TEST52=20250411-01:23:26.799718369=2262=1850cf72-9acb-441d-8b46-896f97af82d2268=1279=0269=183=159753699855=BTC-USD271=0.6232294660=20250411-01:23:26.79808540=137=0b43cf8c-551c-4448-8ba7-c1215f88cfa810=154
20250411-01:23:26.910827000 : 8=FIXT.1.19=32535=X49=Coinbase56=24ab46f784d1b20db435b852086e325034=6350=TEST52=20250411-01:23:26.799724369=2262=1850cf72-9acb-441d-8b46-896f97af82d2268=1279=0269=2278=4d60a78e-b39b-420e-b830-bc0f3f4fdde283=159753699955=BTC-USD270=3.53271=0.6232294660=20250411-01:23:26.79808537=0b43cf8c-551c-4448-8ba7-c1215f88cfa85797=210=140
20250411-01:23:26.911099000 : 8=FIXT.1.19=27935=X49=Coinbase56=24ab46f784d1b20db435b852086e325034=6450=TEST52=20250411-01:23:26.799728369=2262=1850cf72-9acb-441d-8b46-896f97af82d2268=1279=2269=1278=0b43cf8c-551c-4448-8ba7-c1215f88cfa883=159753700055=BTC-USD271=0.0000000060=20250411-01:23:26.79808558=FILLED10=041
20250411-01:23:27.224005000 : 8=FIXT.1.19=27735=X49=Coinbase56=24ab46f784d1b20db435b852086e325034=6550=TEST52=20250411-01:23:27.112948369=2262=1850cf72-9acb-441d-8b46-896f97af82d2268=1279=0269=083=159753700155=BTC-USD29004=2.208895519560=20250411-01:23:27.11160640=137=016cad2d-3959-47cf-9557-9c9efc7a098a10=082
20250411-01:23:27.224517000 : 8=FIXT.1.19=32535=X49=Coinbase56=24ab46f784d1b20db435b852086e325034=6650=TEST52=20250411-01:23:27.112957369=2262=1850cf72-9acb-441d-8b46-896f97af82d2268=1279=0269=2278=c5b88ea9-605d-4595-ac52-f7c3f08523ba83=159753700255=BTC-USD270=3.55271=0.6222240960=20250411-01:23:27.11160637=016cad2d-3959-47cf-9557-9c9efc7a098a5797=110=229
20250411-01:23:27.224864000 : 8=FIXT.1.19=26435=X49=Coinbase56=24ab46f784d1b20db435b852086e325034=6750=TEST52=20250411-01:23:27.112960369=2262=1850cf72-9acb-441d-8b46-896f97af82d2268=1279=2269=0278=016cad2d-3959-47cf-9557-9c9efc7a098a83=159753700355=BTC-USD60=20250411-01:23:27.11160658=FILLED10=092
20250411-01:23:27.254572000 : 8=FIXT.1.19=27335=X49=Coinbase56=24ab46f784d1b20db435b852086e325034=6850=TEST52=20250411-01:23:27.143246369=2262=1850cf72-9acb-441d-8b46-896f97af82d2268=1279=0269=183=159753700455=BTC-USD271=0.6232294660=20250411-01:23:27.14153140=137=e0bf2bda-5980-4302-aa0f-e46a71ccfa6d10=009
20250411-01:23:27.254984000 : 8=FIXT.1.19=32535=X49=Coinbase56=24ab46f784d1b20db435b852086e325034=6950=TEST52=20250411-01:23:27.143258369=2262=1850cf72-9acb-441d-8b46-896f97af82d2268=1279=0269=2278=4d60a78e-b39b-420e-b830-bc0f3f4fdde283=159753700555=BTC-USD270=3.53271=0.6232294660=20250411-01:23:27.14153137=e0bf2bda-5980-4302-aa0f-e46a71ccfa6d5797=210=001
20250411-01:23:27.255412000 : 8=FIXT.1.19=27935=X49=Coinbase56=24ab46f784d1b20db435b852086e325034=7050=TEST52=20250411-01:23:27.143294369=2262=1850cf72-9acb-441d-8b46-896f97af82d2268=1279=2269=1278=e0bf2bda-5980-4302-aa0f-e46a71ccfa6d83=159753700655=BTC-USD271=0.0000000060=20250411-01:23:27.14153158=FILLED10=172
20250411-01:23:27.356793000 : 8=FIXT.1.19=28235=X49=Coinbase56=24ab46f784d1b20db435b852086e325034=7150=TEST52=20250411-01:23:27.245994369=2262=1850cf72-9acb-441d-8b46-896f97af82d2268=1279=0269=083=159753700755=BTC-USD270=3.71271=0.6232294660=20250411-01:23:27.24424840=237=69cbf939-774e-429b-b521-576406aad94e10=197
20250411-01:23:27.357410000 : 8=FIXT.1.19=32535=X49=Coinbase56=24ab46f784d1b20db435b852086e325034=7250=TEST52=20250411-01:23:27.246006369=2262=1850cf72-9acb-441d-8b46-896f97af82d2268=1279=0269=2278=c5b88ea9-605d-4595-ac52-f7c3f08523ba83=159753700855=BTC-USD270=3.55271=0.6232294660=20250411-01:23:27.24424837=69cbf939-774e-429b-b521-576406aad94e5797=110=140
20250411-01:23:27.357797000 : 8=FIXT.1.19=28835=X49=Coinbase56=24ab46f784d1b20db435b852086e325034=7350=TEST52=20250411-01:23:27.246010369=2262=1850cf72-9acb-441d-8b46-896f97af82d2268=1279=2269=0278=69cbf939-774e-429b-b521-576406aad94e83=159753700955=BTC-USD270=3.71271=0.0000000060=20250411-01:23:27.24424858=FILLED10=089
20250411-01:23:27.396168000 : 8=FIXT.1.19=27735=X49=Coinbase56=24ab46f784d1b20db435b852086e325034=7450=TEST52=20250411-01:23:27.286135369=2262=1850cf72-9acb-441d-8b46-896f97af82d2268=1279=0269=083=159753701055=BTC-USD29004=2.208895519560=20250411-01:23:27.28408440=137=bf2e56ec-02da-430e-a158-22c439a6bb4710=100
20250411-01:23:27.396479000 : 8=FIXT.1.19=32535=X49=Coinbase56=24ab46f784d1b20db435b852086e325034=7550=TEST52=20250411-01:23:27.286143369=2262=1850cf72-9acb-441d-8b46-896f97af82d2268=1279=0269=2278=c5b88ea9-605d-4595-ac52-f7c3f08523ba83=159753701155=BTC-USD270=3.55271=0.6222240960=20250411-01:23:27.28408437=bf2e56ec-02da-430e-a158-22c439a6bb475797=110=246
20250411-01:23:27.397133000 : 8=FIXT.1.19=26435=X49=Coinbase56=24ab46f784d1b20db435b852086e325034=7650=TEST52=20250411-01:23:27.286148369=2262=1850cf72-9acb-441d-8b46-896f97af82d2268=1279=2269=0278=bf2e56ec-02da-430e-a158-22c439a6bb4783=159753701255=BTC-USD60=20250411-01:23:27.28408458=FILLED10=120
20250411-01:23:27.410691000 : 8=FIXT.1.19=30135=X49=Coinbase56=24ab46f784d1b20db435b852086e325034=7750=TEST52=20250411-01:23:27.300218369=2262=1850cf72-9acb-441d-8b46-896f97af82d2268=1279=0269=183=159753701355=BTC-USD270=3.33271=0.5892351229004=2.079999973660=20250411-01:23:27.29894440=237=7d2c9cf2-0586-416c-b239-41624ad2c0b710=094
20250411-01:23:27.411216000 : 8=FIXT.1.19=32535=X49=Coinbase56=24ab46f784d1b20db435b852086e325034=7850=TEST52=20250411-01:23:27.300278369=2262=1850cf72-9acb-441d-8b46-896f97af82d2268=1279=0269=2278=4d60a78e-b39b-420e-b830-bc0f3f4fdde283=159753701455=BTC-USD270=3.53271=0.5892351260=20250411-01:23:27.29894437=7d2c9cf2-0586-416c-b239-41624ad2c0b75797=210=001
20250411-01:23:27.411716000 : 8=FIXT.1.19=27935=X49=Coinbase56=24ab46f784d1b20db435b852086e325034=7950=TEST52=20250411-01:23:27.300320369=2262=1850cf72-9acb-441d-8b46-896f97af82d2268=1279=2269=1278=7d2c9cf2-0586-416c-b239-41624ad2c0b783=159753701555=BTC-USD270=3.33271=060=20250411-01:23:27.29894458=FILLED10=152
20250411-01:23:27.424826000 : 8=FIXT.1.19=27335=X49=Coinbase56=24ab46f784d1b20db435b852086e325034=8050=TEST52=20250411-01:23:27.313733369=2262=1850cf72-9acb-441d-8b46-896f97af82d2268=1279=0269=183=159753701655=BTC-USD271=0.6232294660=20250411-01:23:27.31206340=137=95a5d2d3-82da-444d-ad99-762a08e308d910=054
20250411-01:23:27.425113000 : 8=FIXT.1.19=32535=X49=Coinbase56=24ab46f784d1b20db435b852086e325034=8150=TEST52=20250411-01:23:27.313739369=2262=1850cf72-9acb-441d-8b46-896f97af82d2268=1279=0269=2278=4d60a78e-b39b-420e-b830-bc0f3f4fdde283=159753701755=BTC-USD270=3.53271=0.6232294660=20250411-01:23:27.31206337=95a5d2d3-82da-444d-ad99-762a08e308d95797=210=049
20250411-01:23:27.425671000 : 8=FIXT.1.19=27935=X49=Coinbase56=24ab46f784d1b20db435b852086e325034=8250=TEST52=20250411-01:23:27.313742369=2262=1850cf72-9acb-441d-8b46-896f97af82d2268=1279=2269=1278=95a5d2d3-82da-444d-ad99-762a08e308d983=159753701855=BTC-USD271=0.0000000060=20250411-01:23:27.31206358=FILLED10=223
20250411-01:23:27.453115000 : 8=FIXT.1.19=27735=X49=Coinbase56=24ab46f784d1b20db435b852086e325034=8350=TEST52=20250411-01:23:27.343269369=2262=1850cf72-9acb-441d-8b46-896f97af82d2268=1279=0269=083=159753701955=BTC-USD29004=2.208895519560=20250411-01:23:27.34113540=137=84e273eb-5643-4d06-92d4-f9ae85f7321c10=244
20250411-01:23:27.453576000 : 8=FIXT.1.19=32535=X49=Coinbase56=24ab46f784d1b20db435b852086e325034=8450=TEST52=20250411-01:23:27.343328369=2262=1850cf72-9acb-441d-8b46-896f97af82d2268=1279=0269=2278=c5b88ea9-605d-4595-ac52-f7c3f08523ba83=159753702055=BTC-USD270=3.55271=0.6222240960=20250411-01:23:27.34113537=84e273eb-5643-4d06-92d4-f9ae85f7321c5797=110=122
20250411-01:23:27.453896000 : 8=FIXT.1.19=26435=X49=Coinbase56=24ab46f784d1b20db435b852086e325034=8550=TEST52=20250411-01:23:27.343338369=2262=1850cf72-9acb-441d-8b46-896f97af82d2268=1279=2269=0278=84e273eb-5643-4d06-92d4-f9ae85f7321c83=159753702155=BTC-USD60=20250411-01:23:27.34113558=FILLED10=248
20250411-01:23:27.481701000 : 8=FIXT.1.19=27335=X49=Coinbase56=24ab46f784d1b20db435b852086e325034=8650=TEST52=20250411-01:23:27.371212369=2262=1850cf72-9acb-441d-8b46-896f97af82d2268=1279=0269=183=159753702255=BTC-USD271=0.6232294660=20250411-01:23:27.36981340=137=f1028139-7aca-43b4-9b0e-64be3bdca57610=143
20250411-01:23:27.482190000 : 8=FIXT.1.19=32535=X49=Coinbase56=24ab46f784d1b20db435b852086e325034=8750=TEST52=20250411-01:23:27.371331369=2262=1850cf72-9acb-441d-8b46-896f97af82d2268=1279=0269=2278=4d60a78e-b39b-420e-b830-bc0f3f4fdde283=159753702355=BTC-USD270=3.53271=0.6232294660=20250411-01:23:27.36981337=f1028139-7aca-43b4-9b0e-64be3bdca5765797=210=134
20250411-01:23:27.482765000 : 8=FIXT.1.19=27935=X49=Coinbase56=24ab46f784d1b20db435b852086e325034=8850=TEST52=20250411-01:23:27.371358369=2262=1850cf72-9acb-441d-8b46-896f97af82d2268=1279=2269=1278=f1028139-7aca-43b4-9b0e-64be3bdca57683=159753702455=BTC-USD271=0.0000000060=20250411-01:23:27.36981358=FILLED10=067
20250411-01:23:27.724979000 : 8=FIXT.1.19=8335=534=349=24ab46f784d1b20db435b852086e325052=20250411-01:23:27.72456=Coinbase10=112
20250411-01:23:27.738605000 : 8=FIXT.1.19=27735=X49=Coinbase56=24ab46f784d1b20db435b852086e325034=8950=TEST52=20250411-01:23:27.628286369=2262=1850cf72-9acb-441d-8b46-896f97af82d2268=1279=0269=083=159753702555=BTC-USD29004=2.208895519560=20250411-01:23:27.62629640=137=d2b10388-19a5-46aa-8018-d31193b81ce010=188
20250411-01:23:27.739014000 : 8=FIXT.1.19=32535=X49=Coinbase56=24ab46f784d1b20db435b852086e325034=9050=TEST52=20250411-01:23:27.628294369=2262=1850cf72-9acb-441d-8b46-896f97af82d2268=1279=0269=2278=c5b88ea9-605d-4595-ac52-f7c3f08523ba83=159753702655=BTC-USD270=3.55271=0.6222240960=20250411-01:23:27.62629637=d2b10388-19a5-46aa-8018-d31193b81ce05797=110=069
20250411-01:23:27.739238000 : 8=FIXT.1.19=26435=X49=Coinbase56=24ab46f784d1b20db435b852086e325034=9150=TEST52=20250411-01:23:27.628296369=2262=1850cf72-9acb-441d-8b46-896f97af82d2268=1279=2269=0278=d2b10388-19a5-46aa-8018-d31193b81ce083=159753702755=BTC-USD60=20250411-01:23:27.62629658=FILLED10=196
20250411-01:23:27.767470000 : 8=FIXT.1.19=27335=X49=Coinbase56=24ab46f784d1b20db435b852086e325034=9250=TEST52=20250411-01:23:27.656334369=2262=1850cf72-9acb-441d-8b46-896f97af82d2268=1279=0269=183=159753702855=BTC-USD271=0.6232294660=20250411-01:23:27.65505740=137=9a1bfc7a-544f-4905-8eaa-0990a8b56a2e10=166
20250411-01:23:27.767908000 : 8=FIXT.1.19=32535=X49=Coinbase56=24ab46f784d1b20db435b852086e325034=9350=TEST52=20250411-01:23:27.656339369=2262=1850cf72-9acb-441d-8b46-896f97af82d2268=1279=0269=2278=4d60a78e-b39b-420e-b830-bc0f3f4fdde283=159753702955=BTC-USD270=3.53271=0.6232294660=20250411-01:23:27.65505737=9a1bfc7a-544f-4905-8eaa-0990a8b56a2e5797=210=160
20250411-01:23:27.768462000 : 8=FIXT.1.19=27935=X49=Coinbase56=24ab46f784d1b20db435b852086e325034=9450=TEST52=20250411-01:23:27.656342369=2262=1850cf72-9acb-441d-8b46-896f97af82d2268=1279=2269=1278=9a1bfc7a-544f-4905-8eaa-0990a8b56a2e83=159753703055=BTC-USD271=0.0000000060=20250411-01:23:27.65505758=FILLED10=069
20250411-01:23:27.950696000 : 8=FIXT.1.19=11835=549=Coinbase56=24ab46f784d1b20db435b852086e325034=9550=TEST52=20250411-01:23:27.840379369=258=CLIENT_LOGOUT10=020
20250411-01:26:13.190367000 : 8=FIXT.1.19=21535=A34=149=24ab46f784d1b20db435b852086e325052=20250411-01:26:13.17756=Coinbase95=4496=LqdeNxJeH6wlmQ93B3hjk9HcHLuxNhrGFXn45NWpiDg=98=0108=30141=Y553=24ab46f784d1b20db435b852086e3250554=akmwnltyfgb1137=910=090
20250411-01:26:13.449014000 : 8=FIXT.1.19=12535=A49=Coinbase56=24ab46f784d1b20db435b852086e325034=150=TEST52=20250411-01:26:13.331491369=198=0108=30141=Y1137=910=186
20250411-01:26:14.940365000 : 8=FIXT.1.19=17835=V34=249=24ab46f784d1b20db435b852086e325052=20250411-01:26:14.93956=Coinbase1128=9146=155=BTC-USD262=50bb03be-debb-4b06-bc08-08dd0205dd08263=1264=0267=2269=0269=110=177
20250411-01:26:15.415881000 : 8=FIXT.1.19=30735=X49=Coinbase56=24ab46f784d1b20db435b852086e325034=250=TEST52=20250411-01:26:15.300158369=2262=50bb03be-debb-4b06-bc08-08dd0205dd08268=1279=1269=1278=538531e1-5caa-4f12-aed8-a3c4ce631c4383=159754044455=BTC-USD270=3.61271=0.5578617760=20250411-01:26:15.29902058=CHANGE_REASON_MODIFY_ORDER10=090
20250411-01:26:15.420538000 : 8=FIXT.1.19=28135=X49=Coinbase56=24ab46f784d1b20db435b852086e325034=350=TEST52=20250411-01:26:15.304063369=2262=50bb03be-debb-4b06-bc08-08dd0205dd08268=1279=0269=083=159754044555=BTC-USD270=3.88271=0.6232294660=20250411-01:26:15.30246840=237=faa87b8d-eef5-4d6a-90c6-6e2fc66ac4b610=089
20250411-01:26:15.424024000 : 8=FIXT.1.19=32435=X49=Coinbase56=24ab46f784d1b20db435b852086e325034=450=TEST52=20250411-01:26:15.304252369=2262=50bb03be-debb-4b06-bc08-08dd0205dd08268=1279=0269=2278=c5b88ea9-605d-4595-ac52-f7c3f08523ba83=159754044655=BTC-USD270=3.55271=0.6232294660=20250411-01:26:15.30246837=faa87b8d-eef5-4d6a-90c6-6e2fc66ac4b65797=110=039
20250411-01:26:15.427093000 : 8=FIXT.1.19=28735=X49=Coinbase56=24ab46f784d1b20db435b852086e325034=550=TEST52=20250411-01:26:15.304256369=2262=50bb03be-debb-4b06-bc08-08dd0205dd08268=1279=2269=0278=faa87b8d-eef5-4d6a-90c6-6e2fc66ac4b683=159754044755=BTC-USD270=3.88271=0.0000000060=20250411-01:26:15.30246858=FILLED10=005
20250411-01:26:17.769061000 : 8=FIXT.1.19=28035=X49=Coinbase56=24ab46f784d1b20db435b852086e325034=650=TEST52=20250411-01:26:17.652835369=2262=50bb03be-debb-4b06-bc08-08dd0205dd08268=1279=0269=083=159754044855=BTC-USD270=3.9271=0.6197183160=20250411-01:26:17.65136040=237=e8903fc1-79cb-4c33-b9fa-48ced6d535ab10=212
20250411-01:26:17.769469000 : 8=FIXT.1.19=32435=X49=Coinbase56=24ab46f784d1b20db435b852086e325034=750=TEST52=20250411-01:26:17.652923369=2262=50bb03be-debb-4b06-bc08-08dd0205dd08268=1279=0269=2278=c5b88ea9-605d-4595-ac52-f7c3f08523ba83=159754044955=BTC-USD270=3.55271=0.6197183160=20250411-01:26:17.65136037=e8903fc1-79cb-4c33-b9fa-48ced6d535ab5797=110=216
20250411-01:26:17.769832000 : 8=FIXT.1.19=28635=X49=Coinbase56=24ab46f784d1b20db435b852086e325034=850=TEST52=20250411-01:26:17.652928369=2262=50bb03be-debb-4b06-bc08-08dd0205dd08268=1279=2269=0278=e8903fc1-79cb-4c33-b9fa-48ced6d535ab83=159754045055=BTC-USD270=3.9271=0.0000000060=20250411-01:26:17.65136058=FILLED10=116
20250411-01:26:17.822243000 : 8=FIXT.1.19=28135=X49=Coinbase56=24ab46f784d1b20db435b852086e325034=950=TEST52=20250411-01:26:17.706725369=2262=50bb03be-debb-4b06-bc08-08dd0205dd08268=1279=0269=183=159754045155=BTC-USD270=3.26271=0.6197183160=20250411-01:26:17.70502440=237=49d2cb96-c5b9-4539-8829-afe28d0fc9b810=132
20250411-01:26:17.822657000 : 8=FIXT.1.19=32535=X49=Coinbase56=24ab46f784d1b20db435b852086e325034=1050=TEST52=20250411-01:26:17.706788369=2262=50bb03be-debb-4b06-bc08-08dd0205dd08268=1279=0269=2278=4d60a78e-b39b-420e-b830-bc0f3f4fdde283=159754045255=BTC-USD270=3.53271=0.6197183160=20250411-01:26:17.70502437=49d2cb96-c5b9-4539-8829-afe28d0fc9b85797=210=009
20250411-01:26:17.823017000 : 8=FIXT.1.19=28835=X49=Coinbase56=24ab46f784d1b20db435b852086e325034=1150=TEST52=20250411-01:26:17.706797369=2262=50bb03be-debb-4b06-bc08-08dd0205dd08268=1279=2269=1278=49d2cb96-c5b9-4539-8829-afe28d0fc9b883=159754045355=BTC-USD270=3.26271=0.0000000060=20250411-01:26:17.70502458=FILLED10=091
20250411-01:26:20.198380000 : 8=FIXT.1.19=91735=W49=Coinbase56=24ab46f784d1b20db435b852086e325034=1250=TEST52=20250411-01:26:20.080181369=2262=50bb03be-debb-4b06-bc08-08dd0205dd0883=1597540453893=N55=BTC-USD1682=full_trading268=10269=0278=4d60a78e-b39b-420e-b830-bc0f3f4fdde2270=3.53271=259656.18977392269=0278=9d9353ab-229f-423a-89a3-c52a46543bc9270=3.53271=18127.30103418269=0278=58ed893b-e3aa-47af-a913-bb90c77a59fe270=3.51271=0.57427707269=0278=f5fc5e68-a52c-44d3-87ef-3785312f4782270=3.48271=0.29310888269=0278=dcccb470-c535-433a-9198-4e2b4c26d99d270=3.47271=0.29311495269=0278=f05d9766-970d-44ca-aa4d-e8b2720bbda8270=3.46271=0.29026870269=0278=2c4d7d5a-33aa-4058-b546-480b6a2168a4270=3.44271=0.29828577269=0278=37dbcf16-0b3d-4f67-bc90-e36268b99e0e270=3.42271=0.30270947269=0278=5c357a95-8c67-413f-aa0c-de38ec135c4a270=3.42271=0.61971831269=0278=4c63c0b7-30e0-4ef1-931f-0090359f978e270=3.41271=0.3215896210=217
20250411-01:26:20.210845000 : 8=FIXT.1.19=14035=334=349=24ab46f784d1b20db435b852086e325052=20250411-01:26:20.20356=Coinbase45=1258=Tag appears more than once371=269372=W373=1310=182
20250411-01:26:20.212097000 : 8=FIXT.1.19=90835=W49=Coinbase56=24ab46f784d1b20db435b852086e325034=1350=TEST52=20250411-01:26:20.080417369=2262=50bb03be-debb-4b06-bc08-08dd0205dd0883=1597540453893=N55=BTC-USD1682=full_trading268=10269=0278=d6b4aa4e-d588-4c96-83aa-8e8d8accb1a4270=3.41271=0.30121104269=0278=e8b3d8da-1663-413c-b7fb-6aba23b01440270=3.39271=0.31006477269=0278=65009766-5f91-4931-b87d-f0e4e9721a78270=3.39271=0.58572530269=0278=bcbe17c3-9059-4c38-8ab8-8e78f1ef9062270=3.38271=0.32617981269=0278=57bb77fd-337f-49bc-a56f-a4e2dff851ee270=3.37271=0.31071676269=0278=ded4b51d-349f-4726-8379-6761a3576bb6270=3.33271=0.31560513269=0278=ff7aff09-38de-47ac-a3cb-9beacb0b9ad8270=3.33271=0.30682342269=0278=d1da558a-e9d2-4e11-b26e-1eb80a1a34c5270=3.32271=0.31700685269=0278=9ee34527-d4d8-4659-b2ea-cdff3dc4a8fa270=3.32271=0.32181951269=0278=7abf2220-0421-460f-9dbb-14c41564e41a270=3.32271=0.3130843610=230
20250411-01:26:20.213048000 : 8=FIXT.1.19=14035=334=449=24ab46f784d1b20db435b852086e325052=20250411-01:26:20.21256=Coinbase45=1358=Tag appears more than once371=269372=W373=1310=184
20250411-01:26:20.213204000 : 8=FIXT.1.19=90835=W49=Coinbase56=24ab46f784d1b20db435b852086e325034=1450=TEST52=20250411-01:26:20.080666369=2262=50bb03be-debb-4b06-bc08-08dd0205dd0883=1597540453893=N55=BTC-USD1682=full_trading268=10269=0278=69634ec5-f71a-4990-b56d-13c3069a455a270=3.31271=0.32329458269=0278=2f333c17-a386-4d52-8ff1-eadcb99bc22f270=3.31271=0.31999220269=0278=f02efc37-0b1e-470b-99ef-e31012887d73270=3.30271=0.32771570269=0278=6d430950-8078-4987-8995-e581564e368d270=3.29271=0.30702763269=0278=841f895a-cd2d-4082-9a37-b50fc19e35bf270=3.28271=0.32610801269=0278=3cf93093-e42b-4c24-95ea-c367d96427fe270=3.27271=0.33588654269=0278=f29c94bc-d1c2-4145-97b0-ecb77d81a8bf270=3.27271=0.31661408269=0278=d208c4fb-56c6-4911-85c9-77b68a5ba6ab270=3.25271=0.30961623269=0278=e88796ff-68c8-4463-914b-46e09fbaf639270=3.25271=0.33589845269=0278=06f345fb-0292-45fc-8237-9ad1a84b541c270=3.24271=0.3152850710=147
20250411-01:26:20.214228000 : 8=FIXT.1.19=14035=334=549=24ab46f784d1b20db435b852086e325052=20250411-01:26:20.21356=Coinbase45=1458=Tag appears more than once371=269372=W373=1310=187
20250411-01:26:20.214339000 : 8=FIXT.1.19=90835=W49=Coinbase56=24ab46f784d1b20db435b852086e325034=1550=TEST52=20250411-01:26:20.080915369=2262=50bb03be-debb-4b06-bc08-08dd0205dd0883=1597540453893=N55=BTC-USD1682=full_trading268=10269=0278=fa20c2c7-df80-4941-9a9c-a6ef2e579480270=3.23271=0.33432448269=0278=a833d230-a749-4bf4-823e-93adc40b773d270=3.23271=0.31165878269=0278=2abb6e15-b9cd-415b-8c9b-99a61c750310270=3.22271=0.32048714269=0278=ec44a6d8-ae5f-4809-89d7-0f7a3adac547270=3.21271=0.33230954269=0278=9cf61c67-c4fc-4bac-92fd-d4e2b56248aa270=3.21271=0.33583951269=0278=210b2518-bb42-461a-9c7e-b4e04c5ffcc6270=3.21271=0.32669007269=0278=2e3fa1b2-20f1-4694-9be4-322040b75152270=3.21271=0.32907979269=0278=05dd5607-92c9-4296-8cdc-27cdff004dea270=3.21271=0.32776075269=0278=87944de7-a5f1-4033-a3d8-cbc10f3a5232270=3.20271=0.32225170269=0278=30f6bb59-2469-4e6d-8fa5-13666373901f270=3.19271=0.3138649610=009
20250411-01:26:20.215081000 : 8=FIXT.1.19=14035=334=649=24ab46f784d1b20db435b852086e325052=20250411-01:26:20.21456=Coinbase45=1558=Tag appears more than once371=269372=W373=1310=190
20250411-01:26:20.215176000 : 8=FIXT.1.19=90935=W49=Coinbase56=24ab46f784d1b20db435b852086e325034=1650=TEST52=20250411-01:26:20.081166369=2262=50bb03be-debb-4b06-bc08-08dd0205dd0883=1597540453893=N55=BTC-USD1682=full_trading268=10269=0278=6a5d2852-7ddc-456e-acb5-bfadcc0c1360270=3.19271=0.32157390269=0278=5d00d8a2-5aea-4836-ba19-74fe67116df8270=3.18271=0.32651049269=0278=acc71746-3591-4dde-a7e2-c2795d0ad125270=3.17271=0.31577131269=0278=13982796-c2a8-4740-95e2-5aca0fdfd8bb270=3.16271=0.33021170269=0278=9f2f0737-661e-43d7-89f9-959ed5e08306270=3.16271=0.33082075269=0278=7e0e2d14-fa77-4978-8cae-d9660fd13e6d270=3.16271=0.32014975269=0278=82826a7d-848c-4516-a7b6-5ec6881609a8270=2.00271=10.00000000269=0278=590048d5-ee44-49dc-b66d-1a692e055133270=1.94271=0.51546392269=0278=22bdda11-16cd-488b-9fa9-da098dad543e270=1.94271=0.51546392269=0278=d356ef8b-596e-47e7-bf90-cc015b85fc57270=1.93271=0.5233160610=119
20250411-01:26:20.216108000 : 8=FIXT.1.19=14035=334=749=24ab46f784d1b20db435b852086e325052=20250411-01:26:20.21556=Coinbase45=1658=Tag appears more than once371=269372=W373=1310=193
20250411-01:26:20.216199000 : 8=FIXT.1.19=90835=W49=Coinbase56=24ab46f784d1b20db435b852086e325034=1750=TEST52=20250411-01:26:20.081416369=2262=50bb03be-debb-4b06-bc08-08dd0205dd0883=1597540453893=N55=BTC-USD1682=full_trading268=10269=0278=aa8d48bc-97fb-4d00-b923-66d37cc8c66a270=1.93271=0.52331606269=0278=7d51dcb4-a7f8-4cca-b2d0-e902403d1b9f270=1.93271=0.52331606269=0278=f7680950-3af2-4723-a6e4-5cbd528ca900270=1.93271=0.52331606269=0278=fdeff994-4866-47af-9dde-a25947a26606270=1.93271=0.52331606269=0278=65e7e2bb-023d-4936-bb4e-ff7625ba7264270=1.93271=0.52331606269=0278=53732639-572c-4cd5-b61e-e4f534d1d540270=1.93271=0.52331606269=0278=24da8927-1dd1-468b-9437-ff366f5bfa11270=1.93271=0.52331606269=0278=baa5862c-41e8-458c-83d3-c095bb68ed17270=1.93271=0.52331606269=0278=92a3c3e3-7afe-4d02-a0d8-96f512b63bb7270=1.93271=0.52331606269=0278=9d2a564e-f178-4966-9baf-5814a1c1686b270=1.93271=0.5233160610=050
20250411-01:26:20.217286000 : 8=FIXT.1.19=14035=334=849=24ab46f784d1b20db435b852086e325052=20250411-01:26:20.21656=Coinbase45=1758=Tag appears more than once371=269372=W373=1310=196
20250411-01:26:20.217414000 : 8=FIXT.1.19=90835=W49=Coinbase56=24ab46f784d1b20db435b852086e325034=1850=TEST52=20250411-01:26:20.081666369=2262=50bb03be-debb-4b06-bc08-08dd0205dd0883=1597540453893=N55=BTC-USD1682=full_trading268=10269=0278=f9e6b978-87f6-4397-8d82-07cf698c123f270=1.93271=0.52331606269=0278=3e64b388-13d3-441d-b241-aa8dd6fe55e6270=1.93271=0.52331606269=0278=60300433-87b0-4031-bb1e-12cf9d773d3f270=1.93271=0.52331606269=0278=1bdd5f5a-1d99-4eed-af09-c187bcbbd2d8270=1.93271=0.52331606269=0278=4ed6f6b9-77fb-4255-a188-f243dd0cdb3c270=1.93271=0.52331606269=0278=9ad1fc18-5a38-4edb-ac5c-6ac826a8a846270=1.93271=0.52331606269=0278=1c218c8c-baea-4a1f-838e-4a3a94b468e1270=1.93271=0.52331606269=0278=fd70f5e2-d2c9-472a-ab40-a775afafd73d270=1.93271=0.52331606269=0278=96f5e3a5-1c2a-4db6-a3fb-fd1f13d5d559270=1.93271=0.52331606269=0278=4a015a4c-490a-4c40-974f-9dfb7feb335d270=1.93271=0.5233160610=075
20250411-01:26:20.221239000 : 8=FIXT.1.19=14035=334=949=24ab46f784d1b20db435b852086e325052=20250411-01:26:20.21756=Coinbase45=1858=Tag appears more than once371=269372=W373=1310=199
20250411-01:26:20.222312000 : 8=FIXT.1.19=90835=W49=Coinbase56=24ab46f784d1b20db435b852086e325034=1950=TEST52=20250411-01:26:20.081916369=2262=50bb03be-debb-4b06-bc08-08dd0205dd0883=1597540453893=N55=BTC-USD1682=full_trading268=10269=0278=d919363e-2c54-404f-bc0b-063e2f12bec4270=1.93271=0.52331606269=0278=d4636d6c-85c6-4ac9-9afb-70ca636f4ad4270=1.93271=0.52331606269=0278=bda09690-f345-4c33-ae8b-e8c78da11b5a270=1.93271=0.52331606269=0278=1a81ae10-b700-42a0-89a3-7d7a3eea0ebb270=1.93271=0.52331606269=0278=1ace5afa-e550-4abf-a458-52e46e1b54f0270=1.93271=0.52331606269=0278=2332d1c9-67e7-457a-abfe-f5e9a8c2ea05270=1.93271=0.52331606269=0278=6afa1f19-0ec5-49fd-8b74-06a12a6c5ca9270=1.93271=0.52331606269=0278=3fa3413d-c26c-472f-9cc5-da1c48935c63270=1.93271=0.52331606269=0278=3f9e43c4-2e62-4d51-b4cb-ad207c693331270=1.93271=0.52331606269=0278=29e8bfcf-c764-4f7e-997d-09abf72bbc00270=1.93271=0.5233160610=254
20250411-01:26:20.229222000 : 8=FIXT.1.19=14135=334=1049=24ab46f784d1b20db435b852086e325052=20250411-01:26:20.22456=Coinbase45=1958=Tag appears more than once371=269372=W373=1310=239
20250411-01:26:20.229495000 : 8=FIXT.1.19=90835=W49=Coinbase56=24ab46f784d1b20db435b852086e325034=2050=TEST52=20250411-01:26:20.082166369=2262=50bb03be-debb-4b06-bc08-08dd0205dd0883=1597540453893=N55=BTC-USD1682=full_trading268=10269=0278=cf3e8b26-09ae-4dfb-9b84-b12a7e199a5a270=1.93271=0.52331606269=0278=08db3e51-e927-47d3-a9dd-2f887c58dc85270=1.93271=0.52331606269=0278=353ae741-9473-4cc5-9ab7-7e5de8ae55d0270=1.93271=0.52331606269=0278=4d037208-2072-480f-98ac-7be9c24f18f4270=1.93271=0.52331606269=0278=b598f678-da6e-4c01-90ed-d702c42f8a65270=1.93271=0.52331606269=0278=5f69b1a0-b5d1-4715-9be1-9bdf008d97d7270=1.93271=0.52331606269=0278=ef063d15-248a-4eae-97f4-278be5106d80270=1.93271=0.52331606269=0278=f8b20207-84bc-44e9-a2fe-9ad775e2ecb1270=1.93271=0.52331606269=0278=75bce2b7-bc58-4479-8bfb-144f88f2262b270=1.93271=0.52331606269=0278=1f6e2a79-8b10-4a7f-89de-0f1fa03692c7270=1.93271=0.5233160610=229
20250411-01:26:20.231031000 : 8=FIXT.1.19=14135=334=1149=24ab46f784d1b20db435b852086e325052=20250411-01:26:20.22956=Coinbase45=2058=Tag appears more than once371=269372=W373=1310=237
20250411-01:26:20.231224000 : 8=FIXT.1.19=90835=W49=Coinbase56=24ab46f784d1b20db435b852086e325034=2150=TEST52=20250411-01:26:20.082416369=2262=50bb03be-debb-4b06-bc08-08dd0205dd0883=1597540453893=N55=BTC-USD1682=full_trading268=10269=0278=d1b80bf5-9b17-44b4-9577-6fe71170b578270=1.93271=0.52331606269=0278=b891e26a-c20c-4fce-ba1c-487fe139a4cc270=1.93271=0.52331606269=0278=5d06d3f6-3189-4394-b3c5-6a2bda14b6d1270=1.93271=0.52331606269=0278=e5791c0f-3937-4a66-9b98-26f79a3891be270=1.93271=0.52331606269=0278=c62591c6-7dfa-46a7-8f20-6a5f22804999270=1.93271=0.52331606269=0278=7c503558-c0b8-457b-8c46-71ece3f7fc8a270=1.93271=0.52331606269=0278=f763bb56-2f21-4a9b-bd48-f84dc1bd5ee5270=1.93271=0.52331606269=0278=42214b03-1fc2-46b3-9e83-91b23a510e5a270=1.93271=0.52331606269=0278=1c7c52ed-7d39-4326-b3b8-98f05a9b3ef0270=1.93271=0.52331606269=0278=3313309e-45e7-4e7b-8c55-4f9a8ec1b351270=1.93271=0.5233160610=019
20250411-01:26:20.232167000 : 8=FIXT.1.19=14135=334=1249=24ab46f784d1b20db435b852086e325052=20250411-01:26:20.23156=Coinbase45=2158=Tag appears more than once371=269372=W373=1310=232
20250411-01:26:20.430172000 : 8=FIXT.1.19=90835=W49=Coinbase56=24ab46f784d1b20db435b852086e325034=2250=TEST52=20250411-01:26:20.082666369=2262=50bb03be-debb-4b06-bc08-08dd0205dd0883=1597540453893=N55=BTC-USD1682=full_trading268=10269=0278=78801ffb-ec5a-4c74-9d08-3e86fd9db4dd270=1.93271=0.52331606269=0278=abe6eea4-1d9c-47d7-847f-2f44aa561b3f270=1.93271=0.52331606269=0278=6a6eb56d-2010-43e2-b78e-5f098081bb64270=1.93271=0.52331606269=0278=b53c01ff-f450-4b05-8ad1-e7894b45e0e0270=1.93271=0.52331606269=0278=4747863e-c0a6-4ef5-8faf-e8934bca4f8b270=1.93271=0.52331606269=0278=81a8a629-57f4-4e3a-ac25-2e9ee1f357c2270=1.93271=0.52331606269=0278=1e239259-7be4-476a-845d-1b92fd951d8b270=1.93271=0.52331606269=0278=189eb272-48f9-4915-b7e1-a86dcc505c4a270=1.93271=0.52331606269=0278=0562b9f7-aae3-4961-bd97-f5b8cde0ec34270=1.93271=0.52331606269=0278=5103331b-7300-487b-bc2c-a6032bf4be7e270=1.93271=0.5233160610=079
20250411-01:26:20.431186000 : 8=FIXT.1.19=14135=334=1349=24ab46f784d1b20db435b852086e325052=20250411-01:26:20.43056=Coinbase45=2258=Tag appears more than once371=269372=W373=1310=235
20250411-01:26:20.431369000 : 8=FIXT.1.19=91135=W49=Coinbase56=24ab46f784d1b20db435b852086e325034=2350=TEST52=20250411-01:26:20.082916369=2262=50bb03be-debb-4b06-bc08-08dd0205dd0883=1597540453893=N55=BTC-USD1682=full_trading268=10269=0278=78ac85ac-2478-4991-a084-7286982b77cc270=1.93271=0.52331606269=0278=6993b26d-d6dc-4f99-8a53-9500ae5b4ff1270=1.93271=0.52331606269=0278=1c96ab9d-04a6-465a-87e5-3ed33970178f270=1.93271=0.52331606269=0278=6fc0282b-d538-4aa3-8982-bda02bb1b054270=1.93271=0.52331606269=0278=80870aa3-04a2-4d2a-8669-93215130ffee270=1.93271=0.52331606269=0278=b274e872-6923-45fd-b48a-68e685e769cb270=1.93271=0.52331606269=0278=2d4364c0-239c-4f4b-8ce4-2acfe0bb343d270=1.12271=1.00000000269=0278=8fa16a4f-377f-4deb-9a8e-1020aed9edf4270=1.00271=1.00000000269=1278=c5b88ea9-605d-4595-ac52-f7c3f08523ba270=3.55271=9643.73904236269=1278=81523bd3-8912-4789-8761-89a9ee42794b270=3.55271=0.3051896610=029
20250411-01:26:20.432454000 : 8=FIXT.1.19=14135=334=1449=24ab46f784d1b20db435b852086e325052=20250411-01:26:20.43156=Coinbase45=2358=Tag appears more than once371=269372=W373=1310=238
20250411-01:26:20.432569000 : 8=FIXT.1.19=93235=W49=Coinbase56=24ab46f784d1b20db435b852086e325034=2450=TEST52=20250411-01:26:20.083166369=2262=50bb03be-debb-4b06-bc08-08dd0205dd0883=1597540453893=N55=BTC-USD1682=full_trading268=10269=1278=60fc75ca-0052-40b7-9f18-a6aad9d31b84270=3.56271=18037.00000000269=1278=ad00e2cd-d925-46a4-9e7e-941c6faed2c7270=3.57271=18027.00000000269=1278=fec191b5-64da-4a15-ab4b-36a0d3d10750270=3.57271=0.29025301269=1278=02a780aa-8154-4638-a5ca-53b8198cc724270=3.58271=16937.00000000269=1278=911349fb-1960-4904-9a38-0e2497fb7ccb270=3.58271=0.29896312269=1278=d91e89d4-ac5c-4853-9879-ec8ff5e00a71270=3.59271=17163.00000000269=1278=fadcd276-2def-409a-be94-be577f68ff27270=3.59271=0.58114926269=1278=341d0ad8-6c15-4b5e-aebb-e3caa5af575c270=3.60271=17926.00000000269=1278=9d239e03-1215-4cc7-ad44-3f4097ee70ea270=3.61271=18058.08928020269=1278=538531e1-5caa-4f12-aed8-a3c4ce631c43270=3.61271=0.5578617710=080
20250411-01:26:20.433427000 : 8=FIXT.1.19=14135=334=1549=24ab46f784d1b20db435b852086e325052=20250411-01:26:20.43256=Coinbase45=2458=Tag appears more than once371=269372=W373=1310=241
20250411-01:26:20.433523000 : 8=FIXT.1.19=92035=W49=Coinbase56=24ab46f784d1b20db435b852086e325034=2550=TEST52=20250411-01:26:20.083416369=2262=50bb03be-debb-4b06-bc08-08dd0205dd0883=1597540453893=N55=BTC-USD1682=full_trading268=10269=1278=dbb0f332-4189-4df5-879b-e55860b13def270=3.62271=0.28062774269=1278=f7639c39-7e8b-44d1-a2f2-9807e2a3228c270=3.62271=0.27709851269=1278=83be9389-2099-4173-a322-b0933bc99358270=3.62271=19973.00000000269=1278=b89abc22-6b6c-4474-b3fc-ffe21f05cd4e270=3.63271=20016.00000000269=1278=1ee215f8-d2cf-4965-8f44-adcbda3331dd270=3.63271=0.61971831269=1278=ce0af8a3-149c-4603-905a-be65625fe014270=3.64271=0.27806002269=1278=94b8615f-6fa7-4dc9-bbfa-435fe535bebc270=3.64271=22352.63489459269=1278=cae3885d-f5b2-4de1-830c-0085e27bbb69270=3.69271=0.27722678269=1278=b9732128-11b1-44fd-bea3-94da9fc853fb270=3.71271=0.28488329269=1278=818b83a4-e14e-4ad5-b094-6733f0504003270=3.75271=0.2793022510=012
20250411-01:26:20.434370000 : 8=FIXT.1.19=14135=334=1649=24ab46f784d1b20db435b852086e325052=20250411-01:26:20.43356=Coinbase45=2558=Tag appears more than once371=269372=W373=1310=244
20250411-01:26:20.434487000 : 8=FIXT.1.19=91235=W49=Coinbase56=24ab46f784d1b20db435b852086e325034=2650=TEST52=20250411-01:26:20.083666369=2262=50bb03be-debb-4b06-bc08-08dd0205dd0883=1597540453893=N55=BTC-USD1682=full_trading268=10269=1278=3e6990a0-8ef4-4968-8ee8-89b7346c197d270=3.76271=0.28131365269=1278=342794c8-a9d2-4aa5-9886-a819398d69c6270=3.88271=0.27719712269=1278=2839680b-48b3-4f53-86b1-9269987275e7270=3.91271=0.26621275269=1278=fd7b5361-29f8-4b35-bae5-232a64f657b4270=3.95271=0.26131406269=1278=5edaeed0-fae9-4f36-8c77-6fbedf61eefc270=4.02271=0.25091227269=1278=fdbbfd04-ba67-4b23-bbc1-f87f929e7e81270=4.07271=0.24812642269=1278=534b2a85-0852-420d-928b-70cdb6ba2457270=4.10271=0.26961968269=1278=b009f8a1-4a39-493b-b96e-d783e981c915270=4.26271=0.25019574269=1278=729a899c-ac2d-4541-b0a2-cbdd5df9bf98270=10.00271=10.00000000269=1278=eb1e5d45-d081-4ef8-a83e-1f5348fbda96270=10.00271=10.0000000010=041
20250411-01:26:20.435187000 : 8=FIXT.1.19=14135=334=1749=24ab46f784d1b20db435b852086e325052=20250411-01:26:20.43456=Coinbase45=2658=Tag appears more than once371=269372=W373=1310=247
20250411-01:26:20.435333000 : 8=FIXT.1.19=92835=W49=Coinbase56=24ab46f784d1b20db435b852086e325034=2750=TEST52=20250411-01:26:20.083916369=2262=50bb03be-debb-4b06-bc08-08dd0205dd0883=1597540453893=N55=BTC-USD1682=full_trading268=10269=1278=0cd67977-85eb-45fa-ae72-d45b92ca24f4270=10.00271=10.00000000269=1278=5d931559-6758-4b75-9d6d-6438d25b497f270=10.00271=10.00000000269=1278=57e43d1d-644a-493e-acd3-69dc5e64dcde270=10.00271=10.00000000269=1278=c1566121-2b63-494d-ac2d-973e9f0115c0270=10.00271=10.00000000269=1278=d0c4a771-9035-4db9-ae7b-ad2d1db5646d270=10.00271=10.00000000269=1278=52c644ea-628a-4576-8e7e-27ec4c90398b270=10.00271=10.00000000269=1278=c3483f66-d8ce-489a-90b9-2bce69e054ee270=10.00271=10.00000000269=1278=55992a5c-cbcd-464a-8f8d-8b58e81e5c0b270=10.00271=10.00000000269=1278=19077009-6f26-4e2d-9dab-04a28231b752270=10.00271=10.00000000269=1278=692097d1-c978-4024-95e9-2bf348b64bbd270=10.00271=10.0000000010=169
20250411-01:26:20.436152000 : 8=FIXT.1.19=14135=334=1849=24ab46f784d1b20db435b852086e325052=20250411-01:26:20.43556=Coinbase45=2758=Tag appears more than once371=269372=W373=1310=250
20250411-01:26:20.436262000 : 8=FIXT.1.19=93535=W49=Coinbase56=24ab46f784d1b20db435b852086e325034=2850=TEST52=20250411-01:26:20.084166369=2262=50bb03be-debb-4b06-bc08-08dd0205dd0883=1597540453893=N55=BTC-USD1682=full_trading268=10269=1278=99a92935-11b7-4f21-a64c-c746b53d1777270=10.00271=10.00000000269=1278=dc024b0b-0337-4215-9669-5e5636834397270=10.00271=10.00000000269=1278=c90fcc3a-a36c-4c14-b57f-6db78762e017270=10.00271=10.00000000269=1278=7841891a-bb7c-4034-97c1-41164185edc7270=1000.00271=3.10000000269=1278=381c9fa7-1add-4dd2-9233-f41e2c8821fe270=1000.00271=3.10000000269=1278=928e65c2-7e2d-478b-9310-414fb77f5aae270=1000.00271=3.10000000269=1278=ad4bd3ac-9276-40d5-90f9-e47b1d8ee953270=1000.00271=3.10000000269=1278=79e799dc-4a3d-4922-ad1a-f74eb7eff789270=1000.00271=3.10000000269=1278=04f642b7-750f-4967-b786-0d48eea0f158270=1000.00271=3.10000000269=1278=d0ad653d-3272-4a3b-ba7a-a52029a67a92270=1000.00271=3.1000000010=199
20250411-01:26:20.437222000 : 8=FIXT.1.19=14135=334=1949=24ab46f784d1b20db435b852086e325052=20250411-01:26:20.43656=Coinbase45=2858=Tag appears more than once371=269372=W373=1310=253
20250411-01:26:20.437348000 : 8=FIXT.1.19=93835=W49=Coinbase56=24ab46f784d1b20db435b852086e325034=2950=TEST52=20250411-01:26:20.084416369=2262=50bb03be-debb-4b06-bc08-08dd0205dd0883=1597540453893=N55=BTC-USD1682=full_trading268=10269=1278=cad40464-4c62-4bf3-8444-c487fcc8dd01270=1000.00271=3.10000000269=1278=426c6428-d481-4ff7-9de3-f00ff219d654270=1000.00271=3.10000000269=1278=1ed1152d-8c1a-4b29-acdd-bbd1a5c5f35f270=1000.00271=3.10000000269=1278=66526051-b5cb-442f-af90-c609be0a9796270=1000.00271=3.10000000269=1278=f68e4659-5785-4ee9-ac24-3186640a2752270=1000.00271=3.10000000269=1278=38070d38-80a9-4898-8ef7-a0a9da5a4123270=1000.00271=3.10000000269=1278=e4d2d308-ed11-49db-850e-3cbd8258395d270=1000.00271=3.10000000269=1278=d6cfaadc-97ea-43c1-898d-40faea9c1477270=1000.00271=3.10000000269=1278=36876bea-9e3a-4018-b0ac-b75cb8c16953270=1000.00271=3.10000000269=1278=eb244bc5-49e8-4aa3-af8b-3d1a67c90a08270=1000.00271=3.1000000010=172
20250411-01:26:20.438160000 : 8=FIXT.1.19=14135=334=2049=24ab46f784d1b20db435b852086e325052=20250411-01:26:20.43756=Coinbase45=2958=Tag appears more than once371=269372=W373=1310=247
20250411-01:26:20.438257000 : 8=FIXT.1.19=93835=W49=Coinbase56=24ab46f784d1b20db435b852086e325034=3050=TEST52=20250411-01:26:20.084666369=2262=50bb03be-debb-4b06-bc08-08dd0205dd0883=1597540453893=N55=BTC-USD1682=full_trading268=10269=1278=3efba776-29ad-4aeb-82d8-0824f161471e270=1000.00271=3.10000000269=1278=de0ddebd-0ca8-4eca-9985-77c10c8629a9270=1000.00271=3.10000000269=1278=dde4408a-fb6b-441c-a7f3-7b8b23ffdb1f270=1000.00271=3.10000000269=1278=3ebd6434-070f-4b4d-8cf3-00368112466d270=1000.00271=3.10000000269=1278=7aa98e13-65f3-4058-9f91-c1f452d02710270=1000.00271=3.10000000269=1278=e86a1fec-3610-460d-8d85-4e1e222ee159270=1000.00271=3.10000000269=1278=6dfac057-72b1-4f2c-b110-03766dea0d31270=1000.00271=3.10000000269=1278=bbb7d0ea-d251-4612-b53e-e528cc0a24ab270=1000.00271=3.10000000269=1278=0782ca37-48cf-4ff3-a74a-35674661586c270=1000.00271=3.10000000269=1278=aead437d-4b62-457f-ac83-62c7cc329fd1270=1000.00271=3.1000000010=242
20250411-01:26:20.438964000 : 8=FIXT.1.19=14135=334=2149=24ab46f784d1b20db435b852086e325052=20250411-01:26:20.43856=Coinbase45=3058=Tag appears more than once371=269372=W373=1310=241
20250411-01:26:20.439083000 : 8=FIXT.1.19=93835=W49=Coinbase56=24ab46f784d1b20db435b852086e325034=3150=TEST52=20250411-01:26:20.084916369=2262=50bb03be-debb-4b06-bc08-08dd0205dd0883=1597540453893=N55=BTC-USD1682=full_trading268=10269=1278=af5d47bc-a008-4567-b24f-b0298f250471270=1000.00271=3.10000000269=1278=4c260f58-c427-4a9a-969a-44024ae0c714270=1000.00271=3.10000000269=1278=8c7672e5-7ee8-4fbd-8fdf-7e74e9a77db7270=1000.00271=3.10000000269=1278=b53ec3cc-9abe-4570-b903-34d52148073e270=1000.00271=3.10000000269=1278=37ce984a-0387-4ac9-9094-b83f722036ba270=1000.00271=3.10000000269=1278=0d383649-dc6c-4df2-b821-aa0018f132c7270=1000.00271=3.10000000269=1278=e39ae0ce-9e7f-4f0d-a765-5308d473bb61270=1000.00271=3.10000000269=1278=4882324e-3b5c-4b7a-b096-e8c6d9888671270=1000.00271=3.10000000269=1278=6e5c7dbd-a2cc-401f-a5b2-3902088f4ab2270=1000.00271=3.10000000269=1278=10ffac08-946a-4a30-b57a-0d78450345d9270=1000.00271=3.1000000010=033
20250411-01:26:20.439896000 : 8=FIXT.1.19=14135=334=2249=24ab46f784d1b20db435b852086e325052=20250411-01:26:20.43956=Coinbase45=3158=Tag appears more than once371=269372=W373=1310=244
20250411-01:26:20.439997000 : 8=FIXT.1.19=93835=W49=Coinbase56=24ab46f784d1b20db435b852086e325034=3250=TEST52=20250411-01:26:20.085166369=2262=50bb03be-debb-4b06-bc08-08dd0205dd0883=1597540453893=N55=BTC-USD1682=full_trading268=10269=1278=67784af5-72bf-4d16-a6b3-25336e2c1843270=1000.00271=3.10000000269=1278=4d8b3bbc-0dc2-4044-875c-c079ec538136270=1000.00271=3.10000000269=1278=dfba5f1e-21f5-48e3-adce-b8b6bfe71467270=1000.00271=3.10000000269=1278=e51b4e33-5eaa-46ef-936b-a74a890397e8270=1000.00271=3.10000000269=1278=8cf5dfa8-858b-48a3-9d94-78522c257473270=1000.00271=3.10000000269=1278=a153b9d2-993d-4f03-a974-b8a081e128e8270=1000.00271=3.10000000269=1278=1eebe866-0f6e-4d4a-a28b-78f4e3368b0a270=1000.00271=3.10000000269=1278=300132d8-113f-4bf7-ba0c-4d93a272f55b270=1000.00271=3.10000000269=1278=757f3122-27d2-4f32-90b8-ead1eef9b936270=1000.00271=3.10000000269=1278=2b68b5de-4153-4cac-ace3-102e4fa788fd270=1000.00271=3.1000000010=175
20250411-01:26:20.440812000 : 8=FIXT.1.19=14135=334=2349=24ab46f784d1b20db435b852086e325052=20250411-01:26:20.44056=Coinbase45=3258=Tag appears more than once371=269372=W373=1310=238
20250411-01:26:20.440909000 : 8=FIXT.1.19=93835=W49=Coinbase56=24ab46f784d1b20db435b852086e325034=3350=TEST52=20250411-01:26:20.085416369=2262=50bb03be-debb-4b06-bc08-08dd0205dd0883=1597540453893=N55=BTC-USD1682=full_trading268=10269=1278=b01f252a-1657-4df0-a122-58a23109a7c2270=1000.00271=3.10000000269=1278=dbc57e4e-6abd-4d66-8d18-bd13caaa77b1270=1000.00271=3.10000000269=1278=948b05dc-a481-409f-b8ad-a502eb595906270=1000.00271=3.10000000269=1278=e00f9703-6e16-4237-a2c6-701829d11bf1270=1000.00271=3.10000000269=1278=fd52f47a-3f11-47bc-9952-9708617d0ecd270=1000.00271=3.10000000269=1278=f7f75b14-27c3-469c-89fb-6a98b43c61bf270=1000.00271=3.10000000269=1278=25dbeb09-7901-4280-b0c3-720d7ed03d7d270=1000.00271=3.10000000269=1278=52164a1f-599f-4c43-a9ed-f93403506e67270=1000.00271=3.10000000269=1278=c71c35ea-f60f-4a41-b43a-4947bbcbafad270=1000.00271=3.10000000269=1278=2de342bc-a1be-46f3-9fc6-731297726934270=1000.00271=3.1000000010=176
20250411-01:26:20.441815000 : 8=FIXT.1.19=14135=334=2449=24ab46f784d1b20db435b852086e325052=20250411-01:26:20.44156=Coinbase45=3358=Tag appears more than once371=269372=W373=1310=241
20250411-01:26:20.441942000 : 8=FIXT.1.19=93835=W49=Coinbase56=24ab46f784d1b20db435b852086e325034=3450=TEST52=20250411-01:26:20.085666369=2262=50bb03be-debb-4b06-bc08-08dd0205dd0883=1597540453893=N55=BTC-USD1682=full_trading268=10269=1278=7ff4c5fc-bc9b-4845-940b-4837a672e13a270=1000.00271=3.10000000269=1278=2d270775-33eb-4328-8dad-7d206612f9f6270=1000.00271=3.10000000269=1278=c4754378-f787-4100-81af-564443a86a91270=1000.00271=3.10000000269=1278=59e16255-05eb-4fdc-8be1-3c4f83fc094e270=1000.00271=3.10000000269=1278=041b2f98-1185-49cb-964a-f0456b71e692270=1000.00271=3.10000000269=1278=9a2f3529-481e-4e50-a123-7a2095fe6b2c270=1000.00271=3.10000000269=1278=9ed552a3-3295-4878-85dd-87b7b5590212270=1000.00271=3.10000000269=1278=54bec5c2-bafd-4d7d-851d-59e3553a053f270=1000.00271=3.10000000269=1278=543c1acf-52f2-442b-a893-f7aa9a5dfbd1270=1000.00271=3.10000000269=1278=fec999be-cbd0-42ef-b9c3-82ca92ef0b58270=1000.00271=3.1000000010=083
20250411-01:26:20.442916000 : 8=FIXT.1.19=14135=334=2549=24ab46f784d1b20db435b852086e325052=20250411-01:26:20.44256=Coinbase45=3458=Tag appears more than once371=269372=W373=1310=244
20250411-01:26:20.443025000 : 8=FIXT.1.19=93835=W49=Coinbase56=24ab46f784d1b20db435b852086e325034=3550=TEST52=20250411-01:26:20.085916369=2262=50bb03be-debb-4b06-bc08-08dd0205dd0883=1597540453893=N55=BTC-USD1682=full_trading268=10269=1278=24528176-3fc6-45b2-b2f3-9f784c01495a270=1000.00271=3.10000000269=1278=12081678-66a6-4435-a3d7-b65f959cf2ac270=1000.00271=3.10000000269=1278=e7fb6165-8f1a-4b5e-b095-e232b83ee951270=1000.00271=3.10000000269=1278=83ce6582-410a-40bf-9831-8f3d20e3a629270=1000.00271=3.10000000269=1278=bc3a930b-0567-46ba-86a4-712f76466b0b270=1000.00271=3.10000000269=1278=15704973-f5ff-457d-ab31-8f99bb76bf7e270=1000.00271=3.10000000269=1278=7159045b-cbd5-458f-b91f-9fa5241b14b5270=1000.00271=3.10000000269=1278=9fa52a90-f03f-4940-b5ee-39ab937b86f1270=1000.00271=3.10000000269=1278=220f55cd-a279-4bf0-9c80-1dca086d85dc270=1000.00271=3.10000000269=1278=2b1eb468-6bcd-4117-a7c0-214d643ddad4270=1000.00271=3.1000000010=203
20250411-01:26:20.443926000 : 8=FIXT.1.19=14135=334=2649=24ab46f784d1b20db435b852086e325052=20250411-01:26:20.44356=Coinbase45=3558=Tag appears more than once371=269372=W373=1310=247
20250411-01:26:20.444051000 : 8=FIXT.1.19=93835=W49=Coinbase56=24ab46f784d1b20db435b852086e325034=3650=TEST52=20250411-01:26:20.086166369=2262=50bb03be-debb-4b06-bc08-08dd0205dd0883=1597540453893=N55=BTC-USD1682=full_trading268=10269=1278=cc23185d-e72e-42cb-8210-61bab29cd778270=1000.00271=3.10000000269=1278=69bb228b-973b-4176-8708-3231cc40102a270=1000.00271=3.10000000269=1278=2ec8035d-7962-4195-8388-c9fbad52ac8a270=1000.00271=3.10000000269=1278=7d39e416-0b7b-471f-a9ac-455ab1bce5a7270=1000.00271=3.10000000269=1278=7067378d-2a65-41f2-acb0-ef30ddbc3e5a270=1000.00271=3.10000000269=1278=bf3fde78-6cff-4477-b381-4b5d2e68f36f270=1000.00271=3.10000000269=1278=93a2a8a3-61d4-410c-9446-8eabaafc5f29270=1000.00271=3.10000000269=1278=5afddb61-63ab-417b-a28a-41c4c03a6612270=1000.00271=3.10000000269=1278=a4280417-189c-4f76-9d2e-6ec652010bf5270=1000.00271=3.10000000269=1278=ddeb78a2-e110-4828-ba3d-c9b4837e7dd7270=1000.00271=3.1000000010=215
20250411-01:26:20.444885000 : 8=FIXT.1.19=14135=334=2749=24ab46f784d1b20db435b852086e325052=20250411-01:26:20.44456=Coinbase45=3658=Tag appears more than once371=269372=W373=1310=250
20250411-01:26:20.444987000 : 8=FIXT.1.19=93835=W49=Coinbase56=24ab46f784d1b20db435b852086e325034=3750=TEST52=20250411-01:26:20.086417369=2262=50bb03be-debb-4b06-bc08-08dd0205dd0883=1597540453893=N55=BTC-USD1682=full_trading268=10269=1278=fcec6c90-441a-4f4a-a94e-9003355657ef270=1000.00271=3.10000000269=1278=6db15389-dfb3-4156-8a4e-ce2ac80f2b15270=1000.00271=3.10000000269=1278=47dfefc3-6f05-4b57-8aec-2bf3e6c70c2d270=1000.00271=3.10000000269=1278=fb9fd019-4b4f-4880-82bb-3df6d1ef468a270=1000.00271=3.10000000269=1278=2cff9acd-42cb-43a5-8d50-51e676b7e763270=1000.00271=3.10000000269=1278=6e6eeb59-4728-4811-9a44-c857df6aca42270=1000.00271=3.10000000269=1278=81798560-263f-4819-a528-5f3fbbc7b042270=1000.00271=3.10000000269=1278=81fbf9a8-82f4-4fe4-9fa5-3773b212ebf4270=1000.00271=3.10000000269=1278=5d3b9566-276d-47fe-a111-12c17f53f501270=1000.00271=3.10000000269=1278=8eb1b3b3-c813-48b1-b839-993672108d91270=1000.00271=3.1000000010=114
20250411-01:26:20.445809000 : 8=FIXT.1.19=14135=334=2849=24ab46f784d1b20db435b852086e325052=20250411-01:26:20.44556=Coinbase45=3758=Tag appears more than once371=269372=W373=1310=253
20250411-01:26:20.445912000 : 8=FIXT.1.19=93835=W49=Coinbase56=24ab46f784d1b20db435b852086e325034=3850=TEST52=20250411-01:26:20.086667369=2262=50bb03be-debb-4b06-bc08-08dd0205dd0883=1597540453893=N55=BTC-USD1682=full_trading268=10269=1278=4feb6e93-6149-481b-8d58-e1c8e6c5cda1270=1000.00271=3.10000000269=1278=f8611e72-4056-4b7c-9779-4d54cd151d44270=1000.00271=3.10000000269=1278=7a129f7c-d9ba-4ea3-a267-b7d82b2e07d9270=1000.00271=3.10000000269=1278=01f359f0-c38f-416b-af00-183907218793270=1000.00271=3.10000000269=1278=11741cec-9c08-4a20-99dc-6b9f63130b0e270=1000.00271=3.10000000269=1278=08db2574-ad52-4520-ab5b-c3c7591eb781270=1000.00271=3.10000000269=1278=b06f2249-179c-4a15-8e98-7b76083b808b270=1000.00271=3.10000000269=1278=9e88fede-6d19-4c1f-863b-5a7d66781436270=1000.00271=3.10000000269=1278=75e1d8b4-7201-41fe-a687-7d93420af323270=1000.00271=3.10000000269=1278=d00aa7dd-ce7f-4f8b-9a2e-880c1ea30845270=1000.00271=3.1000000010=139
20250411-01:26:20.446797000 : 8=FIXT.1.19=14135=334=2949=24ab46f784d1b20db435b852086e325052=20250411-01:26:20.44656=Coinbase45=3858=Tag appears more than once371=269372=W373=1310=000
20250411-01:26:20.446992000 : 8=FIXT.1.19=93835=W49=Coinbase56=24ab46f784d1b20db435b852086e325034=3950=TEST52=20250411-01:26:20.086916369=2262=50bb03be-debb-4b06-bc08-08dd0205dd0883=1597540453893=N55=BTC-USD1682=full_trading268=10269=1278=584a483f-23bf-4d8b-809f-69cf3c110f60270=1000.00271=3.10000000269=1278=dc98524e-27e2-4863-99e4-7a0097a6ee90270=1000.00271=3.10000000269=1278=82a11ac9-4f46-44b7-a0bc-a5a4cfe686e0270=1000.00271=3.10000000269=1278=f946bb05-900c-41fc-9908-41489e97ff20270=1000.00271=3.10000000269=1278=1f9186d6-0312-4677-ba96-fdb014cdff2c270=1000.00271=3.10000000269=1278=c3b67be7-2b63-4884-b311-80f28496c2c4270=1000.00271=3.10000000269=1278=6576c7f8-a4e2-4417-b854-5fef0e705fbe270=1000.00271=3.10000000269=1278=c2102c71-62f0-4eee-ae60-0777ed26a8e6270=1000.00271=3.10000000269=1278=c823a2b6-849e-4839-a2fd-cd9f459cae6c270=1000.00271=3.10000000269=1278=a051e195-4472-4a8a-8591-08a2c04a33c4270=1000.00271=3.1000000010=030
20250411-01:26:20.447832000 : 8=FIXT.1.19=14135=334=3049=24ab46f784d1b20db435b852086e325052=20250411-01:26:20.44756=Coinbase45=3958=Tag appears more than once371=269372=W373=1310=250
20250411-01:26:20.447929000 : 8=FIXT.1.19=93835=W49=Coinbase56=24ab46f784d1b20db435b852086e325034=4050=TEST52=20250411-01:26:20.087167369=2262=50bb03be-debb-4b06-bc08-08dd0205dd0883=1597540453893=N55=BTC-USD1682=full_trading268=10269=1278=ec81b8c4-b703-4afd-a701-ce34011f60f6270=1000.00271=3.10000000269=1278=b1172677-f493-4f32-a200-0710cf8c397f270=1000.00271=3.10000000269=1278=b1a58a75-5fca-43db-b9c6-a26920e8f66e270=1000.00271=3.10000000269=1278=038bea41-b91d-4884-b992-3e5431ef9857270=1000.00271=3.10000000269=1278=55063782-f2ea-4c84-9491-8e8e89d1dfd1270=1000.00271=3.10000000269=1278=bb2011e8-d05d-40ac-9e9c-3b720422e38d270=1000.00271=3.10000000269=1278=64dd3b4a-ce8a-4b63-9937-266e832c0f21270=1000.00271=3.10000000269=1278=d64f7d2a-aa83-486c-92a8-3314c4eddd58270=1000.00271=3.10000000269=1278=0df9641b-d89d-4222-a8ea-bcddf0d555f5270=1000.00271=3.10000000269=1278=7a315b16-a05f-408d-b8c1-2704af9bf767270=1000.00271=3.1000000010=009
20250411-01:26:20.448785000 : 8=FIXT.1.19=14135=334=3149=24ab46f784d1b20db435b852086e325052=20250411-01:26:20.44856=Coinbase45=4058=Tag appears more than once371=269372=W373=1310=244
20250411-01:26:20.448962000 : 8=FIXT.1.19=93835=W49=Coinbase56=24ab46f784d1b20db435b852086e325034=4150=TEST52=20250411-01:26:20.087417369=2262=50bb03be-debb-4b06-bc08-08dd0205dd0883=1597540453893=N55=BTC-USD1682=full_trading268=10269=1278=0e9712a8-d00f-4864-a478-f7f591718f91270=1000.00271=3.10000000269=1278=94db025d-eada-49e3-b13c-b667ca07f829270=1000.00271=3.10000000269=1278=a88ccd1f-8f8d-46af-8fb6-20adba35f7d1270=1000.00271=3.10000000269=1278=99d4e235-c8ec-4efc-938c-9a1923eafc96270=1000.00271=3.10000000269=1278=a4fc7173-7583-4f8b-b256-2921bef83c84270=1000.00271=3.10000000269=1278=18f8afd4-8bbc-4ffa-8e8f-0c1834d74472270=1000.00271=3.10000000269=1278=21fc8cb6-f894-4d09-884e-810b8ebf2ef3270=1000.00271=3.10000000269=1278=0c13b9e6-6797-4b3e-90ce-a1885b26ba53270=1000.00271=3.10000000269=1278=6d8da581-3998-4fc0-99b6-3c5edbd514cb270=1000.00271=3.10000000269=1278=67a70307-be50-4065-872b-47e0de473bc4270=1000.00271=3.1000000010=190
20250411-01:26:20.449825000 : 8=FIXT.1.19=14135=334=3249=24ab46f784d1b20db435b852086e325052=20250411-01:26:20.44956=Coinbase45=4158=Tag appears more than once371=269372=W373=1310=247
20250411-01:26:20.449949000 : 8=FIXT.1.19=93835=W49=Coinbase56=24ab46f784d1b20db435b852086e325034=4250=TEST52=20250411-01:26:20.087667369=2262=50bb03be-debb-4b06-bc08-08dd0205dd0883=1597540453893=N55=BTC-USD1682=full_trading268=10269=1278=8ce7be0b-98de-46d0-b1b6-307a4bec36e2270=1000.00271=3.10000000269=1278=856b22f8-5884-4739-adc0-bdd851c5c07d270=1000.00271=3.10000000269=1278=c00ae651-a76b-4bfd-be16-3672b345fe29270=1000.00271=3.10000000269=1278=cae248f9-16fc-44ea-9b79-1dacfc285db6270=1000.00271=3.10000000269=1278=42bb223c-88c6-4a18-8ff3-4fd8d9efda8d270=1000.00271=3.10000000269=1278=d7188b01-22b6-4837-a720-077601f7f483270=1000.00271=3.10000000269=1278=5d85a0a6-ddd9-4e0e-9a1a-7f418ef588e5270=1000.00271=3.10000000269=1278=bff4c39f-7a80-42ce-a178-b1221792e445270=1000.00271=3.10000000269=1278=9ea3d263-b5ab-46c5-bf27-8c0e3e0e5e9e270=1000.00271=3.10000000269=1278=b93347df-d2ab-48ec-b326-4454e64f1d4e270=1000.00271=3.1000000010=160
20250411-01:26:20.451314000 : 8=FIXT.1.19=14135=334=3349=24ab46f784d1b20db435b852086e325052=20250411-01:26:20.45056=Coinbase45=4258=Tag appears more than once371=269372=W373=1310=241
20250411-01:26:20.451490000 : 8=FIXT.1.19=93835=W49=Coinbase56=24ab46f784d1b20db435b852086e325034=4350=TEST52=20250411-01:26:20.087917369=2262=50bb03be-debb-4b06-bc08-08dd0205dd0883=1597540453893=N55=BTC-USD1682=full_trading268=10269=1278=57acc40d-8478-444a-990f-067a8e8e846e270=1000.00271=3.10000000269=1278=34419ae2-2c16-427b-a290-845419760fd5270=1000.00271=3.10000000269=1278=ab41de2d-5def-4986-b56e-243d2f99a57c270=1000.00271=3.10000000269=1278=9025524c-03a9-407a-a58a-5258c4ea0a0b270=1000.00271=3.10000000269=1278=60766318-112b-4d83-a384-55693de75519270=1000.00271=3.10000000269=1278=c19b6a2c-086b-4fc1-8dfe-51cb2dc12c1d270=1000.00271=3.10000000269=1278=11126433-0f9c-4450-a35a-39b878e85e68270=1000.00271=3.10000000269=1278=e2e620ee-44fb-4630-a890-d331ba5b2fae270=1000.00271=3.10000000269=1278=9ccf6d4b-a6ca-4a1f-a7bb-77f400ace0c8270=1000.00271=3.10000000269=1278=0e8d6c10-8421-4f19-97dc-d70e715d9033270=1000.00271=3.1000000010=212
20250411-01:26:20.452611000 : 8=FIXT.1.19=14135=334=3449=24ab46f784d1b20db435b852086e325052=20250411-01:26:20.45156=Coinbase45=4358=Tag appears more than once371=269372=W373=1310=244
20250411-01:26:20.452724000 : 8=FIXT.1.19=93835=W49=Coinbase56=24ab46f784d1b20db435b852086e325034=4450=TEST52=20250411-01:26:20.088167369=2262=50bb03be-debb-4b06-bc08-08dd0205dd0883=1597540453893=N55=BTC-USD1682=full_trading268=10269=1278=f31ecd5d-8231-44ea-a5c2-0fcc5a699401270=1000.00271=3.10000000269=1278=37fbb559-dc52-48fe-ab65-24910edc338a270=1000.00271=3.10000000269=1278=bc1435c5-c59c-4017-9e59-f1073f04c7e2270=1000.00271=3.10000000269=1278=9c8e1397-0cee-4b05-a66f-5594040791c4270=1000.00271=3.10000000269=1278=248b6703-f829-42bb-a551-4be3075c381e270=1000.00271=3.10000000269=1278=16d257b0-bc92-44f0-822d-3eba61af4bda270=1000.00271=3.10000000269=1278=06257aa1-4043-4cdb-9286-4342b8e59108270=1000.00271=3.10000000269=1278=210ec210-1443-47dc-9e43-9c9ea720a6c3270=1000.00271=3.10000000269=1278=8b79da5d-b78c-4011-b55f-b35c16dc3724270=1000.00271=3.10000000269=1278=076c3703-1104-4e15-a38a-d95bf133f0c5270=1000.00271=3.1000000010=222
20250411-01:26:20.453611000 : 8=FIXT.1.19=14135=334=3549=24ab46f784d1b20db435b852086e325052=20250411-01:26:20.45356=Coinbase45=4458=Tag appears more than once371=269372=W373=1310=248
20250411-01:26:20.453757000 : 8=FIXT.1.19=93835=W49=Coinbase56=24ab46f784d1b20db435b852086e325034=4550=TEST52=20250411-01:26:20.088417369=2262=50bb03be-debb-4b06-bc08-08dd0205dd0883=1597540453893=N55=BTC-USD1682=full_trading268=10269=1278=f5a3155c-e449-4102-870d-ab8c8dd24c3d270=1000.00271=3.10000000269=1278=1af2681f-2dec-4d25-aaeb-89b8867b4a3c270=1000.00271=3.10000000269=1278=65c3088d-192a-4213-85a3-7257aa8b20a3270=1000.00271=3.10000000269=1278=2aa7989b-5601-4899-8143-01dda3255e4f270=1000.00271=3.10000000269=1278=099b432c-fa2e-4fd7-952e-22f6debf6877270=1000.00271=3.10000000269=1278=2e71cc31-1235-4b7b-a728-e3335631fe5a270=1000.00271=3.10000000269=1278=ce471ffc-1e26-4afe-afab-27ee5ac8debe270=1000.00271=3.10000000269=1278=113b7fc6-8574-40eb-8682-d077245b84f2270=1000.00271=3.10000000269=1278=bcebce2c-eda8-4b85-841d-27ede39fc5a1270=1000.00271=3.10000000269=1278=0aedaae5-6cc6-4a34-8e48-5e67a5ccc148270=1000.00271=3.1000000010=064
20250411-01:26:20.454748000 : 8=FIXT.1.19=14135=334=3649=24ab46f784d1b20db435b852086e325052=20250411-01:26:20.45456=Coinbase45=4558=Tag appears more than once371=269372=W373=1310=251
20250411-01:26:20.454861000 : 8=FIXT.1.19=93835=W49=Coinbase56=24ab46f784d1b20db435b852086e325034=4650=TEST52=20250411-01:26:20.088667369=2262=50bb03be-debb-4b06-bc08-08dd0205dd0883=1597540453893=N55=BTC-USD1682=full_trading268=10269=1278=206e10a5-1173-4860-87b5-7c88afe061f6270=1000.00271=3.10000000269=1278=5c32d94b-696a-4d9b-afa0-665970356008270=1000.00271=3.10000000269=1278=0b7da819-cc1e-4525-a382-ce5b90dc485c270=1000.00271=3.10000000269=1278=2241b3bf-cbbe-44f2-ac75-8032f6283aa8270=1000.00271=3.10000000269=1278=88cada69-adb1-466a-afcd-66e063ad27c0270=1000.00271=3.10000000269=1278=34a52ef5-31c1-4c63-9230-21c85a9a6ba3270=1000.00271=3.10000000269=1278=e109c2c8-fb1d-4ef9-a640-368381323507270=1000.00271=3.10000000269=1278=38fd36c4-4c62-4b4c-8f24-1fe39be94fa1270=1000.00271=3.10000000269=1278=f83f64c8-7d33-472d-a516-9b664ff9c966270=1000.00271=3.10000000269=1278=3411c368-380b-42e6-b656-8552d92904d5270=1000.00271=3.1000000010=094
20250411-01:26:20.456225000 : 8=FIXT.1.19=14135=334=3749=24ab46f784d1b20db435b852086e325052=20250411-01:26:20.45556=Coinbase45=4658=Tag appears more than once371=269372=W373=1310=254
20250411-01:26:20.456365000 : 8=FIXT.1.19=93835=W49=Coinbase56=24ab46f784d1b20db435b852086e325034=4750=TEST52=20250411-01:26:20.088917369=2262=50bb03be-debb-4b06-bc08-08dd0205dd0883=1597540453893=N55=BTC-USD1682=full_trading268=10269=1278=4803796e-79f3-4aa4-a8cb-37f13899bf01270=1000.00271=3.10000000269=1278=823f8fbf-7e6d-4ae3-adb9-3a822ff6d09a270=1000.00271=3.10000000269=1278=135624df-a204-490f-a68b-63d74ee09908270=1000.00271=3.10000000269=1278=47cfdedf-22b9-402c-93bd-f311103fd3e0270=1000.00271=3.10000000269=1278=f9173d5e-d872-4661-93f6-28f527e931f7270=1000.00271=3.10000000269=1278=06ab1365-fd39-4701-bd7f-1915ad3c7602270=1000.00271=3.10000000269=1278=012a7c59-5ae4-4da5-97ba-2e3254c889fb270=1000.00271=3.10000000269=1278=a9a0d42f-ad9e-4ea9-8bf0-d5a441fded40270=1000.00271=3.10000000269=1278=f3f3930e-be0e-40b4-a97d-d19501a54885270=1000.00271=3.10000000269=1278=261922d0-5c81-4ab6-832f-4eff45f64890270=1000.00271=3.1000000010=052
20250411-01:26:20.457564000 : 8=FIXT.1.19=14135=334=3849=24ab46f784d1b20db435b852086e325052=20250411-01:26:20.45656=Coinbase45=4758=Tag appears more than once371=269372=W373=1310=001
20250411-01:26:20.457742000 : 8=FIXT.1.19=93835=W49=Coinbase56=24ab46f784d1b20db435b852086e325034=4850=TEST52=20250411-01:26:20.089167369=2262=50bb03be-debb-4b06-bc08-08dd0205dd0883=1597540453893=N55=BTC-USD1682=full_trading268=10269=1278=3af4e45f-56f6-4c69-894d-d56a14894a98270=1000.00271=3.10000000269=1278=1c1dd248-49e4-44aa-9e69-323b0f41fa0e270=1000.00271=3.10000000269=1278=b16b002d-1cd6-4869-9c1b-f15c758611bf270=1000.00271=3.10000000269=1278=a0520e61-28ad-448d-87c1-49f0c7358628270=1000.00271=3.10000000269=1278=152d0b57-086f-48cc-80b3-ff14ee9375ed270=1000.00271=3.10000000269=1278=c55fc264-67d2-4e9c-8cce-6c834feff648270=1000.00271=3.10000000269=1278=27361968-189a-4fa6-a3a2-eead03c640d6270=1000.00271=3.10000000269=1278=f5b01c67-f98f-44b9-a511-7f07f8883d9e270=1000.00271=3.10000000269=1278=75a5c14f-8434-4533-a10e-0bf6e92e1000270=1000.00271=3.10000000269=1278=a9b0a826-3659-4105-9ecc-21bcd27b736f270=1000.00271=3.1000000010=246
20250411-01:26:20.458718000 : 8=FIXT.1.19=14135=334=3949=24ab46f784d1b20db435b852086e325052=20250411-01:26:20.45856=Coinbase45=4858=Tag appears more than once371=269372=W373=1310=005
20250411-01:26:20.657330000 : 8=FIXT.1.19=93835=W49=Coinbase56=24ab46f784d1b20db435b852086e325034=4950=TEST52=20250411-01:26:20.089417369=2262=50bb03be-debb-4b06-bc08-08dd0205dd0883=1597540453893=N55=BTC-USD1682=full_trading268=10269=1278=1b1bab77-5c52-459b-98e3-e27ff6f8cd04270=1000.00271=3.10000000269=1278=346695f1-fe03-4364-8fc5-006796c8f82f270=1000.00271=3.10000000269=1278=cbbaa36d-2a03-45a2-a230-bd5845d832cd270=1000.00271=3.10000000269=1278=745d4fc0-6710-4c5c-97c3-7b29c4e06839270=1000.00271=3.10000000269=1278=e95fdfba-5db2-4461-8e9c-7bfdf8a9238c270=1000.00271=3.10000000269=1278=33611b39-1fbf-45cc-bf5e-a02bc1f84736270=1000.00271=3.10000000269=1278=51f77b2d-1a69-432d-934b-234eb9e1dfac270=1000.00271=3.10000000269=1278=ab09fdc3-8d50-432f-ab0f-97e8627eac24270=1000.00271=3.10000000269=1278=dde04213-6104-44c5-a811-15834c27b515270=1000.00271=3.10000000269=1278=9af2b85c-4997-4e1b-9147-7d400f059b01270=1000.00271=3.1000000010=012
20250411-01:26:20.658573000 : 8=FIXT.1.19=14135=334=4049=24ab46f784d1b20db435b852086e325052=20250411-01:26:20.65756=Coinbase45=4958=Tag appears more than once371=269372=W373=1310=255
20250411-01:26:20.658734000 : 8=FIXT.1.19=93835=W49=Coinbase56=24ab46f784d1b20db435b852086e325034=5050=TEST52=20250411-01:26:20.089667369=2262=50bb03be-debb-4b06-bc08-08dd0205dd0883=1597540453893=N55=BTC-USD1682=full_trading268=10269=1278=40870860-7a8a-4419-a117-e511f779abfa270=1000.00271=3.10000000269=1278=3e8fa7bd-dde0-4fe4-bb2e-e6279841b019270=1000.00271=3.10000000269=1278=4dde1422-98d8-405b-88df-bf245291ad7a270=1000.00271=3.10000000269=1278=6ee8b5a8-bc2f-4a0a-9ae4-7ff1b5dae941270=1000.00271=3.10000000269=1278=3ebc1f7a-2bb5-4ef0-a82f-844b9540f6e8270=1000.00271=3.10000000269=1278=a82d5bb9-1f1a-4575-b580-8d9b60863b10270=1000.00271=3.10000000269=1278=14f89bd5-0233-435c-b608-2e19131b8f6c270=1000.00271=3.10000000269=1278=a2e319e5-aab7-41d4-9d19-98d771a3f1d3270=1000.00271=3.10000000269=1278=dc965e0b-075a-4ba4-a498-02c96d1664ba270=1000.00271=3.10000000269=1278=67b6e68f-ac11-4c05-a54a-2adb555b0123270=1000.00271=3.1000000010=016
20250411-01:26:20.659597000 : 8=FIXT.1.19=14135=334=4149=24ab46f784d1b20db435b852086e325052=20250411-01:26:20.65956=Coinbase45=5058=Tag appears more than once371=269372=W373=1310=250
20250411-01:26:20.659693000 : 8=FIXT.1.19=93935=W49=Coinbase56=24ab46f784d1b20db435b852086e325034=5150=TEST52=20250411-01:26:20.089917369=2262=50bb03be-debb-4b06-bc08-08dd0205dd0883=1597540453893=N55=BTC-USD1682=full_trading268=10269=1278=866f52a1-dad9-49d7-ac4a-9da3075407a3270=1000.00271=3.10000000269=1278=0e38234d-a010-40f6-9c6f-a0d574e773cf270=1000.00271=3.10000000269=1278=d6af6749-e3c8-4938-8741-1d5f177cf8e1270=1000.00271=3.10000000269=1278=45ff5e59-2c4d-45ac-9fde-403662dfd1ca270=1000.00271=3.10000000269=1278=dcac314e-c54f-44e3-b96d-ef71539766ed270=1000.00271=3.10000000269=1278=dd6d14ea-760f-4884-a546-1d3c40ebdd7c270=1000.00271=3.10000000269=1278=4f3da0c6-46eb-4b64-b973-cc43e24abccb270=1000.00271=3.10000000269=1278=aa40cda8-4abd-4f52-999a-1a90ed5bf41a270=1000.00271=3.10000000269=1278=687ee4fc-f626-4e4f-abee-1f0ee5af3f72270=1000.00271=3.10000000269=1278=b1ad1135-67ec-4c96-99cb-a626137f3f16270=10000.00271=1.0000000010=018
20250411-01:26:20.660261000 : 8=FIXT.1.19=14135=334=4249=24ab46f784d1b20db435b852086e325052=20250411-01:26:20.65956=Coinbase45=5158=Tag appears more than once371=269372=W373=1310=252
20250411-01:26:20.660339000 : 8=FIXT.1.19=95535=W49=Coinbase56=24ab46f784d1b20db435b852086e325034=5250=TEST52=20250411-01:26:20.090167369=2262=50bb03be-debb-4b06-bc08-08dd0205dd0883=1597540453893=N55=BTC-USD1682=full_trading268=10269=1278=e9320f5f-80ae-41ab-af7a-86518d456fb0270=10000.00271=1.00000000269=1278=cd95aff0-36fa-4804-887f-2c3fce3cdc86270=10000.00271=1.00000000269=1278=fbdbcee1-8c29-4478-97df-358d209d8808270=10000.00271=1.00000000269=1278=140f39da-834b-4e42-8e15-6e25287df1f0270=900000.00271=0.00011111269=1278=49f064c5-76fe-4b38-bede-48b60a0a5aec270=900000.00271=0.00011111269=1278=681cf73b-9d37-4101-b940-9da9b1ff61ed270=900000.00271=0.00011111269=1278=3dea1587-e474-4258-b6e8-485c21b56670270=900000.00271=0.00011111269=1278=afd96a7b-3d48-459e-b810-e4ee88353a31270=900000.00271=0.00011111269=1278=a68ae029-b920-4ae7-a775-ccdb800fc252270=900000.00271=0.00001111269=1278=d44508b7-1c9f-4b4f-acb8-99c93d2b99e8270=900000.00271=0.0000111110=005
20250411-01:26:20.661045000 : 8=FIXT.1.19=14135=334=4349=24ab46f784d1b20db435b852086e325052=20250411-01:26:20.66056=Coinbase45=5258=Tag appears more than once371=269372=W373=1310=246
20250411-01:26:20.661122000 : 8=FIXT.1.19=96035=W49=Coinbase56=24ab46f784d1b20db435b852086e325034=5350=TEST52=20250411-01:26:20.090417369=2262=50bb03be-debb-4b06-bc08-08dd0205dd0883=1597540453893=N55=BTC-USD1682=full_trading268=10269=1278=304ff106-de40-4381-89c5-c93f7f3e32ae270=900000.00271=0.00001111269=1278=08a0fef8-fcbb-4857-8463-2599cf331386270=900000.00271=0.00011111269=1278=07b2856d-f899-417c-82d5-886f0d85125e270=900000.00271=0.00011111269=1278=12ecb45e-6af8-4804-a942-5c997b9d1502270=900000.00271=0.00011111269=1278=98676c5f-b851-473c-817a-b29243092a25270=900000.00271=0.00001111269=1278=09afe685-e71f-4ea0-b164-c27737db126d270=900000.00271=0.00001111269=1278=e71ee98f-c329-428d-9893-629b53015ff6270=900000.00271=0.00001111269=1278=124e6fc1-6dde-452b-be03-c00113c8ebdb270=900000.00271=0.00011111269=1278=b71cc7f5-d7c6-4fc0-a0de-59b0eb7fd063270=1000000.00271=1.00000000269=1278=afec127b-a98c-49cb-893f-e385a7e35d32270=1000000.00271=1.0000000010=231
20250411-01:26:20.661848000 : 8=FIXT.1.19=14135=334=4449=24ab46f784d1b20db435b852086e325052=20250411-01:26:20.66156=Coinbase45=5358=Tag appears more than once371=269372=W373=1310=249
20250411-01:26:20.661939000 : 8=FIXT.1.19=35135=W49=Coinbase56=24ab46f784d1b20db435b852086e325034=5450=TEST52=20250411-01:26:20.090667369=2262=50bb03be-debb-4b06-bc08-08dd0205dd0883=1597540453893=Y55=BTC-USD1682=full_trading268=2269=1278=06df7c57-366d-4d2c-acc2-e6c26d60e9c3270=1000000.00271=1.00000000269=1278=b1c4eb2b-90df-44e0-ae4f-515df4086a9d270=9999999.00271=0.0000100010=176
20250411-01:26:20.662532000 : 8=FIXT.1.19=14135=334=4549=24ab46f784d1b20db435b852086e325052=20250411-01:26:20.66256=Coinbase45=5458=Tag appears more than once371=269372=W373=1310=252
20250411-01:26:20.662612000 : 8=FIXT.1.19=27735=X49=Coinbase56=24ab46f784d1b20db435b852086e325034=5550=TEST52=20250411-01:26:20.120312369=2262=50bb03be-debb-4b06-bc08-08dd0205dd08268=1279=0269=083=159754045455=BTC-USD29004=2.208895519560=20250411-01:26:20.11897540=137=8c6d4e09-f5b4-40c0-8f93-e76a979482db10=170
20250411-01:26:20.663483000 : 8=FIXT.1.19=32535=X49=Coinbase56=24ab46f784d1b20db435b852086e325034=5650=TEST52=20250411-01:26:20.120378369=2262=50bb03be-debb-4b06-bc08-08dd0205dd08268=1279=0269=2278=c5b88ea9-605d-4595-ac52-f7c3f08523ba83=159754045555=BTC-USD270=3.55271=0.6222240960=20250411-01:26:20.11897537=8c6d4e09-f5b4-40c0-8f93-e76a979482db5797=110=073
20250411-01:26:20.664179000 : 8=FIXT.1.19=26435=X49=Coinbase56=24ab46f784d1b20db435b852086e325034=5750=TEST52=20250411-01:26:20.120388369=2262=50bb03be-debb-4b06-bc08-08dd0205dd08268=1279=2269=0278=8c6d4e09-f5b4-40c0-8f93-e76a979482db83=159754045655=BTC-USD60=20250411-01:26:20.11897558=FILLED10=199
20250411-01:26:20.666609000 : 8=FIXT.1.19=27335=X49=Coinbase56=24ab46f784d1b20db435b852086e325034=5850=TEST52=20250411-01:26:20.147758369=2262=50bb03be-debb-4b06-bc08-08dd0205dd08268=1279=0269=183=159754045755=BTC-USD271=0.6232294660=20250411-01:26:20.14652540=137=4d7a0697-e634-4487-babf-16bdac411d5310=247
20250411-01:26:20.670332000 : 8=FIXT.1.19=32535=X49=Coinbase56=24ab46f784d1b20db435b852086e325034=5950=TEST52=20250411-01:26:20.147766369=2262=50bb03be-debb-4b06-bc08-08dd0205dd08268=1279=0269=2278=4d60a78e-b39b-420e-b830-bc0f3f4fdde283=159754045855=BTC-USD270=3.53271=0.6232294660=20250411-01:26:20.14652537=4d7a0697-e634-4487-babf-16bdac411d535797=210=235
20250411-01:26:20.670581000 : 8=FIXT.1.19=27935=X49=Coinbase56=24ab46f784d1b20db435b852086e325034=6050=TEST52=20250411-01:26:20.147769369=2262=50bb03be-debb-4b06-bc08-08dd0205dd08268=1279=2269=1278=4d7a0697-e634-4487-babf-16bdac411d5383=159754045955=BTC-USD271=0.0000000060=20250411-01:26:20.14652558=FILLED10=153
20250411-01:26:20.675177000 : 8=FIXT.1.19=28235=X49=Coinbase56=24ab46f784d1b20db435b852086e325034=6150=TEST52=20250411-01:26:20.165379369=2262=50bb03be-debb-4b06-bc08-08dd0205dd08268=1279=0269=083=159754046055=BTC-USD270=3.81271=0.6232294660=20250411-01:26:20.16347240=237=3f5bfc56-aaf8-4fb0-9b56-18e3143dccc810=034
20250411-01:26:20.675527000 : 8=FIXT.1.19=32535=X49=Coinbase56=24ab46f784d1b20db435b852086e325034=6250=TEST52=20250411-01:26:20.165493369=2262=50bb03be-debb-4b06-bc08-08dd0205dd08268=1279=0269=2278=c5b88ea9-605d-4595-ac52-f7c3f08523ba83=159754046155=BTC-USD270=3.55271=0.6232294660=20250411-01:26:20.16347237=3f5bfc56-aaf8-4fb0-9b56-18e3143dccc85797=110=244
20250411-01:26:20.675789000 : 8=FIXT.1.19=28835=X49=Coinbase56=24ab46f784d1b20db435b852086e325034=6350=TEST52=20250411-01:26:20.165495369=2262=50bb03be-debb-4b06-bc08-08dd0205dd08268=1279=2269=0278=3f5bfc56-aaf8-4fb0-9b56-18e3143dccc883=159754046255=BTC-USD270=3.81271=0.0000000060=20250411-01:26:20.16347258=FILLED10=201
20250411-01:26:20.676282000 : 8=FIXT.1.19=28135=X49=Coinbase56=24ab46f784d1b20db435b852086e325034=6450=TEST52=20250411-01:26:20.220711369=2262=50bb03be-debb-4b06-bc08-08dd0205dd08268=1279=0269=183=159754046355=BTC-USD270=3.2271=0.6232294660=20250411-01:26:20.21939740=237=395352d6-fc4e-4412-bb93-4ca6ee7b86bd10=138
20250411-01:26:20.676800000 : 8=FIXT.1.19=32535=X49=Coinbase56=24ab46f784d1b20db435b852086e325034=6550=TEST52=20250411-01:26:20.220719369=2262=50bb03be-debb-4b06-bc08-08dd0205dd08268=1279=0269=2278=4d60a78e-b39b-420e-b830-bc0f3f4fdde283=159754046455=BTC-USD270=3.53271=0.6232294660=20250411-01:26:20.21939737=395352d6-fc4e-4412-bb93-4ca6ee7b86bd5797=210=029
20250411-01:26:20.677184000 : 8=FIXT.1.19=28735=X49=Coinbase56=24ab46f784d1b20db435b852086e325034=6650=TEST52=20250411-01:26:20.220723369=2262=50bb03be-debb-4b06-bc08-08dd0205dd08268=1279=2269=1278=395352d6-fc4e-4412-bb93-4ca6ee7b86bd83=159754046555=BTC-USD270=3.2271=0.0000000060=20250411-01:26:20.21939758=FILLED10=053
20250411-01:26:20.750517000 : 8=FIXT.1.19=27835=X49=Coinbase56=24ab46f784d1b20db435b852086e325034=6750=TEST52=20250411-01:26:20.634273369=39262=50bb03be-debb-4b06-bc08-08dd0205dd08268=1279=0269=083=159754046655=BTC-USD29004=2.208895519560=20250411-01:26:20.63259040=137=15c46d7f-03e8-4e0b-9d19-97a4c0512f7c10=226
20250411-01:26:20.750893000 : 8=FIXT.1.19=32635=X49=Coinbase56=24ab46f784d1b20db435b852086e325034=6850=TEST52=20250411-01:26:20.634284369=39262=50bb03be-debb-4b06-bc08-08dd0205dd08268=1279=0269=2278=c5b88ea9-605d-4595-ac52-f7c3f08523ba83=159754046755=BTC-USD270=3.55271=0.6222240960=20250411-01:26:20.63259037=15c46d7f-03e8-4e0b-9d19-97a4c0512f7c5797=110=119
20250411-01:26:20.751340000 : 8=FIXT.1.19=26535=X49=Coinbase56=24ab46f784d1b20db435b852086e325034=6950=TEST52=20250411-01:26:20.634288369=39262=50bb03be-debb-4b06-bc08-08dd0205dd08268=1279=2269=0278=15c46d7f-03e8-4e0b-9d19-97a4c0512f7c83=159754046855=BTC-USD60=20250411-01:26:20.63259058=FILLED10=248
20250411-01:26:20.778639000 : 8=FIXT.1.19=27435=X49=Coinbase56=24ab46f784d1b20db435b852086e325034=7050=TEST52=20250411-01:26:20.662545369=39262=50bb03be-debb-4b06-bc08-08dd0205dd08268=1279=0269=183=159754046955=BTC-USD271=0.6232294660=20250411-01:26:20.66136640=137=27268f3a-cae2-4732-8210-503de275961b10=109
20250411-01:26:20.779345000 : 8=FIXT.1.19=32635=X49=Coinbase56=24ab46f784d1b20db435b852086e325034=7150=TEST52=20250411-01:26:20.662551369=39262=50bb03be-debb-4b06-bc08-08dd0205dd08268=1279=0269=2278=4d60a78e-b39b-420e-b830-bc0f3f4fdde283=159754047055=BTC-USD270=3.53271=0.6232294660=20250411-01:26:20.66136637=27268f3a-cae2-4732-8210-503de275961b5797=210=086
20250411-01:26:20.780869000 : 8=FIXT.1.19=28035=X49=Coinbase56=24ab46f784d1b20db435b852086e325034=7250=TEST52=20250411-01:26:20.662554369=39262=50bb03be-debb-4b06-bc08-08dd0205dd08268=1279=2269=1278=27268f3a-cae2-4732-8210-503de275961b83=159754047155=BTC-USD271=0.0000000060=20250411-01:26:20.66136658=FILLED10=004
20250411-01:26:20.883927000 : 8=FIXT.1.19=27835=X49=Coinbase56=24ab46f784d1b20db435b852086e325034=7350=TEST52=20250411-01:26:20.753235369=39262=50bb03be-debb-4b06-bc08-08dd0205dd08268=1279=0269=083=159754047255=BTC-USD29004=2.208895519560=20250411-01:26:20.75122140=137=f4b7ac36-8b79-420d-ab46-72c5ccd674ca10=096
20250411-01:26:20.884659000 : 8=FIXT.1.19=32635=X49=Coinbase56=24ab46f784d1b20db435b852086e325034=7450=TEST52=20250411-01:26:20.753247369=39262=50bb03be-debb-4b06-bc08-08dd0205dd08268=1279=0269=2278=c5b88ea9-605d-4595-ac52-f7c3f08523ba83=159754047355=BTC-USD270=3.55271=0.6222240960=20250411-01:26:20.75122137=f4b7ac36-8b79-420d-ab46-72c5ccd674ca5797=110=246
20250411-01:26:20.885239000 : 8=FIXT.1.19=26535=X49=Coinbase56=24ab46f784d1b20db435b852086e325034=7550=TEST52=20250411-01:26:20.753250369=39262=50bb03be-debb-4b06-bc08-08dd0205dd08268=1279=2269=0278=f4b7ac36-8b79-420d-ab46-72c5ccd674ca83=159754047455=BTC-USD60=20250411-01:26:20.75122158=FILLED10=109
20250411-01:26:20.896566000 : 8=FIXT.1.19=27435=X49=Coinbase56=24ab46f784d1b20db435b852086e325034=7650=TEST52=20250411-01:26:20.780736369=45262=50bb03be-debb-4b06-bc08-08dd0205dd08268=1279=0269=183=159754047555=BTC-USD271=0.6232294660=20250411-01:26:20.77924140=137=f2b24617-e847-4392-8bbe-f6dfd053355710=231
20250411-01:26:20.897064000 : 8=FIXT.1.19=32635=X49=Coinbase56=24ab46f784d1b20db435b852086e325034=7750=TEST52=20250411-01:26:20.780756369=45262=50bb03be-debb-4b06-bc08-08dd0205dd08268=1279=0269=2278=4d60a78e-b39b-420e-b830-bc0f3f4fdde283=159754047655=BTC-USD270=3.53271=0.6232294660=20250411-01:26:20.77924137=f2b24617-e847-4392-8bbe-f6dfd05335575797=210=222
20250411-01:26:20.897688000 : 8=FIXT.1.19=28035=X49=Coinbase56=24ab46f784d1b20db435b852086e325034=7850=TEST52=20250411-01:26:20.780763369=45262=50bb03be-debb-4b06-bc08-08dd0205dd08268=1279=2269=1278=f2b24617-e847-4392-8bbe-f6dfd053355783=159754047755=BTC-USD271=0.0000000060=20250411-01:26:20.77924158=FILLED10=135
20250411-01:26:21.265727000 : 8=FIXT.1.19=27835=X49=Coinbase56=24ab46f784d1b20db435b852086e325034=7950=TEST52=20250411-01:26:21.149421369=45262=50bb03be-debb-4b06-bc08-08dd0205dd08268=1279=0269=083=159754047855=BTC-USD29004=2.208895519560=20250411-01:26:21.14738340=137=c2d294a0-7e68-4e98-ab3b-faaea6e70c1c10=202
20250411-01:26:21.266330000 : 8=FIXT.1.19=32635=X49=Coinbase56=24ab46f784d1b20db435b852086e325034=8050=TEST52=20250411-01:26:21.149430369=45262=50bb03be-debb-4b06-bc08-08dd0205dd08268=1279=0269=2278=c5b88ea9-605d-4595-ac52-f7c3f08523ba83=159754047955=BTC-USD270=3.55271=0.6222240960=20250411-01:26:21.14738337=c2d294a0-7e68-4e98-ab3b-faaea6e70c1c5797=110=084
20250411-01:26:21.266607000 : 8=FIXT.1.19=26535=X49=Coinbase56=24ab46f784d1b20db435b852086e325034=8150=TEST52=20250411-01:26:21.149480369=45262=50bb03be-debb-4b06-bc08-08dd0205dd08268=1279=2269=0278=c2d294a0-7e68-4e98-ab3b-faaea6e70c1c83=159754048055=BTC-USD60=20250411-01:26:21.14738358=FILLED10=205
20250411-01:26:21.294743000 : 8=FIXT.1.19=27435=X49=Coinbase56=24ab46f784d1b20db435b852086e325034=8250=TEST52=20250411-01:26:21.177638369=45262=50bb03be-debb-4b06-bc08-08dd0205dd08268=1279=0269=183=159754048155=BTC-USD271=0.6232294660=20250411-01:26:21.17614340=137=34ed055a-fe62-4022-89e2-6ad28f2dbd6e10=093
20250411-01:26:21.295144000 : 8=FIXT.1.19=32635=X49=Coinbase56=24ab46f784d1b20db435b852086e325034=8350=TEST52=20250411-01:26:21.177645369=45262=50bb03be-debb-4b06-bc08-08dd0205dd08268=1279=0269=2278=4d60a78e-b39b-420e-b830-bc0f3f4fdde283=159754048255=BTC-USD270=3.53271=0.6232294660=20250411-01:26:21.17614337=34ed055a-fe62-4022-89e2-6ad28f2dbd6e5797=210=080
20250411-01:26:21.295543000 : 8=FIXT.1.19=28035=X49=Coinbase56=24ab46f784d1b20db435b852086e325034=8450=TEST52=20250411-01:26:21.177648369=45262=50bb03be-debb-4b06-bc08-08dd0205dd08268=1279=2269=1278=34ed055a-fe62-4022-89e2-6ad28f2dbd6e83=159754048355=BTC-USD271=0.0000000060=20250411-01:26:21.17614358=FILLED10=254
20250411-01:26:21.323452000 : 8=FIXT.1.19=27835=X49=Coinbase56=24ab46f784d1b20db435b852086e325034=8550=TEST52=20250411-01:26:21.206948369=45262=50bb03be-debb-4b06-bc08-08dd0205dd08268=1279=0269=083=159754048455=BTC-USD29004=2.208895519560=20250411-01:26:21.20559240=137=18f4c552-a55d-412a-9e68-e5582ef7eb4910=241
20250411-01:26:21.323989000 : 8=FIXT.1.19=32635=X49=Coinbase56=24ab46f784d1b20db435b852086e325034=8650=TEST52=20250411-01:26:21.206958369=45262=50bb03be-debb-4b06-bc08-08dd0205dd08268=1279=0269=2278=c5b88ea9-605d-4595-ac52-f7c3f08523ba83=159754048555=BTC-USD270=3.55271=0.6222240960=20250411-01:26:21.20559237=18f4c552-a55d-412a-9e68-e5582ef7eb495797=110=133
20250411-01:26:21.324412000 : 8=FIXT.1.19=26535=X49=Coinbase56=24ab46f784d1b20db435b852086e325034=8750=TEST52=20250411-01:26:21.206961369=45262=50bb03be-debb-4b06-bc08-08dd0205dd08268=1279=2269=0278=18f4c552-a55d-412a-9e68-e5582ef7eb4983=159754048655=BTC-USD60=20250411-01:26:21.20559258=FILLED10=252
20250411-01:26:21.349488000 : 8=FIXT.1.19=27435=X49=Coinbase56=24ab46f784d1b20db435b852086e325034=8850=TEST52=20250411-01:26:21.234207369=45262=50bb03be-debb-4b06-bc08-08dd0205dd08268=1279=0269=183=159754048755=BTC-USD271=0.6197183160=20250411-01:26:21.23301140=137=90066184-3e55-47f3-88b9-24dd1089311710=224
20250411-01:26:21.349752000 : 8=FIXT.1.19=32635=X49=Coinbase56=24ab46f784d1b20db435b852086e325034=8950=TEST52=20250411-01:26:21.234216369=45262=50bb03be-debb-4b06-bc08-08dd0205dd08268=1279=0269=2278=4d60a78e-b39b-420e-b830-bc0f3f4fdde283=159754048855=BTC-USD270=3.53271=0.6197183160=20250411-01:26:21.23301137=90066184-3e55-47f3-88b9-24dd108931175797=210=213
20250411-01:26:21.350141000 : 8=FIXT.1.19=28035=X49=Coinbase56=24ab46f784d1b20db435b852086e325034=9050=TEST52=20250411-01:26:21.234297369=45262=50bb03be-debb-4b06-bc08-08dd0205dd08268=1279=2269=1278=90066184-3e55-47f3-88b9-24dd1089311783=159754048955=BTC-USD271=0.0000000060=20250411-01:26:21.23301158=FILLED10=126
20250411-01:26:21.551228000 : 8=FIXT.1.19=27835=X49=Coinbase56=24ab46f784d1b20db435b852086e325034=9150=TEST52=20250411-01:26:21.435202369=45262=50bb03be-debb-4b06-bc08-08dd0205dd08268=1279=0269=083=159754049055=BTC-USD29004=2.208895519560=20250411-01:26:21.43358840=137=02fdf37a-4dcb-4ab1-a479-f94b33acb78e10=190
20250411-01:26:21.552034000 : 8=FIXT.1.19=32635=X49=Coinbase56=24ab46f784d1b20db435b852086e325034=9250=TEST52=20250411-01:26:21.435209369=45262=50bb03be-debb-4b06-bc08-08dd0205dd08268=1279=0269=2278=c5b88ea9-605d-4595-ac52-f7c3f08523ba83=159754049155=BTC-USD270=3.55271=0.6222240960=20250411-01:26:21.43358837=02fdf37a-4dcb-4ab1-a479-f94b33acb78e5797=110=088
20250411-01:26:21.552653000 : 8=FIXT.1.19=26535=X49=Coinbase56=24ab46f784d1b20db435b852086e325034=9350=TEST52=20250411-01:26:21.435212369=45262=50bb03be-debb-4b06-bc08-08dd0205dd08268=1279=2269=0278=02fdf37a-4dcb-4ab1-a479-f94b33acb78e83=159754049255=BTC-USD60=20250411-01:26:21.43358858=FILLED10=207
20250411-01:26:21.579327000 : 8=FIXT.1.19=27435=X49=Coinbase56=24ab46f784d1b20db435b852086e325034=9450=TEST52=20250411-01:26:21.462643369=45262=50bb03be-debb-4b06-bc08-08dd0205dd08268=1279=0269=183=159754049355=BTC-USD271=0.6232294660=20250411-01:26:21.46104840=137=6de5ba9e-e51a-47bb-a313-ee530f97e4b710=191
20250411-01:26:21.579813000 : 8=FIXT.1.19=32635=X49=Coinbase56=24ab46f784d1b20db435b852086e325034=9550=TEST52=20250411-01:26:21.462654369=45262=50bb03be-debb-4b06-bc08-08dd0205dd08268=1279=0269=2278=4d60a78e-b39b-420e-b830-bc0f3f4fdde283=159754049455=BTC-USD270=3.53271=0.6232294660=20250411-01:26:21.46104837=6de5ba9e-e51a-47bb-a313-ee530f97e4b75797=210=182
20250411-01:26:21.580287000 : 8=FIXT.1.19=28035=X49=Coinbase56=24ab46f784d1b20db435b852086e325034=9650=TEST52=20250411-01:26:21.462657369=45262=50bb03be-debb-4b06-bc08-08dd0205dd08268=1279=2269=1278=6de5ba9e-e51a-47bb-a313-ee530f97e4b783=159754049555=BTC-USD271=0.0000000060=20250411-01:26:21.46104858=FILLED10=100
20250411-01:26:21.771064000 : 8=FIXT.1.19=28335=X49=Coinbase56=24ab46f784d1b20db435b852086e325034=9750=TEST52=20250411-01:26:21.650583369=45262=50bb03be-debb-4b06-bc08-08dd0205dd08268=1279=0269=183=159754049655=BTC-USD270=3.18271=0.6232294660=20250411-01:26:21.64910140=237=e05baf45-4f1d-49d6-999d-990bc2d9617510=191
20250411-01:26:21.771795000 : 8=FIXT.1.19=32635=X49=Coinbase56=24ab46f784d1b20db435b852086e325034=9850=TEST52=20250411-01:26:21.650590369=45262=50bb03be-debb-4b06-bc08-08dd0205dd08268=1279=0269=2278=4d60a78e-b39b-420e-b830-bc0f3f4fdde283=159754049755=BTC-USD270=3.53271=0.6232294660=20250411-01:26:21.64910137=e05baf45-4f1d-49d6-999d-990bc2d961755797=210=016
20250411-01:26:21.772210000 : 8=FIXT.1.19=28935=X49=Coinbase56=24ab46f784d1b20db435b852086e325034=9950=TEST52=20250411-01:26:21.650593369=45262=50bb03be-debb-4b06-bc08-08dd0205dd08268=1279=2269=1278=e05baf45-4f1d-49d6-999d-990bc2d9617583=159754049855=BTC-USD270=3.18271=0.0000000060=20250411-01:26:21.64910158=FILLED10=104
20250411-01:26:21.823596000 : 8=FIXT.1.19=28435=X49=Coinbase56=24ab46f784d1b20db435b852086e325034=10050=TEST52=20250411-01:26:21.705494369=45262=50bb03be-debb-4b06-bc08-08dd0205dd08268=1279=0269=083=159754049955=BTC-USD270=3.85271=0.6232294660=20250411-01:26:21.70417240=237=8e02672b-8a5a-42e4-8cda-004c8a3f8d2110=245
20250411-01:26:21.824323000 : 8=FIXT.1.19=32735=X49=Coinbase56=24ab46f784d1b20db435b852086e325034=10150=TEST52=20250411-01:26:21.705617369=45262=50bb03be-debb-4b06-bc08-08dd0205dd08268=1279=0269=2278=c5b88ea9-605d-4595-ac52-f7c3f08523ba83=159754050055=BTC-USD270=3.55271=0.6232294660=20250411-01:26:21.70417237=8e02672b-8a5a-42e4-8cda-004c8a3f8d215797=110=177
20250411-01:26:21.825085000 : 8=FIXT.1.19=29035=X49=Coinbase56=24ab46f784d1b20db435b852086e325034=10250=TEST52=20250411-01:26:21.705620369=45262=50bb03be-debb-4b06-bc08-08dd0205dd08268=1279=2269=0278=8e02672b-8a5a-42e4-8cda-004c8a3f8d2183=159754050155=BTC-USD270=3.85271=0.0000000060=20250411-01:26:21.70417258=FILLED10=121
20250411-01:26:21.893635000 : 8=FIXT.1.19=27935=X49=Coinbase56=24ab46f784d1b20db435b852086e325034=10350=TEST52=20250411-01:26:21.777648369=45262=50bb03be-debb-4b06-bc08-08dd0205dd08268=1279=0269=083=159754050255=BTC-USD29004=2.208895519560=20250411-01:26:21.77579240=137=d52472e3-2dff-4d9e-a958-5a1cae06864910=084
20250411-01:26:21.895505000 : 8=FIXT.1.19=32735=X49=Coinbase56=24ab46f784d1b20db435b852086e325034=10450=TEST52=20250411-01:26:21.777655369=45262=50bb03be-debb-4b06-bc08-08dd0205dd08268=1279=0269=2278=c5b88ea9-605d-4595-ac52-f7c3f08523ba83=159754050355=BTC-USD270=3.55271=0.6222240960=20250411-01:26:21.77579237=d52472e3-2dff-4d9e-a958-5a1cae0686495797=110=229
20250411-01:26:21.895898000 : 8=FIXT.1.19=26635=X49=Coinbase56=24ab46f784d1b20db435b852086e325034=10550=TEST52=20250411-01:26:21.777657369=45262=50bb03be-debb-4b06-bc08-08dd0205dd08268=1279=2269=0278=d52472e3-2dff-4d9e-a958-5a1cae06864983=159754050455=BTC-USD60=20250411-01:26:21.77579258=FILLED10=100
20250411-01:26:21.920341000 : 8=FIXT.1.19=27535=X49=Coinbase56=24ab46f784d1b20db435b852086e325034=10650=TEST52=20250411-01:26:21.804955369=45262=50bb03be-debb-4b06-bc08-08dd0205dd08268=1279=0269=183=159754050555=BTC-USD271=0.6197183160=20250411-01:26:21.80345940=137=88525db8-0acb-4c6a-bf12-20317a2cf7b310=126
20250411-01:26:21.920806000 : 8=FIXT.1.19=32735=X49=Coinbase56=24ab46f784d1b20db435b852086e325034=10750=TEST52=20250411-01:26:21.804966369=45262=50bb03be-debb-4b06-bc08-08dd0205dd08268=1279=0269=2278=4d60a78e-b39b-420e-b830-bc0f3f4fdde283=159754050655=BTC-USD270=3.53271=0.6197183160=20250411-01:26:21.80345937=88525db8-0acb-4c6a-bf12-20317a2cf7b35797=210=117
20250411-01:26:21.921242000 : 8=FIXT.1.19=28135=X49=Coinbase56=24ab46f784d1b20db435b852086e325034=10850=TEST52=20250411-01:26:21.804968369=45262=50bb03be-debb-4b06-bc08-08dd0205dd08268=1279=2269=1278=88525db8-0acb-4c6a-bf12-20317a2cf7b383=159754050755=BTC-USD271=0.0000000060=20250411-01:26:21.80345958=FILLED10=032
20250411-01:26:22.121985000 : 8=FIXT.1.19=27935=X49=Coinbase56=24ab46f784d1b20db435b852086e325034=10950=TEST52=20250411-01:26:22.005951369=45262=50bb03be-debb-4b06-bc08-08dd0205dd08268=1279=0269=083=159754050855=BTC-USD29004=2.208895519560=20250411-01:26:22.00398840=137=d3e93dcd-7493-48f6-a402-bcb0a17fa1dd10=191
20250411-01:26:22.122723000 : 8=FIXT.1.19=32735=X49=Coinbase56=24ab46f784d1b20db435b852086e325034=11050=TEST52=20250411-01:26:22.005963369=45262=50bb03be-debb-4b06-bc08-08dd0205dd08268=1279=0269=2278=c5b88ea9-605d-4595-ac52-f7c3f08523ba83=159754050955=BTC-USD270=3.55271=0.6222240960=20250411-01:26:22.00398837=d3e93dcd-7493-48f6-a402-bcb0a17fa1dd5797=110=076
20250411-01:26:22.123339000 : 8=FIXT.1.19=26635=X49=Coinbase56=24ab46f784d1b20db435b852086e325034=11150=TEST52=20250411-01:26:22.006056369=45262=50bb03be-debb-4b06-bc08-08dd0205dd08268=1279=2269=0278=d3e93dcd-7493-48f6-a402-bcb0a17fa1dd83=159754051055=BTC-USD60=20250411-01:26:22.00398858=FILLED10=186
20250411-01:26:22.151651000 : 8=FIXT.1.19=27535=X49=Coinbase56=24ab46f784d1b20db435b852086e325034=11250=TEST52=20250411-01:26:22.035829369=45262=50bb03be-debb-4b06-bc08-08dd0205dd08268=1279=0269=183=159754051155=BTC-USD271=0.6232294660=20250411-01:26:22.03422240=137=bd222214-5a95-4d64-9aa9-8bdf7ea93edd10=173
20250411-01:26:22.152187000 : 8=FIXT.1.19=32735=X49=Coinbase56=24ab46f784d1b20db435b852086e325034=11350=TEST52=20250411-01:26:22.035838369=45262=50bb03be-debb-4b06-bc08-08dd0205dd08268=1279=0269=2278=4d60a78e-b39b-420e-b830-bc0f3f4fdde283=159754051255=BTC-USD270=3.53271=0.6232294660=20250411-01:26:22.03422237=bd222214-5a95-4d64-9aa9-8bdf7ea93edd5797=210=162
20250411-01:26:22.152682000 : 8=FIXT.1.19=28135=X49=Coinbase56=24ab46f784d1b20db435b852086e325034=11450=TEST52=20250411-01:26:22.035841369=45262=50bb03be-debb-4b06-bc08-08dd0205dd08268=1279=2269=1278=bd222214-5a95-4d64-9aa9-8bdf7ea93edd83=159754051355=BTC-USD271=0.0000000060=20250411-01:26:22.03422258=FILLED10=071
20250411-01:26:22.978212000 : 8=FIXT.1.19=27935=X49=Coinbase56=24ab46f784d1b20db435b852086e325034=11550=TEST52=20250411-01:26:22.862520369=45262=50bb03be-debb-4b06-bc08-08dd0205dd08268=1279=0269=083=159754051455=BTC-USD29004=2.208895519560=20250411-01:26:22.86121040=137=1e981f1f-7c4b-4665-99ed-a182ff9e680010=018
20250411-01:26:22.978580000 : 8=FIXT.1.19=32735=X49=Coinbase56=24ab46f784d1b20db435b852086e325034=11650=TEST52=20250411-01:26:22.862528369=45262=50bb03be-debb-4b06-bc08-08dd0205dd08268=1279=0269=2278=c5b88ea9-605d-4595-ac52-f7c3f08523ba83=159754051555=BTC-USD270=3.55271=0.6222240960=20250411-01:26:22.86121037=1e981f1f-7c4b-4665-99ed-a182ff9e68005797=110=173
20250411-01:26:22.978803000 : 8=FIXT.1.19=26635=X49=Coinbase56=24ab46f784d1b20db435b852086e325034=11750=TEST52=20250411-01:26:22.862530369=45262=50bb03be-debb-4b06-bc08-08dd0205dd08268=1279=2269=0278=1e981f1f-7c4b-4665-99ed-a182ff9e680083=159754051655=BTC-USD60=20250411-01:26:22.86121058=FILLED10=035
20250411-01:26:23.006165000 : 8=FIXT.1.19=27535=X49=Coinbase56=24ab46f784d1b20db435b852086e325034=11850=TEST52=20250411-01:26:22.891043369=45262=50bb03be-debb-4b06-bc08-08dd0205dd08268=1279=0269=183=159754051755=BTC-USD271=0.6232294660=20250411-01:26:22.88973240=137=59d93543-22de-4e18-ab8e-e21a16d9884210=020
20250411-01:26:23.006757000 : 8=FIXT.1.19=32735=X49=Coinbase56=24ab46f784d1b20db435b852086e325034=11950=TEST52=20250411-01:26:22.891133369=45262=50bb03be-debb-4b06-bc08-08dd0205dd08268=1279=0269=2278=4d60a78e-b39b-420e-b830-bc0f3f4fdde283=159754051855=BTC-USD270=3.53271=0.6232294660=20250411-01:26:22.88973237=59d93543-22de-4e18-ab8e-e21a16d988425797=210=009
20250411-01:26:23.007238000 : 8=FIXT.1.19=28135=X49=Coinbase56=24ab46f784d1b20db435b852086e325034=12050=TEST52=20250411-01:26:22.891137369=45262=50bb03be-debb-4b06-bc08-08dd0205dd08268=1279=2269=1278=59d93543-22de-4e18-ab8e-e21a16d9884283=159754051955=BTC-USD271=0.0000000060=20250411-01:26:22.88973258=FILLED10=175
20250411-01:26:23.139175000 : 8=FIXT.1.19=28335=X49=Coinbase56=24ab46f784d1b20db435b852086e325034=12150=TEST52=20250411-01:26:23.022991369=45262=50bb03be-debb-4b06-bc08-08dd0205dd08268=1279=0269=183=159754052055=BTC-USD270=3.3271=0.6232294660=20250411-01:26:23.02108140=237=b0d80b53-3f1d-446e-92a7-1d27ddb4d53910=171
20250411-01:26:23.139666000 : 8=FIXT.1.19=32735=X49=Coinbase56=24ab46f784d1b20db435b852086e325034=12250=TEST52=20250411-01:26:23.023072369=45262=50bb03be-debb-4b06-bc08-08dd0205dd08268=1279=0269=2278=4d60a78e-b39b-420e-b830-bc0f3f4fdde283=159754052155=BTC-USD270=3.53271=0.6232294660=20250411-01:26:23.02108137=b0d80b53-3f1d-446e-92a7-1d27ddb4d5395797=210=044
20250411-01:26:23.139968000 : 8=FIXT.1.19=28935=X49=Coinbase56=24ab46f784d1b20db435b852086e325034=12350=TEST52=20250411-01:26:23.023080369=45262=50bb03be-debb-4b06-bc08-08dd0205dd08268=1279=2269=1278=b0d80b53-3f1d-446e-92a7-1d27ddb4d53983=159754052255=BTC-USD270=3.3271=0.0000000060=20250411-01:26:23.02108158=FILLED10=073
20250411-01:26:23.193462000 : 8=FIXT.1.19=28435=X49=Coinbase56=24ab46f784d1b20db435b852086e325034=12450=TEST52=20250411-01:26:23.077948369=45262=50bb03be-debb-4b06-bc08-08dd0205dd08268=1279=0269=083=159754052355=BTC-USD270=3.73271=0.6232294660=20250411-01:26:23.07679340=237=6eb49128-f9b5-4187-a4b5-7ef2e8cd753410=241
20250411-01:26:23.194202000 : 8=FIXT.1.19=32735=X49=Coinbase56=24ab46f784d1b20db435b852086e325034=12550=TEST52=20250411-01:26:23.077957369=45262=50bb03be-debb-4b06-bc08-08dd0205dd08268=1279=0269=2278=c5b88ea9-605d-4595-ac52-f7c3f08523ba83=159754052455=BTC-USD270=3.55271=0.6232294660=20250411-01:26:23.07679337=6eb49128-f9b5-4187-a4b5-7ef2e8cd75345797=110=197
20250411-01:26:23.194559000 : 8=FIXT.1.19=29035=X49=Coinbase56=24ab46f784d1b20db435b852086e325034=12650=TEST52=20250411-01:26:23.078006369=45262=50bb03be-debb-4b06-bc08-08dd0205dd08268=1279=2269=0278=6eb49128-f9b5-4187-a4b5-7ef2e8cd753483=159754052555=BTC-USD270=3.73271=0.0000000060=20250411-01:26:23.07679358=FILLED10=130
20250411-01:26:23.777972000 : 8=FIXT.1.19=27935=X49=Coinbase56=24ab46f784d1b20db435b852086e325034=12750=TEST52=20250411-01:26:23.662296369=45262=50bb03be-debb-4b06-bc08-08dd0205dd08268=1279=0269=083=159754052655=BTC-USD29004=2.208895519560=20250411-01:26:23.66102640=137=2bb40988-0d5e-4649-bbcc-a4122f2dce6310=101
20250411-01:26:23.778371000 : 8=FIXT.1.19=32735=X49=Coinbase56=24ab46f784d1b20db435b852086e325034=12850=TEST52=20250411-01:26:23.662307369=45262=50bb03be-debb-4b06-bc08-08dd0205dd08268=1279=0269=2278=c5b88ea9-605d-4595-ac52-f7c3f08523ba83=159754052755=BTC-USD270=3.55271=0.6222240960=20250411-01:26:23.66102637=2bb40988-0d5e-4649-bbcc-a4122f2dce635797=110=241
20250411-01:26:23.778603000 : 8=FIXT.1.19=26635=X49=Coinbase56=24ab46f784d1b20db435b852086e325034=12950=TEST52=20250411-01:26:23.662310369=45262=50bb03be-debb-4b06-bc08-08dd0205dd08268=1279=2269=0278=2bb40988-0d5e-4649-bbcc-a4122f2dce6383=159754052855=BTC-USD60=20250411-01:26:23.66102658=FILLED10=104
20250411-01:26:23.808879000 : 8=FIXT.1.19=27535=X49=Coinbase56=24ab46f784d1b20db435b852086e325034=13050=TEST52=20250411-01:26:23.690771369=45262=50bb03be-debb-4b06-bc08-08dd0205dd08268=1279=0269=183=159754052955=BTC-USD271=0.6197183160=20250411-01:26:23.68935840=137=94076e01-e375-41d4-98b0-bcfd1ea6c0d210=105
20250411-01:26:23.809314000 : 8=FIXT.1.19=32735=X49=Coinbase56=24ab46f784d1b20db435b852086e325034=13150=TEST52=20250411-01:26:23.690778369=45262=50bb03be-debb-4b06-bc08-08dd0205dd08268=1279=0269=2278=4d60a78e-b39b-420e-b830-bc0f3f4fdde283=159754053055=BTC-USD270=3.53271=0.6197183160=20250411-01:26:23.68935837=94076e01-e375-41d4-98b0-bcfd1ea6c0d25797=210=092
20250411-01:26:23.809503000 : 8=FIXT.1.19=28135=X49=Coinbase56=24ab46f784d1b20db435b852086e325034=13250=TEST52=20250411-01:26:23.690781369=45262=50bb03be-debb-4b06-bc08-08dd0205dd08268=1279=2269=1278=94076e01-e375-41d4-98b0-bcfd1ea6c0d283=159754053155=BTC-USD271=0.0000000060=20250411-01:26:23.68935858=FILLED10=255
20250411-01:26:23.835878000 : 8=FIXT.1.19=27935=X49=Coinbase56=24ab46f784d1b20db435b852086e325034=13350=TEST52=20250411-01:26:23.720730369=45262=50bb03be-debb-4b06-bc08-08dd0205dd08268=1279=0269=083=159754053255=BTC-USD29004=2.208895519560=20250411-01:26:23.71873240=137=f1638f6d-bdd7-4cc7-a831-3c721d3d215c10=094
20250411-01:26:23.836310000 : 8=FIXT.1.19=32735=X49=Coinbase56=24ab46f784d1b20db435b852086e325034=13450=TEST52=20250411-01:26:23.720739369=45262=50bb03be-debb-4b06-bc08-08dd0205dd08268=1279=0269=2278=c5b88ea9-605d-4595-ac52-f7c3f08523ba83=159754053355=BTC-USD270=3.55271=0.6222240960=20250411-01:26:23.71873237=f1638f6d-bdd7-4cc7-a831-3c721d3d215c5797=110=250
20250411-01:26:23.836560000 : 8=FIXT.1.19=26635=X49=Coinbase56=24ab46f784d1b20db435b852086e325034=13550=TEST52=20250411-01:26:23.720743369=45262=50bb03be-debb-4b06-bc08-08dd0205dd08268=1279=2269=0278=f1638f6d-bdd7-4cc7-a831-3c721d3d215c83=159754053455=BTC-USD60=20250411-01:26:23.71873258=FILLED10=114
20250411-01:26:23.864765000 : 8=FIXT.1.19=27535=X49=Coinbase56=24ab46f784d1b20db435b852086e325034=13650=TEST52=20250411-01:26:23.749028369=45262=50bb03be-debb-4b06-bc08-08dd0205dd08268=1279=0269=183=159754053555=BTC-USD271=0.6197183160=20250411-01:26:23.74717640=137=43f5d235-7760-49a9-839e-cc3ee2cfd04b10=120
20250411-01:26:23.865716000 : 8=FIXT.1.19=32735=X49=Coinbase56=24ab46f784d1b20db435b852086e325034=13750=TEST52=20250411-01:26:23.749126369=45262=50bb03be-debb-4b06-bc08-08dd0205dd08268=1279=0269=2278=4d60a78e-b39b-420e-b830-bc0f3f4fdde283=159754053655=BTC-USD270=3.53271=0.6197183160=20250411-01:26:23.74717637=43f5d235-7760-49a9-839e-cc3ee2cfd04b5797=210=108
20250411-01:26:23.867968000 : 8=FIXT.1.19=28135=X49=Coinbase56=24ab46f784d1b20db435b852086e325034=13850=TEST52=20250411-01:26:23.749130369=45262=50bb03be-debb-4b06-bc08-08dd0205dd08268=1279=2269=1278=43f5d235-7760-49a9-839e-cc3ee2cfd04b83=159754053755=BTC-USD271=0.0000000060=20250411-01:26:23.74717658=FILLED10=016
20250411-01:26:24.294694000 : 8=FIXT.1.19=27935=X49=Coinbase56=24ab46f784d1b20db435b852086e325034=13950=TEST52=20250411-01:26:24.177246369=45262=50bb03be-debb-4b06-bc08-08dd0205dd08268=1279=0269=083=159754053855=BTC-USD29004=2.208895519560=20250411-01:26:24.17596040=137=9e2e6c4e-5f45-4ae4-88ec-84f413ed2bfb10=231
20250411-01:26:24.295693000 : 8=FIXT.1.19=32735=X49=Coinbase56=24ab46f784d1b20db435b852086e325034=14050=TEST52=20250411-01:26:24.177259369=45262=50bb03be-debb-4b06-bc08-08dd0205dd08268=1279=0269=2278=c5b88ea9-605d-4595-ac52-f7c3f08523ba83=159754053955=BTC-USD270=3.55271=0.6222240960=20250411-01:26:24.17596037=9e2e6c4e-5f45-4ae4-88ec-84f413ed2bfb5797=110=117
20250411-01:26:24.296033000 : 8=FIXT.1.19=26635=X49=Coinbase56=24ab46f784d1b20db435b852086e325034=14150=TEST52=20250411-01:26:24.177301369=45262=50bb03be-debb-4b06-bc08-08dd0205dd08268=1279=2269=0278=9e2e6c4e-5f45-4ae4-88ec-84f413ed2bfb83=159754054055=BTC-USD60=20250411-01:26:24.17596058=FILLED10=221
20250411-01:26:24.321768000 : 8=FIXT.1.19=27535=X49=Coinbase56=24ab46f784d1b20db435b852086e325034=14250=TEST52=20250411-01:26:24.206797369=45262=50bb03be-debb-4b06-bc08-08dd0205dd08268=1279=0269=183=159754054155=BTC-USD271=0.6232294660=20250411-01:26:24.20485340=137=8ba78182-e236-48af-b574-9079b7199ebb10=021
20250411-01:26:24.322492000 : 8=FIXT.1.19=32735=X49=Coinbase56=24ab46f784d1b20db435b852086e325034=14350=TEST52=20250411-01:26:24.206805369=45262=50bb03be-debb-4b06-bc08-08dd0205dd08268=1279=0269=2278=4d60a78e-b39b-420e-b830-bc0f3f4fdde283=159754054255=BTC-USD270=3.53271=0.6232294660=20250411-01:26:24.20485337=8ba78182-e236-48af-b574-9079b7199ebb5797=210=000
20250411-01:26:24.323186000 : 8=FIXT.1.19=28135=X49=Coinbase56=24ab46f784d1b20db435b852086e325034=14450=TEST52=20250411-01:26:24.206846369=45262=50bb03be-debb-4b06-bc08-08dd0205dd08268=1279=2269=1278=8ba78182-e236-48af-b574-9079b7199ebb83=159754054355=BTC-USD271=0.0000000060=20250411-01:26:24.20485358=FILLED10=176
20250411-01:26:24.636021000 : 8=FIXT.1.19=27935=X49=Coinbase56=24ab46f784d1b20db435b852086e325034=14550=TEST52=20250411-01:26:24.519805369=45262=50bb03be-debb-4b06-bc08-08dd0205dd08268=1279=0269=083=159754054455=BTC-USD29004=2.208895519560=20250411-01:26:24.51792440=137=aadbc4fc-4222-4c73-94ec-8bb58dfbf68e10=056
20250411-01:26:24.636605000 : 8=FIXT.1.19=32735=X49=Coinbase56=24ab46f784d1b20db435b852086e325034=14650=TEST52=20250411-01:26:24.519848369=45262=50bb03be-debb-4b06-bc08-08dd0205dd08268=1279=0269=2278=c5b88ea9-605d-4595-ac52-f7c3f08523ba83=159754054555=BTC-USD270=3.55271=0.6222240960=20250411-01:26:24.51792437=aadbc4fc-4222-4c73-94ec-8bb58dfbf68e5797=110=210
20250411-01:26:24.636969000 : 8=FIXT.1.19=26635=X49=Coinbase56=24ab46f784d1b20db435b852086e325034=14750=TEST52=20250411-01:26:24.519856369=45262=50bb03be-debb-4b06-bc08-08dd0205dd08268=1279=2269=0278=aadbc4fc-4222-4c73-94ec-8bb58dfbf68e83=159754054655=BTC-USD60=20250411-01:26:24.51792458=FILLED10=078
20250411-01:26:24.665906000 : 8=FIXT.1.19=27535=X49=Coinbase56=24ab46f784d1b20db435b852086e325034=14850=TEST52=20250411-01:26:24.548953369=45262=50bb03be-debb-4b06-bc08-08dd0205dd08268=1279=0269=183=159754054755=BTC-USD271=0.6232294660=20250411-01:26:24.54729740=137=d9295c9e-485f-4a57-8a83-e7ffc09a209310=101
20250411-01:26:24.666742000 : 8=FIXT.1.19=32735=X49=Coinbase56=24ab46f784d1b20db435b852086e325034=14950=TEST52=20250411-01:26:24.549045369=45262=50bb03be-debb-4b06-bc08-08dd0205dd08268=1279=0269=2278=4d60a78e-b39b-420e-b830-bc0f3f4fdde283=159754054855=BTC-USD270=3.53271=0.6232294660=20250411-01:26:24.54729737=d9295c9e-485f-4a57-8a83-e7ffc09a20935797=210=083
20250411-01:26:24.667390000 : 8=FIXT.1.19=28135=X49=Coinbase56=24ab46f784d1b20db435b852086e325034=15050=TEST52=20250411-01:26:24.549048369=45262=50bb03be-debb-4b06-bc08-08dd0205dd08268=1279=2269=1278=d9295c9e-485f-4a57-8a83-e7ffc09a209383=159754054955=BTC-USD271=0.0000000060=20250411-01:26:24.54729758=FILLED10=248
20250411-01:26:24.693061000 : 8=FIXT.1.19=27935=X49=Coinbase56=24ab46f784d1b20db435b852086e325034=15150=TEST52=20250411-01:26:24.577238369=45262=50bb03be-debb-4b06-bc08-08dd0205dd08268=1279=0269=083=159754055055=BTC-USD29004=2.208895519560=20250411-01:26:24.57591440=137=983784fe-12fa-4a2a-afdb-0b0a1378c00310=096
20250411-01:26:24.693584000 : 8=FIXT.1.19=32735=X49=Coinbase56=24ab46f784d1b20db435b852086e325034=15250=TEST52=20250411-01:26:24.577320369=45262=50bb03be-debb-4b06-bc08-08dd0205dd08268=1279=0269=2278=c5b88ea9-605d-4595-ac52-f7c3f08523ba83=159754055155=BTC-USD270=3.55271=0.6222240960=20250411-01:26:24.57591437=983784fe-12fa-4a2a-afdb-0b0a1378c0035797=110=235
20250411-01:26:24.694110000 : 8=FIXT.1.19=26635=X49=Coinbase56=24ab46f784d1b20db435b852086e325034=15350=TEST52=20250411-01:26:24.577323369=45262=50bb03be-debb-4b06-bc08-08dd0205dd08268=1279=2269=0278=983784fe-12fa-4a2a-afdb-0b0a1378c00383=159754055255=BTC-USD60=20250411-01:26:24.57591458=FILLED10=107
20250411-01:26:24.722258000 : 8=FIXT.1.19=27535=X49=Coinbase56=24ab46f784d1b20db435b852086e325034=15450=TEST52=20250411-01:26:24.605652369=45262=50bb03be-debb-4b06-bc08-08dd0205dd08268=1279=0269=183=159754055355=BTC-USD271=0.6197183160=20250411-01:26:24.60392140=137=2041be7a-6687-49dd-8dca-fa33cba3dd8e10=030
20250411-01:26:24.722980000 : 8=FIXT.1.19=32735=X49=Coinbase56=24ab46f784d1b20db435b852086e325034=15550=TEST52=20250411-01:26:24.605659369=45262=50bb03be-debb-4b06-bc08-08dd0205dd08268=1279=0269=2278=4d60a78e-b39b-420e-b830-bc0f3f4fdde283=159754055455=BTC-USD270=3.53271=0.6197183160=20250411-01:26:24.60392137=2041be7a-6687-49dd-8dca-fa33cba3dd8e5797=210=026
20250411-01:26:24.723494000 : 8=FIXT.1.19=28135=X49=Coinbase56=24ab46f784d1b20db435b852086e325034=15650=TEST52=20250411-01:26:24.605662369=45262=50bb03be-debb-4b06-bc08-08dd0205dd08268=1279=2269=1278=2041be7a-6687-49dd-8dca-fa33cba3dd8e83=159754055555=BTC-USD271=0.0000000060=20250411-01:26:24.60392158=FILLED10=189
20250411-01:26:24.751840000 : 8=FIXT.1.19=27935=X49=Coinbase56=24ab46f784d1b20db435b852086e325034=15750=TEST52=20250411-01:26:24.634665369=45262=50bb03be-debb-4b06-bc08-08dd0205dd08268=1279=0269=083=159754055655=BTC-USD29004=2.208895519560=20250411-01:26:24.63289240=137=df5b0fcd-84e1-42fb-9126-277c257b688110=038
20250411-01:26:24.752583000 : 8=FIXT.1.19=32735=X49=Coinbase56=24ab46f784d1b20db435b852086e325034=15850=TEST52=20250411-01:26:24.634773369=45262=50bb03be-debb-4b06-bc08-08dd0205dd08268=1279=0269=2278=c5b88ea9-605d-4595-ac52-f7c3f08523ba83=159754055755=BTC-USD270=3.55271=0.6222240960=20250411-01:26:24.63289237=df5b0fcd-84e1-42fb-9126-277c257b68815797=110=185
20250411-01:26:24.753385000 : 8=FIXT.1.19=26635=X49=Coinbase56=24ab46f784d1b20db435b852086e325034=15950=TEST52=20250411-01:26:24.634776369=45262=50bb03be-debb-4b06-bc08-08dd0205dd08268=1279=2269=0278=df5b0fcd-84e1-42fb-9126-277c257b688183=159754055855=BTC-USD60=20250411-01:26:24.63289258=FILLED10=057
20250411-01:26:24.778643000 : 8=FIXT.1.19=27535=X49=Coinbase56=24ab46f784d1b20db435b852086e325034=16050=TEST52=20250411-01:26:24.663249369=45262=50bb03be-debb-4b06-bc08-08dd0205dd08268=1279=0269=183=159754055955=BTC-USD271=0.6197183160=20250411-01:26:24.66134740=137=aaa337e4-152c-4aff-8003-6cda41dcd9f410=237
20250411-01:26:24.779227000 : 8=FIXT.1.19=32735=X49=Coinbase56=24ab46f784d1b20db435b852086e325034=16150=TEST52=20250411-01:26:24.663376369=45262=50bb03be-debb-4b06-bc08-08dd0205dd08268=1279=0269=2278=4d60a78e-b39b-420e-b830-bc0f3f4fdde283=159754056055=BTC-USD270=3.53271=0.6197183160=20250411-01:26:24.66134737=aaa337e4-152c-4aff-8003-6cda41dcd9f45797=210=218
20250411-01:26:24.864592000 : 8=FIXT.1.19=28135=X49=Coinbase56=24ab46f784d1b20db435b852086e325034=16250=TEST52=20250411-01:26:24.663425369=45262=50bb03be-debb-4b06-bc08-08dd0205dd08268=1279=2269=1278=aaa337e4-152c-4aff-8003-6cda41dcd9f483=159754056155=BTC-USD271=0.0000000060=20250411-01:26:24.66134758=FILLED10=126
20250411-01:26:24.922162000 : 8=FIXT.1.19=27935=X49=Coinbase56=24ab46f784d1b20db435b852086e325034=16350=TEST52=20250411-01:26:24.806167369=45262=50bb03be-debb-4b06-bc08-08dd0205dd08268=1279=0269=083=159754056255=BTC-USD29004=2.208895519560=20250411-01:26:24.80426240=137=40dc040c-200b-4605-bc95-8e548427b1ef10=205
20250411-01:26:24.922661000 : 8=FIXT.1.19=32735=X49=Coinbase56=24ab46f784d1b20db435b852086e325034=16450=TEST52=20250411-01:26:24.806176369=45262=50bb03be-debb-4b06-bc08-08dd0205dd08268=1279=0269=2278=c5b88ea9-605d-4595-ac52-f7c3f08523ba83=159754056355=BTC-USD270=3.55271=0.6222240960=20250411-01:26:24.80426237=40dc040c-200b-4605-bc95-8e548427b1ef5797=110=096
20250411-01:26:24.922939000 : 8=FIXT.1.19=26635=X49=Coinbase56=24ab46f784d1b20db435b852086e325034=16550=TEST52=20250411-01:26:24.806179369=45262=50bb03be-debb-4b06-bc08-08dd0205dd08268=1279=2269=0278=40dc040c-200b-4605-bc95-8e548427b1ef83=159754056455=BTC-USD60=20250411-01:26:24.80426258=FILLED10=224
20250411-01:26:24.950736000 : 8=FIXT.1.19=27535=X49=Coinbase56=24ab46f784d1b20db435b852086e325034=16650=TEST52=20250411-01:26:24.834624369=45262=50bb03be-debb-4b06-bc08-08dd0205dd08268=1279=0269=183=159754056555=BTC-USD271=0.6232294660=20250411-01:26:24.83318940=137=23ddc985-01a7-4737-afc0-061675394fbb10=016
20250411-01:26:24.951422000 : 8=FIXT.1.19=32735=X49=Coinbase56=24ab46f784d1b20db435b852086e325034=16750=TEST52=20250411-01:26:24.834632369=45262=50bb03be-debb-4b06-bc08-08dd0205dd08268=1279=0269=2278=4d60a78e-b39b-420e-b830-bc0f3f4fdde283=159754056655=BTC-USD270=3.53271=0.6232294660=20250411-01:26:24.83318937=23ddc985-01a7-4737-afc0-061675394fbb5797=210=004
20250411-01:26:24.951793000 : 8=FIXT.1.19=28135=X49=Coinbase56=24ab46f784d1b20db435b852086e325034=16850=TEST52=20250411-01:26:24.834635369=45262=50bb03be-debb-4b06-bc08-08dd0205dd08268=1279=2269=1278=23ddc985-01a7-4737-afc0-061675394fbb83=159754056755=BTC-USD271=0.0000000060=20250411-01:26:24.83318958=FILLED10=178
20250411-01:26:25.035758000 : 8=FIXT.1.19=27935=X49=Coinbase56=24ab46f784d1b20db435b852086e325034=16950=TEST52=20250411-01:26:24.919879369=45262=50bb03be-debb-4b06-bc08-08dd0205dd08268=1279=0269=083=159754056855=BTC-USD29004=2.208895519560=20250411-01:26:24.91783940=137=e33c06ee-b23b-4705-8ca6-92adb0e14ac410=179
20250411-01:26:25.036456000 : 8=FIXT.1.19=32735=X49=Coinbase56=24ab46f784d1b20db435b852086e325034=17050=TEST52=20250411-01:26:24.919887369=45262=50bb03be-debb-4b06-bc08-08dd0205dd08268=1279=0269=2278=c5b88ea9-605d-4595-ac52-f7c3f08523ba83=159754056955=BTC-USD270=3.55271=0.6222240960=20250411-01:26:24.91783937=e33c06ee-b23b-4705-8ca6-92adb0e14ac45797=110=060
20250411-01:26:25.036999000 : 8=FIXT.1.19=26635=X49=Coinbase56=24ab46f784d1b20db435b852086e325034=17150=TEST52=20250411-01:26:24.919890369=45262=50bb03be-debb-4b06-bc08-08dd0205dd08268=1279=2269=0278=e33c06ee-b23b-4705-8ca6-92adb0e14ac483=159754057055=BTC-USD60=20250411-01:26:24.91783958=FILLED10=170
20250411-01:26:25.065223000 : 8=FIXT.1.19=27535=X49=Coinbase56=24ab46f784d1b20db435b852086e325034=17250=TEST52=20250411-01:26:24.949465369=45262=50bb03be-debb-4b06-bc08-08dd0205dd08268=1279=0269=183=159754057155=BTC-USD271=0.6232294660=20250411-01:26:24.94750040=137=82aa3f9c-a822-4907-9343-0bfe763726b010=223
20250411-01:26:25.065917000 : 8=FIXT.1.19=32735=X49=Coinbase56=24ab46f784d1b20db435b852086e325034=17350=TEST52=20250411-01:26:24.949472369=45262=50bb03be-debb-4b06-bc08-08dd0205dd08268=1279=0269=2278=4d60a78e-b39b-420e-b830-bc0f3f4fdde283=159754057255=BTC-USD270=3.53271=0.6232294660=20250411-01:26:24.94750037=82aa3f9c-a822-4907-9343-0bfe763726b05797=210=210
20250411-01:26:25.066368000 : 8=FIXT.1.19=28135=X49=Coinbase56=24ab46f784d1b20db435b852086e325034=17450=TEST52=20250411-01:26:24.949475369=45262=50bb03be-debb-4b06-bc08-08dd0205dd08268=1279=2269=1278=82aa3f9c-a822-4907-9343-0bfe763726b083=159754057355=BTC-USD271=0.0000000060=20250411-01:26:24.94750058=FILLED10=128
20250411-01:26:25.094440000 : 8=FIXT.1.19=27935=X49=Coinbase56=24ab46f784d1b20db435b852086e325034=17550=TEST52=20250411-01:26:24.978906369=45262=50bb03be-debb-4b06-bc08-08dd0205dd08268=1279=0269=083=159754057455=BTC-USD29004=2.208895519560=20250411-01:26:24.97758340=137=3dbba61e-ffbf-43af-a6b6-d1057539f6dc10=076
20250411-01:26:25.095037000 : 8=FIXT.1.19=32735=X49=Coinbase56=24ab46f784d1b20db435b852086e325034=17650=TEST52=20250411-01:26:24.978913369=45262=50bb03be-debb-4b06-bc08-08dd0205dd08268=1279=0269=2278=c5b88ea9-605d-4595-ac52-f7c3f08523ba83=159754057555=BTC-USD270=3.55271=0.6222240960=20250411-01:26:24.97758337=3dbba61e-ffbf-43af-a6b6-d1057539f6dc5797=110=221
20250411-01:26:25.096281000 : 8=FIXT.1.19=26635=X49=Coinbase56=24ab46f784d1b20db435b852086e325034=17750=TEST52=20250411-01:26:24.978917369=45262=50bb03be-debb-4b06-bc08-08dd0205dd08268=1279=2269=0278=3dbba61e-ffbf-43af-a6b6-d1057539f6dc83=159754057655=BTC-USD60=20250411-01:26:24.97758358=FILLED10=094
20250411-01:26:25.121846000 : 8=FIXT.1.19=27535=X49=Coinbase56=24ab46f784d1b20db435b852086e325034=17850=TEST52=20250411-01:26:25.005635369=45262=50bb03be-debb-4b06-bc08-08dd0205dd08268=1279=0269=183=159754057755=BTC-USD271=0.6197183160=20250411-01:26:25.00419140=137=7dc16ade-5a7b-4acf-a4fd-468b94819b6810=254
20250411-01:26:25.122394000 : 8=FIXT.1.19=32735=X49=Coinbase56=24ab46f784d1b20db435b852086e325034=17950=TEST52=20250411-01:26:25.005641369=45262=50bb03be-debb-4b06-bc08-08dd0205dd08268=1279=0269=2278=4d60a78e-b39b-420e-b830-bc0f3f4fdde283=159754057855=BTC-USD270=3.53271=0.6197183160=20250411-01:26:25.00419137=7dc16ade-5a7b-4acf-a4fd-468b94819b685797=210=240
20250411-01:26:25.122691000 : 8=FIXT.1.19=28135=X49=Coinbase56=24ab46f784d1b20db435b852086e325034=18050=TEST52=20250411-01:26:25.005644369=45262=50bb03be-debb-4b06-bc08-08dd0205dd08268=1279=2269=1278=7dc16ade-5a7b-4acf-a4fd-468b94819b6883=159754057955=BTC-USD271=0.0000000060=20250411-01:26:25.00419158=FILLED10=147
20250411-01:26:25.240416000 : 8=FIXT.1.19=28335=X49=Coinbase56=24ab46f784d1b20db435b852086e325034=18150=TEST52=20250411-01:26:25.124441369=45262=50bb03be-debb-4b06-bc08-08dd0205dd08268=1279=0269=083=159754058055=BTC-USD270=3.5271=0.6232294660=20250411-01:26:25.12312040=237=17676d23-9688-459a-a90d-b5a3ec9b8ba410=150
20250411-01:26:25.241074000 : 8=FIXT.1.19=27935=X49=Coinbase56=24ab46f784d1b20db435b852086e325034=18250=TEST52=20250411-01:26:25.124451369=45262=50bb03be-debb-4b06-bc08-08dd0205dd08268=1279=0269=0278=17676d23-9688-459a-a90d-b5a3ec9b8ba483=159754058155=BTC-USD270=3.5271=0.6232294660=20250411-01:26:25.12312010=001
20250411-01:26:25.524418000 : 8=FIXT.1.19=28435=X49=Coinbase56=24ab46f784d1b20db435b852086e325034=18350=TEST52=20250411-01:26:25.408357369=45262=50bb03be-debb-4b06-bc08-08dd0205dd08268=1279=0269=183=159754058255=BTC-USD270=3.66271=0.6232294660=20250411-01:26:25.40667540=237=44d5e043-ae98-4ab7-809e-6b431af16dc310=016
20250411-01:26:25.524905000 : 8=FIXT.1.19=28035=X49=Coinbase56=24ab46f784d1b20db435b852086e325034=18450=TEST52=20250411-01:26:25.408367369=45262=50bb03be-debb-4b06-bc08-08dd0205dd08268=1279=0269=1278=44d5e043-ae98-4ab7-809e-6b431af16dc383=159754058355=BTC-USD270=3.66271=0.6232294660=20250411-01:26:25.40667510=114
20250411-01:26:25.607339000 : 8=FIXT.1.19=27935=X49=Coinbase56=24ab46f784d1b20db435b852086e325034=18550=TEST52=20250411-01:26:25.491157369=45262=50bb03be-debb-4b06-bc08-08dd0205dd08268=1279=0269=083=159754058455=BTC-USD29004=2.208895519560=20250411-01:26:25.48974440=137=1be8c3c1-6b8f-4859-8b0f-5f54de73a6ea10=193
20250411-01:26:25.607986000 : 8=FIXT.1.19=32735=X49=Coinbase56=24ab46f784d1b20db435b852086e325034=18650=TEST52=20250411-01:26:25.491171369=45262=50bb03be-debb-4b06-bc08-08dd0205dd08268=1279=0269=2278=c5b88ea9-605d-4595-ac52-f7c3f08523ba83=159754058555=BTC-USD270=3.55271=0.6222240960=20250411-01:26:25.48974437=1be8c3c1-6b8f-4859-8b0f-5f54de73a6ea5797=110=080
20250411-01:26:25.608243000 : 8=FIXT.1.19=26635=X49=Coinbase56=24ab46f784d1b20db435b852086e325034=18750=TEST52=20250411-01:26:25.491173369=45262=50bb03be-debb-4b06-bc08-08dd0205dd08268=1279=2269=0278=1be8c3c1-6b8f-4859-8b0f-5f54de73a6ea83=159754058655=BTC-USD60=20250411-01:26:25.48974458=FILLED10=207
20250411-01:26:25.636770000 : 8=FIXT.1.19=27535=X49=Coinbase56=24ab46f784d1b20db435b852086e325034=18850=TEST52=20250411-01:26:25.520604369=45262=50bb03be-debb-4b06-bc08-08dd0205dd08268=1279=0269=183=159754058755=BTC-USD271=0.6232294660=20250411-01:26:25.51852840=137=64a2f98d-1a98-463a-a864-61e3fbae49c810=125
20250411-01:26:25.637331000 : 8=FIXT.1.19=32735=X49=Coinbase56=24ab46f784d1b20db435b852086e325034=18950=TEST52=20250411-01:26:25.520611369=45262=50bb03be-debb-4b06-bc08-08dd0205dd08268=1279=0269=2278=4d60a78e-b39b-420e-b830-bc0f3f4fdde283=159754058855=BTC-USD270=3.53271=0.6232294660=20250411-01:26:25.51852837=64a2f98d-1a98-463a-a864-61e3fbae49c85797=210=112
20250411-01:26:25.637716000 : 8=FIXT.1.19=28135=X49=Coinbase56=24ab46f784d1b20db435b852086e325034=19050=TEST52=20250411-01:26:25.520617369=45262=50bb03be-debb-4b06-bc08-08dd0205dd08268=1279=2269=1278=64a2f98d-1a98-463a-a864-61e3fbae49c883=159754058955=BTC-USD271=0.0000000060=20250411-01:26:25.51852858=FILLED10=024
20250411-01:26:25.950475000 : 8=FIXT.1.19=27935=X49=Coinbase56=24ab46f784d1b20db435b852086e325034=19150=TEST52=20250411-01:26:25.834710369=45262=50bb03be-debb-4b06-bc08-08dd0205dd08268=1279=0269=083=159754059055=BTC-USD29004=2.208895519560=20250411-01:26:25.83351040=137=b02f1f3f-954f-4cc5-9b2b-50776d43c9ab10=108
20250411-01:26:25.950833000 : 8=FIXT.1.19=32735=X49=Coinbase56=24ab46f784d1b20db435b852086e325034=19250=TEST52=20250411-01:26:25.834836369=45262=50bb03be-debb-4b06-bc08-08dd0205dd08268=1279=0269=2278=c5b88ea9-605d-4595-ac52-f7c3f08523ba83=159754059155=BTC-USD270=3.55271=0.6222240960=20250411-01:26:25.83351037=b02f1f3f-954f-4cc5-9b2b-50776d43c9ab5797=110=008
20250411-01:26:25.951168000 : 8=FIXT.1.19=26635=X49=Coinbase56=24ab46f784d1b20db435b852086e325034=19350=TEST52=20250411-01:26:25.834839369=45262=50bb03be-debb-4b06-bc08-08dd0205dd08268=1279=2269=0278=b02f1f3f-954f-4cc5-9b2b-50776d43c9ab83=159754059255=BTC-USD60=20250411-01:26:25.83351058=FILLED10=136
20250411-01:26:25.979170000 : 8=FIXT.1.19=27535=X49=Coinbase56=24ab46f784d1b20db435b852086e325034=19450=TEST52=20250411-01:26:25.863132369=45262=50bb03be-debb-4b06-bc08-08dd0205dd08268=1279=0269=183=159754059355=BTC-USD271=0.6232294660=20250411-01:26:25.86128940=137=63356d4e-d914-457b-9a3f-037a05f9737810=196
20250411-01:26:25.979515000 : 8=FIXT.1.19=32735=X49=Coinbase56=24ab46f784d1b20db435b852086e325034=19550=TEST52=20250411-01:26:25.863140369=45262=50bb03be-debb-4b06-bc08-08dd0205dd08268=1279=0269=2278=4d60a78e-b39b-420e-b830-bc0f3f4fdde283=159754059455=BTC-USD270=3.53271=0.6232294660=20250411-01:26:25.86128937=63356d4e-d914-457b-9a3f-037a05f973785797=210=184
20250411-01:26:25.979763000 : 8=FIXT.1.19=28135=X49=Coinbase56=24ab46f784d1b20db435b852086e325034=19650=TEST52=20250411-01:26:25.863173369=45262=50bb03be-debb-4b06-bc08-08dd0205dd08268=1279=2269=1278=63356d4e-d914-457b-9a3f-037a05f9737883=159754059555=BTC-USD271=0.0000000060=20250411-01:26:25.86128958=FILLED10=105
20250411-01:26:25.989144000 : 8=FIXT.1.19=31035=X49=Coinbase56=24ab46f784d1b20db435b852086e325034=19750=TEST52=20250411-01:26:25.872454369=45262=50bb03be-debb-4b06-bc08-08dd0205dd08268=1279=1269=0278=58ed893b-e3aa-47af-a913-bb90c77a59fe83=159754059655=BTC-USD270=3.51271=0.5447351960=20250411-01:26:25.87096158=CHANGE_REASON_MODIFY_ORDER10=143
20250411-01:26:26.277830000 : 8=FIXT.1.19=32735=X49=Coinbase56=24ab46f784d1b20db435b852086e325034=19850=TEST52=20250411-01:26:26.160004369=45262=50bb03be-debb-4b06-bc08-08dd0205dd08268=1279=0269=2278=c5b88ea9-605d-4595-ac52-f7c3f08523ba83=159754059755=BTC-USD270=3.55271=0.5582153960=20250411-01:26:26.15864437=65009766-5f91-4931-b87d-f0e4e9721a785797=110=010
20250411-01:26:26.279802000 : 8=FIXT.1.19=29035=X49=Coinbase56=24ab46f784d1b20db435b852086e325034=19950=TEST52=20250411-01:26:26.160014369=45262=50bb03be-debb-4b06-bc08-08dd0205dd08268=1279=2269=0278=65009766-5f91-4931-b87d-f0e4e9721a7883=159754059855=BTC-USD270=3.69271=0.0000000060=20250411-01:26:26.15864458=FILLED10=215
20250411-01:26:26.452168000 : 8=FIXT.1.19=28435=X49=Coinbase56=24ab46f784d1b20db435b852086e325034=20050=TEST52=20250411-01:26:26.336218369=45262=50bb03be-debb-4b06-bc08-08dd0205dd08268=1279=0269=083=159754059955=BTC-USD270=3.78271=0.6197183160=20250411-01:26:26.33445340=237=e663677a-76e9-4703-ad17-f0a88aea852c10=233
20250411-01:26:26.452922000 : 8=FIXT.1.19=32735=X49=Coinbase56=24ab46f784d1b20db435b852086e325034=20150=TEST52=20250411-01:26:26.336321369=45262=50bb03be-debb-4b06-bc08-08dd0205dd08268=1279=0269=2278=c5b88ea9-605d-4595-ac52-f7c3f08523ba83=159754060055=BTC-USD270=3.55271=0.6197183160=20250411-01:26:26.33445337=e663677a-76e9-4703-ad17-f0a88aea852c5797=110=161
20250411-01:26:26.453539000 : 8=FIXT.1.19=29035=X49=Coinbase56=24ab46f784d1b20db435b852086e325034=20250=TEST52=20250411-01:26:26.336325369=45262=50bb03be-debb-4b06-bc08-08dd0205dd08268=1279=2269=0278=e663677a-76e9-4703-ad17-f0a88aea852c83=159754060155=BTC-USD270=3.78271=0.0000000060=20250411-01:26:26.33445358=FILLED10=115
20250411-01:26:26.506605000 : 8=FIXT.1.19=30335=X49=Coinbase56=24ab46f784d1b20db435b852086e325034=20350=TEST52=20250411-01:26:26.391123369=45262=50bb03be-debb-4b06-bc08-08dd0205dd08268=1279=0269=183=159754060255=BTC-USD270=3.29271=0.5779036829004=2.039999990460=20250411-01:26:26.38991840=237=750fcb74-bd7b-47ff-a6fc-cf5e2d7632cd10=188
20250411-01:26:26.507085000 : 8=FIXT.1.19=32735=X49=Coinbase56=24ab46f784d1b20db435b852086e325034=20450=TEST52=20250411-01:26:26.391130369=45262=50bb03be-debb-4b06-bc08-08dd0205dd08268=1279=0269=2278=4d60a78e-b39b-420e-b830-bc0f3f4fdde283=159754060355=BTC-USD270=3.53271=0.5779036860=20250411-01:26:26.38991837=750fcb74-bd7b-47ff-a6fc-cf5e2d7632cd5797=210=089
20250411-01:26:26.507488000 : 8=FIXT.1.19=28135=X49=Coinbase56=24ab46f784d1b20db435b852086e325034=20550=TEST52=20250411-01:26:26.391198369=45262=50bb03be-debb-4b06-bc08-08dd0205dd08268=1279=2269=1278=750fcb74-bd7b-47ff-a6fc-cf5e2d7632cd83=159754060455=BTC-USD270=3.29271=060=20250411-01:26:26.38991858=FILLED10=252
20250411-01:26:26.560035000 : 8=FIXT.1.19=31035=X49=Coinbase56=24ab46f784d1b20db435b852086e325034=20650=TEST52=20250411-01:26:26.444198369=45262=50bb03be-debb-4b06-bc08-08dd0205dd08268=1279=1269=1278=538531e1-5caa-4f12-aed8-a3c4ce631c4383=159754060555=BTC-USD270=3.61271=0.5343830560=20250411-01:26:26.44219458=CHANGE_REASON_MODIFY_ORDER10=244
20250411-01:26:26.750906000 : 8=FIXT.1.19=27935=X49=Coinbase56=24ab46f784d1b20db435b852086e325034=20750=TEST52=20250411-01:26:26.635722369=45262=50bb03be-debb-4b06-bc08-08dd0205dd08268=1279=0269=083=159754060655=BTC-USD29004=2.208895519560=20250411-01:26:26.63410740=137=f9b27778-8202-4073-89a7-f8975e57086310=018
20250411-01:26:26.751380000 : 8=FIXT.1.19=32735=X49=Coinbase56=24ab46f784d1b20db435b852086e325034=20850=TEST52=20250411-01:26:26.635735369=45262=50bb03be-debb-4b06-bc08-08dd0205dd08268=1279=0269=2278=c5b88ea9-605d-4595-ac52-f7c3f08523ba83=159754060755=BTC-USD270=3.55271=0.6222240960=20250411-01:26:26.63410737=f9b27778-8202-4073-89a7-f8975e5708635797=110=169
20250411-01:26:26.751633000 : 8=FIXT.1.19=26635=X49=Coinbase56=24ab46f784d1b20db435b852086e325034=20950=TEST52=20250411-01:26:26.635738369=45262=50bb03be-debb-4b06-bc08-08dd0205dd08268=1279=2269=0278=f9b27778-8202-4073-89a7-f8975e57086383=159754060855=BTC-USD60=20250411-01:26:26.63410758=FILLED10=041
20250411-01:26:26.779811000 : 8=FIXT.1.19=27535=X49=Coinbase56=24ab46f784d1b20db435b852086e325034=21050=TEST52=20250411-01:26:26.664258369=45262=50bb03be-debb-4b06-bc08-08dd0205dd08268=1279=0269=183=159754060955=BTC-USD271=0.6232294660=20250411-01:26:26.66210440=137=20075046-dd33-4658-b54c-74f5192b9f5110=115
20250411-01:26:26.780091000 : 8=FIXT.1.19=32735=X49=Coinbase56=24ab46f784d1b20db435b852086e325034=21150=TEST52=20250411-01:26:26.664265369=45262=50bb03be-debb-4b06-bc08-08dd0205dd08268=1279=0269=2278=4d60a78e-b39b-420e-b830-bc0f3f4fdde283=159754061055=BTC-USD270=3.53271=0.6232294660=20250411-01:26:26.66210437=20075046-dd33-4658-b54c-74f5192b9f515797=210=093
20250411-01:26:26.780561000 : 8=FIXT.1.19=28135=X49=Coinbase56=24ab46f784d1b20db435b852086e325034=21250=TEST52=20250411-01:26:26.664269369=45262=50bb03be-debb-4b06-bc08-08dd0205dd08268=1279=2269=1278=20075046-dd33-4658-b54c-74f5192b9f5183=159754061155=BTC-USD271=0.0000000060=20250411-01:26:26.66210458=FILLED10=012
20250411-01:26:26.807484000 : 8=FIXT.1.19=27935=X49=Coinbase56=24ab46f784d1b20db435b852086e325034=21350=TEST52=20250411-01:26:26.691499369=45262=50bb03be-debb-4b06-bc08-08dd0205dd08268=1279=0269=083=159754061255=BTC-USD29004=2.208895519560=20250411-01:26:26.69020440=137=c726fc93-9750-4538-815b-5d1775bced1710=196
20250411-01:26:26.808060000 : 8=FIXT.1.19=32735=X49=Coinbase56=24ab46f784d1b20db435b852086e325034=21450=TEST52=20250411-01:26:26.691614369=45262=50bb03be-debb-4b06-bc08-08dd0205dd08268=1279=0269=2278=c5b88ea9-605d-4595-ac52-f7c3f08523ba83=159754061355=BTC-USD270=3.55271=0.6222240960=20250411-01:26:26.69020437=c726fc93-9750-4538-815b-5d1775bced175797=110=076
20250411-01:26:26.808526000 : 8=FIXT.1.19=26635=X49=Coinbase56=24ab46f784d1b20db435b852086e325034=21550=TEST52=20250411-01:26:26.691617369=45262=50bb03be-debb-4b06-bc08-08dd0205dd08268=1279=2269=0278=c726fc93-9750-4538-815b-5d1775bced1783=159754061455=BTC-USD60=20250411-01:26:26.69020458=FILLED10=204
20250411-01:26:26.836185000 : 8=FIXT.1.19=27535=X49=Coinbase56=24ab46f784d1b20db435b852086e325034=21650=TEST52=20250411-01:26:26.720138369=45262=50bb03be-debb-4b06-bc08-08dd0205dd08268=1279=0269=183=159754061555=BTC-USD271=0.6197183160=20250411-01:26:26.71844240=137=0715c8b5-b116-4a0e-a296-606d3fe2f18110=246
20250411-01:26:26.837568000 : 8=FIXT.1.19=32735=X49=Coinbase56=24ab46f784d1b20db435b852086e325034=21750=TEST52=20250411-01:26:26.720146369=45262=50bb03be-debb-4b06-bc08-08dd0205dd08268=1279=0269=2278=4d60a78e-b39b-420e-b830-bc0f3f4fdde283=159754061655=BTC-USD270=3.53271=0.6197183160=20250411-01:26:26.71844237=0715c8b5-b116-4a0e-a296-606d3fe2f1815797=210=234
20250411-01:26:26.837927000 : 8=FIXT.1.19=28135=X49=Coinbase56=24ab46f784d1b20db435b852086e325034=21850=TEST52=20250411-01:26:26.720149369=45262=50bb03be-debb-4b06-bc08-08dd0205dd08268=1279=2269=1278=0715c8b5-b116-4a0e-a296-606d3fe2f18183=159754061755=BTC-USD271=0.0000000060=20250411-01:26:26.71844258=FILLED10=150
20250411-01:26:26.845061000 : 8=FIXT.1.19=31035=X49=Coinbase56=24ab46f784d1b20db435b852086e325034=21950=TEST52=20250411-01:26:26.729232369=45262=50bb03be-debb-4b06-bc08-08dd0205dd08268=1279=1269=1278=fadcd276-2def-409a-be94-be577f68ff2783=159754061855=BTC-USD270=3.59271=0.5360441560=20250411-01:26:26.72782358=CHANGE_REASON_MODIFY_ORDER10=184
20250411-01:26:26.867358000 : 8=FIXT.1.19=27935=X49=Coinbase56=24ab46f784d1b20db435b852086e325034=22050=TEST52=20250411-01:26:26.750228369=45262=50bb03be-debb-4b06-bc08-08dd0205dd08268=1279=0269=083=159754061955=BTC-USD29004=2.208895519560=20250411-01:26:26.74814240=137=1561dbfe-9d7f-4f02-8924-15acedc523da10=157
20250411-01:26:26.870231000 : 8=FIXT.1.19=32735=X49=Coinbase56=24ab46f784d1b20db435b852086e325034=22150=TEST52=20250411-01:26:26.750302369=45262=50bb03be-debb-4b06-bc08-08dd0205dd08268=1279=0269=2278=c5b88ea9-605d-4595-ac52-f7c3f08523ba83=159754062055=BTC-USD270=3.55271=0.6222240960=20250411-01:26:26.74814237=1561dbfe-9d7f-4f02-8924-15acedc523da5797=110=032
20250411-01:26:26.874001000 : 8=FIXT.1.19=26635=X49=Coinbase56=24ab46f784d1b20db435b852086e325034=22250=TEST52=20250411-01:26:26.750310369=45262=50bb03be-debb-4b06-bc08-08dd0205dd08268=1279=2269=0278=1561dbfe-9d7f-4f02-8924-15acedc523da83=159754062155=BTC-USD60=20250411-01:26:26.74814258=FILLED10=156
20250411-01:26:26.893133000 : 8=FIXT.1.19=27535=X49=Coinbase56=24ab46f784d1b20db435b852086e325034=22350=TEST52=20250411-01:26:26.777113369=45262=50bb03be-debb-4b06-bc08-08dd0205dd08268=1279=0269=183=159754062255=BTC-USD271=0.6197183160=20250411-01:26:26.77568840=137=4c8647bd-e890-4d42-831a-b9ffa738cb2210=123
20250411-01:26:26.893742000 : 8=FIXT.1.19=32735=X49=Coinbase56=24ab46f784d1b20db435b852086e325034=22450=TEST52=20250411-01:26:26.777121369=45262=50bb03be-debb-4b06-bc08-08dd0205dd08268=1279=0269=2278=4d60a78e-b39b-420e-b830-bc0f3f4fdde283=159754062355=BTC-USD270=3.53271=0.6197183160=20250411-01:26:26.77568837=4c8647bd-e890-4d42-831a-b9ffa738cb225797=210=111
20250411-01:26:26.894364000 : 8=FIXT.1.19=28135=X49=Coinbase56=24ab46f784d1b20db435b852086e325034=22550=TEST52=20250411-01:26:26.777124369=45262=50bb03be-debb-4b06-bc08-08dd0205dd08268=1279=2269=1278=4c8647bd-e890-4d42-831a-b9ffa738cb2283=159754062455=BTC-USD271=0.0000000060=20250411-01:26:26.77568858=FILLED10=027
20250411-01:26:27.035996000 : 8=FIXT.1.19=27935=X49=Coinbase56=24ab46f784d1b20db435b852086e325034=22650=TEST52=20250411-01:26:26.920109369=45262=50bb03be-debb-4b06-bc08-08dd0205dd08268=1279=0269=083=159754062555=BTC-USD29004=2.208895519560=20250411-01:26:26.91887740=137=1e2891f6-7fa8-4ece-a647-34438ffebdbe10=238
20250411-01:26:27.036498000 : 8=FIXT.1.19=32735=X49=Coinbase56=24ab46f784d1b20db435b852086e325034=22750=TEST52=20250411-01:26:26.920261369=45262=50bb03be-debb-4b06-bc08-08dd0205dd08268=1279=0269=2278=c5b88ea9-605d-4595-ac52-f7c3f08523ba83=159754062655=BTC-USD270=3.55271=0.6222240960=20250411-01:26:26.91887737=1e2891f6-7fa8-4ece-a647-34438ffebdbe5797=110=128
20250411-01:26:27.036924000 : 8=FIXT.1.19=26635=X49=Coinbase56=24ab46f784d1b20db435b852086e325034=22850=TEST52=20250411-01:26:26.920264369=45262=50bb03be-debb-4b06-bc08-08dd0205dd08268=1279=2269=0278=1e2891f6-7fa8-4ece-a647-34438ffebdbe83=159754062755=BTC-USD60=20250411-01:26:26.91887758=FILLED10=000
20250411-01:26:27.065504000 : 8=FIXT.1.19=27535=X49=Coinbase56=24ab46f784d1b20db435b852086e325034=22950=TEST52=20250411-01:26:26.948498369=45262=50bb03be-debb-4b06-bc08-08dd0205dd08268=1279=0269=183=159754062855=BTC-USD271=0.6232294660=20250411-01:26:26.94672440=137=407858a5-4b67-4b44-934a-500fa458922410=104
20250411-01:26:27.067528000 : 8=FIXT.1.19=32735=X49=Coinbase56=24ab46f784d1b20db435b852086e325034=23050=TEST52=20250411-01:26:26.948507369=45262=50bb03be-debb-4b06-bc08-08dd0205dd08268=1279=0269=2278=4d60a78e-b39b-420e-b830-bc0f3f4fdde283=159754062955=BTC-USD270=3.53271=0.6232294660=20250411-01:26:26.94672437=407858a5-4b67-4b44-934a-500fa45892245797=210=075
20250411-01:26:27.070314000 : 8=FIXT.1.19=28135=X49=Coinbase56=24ab46f784d1b20db435b852086e325034=23150=TEST52=20250411-01:26:26.948511369=45262=50bb03be-debb-4b06-bc08-08dd0205dd08268=1279=2269=1278=407858a5-4b67-4b44-934a-500fa458922483=159754063055=BTC-USD271=0.0000000060=20250411-01:26:26.94672458=FILLED10=232
20250411-01:26:27.435193000 : 8=FIXT.1.19=27935=X49=Coinbase56=24ab46f784d1b20db435b852086e325034=23250=TEST52=20250411-01:26:27.320044369=45262=50bb03be-debb-4b06-bc08-08dd0205dd08268=1279=0269=083=159754063155=BTC-USD29004=2.208895519560=20250411-01:26:27.31800040=137=468bf258-04df-4bc2-a4ba-278d11ae156710=029
20250411-01:26:27.435660000 : 8=FIXT.1.19=32735=X49=Coinbase56=24ab46f784d1b20db435b852086e325034=23350=TEST52=20250411-01:26:27.320054369=45262=50bb03be-debb-4b06-bc08-08dd0205dd08268=1279=0269=2278=c5b88ea9-605d-4595-ac52-f7c3f08523ba83=159754063255=BTC-USD270=3.55271=0.6222240960=20250411-01:26:27.31800037=468bf258-04df-4bc2-a4ba-278d11ae15675797=110=177
20250411-01:26:27.435965000 : 8=FIXT.1.19=26635=X49=Coinbase56=24ab46f784d1b20db435b852086e325034=23450=TEST52=20250411-01:26:27.320068369=45262=50bb03be-debb-4b06-bc08-08dd0205dd08268=1279=2269=0278=468bf258-04df-4bc2-a4ba-278d11ae156783=159754063355=BTC-USD60=20250411-01:26:27.31800058=FILLED10=051
20250411-01:26:27.463945000 : 8=FIXT.1.19=27535=X49=Coinbase56=24ab46f784d1b20db435b852086e325034=23550=TEST52=20250411-01:26:27.348456369=45262=50bb03be-debb-4b06-bc08-08dd0205dd08268=1279=0269=183=159754063455=BTC-USD271=0.6232294660=20250411-01:26:27.34741140=137=f6c6860c-ba12-4f51-bbd2-3ff3ec5947d110=196
20250411-01:26:27.464872000 : 8=FIXT.1.19=32735=X49=Coinbase56=24ab46f784d1b20db435b852086e325034=23650=TEST52=20250411-01:26:27.348463369=45262=50bb03be-debb-4b06-bc08-08dd0205dd08268=1279=0269=2278=4d60a78e-b39b-420e-b830-bc0f3f4fdde283=159754063555=BTC-USD270=3.53271=0.6232294660=20250411-01:26:27.34741137=f6c6860c-ba12-4f51-bbd2-3ff3ec5947d15797=210=183
20250411-01:26:27.465526000 : 8=FIXT.1.19=28135=X49=Coinbase56=24ab46f784d1b20db435b852086e325034=23750=TEST52=20250411-01:26:27.348467369=45262=50bb03be-debb-4b06-bc08-08dd0205dd08268=1279=2269=1278=f6c6860c-ba12-4f51-bbd2-3ff3ec5947d183=159754063655=BTC-USD271=0.0000000060=20250411-01:26:27.34741158=FILLED10=102
20250411-01:26:27.550604000 : 8=FIXT.1.19=27935=X49=Coinbase56=24ab46f784d1b20db435b852086e325034=23850=TEST52=20250411-01:26:27.434427369=45262=50bb03be-debb-4b06-bc08-08dd0205dd08268=1279=0269=083=159754063755=BTC-USD29004=2.208895519560=20250411-01:26:27.43337440=137=98419674-c988-43ea-9d32-202443d54e3f10=107
20250411-01:26:27.551252000 : 8=FIXT.1.19=32735=X49=Coinbase56=24ab46f784d1b20db435b852086e325034=23950=TEST52=20250411-01:26:27.434435369=45262=50bb03be-debb-4b06-bc08-08dd0205dd08268=1279=0269=2278=c5b88ea9-605d-4595-ac52-f7c3f08523ba83=159754063855=BTC-USD270=3.55271=0.6222240960=20250411-01:26:27.43337437=98419674-c988-43ea-9d32-202443d54e3f5797=110=253
20250411-01:26:27.552097000 : 8=FIXT.1.19=26635=X49=Coinbase56=24ab46f784d1b20db435b852086e325034=24050=TEST52=20250411-01:26:27.434438369=45262=50bb03be-debb-4b06-bc08-08dd0205dd08268=1279=2269=0278=98419674-c988-43ea-9d32-202443d54e3f83=159754063955=BTC-USD60=20250411-01:26:27.43337458=FILLED10=116
20250411-01:26:27.579604000 : 8=FIXT.1.19=27535=X49=Coinbase56=24ab46f784d1b20db435b852086e325034=24150=TEST52=20250411-01:26:27.463526369=45262=50bb03be-debb-4b06-bc08-08dd0205dd08268=1279=0269=183=159754064055=BTC-USD271=0.6232294660=20250411-01:26:27.46196740=137=43788237-d6a7-4601-b1cb-cb64b4eb893c10=059
20250411-01:26:27.580082000 : 8=FIXT.1.19=32735=X49=Coinbase56=24ab46f784d1b20db435b852086e325034=24250=TEST52=20250411-01:26:27.463532369=45262=50bb03be-debb-4b06-bc08-08dd0205dd08268=1279=0269=2278=4d60a78e-b39b-420e-b830-bc0f3f4fdde283=159754064155=BTC-USD270=3.53271=0.6232294660=20250411-01:26:27.46196737=43788237-d6a7-4601-b1cb-cb64b4eb893c5797=210=045
20250411-01:26:27.580486000 : 8=FIXT.1.19=28135=X49=Coinbase56=24ab46f784d1b20db435b852086e325034=24350=TEST52=20250411-01:26:27.463535369=45262=50bb03be-debb-4b06-bc08-08dd0205dd08268=1279=2269=1278=43788237-d6a7-4601-b1cb-cb64b4eb893c83=159754064255=BTC-USD271=0.0000000060=20250411-01:26:27.46196758=FILLED10=219
20250411-01:26:27.703405000 : 8=FIXT.1.19=31035=X49=Coinbase56=24ab46f784d1b20db435b852086e325034=24450=TEST52=20250411-01:26:27.587734369=45262=50bb03be-debb-4b06-bc08-08dd0205dd08268=1279=1269=1278=fadcd276-2def-409a-be94-be577f68ff2783=159754064355=BTC-USD270=3.59271=0.5230242560=20250411-01:26:27.58583258=CHANGE_REASON_MODIFY_ORDER10=188
20250411-01:26:27.951788000 : 8=FIXT.1.19=27935=X49=Coinbase56=24ab46f784d1b20db435b852086e325034=24550=TEST52=20250411-01:26:27.834203369=45262=50bb03be-debb-4b06-bc08-08dd0205dd08268=1279=0269=083=159754064455=BTC-USD29004=2.208895519560=20250411-01:26:27.83241940=137=1741623b-05ea-4fc3-b62d-f8530f82d61110=214
20250411-01:26:27.952155000 : 8=FIXT.1.19=32735=X49=Coinbase56=24ab46f784d1b20db435b852086e325034=24650=TEST52=20250411-01:26:27.834289369=45262=50bb03be-debb-4b06-bc08-08dd0205dd08268=1279=0269=2278=c5b88ea9-605d-4595-ac52-f7c3f08523ba83=159754064555=BTC-USD270=3.55271=0.6222240960=20250411-01:26:27.83241937=1741623b-05ea-4fc3-b62d-f8530f82d6115797=110=119
20250411-01:26:27.952743000 : 8=FIXT.1.19=26635=X49=Coinbase56=24ab46f784d1b20db435b852086e325034=24750=TEST52=20250411-01:26:27.834292369=45262=50bb03be-debb-4b06-bc08-08dd0205dd08268=1279=2269=0278=1741623b-05ea-4fc3-b62d-f8530f82d61183=159754064655=BTC-USD60=20250411-01:26:27.83241958=FILLED10=238
20250411-01:26:27.978372000 : 8=FIXT.1.19=27535=X49=Coinbase56=24ab46f784d1b20db435b852086e325034=24850=TEST52=20250411-01:26:27.862633369=45262=50bb03be-debb-4b06-bc08-08dd0205dd08268=1279=0269=183=159754064755=BTC-USD271=0.6232294660=20250411-01:26:27.86106840=137=5ef81035-aaf9-4a54-8141-e72203648bda10=015
20250411-01:26:27.978799000 : 8=FIXT.1.19=32735=X49=Coinbase56=24ab46f784d1b20db435b852086e325034=24950=TEST52=20250411-01:26:27.862641369=45262=50bb03be-debb-4b06-bc08-08dd0205dd08268=1279=0269=2278=4d60a78e-b39b-420e-b830-bc0f3f4fdde283=159754064855=BTC-USD270=3.53271=0.6232294660=20250411-01:26:27.86106837=5ef81035-aaf9-4a54-8141-e72203648bda5797=210=003
20250411-01:26:27.979095000 : 8=FIXT.1.19=28135=X49=Coinbase56=24ab46f784d1b20db435b852086e325034=25050=TEST52=20250411-01:26:27.862645369=45262=50bb03be-debb-4b06-bc08-08dd0205dd08268=1279=2269=1278=5ef81035-aaf9-4a54-8141-e72203648bda83=159754064955=BTC-USD271=0.0000000060=20250411-01:26:27.86106858=FILLED10=169
20250411-01:26:27.987688000 : 8=FIXT.1.19=31035=X49=Coinbase56=24ab46f784d1b20db435b852086e325034=25150=TEST52=20250411-01:26:27.871822369=45262=50bb03be-debb-4b06-bc08-08dd0205dd08268=1279=1269=0278=58ed893b-e3aa-47af-a913-bb90c77a59fe83=159754065055=BTC-USD270=3.51271=0.5353413260=20250411-01:26:27.87025658=CHANGE_REASON_MODIFY_ORDER10=112
20250411-01:26:28.122016000 : 8=FIXT.1.19=27935=X49=Coinbase56=24ab46f784d1b20db435b852086e325034=25250=TEST52=20250411-01:26:28.005961369=45262=50bb03be-debb-4b06-bc08-08dd0205dd08268=1279=0269=083=159754065155=BTC-USD29004=2.208895519560=20250411-01:26:28.00409340=137=0722e741-3098-40af-b02d-26e1b0b35d6810=148
20250411-01:26:28.122425000 : 8=FIXT.1.19=32735=X49=Coinbase56=24ab46f784d1b20db435b852086e325034=25350=TEST52=20250411-01:26:28.005975369=45262=50bb03be-debb-4b06-bc08-08dd0205dd08268=1279=0269=2278=c5b88ea9-605d-4595-ac52-f7c3f08523ba83=159754065255=BTC-USD270=3.55271=0.6222240960=20250411-01:26:28.00409337=0722e741-3098-40af-b02d-26e1b0b35d685797=110=044
20250411-01:26:28.122806000 : 8=FIXT.1.19=26635=X49=Coinbase56=24ab46f784d1b20db435b852086e325034=25450=TEST52=20250411-01:26:28.005987369=45262=50bb03be-debb-4b06-bc08-08dd0205dd08268=1279=2269=0278=0722e741-3098-40af-b02d-26e1b0b35d6883=159754065355=BTC-USD60=20250411-01:26:28.00409358=FILLED10=172
20250411-01:26:28.151187000 : 8=FIXT.1.19=27535=X49=Coinbase56=24ab46f784d1b20db435b852086e325034=25550=TEST52=20250411-01:26:28.034528369=45262=50bb03be-debb-4b06-bc08-08dd0205dd08268=1279=0269=183=159754065455=BTC-USD271=0.6232294660=20250411-01:26:28.03254940=137=df047cbe-bf57-416a-ac54-e8486494587c10=122
20250411-01:26:28.152227000 : 8=FIXT.1.19=32735=X49=Coinbase56=24ab46f784d1b20db435b852086e325034=25650=TEST52=20250411-01:26:28.034536369=45262=50bb03be-debb-4b06-bc08-08dd0205dd08268=1279=0269=2278=4d60a78e-b39b-420e-b830-bc0f3f4fdde283=159754065555=BTC-USD270=3.53271=0.6232294660=20250411-01:26:28.03254937=df047cbe-bf57-416a-ac54-e8486494587c5797=210=110
20250411-01:26:28.152710000 : 8=FIXT.1.19=28135=X49=Coinbase56=24ab46f784d1b20db435b852086e325034=25750=TEST52=20250411-01:26:28.034539369=45262=50bb03be-debb-4b06-bc08-08dd0205dd08268=1279=2269=1278=df047cbe-bf57-416a-ac54-e8486494587c83=159754065655=BTC-USD271=0.0000000060=20250411-01:26:28.03254958=FILLED10=028
20250411-01:26:28.273734000 : 8=FIXT.1.19=31035=X49=Coinbase56=24ab46f784d1b20db435b852086e325034=25850=TEST52=20250411-01:26:28.158021369=45262=50bb03be-debb-4b06-bc08-08dd0205dd08268=1279=1269=1278=538531e1-5caa-4f12-aed8-a3c4ce631c4383=159754065755=BTC-USD270=3.61271=0.5189875160=20250411-01:26:28.15695458=CHANGE_REASON_MODIFY_ORDER10=012
20250411-01:26:28.275320000 : 8=FIXT.1.19=8435=534=4649=24ab46f784d1b20db435b852086e325052=20250411-01:26:28.27456=Coinbase10=172
20250411-01:26:28.395265000 : 8=FIXT.1.19=28435=X49=Coinbase56=24ab46f784d1b20db435b852086e325034=25950=TEST52=20250411-01:26:28.279854369=45262=50bb03be-debb-4b06-bc08-08dd0205dd08268=1279=0269=083=159754065855=BTC-USD270=3.84271=0.6232294660=20250411-01:26:28.27787340=237=db295f4c-7142-4958-b1d9-c5916e22d9f610=224
20250411-01:26:28.396022000 : 8=FIXT.1.19=32735=X49=Coinbase56=24ab46f784d1b20db435b852086e325034=26050=TEST52=20250411-01:26:28.279932369=45262=50bb03be-debb-4b06-bc08-08dd0205dd08268=1279=0269=2278=c5b88ea9-605d-4595-ac52-f7c3f08523ba83=159754065955=BTC-USD270=3.55271=0.6232294660=20250411-01:26:28.27787337=db295f4c-7142-4958-b1d9-c5916e22d9f65797=110=166
20250411-01:26:28.396470000 : 8=FIXT.1.19=29035=X49=Coinbase56=24ab46f784d1b20db435b852086e325034=26150=TEST52=20250411-01:26:28.279934369=45262=50bb03be-debb-4b06-bc08-08dd0205dd08268=1279=2269=0278=db295f4c-7142-4958-b1d9-c5916e22d9f683=159754066055=BTC-USD270=3.84271=0.0000000060=20250411-01:26:28.27787358=FILLED10=108
20250411-01:26:28.421461000 : 8=FIXT.1.19=28435=X49=Coinbase56=24ab46f784d1b20db435b852086e325034=26250=TEST52=20250411-01:26:28.305793369=45262=50bb03be-debb-4b06-bc08-08dd0205dd08268=1279=0269=083=159754066155=BTC-USD270=3.88271=0.6232294660=20250411-01:26:28.30431740=237=2ddbed11-efa8-4a1e-9bbd-0af0e022f3f010=017
20250411-01:26:28.423483000 : 8=FIXT.1.19=32735=X49=Coinbase56=24ab46f784d1b20db435b852086e325034=26350=TEST52=20250411-01:26:28.305799369=45262=50bb03be-debb-4b06-bc08-08dd0205dd08268=1279=0269=2278=c5b88ea9-605d-4595-ac52-f7c3f08523ba83=159754066255=BTC-USD270=3.55271=0.6232294660=20250411-01:26:28.30431737=2ddbed11-efa8-4a1e-9bbd-0af0e022f3f05797=110=229
20250411-01:26:28.427281000 : 8=FIXT.1.19=29035=X49=Coinbase56=24ab46f784d1b20db435b852086e325034=26450=TEST52=20250411-01:26:28.305860369=45262=50bb03be-debb-4b06-bc08-08dd0205dd08268=1279=2269=0278=2ddbed11-efa8-4a1e-9bbd-0af0e022f3f083=159754066355=BTC-USD270=3.88271=0.0000000060=20250411-01:26:28.30431758=FILLED10=171
20250411-01:26:28.450725000 : 8=FIXT.1.19=28435=X49=Coinbase56=24ab46f784d1b20db435b852086e325034=26550=TEST52=20250411-01:26:28.334835369=45262=50bb03be-debb-4b06-bc08-08dd0205dd08268=1279=0269=183=159754066455=BTC-USD270=3.23271=0.6232294660=20250411-01:26:28.33337440=237=66ab4e82-7f17-4eda-89a9-999791134ee610=207
20250411-01:26:28.451392000 : 8=FIXT.1.19=32735=X49=Coinbase56=24ab46f784d1b20db435b852086e325034=26650=TEST52=20250411-01:26:28.334905369=45262=50bb03be-debb-4b06-bc08-08dd0205dd08268=1279=0269=2278=4d60a78e-b39b-420e-b830-bc0f3f4fdde283=159754066555=BTC-USD270=3.53271=0.6232294660=20250411-01:26:28.33337437=66ab4e82-7f17-4eda-89a9-999791134ee65797=210=036
20250411-01:26:28.451906000 : 8=FIXT.1.19=29035=X49=Coinbase56=24ab46f784d1b20db435b852086e325034=26750=TEST52=20250411-01:26:28.334910369=45262=50bb03be-debb-4b06-bc08-08dd0205dd08268=1279=2269=1278=66ab4e82-7f17-4eda-89a9-999791134ee683=159754066655=BTC-USD270=3.23271=0.0000000060=20250411-01:26:28.33337458=FILLED10=104
20250411-01:26:28.505857000 : 8=FIXT.1.19=12035=549=Coinbase56=24ab46f784d1b20db435b852086e325034=26850=TEST52=20250411-01:26:28.390458369=4558=CLIENT_LOGOUT10=120
20250411-01:34:37.582801000 : 8=FIXT.1.19=21535=A34=149=24ab46f784d1b20db435b852086e325052=20250411-01:34:37.57156=Coinbase95=4496=+RM32+RmMolSZFdV4aTo1hG5YzfMNQSdj/Lzr1KlPA4=98=0108=30141=Y553=24ab46f784d1b20db435b852086e3250554=akmwnltyfgb1137=910=104
20250411-01:34:37.905645000 : 8=FIXT.1.19=12535=A49=Coinbase56=24ab46f784d1b20db435b852086e325034=150=TEST52=20250411-01:34:37.720991369=198=0108=30141=Y1137=910=198
20250411-01:34:39.270653000 : 8=FIXT.1.19=17835=V34=249=24ab46f784d1b20db435b852086e325052=20250411-01:34:39.26956=Coinbase1128=9146=155=BTC-USD262=7a00f5f8-0c9f-4483-8ca5-754a13a8781d263=1264=0267=2269=0269=110=236
20250411-01:34:39.743778000 : 8=FIXT.1.19=27635=X49=Coinbase56=24ab46f784d1b20db435b852086e325034=250=TEST52=20250411-01:34:39.622464369=2262=7a00f5f8-0c9f-4483-8ca5-754a13a8781d268=1279=0269=083=159755059855=BTC-USD29004=2.208895519560=20250411-01:34:39.62108640=137=cafa3d40-28c5-4939-8214-f19fc4fa819c10=237
20250411-01:34:39.745075000 : 8=FIXT.1.19=32435=X49=Coinbase56=24ab46f784d1b20db435b852086e325034=350=TEST52=20250411-01:34:39.622511369=2262=7a00f5f8-0c9f-4483-8ca5-754a13a8781d268=1279=0269=2278=c5b88ea9-605d-4595-ac52-f7c3f08523ba83=159755059955=BTC-USD270=3.55271=0.6222240960=20250411-01:34:39.62108637=cafa3d40-28c5-4939-8214-f19fc4fa819c5797=110=121
20250411-01:34:39.745671000 : 8=FIXT.1.19=26335=X49=Coinbase56=24ab46f784d1b20db435b852086e325034=450=TEST52=20250411-01:34:39.622520369=2262=7a00f5f8-0c9f-4483-8ca5-754a13a8781d268=1279=2269=0278=cafa3d40-28c5-4939-8214-f19fc4fa819c83=159755060055=BTC-USD60=20250411-01:34:39.62108658=FILLED10=228
20250411-01:34:39.772102000 : 8=FIXT.1.19=27235=X49=Coinbase56=24ab46f784d1b20db435b852086e325034=550=TEST52=20250411-01:34:39.650833369=2262=7a00f5f8-0c9f-4483-8ca5-754a13a8781d268=1279=0269=183=159755060155=BTC-USD271=0.6232294660=20250411-01:34:39.64924140=137=aff2bf4e-87af-431f-ad28-5e4f2da6677010=152
20250411-01:34:39.772515000 : 8=FIXT.1.19=32435=X49=Coinbase56=24ab46f784d1b20db435b852086e325034=650=TEST52=20250411-01:34:39.650840369=2262=7a00f5f8-0c9f-4483-8ca5-754a13a8781d268=1279=0269=2278=4d60a78e-b39b-420e-b830-bc0f3f4fdde283=159755060255=BTC-USD270=3.53271=0.6232294660=20250411-01:34:39.64924137=aff2bf4e-87af-431f-ad28-5e4f2da667705797=210=139
20250411-01:34:39.772750000 : 8=FIXT.1.19=27835=X49=Coinbase56=24ab46f784d1b20db435b852086e325034=750=TEST52=20250411-01:34:39.650843369=2262=7a00f5f8-0c9f-4483-8ca5-754a13a8781d268=1279=2269=1278=aff2bf4e-87af-431f-ad28-5e4f2da6677083=159755060355=BTC-USD271=0.0000000060=20250411-01:34:39.64924158=FILLED10=066
20250411-01:34:40.430023000 : 8=FIXT.1.19=27635=X49=Coinbase56=24ab46f784d1b20db435b852086e325034=850=TEST52=20250411-01:34:40.308822369=2262=7a00f5f8-0c9f-4483-8ca5-754a13a8781d268=1279=0269=083=159755060455=BTC-USD29004=2.208895519560=20250411-01:34:40.30701040=137=e44b40f5-7b17-4aa3-80d1-3528dabc6df710=233
20250411-01:34:40.430685000 : 8=FIXT.1.19=32435=X49=Coinbase56=24ab46f784d1b20db435b852086e325034=950=TEST52=20250411-01:34:40.308832369=2262=7a00f5f8-0c9f-4483-8ca5-754a13a8781d268=1279=0269=2278=c5b88ea9-605d-4595-ac52-f7c3f08523ba83=159755060555=BTC-USD270=3.55271=0.6222240960=20250411-01:34:40.30701037=e44b40f5-7b17-4aa3-80d1-3528dabc6df75797=110=125
20250411-01:34:40.431118000 : 8=FIXT.1.19=26435=X49=Coinbase56=24ab46f784d1b20db435b852086e325034=1050=TEST52=20250411-01:34:40.308835369=2262=7a00f5f8-0c9f-4483-8ca5-754a13a8781d268=1279=2269=0278=e44b40f5-7b17-4aa3-80d1-3528dabc6df783=159755060655=BTC-USD60=20250411-01:34:40.30701058=FILLED10=037
20250411-01:34:40.431463000 : 8=FIXT.1.19=28235=X49=Coinbase56=24ab46f784d1b20db435b852086e325034=1150=TEST52=20250411-01:34:40.311532369=2262=7a00f5f8-0c9f-4483-8ca5-754a13a8781d268=1279=0269=083=159755060755=BTC-USD270=3.88271=0.6232294660=20250411-01:34:40.30995940=237=8f2ee35d-ca2b-4abf-9c4f-fa0bc7d822ee10=025
20250411-01:34:40.432102000 : 8=FIXT.1.19=32535=X49=Coinbase56=24ab46f784d1b20db435b852086e325034=1250=TEST52=20250411-01:34:40.311598369=2262=7a00f5f8-0c9f-4483-8ca5-754a13a8781d268=1279=0269=2278=c5b88ea9-605d-4595-ac52-f7c3f08523ba83=159755060855=BTC-USD270=3.55271=0.6232294660=20250411-01:34:40.30995937=8f2ee35d-ca2b-4abf-9c4f-fa0bc7d822ee5797=110=243
20250411-01:34:40.433732000 : 8=FIXT.1.19=28835=X49=Coinbase56=24ab46f784d1b20db435b852086e325034=1350=TEST52=20250411-01:34:40.311601369=2262=7a00f5f8-0c9f-4483-8ca5-754a13a8781d268=1279=2269=0278=8f2ee35d-ca2b-4abf-9c4f-fa0bc7d822ee83=159755060955=BTC-USD270=3.88271=0.0000000060=20250411-01:34:40.30995958=FILLED10=190
20250411-01:34:40.457166000 : 8=FIXT.1.19=27335=X49=Coinbase56=24ab46f784d1b20db435b852086e325034=1450=TEST52=20250411-01:34:40.337141369=2262=7a00f5f8-0c9f-4483-8ca5-754a13a8781d268=1279=0269=183=159755061055=BTC-USD271=0.6232294660=20250411-01:34:40.33535240=137=a75a8f0b-4fbb-4d74-97e0-c2fb27fdaa8510=217
20250411-01:34:40.457477000 : 8=FIXT.1.19=32535=X49=Coinbase56=24ab46f784d1b20db435b852086e325034=1550=TEST52=20250411-01:34:40.337150369=2262=7a00f5f8-0c9f-4483-8ca5-754a13a8781d268=1279=0269=2278=4d60a78e-b39b-420e-b830-bc0f3f4fdde283=159755061155=BTC-USD270=3.53271=0.6232294660=20250411-01:34:40.33535237=a75a8f0b-4fbb-4d74-97e0-c2fb27fdaa855797=210=206
20250411-01:34:40.457664000 : 8=FIXT.1.19=27935=X49=Coinbase56=24ab46f784d1b20db435b852086e325034=1650=TEST52=20250411-01:34:40.337155369=2262=7a00f5f8-0c9f-4483-8ca5-754a13a8781d268=1279=2269=1278=a75a8f0b-4fbb-4d74-97e0-c2fb27fdaa8583=159755061255=BTC-USD271=0.0000000060=20250411-01:34:40.33535258=FILLED10=135
20250411-01:34:40.656322000 : 8=FIXT.1.19=27735=X49=Coinbase56=24ab46f784d1b20db435b852086e325034=1750=TEST52=20250411-01:34:40.536413369=2262=7a00f5f8-0c9f-4483-8ca5-754a13a8781d268=1279=0269=083=159755061355=BTC-USD29004=2.208895519560=20250411-01:34:40.53525840=137=243246fb-c92d-41bd-93d7-d55661c2354b10=161
