20250411-01:34:40.656730000 : 8=FIXT.1.19=32535=X49=Coinbase56=24ab46f784d1b20db435b852086e325034=1850=TEST52=20250411-01:34:40.536422369=2262=7a00f5f8-0c9f-4483-8ca5-754a13a8781d268=1279=0269=2278=c5b88ea9-605d-4595-ac52-f7c3f08523ba83=159755061455=BTC-USD270=3.55271=0.6222240960=20250411-01:34:40.53525837=243246fb-c92d-41bd-93d7-d55661c2354b5797=110=052
20250411-01:34:40.656889000 : 8=FIXT.1.19=26435=X49=Coinbase56=24ab46f784d1b20db435b852086e325034=1950=TEST52=20250411-01:34:40.536425369=2262=7a00f5f8-0c9f-4483-8ca5-754a13a8781d268=1279=2269=0278=243246fb-c92d-41bd-93d7-d55661c2354b83=159755061555=BTC-USD60=20250411-01:34:40.53525858=FILLED10=180
20250411-01:34:40.687255000 : 8=FIXT.1.19=27335=X49=Coinbase56=24ab46f784d1b20db435b852086e325034=2050=TEST52=20250411-01:34:40.566008369=2262=7a00f5f8-0c9f-4483-8ca5-754a13a8781d268=1279=0269=183=159755061655=BTC-USD271=0.6232294660=20250411-01:34:40.56520740=137=a969666d-1adf-4b1a-855e-f60a482a183710=252
20250411-01:34:40.687524000 : 8=FIXT.1.19=32535=X49=Coinbase56=24ab46f784d1b20db435b852086e325034=2150=TEST52=20250411-01:34:40.566159369=2262=7a00f5f8-0c9f-4483-8ca5-754a13a8781d268=1279=0269=2278=4d60a78e-b39b-420e-b830-bc0f3f4fdde283=159755061755=BTC-USD270=3.53271=0.6232294660=20250411-01:34:40.56520737=a969666d-1adf-4b1a-855e-f60a482a18375797=210=248
20250411-01:34:40.687763000 : 8=FIXT.1.19=27935=X49=Coinbase56=24ab46f784d1b20db435b852086e325034=2250=TEST52=20250411-01:34:40.566164369=2262=7a00f5f8-0c9f-4483-8ca5-754a13a8781d268=1279=2269=1278=a969666d-1adf-4b1a-855e-f60a482a183783=159755061855=BTC-USD271=0.0000000060=20250411-01:34:40.56520758=FILLED10=168
20250411-01:34:40.771333000 : 8=FIXT.1.19=27735=X49=Coinbase56=24ab46f784d1b20db435b852086e325034=2350=TEST52=20250411-01:34:40.651090369=2262=7a00f5f8-0c9f-4483-8ca5-754a13a8781d268=1279=0269=083=159755061955=BTC-USD29004=2.208895519560=20250411-01:34:40.64973440=137=bec9c59c-1445-49cc-8455-ac8e8432cbb910=073
20250411-01:34:40.771715000 : 8=FIXT.1.19=32535=X49=Coinbase56=24ab46f784d1b20db435b852086e325034=2450=TEST52=20250411-01:34:40.651112369=2262=7a00f5f8-0c9f-4483-8ca5-754a13a8781d268=1279=0269=2278=c5b88ea9-605d-4595-ac52-f7c3f08523ba83=159755062055=BTC-USD270=3.55271=0.6222240960=20250411-01:34:40.64973437=bec9c59c-1445-49cc-8455-ac8e8432cbb95797=110=206
20250411-01:34:40.771903000 : 8=FIXT.1.19=26435=X49=Coinbase56=24ab46f784d1b20db435b852086e325034=2550=TEST52=20250411-01:34:40.651115369=2262=7a00f5f8-0c9f-4483-8ca5-754a13a8781d268=1279=2269=0278=bec9c59c-1445-49cc-8455-ac8e8432cbb983=159755062155=BTC-USD60=20250411-01:34:40.64973458=FILLED10=078
20250411-01:34:40.799940000 : 8=FIXT.1.19=27335=X49=Coinbase56=24ab46f784d1b20db435b852086e325034=2650=TEST52=20250411-01:34:40.679426369=2262=7a00f5f8-0c9f-4483-8ca5-754a13a8781d268=1279=0269=183=159755062255=BTC-USD271=0.6232294660=20250411-01:34:40.67832540=137=2f7c26ed-2c6e-408d-a740-d5ad43d96b8710=109
20250411-01:34:40.800532000 : 8=FIXT.1.19=32535=X49=Coinbase56=24ab46f784d1b20db435b852086e325034=2750=TEST52=20250411-01:34:40.679432369=2262=7a00f5f8-0c9f-4483-8ca5-754a13a8781d268=1279=0269=2278=4d60a78e-b39b-420e-b830-bc0f3f4fdde283=159755062355=BTC-USD270=3.53271=0.6232294660=20250411-01:34:40.67832537=2f7c26ed-2c6e-408d-a740-d5ad43d96b875797=210=095
20250411-01:34:40.800782000 : 8=FIXT.1.19=27935=X49=Coinbase56=24ab46f784d1b20db435b852086e325034=2850=TEST52=20250411-01:34:40.679436369=2262=7a00f5f8-0c9f-4483-8ca5-754a13a8781d268=1279=2269=1278=2f7c26ed-2c6e-408d-a740-d5ad43d96b8783=159755062455=BTC-USD271=0.0000000060=20250411-01:34:40.67832558=FILLED10=023
20250411-01:34:40.819389000 : 8=FIXT.1.19=28235=X49=Coinbase56=24ab46f784d1b20db435b852086e325034=2950=TEST52=20250411-01:34:40.698366369=2262=7a00f5f8-0c9f-4483-8ca5-754a13a8781d268=1279=0269=083=159755062555=BTC-USD270=3.71271=0.6232294660=20250411-01:34:40.69672840=237=3ed3a3f8-551a-4e8a-b7ab-b16ba0afc5b310=193
20250411-01:34:40.819759000 : 8=FIXT.1.19=32535=X49=Coinbase56=24ab46f784d1b20db435b852086e325034=3050=TEST52=20250411-01:34:40.698371369=2262=7a00f5f8-0c9f-4483-8ca5-754a13a8781d268=1279=0269=2278=c5b88ea9-605d-4595-ac52-f7c3f08523ba83=159755062655=BTC-USD270=3.55271=0.6232294660=20250411-01:34:40.69672837=3ed3a3f8-551a-4e8a-b7ab-b16ba0afc5b35797=110=138
20250411-01:34:40.819975000 : 8=FIXT.1.19=28835=X49=Coinbase56=24ab46f784d1b20db435b852086e325034=3150=TEST52=20250411-01:34:40.698374369=2262=7a00f5f8-0c9f-4483-8ca5-754a13a8781d268=1279=2269=0278=3ed3a3f8-551a-4e8a-b7ab-b16ba0afc5b383=159755062755=BTC-USD270=3.71271=0.0000000060=20250411-01:34:40.69672858=FILLED10=095
20250411-01:34:40.820241000 : 8=FIXT.1.19=28235=X49=Coinbase56=24ab46f784d1b20db435b852086e325034=3250=TEST52=20250411-01:34:40.698423369=2262=7a00f5f8-0c9f-4483-8ca5-754a13a8781d268=1279=0269=083=159755062855=BTC-USD270=3.75271=0.6232294660=20250411-01:34:40.69672840=237=82f4c86a-51c6-4d89-9b71-1b86434b786f10=107
20250411-01:34:40.822021000 : 8=FIXT.1.19=32535=X49=Coinbase56=24ab46f784d1b20db435b852086e325034=3350=TEST52=20250411-01:34:40.698431369=2262=7a00f5f8-0c9f-4483-8ca5-754a13a8781d268=1279=0269=2278=c5b88ea9-605d-4595-ac52-f7c3f08523ba83=159755062955=BTC-USD270=3.55271=0.6232294660=20250411-01:34:40.69672837=82f4c86a-51c6-4d89-9b71-1b86434b786f5797=110=060
20250411-01:34:40.822454000 : 8=FIXT.1.19=28835=X49=Coinbase56=24ab46f784d1b20db435b852086e325034=3450=TEST52=20250411-01:34:40.698561369=2262=7a00f5f8-0c9f-4483-8ca5-754a13a8781d268=1279=2269=0278=82f4c86a-51c6-4d89-9b71-1b86434b786f83=159755063055=BTC-USD270=3.75271=0.0000000060=20250411-01:34:40.69672858=FILLED10=013
20250411-01:34:40.822676000 : 8=FIXT.1.19=28235=X49=Coinbase56=24ab46f784d1b20db435b852086e325034=3550=TEST52=20250411-01:34:40.698563369=2262=7a00f5f8-0c9f-4483-8ca5-754a13a8781d268=1279=0269=083=159755063155=BTC-USD270=3.72271=0.6232294660=20250411-01:34:40.69672840=237=3ff3464a-dce0-4c91-842f-3c117de35af510=014
20250411-01:34:40.823325000 : 8=FIXT.1.19=32535=X49=Coinbase56=24ab46f784d1b20db435b852086e325034=3650=TEST52=20250411-01:34:40.698566369=2262=7a00f5f8-0c9f-4483-8ca5-754a13a8781d268=1279=0269=2278=c5b88ea9-605d-4595-ac52-f7c3f08523ba83=159755063255=BTC-USD270=3.55271=0.6232294660=20250411-01:34:40.69672837=3ff3464a-dce0-4c91-842f-3c117de35af55797=110=230
20250411-01:34:40.823499000 : 8=FIXT.1.19=28835=X49=Coinbase56=24ab46f784d1b20db435b852086e325034=3750=TEST52=20250411-01:34:40.698567369=2262=7a00f5f8-0c9f-4483-8ca5-754a13a8781d268=1279=2269=0278=3ff3464a-dce0-4c91-842f-3c117de35af583=159755063355=BTC-USD270=3.72271=0.0000000060=20250411-01:34:40.69672858=FILLED10=186
20250411-01:34:40.825061000 : 8=FIXT.1.19=28235=X49=Coinbase56=24ab46f784d1b20db435b852086e325034=3850=TEST52=20250411-01:34:40.698569369=2262=7a00f5f8-0c9f-4483-8ca5-754a13a8781d268=1279=0269=083=159755063455=BTC-USD270=3.86271=0.6232294660=20250411-01:34:40.69672840=237=13364b4f-cf7f-46f4-957f-de406fede89810=067
20250411-01:34:40.825566000 : 8=FIXT.1.19=32535=X49=Coinbase56=24ab46f784d1b20db435b852086e325034=3950=TEST52=20250411-01:34:40.698571369=2262=7a00f5f8-0c9f-4483-8ca5-754a13a8781d268=1279=0269=2278=c5b88ea9-605d-4595-ac52-f7c3f08523ba83=159755063555=BTC-USD270=3.55271=0.6232294660=20250411-01:34:40.69672837=13364b4f-cf7f-46f4-957f-de406fede8985797=110=012
20250411-01:34:40.826003000 : 8=FIXT.1.19=28835=X49=Coinbase56=24ab46f784d1b20db435b852086e325034=4050=TEST52=20250411-01:34:40.698572369=2262=7a00f5f8-0c9f-4483-8ca5-754a13a8781d268=1279=2269=0278=13364b4f-cf7f-46f4-957f-de406fede89883=159755063655=BTC-USD270=3.86271=0.0000000060=20250411-01:34:40.69672858=FILLED10=220
20250411-01:34:41.045467000 : 8=FIXT.1.19=28235=X49=Coinbase56=24ab46f784d1b20db435b852086e325034=4150=TEST52=20250411-01:34:40.925440369=2262=7a00f5f8-0c9f-4483-8ca5-754a13a8781d268=1279=0269=183=159755063755=BTC-USD270=3.34271=0.6232294660=20250411-01:34:40.92410840=237=ab98530d-a10b-4337-bb40-af67206bcc7310=178
20250411-01:34:41.046125000 : 8=FIXT.1.19=32535=X49=Coinbase56=24ab46f784d1b20db435b852086e325034=4250=TEST52=20250411-01:34:40.925451369=2262=7a00f5f8-0c9f-4483-8ca5-754a13a8781d268=1279=0269=2278=4d60a78e-b39b-420e-b830-bc0f3f4fdde283=159755063855=BTC-USD270=3.53271=0.6232294660=20250411-01:34:40.92410837=ab98530d-a10b-4337-bb40-af67206bcc735797=210=009
20250411-01:34:41.047352000 : 8=FIXT.1.19=28835=X49=Coinbase56=24ab46f784d1b20db435b852086e325034=4350=TEST52=20250411-01:34:40.925455369=2262=7a00f5f8-0c9f-4483-8ca5-754a13a8781d268=1279=2269=1278=ab98530d-a10b-4337-bb40-af67206bcc7383=159755063955=BTC-USD270=3.34271=0.0000000060=20250411-01:34:40.92410858=FILLED10=096
20250411-01:34:41.047520000 : 8=FIXT.1.19=28235=X49=Coinbase56=24ab46f784d1b20db435b852086e325034=4450=TEST52=20250411-01:34:40.925457369=2262=7a00f5f8-0c9f-4483-8ca5-754a13a8781d268=1279=0269=183=159755064055=BTC-USD270=3.31271=0.6232294660=20250411-01:34:40.92410840=237=fcc77e6d-ebb8-4116-8e60-facbab00b76b10=178
20250411-01:34:41.047723000 : 8=FIXT.1.19=32535=X49=Coinbase56=24ab46f784d1b20db435b852086e325034=4550=TEST52=20250411-01:34:40.925461369=2262=7a00f5f8-0c9f-4483-8ca5-754a13a8781d268=1279=0269=2278=4d60a78e-b39b-420e-b830-bc0f3f4fdde283=159755064155=BTC-USD270=3.53271=0.6232294660=20250411-01:34:40.92410837=fcc77e6d-ebb8-4116-8e60-facbab00b76b5797=210=005
20250411-01:34:41.047928000 : 8=FIXT.1.19=28835=X49=Coinbase56=24ab46f784d1b20db435b852086e325034=4650=TEST52=20250411-01:34:40.925463369=2262=7a00f5f8-0c9f-4483-8ca5-754a13a8781d268=1279=2269=1278=fcc77e6d-ebb8-4116-8e60-facbab00b76b83=159755064255=BTC-USD270=3.31271=0.0000000060=20250411-01:34:40.92410858=FILLED10=087
20250411-01:34:41.049213000 : 8=FIXT.1.19=28235=X49=Coinbase56=24ab46f784d1b20db435b852086e325034=4750=TEST52=20250411-01:34:40.925557369=2262=7a00f5f8-0c9f-4483-8ca5-754a13a8781d268=1279=0269=183=159755064355=BTC-USD270=3.29271=0.6232294660=20250411-01:34:40.92410840=237=6fbdaa65-9ed7-4824-9a59-4f9f37f88e4010=251
20250411-01:34:41.049556000 : 8=FIXT.1.19=32535=X49=Coinbase56=24ab46f784d1b20db435b852086e325034=4850=TEST52=20250411-01:34:40.925560369=2262=7a00f5f8-0c9f-4483-8ca5-754a13a8781d268=1279=0269=2278=4d60a78e-b39b-420e-b830-bc0f3f4fdde283=159755064455=BTC-USD270=3.53271=0.6232294660=20250411-01:34:40.92410837=6fbdaa65-9ed7-4824-9a59-4f9f37f88e405797=210=070
20250411-01:34:41.050883000 : 8=FIXT.1.19=28835=X49=Coinbase56=24ab46f784d1b20db435b852086e325034=4950=TEST52=20250411-01:34:40.925562369=2262=7a00f5f8-0c9f-4483-8ca5-754a13a8781d268=1279=2269=1278=6fbdaa65-9ed7-4824-9a59-4f9f37f88e4083=159755064555=BTC-USD270=3.29271=0.0000000060=20250411-01:34:40.92410858=FILLED10=159
20250411-01:34:41.120248000 : 8=FIXT.1.19=27735=X49=Coinbase56=24ab46f784d1b20db435b852086e325034=5050=TEST52=20250411-01:34:40.995196369=2262=7a00f5f8-0c9f-4483-8ca5-754a13a8781d268=1279=0269=083=159755064655=BTC-USD29004=2.208895519560=20250411-01:34:40.99242340=137=861b5ecc-40eb-4b6a-aa5a-b6e4698cae8b10=003
20250411-01:34:41.120703000 : 8=FIXT.1.19=32535=X49=Coinbase56=24ab46f784d1b20db435b852086e325034=5150=TEST52=20250411-01:34:40.995200369=2262=7a00f5f8-0c9f-4483-8ca5-754a13a8781d268=1279=0269=2278=c5b88ea9-605d-4595-ac52-f7c3f08523ba83=159755064755=BTC-USD270=3.55271=0.6222240960=20250411-01:34:40.99242337=861b5ecc-40eb-4b6a-aa5a-b6e4698cae8b5797=110=136
20250411-01:34:41.121081000 : 8=FIXT.1.19=26435=X49=Coinbase56=24ab46f784d1b20db435b852086e325034=5250=TEST52=20250411-01:34:40.995203369=2262=7a00f5f8-0c9f-4483-8ca5-754a13a8781d268=1279=2269=0278=861b5ecc-40eb-4b6a-aa5a-b6e4698cae8b83=159755064855=BTC-USD60=20250411-01:34:40.99242358=FILLED10=008
20250411-01:34:41.143582000 : 8=FIXT.1.19=27335=X49=Coinbase56=24ab46f784d1b20db435b852086e325034=5350=TEST52=20250411-01:34:41.022448369=2262=7a00f5f8-0c9f-4483-8ca5-754a13a8781d268=1279=0269=183=159755064955=BTC-USD271=0.6232294660=20250411-01:34:41.02133540=137=39716da2-d99f-47eb-b206-5ec5529b5c7b10=047
20250411-01:34:41.145259000 : 8=FIXT.1.19=32535=X49=Coinbase56=24ab46f784d1b20db435b852086e325034=5450=TEST52=20250411-01:34:41.022506369=2262=7a00f5f8-0c9f-4483-8ca5-754a13a8781d268=1279=0269=2278=4d60a78e-b39b-420e-b830-bc0f3f4fdde283=159755065055=BTC-USD270=3.53271=0.6232294660=20250411-01:34:41.02133537=39716da2-d99f-47eb-b206-5ec5529b5c7b5797=210=022
20250411-01:34:41.146380000 : 8=FIXT.1.19=27935=X49=Coinbase56=24ab46f784d1b20db435b852086e325034=5550=TEST52=20250411-01:34:41.022512369=2262=7a00f5f8-0c9f-4483-8ca5-754a13a8781d268=1279=2269=1278=39716da2-d99f-47eb-b206-5ec5529b5c7b83=159755065155=BTC-USD271=0.0000000060=20250411-01:34:41.02133558=FILLED10=199
20250411-01:34:41.257057000 : 8=FIXT.1.19=28135=X49=Coinbase56=24ab46f784d1b20db435b852086e325034=5650=TEST52=20250411-01:34:41.134860369=2262=7a00f5f8-0c9f-4483-8ca5-754a13a8781d268=1279=0269=183=159755065255=BTC-USD270=3.6271=0.6232294660=20250411-01:34:41.13336940=237=f3f78323-40ff-440d-83ce-0f351ab9cd2910=155
20250411-01:34:41.257617000 : 8=FIXT.1.19=27735=X49=Coinbase56=24ab46f784d1b20db435b852086e325034=5750=TEST52=20250411-01:34:41.134868369=2262=7a00f5f8-0c9f-4483-8ca5-754a13a8781d268=1279=0269=1278=f3f78323-40ff-440d-83ce-0f351ab9cd2983=159755065355=BTC-USD270=3.6271=0.6232294660=20250411-01:34:41.13336910=013
20250411-01:34:41.404984000 : 8=FIXT.1.19=27735=X49=Coinbase56=24ab46f784d1b20db435b852086e325034=5850=TEST52=20250411-01:34:41.279275369=2262=7a00f5f8-0c9f-4483-8ca5-754a13a8781d268=1279=0269=083=159755065455=BTC-USD29004=2.208895519560=20250411-01:34:41.27763240=137=a67dcfa8-90d3-4cf0-8ad6-36f5d379dd8310=137
20250411-01:34:41.406644000 : 8=FIXT.1.19=32535=X49=Coinbase56=24ab46f784d1b20db435b852086e325034=5950=TEST52=20250411-01:34:41.279281369=2262=7a00f5f8-0c9f-4483-8ca5-754a13a8781d268=1279=0269=2278=c5b88ea9-605d-4595-ac52-f7c3f08523ba83=159755065555=BTC-USD270=3.55271=0.6222240960=20250411-01:34:41.27763237=a67dcfa8-90d3-4cf0-8ad6-36f5d379dd835797=110=025
20250411-01:34:41.407586000 : 8=FIXT.1.19=26435=X49=Coinbase56=24ab46f784d1b20db435b852086e325034=6050=TEST52=20250411-01:34:41.279286369=2262=7a00f5f8-0c9f-4483-8ca5-754a13a8781d268=1279=2269=0278=a67dcfa8-90d3-4cf0-8ad6-36f5d379dd8383=159755065655=BTC-USD60=20250411-01:34:41.27763258=FILLED10=146
20250411-01:34:41.429079000 : 8=FIXT.1.19=27335=X49=Coinbase56=24ab46f784d1b20db435b852086e325034=6150=TEST52=20250411-01:34:41.308692369=2262=7a00f5f8-0c9f-4483-8ca5-754a13a8781d268=1279=0269=183=159755065755=BTC-USD271=0.6232294660=20250411-01:34:41.30707440=137=60ca853b-427d-4fe6-b1e7-10343c6e0a1b10=028
20250411-01:34:41.429846000 : 8=FIXT.1.19=32535=X49=Coinbase56=24ab46f784d1b20db435b852086e325034=6250=TEST52=20250411-01:34:41.308702369=2262=7a00f5f8-0c9f-4483-8ca5-754a13a8781d268=1279=0269=2278=4d60a78e-b39b-420e-b830-bc0f3f4fdde283=159755065855=BTC-USD270=3.53271=0.6232294660=20250411-01:34:41.30707437=60ca853b-427d-4fe6-b1e7-10343c6e0a1b5797=210=009
20250411-01:34:41.430510000 : 8=FIXT.1.19=27935=X49=Coinbase56=24ab46f784d1b20db435b852086e325034=6350=TEST52=20250411-01:34:41.308706369=2262=7a00f5f8-0c9f-4483-8ca5-754a13a8781d268=1279=2269=1278=60ca853b-427d-4fe6-b1e7-10343c6e0a1b83=159755065955=BTC-USD271=0.0000000060=20250411-01:34:41.30707458=FILLED10=193
20250411-01:34:41.431488000 : 8=FIXT.1.19=28235=X49=Coinbase56=24ab46f784d1b20db435b852086e325034=6450=TEST52=20250411-01:34:41.310299369=2262=7a00f5f8-0c9f-4483-8ca5-754a13a8781d268=1279=0269=183=159755066055=BTC-USD270=3.18271=0.6232294660=20250411-01:34:41.30900840=237=372cc98b-f354-4781-9f92-ef032352fb5710=075
20250411-01:34:41.432098000 : 8=FIXT.1.19=32535=X49=Coinbase56=24ab46f784d1b20db435b852086e325034=6550=TEST52=20250411-01:34:41.310303369=2262=7a00f5f8-0c9f-4483-8ca5-754a13a8781d268=1279=0269=2278=4d60a78e-b39b-420e-b830-bc0f3f4fdde283=159755066155=BTC-USD270=3.53271=0.6232294660=20250411-01:34:41.30900837=372cc98b-f354-4781-9f92-ef032352fb575797=210=144
20250411-01:34:41.433073000 : 8=FIXT.1.19=28835=X49=Coinbase56=24ab46f784d1b20db435b852086e325034=6650=TEST52=20250411-01:34:41.310401369=2262=7a00f5f8-0c9f-4483-8ca5-754a13a8781d268=1279=2269=1278=372cc98b-f354-4781-9f92-ef032352fb5783=159755066255=BTC-USD270=3.18271=0.0000000060=20250411-01:34:41.30900858=FILLED10=228
20250411-01:34:41.514882000 : 8=FIXT.1.19=27735=X49=Coinbase56=24ab46f784d1b20db435b852086e325034=6750=TEST52=20250411-01:34:41.394108369=2262=7a00f5f8-0c9f-4483-8ca5-754a13a8781d268=1279=0269=083=159755066355=BTC-USD29004=2.208895519560=20250411-01:34:41.39269240=137=6183a207-bc3e-4f52-913d-a67be46a061310=169
20250411-01:34:41.515448000 : 8=FIXT.1.19=32535=X49=Coinbase56=24ab46f784d1b20db435b852086e325034=6850=TEST52=20250411-01:34:41.394117369=2262=7a00f5f8-0c9f-4483-8ca5-754a13a8781d268=1279=0269=2278=c5b88ea9-605d-4595-ac52-f7c3f08523ba83=159755066455=BTC-USD270=3.55271=0.6222240960=20250411-01:34:41.39269237=6183a207-bc3e-4f52-913d-a67be46a06135797=110=060
20250411-01:34:41.515657000 : 8=FIXT.1.19=26435=X49=Coinbase56=24ab46f784d1b20db435b852086e325034=6950=TEST52=20250411-01:34:41.394120369=2262=7a00f5f8-0c9f-4483-8ca5-754a13a8781d268=1279=2269=0278=6183a207-bc3e-4f52-913d-a67be46a061383=159755066555=BTC-USD60=20250411-01:34:41.39269258=FILLED10=179
20250411-01:34:41.539919000 : 8=FIXT.1.19=28235=X49=Coinbase56=24ab46f784d1b20db435b852086e325034=7050=TEST52=20250411-01:34:41.419257369=2262=7a00f5f8-0c9f-4483-8ca5-754a13a8781d268=1279=0269=083=159755066655=BTC-USD270=3.48271=0.6232294660=20250411-01:34:41.41758040=237=cc53f0bf-e87d-4774-9ece-cc731b02b1c510=102
20250411-01:34:41.540575000 : 8=FIXT.1.19=27835=X49=Coinbase56=24ab46f784d1b20db435b852086e325034=7150=TEST52=20250411-01:34:41.419262369=2262=7a00f5f8-0c9f-4483-8ca5-754a13a8781d268=1279=0269=0278=cc53f0bf-e87d-4774-9ece-cc731b02b1c583=159755066755=BTC-USD270=3.48271=0.6232294660=20250411-01:34:41.41758010=204
20250411-01:34:41.543286000 : 8=FIXT.1.19=27335=X49=Coinbase56=24ab46f784d1b20db435b852086e325034=7250=TEST52=20250411-01:34:41.423014369=2262=7a00f5f8-0c9f-4483-8ca5-754a13a8781d268=1279=0269=183=159755066855=BTC-USD271=0.6232294660=20250411-01:34:41.42183540=137=a0ae5c27-a059-424c-bce1-2c52f56e666810=033
20250411-01:34:41.543484000 : 8=FIXT.1.19=32535=X49=Coinbase56=24ab46f784d1b20db435b852086e325034=7350=TEST52=20250411-01:34:41.423021369=2262=7a00f5f8-0c9f-4483-8ca5-754a13a8781d268=1279=0269=2278=4d60a78e-b39b-420e-b830-bc0f3f4fdde283=159755066955=BTC-USD270=3.53271=0.6232294660=20250411-01:34:41.42183537=a0ae5c27-a059-424c-bce1-2c52f56e66685797=210=020
20250411-01:34:41.543740000 : 8=FIXT.1.19=27935=X49=Coinbase56=24ab46f784d1b20db435b852086e325034=7450=TEST52=20250411-01:34:41.423063369=2262=7a00f5f8-0c9f-4483-8ca5-754a13a8781d268=1279=2269=1278=a0ae5c27-a059-424c-bce1-2c52f56e666883=159755067055=BTC-USD271=0.0000000060=20250411-01:34:41.42183558=FILLED10=197
20250411-01:34:42.309156000 : 8=FIXT.1.19=27735=X49=Coinbase56=24ab46f784d1b20db435b852086e325034=7550=TEST52=20250411-01:34:42.078583369=2262=7a00f5f8-0c9f-4483-8ca5-754a13a8781d268=1279=0269=083=159755067155=BTC-USD29004=2.208895519560=20250411-01:34:42.07714840=137=b9113d84-0705-419d-a4db-b99d7a1dacc710=066
20250411-01:34:42.309788000 : 8=FIXT.1.19=32535=X49=Coinbase56=24ab46f784d1b20db435b852086e325034=7650=TEST52=20250411-01:34:42.078694369=2262=7a00f5f8-0c9f-4483-8ca5-754a13a8781d268=1279=0269=2278=c5b88ea9-605d-4595-ac52-f7c3f08523ba83=159755067255=BTC-USD270=3.55271=0.6222240960=20250411-01:34:42.07714837=b9113d84-0705-419d-a4db-b99d7a1dacc75797=110=216
20250411-01:34:42.310157000 : 8=FIXT.1.19=26435=X49=Coinbase56=24ab46f784d1b20db435b852086e325034=7750=TEST52=20250411-01:34:42.078747369=2262=7a00f5f8-0c9f-4483-8ca5-754a13a8781d268=1279=2269=0278=b9113d84-0705-419d-a4db-b99d7a1dacc783=159755067355=BTC-USD60=20250411-01:34:42.07714858=FILLED10=084
20250411-01:34:42.310553000 : 8=FIXT.1.19=27335=X49=Coinbase56=24ab46f784d1b20db435b852086e325034=7850=TEST52=20250411-01:34:42.108115369=2262=7a00f5f8-0c9f-4483-8ca5-754a13a8781d268=1279=0269=183=159755067455=BTC-USD271=0.6232294660=20250411-01:34:42.10655540=137=046c03f2-053f-450b-b75f-82dcecf82b4110=033
20250411-01:34:42.311559000 : 8=FIXT.1.19=32535=X49=Coinbase56=24ab46f784d1b20db435b852086e325034=7950=TEST52=20250411-01:34:42.108124369=2262=7a00f5f8-0c9f-4483-8ca5-754a13a8781d268=1279=0269=2278=4d60a78e-b39b-420e-b830-bc0f3f4fdde283=159755067555=BTC-USD270=3.53271=0.6232294660=20250411-01:34:42.10655537=046c03f2-053f-450b-b75f-82dcecf82b415797=210=022
20250411-01:34:42.311720000 : 8=FIXT.1.19=27935=X49=Coinbase56=24ab46f784d1b20db435b852086e325034=8050=TEST52=20250411-01:34:42.108201369=2262=7a00f5f8-0c9f-4483-8ca5-754a13a8781d268=1279=2269=1278=046c03f2-053f-450b-b75f-82dcecf82b4183=159755067655=BTC-USD271=0.0000000060=20250411-01:34:42.10655558=FILLED10=189
20250411-01:34:42.399902000 : 8=FIXT.1.19=28235=X49=Coinbase56=24ab46f784d1b20db435b852086e325034=8150=TEST52=20250411-01:34:42.278683369=2262=7a00f5f8-0c9f-4483-8ca5-754a13a8781d268=1279=0269=183=159755067755=BTC-USD270=3.66271=0.6232294660=20250411-01:34:42.27683340=237=f0d87c91-a224-40b3-a344-b13d87abda1710=212
20250411-01:34:42.400529000 : 8=FIXT.1.19=27835=X49=Coinbase56=24ab46f784d1b20db435b852086e325034=8250=TEST52=20250411-01:34:42.278690369=2262=7a00f5f8-0c9f-4483-8ca5-754a13a8781d268=1279=0269=1278=f0d87c91-a224-40b3-a344-b13d87abda1783=159755067855=BTC-USD270=3.66271=0.6232294660=20250411-01:34:42.27683310=060
20250411-01:34:42.572909000 : 8=FIXT.1.19=28235=X49=Coinbase56=24ab46f784d1b20db435b852086e325034=8350=TEST52=20250411-01:34:42.452675369=2262=7a00f5f8-0c9f-4483-8ca5-754a13a8781d268=1279=0269=183=159755067955=BTC-USD270=3.69271=0.6232294660=20250411-01:34:42.45134140=237=207d5707-e412-4dc9-bca8-9b1bd7853e9210=181
20250411-01:34:42.573388000 : 8=FIXT.1.19=27835=X49=Coinbase56=24ab46f784d1b20db435b852086e325034=8450=TEST52=20250411-01:34:42.452682369=2262=7a00f5f8-0c9f-4483-8ca5-754a13a8781d268=1279=0269=1278=207d5707-e412-4dc9-bca8-9b1bd7853e9283=159755068055=BTC-USD270=3.69271=0.6232294660=20250411-01:34:42.45134110=020
20250411-01:34:42.681259000 : 8=FIXT.1.19=28235=X49=Coinbase56=24ab46f784d1b20db435b852086e325034=8550=TEST52=20250411-01:34:42.561273369=2262=7a00f5f8-0c9f-4483-8ca5-754a13a8781d268=1279=0269=083=159755068155=BTC-USD270=3.48271=0.6232294660=20250411-01:34:42.55985740=237=7c61ac46-d01c-425d-89f8-fa885c73362b10=192
20250411-01:34:42.681686000 : 8=FIXT.1.19=27835=X49=Coinbase56=24ab46f784d1b20db435b852086e325034=8650=TEST52=20250411-01:34:42.561279369=2262=7a00f5f8-0c9f-4483-8ca5-754a13a8781d268=1279=0269=0278=7c61ac46-d01c-425d-89f8-fa885c73362b83=159755068255=BTC-USD270=3.48271=0.6232294660=20250411-01:34:42.55985710=048
20250411-01:34:42.887286000 : 8=FIXT.1.19=27735=X49=Coinbase56=24ab46f784d1b20db435b852086e325034=8750=TEST52=20250411-01:34:42.764794369=2262=7a00f5f8-0c9f-4483-8ca5-754a13a8781d268=1279=0269=083=159755068355=BTC-USD29004=2.208895519560=20250411-01:34:42.76347340=137=b0c8e354-1542-4e55-92e4-2981b6f02ea810=152
20250411-01:34:42.888166000 : 8=FIXT.1.19=32535=X49=Coinbase56=24ab46f784d1b20db435b852086e325034=8850=TEST52=20250411-01:34:42.764804369=2262=7a00f5f8-0c9f-4483-8ca5-754a13a8781d268=1279=0269=2278=c5b88ea9-605d-4595-ac52-f7c3f08523ba83=159755068455=BTC-USD270=3.55271=0.6222240960=20250411-01:34:42.76347337=b0c8e354-1542-4e55-92e4-2981b6f02ea85797=110=035
20250411-01:34:42.888407000 : 8=FIXT.1.19=26435=X49=Coinbase56=24ab46f784d1b20db435b852086e325034=8950=TEST52=20250411-01:34:42.764807369=2262=7a00f5f8-0c9f-4483-8ca5-754a13a8781d268=1279=2269=0278=b0c8e354-1542-4e55-92e4-2981b6f02ea883=159755068555=BTC-USD60=20250411-01:34:42.76347358=FILLED10=163
20250411-01:34:42.914217000 : 8=FIXT.1.19=27335=X49=Coinbase56=24ab46f784d1b20db435b852086e325034=9050=TEST52=20250411-01:34:42.794355369=2262=7a00f5f8-0c9f-4483-8ca5-754a13a8781d268=1279=0269=183=159755068655=BTC-USD271=0.6232294660=20250411-01:34:42.79235840=137=a39cabd1-4a23-411d-86fa-2c148b52a99210=055
20250411-01:34:42.914717000 : 8=FIXT.1.19=32535=X49=Coinbase56=24ab46f784d1b20db435b852086e325034=9150=TEST52=20250411-01:34:42.794362369=2262=7a00f5f8-0c9f-4483-8ca5-754a13a8781d268=1279=0269=2278=4d60a78e-b39b-420e-b830-bc0f3f4fdde283=159755068755=BTC-USD270=3.53271=0.6232294660=20250411-01:34:42.79235837=a39cabd1-4a23-411d-86fa-2c148b52a9925797=210=042
20250411-01:34:42.915176000 : 8=FIXT.1.19=27935=X49=Coinbase56=24ab46f784d1b20db435b852086e325034=9250=TEST52=20250411-01:34:42.794365369=2262=7a00f5f8-0c9f-4483-8ca5-754a13a8781d268=1279=2269=1278=a39cabd1-4a23-411d-86fa-2c148b52a99283=159755068855=BTC-USD271=0.0000000060=20250411-01:34:42.79235858=FILLED10=225
20250411-01:34:43.342216000 : 8=FIXT.1.19=27735=X49=Coinbase56=24ab46f784d1b20db435b852086e325034=9350=TEST52=20250411-01:34:43.222170369=2262=7a00f5f8-0c9f-4483-8ca5-754a13a8781d268=1279=0269=083=159755068955=BTC-USD29004=2.208895519560=20250411-01:34:43.22101040=137=aba51461-a9a5-4afc-b3f0-1cdd81ea47c910=171
20250411-01:34:43.342904000 : 8=FIXT.1.19=32535=X49=Coinbase56=24ab46f784d1b20db435b852086e325034=9450=TEST52=20250411-01:34:43.222184369=2262=7a00f5f8-0c9f-4483-8ca5-754a13a8781d268=1279=0269=2278=c5b88ea9-605d-4595-ac52-f7c3f08523ba83=159755069055=BTC-USD270=3.55271=0.6222240960=20250411-01:34:43.22101037=aba51461-a9a5-4afc-b3f0-1cdd81ea47c95797=110=058
20250411-01:34:43.343463000 : 8=FIXT.1.19=26435=X49=Coinbase56=24ab46f784d1b20db435b852086e325034=9550=TEST52=20250411-01:34:43.222186369=2262=7a00f5f8-0c9f-4483-8ca5-754a13a8781d268=1279=2269=0278=aba51461-a9a5-4afc-b3f0-1cdd81ea47c983=159755069155=BTC-USD60=20250411-01:34:43.22101058=FILLED10=185
20250411-01:34:43.370785000 : 8=FIXT.1.19=27335=X49=Coinbase56=24ab46f784d1b20db435b852086e325034=9650=TEST52=20250411-01:34:43.250334369=2262=7a00f5f8-0c9f-4483-8ca5-754a13a8781d268=1279=0269=183=159755069255=BTC-USD271=0.6232294660=20250411-01:34:43.24884240=137=d5bfd2aa-b9b1-479f-b564-5dcdafa4533f10=036
20250411-01:34:43.371364000 : 8=FIXT.1.19=32535=X49=Coinbase56=24ab46f784d1b20db435b852086e325034=9750=TEST52=20250411-01:34:43.250345369=2262=7a00f5f8-0c9f-4483-8ca5-754a13a8781d268=1279=0269=2278=4d60a78e-b39b-420e-b830-bc0f3f4fdde283=159755069355=BTC-USD270=3.53271=0.6232294660=20250411-01:34:43.24884237=d5bfd2aa-b9b1-479f-b564-5dcdafa4533f5797=210=027
20250411-01:34:43.371681000 : 8=FIXT.1.19=27935=X49=Coinbase56=24ab46f784d1b20db435b852086e325034=9850=TEST52=20250411-01:34:43.250349369=2262=7a00f5f8-0c9f-4483-8ca5-754a13a8781d268=1279=2269=1278=d5bfd2aa-b9b1-479f-b564-5dcdafa4533f83=159755069455=BTC-USD271=0.0000000060=20250411-01:34:43.24884258=FILLED10=211
20250411-01:34:43.399239000 : 8=FIXT.1.19=27735=X49=Coinbase56=24ab46f784d1b20db435b852086e325034=9950=TEST52=20250411-01:34:43.278743369=2262=7a00f5f8-0c9f-4483-8ca5-754a13a8781d268=1279=0269=083=159755069555=BTC-USD29004=2.208895519560=20250411-01:34:43.27735640=137=17fed1f9-142f-4716-923d-66738540dc2710=118
20250411-01:34:43.399773000 : 8=FIXT.1.19=32635=X49=Coinbase56=24ab46f784d1b20db435b852086e325034=10050=TEST52=20250411-01:34:43.278750369=2262=7a00f5f8-0c9f-4483-8ca5-754a13a8781d268=1279=0269=2278=c5b88ea9-605d-4595-ac52-f7c3f08523ba83=159755069655=BTC-USD270=3.55271=0.6222240960=20250411-01:34:43.27735637=17fed1f9-142f-4716-923d-66738540dc275797=110=038
20250411-01:34:43.400186000 : 8=FIXT.1.19=26535=X49=Coinbase56=24ab46f784d1b20db435b852086e325034=10150=TEST52=20250411-01:34:43.278754369=2262=7a00f5f8-0c9f-4483-8ca5-754a13a8781d268=1279=2269=0278=17fed1f9-142f-4716-923d-66738540dc2783=159755069755=BTC-USD60=20250411-01:34:43.27735658=FILLED10=167
20250411-01:34:43.427208000 : 8=FIXT.1.19=27435=X49=Coinbase56=24ab46f784d1b20db435b852086e325034=10250=TEST52=20250411-01:34:43.307146369=2262=7a00f5f8-0c9f-4483-8ca5-754a13a8781d268=1279=0269=183=159755069855=BTC-USD271=0.6197183160=20250411-01:34:43.30571940=137=f5b5b6b1-7d2e-42b6-9650-73a5097225f810=219
20250411-01:34:43.427690000 : 8=FIXT.1.19=32635=X49=Coinbase56=24ab46f784d1b20db435b852086e325034=10350=TEST52=20250411-01:34:43.307154369=2262=7a00f5f8-0c9f-4483-8ca5-754a13a8781d268=1279=0269=2278=4d60a78e-b39b-420e-b830-bc0f3f4fdde283=159755069955=BTC-USD270=3.53271=0.6197183160=20250411-01:34:43.30571937=f5b5b6b1-7d2e-42b6-9650-73a5097225f85797=210=207
20250411-01:34:43.428112000 : 8=FIXT.1.19=28035=X49=Coinbase56=24ab46f784d1b20db435b852086e325034=10450=TEST52=20250411-01:34:43.307157369=2262=7a00f5f8-0c9f-4483-8ca5-754a13a8781d268=1279=2269=1278=f5b5b6b1-7d2e-42b6-9650-73a5097225f883=159755070055=BTC-USD271=0.0000000060=20250411-01:34:43.30571958=FILLED10=105
20250411-01:34:43.570702000 : 8=FIXT.1.19=27835=X49=Coinbase56=24ab46f784d1b20db435b852086e325034=10550=TEST52=20250411-01:34:43.450419369=2262=7a00f5f8-0c9f-4483-8ca5-754a13a8781d268=1279=0269=083=159755070155=BTC-USD29004=2.208895519560=20250411-01:34:43.44883540=137=0a5c0524-945a-45ee-9f3b-7194703148bd10=170
20250411-01:34:43.571489000 : 8=FIXT.1.19=32635=X49=Coinbase56=24ab46f784d1b20db435b852086e325034=10650=TEST52=20250411-01:34:43.450426369=2262=7a00f5f8-0c9f-4483-8ca5-754a13a8781d268=1279=0269=2278=c5b88ea9-605d-4595-ac52-f7c3f08523ba83=159755070255=BTC-USD270=3.55271=0.6222240960=20250411-01:34:43.44883537=0a5c0524-945a-45ee-9f3b-7194703148bd5797=110=059
20250411-01:34:43.571761000 : 8=FIXT.1.19=26535=X49=Coinbase56=24ab46f784d1b20db435b852086e325034=10750=TEST52=20250411-01:34:43.450431369=2262=7a00f5f8-0c9f-4483-8ca5-754a13a8781d268=1279=2269=0278=0a5c0524-945a-45ee-9f3b-7194703148bd83=159755070355=BTC-USD60=20250411-01:34:43.44883558=FILLED10=180
20250411-01:34:43.600965000 : 8=FIXT.1.19=27435=X49=Coinbase56=24ab46f784d1b20db435b852086e325034=10850=TEST52=20250411-01:34:43.479940369=2262=7a00f5f8-0c9f-4483-8ca5-754a13a8781d268=1279=0269=183=159755070455=BTC-USD271=0.6232294660=20250411-01:34:43.47795940=137=b2f8a840-2a97-4894-9a81-cab98888245e10=004
20250411-01:34:43.601754000 : 8=FIXT.1.19=32635=X49=Coinbase56=24ab46f784d1b20db435b852086e325034=10950=TEST52=20250411-01:34:43.479948369=2262=7a00f5f8-0c9f-4483-8ca5-754a13a8781d268=1279=0269=2278=4d60a78e-b39b-420e-b830-bc0f3f4fdde283=159755070555=BTC-USD270=3.53271=0.6232294660=20250411-01:34:43.47795937=b2f8a840-2a97-4894-9a81-cab98888245e5797=210=001
20250411-01:34:43.602394000 : 8=FIXT.1.19=28035=X49=Coinbase56=24ab46f784d1b20db435b852086e325034=11050=TEST52=20250411-01:34:43.479952369=2262=7a00f5f8-0c9f-4483-8ca5-754a13a8781d268=1279=2269=1278=b2f8a840-2a97-4894-9a81-cab98888245e83=159755070655=BTC-USD271=0.0000000060=20250411-01:34:43.47795958=FILLED10=158
20250411-01:34:43.971363000 : 8=FIXT.1.19=27835=X49=Coinbase56=24ab46f784d1b20db435b852086e325034=11150=TEST52=20250411-01:34:43.850957369=2262=7a00f5f8-0c9f-4483-8ca5-754a13a8781d268=1279=0269=083=159755070755=BTC-USD29004=2.208895519560=20250411-01:34:43.84925040=137=44e51475-f3ea-47ca-8a0e-cc4829d8ddcc10=218
20250411-01:34:43.973700000 : 8=FIXT.1.19=32635=X49=Coinbase56=24ab46f784d1b20db435b852086e325034=11250=TEST52=20250411-01:34:43.851038369=2262=7a00f5f8-0c9f-4483-8ca5-754a13a8781d268=1279=0269=2278=c5b88ea9-605d-4595-ac52-f7c3f08523ba83=159755070855=BTC-USD270=3.55271=0.6222240960=20250411-01:34:43.84925037=44e51475-f3ea-47ca-8a0e-cc4829d8ddcc5797=110=100
20250411-01:34:43.974458000 : 8=FIXT.1.19=26535=X49=Coinbase56=24ab46f784d1b20db435b852086e325034=11350=TEST52=20250411-01:34:43.851087369=2262=7a00f5f8-0c9f-4483-8ca5-754a13a8781d268=1279=2269=0278=44e51475-f3ea-47ca-8a0e-cc4829d8ddcc83=159755070955=BTC-USD60=20250411-01:34:43.84925058=FILLED10=229
20250411-01:34:44.000228000 : 8=FIXT.1.19=27435=X49=Coinbase56=24ab46f784d1b20db435b852086e325034=11450=TEST52=20250411-01:34:43.880437369=2262=7a00f5f8-0c9f-4483-8ca5-754a13a8781d268=1279=0269=183=159755071055=BTC-USD271=0.6232294660=20250411-01:34:43.87876040=137=1e891762-269d-403b-9bb4-5692107ad4ee10=224
20250411-01:34:44.000708000 : 8=FIXT.1.19=32635=X49=Coinbase56=24ab46f784d1b20db435b852086e325034=11550=TEST52=20250411-01:34:43.880565369=2262=7a00f5f8-0c9f-4483-8ca5-754a13a8781d268=1279=0269=2278=4d60a78e-b39b-420e-b830-bc0f3f4fdde283=159755071155=BTC-USD270=3.53271=0.6232294660=20250411-01:34:43.87876037=1e891762-269d-403b-9bb4-5692107ad4ee5797=210=215
20250411-01:34:44.001079000 : 8=FIXT.1.19=28035=X49=Coinbase56=24ab46f784d1b20db435b852086e325034=11650=TEST52=20250411-01:34:43.880567369=2262=7a00f5f8-0c9f-4483-8ca5-754a13a8781d268=1279=2269=1278=1e891762-269d-403b-9bb4-5692107ad4ee83=159755071255=BTC-USD271=0.0000000060=20250411-01:34:43.87876058=FILLED10=132
20250411-01:34:44.132780000 : 8=FIXT.1.19=28335=X49=Coinbase56=24ab46f784d1b20db435b852086e325034=11750=TEST52=20250411-01:34:44.011431369=2262=7a00f5f8-0c9f-4483-8ca5-754a13a8781d268=1279=0269=183=159755071355=BTC-USD270=3.35271=0.6232294660=20250411-01:34:44.00977140=237=2c19972a-eba3-462f-8f66-439e6fd72b1510=209
20250411-01:34:44.133404000 : 8=FIXT.1.19=32635=X49=Coinbase56=24ab46f784d1b20db435b852086e325034=11850=TEST52=20250411-01:34:44.011439369=2262=7a00f5f8-0c9f-4483-8ca5-754a13a8781d268=1279=0269=2278=4d60a78e-b39b-420e-b830-bc0f3f4fdde283=159755071455=BTC-USD270=3.53271=0.6232294660=20250411-01:34:44.00977137=2c19972a-eba3-462f-8f66-439e6fd72b155797=210=045
20250411-01:34:44.138926000 : 8=FIXT.1.19=28935=X49=Coinbase56=24ab46f784d1b20db435b852086e325034=11950=TEST52=20250411-01:34:44.011442369=2262=7a00f5f8-0c9f-4483-8ca5-754a13a8781d268=1279=2269=1278=2c19972a-eba3-462f-8f66-439e6fd72b1583=159755071555=BTC-USD270=3.35271=0.0000000060=20250411-01:34:44.00977158=FILLED10=123
20250411-01:34:44.186357000 : 8=FIXT.1.19=28335=X49=Coinbase56=24ab46f784d1b20db435b852086e325034=12050=TEST52=20250411-01:34:44.066502369=2262=7a00f5f8-0c9f-4483-8ca5-754a13a8781d268=1279=0269=083=159755071655=BTC-USD270=3.82271=0.6232294660=20250411-01:34:44.06468740=237=aa5e45d7-32cd-404e-a037-92069fef2bf910=050
20250411-01:34:44.186881000 : 8=FIXT.1.19=32635=X49=Coinbase56=24ab46f784d1b20db435b852086e325034=12150=TEST52=20250411-01:34:44.066600369=2262=7a00f5f8-0c9f-4483-8ca5-754a13a8781d268=1279=0269=2278=c5b88ea9-605d-4595-ac52-f7c3f08523ba83=159755071755=BTC-USD270=3.55271=0.6232294660=20250411-01:34:44.06468737=aa5e45d7-32cd-404e-a037-92069fef2bf95797=110=005
20250411-01:34:44.187366000 : 8=FIXT.1.19=28935=X49=Coinbase56=24ab46f784d1b20db435b852086e325034=12250=TEST52=20250411-01:34:44.066678369=2262=7a00f5f8-0c9f-4483-8ca5-754a13a8781d268=1279=2269=0278=aa5e45d7-32cd-404e-a037-92069fef2bf983=159755071855=BTC-USD270=3.82271=0.0000000060=20250411-01:34:44.06468758=FILLED10=232
20250411-01:34:44.373139000 : 8=FIXT.1.19=27835=X49=Coinbase56=24ab46f784d1b20db435b852086e325034=12350=TEST52=20250411-01:34:44.250376369=2262=7a00f5f8-0c9f-4483-8ca5-754a13a8781d268=1279=0269=083=159755071955=BTC-USD29004=2.208895519560=20250411-01:34:44.24911240=137=3c861258-b632-4c6c-bb1a-d3b46ec2bf3810=095
20250411-01:34:44.373917000 : 8=FIXT.1.19=32635=X49=Coinbase56=24ab46f784d1b20db435b852086e325034=12450=TEST52=20250411-01:34:44.250416369=2262=7a00f5f8-0c9f-4483-8ca5-754a13a8781d268=1279=0269=2278=c5b88ea9-605d-4595-ac52-f7c3f08523ba83=159755072055=BTC-USD270=3.55271=0.6222240960=20250411-01:34:44.24911237=3c861258-b632-4c6c-bb1a-d3b46ec2bf385797=110=228
20250411-01:34:44.374916000 : 8=FIXT.1.19=26535=X49=Coinbase56=24ab46f784d1b20db435b852086e325034=12550=TEST52=20250411-01:34:44.250420369=2262=7a00f5f8-0c9f-4483-8ca5-754a13a8781d268=1279=2269=0278=3c861258-b632-4c6c-bb1a-d3b46ec2bf3883=159755072155=BTC-USD60=20250411-01:34:44.24911258=FILLED10=092
20250411-01:34:44.399946000 : 8=FIXT.1.19=27435=X49=Coinbase56=24ab46f784d1b20db435b852086e325034=12650=TEST52=20250411-01:34:44.279945369=2262=7a00f5f8-0c9f-4483-8ca5-754a13a8781d268=1279=0269=183=159755072255=BTC-USD271=0.6197183160=20250411-01:34:44.27876640=137=651866e6-0425-49ca-a98e-e0e3c356289610=206
20250411-01:34:44.400235000 : 8=FIXT.1.19=32635=X49=Coinbase56=24ab46f784d1b20db435b852086e325034=12750=TEST52=20250411-01:34:44.279951369=2262=7a00f5f8-0c9f-4483-8ca5-754a13a8781d268=1279=0269=2278=4d60a78e-b39b-420e-b830-bc0f3f4fdde283=159755072355=BTC-USD270=3.53271=0.6197183160=20250411-01:34:44.27876637=651866e6-0425-49ca-a98e-e0e3c35628965797=210=192
20250411-01:34:44.400923000 : 8=FIXT.1.19=28035=X49=Coinbase56=24ab46f784d1b20db435b852086e325034=12850=TEST52=20250411-01:34:44.279954369=2262=7a00f5f8-0c9f-4483-8ca5-754a13a8781d268=1279=2269=1278=651866e6-0425-49ca-a98e-e0e3c356289683=159755072455=BTC-USD271=0.0000000060=20250411-01:34:44.27876658=FILLED10=108
20250411-01:34:44.488227000 : 8=FIXT.1.19=27835=X49=Coinbase56=24ab46f784d1b20db435b852086e325034=12950=TEST52=20250411-01:34:44.365252369=2262=7a00f5f8-0c9f-4483-8ca5-754a13a8781d268=1279=0269=083=159755072555=BTC-USD29004=2.208895519560=20250411-01:34:44.36387140=137=ee9e15b4-87ba-4a54-aa41-254cbb4d1d7010=149
20250411-01:34:44.488778000 : 8=FIXT.1.19=32635=X49=Coinbase56=24ab46f784d1b20db435b852086e325034=13050=TEST52=20250411-01:34:44.365310369=2262=7a00f5f8-0c9f-4483-8ca5-754a13a8781d268=1279=0269=2278=c5b88ea9-605d-4595-ac52-f7c3f08523ba83=159755072655=BTC-USD270=3.55271=0.6222240960=20250411-01:34:44.36387137=ee9e15b4-87ba-4a54-aa41-254cbb4d1d705797=110=026
20250411-01:34:44.489101000 : 8=FIXT.1.19=26535=X49=Coinbase56=24ab46f784d1b20db435b852086e325034=13150=TEST52=20250411-01:34:44.365324369=2262=7a00f5f8-0c9f-4483-8ca5-754a13a8781d268=1279=2269=0278=ee9e15b4-87ba-4a54-aa41-254cbb4d1d7083=159755072755=BTC-USD60=20250411-01:34:44.36387158=FILLED10=156
20250411-01:34:44.507209000 : 8=FIXT.1.19=91835=W49=Coinbase56=24ab46f784d1b20db435b852086e325034=13250=TEST52=20250411-01:34:44.387254369=2262=7a00f5f8-0c9f-4483-8ca5-754a13a8781d83=1597550721893=N55=BTC-USD1682=full_trading268=10269=0278=4d60a78e-b39b-420e-b830-bc0f3f4fdde2270=3.53271=258654.05920977269=0278=9d9353ab-229f-423a-89a3-c52a46543bc9270=3.53271=18127.30103418269=0278=f5fc5e68-a52c-44d3-87ef-3785312f4782270=3.48271=0.29310888269=0278=cc53f0bf-e87d-4774-9ece-cc731b02b1c5270=3.48271=0.62322946269=0278=7c61ac46-d01c-425d-89f8-fa885c73362b270=3.48271=0.62322946269=0278=dcccb470-c535-433a-9198-4e2b4c26d99d270=3.47271=0.29311495269=0278=f05d9766-970d-44ca-aa4d-e8b2720bbda8270=3.46271=0.29026870269=0278=911afd4c-2c13-4fb7-a980-efb8f5115621270=3.46271=0.62322946269=0278=2c4d7d5a-33aa-4058-b546-480b6a2168a4270=3.44271=0.29828577269=0278=37dbcf16-0b3d-4f67-bc90-e36268b99e0e270=3.42271=0.3027094710=121
20250411-01:34:44.511070000 : 8=FIXT.1.19=14135=334=349=24ab46f784d1b20db435b852086e325052=20250411-01:34:44.51056=Coinbase45=13258=Tag appears more than once371=269372=W373=1310=240
20250411-01:34:44.511240000 : 8=FIXT.1.19=90935=W49=Coinbase56=24ab46f784d1b20db435b852086e325034=13350=TEST52=20250411-01:34:44.387495369=2262=7a00f5f8-0c9f-4483-8ca5-754a13a8781d83=1597550721893=N55=BTC-USD1682=full_trading268=10269=0278=4c63c0b7-30e0-4ef1-931f-0090359f978e270=3.41271=0.32158962269=0278=d6b4aa4e-d588-4c96-83aa-8e8d8accb1a4270=3.41271=0.30121104269=0278=e8b3d8da-1663-413c-b7fb-6aba23b01440270=3.39271=0.31006477269=0278=bcbe17c3-9059-4c38-8ab8-8e78f1ef9062270=3.38271=0.32617981269=0278=57bb77fd-337f-49bc-a56f-a4e2dff851ee270=3.37271=0.31071676269=0278=ded4b51d-349f-4726-8379-6761a3576bb6270=3.33271=0.31560513269=0278=ff7aff09-38de-47ac-a3cb-9beacb0b9ad8270=3.33271=0.30682342269=0278=d1da558a-e9d2-4e11-b26e-1eb80a1a34c5270=3.32271=0.31700685269=0278=9ee34527-d4d8-4659-b2ea-cdff3dc4a8fa270=3.32271=0.32181951269=0278=7abf2220-0421-460f-9dbb-14c41564e41a270=3.32271=0.3130843610=172
20250411-01:34:44.512056000 : 8=FIXT.1.19=14135=334=449=24ab46f784d1b20db435b852086e325052=20250411-01:34:44.51156=Coinbase45=13358=Tag appears more than once371=269372=W373=1310=243
20250411-01:34:44.512179000 : 8=FIXT.1.19=90935=W49=Coinbase56=24ab46f784d1b20db435b852086e325034=13450=TEST52=20250411-01:34:44.387745369=2262=7a00f5f8-0c9f-4483-8ca5-754a13a8781d83=1597550721893=N55=BTC-USD1682=full_trading268=10269=0278=69634ec5-f71a-4990-b56d-13c3069a455a270=3.31271=0.32329458269=0278=2f333c17-a386-4d52-8ff1-eadcb99bc22f270=3.31271=0.31999220269=0278=f02efc37-0b1e-470b-99ef-e31012887d73270=3.30271=0.32771570269=0278=6d430950-8078-4987-8995-e581564e368d270=3.29271=0.30702763269=0278=841f895a-cd2d-4082-9a37-b50fc19e35bf270=3.28271=0.32610801269=0278=3cf93093-e42b-4c24-95ea-c367d96427fe270=3.27271=0.33588654269=0278=f29c94bc-d1c2-4145-97b0-ecb77d81a8bf270=3.27271=0.31661408269=0278=d208c4fb-56c6-4911-85c9-77b68a5ba6ab270=3.25271=0.30961623269=0278=e88796ff-68c8-4463-914b-46e09fbaf639270=3.25271=0.33589845269=0278=06f345fb-0292-45fc-8237-9ad1a84b541c270=3.24271=0.3152850710=012
20250411-01:34:44.512955000 : 8=FIXT.1.19=14135=334=549=24ab46f784d1b20db435b852086e325052=20250411-01:34:44.51256=Coinbase45=13458=Tag appears more than once371=269372=W373=1310=246
20250411-01:34:44.513118000 : 8=FIXT.1.19=90935=W49=Coinbase56=24ab46f784d1b20db435b852086e325034=13550=TEST52=20250411-01:34:44.387995369=2262=7a00f5f8-0c9f-4483-8ca5-754a13a8781d83=1597550721893=N55=BTC-USD1682=full_trading268=10269=0278=fa20c2c7-df80-4941-9a9c-a6ef2e579480270=3.23271=0.33432448269=0278=a833d230-a749-4bf4-823e-93adc40b773d270=3.23271=0.31165878269=0278=2abb6e15-b9cd-415b-8c9b-99a61c750310270=3.22271=0.32048714269=0278=ec44a6d8-ae5f-4809-89d7-0f7a3adac547270=3.21271=0.33230954269=0278=9cf61c67-c4fc-4bac-92fd-d4e2b56248aa270=3.21271=0.33583951269=0278=210b2518-bb42-461a-9c7e-b4e04c5ffcc6270=3.21271=0.32669007269=0278=2e3fa1b2-20f1-4694-9be4-322040b75152270=3.21271=0.32907979269=0278=05dd5607-92c9-4296-8cdc-27cdff004dea270=3.21271=0.32776075269=0278=87944de7-a5f1-4033-a3d8-cbc10f3a5232270=3.20271=0.32225170269=0278=30f6bb59-2469-4e6d-8fa5-13666373901f270=3.19271=0.3138649610=140
20250411-01:34:44.514085000 : 8=FIXT.1.19=14135=334=649=24ab46f784d1b20db435b852086e325052=20250411-01:34:44.51356=Coinbase45=13558=Tag appears more than once371=269372=W373=1310=249
20250411-01:34:44.514175000 : 8=FIXT.1.19=91035=W49=Coinbase56=24ab46f784d1b20db435b852086e325034=13650=TEST52=20250411-01:34:44.388245369=2262=7a00f5f8-0c9f-4483-8ca5-754a13a8781d83=1597550721893=N55=BTC-USD1682=full_trading268=10269=0278=6a5d2852-7ddc-456e-acb5-bfadcc0c1360270=3.19271=0.32157390269=0278=5d00d8a2-5aea-4836-ba19-74fe67116df8270=3.18271=0.32651049269=0278=acc71746-3591-4dde-a7e2-c2795d0ad125270=3.17271=0.31577131269=0278=13982796-c2a8-4740-95e2-5aca0fdfd8bb270=3.16271=0.33021170269=0278=9f2f0737-661e-43d7-89f9-959ed5e08306270=3.16271=0.33082075269=0278=7e0e2d14-fa77-4978-8cae-d9660fd13e6d270=3.16271=0.32014975269=0278=82826a7d-848c-4516-a7b6-5ec6881609a8270=2.00271=10.00000000269=0278=590048d5-ee44-49dc-b66d-1a692e055133270=1.94271=0.51546392269=0278=22bdda11-16cd-488b-9fa9-da098dad543e270=1.94271=0.51546392269=0278=d356ef8b-596e-47e7-bf90-cc015b85fc57270=1.93271=0.5233160610=231
20250411-01:34:44.514920000 : 8=FIXT.1.19=14135=334=749=24ab46f784d1b20db435b852086e325052=20250411-01:34:44.51456=Coinbase45=13658=Tag appears more than once371=269372=W373=1310=252
20250411-01:34:44.515067000 : 8=FIXT.1.19=90935=W49=Coinbase56=24ab46f784d1b20db435b852086e325034=13750=TEST52=20250411-01:34:44.388495369=2262=7a00f5f8-0c9f-4483-8ca5-754a13a8781d83=1597550721893=N55=BTC-USD1682=full_trading268=10269=0278=aa8d48bc-97fb-4d00-b923-66d37cc8c66a270=1.93271=0.52331606269=0278=7d51dcb4-a7f8-4cca-b2d0-e902403d1b9f270=1.93271=0.52331606269=0278=f7680950-3af2-4723-a6e4-5cbd528ca900270=1.93271=0.52331606269=0278=fdeff994-4866-47af-9dde-a25947a26606270=1.93271=0.52331606269=0278=65e7e2bb-023d-4936-bb4e-ff7625ba7264270=1.93271=0.52331606269=0278=53732639-572c-4cd5-b61e-e4f534d1d540270=1.93271=0.52331606269=0278=24da8927-1dd1-468b-9437-ff366f5bfa11270=1.93271=0.52331606269=0278=baa5862c-41e8-458c-83d3-c095bb68ed17270=1.93271=0.52331606269=0278=92a3c3e3-7afe-4d02-a0d8-96f512b63bb7270=1.93271=0.52331606269=0278=9d2a564e-f178-4966-9baf-5814a1c1686b270=1.93271=0.5233160610=180
20250411-01:34:44.515657000 : 8=FIXT.1.19=14135=334=849=24ab46f784d1b20db435b852086e325052=20250411-01:34:44.51556=Coinbase45=13758=Tag appears more than once371=269372=W373=1310=255
20250411-01:34:44.515741000 : 8=FIXT.1.19=90935=W49=Coinbase56=24ab46f784d1b20db435b852086e325034=13850=TEST52=20250411-01:34:44.388745369=2262=7a00f5f8-0c9f-4483-8ca5-754a13a8781d83=1597550721893=N55=BTC-USD1682=full_trading268=10269=0278=f9e6b978-87f6-4397-8d82-07cf698c123f270=1.93271=0.52331606269=0278=3e64b388-13d3-441d-b241-aa8dd6fe55e6270=1.93271=0.52331606269=0278=60300433-87b0-4031-bb1e-12cf9d773d3f270=1.93271=0.52331606269=0278=1bdd5f5a-1d99-4eed-af09-c187bcbbd2d8270=1.93271=0.52331606269=0278=4ed6f6b9-77fb-4255-a188-f243dd0cdb3c270=1.93271=0.52331606269=0278=9ad1fc18-5a38-4edb-ac5c-6ac826a8a846270=1.93271=0.52331606269=0278=1c218c8c-baea-4a1f-838e-4a3a94b468e1270=1.93271=0.52331606269=0278=fd70f5e2-d2c9-472a-ab40-a775afafd73d270=1.93271=0.52331606269=0278=96f5e3a5-1c2a-4db6-a3fb-fd1f13d5d559270=1.93271=0.52331606269=0278=4a015a4c-490a-4c40-974f-9dfb7feb335d270=1.93271=0.5233160610=196
20250411-01:34:44.516681000 : 8=FIXT.1.19=14135=334=949=24ab46f784d1b20db435b852086e325052=20250411-01:34:44.51656=Coinbase45=13858=Tag appears more than once371=269372=W373=1310=002
20250411-01:34:44.516772000 : 8=FIXT.1.19=90935=W49=Coinbase56=24ab46f784d1b20db435b852086e325034=13950=TEST52=20250411-01:34:44.388995369=2262=7a00f5f8-0c9f-4483-8ca5-754a13a8781d83=1597550721893=N55=BTC-USD1682=full_trading268=10269=0278=d919363e-2c54-404f-bc0b-063e2f12bec4270=1.93271=0.52331606269=0278=d4636d6c-85c6-4ac9-9afb-70ca636f4ad4270=1.93271=0.52331606269=0278=bda09690-f345-4c33-ae8b-e8c78da11b5a270=1.93271=0.52331606269=0278=1a81ae10-b700-42a0-89a3-7d7a3eea0ebb270=1.93271=0.52331606269=0278=1ace5afa-e550-4abf-a458-52e46e1b54f0270=1.93271=0.52331606269=0278=2332d1c9-67e7-457a-abfe-f5e9a8c2ea05270=1.93271=0.52331606269=0278=6afa1f19-0ec5-49fd-8b74-06a12a6c5ca9270=1.93271=0.52331606269=0278=3fa3413d-c26c-472f-9cc5-da1c48935c63270=1.93271=0.52331606269=0278=3f9e43c4-2e62-4d51-b4cb-ad207c693331270=1.93271=0.52331606269=0278=29e8bfcf-c764-4f7e-997d-09abf72bbc00270=1.93271=0.5233160610=128
20250411-01:34:44.517498000 : 8=FIXT.1.19=14235=334=1049=24ab46f784d1b20db435b852086e325052=20250411-01:34:44.51756=Coinbase45=13958=Tag appears more than once371=269372=W373=1310=045
20250411-01:34:44.517582000 : 8=FIXT.1.19=90935=W49=Coinbase56=24ab46f784d1b20db435b852086e325034=14050=TEST52=20250411-01:34:44.389245369=2262=7a00f5f8-0c9f-4483-8ca5-754a13a8781d83=1597550721893=N55=BTC-USD1682=full_trading268=10269=0278=cf3e8b26-09ae-4dfb-9b84-b12a7e199a5a270=1.93271=0.52331606269=0278=08db3e51-e927-47d3-a9dd-2f887c58dc85270=1.93271=0.52331606269=0278=353ae741-9473-4cc5-9ab7-7e5de8ae55d0270=1.93271=0.52331606269=0278=4d037208-2072-480f-98ac-7be9c24f18f4270=1.93271=0.52331606269=0278=b598f678-da6e-4c01-90ed-d702c42f8a65270=1.93271=0.52331606269=0278=5f69b1a0-b5d1-4715-9be1-9bdf008d97d7270=1.93271=0.52331606269=0278=ef063d15-248a-4eae-97f4-278be5106d80270=1.93271=0.52331606269=0278=f8b20207-84bc-44e9-a2fe-9ad775e2ecb1270=1.93271=0.52331606269=0278=75bce2b7-bc58-4479-8bfb-144f88f2262b270=1.93271=0.52331606269=0278=1f6e2a79-8b10-4a7f-89de-0f1fa03692c7270=1.93271=0.5233160610=094
20250411-01:34:44.518214000 : 8=FIXT.1.19=14235=334=1149=24ab46f784d1b20db435b852086e325052=20250411-01:34:44.51756=Coinbase45=14058=Tag appears more than once371=269372=W373=1310=038
20250411-01:34:44.518303000 : 8=FIXT.1.19=90935=W49=Coinbase56=24ab46f784d1b20db435b852086e325034=14150=TEST52=20250411-01:34:44.389495369=2262=7a00f5f8-0c9f-4483-8ca5-754a13a8781d83=1597550721893=N55=BTC-USD1682=full_trading268=10269=0278=d1b80bf5-9b17-44b4-9577-6fe71170b578270=1.93271=0.52331606269=0278=b891e26a-c20c-4fce-ba1c-487fe139a4cc270=1.93271=0.52331606269=0278=5d06d3f6-3189-4394-b3c5-6a2bda14b6d1270=1.93271=0.52331606269=0278=e5791c0f-3937-4a66-9b98-26f79a3891be270=1.93271=0.52331606269=0278=c62591c6-7dfa-46a7-8f20-6a5f22804999270=1.93271=0.52331606269=0278=7c503558-c0b8-457b-8c46-71ece3f7fc8a270=1.93271=0.52331606269=0278=f763bb56-2f21-4a9b-bd48-f84dc1bd5ee5270=1.93271=0.52331606269=0278=42214b03-1fc2-46b3-9e83-91b23a510e5a270=1.93271=0.52331606269=0278=1c7c52ed-7d39-4326-b3b8-98f05a9b3ef0270=1.93271=0.52331606269=0278=3313309e-45e7-4e7b-8c55-4f9a8ec1b351270=1.93271=0.5233160610=149
20250411-01:34:44.518954000 : 8=FIXT.1.19=14235=334=1249=24ab46f784d1b20db435b852086e325052=20250411-01:34:44.51856=Coinbase45=14158=Tag appears more than once371=269372=W373=1310=041
20250411-01:34:44.519068000 : 8=FIXT.1.19=90935=W49=Coinbase56=24ab46f784d1b20db435b852086e325034=14250=TEST52=20250411-01:34:44.389745369=2262=7a00f5f8-0c9f-4483-8ca5-754a13a8781d83=1597550721893=N55=BTC-USD1682=full_trading268=10269=0278=78801ffb-ec5a-4c74-9d08-3e86fd9db4dd270=1.93271=0.52331606269=0278=abe6eea4-1d9c-47d7-847f-2f44aa561b3f270=1.93271=0.52331606269=0278=6a6eb56d-2010-43e2-b78e-5f098081bb64270=1.93271=0.52331606269=0278=b53c01ff-f450-4b05-8ad1-e7894b45e0e0270=1.93271=0.52331606269=0278=4747863e-c0a6-4ef5-8faf-e8934bca4f8b270=1.93271=0.52331606269=0278=81a8a629-57f4-4e3a-ac25-2e9ee1f357c2270=1.93271=0.52331606269=0278=1e239259-7be4-476a-845d-1b92fd951d8b270=1.93271=0.52331606269=0278=189eb272-48f9-4915-b7e1-a86dcc505c4a270=1.93271=0.52331606269=0278=0562b9f7-aae3-4961-bd97-f5b8cde0ec34270=1.93271=0.52331606269=0278=5103331b-7300-487b-bc2c-a6032bf4be7e270=1.93271=0.5233160610=200
20250411-01:34:44.519818000 : 8=FIXT.1.19=14235=334=1349=24ab46f784d1b20db435b852086e325052=20250411-01:34:44.51956=Coinbase45=14258=Tag appears more than once371=269372=W373=1310=044
20250411-01:34:44.520081000 : 8=FIXT.1.19=91235=W49=Coinbase56=24ab46f784d1b20db435b852086e325034=14350=TEST52=20250411-01:34:44.389995369=2262=7a00f5f8-0c9f-4483-8ca5-754a13a8781d83=1597550721893=N55=BTC-USD1682=full_trading268=10269=0278=78ac85ac-2478-4991-a084-7286982b77cc270=1.93271=0.52331606269=0278=6993b26d-d6dc-4f99-8a53-9500ae5b4ff1270=1.93271=0.52331606269=0278=1c96ab9d-04a6-465a-87e5-3ed33970178f270=1.93271=0.52331606269=0278=6fc0282b-d538-4aa3-8982-bda02bb1b054270=1.93271=0.52331606269=0278=80870aa3-04a2-4d2a-8669-93215130ffee270=1.93271=0.52331606269=0278=b274e872-6923-45fd-b48a-68e685e769cb270=1.93271=0.52331606269=0278=2d4364c0-239c-4f4b-8ce4-2acfe0bb343d270=1.12271=1.00000000269=0278=8fa16a4f-377f-4deb-9a8e-1020aed9edf4270=1.00271=1.00000000269=1278=c5b88ea9-605d-4595-ac52-f7c3f08523ba270=3.55271=8640.34656672269=1278=81523bd3-8912-4789-8761-89a9ee42794b270=3.55271=0.3051896610=160
20250411-01:34:44.520711000 : 8=FIXT.1.19=14235=334=1449=24ab46f784d1b20db435b852086e325052=20250411-01:34:44.52056=Coinbase45=14358=Tag appears more than once371=269372=W373=1310=038
20250411-01:34:44.597368000 : 8=FIXT.1.19=92935=W49=Coinbase56=24ab46f784d1b20db435b852086e325034=14450=TEST52=20250411-01:34:44.390246369=2262=7a00f5f8-0c9f-4483-8ca5-754a13a8781d83=1597550721893=N55=BTC-USD1682=full_trading268=10269=1278=60fc75ca-0052-40b7-9f18-a6aad9d31b84270=3.56271=18037.00000000269=1278=ad00e2cd-d925-46a4-9e7e-941c6faed2c7270=3.57271=18027.00000000269=1278=fec191b5-64da-4a15-ab4b-36a0d3d10750270=3.57271=0.29025301269=1278=71ec06da-63f1-4c6e-b8d4-d4fa56c3ce8c270=3.57271=0.62322946269=1278=02a780aa-8154-4638-a5ca-53b8198cc724270=3.58271=16937.00000000269=1278=911349fb-1960-4904-9a38-0e2497fb7ccb270=3.58271=0.29896312269=1278=67e651a5-16f0-453a-b356-5935f8f7174e270=3.58271=0.62322946269=1278=d91e89d4-ac5c-4853-9879-ec8ff5e00a71270=3.59271=17163.00000000269=1278=341d0ad8-6c15-4b5e-aebb-e3caa5af575c270=3.60271=17926.00000000269=1278=f3f78323-40ff-440d-83ce-0f351ab9cd29270=3.60271=0.6232294610=058
20250411-01:34:44.598337000 : 8=FIXT.1.19=14235=334=1549=24ab46f784d1b20db435b852086e325052=20250411-01:34:44.59756=Coinbase45=14458=Tag appears more than once371=269372=W373=1310=054
20250411-01:34:44.598458000 : 8=FIXT.1.19=92535=W49=Coinbase56=24ab46f784d1b20db435b852086e325034=14550=TEST52=20250411-01:34:44.390496369=2262=7a00f5f8-0c9f-4483-8ca5-754a13a8781d83=1597550721893=N55=BTC-USD1682=full_trading268=10269=1278=9d239e03-1215-4cc7-ad44-3f4097ee70ea270=3.61271=18058.08928020269=1278=dbb0f332-4189-4df5-879b-e55860b13def270=3.62271=0.28062774269=1278=f7639c39-7e8b-44d1-a2f2-9807e2a3228c270=3.62271=0.27709851269=1278=83be9389-2099-4173-a322-b0933bc99358270=3.62271=19973.00000000269=1278=b89abc22-6b6c-4474-b3fc-ffe21f05cd4e270=3.63271=20016.00000000269=1278=ce0af8a3-149c-4603-905a-be65625fe014270=3.64271=0.27806002269=1278=94b8615f-6fa7-4dc9-bbfa-435fe535bebc270=3.64271=22352.63489459269=1278=f0d87c91-a224-40b3-a344-b13d87abda17270=3.66271=0.62322946269=1278=cae3885d-f5b2-4de1-830c-0085e27bbb69270=3.69271=0.27722678269=1278=207d5707-e412-4dc9-bca8-9b1bd7853e92270=3.69271=0.6232294610=247
20250411-01:34:44.599077000 : 8=FIXT.1.19=14235=334=1649=24ab46f784d1b20db435b852086e325052=20250411-01:34:44.59856=Coinbase45=14558=Tag appears more than once371=269372=W373=1310=057
20250411-01:34:44.599277000 : 8=FIXT.1.19=90935=W49=Coinbase56=24ab46f784d1b20db435b852086e325034=14650=TEST52=20250411-01:34:44.390746369=2262=7a00f5f8-0c9f-4483-8ca5-754a13a8781d83=1597550721893=N55=BTC-USD1682=full_trading268=10269=1278=b9732128-11b1-44fd-bea3-94da9fc853fb270=3.71271=0.28488329269=1278=818b83a4-e14e-4ad5-b094-6733f0504003270=3.75271=0.27930225269=1278=3e6990a0-8ef4-4968-8ee8-89b7346c197d270=3.76271=0.28131365269=1278=342794c8-a9d2-4aa5-9886-a819398d69c6270=3.88271=0.27719712269=1278=2839680b-48b3-4f53-86b1-9269987275e7270=3.91271=0.26621275269=1278=fd7b5361-29f8-4b35-bae5-232a64f657b4270=3.95271=0.26131406269=1278=5edaeed0-fae9-4f36-8c77-6fbedf61eefc270=4.02271=0.25091227269=1278=fdbbfd04-ba67-4b23-bbc1-f87f929e7e81270=4.07271=0.24812642269=1278=534b2a85-0852-420d-928b-70cdb6ba2457270=4.10271=0.26961968269=1278=b009f8a1-4a39-493b-b96e-d783e981c915270=4.26271=0.2501957410=157
20250411-01:34:44.600063000 : 8=FIXT.1.19=14235=334=1749=24ab46f784d1b20db435b852086e325052=20250411-01:34:44.59956=Coinbase45=14658=Tag appears more than once371=269372=W373=1310=060
20250411-01:34:44.600135000 : 8=FIXT.1.19=92935=W49=Coinbase56=24ab46f784d1b20db435b852086e325034=14750=TEST52=20250411-01:34:44.390996369=2262=7a00f5f8-0c9f-4483-8ca5-754a13a8781d83=1597550721893=N55=BTC-USD1682=full_trading268=10269=1278=729a899c-ac2d-4541-b0a2-cbdd5df9bf98270=10.00271=10.00000000269=1278=eb1e5d45-d081-4ef8-a83e-1f5348fbda96270=10.00271=10.00000000269=1278=0cd67977-85eb-45fa-ae72-d45b92ca24f4270=10.00271=10.00000000269=1278=5d931559-6758-4b75-9d6d-6438d25b497f270=10.00271=10.00000000269=1278=57e43d1d-644a-493e-acd3-69dc5e64dcde270=10.00271=10.00000000269=1278=c1566121-2b63-494d-ac2d-973e9f0115c0270=10.00271=10.00000000269=1278=d0c4a771-9035-4db9-ae7b-ad2d1db5646d270=10.00271=10.00000000269=1278=52c644ea-628a-4576-8e7e-27ec4c90398b270=10.00271=10.00000000269=1278=c3483f66-d8ce-489a-90b9-2bce69e054ee270=10.00271=10.00000000269=1278=55992a5c-cbcd-464a-8f8d-8b58e81e5c0b270=10.00271=10.0000000010=108
20250411-01:34:44.600699000 : 8=FIXT.1.19=14235=334=1849=24ab46f784d1b20db435b852086e325052=20250411-01:34:44.60056=Coinbase45=14758=Tag appears more than once371=269372=W373=1310=045
20250411-01:34:44.625328000 : 8=FIXT.1.19=93435=W49=Coinbase56=24ab46f784d1b20db435b852086e325034=14850=TEST52=20250411-01:34:44.391246369=2262=7a00f5f8-0c9f-4483-8ca5-754a13a8781d83=1597550721893=N55=BTC-USD1682=full_trading268=10269=1278=19077009-6f26-4e2d-9dab-04a28231b752270=10.00271=10.00000000269=1278=692097d1-c978-4024-95e9-2bf348b64bbd270=10.00271=10.00000000269=1278=99a92935-11b7-4f21-a64c-c746b53d1777270=10.00271=10.00000000269=1278=dc024b0b-0337-4215-9669-5e5636834397270=10.00271=10.00000000269=1278=c90fcc3a-a36c-4c14-b57f-6db78762e017270=10.00271=10.00000000269=1278=7841891a-bb7c-4034-97c1-41164185edc7270=1000.00271=3.10000000269=1278=381c9fa7-1add-4dd2-9233-f41e2c8821fe270=1000.00271=3.10000000269=1278=928e65c2-7e2d-478b-9310-414fb77f5aae270=1000.00271=3.10000000269=1278=ad4bd3ac-9276-40d5-90f9-e47b1d8ee953270=1000.00271=3.10000000269=1278=79e799dc-4a3d-4922-ad1a-f74eb7eff789270=1000.00271=3.1000000010=033
20250411-01:34:44.626558000 : 8=FIXT.1.19=14235=334=1949=24ab46f784d1b20db435b852086e325052=20250411-01:34:44.62556=Coinbase45=14858=Tag appears more than once371=269372=W373=1310=054
20250411-01:34:44.626711000 : 8=FIXT.1.19=93935=W49=Coinbase56=24ab46f784d1b20db435b852086e325034=14950=TEST52=20250411-01:34:44.391496369=2262=7a00f5f8-0c9f-4483-8ca5-754a13a8781d83=1597550721893=N55=BTC-USD1682=full_trading268=10269=1278=04f642b7-750f-4967-b786-0d48eea0f158270=1000.00271=3.10000000269=1278=d0ad653d-3272-4a3b-ba7a-a52029a67a92270=1000.00271=3.10000000269=1278=cad40464-4c62-4bf3-8444-c487fcc8dd01270=1000.00271=3.10000000269=1278=426c6428-d481-4ff7-9de3-f00ff219d654270=1000.00271=3.10000000269=1278=1ed1152d-8c1a-4b29-acdd-bbd1a5c5f35f270=1000.00271=3.10000000269=1278=66526051-b5cb-442f-af90-c609be0a9796270=1000.00271=3.10000000269=1278=f68e4659-5785-4ee9-ac24-3186640a2752270=1000.00271=3.10000000269=1278=38070d38-80a9-4898-8ef7-a0a9da5a4123270=1000.00271=3.10000000269=1278=e4d2d308-ed11-49db-850e-3cbd8258395d270=1000.00271=3.10000000269=1278=d6cfaadc-97ea-43c1-898d-40faea9c1477270=1000.00271=3.1000000010=055
20250411-01:34:44.628875000 : 8=FIXT.1.19=14235=334=2049=24ab46f784d1b20db435b852086e325052=20250411-01:34:44.62856=Coinbase45=14958=Tag appears more than once371=269372=W373=1310=050
20250411-01:34:44.629055000 : 8=FIXT.1.19=93935=W49=Coinbase56=24ab46f784d1b20db435b852086e325034=15050=TEST52=20250411-01:34:44.391746369=2262=7a00f5f8-0c9f-4483-8ca5-754a13a8781d83=1597550721893=N55=BTC-USD1682=full_trading268=10269=1278=36876bea-9e3a-4018-b0ac-b75cb8c16953270=1000.00271=3.10000000269=1278=eb244bc5-49e8-4aa3-af8b-3d1a67c90a08270=1000.00271=3.10000000269=1278=3efba776-29ad-4aeb-82d8-0824f161471e270=1000.00271=3.10000000269=1278=de0ddebd-0ca8-4eca-9985-77c10c8629a9270=1000.00271=3.10000000269=1278=dde4408a-fb6b-441c-a7f3-7b8b23ffdb1f270=1000.00271=3.10000000269=1278=3ebd6434-070f-4b4d-8cf3-00368112466d270=1000.00271=3.10000000269=1278=7aa98e13-65f3-4058-9f91-c1f452d02710270=1000.00271=3.10000000269=1278=e86a1fec-3610-460d-8d85-4e1e222ee159270=1000.00271=3.10000000269=1278=6dfac057-72b1-4f2c-b110-03766dea0d31270=1000.00271=3.10000000269=1278=bbb7d0ea-d251-4612-b53e-e528cc0a24ab270=1000.00271=3.1000000010=221
20250411-01:34:44.629771000 : 8=FIXT.1.19=14235=334=2149=24ab46f784d1b20db435b852086e325052=20250411-01:34:44.62956=Coinbase45=15058=Tag appears more than once371=269372=W373=1310=044
20250411-01:34:44.716186000 : 8=FIXT.1.19=93935=W49=Coinbase56=24ab46f784d1b20db435b852086e325034=15150=TEST52=20250411-01:34:44.391996369=2262=7a00f5f8-0c9f-4483-8ca5-754a13a8781d83=1597550721893=N55=BTC-USD1682=full_trading268=10269=1278=0782ca37-48cf-4ff3-a74a-35674661586c270=1000.00271=3.10000000269=1278=aead437d-4b62-457f-ac83-62c7cc329fd1270=1000.00271=3.10000000269=1278=af5d47bc-a008-4567-b24f-b0298f250471270=1000.00271=3.10000000269=1278=4c260f58-c427-4a9a-969a-44024ae0c714270=1000.00271=3.10000000269=1278=8c7672e5-7ee8-4fbd-8fdf-7e74e9a77db7270=1000.00271=3.10000000269=1278=b53ec3cc-9abe-4570-b903-34d52148073e270=1000.00271=3.10000000269=1278=37ce984a-0387-4ac9-9094-b83f722036ba270=1000.00271=3.10000000269=1278=0d383649-dc6c-4df2-b821-aa0018f132c7270=1000.00271=3.10000000269=1278=e39ae0ce-9e7f-4f0d-a765-5308d473bb61270=1000.00271=3.10000000269=1278=4882324e-3b5c-4b7a-b096-e8c6d9888671270=1000.00271=3.1000000010=148
20250411-01:34:44.717153000 : 8=FIXT.1.19=14235=334=2249=24ab46f784d1b20db435b852086e325052=20250411-01:34:44.71656=Coinbase45=15158=Tag appears more than once371=269372=W373=1310=043
20250411-01:34:44.717329000 : 8=FIXT.1.19=93935=W49=Coinbase56=24ab46f784d1b20db435b852086e325034=15250=TEST52=20250411-01:34:44.392246369=2262=7a00f5f8-0c9f-4483-8ca5-754a13a8781d83=1597550721893=N55=BTC-USD1682=full_trading268=10269=1278=6e5c7dbd-a2cc-401f-a5b2-3902088f4ab2270=1000.00271=3.10000000269=1278=10ffac08-946a-4a30-b57a-0d78450345d9270=1000.00271=3.10000000269=1278=67784af5-72bf-4d16-a6b3-25336e2c1843270=1000.00271=3.10000000269=1278=4d8b3bbc-0dc2-4044-875c-c079ec538136270=1000.00271=3.10000000269=1278=dfba5f1e-21f5-48e3-adce-b8b6bfe71467270=1000.00271=3.10000000269=1278=e51b4e33-5eaa-46ef-936b-a74a890397e8270=1000.00271=3.10000000269=1278=8cf5dfa8-858b-48a3-9d94-78522c257473270=1000.00271=3.10000000269=1278=a153b9d2-993d-4f03-a974-b8a081e128e8270=1000.00271=3.10000000269=1278=1eebe866-0f6e-4d4a-a28b-78f4e3368b0a270=1000.00271=3.10000000269=1278=300132d8-113f-4bf7-ba0c-4d93a272f55b270=1000.00271=3.1000000010=164
20250411-01:34:44.718135000 : 8=FIXT.1.19=14235=334=2349=24ab46f784d1b20db435b852086e325052=20250411-01:34:44.71756=Coinbase45=15258=Tag appears more than once371=269372=W373=1310=046
20250411-01:34:44.718322000 : 8=FIXT.1.19=93935=W49=Coinbase56=24ab46f784d1b20db435b852086e325034=15350=TEST52=20250411-01:34:44.392496369=2262=7a00f5f8-0c9f-4483-8ca5-754a13a8781d83=1597550721893=N55=BTC-USD1682=full_trading268=10269=1278=757f3122-27d2-4f32-90b8-ead1eef9b936270=1000.00271=3.10000000269=1278=2b68b5de-4153-4cac-ace3-102e4fa788fd270=1000.00271=3.10000000269=1278=b01f252a-1657-4df0-a122-58a23109a7c2270=1000.00271=3.10000000269=1278=dbc57e4e-6abd-4d66-8d18-bd13caaa77b1270=1000.00271=3.10000000269=1278=948b05dc-a481-409f-b8ad-a502eb595906270=1000.00271=3.10000000269=1278=e00f9703-6e16-4237-a2c6-701829d11bf1270=1000.00271=3.10000000269=1278=fd52f47a-3f11-47bc-9952-9708617d0ecd270=1000.00271=3.10000000269=1278=f7f75b14-27c3-469c-89fb-6a98b43c61bf270=1000.00271=3.10000000269=1278=25dbeb09-7901-4280-b0c3-720d7ed03d7d270=1000.00271=3.10000000269=1278=52164a1f-599f-4c43-a9ed-f93403506e67270=1000.00271=3.1000000010=006
20250411-01:34:44.719230000 : 8=FIXT.1.19=14235=334=2449=24ab46f784d1b20db435b852086e325052=20250411-01:34:44.71856=Coinbase45=15358=Tag appears more than once371=269372=W373=1310=049
20250411-01:34:44.719318000 : 8=FIXT.1.19=93935=W49=Coinbase56=24ab46f784d1b20db435b852086e325034=15450=TEST52=20250411-01:34:44.392746369=2262=7a00f5f8-0c9f-4483-8ca5-754a13a8781d83=1597550721893=N55=BTC-USD1682=full_trading268=10269=1278=c71c35ea-f60f-4a41-b43a-4947bbcbafad270=1000.00271=3.10000000269=1278=2de342bc-a1be-46f3-9fc6-731297726934270=1000.00271=3.10000000269=1278=7ff4c5fc-bc9b-4845-940b-4837a672e13a270=1000.00271=3.10000000269=1278=2d270775-33eb-4328-8dad-7d206612f9f6270=1000.00271=3.10000000269=1278=c4754378-f787-4100-81af-564443a86a91270=1000.00271=3.10000000269=1278=59e16255-05eb-4fdc-8be1-3c4f83fc094e270=1000.00271=3.10000000269=1278=041b2f98-1185-49cb-964a-f0456b71e692270=1000.00271=3.10000000269=1278=9a2f3529-481e-4e50-a123-7a2095fe6b2c270=1000.00271=3.10000000269=1278=9ed552a3-3295-4878-85dd-87b7b5590212270=1000.00271=3.10000000269=1278=54bec5c2-bafd-4d7d-851d-59e3553a053f270=1000.00271=3.1000000010=197
20250411-01:34:44.720138000 : 8=FIXT.1.19=14235=334=2549=24ab46f784d1b20db435b852086e325052=20250411-01:34:44.71956=Coinbase45=15458=Tag appears more than once371=269372=W373=1310=052
20250411-01:34:44.720270000 : 8=FIXT.1.19=93935=W49=Coinbase56=24ab46f784d1b20db435b852086e325034=15550=TEST52=20250411-01:34:44.392996369=2262=7a00f5f8-0c9f-4483-8ca5-754a13a8781d83=1597550721893=N55=BTC-USD1682=full_trading268=10269=1278=543c1acf-52f2-442b-a893-f7aa9a5dfbd1270=1000.00271=3.10000000269=1278=fec999be-cbd0-42ef-b9c3-82ca92ef0b58270=1000.00271=3.10000000269=1278=24528176-3fc6-45b2-b2f3-9f784c01495a270=1000.00271=3.10000000269=1278=12081678-66a6-4435-a3d7-b65f959cf2ac270=1000.00271=3.10000000269=1278=e7fb6165-8f1a-4b5e-b095-e232b83ee951270=1000.00271=3.10000000269=1278=83ce6582-410a-40bf-9831-8f3d20e3a629270=1000.00271=3.10000000269=1278=bc3a930b-0567-46ba-86a4-712f76466b0b270=1000.00271=3.10000000269=1278=15704973-f5ff-457d-ab31-8f99bb76bf7e270=1000.00271=3.10000000269=1278=7159045b-cbd5-458f-b91f-9fa5241b14b5270=1000.00271=3.10000000269=1278=9fa52a90-f03f-4940-b5ee-39ab937b86f1270=1000.00271=3.1000000010=129
20250411-01:34:44.720962000 : 8=FIXT.1.19=14235=334=2649=24ab46f784d1b20db435b852086e325052=20250411-01:34:44.72056=Coinbase45=15558=Tag appears more than once371=269372=W373=1310=046
20250411-01:34:44.733619000 : 8=FIXT.1.19=93935=W49=Coinbase56=24ab46f784d1b20db435b852086e325034=15650=TEST52=20250411-01:34:44.393246369=2262=7a00f5f8-0c9f-4483-8ca5-754a13a8781d83=1597550721893=N55=BTC-USD1682=full_trading268=10269=1278=220f55cd-a279-4bf0-9c80-1dca086d85dc270=1000.00271=3.10000000269=1278=2b1eb468-6bcd-4117-a7c0-214d643ddad4270=1000.00271=3.10000000269=1278=cc23185d-e72e-42cb-8210-61bab29cd778270=1000.00271=3.10000000269=1278=69bb228b-973b-4176-8708-3231cc40102a270=1000.00271=3.10000000269=1278=2ec8035d-7962-4195-8388-c9fbad52ac8a270=1000.00271=3.10000000269=1278=7d39e416-0b7b-471f-a9ac-455ab1bce5a7270=1000.00271=3.10000000269=1278=7067378d-2a65-41f2-acb0-ef30ddbc3e5a270=1000.00271=3.10000000269=1278=bf3fde78-6cff-4477-b381-4b5d2e68f36f270=1000.00271=3.10000000269=1278=93a2a8a3-61d4-410c-9446-8eabaafc5f29270=1000.00271=3.10000000269=1278=5afddb61-63ab-417b-a28a-41c4c03a6612270=1000.00271=3.1000000010=184
20250411-01:34:44.734327000 : 8=FIXT.1.19=14235=334=2749=24ab46f784d1b20db435b852086e325052=20250411-01:34:44.73356=Coinbase45=15658=Tag appears more than once371=269372=W373=1310=052
20250411-01:34:44.734426000 : 8=FIXT.1.19=93935=W49=Coinbase56=24ab46f784d1b20db435b852086e325034=15750=TEST52=20250411-01:34:44.393496369=2262=7a00f5f8-0c9f-4483-8ca5-754a13a8781d83=1597550721893=N55=BTC-USD1682=full_trading268=10269=1278=a4280417-189c-4f76-9d2e-6ec652010bf5270=1000.00271=3.10000000269=1278=ddeb78a2-e110-4828-ba3d-c9b4837e7dd7270=1000.00271=3.10000000269=1278=fcec6c90-441a-4f4a-a94e-9003355657ef270=1000.00271=3.10000000269=1278=6db15389-dfb3-4156-8a4e-ce2ac80f2b15270=1000.00271=3.10000000269=1278=47dfefc3-6f05-4b57-8aec-2bf3e6c70c2d270=1000.00271=3.10000000269=1278=fb9fd019-4b4f-4880-82bb-3df6d1ef468a270=1000.00271=3.10000000269=1278=2cff9acd-42cb-43a5-8d50-51e676b7e763270=1000.00271=3.10000000269=1278=6e6eeb59-4728-4811-9a44-c857df6aca42270=1000.00271=3.10000000269=1278=81798560-263f-4819-a528-5f3fbbc7b042270=1000.00271=3.10000000269=1278=81fbf9a8-82f4-4fe4-9fa5-3773b212ebf4270=1000.00271=3.1000000010=016
20250411-01:34:44.735143000 : 8=FIXT.1.19=14235=334=2849=24ab46f784d1b20db435b852086e325052=20250411-01:34:44.73456=Coinbase45=15758=Tag appears more than once371=269372=W373=1310=055
20250411-01:34:44.735228000 : 8=FIXT.1.19=27435=X49=Coinbase56=24ab46f784d1b20db435b852086e325034=15850=TEST52=20250411-01:34:44.393721369=2262=7a00f5f8-0c9f-4483-8ca5-754a13a8781d268=1279=0269=183=159755072855=BTC-USD271=0.6232294660=20250411-01:34:44.39267640=137=db262b1c-4cee-4bc2-9c3c-ee077af96b2610=048
20250411-01:34:44.735538000 : 8=FIXT.1.19=93935=W49=Coinbase56=24ab46f784d1b20db435b852086e325034=15950=TEST52=20250411-01:34:44.393747369=2262=7a00f5f8-0c9f-4483-8ca5-754a13a8781d83=1597550721893=N55=BTC-USD1682=full_trading268=10269=1278=5d3b9566-276d-47fe-a111-12c17f53f501270=1000.00271=3.10000000269=1278=8eb1b3b3-c813-48b1-b839-993672108d91270=1000.00271=3.10000000269=1278=4feb6e93-6149-481b-8d58-e1c8e6c5cda1270=1000.00271=3.10000000269=1278=f8611e72-4056-4b7c-9779-4d54cd151d44270=1000.00271=3.10000000269=1278=7a129f7c-d9ba-4ea3-a267-b7d82b2e07d9270=1000.00271=3.10000000269=1278=01f359f0-c38f-416b-af00-183907218793270=1000.00271=3.10000000269=1278=11741cec-9c08-4a20-99dc-6b9f63130b0e270=1000.00271=3.10000000269=1278=08db2574-ad52-4520-ab5b-c3c7591eb781270=1000.00271=3.10000000269=1278=b06f2249-179c-4a15-8e98-7b76083b808b270=1000.00271=3.10000000269=1278=9e88fede-6d19-4c1f-863b-5a7d66781436270=1000.00271=3.1000000010=182
20250411-01:34:44.736177000 : 8=FIXT.1.19=14235=334=2949=24ab46f784d1b20db435b852086e325052=20250411-01:34:44.73556=Coinbase45=15958=Tag appears more than once371=269372=W373=1310=059
20250411-01:34:44.736259000 : 8=FIXT.1.19=32635=X49=Coinbase56=24ab46f784d1b20db435b852086e325034=16050=TEST52=20250411-01:34:44.393818369=2262=7a00f5f8-0c9f-4483-8ca5-754a13a8781d268=1279=0269=2278=4d60a78e-b39b-420e-b830-bc0f3f4fdde283=159755072955=BTC-USD270=3.53271=0.6232294660=20250411-01:34:44.39267637=db262b1c-4cee-4bc2-9c3c-ee077af96b265797=210=036
20250411-01:34:44.736525000 : 8=FIXT.1.19=28035=X49=Coinbase56=24ab46f784d1b20db435b852086e325034=16150=TEST52=20250411-01:34:44.393821369=2262=7a00f5f8-0c9f-4483-8ca5-754a13a8781d268=1279=2269=1278=db262b1c-4cee-4bc2-9c3c-ee077af96b2683=159755073055=BTC-USD271=0.0000000060=20250411-01:34:44.39267658=FILLED10=192
20250411-01:34:44.737984000 : 8=FIXT.1.19=93935=W49=Coinbase56=24ab46f784d1b20db435b852086e325034=16250=TEST52=20250411-01:34:44.393996369=2262=7a00f5f8-0c9f-4483-8ca5-754a13a8781d83=1597550721893=N55=BTC-USD1682=full_trading268=10269=1278=75e1d8b4-7201-41fe-a687-7d93420af323270=1000.00271=3.10000000269=1278=d00aa7dd-ce7f-4f8b-9a2e-880c1ea30845270=1000.00271=3.10000000269=1278=584a483f-23bf-4d8b-809f-69cf3c110f60270=1000.00271=3.10000000269=1278=dc98524e-27e2-4863-99e4-7a0097a6ee90270=1000.00271=3.10000000269=1278=82a11ac9-4f46-44b7-a0bc-a5a4cfe686e0270=1000.00271=3.10000000269=1278=f946bb05-900c-41fc-9908-41489e97ff20270=1000.00271=3.10000000269=1278=1f9186d6-0312-4677-ba96-fdb014cdff2c270=1000.00271=3.10000000269=1278=c3b67be7-2b63-4884-b311-80f28496c2c4270=1000.00271=3.10000000269=1278=6576c7f8-a4e2-4417-b854-5fef0e705fbe270=1000.00271=3.10000000269=1278=c2102c71-62f0-4eee-ae60-0777ed26a8e6270=1000.00271=3.1000000010=234
20250411-01:34:44.739645000 : 8=FIXT.1.19=14235=334=3049=24ab46f784d1b20db435b852086e325052=20250411-01:34:44.73856=Coinbase45=16258=Tag appears more than once371=269372=W373=1310=048
20250411-01:34:44.739807000 : 8=FIXT.1.19=93935=W49=Coinbase56=24ab46f784d1b20db435b852086e325034=16350=TEST52=20250411-01:34:44.394246369=2262=7a00f5f8-0c9f-4483-8ca5-754a13a8781d83=1597550721893=N55=BTC-USD1682=full_trading268=10269=1278=c823a2b6-849e-4839-a2fd-cd9f459cae6c270=1000.00271=3.10000000269=1278=a051e195-4472-4a8a-8591-08a2c04a33c4270=1000.00271=3.10000000269=1278=ec81b8c4-b703-4afd-a701-ce34011f60f6270=1000.00271=3.10000000269=1278=b1172677-f493-4f32-a200-0710cf8c397f270=1000.00271=3.10000000269=1278=b1a58a75-5fca-43db-b9c6-a26920e8f66e270=1000.00271=3.10000000269=1278=038bea41-b91d-4884-b992-3e5431ef9857270=1000.00271=3.10000000269=1278=55063782-f2ea-4c84-9491-8e8e89d1dfd1270=1000.00271=3.10000000269=1278=bb2011e8-d05d-40ac-9e9c-3b720422e38d270=1000.00271=3.10000000269=1278=64dd3b4a-ce8a-4b63-9937-266e832c0f21270=1000.00271=3.10000000269=1278=d64f7d2a-aa83-486c-92a8-3314c4eddd58270=1000.00271=3.1000000010=193
20250411-01:34:44.741865000 : 8=FIXT.1.19=14235=334=3149=24ab46f784d1b20db435b852086e325052=20250411-01:34:44.74156=Coinbase45=16358=Tag appears more than once371=269372=W373=1310=044
20250411-01:34:44.742331000 : 8=FIXT.1.19=93935=W49=Coinbase56=24ab46f784d1b20db435b852086e325034=16450=TEST52=20250411-01:34:44.394496369=2262=7a00f5f8-0c9f-4483-8ca5-754a13a8781d83=1597550721893=N55=BTC-USD1682=full_trading268=10269=1278=0df9641b-d89d-4222-a8ea-bcddf0d555f5270=1000.00271=3.10000000269=1278=7a315b16-a05f-408d-b8c1-2704af9bf767270=1000.00271=3.10000000269=1278=0e9712a8-d00f-4864-a478-f7f591718f91270=1000.00271=3.10000000269=1278=94db025d-eada-49e3-b13c-b667ca07f829270=1000.00271=3.10000000269=1278=a88ccd1f-8f8d-46af-8fb6-20adba35f7d1270=1000.00271=3.10000000269=1278=99d4e235-c8ec-4efc-938c-9a1923eafc96270=1000.00271=3.10000000269=1278=a4fc7173-7583-4f8b-b256-2921bef83c84270=1000.00271=3.10000000269=1278=18f8afd4-8bbc-4ffa-8e8f-0c1834d74472270=1000.00271=3.10000000269=1278=21fc8cb6-f894-4d09-884e-810b8ebf2ef3270=1000.00271=3.10000000269=1278=0c13b9e6-6797-4b3e-90ce-a1885b26ba53270=1000.00271=3.1000000010=235
20250411-01:34:44.743977000 : 8=FIXT.1.19=14235=334=3249=24ab46f784d1b20db435b852086e325052=20250411-01:34:44.74356=Coinbase45=16458=Tag appears more than once371=269372=W373=1310=048
20250411-01:34:44.744138000 : 8=FIXT.1.19=93935=W49=Coinbase56=24ab46f784d1b20db435b852086e325034=16550=TEST52=20250411-01:34:44.394746369=2262=7a00f5f8-0c9f-4483-8ca5-754a13a8781d83=1597550721893=N55=BTC-USD1682=full_trading268=10269=1278=6d8da581-3998-4fc0-99b6-3c5edbd514cb270=1000.00271=3.10000000269=1278=67a70307-be50-4065-872b-47e0de473bc4270=1000.00271=3.10000000269=1278=8ce7be0b-98de-46d0-b1b6-307a4bec36e2270=1000.00271=3.10000000269=1278=856b22f8-5884-4739-adc0-bdd851c5c07d270=1000.00271=3.10000000269=1278=c00ae651-a76b-4bfd-be16-3672b345fe29270=1000.00271=3.10000000269=1278=cae248f9-16fc-44ea-9b79-1dacfc285db6270=1000.00271=3.10000000269=1278=42bb223c-88c6-4a18-8ff3-4fd8d9efda8d270=1000.00271=3.10000000269=1278=d7188b01-22b6-4837-a720-077601f7f483270=1000.00271=3.10000000269=1278=5d85a0a6-ddd9-4e0e-9a1a-7f418ef588e5270=1000.00271=3.10000000269=1278=bff4c39f-7a80-42ce-a178-b1221792e445270=1000.00271=3.1000000010=251
20250411-01:34:44.745217000 : 8=FIXT.1.19=14235=334=3349=24ab46f784d1b20db435b852086e325052=20250411-01:34:44.74456=Coinbase45=16558=Tag appears more than once371=269372=W373=1310=051
20250411-01:34:44.745386000 : 8=FIXT.1.19=93935=W49=Coinbase56=24ab46f784d1b20db435b852086e325034=16650=TEST52=20250411-01:34:44.394996369=2262=7a00f5f8-0c9f-4483-8ca5-754a13a8781d83=1597550721893=N55=BTC-USD1682=full_trading268=10269=1278=9ea3d263-b5ab-46c5-bf27-8c0e3e0e5e9e270=1000.00271=3.10000000269=1278=b93347df-d2ab-48ec-b326-4454e64f1d4e270=1000.00271=3.10000000269=1278=57acc40d-8478-444a-990f-067a8e8e846e270=1000.00271=3.10000000269=1278=34419ae2-2c16-427b-a290-845419760fd5270=1000.00271=3.10000000269=1278=ab41de2d-5def-4986-b56e-243d2f99a57c270=1000.00271=3.10000000269=1278=9025524c-03a9-407a-a58a-5258c4ea0a0b270=1000.00271=3.10000000269=1278=60766318-112b-4d83-a384-55693de75519270=1000.00271=3.10000000269=1278=c19b6a2c-086b-4fc1-8dfe-51cb2dc12c1d270=1000.00271=3.10000000269=1278=11126433-0f9c-4450-a35a-39b878e85e68270=1000.00271=3.10000000269=1278=e2e620ee-44fb-4630-a890-d331ba5b2fae270=1000.00271=3.1000000010=142
20250411-01:34:44.745978000 : 8=FIXT.1.19=14235=334=3449=24ab46f784d1b20db435b852086e325052=20250411-01:34:44.74556=Coinbase45=16658=Tag appears more than once371=269372=W373=1310=054
20250411-01:34:44.746065000 : 8=FIXT.1.19=93935=W49=Coinbase56=24ab46f784d1b20db435b852086e325034=16750=TEST52=20250411-01:34:44.395247369=2262=7a00f5f8-0c9f-4483-8ca5-754a13a8781d83=1597550721893=N55=BTC-USD1682=full_trading268=10269=1278=9ccf6d4b-a6ca-4a1f-a7bb-77f400ace0c8270=1000.00271=3.10000000269=1278=0e8d6c10-8421-4f19-97dc-d70e715d9033270=1000.00271=3.10000000269=1278=f31ecd5d-8231-44ea-a5c2-0fcc5a699401270=1000.00271=3.10000000269=1278=37fbb559-dc52-48fe-ab65-24910edc338a270=1000.00271=3.10000000269=1278=bc1435c5-c59c-4017-9e59-f1073f04c7e2270=1000.00271=3.10000000269=1278=9c8e1397-0cee-4b05-a66f-5594040791c4270=1000.00271=3.10000000269=1278=248b6703-f829-42bb-a551-4be3075c381e270=1000.00271=3.10000000269=1278=16d257b0-bc92-44f0-822d-3eba61af4bda270=1000.00271=3.10000000269=1278=06257aa1-4043-4cdb-9286-4342b8e59108270=1000.00271=3.10000000269=1278=210ec210-1443-47dc-9e43-9c9ea720a6c3270=1000.00271=3.1000000010=126
20250411-01:34:44.746636000 : 8=FIXT.1.19=14235=334=3549=24ab46f784d1b20db435b852086e325052=20250411-01:34:44.74656=Coinbase45=16758=Tag appears more than once371=269372=W373=1310=057
20250411-01:34:44.746720000 : 8=FIXT.1.19=93935=W49=Coinbase56=24ab46f784d1b20db435b852086e325034=16850=TEST52=20250411-01:34:44.395497369=2262=7a00f5f8-0c9f-4483-8ca5-754a13a8781d83=1597550721893=N55=BTC-USD1682=full_trading268=10269=1278=8b79da5d-b78c-4011-b55f-b35c16dc3724270=1000.00271=3.10000000269=1278=076c3703-1104-4e15-a38a-d95bf133f0c5270=1000.00271=3.10000000269=1278=f5a3155c-e449-4102-870d-ab8c8dd24c3d270=1000.00271=3.10000000269=1278=1af2681f-2dec-4d25-aaeb-89b8867b4a3c270=1000.00271=3.10000000269=1278=65c3088d-192a-4213-85a3-7257aa8b20a3270=1000.00271=3.10000000269=1278=2aa7989b-5601-4899-8143-01dda3255e4f270=1000.00271=3.10000000269=1278=099b432c-fa2e-4fd7-952e-22f6debf6877270=1000.00271=3.10000000269=1278=2e71cc31-1235-4b7b-a728-e3335631fe5a270=1000.00271=3.10000000269=1278=ce471ffc-1e26-4afe-afab-27ee5ac8debe270=1000.00271=3.10000000269=1278=113b7fc6-8574-40eb-8682-d077245b84f2270=1000.00271=3.1000000010=104
20250411-01:34:44.747596000 : 8=FIXT.1.19=14235=334=3649=24ab46f784d1b20db435b852086e325052=20250411-01:34:44.74756=Coinbase45=16858=Tag appears more than once371=269372=W373=1310=060
20250411-01:34:44.747710000 : 8=FIXT.1.19=93935=W49=Coinbase56=24ab46f784d1b20db435b852086e325034=16950=TEST52=20250411-01:34:44.395747369=2262=7a00f5f8-0c9f-4483-8ca5-754a13a8781d83=1597550721893=N55=BTC-USD1682=full_trading268=10269=1278=bcebce2c-eda8-4b85-841d-27ede39fc5a1270=1000.00271=3.10000000269=1278=0aedaae5-6cc6-4a34-8e48-5e67a5ccc148270=1000.00271=3.10000000269=1278=206e10a5-1173-4860-87b5-7c88afe061f6270=1000.00271=3.10000000269=1278=5c32d94b-696a-4d9b-afa0-665970356008270=1000.00271=3.10000000269=1278=0b7da819-cc1e-4525-a382-ce5b90dc485c270=1000.00271=3.10000000269=1278=2241b3bf-cbbe-44f2-ac75-8032f6283aa8270=1000.00271=3.10000000269=1278=88cada69-adb1-466a-afcd-66e063ad27c0270=1000.00271=3.10000000269=1278=34a52ef5-31c1-4c63-9230-21c85a9a6ba3270=1000.00271=3.10000000269=1278=e109c2c8-fb1d-4ef9-a640-368381323507270=1000.00271=3.10000000269=1278=38fd36c4-4c62-4b4c-8f24-1fe39be94fa1270=1000.00271=3.1000000010=218
20250411-01:34:44.748523000 : 8=FIXT.1.19=14235=334=3749=24ab46f784d1b20db435b852086e325052=20250411-01:34:44.74856=Coinbase45=16958=Tag appears more than once371=269372=W373=1310=063
20250411-01:34:44.748609000 : 8=FIXT.1.19=93935=W49=Coinbase56=24ab46f784d1b20db435b852086e325034=17050=TEST52=20250411-01:34:44.395997369=2262=7a00f5f8-0c9f-4483-8ca5-754a13a8781d83=1597550721893=N55=BTC-USD1682=full_trading268=10269=1278=f83f64c8-7d33-472d-a516-9b664ff9c966270=1000.00271=3.10000000269=1278=3411c368-380b-42e6-b656-8552d92904d5270=1000.00271=3.10000000269=1278=4803796e-79f3-4aa4-a8cb-37f13899bf01270=1000.00271=3.10000000269=1278=823f8fbf-7e6d-4ae3-adb9-3a822ff6d09a270=1000.00271=3.10000000269=1278=135624df-a204-490f-a68b-63d74ee09908270=1000.00271=3.10000000269=1278=47cfdedf-22b9-402c-93bd-f311103fd3e0270=1000.00271=3.10000000269=1278=f9173d5e-d872-4661-93f6-28f527e931f7270=1000.00271=3.10000000269=1278=06ab1365-fd39-4701-bd7f-1915ad3c7602270=1000.00271=3.10000000269=1278=012a7c59-5ae4-4da5-97ba-2e3254c889fb270=1000.00271=3.10000000269=1278=a9a0d42f-ad9e-4ea9-8bf0-d5a441fded40270=1000.00271=3.1000000010=007
20250411-01:34:44.749364000 : 8=FIXT.1.19=14235=334=3849=24ab46f784d1b20db435b852086e325052=20250411-01:34:44.74856=Coinbase45=17058=Tag appears more than once371=269372=W373=1310=056
20250411-01:34:44.749464000 : 8=FIXT.1.19=93935=W49=Coinbase56=24ab46f784d1b20db435b852086e325034=17150=TEST52=20250411-01:34:44.396247369=2262=7a00f5f8-0c9f-4483-8ca5-754a13a8781d83=1597550721893=N55=BTC-USD1682=full_trading268=10269=1278=f3f3930e-be0e-40b4-a97d-d19501a54885270=1000.00271=3.10000000269=1278=261922d0-5c81-4ab6-832f-4eff45f64890270=1000.00271=3.10000000269=1278=3af4e45f-56f6-4c69-894d-d56a14894a98270=1000.00271=3.10000000269=1278=1c1dd248-49e4-44aa-9e69-323b0f41fa0e270=1000.00271=3.10000000269=1278=b16b002d-1cd6-4869-9c1b-f15c758611bf270=1000.00271=3.10000000269=1278=a0520e61-28ad-448d-87c1-49f0c7358628270=1000.00271=3.10000000269=1278=152d0b57-086f-48cc-80b3-ff14ee9375ed270=1000.00271=3.10000000269=1278=c55fc264-67d2-4e9c-8cce-6c834feff648270=1000.00271=3.10000000269=1278=27361968-189a-4fa6-a3a2-eead03c640d6270=1000.00271=3.10000000269=1278=f5b01c67-f98f-44b9-a511-7f07f8883d9e270=1000.00271=3.1000000010=128
20250411-01:34:44.750062000 : 8=FIXT.1.19=14235=334=3949=24ab46f784d1b20db435b852086e325052=20250411-01:34:44.74956=Coinbase45=17158=Tag appears more than once371=269372=W373=1310=059
20250411-01:34:44.750155000 : 8=FIXT.1.19=93935=W49=Coinbase56=24ab46f784d1b20db435b852086e325034=17250=TEST52=20250411-01:34:44.396497369=2262=7a00f5f8-0c9f-4483-8ca5-754a13a8781d83=1597550721893=N55=BTC-USD1682=full_trading268=10269=1278=75a5c14f-8434-4533-a10e-0bf6e92e1000270=1000.00271=3.10000000269=1278=a9b0a826-3659-4105-9ecc-21bcd27b736f270=1000.00271=3.10000000269=1278=1b1bab77-5c52-459b-98e3-e27ff6f8cd04270=1000.00271=3.10000000269=1278=346695f1-fe03-4364-8fc5-006796c8f82f270=1000.00271=3.10000000269=1278=cbbaa36d-2a03-45a2-a230-bd5845d832cd270=1000.00271=3.10000000269=1278=745d4fc0-6710-4c5c-97c3-7b29c4e06839270=1000.00271=3.10000000269=1278=e95fdfba-5db2-4461-8e9c-7bfdf8a9238c270=1000.00271=3.10000000269=1278=33611b39-1fbf-45cc-bf5e-a02bc1f84736270=1000.00271=3.10000000269=1278=51f77b2d-1a69-432d-934b-234eb9e1dfac270=1000.00271=3.10000000269=1278=ab09fdc3-8d50-432f-ab0f-97e8627eac24270=1000.00271=3.1000000010=057
20250411-01:34:44.750791000 : 8=FIXT.1.19=14235=334=4049=24ab46f784d1b20db435b852086e325052=20250411-01:34:44.75056=Coinbase45=17258=Tag appears more than once371=269372=W373=1310=044
20250411-01:34:44.750868000 : 8=FIXT.1.19=93935=W49=Coinbase56=24ab46f784d1b20db435b852086e325034=17350=TEST52=20250411-01:34:44.396747369=2262=7a00f5f8-0c9f-4483-8ca5-754a13a8781d83=1597550721893=N55=BTC-USD1682=full_trading268=10269=1278=dde04213-6104-44c5-a811-15834c27b515270=1000.00271=3.10000000269=1278=9af2b85c-4997-4e1b-9147-7d400f059b01270=1000.00271=3.10000000269=1278=40870860-7a8a-4419-a117-e511f779abfa270=1000.00271=3.10000000269=1278=3e8fa7bd-dde0-4fe4-bb2e-e6279841b019270=1000.00271=3.10000000269=1278=4dde1422-98d8-405b-88df-bf245291ad7a270=1000.00271=3.10000000269=1278=6ee8b5a8-bc2f-4a0a-9ae4-7ff1b5dae941270=1000.00271=3.10000000269=1278=3ebc1f7a-2bb5-4ef0-a82f-844b9540f6e8270=1000.00271=3.10000000269=1278=a82d5bb9-1f1a-4575-b580-8d9b60863b10270=1000.00271=3.10000000269=1278=14f89bd5-0233-435c-b608-2e19131b8f6c270=1000.00271=3.10000000269=1278=a2e319e5-aab7-41d4-9d19-98d771a3f1d3270=1000.00271=3.1000000010=016
20250411-01:34:44.751790000 : 8=FIXT.1.19=14235=334=4149=24ab46f784d1b20db435b852086e325052=20250411-01:34:44.75156=Coinbase45=17358=Tag appears more than once371=269372=W373=1310=047
20250411-01:34:44.751901000 : 8=FIXT.1.19=93935=W49=Coinbase56=24ab46f784d1b20db435b852086e325034=17450=TEST52=20250411-01:34:44.396997369=2262=7a00f5f8-0c9f-4483-8ca5-754a13a8781d83=1597550721893=N55=BTC-USD1682=full_trading268=10269=1278=dc965e0b-075a-4ba4-a498-02c96d1664ba270=1000.00271=3.10000000269=1278=67b6e68f-ac11-4c05-a54a-2adb555b0123270=1000.00271=3.10000000269=1278=866f52a1-dad9-49d7-ac4a-9da3075407a3270=1000.00271=3.10000000269=1278=0e38234d-a010-40f6-9c6f-a0d574e773cf270=1000.00271=3.10000000269=1278=d6af6749-e3c8-4938-8741-1d5f177cf8e1270=1000.00271=3.10000000269=1278=45ff5e59-2c4d-45ac-9fde-403662dfd1ca270=1000.00271=3.10000000269=1278=dcac314e-c54f-44e3-b96d-ef71539766ed270=1000.00271=3.10000000269=1278=dd6d14ea-760f-4884-a546-1d3c40ebdd7c270=1000.00271=3.10000000269=1278=4f3da0c6-46eb-4b64-b973-cc43e24abccb270=1000.00271=3.10000000269=1278=aa40cda8-4abd-4f52-999a-1a90ed5bf41a270=1000.00271=3.1000000010=117
20250411-01:34:44.752548000 : 8=FIXT.1.19=14235=334=4249=24ab46f784d1b20db435b852086e325052=20250411-01:34:44.75256=Coinbase45=17458=Tag appears more than once371=269372=W373=1310=050
20250411-01:34:44.752644000 : 8=FIXT.1.19=95335=W49=Coinbase56=24ab46f784d1b20db435b852086e325034=17550=TEST52=20250411-01:34:44.397247369=2262=7a00f5f8-0c9f-4483-8ca5-754a13a8781d83=1597550721893=N55=BTC-USD1682=full_trading268=10269=1278=687ee4fc-f626-4e4f-abee-1f0ee5af3f72270=1000.00271=3.10000000269=1278=b1ad1135-67ec-4c96-99cb-a626137f3f16270=10000.00271=1.00000000269=1278=e9320f5f-80ae-41ab-af7a-86518d456fb0270=10000.00271=1.00000000269=1278=cd95aff0-36fa-4804-887f-2c3fce3cdc86270=10000.00271=1.00000000269=1278=fbdbcee1-8c29-4478-97df-358d209d8808270=10000.00271=1.00000000269=1278=140f39da-834b-4e42-8e15-6e25287df1f0270=900000.00271=0.00011111269=1278=49f064c5-76fe-4b38-bede-48b60a0a5aec270=900000.00271=0.00011111269=1278=681cf73b-9d37-4101-b940-9da9b1ff61ed270=900000.00271=0.00011111269=1278=3dea1587-e474-4258-b6e8-485c21b56670270=900000.00271=0.00011111269=1278=afd96a7b-3d48-459e-b810-e4ee88353a31270=900000.00271=0.0001111110=060
20250411-01:34:44.753339000 : 8=FIXT.1.19=14235=334=4349=24ab46f784d1b20db435b852086e325052=20250411-01:34:44.75256=Coinbase45=17558=Tag appears more than once371=269372=W373=1310=052
20250411-01:34:44.753512000 : 8=FIXT.1.19=95935=W49=Coinbase56=24ab46f784d1b20db435b852086e325034=17650=TEST52=20250411-01:34:44.397497369=2262=7a00f5f8-0c9f-4483-8ca5-754a13a8781d83=1597550721893=N55=BTC-USD1682=full_trading268=10269=1278=a68ae029-b920-4ae7-a775-ccdb800fc252270=900000.00271=0.00001111269=1278=d44508b7-1c9f-4b4f-acb8-99c93d2b99e8270=900000.00271=0.00001111269=1278=304ff106-de40-4381-89c5-c93f7f3e32ae270=900000.00271=0.00001111269=1278=08a0fef8-fcbb-4857-8463-2599cf331386270=900000.00271=0.00011111269=1278=07b2856d-f899-417c-82d5-886f0d85125e270=900000.00271=0.00011111269=1278=12ecb45e-6af8-4804-a942-5c997b9d1502270=900000.00271=0.00011111269=1278=98676c5f-b851-473c-817a-b29243092a25270=900000.00271=0.00001111269=1278=09afe685-e71f-4ea0-b164-c27737db126d270=900000.00271=0.00001111269=1278=e71ee98f-c329-428d-9893-629b53015ff6270=900000.00271=0.00001111269=1278=124e6fc1-6dde-452b-be03-c00113c8ebdb270=900000.00271=0.0001111110=112
20250411-01:34:44.754137000 : 8=FIXT.1.19=14235=334=4449=24ab46f784d1b20db435b852086e325052=20250411-01:34:44.75356=Coinbase45=17658=Tag appears more than once371=269372=W373=1310=055
20250411-01:34:44.754307000 : 8=FIXT.1.19=50635=W49=Coinbase56=24ab46f784d1b20db435b852086e325034=17750=TEST52=20250411-01:34:44.397747369=2262=7a00f5f8-0c9f-4483-8ca5-754a13a8781d83=1597550721893=Y55=BTC-USD1682=full_trading268=4269=1278=b71cc7f5-d7c6-4fc0-a0de-59b0eb7fd063270=1000000.00271=1.00000000269=1278=afec127b-a98c-49cb-893f-e385a7e35d32270=1000000.00271=1.00000000269=1278=06df7c57-366d-4d2c-acc2-e6c26d60e9c3270=1000000.00271=1.00000000269=1278=b1c4eb2b-90df-44e0-ae4f-515df4086a9d270=9999999.00271=0.0000100010=253
20250411-01:34:44.754908000 : 8=FIXT.1.19=14235=334=4549=24ab46f784d1b20db435b852086e325052=20250411-01:34:44.75456=Coinbase45=17758=Tag appears more than once371=269372=W373=1310=058
20250411-01:34:44.755071000 : 8=FIXT.1.19=27835=X49=Coinbase56=24ab46f784d1b20db435b852086e325034=17850=TEST52=20250411-01:34:44.537244369=2262=7a00f5f8-0c9f-4483-8ca5-754a13a8781d268=1279=0269=083=159755073155=BTC-USD29004=2.208895519560=20250411-01:34:44.53527040=137=f1075dc2-e492-48b1-88f9-3fa88683161410=150
20250411-01:34:44.755366000 : 8=FIXT.1.19=32635=X49=Coinbase56=24ab46f784d1b20db435b852086e325034=17950=TEST52=20250411-01:34:44.537255369=2262=7a00f5f8-0c9f-4483-8ca5-754a13a8781d268=1279=0269=2278=c5b88ea9-605d-4595-ac52-f7c3f08523ba83=159755073255=BTC-USD270=3.55271=0.6222240960=20250411-01:34:44.53527037=f1075dc2-e492-48b1-88f9-3fa8868316145797=110=043
20250411-01:34:44.755538000 : 8=FIXT.1.19=26535=X49=Coinbase56=24ab46f784d1b20db435b852086e325034=18050=TEST52=20250411-01:34:44.537257369=2262=7a00f5f8-0c9f-4483-8ca5-754a13a8781d268=1279=2269=0278=f1075dc2-e492-48b1-88f9-3fa88683161483=159755073355=BTC-USD60=20250411-01:34:44.53527058=FILLED10=161
20250411-01:34:44.756554000 : 8=FIXT.1.19=27435=X49=Coinbase56=24ab46f784d1b20db435b852086e325034=18150=TEST52=20250411-01:34:44.565718369=2262=7a00f5f8-0c9f-4483-8ca5-754a13a8781d268=1279=0269=183=159755073455=BTC-USD271=0.6232294660=20250411-01:34:44.56448940=137=20ce0c9b-209a-4ca5-a0f3-ade998dbc62f10=045
20250411-01:34:44.756722000 : 8=FIXT.1.19=32635=X49=Coinbase56=24ab46f784d1b20db435b852086e325034=18250=TEST52=20250411-01:34:44.565725369=2262=7a00f5f8-0c9f-4483-8ca5-754a13a8781d268=1279=0269=2278=4d60a78e-b39b-420e-b830-bc0f3f4fdde283=159755073555=BTC-USD270=3.53271=0.6232294660=20250411-01:34:44.56448937=20ce0c9b-209a-4ca5-a0f3-ade998dbc62f5797=210=032
20250411-01:34:44.756901000 : 8=FIXT.1.19=28035=X49=Coinbase56=24ab46f784d1b20db435b852086e325034=18350=TEST52=20250411-01:34:44.565728369=2262=7a00f5f8-0c9f-4483-8ca5-754a13a8781d268=1279=2269=1278=20ce0c9b-209a-4ca5-a0f3-ade998dbc62f83=159755073655=BTC-USD271=0.0000000060=20250411-01:34:44.56448958=FILLED10=206
20250411-01:34:45.000357000 : 8=FIXT.1.19=27935=X49=Coinbase56=24ab46f784d1b20db435b852086e325034=18450=TEST52=20250411-01:34:44.879893369=45262=7a00f5f8-0c9f-4483-8ca5-754a13a8781d268=1279=0269=083=159755073755=BTC-USD29004=2.208895519560=20250411-01:34:44.87825040=137=98893bba-1604-4907-ae66-dc9ff5b131ec10=162
20250411-01:34:45.001327000 : 8=FIXT.1.19=32735=X49=Coinbase56=24ab46f784d1b20db435b852086e325034=18550=TEST52=20250411-01:34:44.879982369=45262=7a00f5f8-0c9f-4483-8ca5-754a13a8781d268=1279=0269=2278=c5b88ea9-605d-4595-ac52-f7c3f08523ba83=159755073855=BTC-USD270=3.55271=0.6222240960=20250411-01:34:44.87825037=98893bba-1604-4907-ae66-dc9ff5b131ec5797=110=052
20250411-01:34:45.001557000 : 8=FIXT.1.19=26635=X49=Coinbase56=24ab46f784d1b20db435b852086e325034=18650=TEST52=20250411-01:34:44.879984369=45262=7a00f5f8-0c9f-4483-8ca5-754a13a8781d268=1279=2269=0278=98893bba-1604-4907-ae66-dc9ff5b131ec83=159755073955=BTC-USD60=20250411-01:34:44.87825058=FILLED10=179
20250411-01:34:45.030534000 : 8=FIXT.1.19=27535=X49=Coinbase56=24ab46f784d1b20db435b852086e325034=18750=TEST52=20250411-01:34:44.908240369=45262=7a00f5f8-0c9f-4483-8ca5-754a13a8781d268=1279=0269=183=159755074055=BTC-USD271=0.6232294660=20250411-01:34:44.90714240=137=2056ed4e-2ef9-40ee-8b44-b3125735ffba10=204
20250411-01:34:45.031344000 : 8=FIXT.1.19=32735=X49=Coinbase56=24ab46f784d1b20db435b852086e325034=18850=TEST52=20250411-01:34:44.908303369=45262=7a00f5f8-0c9f-4483-8ca5-754a13a8781d268=1279=0269=2278=4d60a78e-b39b-420e-b830-bc0f3f4fdde283=159755074155=BTC-USD270=3.53271=0.6232294660=20250411-01:34:44.90714237=2056ed4e-2ef9-40ee-8b44-b3125735ffba5797=210=193
20250411-01:34:45.031740000 : 8=FIXT.1.19=28135=X49=Coinbase56=24ab46f784d1b20db435b852086e325034=18950=TEST52=20250411-01:34:44.908306369=45262=7a00f5f8-0c9f-4483-8ca5-754a13a8781d268=1279=2269=1278=2056ed4e-2ef9-40ee-8b44-b3125735ffba83=159755074255=BTC-USD271=0.0000000060=20250411-01:34:44.90714258=FILLED10=111
20250411-01:34:45.277616000 : 8=FIXT.1.19=28435=X49=Coinbase56=24ab46f784d1b20db435b852086e325034=19050=TEST52=20250411-01:34:45.154111369=45262=7a00f5f8-0c9f-4483-8ca5-754a13a8781d268=1279=0269=183=159755074355=BTC-USD270=3.25271=0.6232294660=20250411-01:34:45.15280140=237=ab20a703-f4d3-48d7-8c39-dc219db1ad3b10=126
20250411-01:34:45.278412000 : 8=FIXT.1.19=32735=X49=Coinbase56=24ab46f784d1b20db435b852086e325034=19150=TEST52=20250411-01:34:45.154124369=45262=7a00f5f8-0c9f-4483-8ca5-754a13a8781d268=1279=0269=2278=4d60a78e-b39b-420e-b830-bc0f3f4fdde283=159755074455=BTC-USD270=3.53271=0.6232294660=20250411-01:34:45.15280137=ab20a703-f4d3-48d7-8c39-dc219db1ad3b5797=210=215
20250411-01:34:45.279949000 : 8=FIXT.1.19=29035=X49=Coinbase56=24ab46f784d1b20db435b852086e325034=19250=TEST52=20250411-01:34:45.154126369=45262=7a00f5f8-0c9f-4483-8ca5-754a13a8781d268=1279=2269=1278=ab20a703-f4d3-48d7-8c39-dc219db1ad3b83=159755074555=BTC-USD270=3.25271=0.0000000060=20250411-01:34:45.15280158=FILLED10=035
20250411-01:34:45.330191000 : 8=FIXT.1.19=28435=X49=Coinbase56=24ab46f784d1b20db435b852086e325034=19350=TEST52=20250411-01:34:45.209475369=45262=7a00f5f8-0c9f-4483-8ca5-754a13a8781d268=1279=0269=083=159755074655=BTC-USD270=3.75271=0.6232294660=20250411-01:34:45.20759540=237=9d5ae129-cb95-47ec-96b8-1d21d367db7010=090
20250411-01:34:45.331135000 : 8=FIXT.1.19=32735=X49=Coinbase56=24ab46f784d1b20db435b852086e325034=19450=TEST52=20250411-01:34:45.209484369=45262=7a00f5f8-0c9f-4483-8ca5-754a13a8781d268=1279=0269=2278=c5b88ea9-605d-4595-ac52-f7c3f08523ba83=159755074755=BTC-USD270=3.55271=0.6232294660=20250411-01:34:45.20759537=9d5ae129-cb95-47ec-96b8-1d21d367db705797=110=044
20250411-01:34:45.331832000 : 8=FIXT.1.19=29035=X49=Coinbase56=24ab46f784d1b20db435b852086e325034=19550=TEST52=20250411-01:34:45.209487369=45262=7a00f5f8-0c9f-4483-8ca5-754a13a8781d268=1279=2269=0278=9d5ae129-cb95-47ec-96b8-1d21d367db7083=159755074855=BTC-USD270=3.75271=0.0000000060=20250411-01:34:45.20759558=FILLED10=252
20250411-01:34:45.342720000 : 8=FIXT.1.19=27935=X49=Coinbase56=24ab46f784d1b20db435b852086e325034=19650=TEST52=20250411-01:34:45.222138369=45262=7a00f5f8-0c9f-4483-8ca5-754a13a8781d268=1279=0269=083=159755074955=BTC-USD29004=2.208895519560=20250411-01:34:45.22090340=137=215f8c96-0791-4c15-88ff-a887de48d2f610=056
20250411-01:34:45.343190000 : 8=FIXT.1.19=32735=X49=Coinbase56=24ab46f784d1b20db435b852086e325034=19750=TEST52=20250411-01:34:45.222145369=45262=7a00f5f8-0c9f-4483-8ca5-754a13a8781d268=1279=0269=2278=c5b88ea9-605d-4595-ac52-f7c3f08523ba83=159755075055=BTC-USD270=3.55271=0.6222240960=20250411-01:34:45.22090337=215f8c96-0791-4c15-88ff-a887de48d2f65797=110=192
20250411-01:34:45.343392000 : 8=FIXT.1.19=26635=X49=Coinbase56=24ab46f784d1b20db435b852086e325034=19850=TEST52=20250411-01:34:45.222147369=45262=7a00f5f8-0c9f-4483-8ca5-754a13a8781d268=1279=2269=0278=215f8c96-0791-4c15-88ff-a887de48d2f683=159755075155=BTC-USD60=20250411-01:34:45.22090358=FILLED10=063
20250411-01:34:45.370866000 : 8=FIXT.1.19=27535=X49=Coinbase56=24ab46f784d1b20db435b852086e325034=19950=TEST52=20250411-01:34:45.250341369=45262=7a00f5f8-0c9f-4483-8ca5-754a13a8781d268=1279=0269=183=159755075255=BTC-USD271=0.6232294660=20250411-01:34:45.24929340=137=bdcd542b-7575-41c9-982a-f6d1b0779f3710=131
20250411-01:34:45.371477000 : 8=FIXT.1.19=32735=X49=Coinbase56=24ab46f784d1b20db435b852086e325034=20050=TEST52=20250411-01:34:45.250353369=45262=7a00f5f8-0c9f-4483-8ca5-754a13a8781d268=1279=0269=2278=4d60a78e-b39b-420e-b830-bc0f3f4fdde283=159755075355=BTC-USD270=3.53271=0.6232294660=20250411-01:34:45.24929337=bdcd542b-7575-41c9-982a-f6d1b0779f375797=210=105
20250411-01:34:45.371712000 : 8=FIXT.1.19=28135=X49=Coinbase56=24ab46f784d1b20db435b852086e325034=20150=TEST52=20250411-01:34:45.250355369=45262=7a00f5f8-0c9f-4483-8ca5-754a13a8781d268=1279=2269=1278=bdcd542b-7575-41c9-982a-f6d1b0779f3783=159755075455=BTC-USD271=0.0000000060=20250411-01:34:45.24929358=FILLED10=022
20250411-01:34:45.687073000 : 8=FIXT.1.19=27935=X49=Coinbase56=24ab46f784d1b20db435b852086e325034=20250=TEST52=20250411-01:34:45.508547369=45262=7a00f5f8-0c9f-4483-8ca5-754a13a8781d268=1279=0269=083=159755075555=BTC-USD29004=2.208895519560=20250411-01:34:45.50748740=137=6e2e23b9-699f-415e-898e-f0703321153110=159
20250411-01:34:45.688172000 : 8=FIXT.1.19=32735=X49=Coinbase56=24ab46f784d1b20db435b852086e325034=20350=TEST52=20250411-01:34:45.508555369=45262=7a00f5f8-0c9f-4483-8ca5-754a13a8781d268=1279=0269=2278=c5b88ea9-605d-4595-ac52-f7c3f08523ba83=159755075655=BTC-USD270=3.55271=0.6222240960=20250411-01:34:45.50748737=6e2e23b9-699f-415e-898e-f070332115315797=110=049
20250411-01:34:45.688666000 : 8=FIXT.1.19=26635=X49=Coinbase56=24ab46f784d1b20db435b852086e325034=20450=TEST52=20250411-01:34:45.508560369=45262=7a00f5f8-0c9f-4483-8ca5-754a13a8781d268=1279=2269=0278=6e2e23b9-699f-415e-898e-f0703321153183=159755075755=BTC-USD60=20250411-01:34:45.50748758=FILLED10=170
20250411-01:34:45.689178000 : 8=FIXT.1.19=27535=X49=Coinbase56=24ab46f784d1b20db435b852086e325034=20550=TEST52=20250411-01:34:45.536983369=45262=7a00f5f8-0c9f-4483-8ca5-754a13a8781d268=1279=0269=183=159755075855=BTC-USD271=0.6232294660=20250411-01:34:45.53520440=137=9fb9db5c-d55e-4954-8bd5-2ae0f956d94810=244
20250411-01:34:45.690428000 : 8=FIXT.1.19=32735=X49=Coinbase56=24ab46f784d1b20db435b852086e325034=20650=TEST52=20250411-01:34:45.536989369=45262=7a00f5f8-0c9f-4483-8ca5-754a13a8781d268=1279=0269=2278=4d60a78e-b39b-420e-b830-bc0f3f4fdde283=159755075955=BTC-USD270=3.53271=0.6232294660=20250411-01:34:45.53520437=9fb9db5c-d55e-4954-8bd5-2ae0f956d9485797=210=239
20250411-01:34:45.690746000 : 8=FIXT.1.19=28135=X49=Coinbase56=24ab46f784d1b20db435b852086e325034=20750=TEST52=20250411-01:34:45.536992369=45262=7a00f5f8-0c9f-4483-8ca5-754a13a8781d268=1279=2269=1278=9fb9db5c-d55e-4954-8bd5-2ae0f956d94883=159755076055=BTC-USD271=0.0000000060=20250411-01:34:45.53520458=FILLED10=139
20250411-01:34:45.692097000 : 8=FIXT.1.19=27935=X49=Coinbase56=24ab46f784d1b20db435b852086e325034=20850=TEST52=20250411-01:34:45.566372369=45262=7a00f5f8-0c9f-4483-8ca5-754a13a8781d268=1279=0269=083=159755076155=BTC-USD29004=2.208895519560=20250411-01:34:45.56485040=137=299e56ba-de73-4c4a-aa9e-c06d55c6fa8810=031
20250411-01:34:45.692309000 : 8=FIXT.1.19=32735=X49=Coinbase56=24ab46f784d1b20db435b852086e325034=20950=TEST52=20250411-01:34:45.566412369=45262=7a00f5f8-0c9f-4483-8ca5-754a13a8781d268=1279=0269=2278=c5b88ea9-605d-4595-ac52-f7c3f08523ba83=159755076255=BTC-USD270=3.55271=0.6222240960=20250411-01:34:45.56485037=299e56ba-de73-4c4a-aa9e-c06d55c6fa885797=110=173
20250411-01:34:45.693026000 : 8=FIXT.1.19=26635=X49=Coinbase56=24ab46f784d1b20db435b852086e325034=21050=TEST52=20250411-01:34:45.566416369=45262=7a00f5f8-0c9f-4483-8ca5-754a13a8781d268=1279=2269=0278=299e56ba-de73-4c4a-aa9e-c06d55c6fa8883=159755076355=BTC-USD60=20250411-01:34:45.56485058=FILLED10=037
20250411-01:34:45.714958000 : 8=FIXT.1.19=27535=X49=Coinbase56=24ab46f784d1b20db435b852086e325034=21150=TEST52=20250411-01:34:45.594760369=45262=7a00f5f8-0c9f-4483-8ca5-754a13a8781d268=1279=0269=183=159755076455=BTC-USD271=0.6197183160=20250411-01:34:45.59317240=137=62495b25-508a-4361-9e33-348c97afa0ba10=022
20250411-01:34:45.715275000 : 8=FIXT.1.19=32735=X49=Coinbase56=24ab46f784d1b20db435b852086e325034=21250=TEST52=20250411-01:34:45.594766369=45262=7a00f5f8-0c9f-4483-8ca5-754a13a8781d268=1279=0269=2278=4d60a78e-b39b-420e-b830-bc0f3f4fdde283=159755076555=BTC-USD270=3.53271=0.6197183160=20250411-01:34:45.59317237=62495b25-508a-4361-9e33-348c97afa0ba5797=210=017
20250411-01:34:45.715775000 : 8=FIXT.1.19=28135=X49=Coinbase56=24ab46f784d1b20db435b852086e325034=21350=TEST52=20250411-01:34:45.594795369=45262=7a00f5f8-0c9f-4483-8ca5-754a13a8781d268=1279=2269=1278=62495b25-508a-4361-9e33-348c97afa0ba83=159755076655=BTC-USD271=0.0000000060=20250411-01:34:45.59317258=FILLED10=188
20250411-01:34:45.743673000 : 8=FIXT.1.19=27935=X49=Coinbase56=24ab46f784d1b20db435b852086e325034=21450=TEST52=20250411-01:34:45.622353369=45262=7a00f5f8-0c9f-4483-8ca5-754a13a8781d268=1279=0269=083=159755076755=BTC-USD29004=2.208895519560=20250411-01:34:45.62077140=137=231b2709-64e4-4618-99b4-87d448c3a8e610=157
20250411-01:34:45.744011000 : 8=FIXT.1.19=32735=X49=Coinbase56=24ab46f784d1b20db435b852086e325034=21550=TEST52=20250411-01:34:45.622443369=45262=7a00f5f8-0c9f-4483-8ca5-754a13a8781d268=1279=0269=2278=c5b88ea9-605d-4595-ac52-f7c3f08523ba83=159755076855=BTC-USD270=3.55271=0.6222240960=20250411-01:34:45.62077137=231b2709-64e4-4618-99b4-87d448c3a8e65797=110=048
20250411-01:34:45.744205000 : 8=FIXT.1.19=26635=X49=Coinbase56=24ab46f784d1b20db435b852086e325034=21650=TEST52=20250411-01:34:45.622491369=45262=7a00f5f8-0c9f-4483-8ca5-754a13a8781d268=1279=2269=0278=231b2709-64e4-4618-99b4-87d448c3a8e683=159755076955=BTC-USD60=20250411-01:34:45.62077158=FILLED10=176
20250411-01:34:45.771672000 : 8=FIXT.1.19=27535=X49=Coinbase56=24ab46f784d1b20db435b852086e325034=21750=TEST52=20250411-01:34:45.651072369=45262=7a00f5f8-0c9f-4483-8ca5-754a13a8781d268=1279=0269=183=159755077055=BTC-USD271=0.6197183160=20250411-01:34:45.64987940=137=bdc82398-9171-48dc-afd3-5cbb8a06bde310=066
20250411-01:34:45.772265000 : 8=FIXT.1.19=32735=X49=Coinbase56=24ab46f784d1b20db435b852086e325034=21850=TEST52=20250411-01:34:45.651077369=45262=7a00f5f8-0c9f-4483-8ca5-754a13a8781d268=1279=0269=2278=4d60a78e-b39b-420e-b830-bc0f3f4fdde283=159755077155=BTC-USD270=3.53271=0.6197183160=20250411-01:34:45.64987937=bdc82398-9171-48dc-afd3-5cbb8a06bde35797=210=060
20250411-01:34:45.772474000 : 8=FIXT.1.19=28135=X49=Coinbase56=24ab46f784d1b20db435b852086e325034=21950=TEST52=20250411-01:34:45.651080369=45262=7a00f5f8-0c9f-4483-8ca5-754a13a8781d268=1279=2269=1278=bdc82398-9171-48dc-afd3-5cbb8a06bde383=159755077255=BTC-USD271=0.0000000060=20250411-01:34:45.64987958=FILLED10=223
20250411-01:34:45.857628000 : 8=FIXT.1.19=27935=X49=Coinbase56=24ab46f784d1b20db435b852086e325034=22050=TEST52=20250411-01:34:45.736904369=45262=7a00f5f8-0c9f-4483-8ca5-754a13a8781d268=1279=0269=083=159755077355=BTC-USD29004=2.208895519560=20250411-01:34:45.73487140=137=842c8b07-8238-4a96-a36d-0c9d8bdd449110=046
20250411-01:34:45.858213000 : 8=FIXT.1.19=32735=X49=Coinbase56=24ab46f784d1b20db435b852086e325034=22150=TEST52=20250411-01:34:45.736912369=45262=7a00f5f8-0c9f-4483-8ca5-754a13a8781d268=1279=0269=2278=c5b88ea9-605d-4595-ac52-f7c3f08523ba83=159755077455=BTC-USD270=3.55271=0.6222240960=20250411-01:34:45.73487137=842c8b07-8238-4a96-a36d-0c9d8bdd44915797=110=192
20250411-01:34:45.858435000 : 8=FIXT.1.19=26635=X49=Coinbase56=24ab46f784d1b20db435b852086e325034=22250=TEST52=20250411-01:34:45.736915369=45262=7a00f5f8-0c9f-4483-8ca5-754a13a8781d268=1279=2269=0278=842c8b07-8238-4a96-a36d-0c9d8bdd449183=159755077555=BTC-USD60=20250411-01:34:45.73487158=FILLED10=064
20250411-01:34:45.885781000 : 8=FIXT.1.19=27535=X49=Coinbase56=24ab46f784d1b20db435b852086e325034=22350=TEST52=20250411-01:34:45.765148369=45262=7a00f5f8-0c9f-4483-8ca5-754a13a8781d268=1279=0269=183=159755077655=BTC-USD271=0.6232294660=20250411-01:34:45.76387740=137=f11c3a82-7242-42f7-a88c-beb244fc3ad010=216
20250411-01:34:45.886212000 : 8=FIXT.1.19=32735=X49=Coinbase56=24ab46f784d1b20db435b852086e325034=22450=TEST52=20250411-01:34:45.765157369=45262=7a00f5f8-0c9f-4483-8ca5-754a13a8781d268=1279=0269=2278=4d60a78e-b39b-420e-b830-bc0f3f4fdde283=159755077755=BTC-USD270=3.53271=0.6232294660=20250411-01:34:45.76387737=f11c3a82-7242-42f7-a88c-beb244fc3ad05797=210=205
20250411-01:34:45.886482000 : 8=FIXT.1.19=28135=X49=Coinbase56=24ab46f784d1b20db435b852086e325034=22550=TEST52=20250411-01:34:45.765159369=45262=7a00f5f8-0c9f-4483-8ca5-754a13a8781d268=1279=2269=1278=f11c3a82-7242-42f7-a88c-beb244fc3ad083=159755077855=BTC-USD271=0.0000000060=20250411-01:34:45.76387758=FILLED10=122
20250411-01:34:46.486106000 : 8=FIXT.1.19=27935=X49=Coinbase56=24ab46f784d1b20db435b852086e325034=22650=TEST52=20250411-01:34:46.365680369=45262=7a00f5f8-0c9f-4483-8ca5-754a13a8781d268=1279=0269=083=159755077955=BTC-USD29004=2.208895519560=20250411-01:34:46.36380540=137=c73dadc2-d32d-4f6a-85d0-17801bb4a85e10=223
20250411-01:34:46.486669000 : 8=FIXT.1.19=32735=X49=Coinbase56=24ab46f784d1b20db435b852086e325034=22750=TEST52=20250411-01:34:46.365688369=45262=7a00f5f8-0c9f-4483-8ca5-754a13a8781d268=1279=0269=2278=c5b88ea9-605d-4595-ac52-f7c3f08523ba83=159755078055=BTC-USD270=3.55271=0.6222240960=20250411-01:34:46.36380537=c73dadc2-d32d-4f6a-85d0-17801bb4a85e5797=110=113
20250411-01:34:46.486883000 : 8=FIXT.1.19=26635=X49=Coinbase56=24ab46f784d1b20db435b852086e325034=22850=TEST52=20250411-01:34:46.365693369=45262=7a00f5f8-0c9f-4483-8ca5-754a13a8781d268=1279=2269=0278=c73dadc2-d32d-4f6a-85d0-17801bb4a85e83=159755078155=BTC-USD60=20250411-01:34:46.36380558=FILLED10=234
20250411-01:34:46.514841000 : 8=FIXT.1.19=27535=X49=Coinbase56=24ab46f784d1b20db435b852086e325034=22950=TEST52=20250411-01:34:46.394051369=45262=7a00f5f8-0c9f-4483-8ca5-754a13a8781d268=1279=0269=183=159755078255=BTC-USD271=0.6232294660=20250411-01:34:46.39194540=137=28e82ff2-abd4-4cb4-b17d-77d0a4be12b410=046
20250411-01:34:46.515482000 : 8=FIXT.1.19=32735=X49=Coinbase56=24ab46f784d1b20db435b852086e325034=23050=TEST52=20250411-01:34:46.394058369=45262=7a00f5f8-0c9f-4483-8ca5-754a13a8781d268=1279=0269=2278=4d60a78e-b39b-420e-b830-bc0f3f4fdde283=159755078355=BTC-USD270=3.53271=0.6232294660=20250411-01:34:46.39194537=28e82ff2-abd4-4cb4-b17d-77d0a4be12b45797=210=033
20250411-01:34:46.515675000 : 8=FIXT.1.19=28135=X49=Coinbase56=24ab46f784d1b20db435b852086e325034=23150=TEST52=20250411-01:34:46.394061369=45262=7a00f5f8-0c9f-4483-8ca5-754a13a8781d268=1279=2269=1278=28e82ff2-abd4-4cb4-b17d-77d0a4be12b483=159755078455=BTC-USD271=0.0000000060=20250411-01:34:46.39194558=FILLED10=198
20250411-01:34:46.813821000 : 8=FIXT.1.19=27935=X49=Coinbase56=24ab46f784d1b20db435b852086e325034=23250=TEST52=20250411-01:34:46.650707369=45262=7a00f5f8-0c9f-4483-8ca5-754a13a8781d268=1279=0269=083=159755078555=BTC-USD29004=2.208895519560=20250411-01:34:46.64894540=137=839bb12d-c567-43b2-9b55-127065c22b9b10=248
20250411-01:34:46.814402000 : 8=FIXT.1.19=32735=X49=Coinbase56=24ab46f784d1b20db435b852086e325034=23350=TEST52=20250411-01:34:46.650715369=45262=7a00f5f8-0c9f-4483-8ca5-754a13a8781d268=1279=0269=2278=c5b88ea9-605d-4595-ac52-f7c3f08523ba83=159755078655=BTC-USD270=3.55271=0.6222240960=20250411-01:34:46.64894537=839bb12d-c567-43b2-9b55-127065c22b9b5797=110=138
20250411-01:34:46.814618000 : 8=FIXT.1.19=26635=X49=Coinbase56=24ab46f784d1b20db435b852086e325034=23450=TEST52=20250411-01:34:46.650718369=45262=7a00f5f8-0c9f-4483-8ca5-754a13a8781d268=1279=2269=0278=839bb12d-c567-43b2-9b55-127065c22b9b83=159755078755=BTC-USD60=20250411-01:34:46.64894558=FILLED10=010
20250411-01:34:46.814937000 : 8=FIXT.1.19=27535=X49=Coinbase56=24ab46f784d1b20db435b852086e325034=23550=TEST52=20250411-01:34:46.681126369=45262=7a00f5f8-0c9f-4483-8ca5-754a13a8781d268=1279=0269=183=159755078855=BTC-USD271=0.6232294660=20250411-01:34:46.67951540=137=27bd02bf-0b47-471c-8c3e-d73622b759da10=173
20250411-01:34:46.815936000 : 8=FIXT.1.19=32735=X49=Coinbase56=24ab46f784d1b20db435b852086e325034=23650=TEST52=20250411-01:34:46.681135369=45262=7a00f5f8-0c9f-4483-8ca5-754a13a8781d268=1279=0269=2278=4d60a78e-b39b-420e-b830-bc0f3f4fdde283=159755078955=BTC-USD270=3.53271=0.6232294660=20250411-01:34:46.67951537=27bd02bf-0b47-471c-8c3e-d73622b759da5797=210=162
20250411-01:34:46.816232000 : 8=FIXT.1.19=28135=X49=Coinbase56=24ab46f784d1b20db435b852086e325034=23750=TEST52=20250411-01:34:46.681139369=45262=7a00f5f8-0c9f-4483-8ca5-754a13a8781d268=1279=2269=1278=27bd02bf-0b47-471c-8c3e-d73622b759da83=159755079055=BTC-USD271=0.0000000060=20250411-01:34:46.67951558=FILLED10=072
20250411-01:34:47.018639000 : 8=FIXT.1.19=27935=X49=Coinbase56=24ab46f784d1b20db435b852086e325034=23850=TEST52=20250411-01:34:46.821615369=45262=7a00f5f8-0c9f-4483-8ca5-754a13a8781d268=1279=0269=083=159755079155=BTC-USD29004=2.208895519560=20250411-01:34:46.82026140=137=2d2f27ee-13d3-4bdc-9990-945ba5c6b11110=119
20250411-01:34:47.019422000 : 8=FIXT.1.19=32735=X49=Coinbase56=24ab46f784d1b20db435b852086e325034=23950=TEST52=20250411-01:34:46.821629369=45262=7a00f5f8-0c9f-4483-8ca5-754a13a8781d268=1279=0269=2278=c5b88ea9-605d-4595-ac52-f7c3f08523ba83=159755079255=BTC-USD270=3.55271=0.6222240960=20250411-01:34:46.82026137=2d2f27ee-13d3-4bdc-9990-945ba5c6b1115797=110=015
20250411-01:34:47.020001000 : 8=FIXT.1.19=26635=X49=Coinbase56=24ab46f784d1b20db435b852086e325034=24050=TEST52=20250411-01:34:46.821647369=45262=7a00f5f8-0c9f-4483-8ca5-754a13a8781d268=1279=2269=0278=2d2f27ee-13d3-4bdc-9990-945ba5c6b11183=159755079355=BTC-USD60=20250411-01:34:46.82026158=FILLED10=131
20250411-01:34:47.023461000 : 8=FIXT.1.19=27535=X49=Coinbase56=24ab46f784d1b20db435b852086e325034=24150=TEST52=20250411-01:34:46.851904369=45262=7a00f5f8-0c9f-4483-8ca5-754a13a8781d268=1279=0269=183=159755079455=BTC-USD271=0.6232294660=20250411-01:34:46.85017840=137=64ef0a49-8b8b-4aae-800a-bbe810a959f910=014
20250411-01:34:47.023949000 : 8=FIXT.1.19=32735=X49=Coinbase56=24ab46f784d1b20db435b852086e325034=24250=TEST52=20250411-01:34:46.851911369=45262=7a00f5f8-0c9f-4483-8ca5-754a13a8781d268=1279=0269=2278=4d60a78e-b39b-420e-b830-bc0f3f4fdde283=159755079555=BTC-USD270=3.53271=0.6232294660=20250411-01:34:46.85017837=64ef0a49-8b8b-4aae-800a-bbe810a959f95797=210=001
20250411-01:34:47.026226000 : 8=FIXT.1.19=28135=X49=Coinbase56=24ab46f784d1b20db435b852086e325034=24350=TEST52=20250411-01:34:46.851912369=45262=7a00f5f8-0c9f-4483-8ca5-754a13a8781d268=1279=2269=1278=64ef0a49-8b8b-4aae-800a-bbe810a959f983=159755079655=BTC-USD271=0.0000000060=20250411-01:34:46.85017858=FILLED10=173
20250411-01:34:47.430016000 : 8=FIXT.1.19=27935=X49=Coinbase56=24ab46f784d1b20db435b852086e325034=24450=TEST52=20250411-01:34:47.221943369=45262=7a00f5f8-0c9f-4483-8ca5-754a13a8781d268=1279=0269=083=159755079755=BTC-USD29004=2.208895519560=20250411-01:34:47.22081640=137=e3aad46e-12ff-42b5-8eda-91adb680ed1210=052
20250411-01:34:47.430808000 : 8=FIXT.1.19=32735=X49=Coinbase56=24ab46f784d1b20db435b852086e325034=24550=TEST52=20250411-01:34:47.221950369=45262=7a00f5f8-0c9f-4483-8ca5-754a13a8781d268=1279=0269=2278=c5b88ea9-605d-4595-ac52-f7c3f08523ba83=159755079855=BTC-USD270=3.55271=0.6222240960=20250411-01:34:47.22081637=e3aad46e-12ff-42b5-8eda-91adb680ed125797=110=197
20250411-01:34:47.432284000 : 8=FIXT.1.19=26635=X49=Coinbase56=24ab46f784d1b20db435b852086e325034=24650=TEST52=20250411-01:34:47.221983369=45262=7a00f5f8-0c9f-4483-8ca5-754a13a8781d268=1279=2269=0278=e3aad46e-12ff-42b5-8eda-91adb680ed1283=159755079955=BTC-USD60=20250411-01:34:47.22081658=FILLED10=072
20250411-01:34:47.433269000 : 8=FIXT.1.19=27535=X49=Coinbase56=24ab46f784d1b20db435b852086e325034=24750=TEST52=20250411-01:34:47.251552369=45262=7a00f5f8-0c9f-4483-8ca5-754a13a8781d268=1279=0269=183=159755080055=BTC-USD271=0.6232294660=20250411-01:34:47.25000440=137=3e976a93-c3a9-4448-be4f-f5d995ac8b8510=174
20250411-01:34:47.434441000 : 8=FIXT.1.19=32735=X49=Coinbase56=24ab46f784d1b20db435b852086e325034=24850=TEST52=20250411-01:34:47.251565369=45262=7a00f5f8-0c9f-4483-8ca5-754a13a8781d268=1279=0269=2278=4d60a78e-b39b-420e-b830-bc0f3f4fdde283=159755080155=BTC-USD270=3.53271=0.6232294660=20250411-01:34:47.25000437=3e976a93-c3a9-4448-be4f-f5d995ac8b855797=210=167
20250411-01:34:47.435528000 : 8=FIXT.1.19=28135=X49=Coinbase56=24ab46f784d1b20db435b852086e325034=24950=TEST52=20250411-01:34:47.251568369=45262=7a00f5f8-0c9f-4483-8ca5-754a13a8781d268=1279=2269=1278=3e976a93-c3a9-4448-be4f-f5d995ac8b8583=159755080255=BTC-USD271=0.0000000060=20250411-01:34:47.25000458=FILLED10=085
20250411-01:34:47.542234000 : 8=FIXT.1.19=28435=X49=Coinbase56=24ab46f784d1b20db435b852086e325034=25050=TEST52=20250411-01:34:47.421856369=45262=7a00f5f8-0c9f-4483-8ca5-754a13a8781d268=1279=0269=183=159755080355=BTC-USD270=3.56271=0.6232294660=20250411-01:34:47.41993040=237=c1b79834-dc7b-4f7e-8b98-30104e9906d810=250
20250411-01:34:47.542880000 : 8=FIXT.1.19=28035=X49=Coinbase56=24ab46f784d1b20db435b852086e325034=25150=TEST52=20250411-01:34:47.421864369=45262=7a00f5f8-0c9f-4483-8ca5-754a13a8781d268=1279=0269=1278=c1b79834-dc7b-4f7e-8b98-30104e9906d883=159755080455=BTC-USD270=3.56271=0.6232294660=20250411-01:34:47.41993010=090
20250411-01:34:47.544225000 : 8=FIXT.1.19=28435=X49=Coinbase56=24ab46f784d1b20db435b852086e325034=25250=TEST52=20250411-01:34:47.421866369=45262=7a00f5f8-0c9f-4483-8ca5-754a13a8781d268=1279=0269=183=159755080555=BTC-USD270=3.61271=0.6232294660=20250411-01:34:47.41993040=237=86ef6a57-3e2c-4c6b-a6f1-813a4637861510=239
20250411-01:34:47.544438000 : 8=FIXT.1.19=28035=X49=Coinbase56=24ab46f784d1b20db435b852086e325034=25350=TEST52=20250411-01:34:47.421867369=45262=7a00f5f8-0c9f-4483-8ca5-754a13a8781d268=1279=0269=1278=86ef6a57-3e2c-4c6b-a6f1-813a4637861583=159755080655=BTC-USD270=3.61271=0.6232294660=20250411-01:34:47.41993010=081
20250411-01:34:47.628553000 : 8=FIXT.1.19=27935=X49=Coinbase56=24ab46f784d1b20db435b852086e325034=25450=TEST52=20250411-01:34:47.507944369=45262=7a00f5f8-0c9f-4483-8ca5-754a13a8781d268=1279=0269=083=159755080755=BTC-USD29004=2.208895519560=20250411-01:34:47.50655140=137=016bea84-83d9-44e6-b161-9da1376c10b210=025
20250411-01:34:47.629075000 : 8=FIXT.1.19=32735=X49=Coinbase56=24ab46f784d1b20db435b852086e325034=25550=TEST52=20250411-01:34:47.507950369=45262=7a00f5f8-0c9f-4483-8ca5-754a13a8781d268=1279=0269=2278=c5b88ea9-605d-4595-ac52-f7c3f08523ba83=159755080855=BTC-USD270=3.55271=0.6222240960=20250411-01:34:47.50655137=016bea84-83d9-44e6-b161-9da1376c10b25797=110=169
20250411-01:34:47.629770000 : 8=FIXT.1.19=26635=X49=Coinbase56=24ab46f784d1b20db435b852086e325034=25650=TEST52=20250411-01:34:47.507978369=45262=7a00f5f8-0c9f-4483-8ca5-754a13a8781d268=1279=2269=0278=016bea84-83d9-44e6-b161-9da1376c10b283=159755080955=BTC-USD60=20250411-01:34:47.50655158=FILLED10=048
20250411-01:34:47.657697000 : 8=FIXT.1.19=27535=X49=Coinbase56=24ab46f784d1b20db435b852086e325034=25750=TEST52=20250411-01:34:47.536543369=45262=7a00f5f8-0c9f-4483-8ca5-754a13a8781d268=1279=0269=183=159755081055=BTC-USD271=0.6232294660=20250411-01:34:47.53532740=137=2fb25a47-8f34-4fb5-b35f-c831f4937d3310=124
20250411-01:34:47.658019000 : 8=FIXT.1.19=32735=X49=Coinbase56=24ab46f784d1b20db435b852086e325034=25850=TEST52=20250411-01:34:47.536550369=45262=7a00f5f8-0c9f-4483-8ca5-754a13a8781d268=1279=0269=2278=4d60a78e-b39b-420e-b830-bc0f3f4fdde283=159755081155=BTC-USD270=3.53271=0.6232294660=20250411-01:34:47.53532737=2fb25a47-8f34-4fb5-b35f-c831f4937d335797=210=111
20250411-01:34:47.658421000 : 8=FIXT.1.19=28135=X49=Coinbase56=24ab46f784d1b20db435b852086e325034=25950=TEST52=20250411-01:34:47.536583369=45262=7a00f5f8-0c9f-4483-8ca5-754a13a8781d268=1279=2269=1278=2fb25a47-8f34-4fb5-b35f-c831f4937d3383=159755081255=BTC-USD271=0.0000000060=20250411-01:34:47.53532758=FILLED10=032
20250411-01:34:47.743525000 : 8=FIXT.1.19=27935=X49=Coinbase56=24ab46f784d1b20db435b852086e325034=26050=TEST52=20250411-01:34:47.622790369=45262=7a00f5f8-0c9f-4483-8ca5-754a13a8781d268=1279=0269=083=159755081355=BTC-USD29004=2.208895519560=20250411-01:34:47.62081640=137=0b188232-ef05-4adc-9665-1341939d046110=135
20250411-01:34:47.743963000 : 8=FIXT.1.19=32735=X49=Coinbase56=24ab46f784d1b20db435b852086e325034=26150=TEST52=20250411-01:34:47.622797369=45262=7a00f5f8-0c9f-4483-8ca5-754a13a8781d268=1279=0269=2278=c5b88ea9-605d-4595-ac52-f7c3f08523ba83=159755081455=BTC-USD270=3.55271=0.6222240960=20250411-01:34:47.62081637=0b188232-ef05-4adc-9665-1341939d04615797=110=033
20250411-01:34:47.744343000 : 8=FIXT.1.19=26635=X49=Coinbase56=24ab46f784d1b20db435b852086e325034=26250=TEST52=20250411-01:34:47.622800369=45262=7a00f5f8-0c9f-4483-8ca5-754a13a8781d268=1279=2269=0278=0b188232-ef05-4adc-9665-1341939d046183=159755081555=BTC-USD60=20250411-01:34:47.62081658=FILLED10=143
20250411-01:34:47.772410000 : 8=FIXT.1.19=27535=X49=Coinbase56=24ab46f784d1b20db435b852086e325034=26350=TEST52=20250411-01:34:47.651158369=45262=7a00f5f8-0c9f-4483-8ca5-754a13a8781d268=1279=0269=183=159755081655=BTC-USD271=0.6232294660=20250411-01:34:47.64933340=137=c22f2d3e-d2e2-479c-9e5d-213644930d6610=079
20250411-01:34:47.772733000 : 8=FIXT.1.19=32735=X49=Coinbase56=24ab46f784d1b20db435b852086e325034=26450=TEST52=20250411-01:34:47.651164369=45262=7a00f5f8-0c9f-4483-8ca5-754a13a8781d268=1279=0269=2278=4d60a78e-b39b-420e-b830-bc0f3f4fdde283=159755081755=BTC-USD270=3.53271=0.6232294660=20250411-01:34:47.64933337=c22f2d3e-d2e2-479c-9e5d-213644930d665797=210=065
20250411-01:34:47.773008000 : 8=FIXT.1.19=28135=X49=Coinbase56=24ab46f784d1b20db435b852086e325034=26550=TEST52=20250411-01:34:47.651166369=45262=7a00f5f8-0c9f-4483-8ca5-754a13a8781d268=1279=2269=1278=c22f2d3e-d2e2-479c-9e5d-213644930d6683=159755081855=BTC-USD271=0.0000000060=20250411-01:34:47.64933358=FILLED10=238
20250411-01:34:47.787197000 : 8=FIXT.1.19=28435=X49=Coinbase56=24ab46f784d1b20db435b852086e325034=26650=TEST52=20250411-01:34:47.667822369=45262=7a00f5f8-0c9f-4483-8ca5-754a13a8781d268=1279=0269=083=159755081955=BTC-USD270=3.78271=0.6232294660=20250411-01:34:47.66655240=237=7aab8a47-8ea6-4e6a-ae29-36cf14aeb86410=242
20250411-01:34:47.787597000 : 8=FIXT.1.19=32735=X49=Coinbase56=24ab46f784d1b20db435b852086e325034=26750=TEST52=20250411-01:34:47.667826369=45262=7a00f5f8-0c9f-4483-8ca5-754a13a8781d268=1279=0269=2278=c5b88ea9-605d-4595-ac52-f7c3f08523ba83=159755082055=BTC-USD270=3.55271=0.6232294660=20250411-01:34:47.66655237=7aab8a47-8ea6-4e6a-ae29-36cf14aeb8645797=110=188
20250411-01:34:47.787937000 : 8=FIXT.1.19=29035=X49=Coinbase56=24ab46f784d1b20db435b852086e325034=26850=TEST52=20250411-01:34:47.667829369=45262=7a00f5f8-0c9f-4483-8ca5-754a13a8781d268=1279=2269=0278=7aab8a47-8ea6-4e6a-ae29-36cf14aeb86483=159755082155=BTC-USD270=3.78271=0.0000000060=20250411-01:34:47.66655258=FILLED10=143
20250411-01:34:47.843969000 : 8=FIXT.1.19=28435=X49=Coinbase56=24ab46f784d1b20db435b852086e325034=26950=TEST52=20250411-01:34:47.723328369=45262=7a00f5f8-0c9f-4483-8ca5-754a13a8781d268=1279=0269=183=159755082255=BTC-USD270=3.23271=0.6232294660=20250411-01:34:47.72181540=237=80943bee-6328-43f8-9089-1b4e5dee222b10=242
20250411-01:34:47.844522000 : 8=FIXT.1.19=32735=X49=Coinbase56=24ab46f784d1b20db435b852086e325034=27050=TEST52=20250411-01:34:47.723335369=45262=7a00f5f8-0c9f-4483-8ca5-754a13a8781d268=1279=0269=2278=4d60a78e-b39b-420e-b830-bc0f3f4fdde283=159755082355=BTC-USD270=3.53271=0.6232294660=20250411-01:34:47.72181537=80943bee-6328-43f8-9089-1b4e5dee222b5797=210=062
20250411-01:34:47.845637000 : 8=FIXT.1.19=29035=X49=Coinbase56=24ab46f784d1b20db435b852086e325034=27150=TEST52=20250411-01:34:47.723338369=45262=7a00f5f8-0c9f-4483-8ca5-754a13a8781d268=1279=2269=1278=80943bee-6328-43f8-9089-1b4e5dee222b83=159755082455=BTC-USD270=3.23271=0.0000000060=20250411-01:34:47.72181558=FILLED10=137
20250411-01:34:47.914011000 : 8=FIXT.1.19=27935=X49=Coinbase56=24ab46f784d1b20db435b852086e325034=27250=TEST52=20250411-01:34:47.793808369=45262=7a00f5f8-0c9f-4483-8ca5-754a13a8781d268=1279=0269=083=159755082555=BTC-USD29004=2.208895519560=20250411-01:34:47.79230740=137=dabea334-f4b3-4e40-b32d-aebdade18d2610=151
20250411-01:34:47.914490000 : 8=FIXT.1.19=32735=X49=Coinbase56=24ab46f784d1b20db435b852086e325034=27350=TEST52=20250411-01:34:47.793816369=45262=7a00f5f8-0c9f-4483-8ca5-754a13a8781d268=1279=0269=2278=c5b88ea9-605d-4595-ac52-f7c3f08523ba83=159755082655=BTC-USD270=3.55271=0.6222240960=20250411-01:34:47.79230737=dabea334-f4b3-4e40-b32d-aebdade18d265797=110=041
20250411-01:34:47.914728000 : 8=FIXT.1.19=26635=X49=Coinbase56=24ab46f784d1b20db435b852086e325034=27450=TEST52=20250411-01:34:47.793820369=45262=7a00f5f8-0c9f-4483-8ca5-754a13a8781d268=1279=2269=0278=dabea334-f4b3-4e40-b32d-aebdade18d2683=159755082755=BTC-USD60=20250411-01:34:47.79230758=FILLED10=161
20250411-01:34:47.944062000 : 8=FIXT.1.19=27535=X49=Coinbase56=24ab46f784d1b20db435b852086e325034=27550=TEST52=20250411-01:34:47.822369369=45262=7a00f5f8-0c9f-4483-8ca5-754a13a8781d268=1279=0269=183=159755082855=BTC-USD271=0.6232294660=20250411-01:34:47.82120140=137=1c788c10-baa5-41be-a299-b7c12084821c10=103
20250411-01:34:47.945648000 : 8=FIXT.1.19=32735=X49=Coinbase56=24ab46f784d1b20db435b852086e325034=27650=TEST52=20250411-01:34:47.822393369=45262=7a00f5f8-0c9f-4483-8ca5-754a13a8781d268=1279=0269=2278=4d60a78e-b39b-420e-b830-bc0f3f4fdde283=159755082955=BTC-USD270=3.53271=0.6232294660=20250411-01:34:47.82120137=1c788c10-baa5-41be-a299-b7c12084821c5797=210=089
20250411-01:34:47.946239000 : 8=FIXT.1.19=28135=X49=Coinbase56=24ab46f784d1b20db435b852086e325034=27750=TEST52=20250411-01:34:47.822433369=45262=7a00f5f8-0c9f-4483-8ca5-754a13a8781d268=1279=2269=1278=1c788c10-baa5-41be-a299-b7c12084821c83=159755083055=BTC-USD271=0.0000000060=20250411-01:34:47.82120158=FILLED10=246
20250411-01:34:48.112292000 : 8=FIXT.1.19=28435=X49=Coinbase56=24ab46f784d1b20db435b852086e325034=27850=TEST52=20250411-01:34:47.991236369=45262=7a00f5f8-0c9f-4483-8ca5-754a13a8781d268=1279=0269=083=159755083155=BTC-USD270=3.52271=0.6232294660=20250411-01:34:47.99004440=237=a05216be-9cef-43f0-95d3-145c06c08c5e10=071
20250411-01:34:48.113501000 : 8=FIXT.1.19=28035=X49=Coinbase56=24ab46f784d1b20db435b852086e325034=27950=TEST52=20250411-01:34:47.991243369=45262=7a00f5f8-0c9f-4483-8ca5-754a13a8781d268=1279=0269=0278=a05216be-9cef-43f0-95d3-145c06c08c5e83=159755083255=BTC-USD270=3.52271=0.6232294660=20250411-01:34:47.99004410=166
20250411-01:34:48.113794000 : 8=FIXT.1.19=28435=X49=Coinbase56=24ab46f784d1b20db435b852086e325034=28050=TEST52=20250411-01:34:47.991245369=45262=7a00f5f8-0c9f-4483-8ca5-754a13a8781d268=1279=0269=083=159755083355=BTC-USD270=3.43271=0.6232294660=20250411-01:34:47.99004440=237=353ef4a4-365a-43a3-aca5-38b00e85544010=215
20250411-01:34:48.114087000 : 8=FIXT.1.19=28035=X49=Coinbase56=24ab46f784d1b20db435b852086e325034=28150=TEST52=20250411-01:34:47.991299369=45262=7a00f5f8-0c9f-4483-8ca5-754a13a8781d268=1279=0269=0278=353ef4a4-365a-43a3-aca5-38b00e85544083=159755083455=BTC-USD270=3.43271=0.6232294660=20250411-01:34:47.99004410=065
20250411-01:34:48.289896000 : 8=FIXT.1.19=28435=X49=Coinbase56=24ab46f784d1b20db435b852086e325034=28250=TEST52=20250411-01:34:48.167448369=45262=7a00f5f8-0c9f-4483-8ca5-754a13a8781d268=1279=0269=183=159755083555=BTC-USD270=3.55271=0.6232294660=20250411-01:34:48.16561140=237=d08bb7a6-33e2-4882-814d-7bb0629d6f6b10=034
20250411-01:34:48.290376000 : 8=FIXT.1.19=28035=X49=Coinbase56=24ab46f784d1b20db435b852086e325034=28350=TEST52=20250411-01:34:48.167452369=45262=7a00f5f8-0c9f-4483-8ca5-754a13a8781d268=1279=0269=1278=d08bb7a6-33e2-4882-814d-7bb0629d6f6b83=159755083655=BTC-USD270=3.55271=0.6232294660=20250411-01:34:48.16561110=126
20250411-01:34:48.542820000 : 8=FIXT.1.19=27935=X49=Coinbase56=24ab46f784d1b20db435b852086e325034=28450=TEST52=20250411-01:34:48.421753369=45262=7a00f5f8-0c9f-4483-8ca5-754a13a8781d268=1279=0269=083=159755083755=BTC-USD29004=2.208895519560=20250411-01:34:48.42020940=137=98466b0a-debe-4dbe-a644-8b67b2afe34410=018
20250411-01:34:48.543737000 : 8=FIXT.1.19=32735=X49=Coinbase56=24ab46f784d1b20db435b852086e325034=28550=TEST52=20250411-01:34:48.421761369=45262=7a00f5f8-0c9f-4483-8ca5-754a13a8781d268=1279=0269=2278=c5b88ea9-605d-4595-ac52-f7c3f08523ba83=159755083855=BTC-USD270=3.55271=0.6222240960=20250411-01:34:48.42020937=98466b0a-debe-4dbe-a644-8b67b2afe3445797=110=164
20250411-01:34:48.544390000 : 8=FIXT.1.19=26635=X49=Coinbase56=24ab46f784d1b20db435b852086e325034=28650=TEST52=20250411-01:34:48.421764369=45262=7a00f5f8-0c9f-4483-8ca5-754a13a8781d268=1279=2269=0278=98466b0a-debe-4dbe-a644-8b67b2afe34483=159755083955=BTC-USD60=20250411-01:34:48.42020958=FILLED10=036
20250411-01:34:48.571972000 : 8=FIXT.1.19=27535=X49=Coinbase56=24ab46f784d1b20db435b852086e325034=28750=TEST52=20250411-01:34:48.451136369=45262=7a00f5f8-0c9f-4483-8ca5-754a13a8781d268=1279=0269=183=159755084055=BTC-USD271=0.6232294660=20250411-01:34:48.44925740=137=f25072a9-fb5f-44f5-859c-0d0de65fee9210=237
20250411-01:34:48.572768000 : 8=FIXT.1.19=32735=X49=Coinbase56=24ab46f784d1b20db435b852086e325034=28850=TEST52=20250411-01:34:48.451143369=45262=7a00f5f8-0c9f-4483-8ca5-754a13a8781d268=1279=0269=2278=4d60a78e-b39b-420e-b830-bc0f3f4fdde283=159755084155=BTC-USD270=3.53271=0.6232294660=20250411-01:34:48.44925737=f25072a9-fb5f-44f5-859c-0d0de65fee925797=210=224
20250411-01:34:48.573267000 : 8=FIXT.1.19=28135=X49=Coinbase56=24ab46f784d1b20db435b852086e325034=28950=TEST52=20250411-01:34:48.451145369=45262=7a00f5f8-0c9f-4483-8ca5-754a13a8781d268=1279=2269=1278=f25072a9-fb5f-44f5-859c-0d0de65fee9283=159755084255=BTC-USD271=0.0000000060=20250411-01:34:48.44925758=FILLED10=141
20250411-01:34:48.588470000 : 8=FIXT.1.19=28435=X49=Coinbase56=24ab46f784d1b20db435b852086e325034=29050=TEST52=20250411-01:34:48.467748369=45262=7a00f5f8-0c9f-4483-8ca5-754a13a8781d268=1279=0269=183=159755084355=BTC-USD270=3.27271=0.6232294660=20250411-01:34:48.46657740=237=3b0241b9-eee6-4298-8d2e-7be8dc45044d10=102
20250411-01:34:48.589160000 : 8=FIXT.1.19=32735=X49=Coinbase56=24ab46f784d1b20db435b852086e325034=29150=TEST52=20250411-01:34:48.467754369=45262=7a00f5f8-0c9f-4483-8ca5-754a13a8781d268=1279=0269=2278=4d60a78e-b39b-420e-b830-bc0f3f4fdde283=159755084455=BTC-USD270=3.53271=0.6232294660=20250411-01:34:48.46657737=3b0241b9-eee6-4298-8d2e-7be8dc45044d5797=210=182
20250411-01:34:48.590364000 : 8=FIXT.1.19=29035=X49=Coinbase56=24ab46f784d1b20db435b852086e325034=29250=TEST52=20250411-01:34:48.467756369=45262=7a00f5f8-0c9f-4483-8ca5-754a13a8781d268=1279=2269=1278=3b0241b9-eee6-4298-8d2e-7be8dc45044d83=159755084555=BTC-USD270=3.27271=0.0000000060=20250411-01:34:48.46657758=FILLED10=004
20250411-01:34:48.643753000 : 8=FIXT.1.19=28435=X49=Coinbase56=24ab46f784d1b20db435b852086e325034=29350=TEST52=20250411-01:34:48.523880369=45262=7a00f5f8-0c9f-4483-8ca5-754a13a8781d268=1279=0269=083=159755084655=BTC-USD270=3.82271=0.6232294660=20250411-01:34:48.52263740=237=b27dcea6-416d-48c6-acb0-5ee631ee815310=172
20250411-01:34:48.644209000 : 8=FIXT.1.19=32735=X49=Coinbase56=24ab46f784d1b20db435b852086e325034=29450=TEST52=20250411-01:34:48.523888369=45262=7a00f5f8-0c9f-4483-8ca5-754a13a8781d268=1279=0269=2278=c5b88ea9-605d-4595-ac52-f7c3f08523ba83=159755084755=BTC-USD270=3.55271=0.6232294660=20250411-01:34:48.52263737=b27dcea6-416d-48c6-acb0-5ee631ee81535797=110=136
20250411-01:34:48.644466000 : 8=FIXT.1.19=29035=X49=Coinbase56=24ab46f784d1b20db435b852086e325034=29550=TEST52=20250411-01:34:48.523893369=45262=7a00f5f8-0c9f-4483-8ca5-754a13a8781d268=1279=2269=0278=b27dcea6-416d-48c6-acb0-5ee631ee815383=159755084855=BTC-USD270=3.82271=0.0000000060=20250411-01:34:48.52263758=FILLED10=079
20250411-01:34:48.658584000 : 8=FIXT.1.19=27935=X49=Coinbase56=24ab46f784d1b20db435b852086e325034=29650=TEST52=20250411-01:34:48.537223369=45262=7a00f5f8-0c9f-4483-8ca5-754a13a8781d268=1279=0269=083=159755084955=BTC-USD29004=2.208895519560=20250411-01:34:48.53529640=137=47afdb25-f40e-4aa9-85d1-f36bf4f07c8010=243
20250411-01:34:48.658880000 : 8=FIXT.1.19=32735=X49=Coinbase56=24ab46f784d1b20db435b852086e325034=29750=TEST52=20250411-01:34:48.537228369=45262=7a00f5f8-0c9f-4483-8ca5-754a13a8781d268=1279=0269=2278=c5b88ea9-605d-4595-ac52-f7c3f08523ba83=159755085055=BTC-USD270=3.55271=0.6222240960=20250411-01:34:48.53529637=47afdb25-f40e-4aa9-85d1-f36bf4f07c805797=110=130
20250411-01:34:48.659165000 : 8=FIXT.1.19=26635=X49=Coinbase56=24ab46f784d1b20db435b852086e325034=29850=TEST52=20250411-01:34:48.537232369=45262=7a00f5f8-0c9f-4483-8ca5-754a13a8781d268=1279=2269=0278=47afdb25-f40e-4aa9-85d1-f36bf4f07c8083=159755085155=BTC-USD60=20250411-01:34:48.53529658=FILLED10=250
20250411-01:34:48.685349000 : 8=FIXT.1.19=27535=X49=Coinbase56=24ab46f784d1b20db435b852086e325034=29950=TEST52=20250411-01:34:48.565158369=45262=7a00f5f8-0c9f-4483-8ca5-754a13a8781d268=1279=0269=183=159755085255=BTC-USD271=0.6232294660=20250411-01:34:48.56356340=137=9fb8bcf5-ecc6-4ad9-aa5f-1cd797c5369810=146
20250411-01:34:48.685739000 : 8=FIXT.1.19=32735=X49=Coinbase56=24ab46f784d1b20db435b852086e325034=30050=TEST52=20250411-01:34:48.565201369=45262=7a00f5f8-0c9f-4483-8ca5-754a13a8781d268=1279=0269=2278=4d60a78e-b39b-420e-b830-bc0f3f4fdde283=159755085355=BTC-USD270=3.53271=0.6232294660=20250411-01:34:48.56356337=9fb8bcf5-ecc6-4ad9-aa5f-1cd797c536985797=210=106
20250411-01:34:48.685940000 : 8=FIXT.1.19=28135=X49=Coinbase56=24ab46f784d1b20db435b852086e325034=30150=TEST52=20250411-01:34:48.565208369=45262=7a00f5f8-0c9f-4483-8ca5-754a13a8781d268=1279=2269=1278=9fb8bcf5-ecc6-4ad9-aa5f-1cd797c5369883=159755085455=BTC-USD271=0.0000000060=20250411-01:34:48.56356358=FILLED10=028
20250411-01:34:48.702588000 : 8=FIXT.1.19=28435=X49=Coinbase56=24ab46f784d1b20db435b852086e325034=30250=TEST52=20250411-01:34:48.582696369=45262=7a00f5f8-0c9f-4483-8ca5-754a13a8781d268=1279=0269=083=159755085555=BTC-USD270=3.74271=0.6232294660=20250411-01:34:48.58159240=237=ba79302b-c614-4efe-8118-76891b56d81b10=000
20250411-01:34:48.702857000 : 8=FIXT.1.19=32735=X49=Coinbase56=24ab46f784d1b20db435b852086e325034=30350=TEST52=20250411-01:34:48.582828369=45262=7a00f5f8-0c9f-4483-8ca5-754a13a8781d268=1279=0269=2278=c5b88ea9-605d-4595-ac52-f7c3f08523ba83=159755085655=BTC-USD270=3.55271=0.6232294660=20250411-01:34:48.58159237=ba79302b-c614-4efe-8118-76891b56d81b5797=110=208
20250411-01:34:48.703042000 : 8=FIXT.1.19=29035=X49=Coinbase56=24ab46f784d1b20db435b852086e325034=30450=TEST52=20250411-01:34:48.582829369=45262=7a00f5f8-0c9f-4483-8ca5-754a13a8781d268=1279=2269=0278=ba79302b-c614-4efe-8118-76891b56d81b83=159755085755=BTC-USD270=3.74271=0.0000000060=20250411-01:34:48.58159258=FILLED10=157
20250411-01:34:48.703215000 : 8=FIXT.1.19=28435=X49=Coinbase56=24ab46f784d1b20db435b852086e325034=30550=TEST52=20250411-01:34:48.582831369=45262=7a00f5f8-0c9f-4483-8ca5-754a13a8781d268=1279=0269=083=159755085855=BTC-USD270=3.85271=0.6232294660=20250411-01:34:48.58159240=237=7292ef04-09f2-44df-8697-719ee578954010=139
20250411-01:34:48.704248000 : 8=FIXT.1.19=32735=X49=Coinbase56=24ab46f784d1b20db435b852086e325034=30650=TEST52=20250411-01:34:48.582834369=45262=7a00f5f8-0c9f-4483-8ca5-754a13a8781d268=1279=0269=2278=c5b88ea9-605d-4595-ac52-f7c3f08523ba83=159755085955=BTC-USD270=3.55271=0.6232294660=20250411-01:34:48.58159237=7292ef04-09f2-44df-8697-719ee57895405797=110=095
20250411-01:34:48.704440000 : 8=FIXT.1.19=29035=X49=Coinbase56=24ab46f784d1b20db435b852086e325034=30750=TEST52=20250411-01:34:48.582836369=45262=7a00f5f8-0c9f-4483-8ca5-754a13a8781d268=1279=2269=0278=7292ef04-09f2-44df-8697-719ee578954083=159755086055=BTC-USD270=3.85271=0.0000000060=20250411-01:34:48.58159258=FILLED10=038
20250411-01:34:48.817445000 : 8=FIXT.1.19=28435=X49=Coinbase56=24ab46f784d1b20db435b852086e325034=30850=TEST52=20250411-01:34:48.697263369=45262=7a00f5f8-0c9f-4483-8ca5-754a13a8781d268=1279=0269=183=159755086155=BTC-USD270=3.34271=0.6232294660=20250411-01:34:48.69526840=237=46343281-21f5-4123-9ebd-928adfb7e82210=205
20250411-01:34:48.817969000 : 8=FIXT.1.19=32735=X49=Coinbase56=24ab46f784d1b20db435b852086e325034=30950=TEST52=20250411-01:34:48.697402369=45262=7a00f5f8-0c9f-4483-8ca5-754a13a8781d268=1279=0269=2278=4d60a78e-b39b-420e-b830-bc0f3f4fdde283=159755086255=BTC-USD270=3.53271=0.6232294660=20250411-01:34:48.69526837=46343281-21f5-4123-9ebd-928adfb7e8225797=210=029
20250411-01:34:48.818174000 : 8=FIXT.1.19=29035=X49=Coinbase56=24ab46f784d1b20db435b852086e325034=31050=TEST52=20250411-01:34:48.697406369=45262=7a00f5f8-0c9f-4483-8ca5-754a13a8781d268=1279=2269=1278=46343281-21f5-4123-9ebd-928adfb7e82283=159755086355=BTC-USD270=3.34271=0.0000000060=20250411-01:34:48.69526858=FILLED10=098
20250411-01:34:48.818702000 : 8=FIXT.1.19=28435=X49=Coinbase56=24ab46f784d1b20db435b852086e325034=31150=TEST52=20250411-01:34:48.697407369=45262=7a00f5f8-0c9f-4483-8ca5-754a13a8781d268=1279=0269=183=159755086455=BTC-USD270=3.24271=0.6232294660=20250411-01:34:48.69526840=237=06f32bb3-4244-4852-a4d6-6f180fe3ee8510=248
20250411-01:34:48.819806000 : 8=FIXT.1.19=32735=X49=Coinbase56=24ab46f784d1b20db435b852086e325034=31250=TEST52=20250411-01:34:48.697457369=45262=7a00f5f8-0c9f-4483-8ca5-754a13a8781d268=1279=0269=2278=4d60a78e-b39b-420e-b830-bc0f3f4fdde283=159755086555=BTC-USD270=3.53271=0.6232294660=20250411-01:34:48.69526837=06f32bb3-4244-4852-a4d6-6f180fe3ee855797=210=083
20250411-01:34:48.820015000 : 8=FIXT.1.19=29035=X49=Coinbase56=24ab46f784d1b20db435b852086e325034=31350=TEST52=20250411-01:34:48.697460369=45262=7a00f5f8-0c9f-4483-8ca5-754a13a8781d268=1279=2269=1278=06f32bb3-4244-4852-a4d6-6f180fe3ee8583=159755086655=BTC-USD270=3.24271=0.0000000060=20250411-01:34:48.69526858=FILLED10=150
20250411-01:34:49.001196000 : 8=FIXT.1.19=27935=X49=Coinbase56=24ab46f784d1b20db435b852086e325034=31450=TEST52=20250411-01:34:48.879595369=45262=7a00f5f8-0c9f-4483-8ca5-754a13a8781d268=1279=0269=083=159755086755=BTC-USD29004=2.208895519560=20250411-01:34:48.87762740=137=54bd74fc-2f0b-48ef-9e21-fa669dd4774510=232
20250411-01:34:49.001741000 : 8=FIXT.1.19=32735=X49=Coinbase56=24ab46f784d1b20db435b852086e325034=31550=TEST52=20250411-01:34:48.879605369=45262=7a00f5f8-0c9f-4483-8ca5-754a13a8781d268=1279=0269=2278=c5b88ea9-605d-4595-ac52-f7c3f08523ba83=159755086855=BTC-USD270=3.55271=0.6222240960=20250411-01:34:48.87762737=54bd74fc-2f0b-48ef-9e21-fa669dd477455797=110=115
20250411-01:34:49.001941000 : 8=FIXT.1.19=26635=X49=Coinbase56=24ab46f784d1b20db435b852086e325034=31650=TEST52=20250411-01:34:48.879608369=45262=7a00f5f8-0c9f-4483-8ca5-754a13a8781d268=1279=2269=0278=54bd74fc-2f0b-48ef-9e21-fa669dd4774583=159755086955=BTC-USD60=20250411-01:34:48.87762758=FILLED10=243
20250411-01:34:49.028677000 : 8=FIXT.1.19=27535=X49=Coinbase56=24ab46f784d1b20db435b852086e325034=31750=TEST52=20250411-01:34:48.907764369=45262=7a00f5f8-0c9f-4483-8ca5-754a13a8781d268=1279=0269=183=159755087055=BTC-USD271=0.6232294660=20250411-01:34:48.90645140=137=53d02566-fb20-40cf-8420-bb29dc3aa00a10=143
20250411-01:34:49.029144000 : 8=FIXT.1.19=32735=X49=Coinbase56=24ab46f784d1b20db435b852086e325034=31850=TEST52=20250411-01:34:48.907771369=45262=7a00f5f8-0c9f-4483-8ca5-754a13a8781d268=1279=0269=2278=4d60a78e-b39b-420e-b830-bc0f3f4fdde283=159755087155=BTC-USD270=3.53271=0.6232294660=20250411-01:34:48.90645137=53d02566-fb20-40cf-8420-bb29dc3aa00a5797=210=130
20250411-01:34:49.029434000 : 8=FIXT.1.19=28135=X49=Coinbase56=24ab46f784d1b20db435b852086e325034=31950=TEST52=20250411-01:34:48.907774369=45262=7a00f5f8-0c9f-4483-8ca5-754a13a8781d268=1279=2269=1278=53d02566-fb20-40cf-8420-bb29dc3aa00a83=159755087255=BTC-USD271=0.0000000060=20250411-01:34:48.90645158=FILLED10=048
20250411-01:34:49.503506000 : 8=FIXT.1.19=28435=X49=Coinbase56=24ab46f784d1b20db435b852086e325034=32050=TEST52=20250411-01:34:49.383071369=45262=7a00f5f8-0c9f-4483-8ca5-754a13a8781d268=1279=0269=083=159755087355=BTC-USD270=3.83271=0.6232294660=20250411-01:34:49.38117840=237=c844e4f2-86e1-4f7c-971c-326a3571161d10=193
20250411-01:34:49.504324000 : 8=FIXT.1.19=32735=X49=Coinbase56=24ab46f784d1b20db435b852086e325034=32150=TEST52=20250411-01:34:49.383128369=45262=7a00f5f8-0c9f-4483-8ca5-754a13a8781d268=1279=0269=2278=c5b88ea9-605d-4595-ac52-f7c3f08523ba83=159755087455=BTC-USD270=3.55271=0.6232294660=20250411-01:34:49.38117837=c844e4f2-86e1-4f7c-971c-326a3571161d5797=110=151
20250411-01:34:49.504552000 : 8=FIXT.1.19=29035=X49=Coinbase56=24ab46f784d1b20db435b852086e325034=32250=TEST52=20250411-01:34:49.383132369=45262=7a00f5f8-0c9f-4483-8ca5-754a13a8781d268=1279=2269=0278=c844e4f2-86e1-4f7c-971c-326a3571161d83=159755087555=BTC-USD270=3.83271=0.0000000060=20250411-01:34:49.38117858=FILLED10=094
20250411-01:34:49.558979000 : 8=FIXT.1.19=28435=X49=Coinbase56=24ab46f784d1b20db435b852086e325034=32350=TEST52=20250411-01:34:49.436837369=45262=7a00f5f8-0c9f-4483-8ca5-754a13a8781d268=1279=0269=183=159755087655=BTC-USD270=3.24271=0.6232294660=20250411-01:34:49.43576040=237=7e3adb5e-b305-4707-893b-979442f4931210=159
20250411-01:34:49.559609000 : 8=FIXT.1.19=32735=X49=Coinbase56=24ab46f784d1b20db435b852086e325034=32450=TEST52=20250411-01:34:49.436846369=45262=7a00f5f8-0c9f-4483-8ca5-754a13a8781d268=1279=0269=2278=4d60a78e-b39b-420e-b830-bc0f3f4fdde283=159755087755=BTC-USD270=3.53271=0.6232294660=20250411-01:34:49.43576037=7e3adb5e-b305-4707-893b-979442f493125797=210=245
20250411-01:34:49.560243000 : 8=FIXT.1.19=29035=X49=Coinbase56=24ab46f784d1b20db435b852086e325034=32550=TEST52=20250411-01:34:49.436849369=45262=7a00f5f8-0c9f-4483-8ca5-754a13a8781d268=1279=2269=1278=7e3adb5e-b305-4707-893b-979442f4931283=159755087855=BTC-USD270=3.24271=0.0000000060=20250411-01:34:49.43576058=FILLED10=065
20250411-01:34:49.628907000 : 8=FIXT.1.19=27935=X49=Coinbase56=24ab46f784d1b20db435b852086e325034=32650=TEST52=20250411-01:34:49.508194369=45262=7a00f5f8-0c9f-4483-8ca5-754a13a8781d268=1279=0269=083=159755087955=BTC-USD29004=2.208895519560=20250411-01:34:49.50656640=137=d45b3ca1-ad44-4641-b9a9-ab636dbb246410=181
20250411-01:34:49.629421000 : 8=FIXT.1.19=32735=X49=Coinbase56=24ab46f784d1b20db435b852086e325034=32750=TEST52=20250411-01:34:49.508207369=45262=7a00f5f8-0c9f-4483-8ca5-754a13a8781d268=1279=0269=2278=c5b88ea9-605d-4595-ac52-f7c3f08523ba83=159755088055=BTC-USD270=3.55271=0.6222240960=20250411-01:34:49.50656637=d45b3ca1-ad44-4641-b9a9-ab636dbb24645797=110=058
20250411-01:34:49.629678000 : 8=FIXT.1.19=26635=X49=Coinbase56=24ab46f784d1b20db435b852086e325034=32850=TEST52=20250411-01:34:49.508212369=45262=7a00f5f8-0c9f-4483-8ca5-754a13a8781d268=1279=2269=0278=d45b3ca1-ad44-4641-b9a9-ab636dbb246483=159755088155=BTC-USD60=20250411-01:34:49.50656658=FILLED10=179
20250411-01:34:49.657465000 : 8=FIXT.1.19=27535=X49=Coinbase56=24ab46f784d1b20db435b852086e325034=32950=TEST52=20250411-01:34:49.536557369=45262=7a00f5f8-0c9f-4483-8ca5-754a13a8781d268=1279=0269=183=159755088255=BTC-USD271=0.6232294660=20250411-01:34:49.53518440=137=789e4c42-7bfc-4708-8ede-f142274575d010=106
20250411-01:34:49.657966000 : 8=FIXT.1.19=32735=X49=Coinbase56=24ab46f784d1b20db435b852086e325034=33050=TEST52=20250411-01:34:49.536572369=45262=7a00f5f8-0c9f-4483-8ca5-754a13a8781d268=1279=0269=2278=4d60a78e-b39b-420e-b830-bc0f3f4fdde283=159755088355=BTC-USD270=3.53271=0.6232294660=20250411-01:34:49.53518437=789e4c42-7bfc-4708-8ede-f142274575d05797=210=083
20250411-01:34:49.658679000 : 8=FIXT.1.19=28135=X49=Coinbase56=24ab46f784d1b20db435b852086e325034=33150=TEST52=20250411-01:34:49.536578369=45262=7a00f5f8-0c9f-4483-8ca5-754a13a8781d268=1279=2269=1278=789e4c42-7bfc-4708-8ede-f142274575d083=159755088455=BTC-USD271=0.0000000060=20250411-01:34:49.53518458=FILLED10=004
20250411-01:34:49.685813000 : 8=FIXT.1.19=27935=X49=Coinbase56=24ab46f784d1b20db435b852086e325034=33250=TEST52=20250411-01:34:49.565196369=45262=7a00f5f8-0c9f-4483-8ca5-754a13a8781d268=1279=0269=083=159755088555=BTC-USD29004=2.208895519560=20250411-01:34:49.56317440=137=b27202b1-f567-4828-af4d-3a49c6244a8c10=047
20250411-01:34:49.686286000 : 8=FIXT.1.19=32735=X49=Coinbase56=24ab46f784d1b20db435b852086e325034=33350=TEST52=20250411-01:34:49.565202369=45262=7a00f5f8-0c9f-4483-8ca5-754a13a8781d268=1279=0269=2278=c5b88ea9-605d-4595-ac52-f7c3f08523ba83=159755088655=BTC-USD270=3.55271=0.6222240960=20250411-01:34:49.56317437=b27202b1-f567-4828-af4d-3a49c6244a8c5797=110=182
20250411-01:34:49.686526000 : 8=FIXT.1.19=26635=X49=Coinbase56=24ab46f784d1b20db435b852086e325034=33450=TEST52=20250411-01:34:49.565205369=45262=7a00f5f8-0c9f-4483-8ca5-754a13a8781d268=1279=2269=0278=b27202b1-f567-4828-af4d-3a49c6244a8c83=159755088755=BTC-USD60=20250411-01:34:49.56317458=FILLED10=054
20250411-01:34:49.713342000 : 8=FIXT.1.19=27535=X49=Coinbase56=24ab46f784d1b20db435b852086e325034=33550=TEST52=20250411-01:34:49.593547369=45262=7a00f5f8-0c9f-4483-8ca5-754a13a8781d268=1279=0269=183=159755088855=BTC-USD271=0.6197183160=20250411-01:34:49.59199040=137=9a2e69bd-f6a1-4757-8c43-f87500c8bc0510=160
20250411-01:34:49.713726000 : 8=FIXT.1.19=32735=X49=Coinbase56=24ab46f784d1b20db435b852086e325034=33650=TEST52=20250411-01:34:49.593554369=45262=7a00f5f8-0c9f-4483-8ca5-754a13a8781d268=1279=0269=2278=4d60a78e-b39b-420e-b830-bc0f3f4fdde283=159755088955=BTC-USD270=3.53271=0.6197183160=20250411-01:34:49.59199037=9a2e69bd-f6a1-4757-8c43-f87500c8bc055797=210=147
20250411-01:34:49.714256000 : 8=FIXT.1.19=28135=X49=Coinbase56=24ab46f784d1b20db435b852086e325034=33750=TEST52=20250411-01:34:49.593557369=45262=7a00f5f8-0c9f-4483-8ca5-754a13a8781d268=1279=2269=1278=9a2e69bd-f6a1-4757-8c43-f87500c8bc0583=159755089055=BTC-USD271=0.0000000060=20250411-01:34:49.59199058=FILLED10=054
20250411-01:34:49.800095000 : 8=FIXT.1.19=27935=X49=Coinbase56=24ab46f784d1b20db435b852086e325034=33850=TEST52=20250411-01:34:49.679370369=45262=7a00f5f8-0c9f-4483-8ca5-754a13a8781d268=1279=0269=083=159755089155=BTC-USD29004=2.208895519560=20250411-01:34:49.67788240=137=2adb742d-0471-404b-a8cd-948b1e14dda410=190
20250411-01:34:49.800882000 : 8=FIXT.1.19=32735=X49=Coinbase56=24ab46f784d1b20db435b852086e325034=33950=TEST52=20250411-01:34:49.679438369=45262=7a00f5f8-0c9f-4483-8ca5-754a13a8781d268=1279=0269=2278=c5b88ea9-605d-4595-ac52-f7c3f08523ba83=159755089255=BTC-USD270=3.55271=0.6222240960=20250411-01:34:49.67788237=2adb742d-0471-404b-a8cd-948b1e14dda45797=110=086
20250411-01:34:49.801167000 : 8=FIXT.1.19=26635=X49=Coinbase56=24ab46f784d1b20db435b852086e325034=34050=TEST52=20250411-01:34:49.679492369=45262=7a00f5f8-0c9f-4483-8ca5-754a13a8781d268=1279=2269=0278=2adb742d-0471-404b-a8cd-948b1e14dda483=159755089355=BTC-USD60=20250411-01:34:49.67788258=FILLED10=202
20250411-01:34:49.829314000 : 8=FIXT.1.19=27535=X49=Coinbase56=24ab46f784d1b20db435b852086e325034=34150=TEST52=20250411-01:34:49.708699369=45262=7a00f5f8-0c9f-4483-8ca5-754a13a8781d268=1279=0269=183=159755089455=BTC-USD271=0.6232294660=20250411-01:34:49.70670740=137=8e65c9ff-583c-4b25-8394-ad1cbd4f097010=205
20250411-01:34:49.830030000 : 8=FIXT.1.19=32735=X49=Coinbase56=24ab46f784d1b20db435b852086e325034=34250=TEST52=20250411-01:34:49.708706369=45262=7a00f5f8-0c9f-4483-8ca5-754a13a8781d268=1279=0269=2278=4d60a78e-b39b-420e-b830-bc0f3f4fdde283=159755089555=BTC-USD270=3.53271=0.6232294660=20250411-01:34:49.70670737=8e65c9ff-583c-4b25-8394-ad1cbd4f09705797=210=183
20250411-01:34:49.830350000 : 8=FIXT.1.19=28135=X49=Coinbase56=24ab46f784d1b20db435b852086e325034=34350=TEST52=20250411-01:34:49.708712369=45262=7a00f5f8-0c9f-4483-8ca5-754a13a8781d268=1279=2269=1278=8e65c9ff-583c-4b25-8394-ad1cbd4f097083=159755089655=BTC-USD271=0.0000000060=20250411-01:34:49.70670758=FILLED10=095
20250411-01:34:49.857168000 : 8=FIXT.1.19=27935=X49=Coinbase56=24ab46f784d1b20db435b852086e325034=34450=TEST52=20250411-01:34:49.736435369=45262=7a00f5f8-0c9f-4483-8ca5-754a13a8781d268=1279=0269=083=159755089755=BTC-USD29004=2.208895519560=20250411-01:34:49.73452640=137=5236ce4a-6e61-4202-9123-c6f6273f668b10=214
20250411-01:34:49.857407000 : 8=FIXT.1.19=32735=X49=Coinbase56=24ab46f784d1b20db435b852086e325034=34550=TEST52=20250411-01:34:49.736440369=45262=7a00f5f8-0c9f-4483-8ca5-754a13a8781d268=1279=0269=2278=c5b88ea9-605d-4595-ac52-f7c3f08523ba83=159755089855=BTC-USD270=3.55271=0.6222240960=20250411-01:34:49.73452637=5236ce4a-6e61-4202-9123-c6f6273f668b5797=110=101
20250411-01:34:49.857592000 : 8=FIXT.1.19=26635=X49=Coinbase56=24ab46f784d1b20db435b852086e325034=34650=TEST52=20250411-01:34:49.736443369=45262=7a00f5f8-0c9f-4483-8ca5-754a13a8781d268=1279=2269=0278=5236ce4a-6e61-4202-9123-c6f6273f668b83=159755089955=BTC-USD60=20250411-01:34:49.73452658=FILLED10=229
20250411-01:34:49.887675000 : 8=FIXT.1.19=27535=X49=Coinbase56=24ab46f784d1b20db435b852086e325034=34750=TEST52=20250411-01:34:49.765967369=45262=7a00f5f8-0c9f-4483-8ca5-754a13a8781d268=1279=0269=183=159755090055=BTC-USD271=0.6197183160=20250411-01:34:49.76447940=137=963b50ad-3fdd-4e6e-a6be-a5dc09c8502610=082
20250411-01:34:49.888320000 : 8=FIXT.1.19=32735=X49=Coinbase56=24ab46f784d1b20db435b852086e325034=34850=TEST52=20250411-01:34:49.765973369=45262=7a00f5f8-0c9f-4483-8ca5-754a13a8781d268=1279=0269=2278=4d60a78e-b39b-420e-b830-bc0f3f4fdde283=159755090155=BTC-USD270=3.53271=0.6197183160=20250411-01:34:49.76447937=963b50ad-3fdd-4e6e-a6be-a5dc09c850265797=210=068
20250411-01:34:49.888661000 : 8=FIXT.1.19=28135=X49=Coinbase56=24ab46f784d1b20db435b852086e325034=34950=TEST52=20250411-01:34:49.765976369=45262=7a00f5f8-0c9f-4483-8ca5-754a13a8781d268=1279=2269=1278=963b50ad-3fdd-4e6e-a6be-a5dc09c8502683=159755090255=BTC-USD271=0.0000000060=20250411-01:34:49.76447958=FILLED10=240
20250411-01:34:49.971130000 : 8=FIXT.1.19=27935=X49=Coinbase56=24ab46f784d1b20db435b852086e325034=35050=TEST52=20250411-01:34:49.851063369=45262=7a00f5f8-0c9f-4483-8ca5-754a13a8781d268=1279=0269=083=159755090355=BTC-USD29004=2.208895519560=20250411-01:34:49.84912540=137=4d177d75-01a3-4a32-b879-4442d71ee19110=192
20250411-01:34:49.971552000 : 8=FIXT.1.19=32735=X49=Coinbase56=24ab46f784d1b20db435b852086e325034=35150=TEST52=20250411-01:34:49.851149369=45262=7a00f5f8-0c9f-4483-8ca5-754a13a8781d268=1279=0269=2278=c5b88ea9-605d-4595-ac52-f7c3f08523ba83=159755090455=BTC-USD270=3.55271=0.6222240960=20250411-01:34:49.84912537=4d177d75-01a3-4a32-b879-4442d71ee1915797=110=088
20250411-01:34:49.971926000 : 8=FIXT.1.19=26635=X49=Coinbase56=24ab46f784d1b20db435b852086e325034=35250=TEST52=20250411-01:34:49.851154369=45262=7a00f5f8-0c9f-4483-8ca5-754a13a8781d268=1279=2269=0278=4d177d75-01a3-4a32-b879-4442d71ee19183=159755090555=BTC-USD60=20250411-01:34:49.84912558=FILLED10=209
20250411-01:34:49.999558000 : 8=FIXT.1.19=27535=X49=Coinbase56=24ab46f784d1b20db435b852086e325034=35350=TEST52=20250411-01:34:49.879404369=45262=7a00f5f8-0c9f-4483-8ca5-754a13a8781d268=1279=0269=183=159755090655=BTC-USD271=0.6232294660=20250411-01:34:49.87753740=137=a0c007ab-24d1-4a59-a4a7-9043ebd743a710=166
20250411-01:34:49.999930000 : 8=FIXT.1.19=32735=X49=Coinbase56=24ab46f784d1b20db435b852086e325034=35450=TEST52=20250411-01:34:49.879498369=45262=7a00f5f8-0c9f-4483-8ca5-754a13a8781d268=1279=0269=2278=4d60a78e-b39b-420e-b830-bc0f3f4fdde283=159755090755=BTC-USD270=3.53271=0.6232294660=20250411-01:34:49.87753737=a0c007ab-24d1-4a59-a4a7-9043ebd743a75797=210=168
20250411-01:34:50.000484000 : 8=FIXT.1.19=28135=X49=Coinbase56=24ab46f784d1b20db435b852086e325034=35550=TEST52=20250411-01:34:49.879541369=45262=7a00f5f8-0c9f-4483-8ca5-754a13a8781d268=1279=2269=1278=a0c007ab-24d1-4a59-a4a7-9043ebd743a783=159755090855=BTC-USD271=0.0000000060=20250411-01:34:49.87753758=FILLED10=072
20250411-01:34:50.315699000 : 8=FIXT.1.19=27935=X49=Coinbase56=24ab46f784d1b20db435b852086e325034=35650=TEST52=20250411-01:34:50.194167369=45262=7a00f5f8-0c9f-4483-8ca5-754a13a8781d268=1279=0269=083=159755090955=BTC-USD29004=2.208895519560=20250411-01:34:50.19243940=137=99d80afd-03fc-40ed-85d0-1da402c20b0310=154
20250411-01:34:50.316632000 : 8=FIXT.1.19=32735=X49=Coinbase56=24ab46f784d1b20db435b852086e325034=35750=TEST52=20250411-01:34:50.194183369=45262=7a00f5f8-0c9f-4483-8ca5-754a13a8781d268=1279=0269=2278=c5b88ea9-605d-4595-ac52-f7c3f08523ba83=159755091055=BTC-USD270=3.55271=0.6222240960=20250411-01:34:50.19243937=99d80afd-03fc-40ed-85d0-1da402c20b035797=110=034
20250411-01:34:50.316892000 : 8=FIXT.1.19=26635=X49=Coinbase56=24ab46f784d1b20db435b852086e325034=35850=TEST52=20250411-01:34:50.194186369=45262=7a00f5f8-0c9f-4483-8ca5-754a13a8781d268=1279=2269=0278=99d80afd-03fc-40ed-85d0-1da402c20b0383=159755091155=BTC-USD60=20250411-01:34:50.19243958=FILLED10=162
20250411-01:34:50.344287000 : 8=FIXT.1.19=27535=X49=Coinbase56=24ab46f784d1b20db435b852086e325034=35950=TEST52=20250411-01:34:50.223545369=45262=7a00f5f8-0c9f-4483-8ca5-754a13a8781d268=1279=0269=183=159755091255=BTC-USD271=0.6232294660=20250411-01:34:50.22170340=137=31747c3f-675a-45d0-a59a-57ac7b4c30bb10=135
20250411-01:34:50.344771000 : 8=FIXT.1.19=32735=X49=Coinbase56=24ab46f784d1b20db435b852086e325034=36050=TEST52=20250411-01:34:50.223551369=45262=7a00f5f8-0c9f-4483-8ca5-754a13a8781d268=1279=0269=2278=4d60a78e-b39b-420e-b830-bc0f3f4fdde283=159755091355=BTC-USD270=3.53271=0.6232294660=20250411-01:34:50.22170337=31747c3f-675a-45d0-a59a-57ac7b4c30bb5797=210=112
20250411-01:34:50.345170000 : 8=FIXT.1.19=28135=X49=Coinbase56=24ab46f784d1b20db435b852086e325034=36150=TEST52=20250411-01:34:50.223555369=45262=7a00f5f8-0c9f-4483-8ca5-754a13a8781d268=1279=2269=1278=31747c3f-675a-45d0-a59a-57ac7b4c30bb83=159755091455=BTC-USD271=0.0000000060=20250411-01:34:50.22170358=FILLED10=031
20250411-01:34:50.418138000 : 8=FIXT.1.19=28435=X49=Coinbase56=24ab46f784d1b20db435b852086e325034=36250=TEST52=20250411-01:34:50.296941369=45262=7a00f5f8-0c9f-4483-8ca5-754a13a8781d268=1279=0269=083=159755091555=BTC-USD270=3.83271=0.6232294660=20250411-01:34:50.29536140=237=9abc62ba-bd17-4008-ad55-cd189d84b73a10=156
20250411-01:34:50.418662000 : 8=FIXT.1.19=32735=X49=Coinbase56=24ab46f784d1b20db435b852086e325034=36350=TEST52=20250411-01:34:50.296948369=45262=7a00f5f8-0c9f-4483-8ca5-754a13a8781d268=1279=0269=2278=c5b88ea9-605d-4595-ac52-f7c3f08523ba83=159755091655=BTC-USD270=3.55271=0.6232294660=20250411-01:34:50.29536137=9abc62ba-bd17-4008-ad55-cd189d84b73a5797=110=118
20250411-01:34:50.418864000 : 8=FIXT.1.19=29035=X49=Coinbase56=24ab46f784d1b20db435b852086e325034=36450=TEST52=20250411-01:34:50.296951369=45262=7a00f5f8-0c9f-4483-8ca5-754a13a8781d268=1279=2269=0278=9abc62ba-bd17-4008-ad55-cd189d84b73a83=159755091755=BTC-USD270=3.83271=0.0000000060=20250411-01:34:50.29536158=FILLED10=060
20250411-01:34:50.473006000 : 8=FIXT.1.19=28435=X49=Coinbase56=24ab46f784d1b20db435b852086e325034=36550=TEST52=20250411-01:34:50.352153369=45262=7a00f5f8-0c9f-4483-8ca5-754a13a8781d268=1279=0269=183=159755091855=BTC-USD270=3.32271=0.6232294660=20250411-01:34:50.35059040=237=5bd72a31-8c01-43c9-9f71-4cc33e9b51a710=001
20250411-01:34:50.473503000 : 8=FIXT.1.19=32735=X49=Coinbase56=24ab46f784d1b20db435b852086e325034=36650=TEST52=20250411-01:34:50.352158369=45262=7a00f5f8-0c9f-4483-8ca5-754a13a8781d268=1279=0269=2278=4d60a78e-b39b-420e-b830-bc0f3f4fdde283=159755091955=BTC-USD270=3.53271=0.6232294660=20250411-01:34:50.35059037=5bd72a31-8c01-43c9-9f71-4cc33e9b51a75797=210=093
20250411-01:34:50.473860000 : 8=FIXT.1.19=29035=X49=Coinbase56=24ab46f784d1b20db435b852086e325034=36750=TEST52=20250411-01:34:50.352162369=45262=7a00f5f8-0c9f-4483-8ca5-754a13a8781d268=1279=2269=1278=5bd72a31-8c01-43c9-9f71-4cc33e9b51a783=159755092055=BTC-USD270=3.32271=0.0000000060=20250411-01:34:50.35059058=FILLED10=151
20250411-01:34:50.487344000 : 8=FIXT.1.19=27935=X49=Coinbase56=24ab46f784d1b20db435b852086e325034=36850=TEST52=20250411-01:34:50.365280369=45262=7a00f5f8-0c9f-4483-8ca5-754a13a8781d268=1279=0269=083=159755092155=BTC-USD29004=2.208895519560=20250411-01:34:50.36368240=137=fd0da4a9-e241-4b48-817c-89b75fdc1d4810=181
20250411-01:34:50.487631000 : 8=FIXT.1.19=32735=X49=Coinbase56=24ab46f784d1b20db435b852086e325034=36950=TEST52=20250411-01:34:50.365291369=45262=7a00f5f8-0c9f-4483-8ca5-754a13a8781d268=1279=0269=2278=c5b88ea9-605d-4595-ac52-f7c3f08523ba83=159755092255=BTC-USD270=3.55271=0.6222240960=20250411-01:34:50.36368237=fd0da4a9-e241-4b48-817c-89b75fdc1d485797=110=074
20250411-01:34:50.487822000 : 8=FIXT.1.19=26635=X49=Coinbase56=24ab46f784d1b20db435b852086e325034=37050=TEST52=20250411-01:34:50.365296369=45262=7a00f5f8-0c9f-4483-8ca5-754a13a8781d268=1279=2269=0278=fd0da4a9-e241-4b48-817c-89b75fdc1d4883=159755092355=BTC-USD60=20250411-01:34:50.36368258=FILLED10=195
20250411-01:34:50.515098000 : 8=FIXT.1.19=27535=X49=Coinbase56=24ab46f784d1b20db435b852086e325034=37150=TEST52=20250411-01:34:50.394307369=45262=7a00f5f8-0c9f-4483-8ca5-754a13a8781d268=1279=0269=183=159755092455=BTC-USD271=0.6197183160=20250411-01:34:50.39264440=137=df3a2ad0-79a9-4640-9db4-acb0f9a3d46710=253
20250411-01:34:50.515363000 : 8=FIXT.1.19=32735=X49=Coinbase56=24ab46f784d1b20db435b852086e325034=37250=TEST52=20250411-01:34:50.394321369=45262=7a00f5f8-0c9f-4483-8ca5-754a13a8781d268=1279=0269=2278=4d60a78e-b39b-420e-b830-bc0f3f4fdde283=159755092555=BTC-USD270=3.53271=0.6197183160=20250411-01:34:50.39264437=df3a2ad0-79a9-4640-9db4-acb0f9a3d4675797=210=238
20250411-01:34:50.515615000 : 8=FIXT.1.19=28135=X49=Coinbase56=24ab46f784d1b20db435b852086e325034=37350=TEST52=20250411-01:34:50.394325369=45262=7a00f5f8-0c9f-4483-8ca5-754a13a8781d268=1279=2269=1278=df3a2ad0-79a9-4640-9db4-acb0f9a3d46783=159755092655=BTC-USD271=0.0000000060=20250411-01:34:50.39264458=FILLED10=155
20250411-01:34:51.116144000 : 8=FIXT.1.19=28435=X49=Coinbase56=24ab46f784d1b20db435b852086e325034=37450=TEST52=20250411-01:34:50.982635369=45262=7a00f5f8-0c9f-4483-8ca5-754a13a8781d268=1279=0269=083=159755092755=BTC-USD270=3.84271=0.6232294660=20250411-01:34:50.98118940=237=5f157b9c-3c6a-4630-8003-b660d6a8661410=147
20250411-01:34:51.116840000 : 8=FIXT.1.19=32735=X49=Coinbase56=24ab46f784d1b20db435b852086e325034=37550=TEST52=20250411-01:34:50.982693369=45262=7a00f5f8-0c9f-4483-8ca5-754a13a8781d268=1279=0269=2278=c5b88ea9-605d-4595-ac52-f7c3f08523ba83=159755092855=BTC-USD270=3.55271=0.6232294660=20250411-01:34:50.98118937=5f157b9c-3c6a-4630-8003-b660d6a866145797=110=105
20250411-01:34:51.117091000 : 8=FIXT.1.19=29035=X49=Coinbase56=24ab46f784d1b20db435b852086e325034=37650=TEST52=20250411-01:34:50.982700369=45262=7a00f5f8-0c9f-4483-8ca5-754a13a8781d268=1279=2269=0278=5f157b9c-3c6a-4630-8003-b660d6a8661483=159755092955=BTC-USD270=3.84271=0.0000000060=20250411-01:34:50.98118958=FILLED10=043
20250411-01:34:51.117626000 : 8=FIXT.1.19=27935=X49=Coinbase56=24ab46f784d1b20db435b852086e325034=37750=TEST52=20250411-01:34:50.994878369=45262=7a00f5f8-0c9f-4483-8ca5-754a13a8781d268=1279=0269=083=159755093055=BTC-USD29004=2.208895519560=20250411-01:34:50.99321240=137=2ebbd8e4-e800-4e9e-a3e7-b01b3b35189a10=230
20250411-01:34:51.118841000 : 8=FIXT.1.19=32735=X49=Coinbase56=24ab46f784d1b20db435b852086e325034=37850=TEST52=20250411-01:34:50.994885369=45262=7a00f5f8-0c9f-4483-8ca5-754a13a8781d268=1279=0269=2278=c5b88ea9-605d-4595-ac52-f7c3f08523ba83=159755093155=BTC-USD270=3.55271=0.6222240960=20250411-01:34:50.99321237=2ebbd8e4-e800-4e9e-a3e7-b01b3b35189a5797=110=119
20250411-01:34:51.119091000 : 8=FIXT.1.19=26635=X49=Coinbase56=24ab46f784d1b20db435b852086e325034=37950=TEST52=20250411-01:34:50.994889369=45262=7a00f5f8-0c9f-4483-8ca5-754a13a8781d268=1279=2269=0278=2ebbd8e4-e800-4e9e-a3e7-b01b3b35189a83=159755093255=BTC-USD60=20250411-01:34:50.99321258=FILLED10=248
20250411-01:34:51.142036000 : 8=FIXT.1.19=27535=X49=Coinbase56=24ab46f784d1b20db435b852086e325034=38050=TEST52=20250411-01:34:51.021680369=45262=7a00f5f8-0c9f-4483-8ca5-754a13a8781d268=1279=0269=183=159755093355=BTC-USD271=0.6232294660=20250411-01:34:51.02033840=137=06391269-e441-42e9-aa1e-8d2999bc397510=222
20250411-01:34:51.142265000 : 8=FIXT.1.19=32735=X49=Coinbase56=24ab46f784d1b20db435b852086e325034=38150=TEST52=20250411-01:34:51.021720369=45262=7a00f5f8-0c9f-4483-8ca5-754a13a8781d268=1279=0269=2278=4d60a78e-b39b-420e-b830-bc0f3f4fdde283=159755093455=BTC-USD270=3.53271=0.6232294660=20250411-01:34:51.02033837=06391269-e441-42e9-aa1e-8d2999bc39755797=210=206
20250411-01:34:51.142415000 : 8=FIXT.1.19=28135=X49=Coinbase56=24ab46f784d1b20db435b852086e325034=38250=TEST52=20250411-01:34:51.021725369=45262=7a00f5f8-0c9f-4483-8ca5-754a13a8781d268=1279=2269=1278=06391269-e441-42e9-aa1e-8d2999bc397583=159755093555=BTC-USD271=0.0000000060=20250411-01:34:51.02033858=FILLED10=126
20250411-01:34:51.158684000 : 8=FIXT.1.19=28435=X49=Coinbase56=24ab46f784d1b20db435b852086e325034=38350=TEST52=20250411-01:34:51.038317369=45262=7a00f5f8-0c9f-4483-8ca5-754a13a8781d268=1279=0269=183=159755093655=BTC-USD270=3.24271=0.6232294660=20250411-01:34:51.03689640=237=bd50b304-270b-474c-8029-29eabd0ee18b10=052
20250411-01:34:51.159127000 : 8=FIXT.1.19=32735=X49=Coinbase56=24ab46f784d1b20db435b852086e325034=38450=TEST52=20250411-01:34:51.038323369=45262=7a00f5f8-0c9f-4483-8ca5-754a13a8781d268=1279=0269=2278=4d60a78e-b39b-420e-b830-bc0f3f4fdde283=159755093755=BTC-USD270=3.53271=0.6232294660=20250411-01:34:51.03689637=bd50b304-270b-474c-8029-29eabd0ee18b5797=210=135
20250411-01:34:51.159299000 : 8=FIXT.1.19=29035=X49=Coinbase56=24ab46f784d1b20db435b852086e325034=38550=TEST52=20250411-01:34:51.038326369=45262=7a00f5f8-0c9f-4483-8ca5-754a13a8781d268=1279=2269=1278=bd50b304-270b-474c-8029-29eabd0ee18b83=159755093855=BTC-USD270=3.24271=0.0000000060=20250411-01:34:51.03689658=FILLED10=211
20250411-01:34:51.228421000 : 8=FIXT.1.19=27935=X49=Coinbase56=24ab46f784d1b20db435b852086e325034=38650=TEST52=20250411-01:34:51.107833369=45262=7a00f5f8-0c9f-4483-8ca5-754a13a8781d268=1279=0269=083=159755093955=BTC-USD29004=2.208895519560=20250411-01:34:51.10654140=137=7cee9ecb-adbe-4b89-b76f-cf26139db16110=115
20250411-01:34:51.229805000 : 8=FIXT.1.19=32735=X49=Coinbase56=24ab46f784d1b20db435b852086e325034=38750=TEST52=20250411-01:34:51.107840369=45262=7a00f5f8-0c9f-4483-8ca5-754a13a8781d268=1279=0269=2278=c5b88ea9-605d-4595-ac52-f7c3f08523ba83=159755094055=BTC-USD270=3.55271=0.6222240960=20250411-01:34:51.10654137=7cee9ecb-adbe-4b89-b76f-cf26139db1615797=110=251
20250411-01:34:51.231157000 : 8=FIXT.1.19=26635=X49=Coinbase56=24ab46f784d1b20db435b852086e325034=38850=TEST52=20250411-01:34:51.107844369=45262=7a00f5f8-0c9f-4483-8ca5-754a13a8781d268=1279=2269=0278=7cee9ecb-adbe-4b89-b76f-cf26139db16183=159755094155=BTC-USD60=20250411-01:34:51.10654158=FILLED10=124
20250411-01:34:51.257112000 : 8=FIXT.1.19=27535=X49=Coinbase56=24ab46f784d1b20db435b852086e325034=38950=TEST52=20250411-01:34:51.137155369=45262=7a00f5f8-0c9f-4483-8ca5-754a13a8781d268=1279=0269=183=159755094255=BTC-USD271=0.6232294660=20250411-01:34:51.13521640=137=f9b064c9-4d4c-4508-96cc-261c5ab06cd010=151
20250411-01:34:51.257386000 : 8=FIXT.1.19=32735=X49=Coinbase56=24ab46f784d1b20db435b852086e325034=39050=TEST52=20250411-01:34:51.137167369=45262=7a00f5f8-0c9f-4483-8ca5-754a13a8781d268=1279=0269=2278=4d60a78e-b39b-420e-b830-bc0f3f4fdde283=159755094355=BTC-USD270=3.53271=0.6232294660=20250411-01:34:51.13521637=f9b064c9-4d4c-4508-96cc-261c5ab06cd05797=210=134
20250411-01:34:51.257600000 : 8=FIXT.1.19=28135=X49=Coinbase56=24ab46f784d1b20db435b852086e325034=39150=TEST52=20250411-01:34:51.137171369=45262=7a00f5f8-0c9f-4483-8ca5-754a13a8781d268=1279=2269=1278=f9b064c9-4d4c-4508-96cc-261c5ab06cd083=159755094455=BTC-USD271=0.0000000060=20250411-01:34:51.13521658=FILLED10=044
20250411-01:34:51.514554000 : 8=FIXT.1.19=27935=X49=Coinbase56=24ab46f784d1b20db435b852086e325034=39250=TEST52=20250411-01:34:51.393519369=45262=7a00f5f8-0c9f-4483-8ca5-754a13a8781d268=1279=0269=083=159755094555=BTC-USD29004=2.208895519560=20250411-01:34:51.39181140=137=54d19f38-62b3-4f01-9258-08ef2720f5a010=194
20250411-01:34:51.515471000 : 8=FIXT.1.19=32735=X49=Coinbase56=24ab46f784d1b20db435b852086e325034=39350=TEST52=20250411-01:34:51.393571369=45262=7a00f5f8-0c9f-4483-8ca5-754a13a8781d268=1279=0269=2278=c5b88ea9-605d-4595-ac52-f7c3f08523ba83=159755094655=BTC-USD270=3.55271=0.6222240960=20250411-01:34:51.39181137=54d19f38-62b3-4f01-9258-08ef2720f5a05797=110=083
20250411-01:34:51.515677000 : 8=FIXT.1.19=26635=X49=Coinbase56=24ab46f784d1b20db435b852086e325034=39450=TEST52=20250411-01:34:51.393575369=45262=7a00f5f8-0c9f-4483-8ca5-754a13a8781d268=1279=2269=0278=54d19f38-62b3-4f01-9258-08ef2720f5a083=159755094755=BTC-USD60=20250411-01:34:51.39181158=FILLED10=212
20250411-01:34:51.544279000 : 8=FIXT.1.19=27535=X49=Coinbase56=24ab46f784d1b20db435b852086e325034=39550=TEST52=20250411-01:34:51.423981369=45262=7a00f5f8-0c9f-4483-8ca5-754a13a8781d268=1279=0269=183=159755094855=BTC-USD271=0.6232294660=20250411-01:34:51.42188240=137=b34f1903-53a5-47cb-a24f-9ea0266ba5e810=162
20250411-01:34:51.544713000 : 8=FIXT.1.19=32735=X49=Coinbase56=24ab46f784d1b20db435b852086e325034=39650=TEST52=20250411-01:34:51.423989369=45262=7a00f5f8-0c9f-4483-8ca5-754a13a8781d268=1279=0269=2278=4d60a78e-b39b-420e-b830-bc0f3f4fdde283=159755094955=BTC-USD270=3.53271=0.6232294660=20250411-01:34:51.42188237=b34f1903-53a5-47cb-a24f-9ea0266ba5e85797=210=159
20250411-01:34:51.544869000 : 8=FIXT.1.19=28135=X49=Coinbase56=24ab46f784d1b20db435b852086e325034=39750=TEST52=20250411-01:34:51.423992369=45262=7a00f5f8-0c9f-4483-8ca5-754a13a8781d268=1279=2269=1278=b34f1903-53a5-47cb-a24f-9ea0266ba5e883=159755095055=BTC-USD271=0.0000000060=20250411-01:34:51.42188258=FILLED10=059
20250411-01:34:51.859820000 : 8=FIXT.1.19=27935=X49=Coinbase56=24ab46f784d1b20db435b852086e325034=39850=TEST52=20250411-01:34:51.737513369=45262=7a00f5f8-0c9f-4483-8ca5-754a13a8781d268=1279=0269=083=159755095155=BTC-USD29004=2.208895519560=20250411-01:34:51.73587640=137=e6801a24-cea7-4c3d-8784-8269976c83be10=068
20250411-01:34:51.860626000 : 8=FIXT.1.19=32735=X49=Coinbase56=24ab46f784d1b20db435b852086e325034=39950=TEST52=20250411-01:34:51.737519369=45262=7a00f5f8-0c9f-4483-8ca5-754a13a8781d268=1279=0269=2278=c5b88ea9-605d-4595-ac52-f7c3f08523ba83=159755095255=BTC-USD270=3.55271=0.6222240960=20250411-01:34:51.73587637=e6801a24-cea7-4c3d-8784-8269976c83be5797=110=221
20250411-01:34:51.861632000 : 8=FIXT.1.19=26635=X49=Coinbase56=24ab46f784d1b20db435b852086e325034=40050=TEST52=20250411-01:34:51.737522369=45262=7a00f5f8-0c9f-4483-8ca5-754a13a8781d268=1279=2269=0278=e6801a24-cea7-4c3d-8784-8269976c83be83=159755095355=BTC-USD60=20250411-01:34:51.73587658=FILLED10=066
20250411-01:34:51.884928000 : 8=FIXT.1.19=27535=X49=Coinbase56=24ab46f784d1b20db435b852086e325034=40150=TEST52=20250411-01:34:51.764696369=45262=7a00f5f8-0c9f-4483-8ca5-754a13a8781d268=1279=0269=183=159755095455=BTC-USD271=0.6232294660=20250411-01:34:51.76297140=137=2faf2c23-96f9-450c-8dfa-dd7a870f045110=225
20250411-01:34:51.885434000 : 8=FIXT.1.19=32735=X49=Coinbase56=24ab46f784d1b20db435b852086e325034=40250=TEST52=20250411-01:34:51.764702369=45262=7a00f5f8-0c9f-4483-8ca5-754a13a8781d268=1279=0269=2278=4d60a78e-b39b-420e-b830-bc0f3f4fdde283=159755095555=BTC-USD270=3.53271=0.6232294660=20250411-01:34:51.76297137=2faf2c23-96f9-450c-8dfa-dd7a870f04515797=210=202
20250411-01:34:51.885701000 : 8=FIXT.1.19=28135=X49=Coinbase56=24ab46f784d1b20db435b852086e325034=40350=TEST52=20250411-01:34:51.764705369=45262=7a00f5f8-0c9f-4483-8ca5-754a13a8781d268=1279=2269=1278=2faf2c23-96f9-450c-8dfa-dd7a870f045183=159755095655=BTC-USD271=0.0000000060=20250411-01:34:51.76297158=FILLED10=120
20250411-01:34:52.942856000 : 8=FIXT.1.19=27935=X49=Coinbase56=24ab46f784d1b20db435b852086e325034=40450=TEST52=20250411-01:34:52.821948369=45262=7a00f5f8-0c9f-4483-8ca5-754a13a8781d268=1279=0269=083=159755095755=BTC-USD29004=2.208895519560=20250411-01:34:52.82063240=137=e0431634-aaa5-4c58-a92c-12afa01cac7910=151
20250411-01:34:52.943789000 : 8=FIXT.1.19=32735=X49=Coinbase56=24ab46f784d1b20db435b852086e325034=40550=TEST52=20250411-01:34:52.821956369=45262=7a00f5f8-0c9f-4483-8ca5-754a13a8781d268=1279=0269=2278=c5b88ea9-605d-4595-ac52-f7c3f08523ba83=159755095855=BTC-USD270=3.55271=0.6222240960=20250411-01:34:52.82063237=e0431634-aaa5-4c58-a92c-12afa01cac795797=110=041
20250411-01:34:52.944249000 : 8=FIXT.1.19=26635=X49=Coinbase56=24ab46f784d1b20db435b852086e325034=40650=TEST52=20250411-01:34:52.821961369=45262=7a00f5f8-0c9f-4483-8ca5-754a13a8781d268=1279=2269=0278=e0431634-aaa5-4c58-a92c-12afa01cac7983=159755095955=BTC-USD60=20250411-01:34:52.82063258=FILLED10=162
20250411-01:34:52.971207000 : 8=FIXT.1.19=27535=X49=Coinbase56=24ab46f784d1b20db435b852086e325034=40750=TEST52=20250411-01:34:52.851256369=45262=7a00f5f8-0c9f-4483-8ca5-754a13a8781d268=1279=0269=183=159755096055=BTC-USD271=0.6232294660=20250411-01:34:52.84924640=137=8350f856-2704-4881-9b3e-040bba58ef9210=241
20250411-01:34:52.971582000 : 8=FIXT.1.19=32735=X49=Coinbase56=24ab46f784d1b20db435b852086e325034=40850=TEST52=20250411-01:34:52.851263369=45262=7a00f5f8-0c9f-4483-8ca5-754a13a8781d268=1279=0269=2278=4d60a78e-b39b-420e-b830-bc0f3f4fdde283=159755096155=BTC-USD270=3.53271=0.6232294660=20250411-01:34:52.84924637=8350f856-2704-4881-9b3e-040bba58ef925797=210=228
20250411-01:34:52.971767000 : 8=FIXT.1.19=28135=X49=Coinbase56=24ab46f784d1b20db435b852086e325034=40950=TEST52=20250411-01:34:52.851266369=45262=7a00f5f8-0c9f-4483-8ca5-754a13a8781d268=1279=2269=1278=8350f856-2704-4881-9b3e-040bba58ef9283=159755096255=BTC-USD271=0.0000000060=20250411-01:34:52.84924658=FILLED10=146
20250411-01:34:53.056974000 : 8=FIXT.1.19=27935=X49=Coinbase56=24ab46f784d1b20db435b852086e325034=41050=TEST52=20250411-01:34:52.936615369=45262=7a00f5f8-0c9f-4483-8ca5-754a13a8781d268=1279=0269=083=159755096355=BTC-USD29004=2.208895519560=20250411-01:34:52.93545640=137=48f47e90-dbc7-4df6-9c37-10a32907c42510=044
20250411-01:34:53.057526000 : 8=FIXT.1.19=32735=X49=Coinbase56=24ab46f784d1b20db435b852086e325034=41150=TEST52=20250411-01:34:52.936742369=45262=7a00f5f8-0c9f-4483-8ca5-754a13a8781d268=1279=0269=2278=c5b88ea9-605d-4595-ac52-f7c3f08523ba83=159755096455=BTC-USD270=3.55271=0.6222240960=20250411-01:34:52.93545637=48f47e90-dbc7-4df6-9c37-10a32907c4255797=110=192
20250411-01:34:53.057790000 : 8=FIXT.1.19=26635=X49=Coinbase56=24ab46f784d1b20db435b852086e325034=41250=TEST52=20250411-01:34:52.936745369=45262=7a00f5f8-0c9f-4483-8ca5-754a13a8781d268=1279=2269=0278=48f47e90-dbc7-4df6-9c37-10a32907c42583=159755096555=BTC-USD60=20250411-01:34:52.93545658=FILLED10=064
20250411-01:34:53.085299000 : 8=FIXT.1.19=27535=X49=Coinbase56=24ab46f784d1b20db435b852086e325034=41350=TEST52=20250411-01:34:52.965229369=45262=7a00f5f8-0c9f-4483-8ca5-754a13a8781d268=1279=0269=183=159755096655=BTC-USD271=0.6232294660=20250411-01:34:52.96395340=137=c798d93f-525c-44b7-ae43-6d11ffd48ada10=030
20250411-01:34:53.085701000 : 8=FIXT.1.19=32735=X49=Coinbase56=24ab46f784d1b20db435b852086e325034=41450=TEST52=20250411-01:34:52.965237369=45262=7a00f5f8-0c9f-4483-8ca5-754a13a8781d268=1279=0269=2278=4d60a78e-b39b-420e-b830-bc0f3f4fdde283=159755096755=BTC-USD270=3.53271=0.6232294660=20250411-01:34:52.96395337=c798d93f-525c-44b7-ae43-6d11ffd48ada5797=210=018
20250411-01:34:53.085924000 : 8=FIXT.1.19=28135=X49=Coinbase56=24ab46f784d1b20db435b852086e325034=41550=TEST52=20250411-01:34:52.965240369=45262=7a00f5f8-0c9f-4483-8ca5-754a13a8781d268=1279=2269=1278=c798d93f-525c-44b7-ae43-6d11ffd48ada83=159755096855=BTC-USD271=0.0000000060=20250411-01:34:52.96395358=FILLED10=183
20250411-01:34:53.286142000 : 8=FIXT.1.19=27935=X49=Coinbase56=24ab46f784d1b20db435b852086e325034=41650=TEST52=20250411-01:34:53.165250369=45262=7a00f5f8-0c9f-4483-8ca5-754a13a8781d268=1279=0269=083=159755096955=BTC-USD29004=2.208895519560=20250411-01:34:53.16382840=137=80ec27f9-caf2-4d0a-bcc9-f41a39217a0010=210
20250411-01:34:53.286733000 : 8=FIXT.1.19=32735=X49=Coinbase56=24ab46f784d1b20db435b852086e325034=41750=TEST52=20250411-01:34:53.165262369=45262=7a00f5f8-0c9f-4483-8ca5-754a13a8781d268=1279=0269=2278=c5b88ea9-605d-4595-ac52-f7c3f08523ba83=159755097055=BTC-USD270=3.55271=0.6222240960=20250411-01:34:53.16382837=80ec27f9-caf2-4d0a-bcc9-f41a39217a005797=110=095
20250411-01:34:53.287139000 : 8=FIXT.1.19=26635=X49=Coinbase56=24ab46f784d1b20db435b852086e325034=41850=TEST52=20250411-01:34:53.165266369=45262=7a00f5f8-0c9f-4483-8ca5-754a13a8781d268=1279=2269=0278=80ec27f9-caf2-4d0a-bcc9-f41a39217a0083=159755097155=BTC-USD60=20250411-01:34:53.16382858=FILLED10=224
20250411-01:34:53.312535000 : 8=FIXT.1.19=27535=X49=Coinbase56=24ab46f784d1b20db435b852086e325034=41950=TEST52=20250411-01:34:53.192582369=45262=7a00f5f8-0c9f-4483-8ca5-754a13a8781d268=1279=0269=183=159755097255=BTC-USD271=0.6232294660=20250411-01:34:53.19156240=137=93008cb8-77ba-4710-92cd-77c1ff9f9da410=181
20250411-01:34:53.312842000 : 8=FIXT.1.19=32735=X49=Coinbase56=24ab46f784d1b20db435b852086e325034=42050=TEST52=20250411-01:34:53.192589369=45262=7a00f5f8-0c9f-4483-8ca5-754a13a8781d268=1279=0269=2278=4d60a78e-b39b-420e-b830-bc0f3f4fdde283=159755097355=BTC-USD270=3.53271=0.6232294660=20250411-01:34:53.19156237=93008cb8-77ba-4710-92cd-77c1ff9f9da45797=210=168
20250411-01:34:53.313003000 : 8=FIXT.1.19=28135=X49=Coinbase56=24ab46f784d1b20db435b852086e325034=42150=TEST52=20250411-01:34:53.192592369=45262=7a00f5f8-0c9f-4483-8ca5-754a13a8781d268=1279=2269=1278=93008cb8-77ba-4710-92cd-77c1ff9f9da483=159755097455=BTC-USD271=0.0000000060=20250411-01:34:53.19156258=FILLED10=077
20250411-01:34:53.515133000 : 8=FIXT.1.19=27935=X49=Coinbase56=24ab46f784d1b20db435b852086e325034=42250=TEST52=20250411-01:34:53.393864369=45262=7a00f5f8-0c9f-4483-8ca5-754a13a8781d268=1279=0269=083=159755097555=BTC-USD29004=2.208895519560=20250411-01:34:53.39206040=137=7da50878-9004-4a59-adc2-7cc5638fadc210=134
20250411-01:34:53.515666000 : 8=FIXT.1.19=32735=X49=Coinbase56=24ab46f784d1b20db435b852086e325034=42350=TEST52=20250411-01:34:53.393875369=45262=7a00f5f8-0c9f-4483-8ca5-754a13a8781d268=1279=0269=2278=c5b88ea9-605d-4595-ac52-f7c3f08523ba83=159755097655=BTC-USD270=3.55271=0.6222240960=20250411-01:34:53.39206037=7da50878-9004-4a59-adc2-7cc5638fadc25797=110=027
20250411-01:34:53.515870000 : 8=FIXT.1.19=26635=X49=Coinbase56=24ab46f784d1b20db435b852086e325034=42450=TEST52=20250411-01:34:53.393877369=45262=7a00f5f8-0c9f-4483-8ca5-754a13a8781d268=1279=2269=0278=7da50878-9004-4a59-adc2-7cc5638fadc283=159755097755=BTC-USD60=20250411-01:34:53.39206058=FILLED10=154
20250411-01:34:53.543359000 : 8=FIXT.1.19=27535=X49=Coinbase56=24ab46f784d1b20db435b852086e325034=42550=TEST52=20250411-01:34:53.421522369=45262=7a00f5f8-0c9f-4483-8ca5-754a13a8781d268=1279=0269=183=159755097855=BTC-USD271=0.6232294660=20250411-01:34:53.42073640=137=0a8b7ed8-57ae-470e-a781-f5f266da0a4f10=001
20250411-01:34:53.543927000 : 8=FIXT.1.19=32735=X49=Coinbase56=24ab46f784d1b20db435b852086e325034=42650=TEST52=20250411-01:34:53.421530369=45262=7a00f5f8-0c9f-4483-8ca5-754a13a8781d268=1279=0269=2278=4d60a78e-b39b-420e-b830-bc0f3f4fdde283=159755097955=BTC-USD270=3.53271=0.6232294660=20250411-01:34:53.42073637=0a8b7ed8-57ae-470e-a781-f5f266da0a4f5797=210=245
20250411-01:34:53.544162000 : 8=FIXT.1.19=28135=X49=Coinbase56=24ab46f784d1b20db435b852086e325034=42750=TEST52=20250411-01:34:53.421648369=45262=7a00f5f8-0c9f-4483-8ca5-754a13a8781d268=1279=2269=1278=0a8b7ed8-57ae-470e-a781-f5f266da0a4f83=159755098055=BTC-USD271=0.0000000060=20250411-01:34:53.42073658=FILLED10=161
20250411-01:34:53.630029000 : 8=FIXT.1.19=27935=X49=Coinbase56=24ab46f784d1b20db435b852086e325034=42850=TEST52=20250411-01:34:53.508599369=45262=7a00f5f8-0c9f-4483-8ca5-754a13a8781d268=1279=0269=083=159755098155=BTC-USD29004=2.208895519560=20250411-01:34:53.50675340=137=8e76d75a-9028-4b66-8626-cca5d79c8f4b10=122
20250411-01:34:53.630545000 : 8=FIXT.1.19=32735=X49=Coinbase56=24ab46f784d1b20db435b852086e325034=42950=TEST52=20250411-01:34:53.508604369=45262=7a00f5f8-0c9f-4483-8ca5-754a13a8781d268=1279=0269=2278=c5b88ea9-605d-4595-ac52-f7c3f08523ba83=159755098255=BTC-USD270=3.55271=0.6222240960=20250411-01:34:53.50675337=8e76d75a-9028-4b66-8626-cca5d79c8f4b5797=110=000
20250411-01:34:53.630863000 : 8=FIXT.1.19=26635=X49=Coinbase56=24ab46f784d1b20db435b852086e325034=43050=TEST52=20250411-01:34:53.508607369=45262=7a00f5f8-0c9f-4483-8ca5-754a13a8781d268=1279=2269=0278=8e76d75a-9028-4b66-8626-cca5d79c8f4b83=159755098355=BTC-USD60=20250411-01:34:53.50675358=FILLED10=119
20250411-01:34:53.656862000 : 8=FIXT.1.19=27535=X49=Coinbase56=24ab46f784d1b20db435b852086e325034=43150=TEST52=20250411-01:34:53.536818369=45262=7a00f5f8-0c9f-4483-8ca5-754a13a8781d268=1279=0269=183=159755098455=BTC-USD271=0.6232294660=20250411-01:34:53.53556840=137=12e731c3-7367-4d1e-a96e-683a95bdd20d10=130
20250411-01:34:53.657222000 : 8=FIXT.1.19=32735=X49=Coinbase56=24ab46f784d1b20db435b852086e325034=43250=TEST52=20250411-01:34:53.536824369=45262=7a00f5f8-0c9f-4483-8ca5-754a13a8781d268=1279=0269=2278=4d60a78e-b39b-420e-b830-bc0f3f4fdde283=159755098555=BTC-USD270=3.53271=0.6232294660=20250411-01:34:53.53556837=12e731c3-7367-4d1e-a96e-683a95bdd20d5797=210=116
20250411-01:34:53.657423000 : 8=FIXT.1.19=28135=X49=Coinbase56=24ab46f784d1b20db435b852086e325034=43350=TEST52=20250411-01:34:53.536827369=45262=7a00f5f8-0c9f-4483-8ca5-754a13a8781d268=1279=2269=1278=12e731c3-7367-4d1e-a96e-683a95bdd20d83=159755098655=BTC-USD271=0.0000000060=20250411-01:34:53.53556858=FILLED10=034
20250411-01:34:53.732314000 : 8=FIXT.1.19=28435=X49=Coinbase56=24ab46f784d1b20db435b852086e325034=43450=TEST52=20250411-01:34:53.611212369=45262=7a00f5f8-0c9f-4483-8ca5-754a13a8781d268=1279=0269=183=159755098755=BTC-USD270=3.27271=0.6232294660=20250411-01:34:53.60928940=237=b8d850ec-04e9-4785-948e-ad08de546df910=102
20250411-01:34:53.732573000 : 8=FIXT.1.19=32735=X49=Coinbase56=24ab46f784d1b20db435b852086e325034=43550=TEST52=20250411-01:34:53.611219369=45262=7a00f5f8-0c9f-4483-8ca5-754a13a8781d268=1279=0269=2278=4d60a78e-b39b-420e-b830-bc0f3f4fdde283=159755098855=BTC-USD270=3.53271=0.6232294660=20250411-01:34:53.60928937=b8d850ec-04e9-4785-948e-ad08de546df95797=210=192
20250411-01:34:53.732763000 : 8=FIXT.1.19=29035=X49=Coinbase56=24ab46f784d1b20db435b852086e325034=43650=TEST52=20250411-01:34:53.611223369=45262=7a00f5f8-0c9f-4483-8ca5-754a13a8781d268=1279=2269=1278=b8d850ec-04e9-4785-948e-ad08de546df983=159755098955=BTC-USD270=3.27271=0.0000000060=20250411-01:34:53.60928958=FILLED10=007
20250411-01:34:53.788699000 : 8=FIXT.1.19=28335=X49=Coinbase56=24ab46f784d1b20db435b852086e325034=43750=TEST52=20250411-01:34:53.666378369=45262=7a00f5f8-0c9f-4483-8ca5-754a13a8781d268=1279=0269=083=159755099055=BTC-USD270=3.8271=0.6232294660=20250411-01:34:53.66526440=237=746bd5a0-8e99-44de-9d72-6f119773dbfb10=060
20250411-01:34:53.789269000 : 8=FIXT.1.19=32735=X49=Coinbase56=24ab46f784d1b20db435b852086e325034=43850=TEST52=20250411-01:34:53.666384369=45262=7a00f5f8-0c9f-4483-8ca5-754a13a8781d268=1279=0269=2278=c5b88ea9-605d-4595-ac52-f7c3f08523ba83=159755099155=BTC-USD270=3.55271=0.6232294660=20250411-01:34:53.66526437=746bd5a0-8e99-44de-9d72-6f119773dbfb5797=110=064
20250411-01:34:53.789453000 : 8=FIXT.1.19=28935=X49=Coinbase56=24ab46f784d1b20db435b852086e325034=43950=TEST52=20250411-01:34:53.666387369=45262=7a00f5f8-0c9f-4483-8ca5-754a13a8781d268=1279=2269=0278=746bd5a0-8e99-44de-9d72-6f119773dbfb83=159755099255=BTC-USD270=3.8271=0.0000000060=20250411-01:34:53.66526458=FILLED10=228
20250411-01:34:54.029807000 : 8=FIXT.1.19=27935=X49=Coinbase56=24ab46f784d1b20db435b852086e325034=44050=TEST52=20250411-01:34:53.909025369=45262=7a00f5f8-0c9f-4483-8ca5-754a13a8781d268=1279=0269=083=159755099355=BTC-USD29004=2.208895519560=20250411-01:34:53.90724640=137=6ef130f7-b83f-425c-969e-395486f1377110=221
20250411-01:34:54.030402000 : 8=FIXT.1.19=32735=X49=Coinbase56=24ab46f784d1b20db435b852086e325034=44150=TEST52=20250411-01:34:53.909036369=45262=7a00f5f8-0c9f-4483-8ca5-754a13a8781d268=1279=0269=2278=c5b88ea9-605d-4595-ac52-f7c3f08523ba83=159755099455=BTC-USD270=3.55271=0.6222240960=20250411-01:34:53.90724637=6ef130f7-b83f-425c-969e-395486f137715797=110=114
20250411-01:34:54.030790000 : 8=FIXT.1.19=26635=X49=Coinbase56=24ab46f784d1b20db435b852086e325034=44250=TEST52=20250411-01:34:53.909039369=45262=7a00f5f8-0c9f-4483-8ca5-754a13a8781d268=1279=2269=0278=6ef130f7-b83f-425c-969e-395486f1377183=159755099555=BTC-USD60=20250411-01:34:53.90724658=FILLED10=242
20250411-01:34:54.057314000 : 8=FIXT.1.19=27535=X49=Coinbase56=24ab46f784d1b20db435b852086e325034=44350=TEST52=20250411-01:34:53.936122369=45262=7a00f5f8-0c9f-4483-8ca5-754a13a8781d268=1279=0269=183=159755099655=BTC-USD271=0.6197183160=20250411-01:34:53.93444340=137=2c71d7dd-06d2-4cea-be1e-fec8f9a5ef3010=201
20250411-01:34:54.057814000 : 8=FIXT.1.19=32735=X49=Coinbase56=24ab46f784d1b20db435b852086e325034=44450=TEST52=20250411-01:34:53.936132369=45262=7a00f5f8-0c9f-4483-8ca5-754a13a8781d268=1279=0269=2278=4d60a78e-b39b-420e-b830-bc0f3f4fdde283=159755099755=BTC-USD270=3.53271=0.6197183160=20250411-01:34:53.93444337=2c71d7dd-06d2-4cea-be1e-fec8f9a5ef305797=210=191
20250411-01:34:54.058230000 : 8=FIXT.1.19=28135=X49=Coinbase56=24ab46f784d1b20db435b852086e325034=44550=TEST52=20250411-01:34:53.936135369=45262=7a00f5f8-0c9f-4483-8ca5-754a13a8781d268=1279=2269=1278=2c71d7dd-06d2-4cea-be1e-fec8f9a5ef3083=159755099855=BTC-USD271=0.0000000060=20250411-01:34:53.93444358=FILLED10=107
20250411-01:34:54.189981000 : 8=FIXT.1.19=28335=X49=Coinbase56=24ab46f784d1b20db435b852086e325034=44650=TEST52=20250411-01:34:54.068501369=45262=7a00f5f8-0c9f-4483-8ca5-754a13a8781d268=1279=0269=183=159755099955=BTC-USD270=3.2271=0.6232294660=20250411-01:34:54.06663840=237=0b2e42a9-0789-4785-9799-43203608e98c10=231
20250411-01:34:54.190511000 : 8=FIXT.1.19=32735=X49=Coinbase56=24ab46f784d1b20db435b852086e325034=44750=TEST52=20250411-01:34:54.068511369=45262=7a00f5f8-0c9f-4483-8ca5-754a13a8781d268=1279=0269=2278=4d60a78e-b39b-420e-b830-bc0f3f4fdde283=159755100055=BTC-USD270=3.53271=0.6232294660=20250411-01:34:54.06663837=0b2e42a9-0789-4785-9799-43203608e98c5797=210=088
20250411-01:34:54.190838000 : 8=FIXT.1.19=28935=X49=Coinbase56=24ab46f784d1b20db435b852086e325034=44850=TEST52=20250411-01:34:54.068513369=45262=7a00f5f8-0c9f-4483-8ca5-754a13a8781d268=1279=2269=1278=0b2e42a9-0789-4785-9799-43203608e98c83=159755100155=BTC-USD270=3.2271=0.0000000060=20250411-01:34:54.06663858=FILLED10=119
20250411-01:34:54.246289000 : 8=FIXT.1.19=28435=X49=Coinbase56=24ab46f784d1b20db435b852086e325034=44950=TEST52=20250411-01:34:54.125822369=45262=7a00f5f8-0c9f-4483-8ca5-754a13a8781d268=1279=0269=083=159755100255=BTC-USD270=3.84271=0.6232294660=20250411-01:34:54.12407940=237=188c270a-ccad-4a98-8201-d5f9a6709aa710=058
20250411-01:34:54.246869000 : 8=FIXT.1.19=32735=X49=Coinbase56=24ab46f784d1b20db435b852086e325034=45050=TEST52=20250411-01:34:54.125938369=45262=7a00f5f8-0c9f-4483-8ca5-754a13a8781d268=1279=0269=2278=c5b88ea9-605d-4595-ac52-f7c3f08523ba83=159755100355=BTC-USD270=3.55271=0.6232294660=20250411-01:34:54.12407937=188c270a-ccad-4a98-8201-d5f9a6709aa75797=110=011
20250411-01:34:54.247216000 : 8=FIXT.1.19=29035=X49=Coinbase56=24ab46f784d1b20db435b852086e325034=45150=TEST52=20250411-01:34:54.125941369=45262=7a00f5f8-0c9f-4483-8ca5-754a13a8781d268=1279=2269=0278=188c270a-ccad-4a98-8201-d5f9a6709aa783=159755100455=BTC-USD270=3.84271=0.0000000060=20250411-01:34:54.12407958=FILLED10=210
20250411-01:34:54.316143000 : 8=FIXT.1.19=27935=X49=Coinbase56=24ab46f784d1b20db435b852086e325034=45250=TEST52=20250411-01:34:54.193454369=45262=7a00f5f8-0c9f-4483-8ca5-754a13a8781d268=1279=0269=083=159755100555=BTC-USD29004=2.208895519560=20250411-01:34:54.19223040=137=e497a236-ccc3-4f2b-946e-e1cd7491106010=061
20250411-01:34:54.316688000 : 8=FIXT.1.19=32735=X49=Coinbase56=24ab46f784d1b20db435b852086e325034=45350=TEST52=20250411-01:34:54.193461369=45262=7a00f5f8-0c9f-4483-8ca5-754a13a8781d268=1279=0269=2278=c5b88ea9-605d-4595-ac52-f7c3f08523ba83=159755100655=BTC-USD270=3.55271=0.6222240960=20250411-01:34:54.19223037=e497a236-ccc3-4f2b-946e-e1cd749110605797=110=206
20250411-01:34:54.316948000 : 8=FIXT.1.19=26635=X49=Coinbase56=24ab46f784d1b20db435b852086e325034=45450=TEST52=20250411-01:34:54.193464369=45262=7a00f5f8-0c9f-4483-8ca5-754a13a8781d268=1279=2269=0278=e497a236-ccc3-4f2b-946e-e1cd7491106083=159755100755=BTC-USD60=20250411-01:34:54.19223058=FILLED10=078
20250411-01:34:54.342818000 : 8=FIXT.1.19=27535=X49=Coinbase56=24ab46f784d1b20db435b852086e325034=45550=TEST52=20250411-01:34:54.222535369=45262=7a00f5f8-0c9f-4483-8ca5-754a13a8781d268=1279=0269=183=159755100855=BTC-USD271=0.6197183160=20250411-01:34:54.22138640=137=ecb6947c-36a8-401c-9e12-a7d0383378b110=056
20250411-01:34:54.343385000 : 8=FIXT.1.19=32735=X49=Coinbase56=24ab46f784d1b20db435b852086e325034=45650=TEST52=20250411-01:34:54.222540369=45262=7a00f5f8-0c9f-4483-8ca5-754a13a8781d268=1279=0269=2278=4d60a78e-b39b-420e-b830-bc0f3f4fdde283=159755100955=BTC-USD270=3.53271=0.6197183160=20250411-01:34:54.22138637=ecb6947c-36a8-401c-9e12-a7d0383378b15797=210=041
20250411-01:34:54.343562000 : 8=FIXT.1.19=28135=X49=Coinbase56=24ab46f784d1b20db435b852086e325034=45750=TEST52=20250411-01:34:54.222543369=45262=7a00f5f8-0c9f-4483-8ca5-754a13a8781d268=1279=2269=1278=ecb6947c-36a8-401c-9e12-a7d0383378b183=159755101055=BTC-USD271=0.0000000060=20250411-01:34:54.22138658=FILLED10=204
20250411-01:34:54.371289000 : 8=FIXT.1.19=27935=X49=Coinbase56=24ab46f784d1b20db435b852086e325034=45850=TEST52=20250411-01:34:54.251028369=45262=7a00f5f8-0c9f-4483-8ca5-754a13a8781d268=1279=0269=083=159755101155=BTC-USD29004=2.208895519560=20250411-01:34:54.24953340=137=d572e9dc-c159-4f52-bd76-d17c2f95b98b10=184
20250411-01:34:54.371597000 : 8=FIXT.1.19=32735=X49=Coinbase56=24ab46f784d1b20db435b852086e325034=45950=TEST52=20250411-01:34:54.251033369=45262=7a00f5f8-0c9f-4483-8ca5-754a13a8781d268=1279=0269=2278=c5b88ea9-605d-4595-ac52-f7c3f08523ba83=159755101255=BTC-USD270=3.55271=0.6222240960=20250411-01:34:54.24953337=d572e9dc-c159-4f52-bd76-d17c2f95b98b5797=110=071
20250411-01:34:54.371797000 : 8=FIXT.1.19=26635=X49=Coinbase56=24ab46f784d1b20db435b852086e325034=46050=TEST52=20250411-01:34:54.251036369=45262=7a00f5f8-0c9f-4483-8ca5-754a13a8781d268=1279=2269=0278=d572e9dc-c159-4f52-bd76-d17c2f95b98b83=159755101355=BTC-USD60=20250411-01:34:54.24953358=FILLED10=190
20250411-01:34:54.399940000 : 8=FIXT.1.19=27535=X49=Coinbase56=24ab46f784d1b20db435b852086e325034=46150=TEST52=20250411-01:34:54.279568369=45262=7a00f5f8-0c9f-4483-8ca5-754a13a8781d268=1279=0269=183=159755101455=BTC-USD271=0.6197183160=20250411-01:34:54.27758140=137=c0d60678-4dc3-4151-a65c-6c82c3560f7510=027
20250411-01:34:54.400250000 : 8=FIXT.1.19=32735=X49=Coinbase56=24ab46f784d1b20db435b852086e325034=46250=TEST52=20250411-01:34:54.279573369=45262=7a00f5f8-0c9f-4483-8ca5-754a13a8781d268=1279=0269=2278=4d60a78e-b39b-420e-b830-bc0f3f4fdde283=159755101555=BTC-USD270=3.53271=0.6197183160=20250411-01:34:54.27758137=c0d60678-4dc3-4151-a65c-6c82c3560f755797=210=012
20250411-01:34:54.400432000 : 8=FIXT.1.19=28135=X49=Coinbase56=24ab46f784d1b20db435b852086e325034=46350=TEST52=20250411-01:34:54.279577369=45262=7a00f5f8-0c9f-4483-8ca5-754a13a8781d268=1279=2269=1278=c0d60678-4dc3-4151-a65c-6c82c3560f7583=159755101655=BTC-USD271=0.0000000060=20250411-01:34:54.27758158=FILLED10=185
20250411-01:34:54.433963000 : 8=FIXT.1.19=28435=X49=Coinbase56=24ab46f784d1b20db435b852086e325034=46450=TEST52=20250411-01:34:54.313815369=45262=7a00f5f8-0c9f-4483-8ca5-754a13a8781d268=1279=0269=083=159755101755=BTC-USD270=3.91271=0.6197183160=20250411-01:34:54.31191240=237=bcf205a1-6922-4bf2-b45f-5f920bca9c7510=096
20250411-01:34:54.434550000 : 8=FIXT.1.19=32735=X49=Coinbase56=24ab46f784d1b20db435b852086e325034=46550=TEST52=20250411-01:34:54.313825369=45262=7a00f5f8-0c9f-4483-8ca5-754a13a8781d268=1279=0269=2278=c5b88ea9-605d-4595-ac52-f7c3f08523ba83=159755101855=BTC-USD270=3.55271=0.6197183160=20250411-01:34:54.31191237=bcf205a1-6922-4bf2-b45f-5f920bca9c755797=110=053
20250411-01:34:54.434911000 : 8=FIXT.1.19=29035=X49=Coinbase56=24ab46f784d1b20db435b852086e325034=46650=TEST52=20250411-01:34:54.313829369=45262=7a00f5f8-0c9f-4483-8ca5-754a13a8781d268=1279=2269=0278=bcf205a1-6922-4bf2-b45f-5f920bca9c7583=159755101955=BTC-USD270=3.91271=0.0000000060=20250411-01:34:54.31191258=FILLED10=002
20250411-01:34:54.762304000 : 8=FIXT.1.19=28335=X49=Coinbase56=24ab46f784d1b20db435b852086e325034=46750=TEST52=20250411-01:34:54.640800369=45262=7a00f5f8-0c9f-4483-8ca5-754a13a8781d268=1279=0269=183=159755102055=BTC-USD270=3.3271=0.6197183160=20250411-01:34:54.63901640=237=eb1feba6-8bd6-4f86-b5f0-77315a0f96e910=113
20250411-01:34:54.763269000 : 8=FIXT.1.19=32735=X49=Coinbase56=24ab46f784d1b20db435b852086e325034=46850=TEST52=20250411-01:34:54.640809369=45262=7a00f5f8-0c9f-4483-8ca5-754a13a8781d268=1279=0269=2278=4d60a78e-b39b-420e-b830-bc0f3f4fdde283=159755102155=BTC-USD270=3.53271=0.6197183160=20250411-01:34:54.63901637=eb1feba6-8bd6-4f86-b5f0-77315a0f96e95797=210=004
20250411-01:34:54.763489000 : 8=FIXT.1.19=28935=X49=Coinbase56=24ab46f784d1b20db435b852086e325034=46950=TEST52=20250411-01:34:54.640812369=45262=7a00f5f8-0c9f-4483-8ca5-754a13a8781d268=1279=2269=1278=eb1feba6-8bd6-4f86-b5f0-77315a0f96e983=159755102255=BTC-USD270=3.3271=0.0000000060=20250411-01:34:54.63901658=FILLED10=026
20250411-01:34:54.778712000 : 8=FIXT.1.19=27935=X49=Coinbase56=24ab46f784d1b20db435b852086e325034=47050=TEST52=20250411-01:34:54.651026369=45262=7a00f5f8-0c9f-4483-8ca5-754a13a8781d268=1279=0269=083=159755102355=BTC-USD29004=2.208895519560=20250411-01:34:54.64971840=137=a0710dc8-1fc4-4cf7-bbd9-457952cdec8710=226
20250411-01:34:54.779252000 : 8=FIXT.1.19=32735=X49=Coinbase56=24ab46f784d1b20db435b852086e325034=47150=TEST52=20250411-01:34:54.651036369=45262=7a00f5f8-0c9f-4483-8ca5-754a13a8781d268=1279=0269=2278=c5b88ea9-605d-4595-ac52-f7c3f08523ba83=159755102455=BTC-USD270=3.55271=0.6222240960=20250411-01:34:54.64971837=a0710dc8-1fc4-4cf7-bbd9-457952cdec875797=110=118
20250411-01:34:54.779821000 : 8=FIXT.1.19=26635=X49=Coinbase56=24ab46f784d1b20db435b852086e325034=47250=TEST52=20250411-01:34:54.651039369=45262=7a00f5f8-0c9f-4483-8ca5-754a13a8781d268=1279=2269=0278=a0710dc8-1fc4-4cf7-bbd9-457952cdec8783=159755102555=BTC-USD60=20250411-01:34:54.64971858=FILLED10=246
20250411-01:34:54.799644000 : 8=FIXT.1.19=27535=X49=Coinbase56=24ab46f784d1b20db435b852086e325034=47350=TEST52=20250411-01:34:54.679372369=45262=7a00f5f8-0c9f-4483-8ca5-754a13a8781d268=1279=0269=183=159755102655=BTC-USD271=0.6197183160=20250411-01:34:54.67742140=137=5f2ec446-5381-4570-8744-7443d02af36e10=195
20250411-01:34:54.800073000 : 8=FIXT.1.19=32735=X49=Coinbase56=24ab46f784d1b20db435b852086e325034=47450=TEST52=20250411-01:34:54.679383369=45262=7a00f5f8-0c9f-4483-8ca5-754a13a8781d268=1279=0269=2278=4d60a78e-b39b-420e-b830-bc0f3f4fdde283=159755102755=BTC-USD270=3.53271=0.6197183160=20250411-01:34:54.67742137=5f2ec446-5381-4570-8744-7443d02af36e5797=210=186
20250411-01:34:54.800490000 : 8=FIXT.1.19=28135=X49=Coinbase56=24ab46f784d1b20db435b852086e325034=47550=TEST52=20250411-01:34:54.679388369=45262=7a00f5f8-0c9f-4483-8ca5-754a13a8781d268=1279=2269=1278=5f2ec446-5381-4570-8744-7443d02af36e83=159755102855=BTC-USD271=0.0000000060=20250411-01:34:54.67742158=FILLED10=104
20250411-01:34:54.815107000 : 8=FIXT.1.19=28435=X49=Coinbase56=24ab46f784d1b20db435b852086e325034=47650=TEST52=20250411-01:34:54.694931369=45262=7a00f5f8-0c9f-4483-8ca5-754a13a8781d268=1279=0269=083=159755102955=BTC-USD270=3.88271=0.6197183160=20250411-01:34:54.69379440=237=efb646e6-7fbe-4496-b6ba-2769e123bd3310=159
20250411-01:34:54.815846000 : 8=FIXT.1.19=32735=X49=Coinbase56=24ab46f784d1b20db435b852086e325034=47750=TEST52=20250411-01:34:54.694937369=45262=7a00f5f8-0c9f-4483-8ca5-754a13a8781d268=1279=0269=2278=c5b88ea9-605d-4595-ac52-f7c3f08523ba83=159755103055=BTC-USD270=3.55271=0.6197183160=20250411-01:34:54.69379437=efb646e6-7fbe-4496-b6ba-2769e123bd335797=110=106
20250411-01:34:54.816188000 : 8=FIXT.1.19=29035=X49=Coinbase56=24ab46f784d1b20db435b852086e325034=47850=TEST52=20250411-01:34:54.694941369=45262=7a00f5f8-0c9f-4483-8ca5-754a13a8781d268=1279=2269=0278=efb646e6-7fbe-4496-b6ba-2769e123bd3383=159755103155=BTC-USD270=3.88271=0.0000000060=20250411-01:34:54.69379458=FILLED10=052
20250411-01:34:55.201080000 : 8=FIXT.1.19=8435=534=4649=24ab46f784d1b20db435b852086e325052=20250411-01:34:55.20056=Coinbase10=160
20250411-01:34:55.428188000 : 8=FIXT.1.19=12035=549=Coinbase56=24ab46f784d1b20db435b852086e325034=47950=TEST52=20250411-01:34:55.307280369=4558=CLIENT_LOGOUT10=114
20250411-01:35:23.187654000 : 8=FIXT.1.19=21535=A34=149=24ab46f784d1b20db435b852086e325052=20250411-01:35:23.17856=Coinbase95=4496=uuHKIc0qVZyyOsXKvX/9iTR326GLLMDXpmWnYvJfPtg=98=0108=30141=Y553=24ab46f784d1b20db435b852086e3250554=akmwnltyfgb1137=910=119
20250411-01:35:23.443517000 : 8=FIXT.1.19=12535=A49=Coinbase56=24ab46f784d1b20db435b852086e325034=150=TEST52=20250411-01:35:23.320941369=198=0108=30141=Y1137=910=185
20250411-01:35:24.940484000 : 8=FIXT.1.19=17835=V34=249=24ab46f784d1b20db435b852086e325052=20250411-01:35:24.93956=Coinbase1128=9146=155=BTC-USD262=ac9dc520-fd90-4708-a92a-3ceddd7c32a3263=1264=0267=2269=0269=110=202
20250411-01:35:25.259378000 : 8=FIXT.1.19=27635=X49=Coinbase56=24ab46f784d1b20db435b852086e325034=250=TEST52=20250411-01:35:25.138113369=2262=ac9dc520-fd90-4708-a92a-3ceddd7c32a3268=1279=0269=083=159755161155=BTC-USD29004=2.208895519560=20250411-01:35:25.13610540=137=751dc36a-eec9-4cd0-96a5-2dafee84112a10=044
20250411-01:35:25.260060000 : 8=FIXT.1.19=32435=X49=Coinbase56=24ab46f784d1b20db435b852086e325034=350=TEST52=20250411-01:35:25.138118369=2262=ac9dc520-fd90-4708-a92a-3ceddd7c32a3268=1279=0269=2278=c5b88ea9-605d-4595-ac52-f7c3f08523ba83=159755161255=BTC-USD270=3.55271=0.6222240960=20250411-01:35:25.13610537=751dc36a-eec9-4cd0-96a5-2dafee84112a5797=110=196
20250411-01:35:25.260351000 : 8=FIXT.1.19=26335=X49=Coinbase56=24ab46f784d1b20db435b852086e325034=450=TEST52=20250411-01:35:25.138121369=2262=ac9dc520-fd90-4708-a92a-3ceddd7c32a3268=1279=2269=0278=751dc36a-eec9-4cd0-96a5-2dafee84112a83=159755161355=BTC-USD60=20250411-01:35:25.13610558=FILLED10=059
20250411-01:35:25.285389000 : 8=FIXT.1.19=27235=X49=Coinbase56=24ab46f784d1b20db435b852086e325034=550=TEST52=20250411-01:35:25.164926369=2262=ac9dc520-fd90-4708-a92a-3ceddd7c32a3268=1279=0269=183=159755161455=BTC-USD271=0.6232294660=20250411-01:35:25.16389240=137=c7e7c7ef-5d9d-4989-8e99-59af0e7545a610=022
20250411-01:35:25.285848000 : 8=FIXT.1.19=32435=X49=Coinbase56=24ab46f784d1b20db435b852086e325034=650=TEST52=20250411-01:35:25.164931369=2262=ac9dc520-fd90-4708-a92a-3ceddd7c32a3268=1279=0269=2278=4d60a78e-b39b-420e-b830-bc0f3f4fdde283=159755161555=BTC-USD270=3.53271=0.6232294660=20250411-01:35:25.16389237=c7e7c7ef-5d9d-4989-8e99-59af0e7545a65797=210=007
20250411-01:35:25.286117000 : 8=FIXT.1.19=27835=X49=Coinbase56=24ab46f784d1b20db435b852086e325034=750=TEST52=20250411-01:35:25.164934369=2262=ac9dc520-fd90-4708-a92a-3ceddd7c32a3268=1279=2269=1278=c7e7c7ef-5d9d-4989-8e99-59af0e7545a683=159755161655=BTC-USD271=0.0000000060=20250411-01:35:25.16389258=FILLED10=190
20250411-01:35:25.394829000 : 8=FIXT.1.19=27635=X49=Coinbase56=24ab46f784d1b20db435b852086e325034=850=TEST52=20250411-01:35:25.252151369=2262=ac9dc520-fd90-4708-a92a-3ceddd7c32a3268=1279=0269=083=159755161755=BTC-USD29004=2.208895519560=20250411-01:35:25.25077040=137=4a733d79-d868-4ed2-ae59-e8a3297d780910=114
20250411-01:35:25.395406000 : 8=FIXT.1.19=32435=X49=Coinbase56=24ab46f784d1b20db435b852086e325034=950=TEST52=20250411-01:35:25.252156369=2262=ac9dc520-fd90-4708-a92a-3ceddd7c32a3268=1279=0269=2278=c5b88ea9-605d-4595-ac52-f7c3f08523ba83=159755161855=BTC-USD270=3.55271=0.6222240960=20250411-01:35:25.25077037=4a733d79-d868-4ed2-ae59-e8a3297d78095797=110=010
