20250410-22:56:03.468695000 : 8=FIXT.1.19=21535=A34=149=24ab46f784d1b20db435b852086e325052=20250410-22:56:03.46156=Coinbase95=4496=2dCqr3WZycXngmM9qjf65eVMpkZ3A9BiaKLiSHCicuY=98=0108=30141=Y553=24ab46f784d1b20db435b852086e3250554=akmwnltyfgb1137=910=102
20250410-22:56:03.731794000 : 8=FIXT.1.19=12535=A49=Coinbase56=24ab46f784d1b20db435b852086e325034=150=TEST52=20250410-22:56:03.618997369=198=0108=30141=Y1137=910=209
20250410-22:56:04.934982000 : 8=FIXT.1.19=17835=V34=249=24ab46f784d1b20db435b852086e325052=20250410-22:56:04.93456=Coinbase1128=9146=155=BTC-USD262=4f9e712e-7ce4-4e8c-aa34-3f64600137ce263=1264=0267=2269=0269=110=067
20250410-22:56:05.285936000 : 8=FIXT.1.19=27635=X49=Coinbase56=24ab46f784d1b20db435b852086e325034=250=TEST52=20250410-22:56:05.175855369=2262=4f9e712e-7ce4-4e8c-aa34-3f64600137ce268=1279=0269=083=159735929555=BTC-USD29004=2.208895536660=20250410-22:56:05.17409940=137=f16c44ab-2a03-4faf-8452-c98a43d3095910=026
20250410-22:56:05.286533000 : 8=FIXT.1.19=32435=X49=Coinbase56=24ab46f784d1b20db435b852086e325034=350=TEST52=20250410-22:56:05.175872369=2262=4f9e712e-7ce4-4e8c-aa34-3f64600137ce268=1279=0269=2278=b9704cf1-f180-4d92-90da-6bb364d4a71583=159735929655=BTC-USD270=3.54271=0.6239817960=20250410-22:56:05.17409937=f16c44ab-2a03-4faf-8452-c98a43d309595797=110=130
20250410-22:56:05.286793000 : 8=FIXT.1.19=26335=X49=Coinbase56=24ab46f784d1b20db435b852086e325034=450=TEST52=20250410-22:56:05.175877369=2262=4f9e712e-7ce4-4e8c-aa34-3f64600137ce268=1279=2269=0278=f16c44ab-2a03-4faf-8452-c98a43d3095983=159735929755=BTC-USD60=20250410-22:56:05.17409958=FILLED10=046
20250410-22:56:05.312747000 : 8=FIXT.1.19=27235=X49=Coinbase56=24ab46f784d1b20db435b852086e325034=550=TEST52=20250410-22:56:05.205158369=2262=4f9e712e-7ce4-4e8c-aa34-3f64600137ce268=1279=0269=183=159735929855=BTC-USD271=0.6232294660=20250410-22:56:05.20322140=137=94629cf4-d7b7-4748-8c9f-fea49bae838c10=174
20250410-22:56:05.313217000 : 8=FIXT.1.19=32435=X49=Coinbase56=24ab46f784d1b20db435b852086e325034=650=TEST52=20250410-22:56:05.205168369=2262=4f9e712e-7ce4-4e8c-aa34-3f64600137ce268=1279=0269=2278=4d60a78e-b39b-420e-b830-bc0f3f4fdde283=159735929955=BTC-USD270=3.53271=0.6232294660=20250410-22:56:05.20322137=94629cf4-d7b7-4748-8c9f-fea49bae838c5797=210=164
20250410-22:56:05.313711000 : 8=FIXT.1.19=27835=X49=Coinbase56=24ab46f784d1b20db435b852086e325034=750=TEST52=20250410-22:56:05.205181369=2262=4f9e712e-7ce4-4e8c-aa34-3f64600137ce268=1279=2269=1278=94629cf4-d7b7-4748-8c9f-fea49bae838c83=159735930055=BTC-USD271=0.0000000060=20250410-22:56:05.20322158=FILLED10=065
20250410-22:56:05.398342000 : 8=FIXT.1.19=27635=X49=Coinbase56=24ab46f784d1b20db435b852086e325034=850=TEST52=20250410-22:56:05.290625369=2262=4f9e712e-7ce4-4e8c-aa34-3f64600137ce268=1279=0269=083=159735930155=BTC-USD29004=2.208895536660=20250410-22:56:05.28883840=137=08728152-484f-4620-b378-26f805fe705910=007
20250410-22:56:05.398767000 : 8=FIXT.1.19=32435=X49=Coinbase56=24ab46f784d1b20db435b852086e325034=950=TEST52=20250410-22:56:05.290687369=2262=4f9e712e-7ce4-4e8c-aa34-3f64600137ce268=1279=0269=2278=b9704cf1-f180-4d92-90da-6bb364d4a71583=159735930255=BTC-USD270=3.54271=0.6239817960=20250410-22:56:05.28883837=08728152-484f-4620-b378-26f805fe70595797=110=120
20250410-22:56:05.399083000 : 8=FIXT.1.19=26435=X49=Coinbase56=24ab46f784d1b20db435b852086e325034=1050=TEST52=20250410-22:56:05.290693369=2262=4f9e712e-7ce4-4e8c-aa34-3f64600137ce268=1279=2269=0278=08728152-484f-4620-b378-26f805fe705983=159735930355=BTC-USD60=20250410-22:56:05.28883858=FILLED10=068
20250410-22:56:05.425526000 : 8=FIXT.1.19=27335=X49=Coinbase56=24ab46f784d1b20db435b852086e325034=1150=TEST52=20250410-22:56:05.318339369=2262=4f9e712e-7ce4-4e8c-aa34-3f64600137ce268=1279=0269=183=159735930455=BTC-USD271=0.6232294660=20250410-22:56:05.31711540=137=9e413ec3-8ca1-4bc0-8655-490b9c36027810=251
20250410-22:56:05.426100000 : 8=FIXT.1.19=32535=X49=Coinbase56=24ab46f784d1b20db435b852086e325034=1250=TEST52=20250410-22:56:05.318441369=2262=4f9e712e-7ce4-4e8c-aa34-3f64600137ce268=1279=0269=2278=4d60a78e-b39b-420e-b830-bc0f3f4fdde283=159735930555=BTC-USD270=3.53271=0.6232294660=20250410-22:56:05.31711537=9e413ec3-8ca1-4bc0-8655-490b9c3602785797=210=234
20250410-22:56:05.426427000 : 8=FIXT.1.19=27935=X49=Coinbase56=24ab46f784d1b20db435b852086e325034=1350=TEST52=20250410-22:56:05.318493369=2262=4f9e712e-7ce4-4e8c-aa34-3f64600137ce268=1279=2269=1278=9e413ec3-8ca1-4bc0-8655-490b9c36027883=159735930655=BTC-USD271=0.0000000060=20250410-22:56:05.31711558=FILLED10=165
20250410-22:56:05.684376000 : 8=FIXT.1.19=27735=X49=Coinbase56=24ab46f784d1b20db435b852086e325034=1450=TEST52=20250410-22:56:05.577043369=2262=4f9e712e-7ce4-4e8c-aa34-3f64600137ce268=1279=0269=083=159735930755=BTC-USD29004=2.208895536660=20250410-22:56:05.57562240=137=695d7429-d947-45ab-891a-a5d5979cf8f710=060
20250410-22:56:05.684805000 : 8=FIXT.1.19=32535=X49=Coinbase56=24ab46f784d1b20db435b852086e325034=1550=TEST52=20250410-22:56:05.577056369=2262=4f9e712e-7ce4-4e8c-aa34-3f64600137ce268=1279=0269=2278=b9704cf1-f180-4d92-90da-6bb364d4a71583=159735930855=BTC-USD270=3.54271=0.6239817960=20250410-22:56:05.57562237=695d7429-d947-45ab-891a-a5d5979cf8f75797=110=169
20250410-22:56:05.685171000 : 8=FIXT.1.19=26435=X49=Coinbase56=24ab46f784d1b20db435b852086e325034=1650=TEST52=20250410-22:56:05.577058369=2262=4f9e712e-7ce4-4e8c-aa34-3f64600137ce268=1279=2269=0278=695d7429-d947-45ab-891a-a5d5979cf8f783=159735930955=BTC-USD60=20250410-22:56:05.57562258=FILLED10=082
20250410-22:56:05.711120000 : 8=FIXT.1.19=27335=X49=Coinbase56=24ab46f784d1b20db435b852086e325034=1750=TEST52=20250410-22:56:05.604438369=2262=4f9e712e-7ce4-4e8c-aa34-3f64600137ce268=1279=0269=183=159735931055=BTC-USD271=0.6232294660=20250410-22:56:05.60321040=137=4ee7bd2a-db36-471d-8eb0-84f514ddb2b310=011
20250410-22:56:05.711512000 : 8=FIXT.1.19=32535=X49=Coinbase56=24ab46f784d1b20db435b852086e325034=1850=TEST52=20250410-22:56:05.604446369=2262=4f9e712e-7ce4-4e8c-aa34-3f64600137ce268=1279=0269=2278=4d60a78e-b39b-420e-b830-bc0f3f4fdde283=159735931155=BTC-USD270=3.53271=0.6232294660=20250410-22:56:05.60321037=4ee7bd2a-db36-471d-8eb0-84f514ddb2b35797=210=255
20250410-22:56:05.711837000 : 8=FIXT.1.19=27935=X49=Coinbase56=24ab46f784d1b20db435b852086e325034=1950=TEST52=20250410-22:56:05.604449369=2262=4f9e712e-7ce4-4e8c-aa34-3f64600137ce268=1279=2269=1278=4ee7bd2a-db36-471d-8eb0-84f514ddb2b383=159735931255=BTC-USD271=0.0000000060=20250410-22:56:05.60321058=FILLED10=182
20250410-22:56:06.100719000 : 8=FIXT.1.19=8335=534=349=24ab46f784d1b20db435b852086e325052=20250410-22:56:06.09956=Coinbase10=122
20250410-22:56:06.198439000 : 8=FIXT.1.19=27735=X49=Coinbase56=24ab46f784d1b20db435b852086e325034=2050=TEST52=20250410-22:56:06.090965369=2262=4f9e712e-7ce4-4e8c-aa34-3f64600137ce268=1279=0269=083=159735931355=BTC-USD29004=2.208895536660=20250410-22:56:06.08947540=137=a9872b85-6456-43f7-b949-bfe33c3f642d10=048
20250410-22:56:06.198932000 : 8=FIXT.1.19=32535=X49=Coinbase56=24ab46f784d1b20db435b852086e325034=2150=TEST52=20250410-22:56:06.091053369=2262=4f9e712e-7ce4-4e8c-aa34-3f64600137ce268=1279=0269=2278=b9704cf1-f180-4d92-90da-6bb364d4a71583=159735931455=BTC-USD270=3.54271=0.6239817960=20250410-22:56:06.08947537=a9872b85-6456-43f7-b949-bfe33c3f642d5797=110=142
20250410-22:56:06.199191000 : 8=FIXT.1.19=26435=X49=Coinbase56=24ab46f784d1b20db435b852086e325034=2250=TEST52=20250410-22:56:06.091060369=2262=4f9e712e-7ce4-4e8c-aa34-3f64600137ce268=1279=2269=0278=a9872b85-6456-43f7-b949-bfe33c3f642d83=159735931555=BTC-USD60=20250410-22:56:06.08947558=FILLED10=051
20250410-22:56:06.227777000 : 8=FIXT.1.19=27335=X49=Coinbase56=24ab46f784d1b20db435b852086e325034=2350=TEST52=20250410-22:56:06.118347369=2262=4f9e712e-7ce4-4e8c-aa34-3f64600137ce268=1279=0269=183=159735931655=BTC-USD271=0.6232294660=20250410-22:56:06.11656340=137=bcdbbba7-59cd-47db-9627-641cfac8bbbe10=224
20250410-22:56:06.228317000 : 8=FIXT.1.19=32535=X49=Coinbase56=24ab46f784d1b20db435b852086e325034=2450=TEST52=20250410-22:56:06.118355369=2262=4f9e712e-7ce4-4e8c-aa34-3f64600137ce268=1279=0269=2278=4d60a78e-b39b-420e-b830-bc0f3f4fdde283=159735931755=BTC-USD270=3.53271=0.6232294660=20250410-22:56:06.11656337=bcdbbba7-59cd-47db-9627-641cfac8bbbe5797=210=212
20250410-22:56:06.228574000 : 8=FIXT.1.19=27935=X49=Coinbase56=24ab46f784d1b20db435b852086e325034=2550=TEST52=20250410-22:56:06.118357369=2262=4f9e712e-7ce4-4e8c-aa34-3f64600137ce268=1279=2269=1278=bcdbbba7-59cd-47db-9627-641cfac8bbbe83=159735931855=BTC-USD271=0.0000000060=20250410-22:56:06.11656358=FILLED10=138
20250410-22:56:06.233162000 : 8=FIXT.1.19=28235=X49=Coinbase56=24ab46f784d1b20db435b852086e325034=2650=TEST52=20250410-22:56:06.125335369=2262=4f9e712e-7ce4-4e8c-aa34-3f64600137ce268=1279=0269=083=159735931955=BTC-USD270=3.88271=0.6232294660=20250410-22:56:06.12342440=237=2ec1c04d-f4f5-4473-b2ce-1d1cdc8d9e3210=187
20250410-22:56:06.233359000 : 8=FIXT.1.19=32535=X49=Coinbase56=24ab46f784d1b20db435b852086e325034=2750=TEST52=20250410-22:56:06.125341369=2262=4f9e712e-7ce4-4e8c-aa34-3f64600137ce268=1279=0269=2278=b9704cf1-f180-4d92-90da-6bb364d4a71583=159735932055=BTC-USD270=3.54271=0.6232294660=20250410-22:56:06.12342437=2ec1c04d-f4f5-4473-b2ce-1d1cdc8d9e325797=110=065
20250410-22:56:06.233550000 : 8=FIXT.1.19=28835=X49=Coinbase56=24ab46f784d1b20db435b852086e325034=2850=TEST52=20250410-22:56:06.125343369=2262=4f9e712e-7ce4-4e8c-aa34-3f64600137ce268=1279=2269=0278=2ec1c04d-f4f5-4473-b2ce-1d1cdc8d9e3283=159735932155=BTC-USD270=3.88271=0.0000000060=20250410-22:56:06.12342458=FILLED10=089
20250410-22:56:06.326622000 : 8=FIXT.1.19=11835=549=Coinbase56=24ab46f784d1b20db435b852086e325034=2950=TEST52=20250410-22:56:06.220341369=258=CLIENT_LOGOUT10=003
20250410-22:58:12.951365000 : 8=FIXT.1.19=21535=A34=149=24ab46f784d1b20db435b852086e325052=20250410-22:58:12.94456=Coinbase95=4496=5lGDhC2f0OdYNlvhbRew1bFsdhAgXRvR3z3x3MPfAmc=98=0108=30141=Y553=24ab46f784d1b20db435b852086e3250554=akmwnltyfgb1137=910=092
20250410-22:58:13.204750000 : 8=FIXT.1.19=12535=A49=Coinbase56=24ab46f784d1b20db435b852086e325034=150=TEST52=20250410-22:58:13.095458369=198=0108=30141=Y1137=910=203
20250410-22:58:14.216094000 : 8=FIXT.1.19=17835=V34=249=24ab46f784d1b20db435b852086e325052=20250410-22:58:14.21556=Coinbase1128=9146=155=BTC-USD262=cf1c957f-e1dc-4130-bd81-966e629da3c6263=1264=0267=2269=0269=110=115
20250410-22:58:14.501584000 : 8=FIXT.1.19=28135=X49=Coinbase56=24ab46f784d1b20db435b852086e325034=250=TEST52=20250410-22:58:14.366135369=2262=cf1c957f-e1dc-4130-bd81-966e629da3c6268=1279=0269=083=159736175955=BTC-USD270=3.48271=0.6214689360=20250410-22:58:14.36488640=237=628b4f25-c269-4093-9366-675e42d945d310=070
20250410-22:58:14.503004000 : 8=FIXT.1.19=27735=X49=Coinbase56=24ab46f784d1b20db435b852086e325034=350=TEST52=20250410-22:58:14.366142369=2262=cf1c957f-e1dc-4130-bd81-966e629da3c6268=1279=0269=0278=628b4f25-c269-4093-9366-675e42d945d383=159736176055=BTC-USD270=3.48271=0.6214689360=20250410-22:58:14.36488610=165
20250410-22:58:14.661273000 : 8=FIXT.1.19=27635=X49=Coinbase56=24ab46f784d1b20db435b852086e325034=450=TEST52=20250410-22:58:14.552553369=2262=cf1c957f-e1dc-4130-bd81-966e629da3c6268=1279=0269=083=159736176155=BTC-USD29004=2.208895536660=20250410-22:58:14.55081640=137=3b54020b-242f-424f-b156-e35eac57b86310=005
20250410-22:58:14.661872000 : 8=FIXT.1.19=32435=X49=Coinbase56=24ab46f784d1b20db435b852086e325034=550=TEST52=20250410-22:58:14.552564369=2262=cf1c957f-e1dc-4130-bd81-966e629da3c6268=1279=0269=2278=b9704cf1-f180-4d92-90da-6bb364d4a71583=159736176255=BTC-USD270=3.54271=0.6239817960=20250410-22:58:14.55081637=3b54020b-242f-424f-b156-e35eac57b8635797=110=112
20250410-22:58:14.662349000 : 8=FIXT.1.19=26335=X49=Coinbase56=24ab46f784d1b20db435b852086e325034=650=TEST52=20250410-22:58:14.552568369=2262=cf1c957f-e1dc-4130-bd81-966e629da3c6268=1279=2269=0278=3b54020b-242f-424f-b156-e35eac57b86383=159736176355=BTC-USD60=20250410-22:58:14.55081658=FILLED10=027
20250410-22:58:14.688680000 : 8=FIXT.1.19=27235=X49=Coinbase56=24ab46f784d1b20db435b852086e325034=750=TEST52=20250410-22:58:14.579846369=2262=cf1c957f-e1dc-4130-bd81-966e629da3c6268=1279=0269=183=159736176455=BTC-USD271=0.6232294660=20250410-22:58:14.57858940=137=6a8c57f6-feb3-439e-975a-c0a2b7cbde9e10=139
20250410-22:58:14.688988000 : 8=FIXT.1.19=32435=X49=Coinbase56=24ab46f784d1b20db435b852086e325034=850=TEST52=20250410-22:58:14.579855369=2262=cf1c957f-e1dc-4130-bd81-966e629da3c6268=1279=0269=2278=4d60a78e-b39b-420e-b830-bc0f3f4fdde283=159736176555=BTC-USD270=3.53271=0.6232294660=20250410-22:58:14.57858937=6a8c57f6-feb3-439e-975a-c0a2b7cbde9e5797=210=128
20250410-22:58:14.689447000 : 8=FIXT.1.19=27835=X49=Coinbase56=24ab46f784d1b20db435b852086e325034=950=TEST52=20250410-22:58:14.579859369=2262=cf1c957f-e1dc-4130-bd81-966e629da3c6268=1279=2269=1278=6a8c57f6-feb3-439e-975a-c0a2b7cbde9e83=159736176655=BTC-USD271=0.0000000060=20250410-22:58:14.57858958=FILLED10=056
20250410-22:58:15.059386000 : 8=FIXT.1.19=27735=X49=Coinbase56=24ab46f784d1b20db435b852086e325034=1050=TEST52=20250410-22:58:14.950932369=2262=cf1c957f-e1dc-4130-bd81-966e629da3c6268=1279=0269=083=159736176755=BTC-USD29004=2.208895536660=20250410-22:58:14.94976640=137=7e329d79-cc5d-4769-831c-7e819003da4010=057
20250410-22:58:15.059835000 : 8=FIXT.1.19=32535=X49=Coinbase56=24ab46f784d1b20db435b852086e325034=1150=TEST52=20250410-22:58:14.950990369=2262=cf1c957f-e1dc-4130-bd81-966e629da3c6268=1279=0269=2278=b9704cf1-f180-4d92-90da-6bb364d4a71583=159736176855=BTC-USD270=3.54271=0.6239817960=20250410-22:58:14.94976637=7e329d79-cc5d-4769-831c-7e819003da405797=110=166
20250410-22:58:15.060114000 : 8=FIXT.1.19=26435=X49=Coinbase56=24ab46f784d1b20db435b852086e325034=1250=TEST52=20250410-22:58:14.950996369=2262=cf1c957f-e1dc-4130-bd81-966e629da3c6268=1279=2269=0278=7e329d79-cc5d-4769-831c-7e819003da4083=159736176955=BTC-USD60=20250410-22:58:14.94976658=FILLED10=083
20250410-22:58:15.088959000 : 8=FIXT.1.19=27335=X49=Coinbase56=24ab46f784d1b20db435b852086e325034=1350=TEST52=20250410-22:58:14.980566369=2262=cf1c957f-e1dc-4130-bd81-966e629da3c6268=1279=0269=183=159736177055=BTC-USD271=0.6232294660=20250410-22:58:14.97857040=137=5fd55ea0-395e-4863-926d-02e0ec4cc9c510=228
20250410-22:58:15.089375000 : 8=FIXT.1.19=32535=X49=Coinbase56=24ab46f784d1b20db435b852086e325034=1450=TEST52=20250410-22:58:14.980575369=2262=cf1c957f-e1dc-4130-bd81-966e629da3c6268=1279=0269=2278=4d60a78e-b39b-420e-b830-bc0f3f4fdde283=159736177155=BTC-USD270=3.53271=0.6232294660=20250410-22:58:14.97857037=5fd55ea0-395e-4863-926d-02e0ec4cc9c55797=210=217
20250410-22:58:15.089559000 : 8=FIXT.1.19=27935=X49=Coinbase56=24ab46f784d1b20db435b852086e325034=1550=TEST52=20250410-22:58:14.980580369=2262=cf1c957f-e1dc-4130-bd81-966e629da3c6268=1279=2269=1278=5fd55ea0-395e-4863-926d-02e0ec4cc9c583=159736177255=BTC-USD271=0.0000000060=20250410-22:58:14.97857058=FILLED10=137
20250410-22:58:15.516054000 : 8=FIXT.1.19=27735=X49=Coinbase56=24ab46f784d1b20db435b852086e325034=1650=TEST52=20250410-22:58:15.408065369=2262=cf1c957f-e1dc-4130-bd81-966e629da3c6268=1279=0269=083=159736177355=BTC-USD29004=2.208895536660=20250410-22:58:15.40655940=137=ed62f742-6a5b-4f23-973c-2a672a53d53710=082
20250410-22:58:15.516452000 : 8=FIXT.1.19=32535=X49=Coinbase56=24ab46f784d1b20db435b852086e325034=1750=TEST52=20250410-22:58:15.408074369=2262=cf1c957f-e1dc-4130-bd81-966e629da3c6268=1279=0269=2278=b9704cf1-f180-4d92-90da-6bb364d4a71583=159736177455=BTC-USD270=3.54271=0.6239817960=20250410-22:58:15.40655937=ed62f742-6a5b-4f23-973c-2a672a53d5375797=110=187
20250410-22:58:15.516787000 : 8=FIXT.1.19=26435=X49=Coinbase56=24ab46f784d1b20db435b852086e325034=1850=TEST52=20250410-22:58:15.408078369=2262=cf1c957f-e1dc-4130-bd81-966e629da3c6268=1279=2269=0278=ed62f742-6a5b-4f23-973c-2a672a53d53783=159736177555=BTC-USD60=20250410-22:58:15.40655958=FILLED10=102
20250410-22:58:15.546036000 : 8=FIXT.1.19=27335=X49=Coinbase56=24ab46f784d1b20db435b852086e325034=1950=TEST52=20250410-22:58:15.437086369=2262=cf1c957f-e1dc-4130-bd81-966e629da3c6268=1279=0269=183=159736177655=BTC-USD271=0.6232294660=20250410-22:58:15.43515540=137=6bc56c4a-223f-43a3-8184-821dedd1162a10=152
20250410-22:58:15.546255000 : 8=FIXT.1.19=32535=X49=Coinbase56=24ab46f784d1b20db435b852086e325034=2050=TEST52=20250410-22:58:15.437094369=2262=cf1c957f-e1dc-4130-bd81-966e629da3c6268=1279=0269=2278=4d60a78e-b39b-420e-b830-bc0f3f4fdde283=159736177755=BTC-USD270=3.53271=0.6232294660=20250410-22:58:15.43515537=6bc56c4a-223f-43a3-8184-821dedd1162a5797=210=131
20250410-22:58:15.546532000 : 8=FIXT.1.19=27935=X49=Coinbase56=24ab46f784d1b20db435b852086e325034=2150=TEST52=20250410-22:58:15.437098369=2262=cf1c957f-e1dc-4130-bd81-966e629da3c6268=1279=2269=1278=6bc56c4a-223f-43a3-8184-821dedd1162a83=159736177855=BTC-USD271=0.0000000060=20250410-22:58:15.43515558=FILLED10=059
20250410-22:58:15.859281000 : 8=FIXT.1.19=27735=X49=Coinbase56=24ab46f784d1b20db435b852086e325034=2250=TEST52=20250410-22:58:15.751149369=2262=cf1c957f-e1dc-4130-bd81-966e629da3c6268=1279=0269=083=159736177955=BTC-USD29004=2.208895536660=20250410-22:58:15.74996940=137=938fdd87-425e-4c94-980a-ccdc5567f08210=174
20250410-22:58:15.860410000 : 8=FIXT.1.19=32535=X49=Coinbase56=24ab46f784d1b20db435b852086e325034=2350=TEST52=20250410-22:58:15.751156369=2262=cf1c957f-e1dc-4130-bd81-966e629da3c6268=1279=0269=2278=b9704cf1-f180-4d92-90da-6bb364d4a71583=159736178055=BTC-USD270=3.54271=0.6239817960=20250410-22:58:15.74996937=938fdd87-425e-4c94-980a-ccdc5567f0825797=110=012
20250410-22:58:15.860682000 : 8=FIXT.1.19=26435=X49=Coinbase56=24ab46f784d1b20db435b852086e325034=2450=TEST52=20250410-22:58:15.751161369=2262=cf1c957f-e1dc-4130-bd81-966e629da3c6268=1279=2269=0278=938fdd87-425e-4c94-980a-ccdc5567f08283=159736178155=BTC-USD60=20250410-22:58:15.74996958=FILLED10=175
20250410-22:58:15.892564000 : 8=FIXT.1.19=27335=X49=Coinbase56=24ab46f784d1b20db435b852086e325034=2550=TEST52=20250410-22:58:15.784402369=2262=cf1c957f-e1dc-4130-bd81-966e629da3c6268=1279=0269=183=159736178255=BTC-USD271=0.6232294660=20250410-22:58:15.78321340=137=8be03ef9-0abc-4fcc-a337-5bd6d90a15da10=178
20250410-22:58:15.893044000 : 8=FIXT.1.19=32535=X49=Coinbase56=24ab46f784d1b20db435b852086e325034=2650=TEST52=20250410-22:58:15.784408369=2262=cf1c957f-e1dc-4130-bd81-966e629da3c6268=1279=0269=2278=4d60a78e-b39b-420e-b830-bc0f3f4fdde283=159736178355=BTC-USD270=3.53271=0.6232294660=20250410-22:58:15.78321337=8be03ef9-0abc-4fcc-a337-5bd6d90a15da5797=210=173
20250410-22:58:15.893364000 : 8=FIXT.1.19=27935=X49=Coinbase56=24ab46f784d1b20db435b852086e325034=2750=TEST52=20250410-22:58:15.784413369=2262=cf1c957f-e1dc-4130-bd81-966e629da3c6268=1279=2269=1278=8be03ef9-0abc-4fcc-a337-5bd6d90a15da83=159736178455=BTC-USD271=0.0000000060=20250410-22:58:15.78321358=FILLED10=093
20250410-22:58:16.234819000 : 8=FIXT.1.19=28235=X49=Coinbase56=24ab46f784d1b20db435b852086e325034=2850=TEST52=20250410-22:58:16.124511369=2262=cf1c957f-e1dc-4130-bd81-966e629da3c6268=1279=0269=183=159736178555=BTC-USD270=3.18271=0.6232294660=20250410-22:58:16.12359640=237=e77399ae-b07a-4819-a111-71feae4ee71510=117
20250410-22:58:16.237301000 : 8=FIXT.1.19=32535=X49=Coinbase56=24ab46f784d1b20db435b852086e325034=2950=TEST52=20250410-22:58:16.124637369=2262=cf1c957f-e1dc-4130-bd81-966e629da3c6268=1279=0269=2278=4d60a78e-b39b-420e-b830-bc0f3f4fdde283=159736178655=BTC-USD270=3.53271=0.6232294660=20250410-22:58:16.12359637=e77399ae-b07a-4819-a111-71feae4ee7155797=210=209
20250410-22:58:16.239144000 : 8=FIXT.1.19=28835=X49=Coinbase56=24ab46f784d1b20db435b852086e325034=3050=TEST52=20250410-22:58:16.124672369=2262=cf1c957f-e1dc-4130-bd81-966e629da3c6268=1279=2269=1278=e77399ae-b07a-4819-a111-71feae4ee71583=159736178755=BTC-USD270=3.18271=0.0000000060=20250410-22:58:16.12359658=FILLED10=028
20250410-22:58:16.716555000 : 8=FIXT.1.19=27735=X49=Coinbase56=24ab46f784d1b20db435b852086e325034=3150=TEST52=20250410-22:58:16.607970369=2262=cf1c957f-e1dc-4130-bd81-966e629da3c6268=1279=0269=083=159736178855=BTC-USD29004=2.208895536660=20250410-22:58:16.60656340=137=a1f34149-3351-4e2d-908f-469c3317139210=151
20250410-22:58:16.717140000 : 8=FIXT.1.19=32535=X49=Coinbase56=24ab46f784d1b20db435b852086e325034=3250=TEST52=20250410-22:58:16.607980369=2262=cf1c957f-e1dc-4130-bd81-966e629da3c6268=1279=0269=2278=b9704cf1-f180-4d92-90da-6bb364d4a71583=159736178955=BTC-USD270=3.54271=0.6239817960=20250410-22:58:16.60656337=a1f34149-3351-4e2d-908f-469c331713925797=110=001
20250410-22:58:16.717481000 : 8=FIXT.1.19=26435=X49=Coinbase56=24ab46f784d1b20db435b852086e325034=3350=TEST52=20250410-22:58:16.607985369=2262=cf1c957f-e1dc-4130-bd81-966e629da3c6268=1279=2269=0278=a1f34149-3351-4e2d-908f-469c3317139283=159736179055=BTC-USD60=20250410-22:58:16.60656358=FILLED10=164
20250410-22:58:16.750301000 : 8=FIXT.1.19=27335=X49=Coinbase56=24ab46f784d1b20db435b852086e325034=3450=TEST52=20250410-22:58:16.638514369=2262=cf1c957f-e1dc-4130-bd81-966e629da3c6268=1279=0269=183=159736179155=BTC-USD271=0.6232294660=20250410-22:58:16.63709440=137=f193b908-a6c8-4497-8443-958efd9d4b6910=113
20250410-22:58:16.750627000 : 8=FIXT.1.19=32535=X49=Coinbase56=24ab46f784d1b20db435b852086e325034=3550=TEST52=20250410-22:58:16.638523369=2262=cf1c957f-e1dc-4130-bd81-966e629da3c6268=1279=0269=2278=4d60a78e-b39b-420e-b830-bc0f3f4fdde283=159736179255=BTC-USD270=3.53271=0.6232294660=20250410-22:58:16.63709437=f193b908-a6c8-4497-8443-958efd9d4b695797=210=102
20250410-22:58:16.751041000 : 8=FIXT.1.19=27935=X49=Coinbase56=24ab46f784d1b20db435b852086e325034=3650=TEST52=20250410-22:58:16.638527369=2262=cf1c957f-e1dc-4130-bd81-966e629da3c6268=1279=2269=1278=f193b908-a6c8-4497-8443-958efd9d4b6983=159736179355=BTC-USD271=0.0000000060=20250410-22:58:16.63709458=FILLED10=030
20250410-22:58:16.978715000 : 8=FIXT.1.19=27735=X49=Coinbase56=24ab46f784d1b20db435b852086e325034=3750=TEST52=20250410-22:58:16.837933369=2262=cf1c957f-e1dc-4130-bd81-966e629da3c6268=1279=0269=083=159736179455=BTC-USD29004=2.208895536660=20250410-22:58:16.83597740=137=dcfa1211-d2a0-452e-b8a0-2b130d08112910=111
20250410-22:58:16.994484000 : 8=FIXT.1.19=32535=X49=Coinbase56=24ab46f784d1b20db435b852086e325034=3850=TEST52=20250410-22:58:16.837942369=2262=cf1c957f-e1dc-4130-bd81-966e629da3c6268=1279=0269=2278=b9704cf1-f180-4d92-90da-6bb364d4a71583=159736179555=BTC-USD270=3.54271=0.6239817960=20250410-22:58:16.83597737=dcfa1211-d2a0-452e-b8a0-2b130d0811295797=110=216
20250410-22:58:16.997570000 : 8=FIXT.1.19=26435=X49=Coinbase56=24ab46f784d1b20db435b852086e325034=3950=TEST52=20250410-22:58:16.837946369=2262=cf1c957f-e1dc-4130-bd81-966e629da3c6268=1279=2269=0278=dcfa1211-d2a0-452e-b8a0-2b130d08112983=159736179655=BTC-USD60=20250410-22:58:16.83597758=FILLED10=131
20250410-22:58:17.010313000 : 8=FIXT.1.19=27335=X49=Coinbase56=24ab46f784d1b20db435b852086e325034=4050=TEST52=20250410-22:58:16.865266369=2262=cf1c957f-e1dc-4130-bd81-966e629da3c6268=1279=0269=183=159736179755=BTC-USD271=0.6232294660=20250410-22:58:16.86378340=137=db84146c-09b6-4324-97f0-303cf9f94e8010=098
20250410-22:58:17.011626000 : 8=FIXT.1.19=32535=X49=Coinbase56=24ab46f784d1b20db435b852086e325034=4150=TEST52=20250410-22:58:16.865274369=2262=cf1c957f-e1dc-4130-bd81-966e629da3c6268=1279=0269=2278=4d60a78e-b39b-420e-b830-bc0f3f4fdde283=159736179855=BTC-USD270=3.53271=0.6232294660=20250410-22:58:16.86378337=db84146c-09b6-4324-97f0-303cf9f94e805797=210=086
20250410-22:58:17.014839000 : 8=FIXT.1.19=27935=X49=Coinbase56=24ab46f784d1b20db435b852086e325034=4250=TEST52=20250410-22:58:16.865278369=2262=cf1c957f-e1dc-4130-bd81-966e629da3c6268=1279=2269=1278=db84146c-09b6-4324-97f0-303cf9f94e8083=159736179955=BTC-USD271=0.0000000060=20250410-22:58:16.86378358=FILLED10=014
20250410-22:58:17.235434000 : 8=FIXT.1.19=28235=X49=Coinbase56=24ab46f784d1b20db435b852086e325034=4350=TEST52=20250410-22:58:17.127579369=2262=cf1c957f-e1dc-4130-bd81-966e629da3c6268=1279=0269=083=159736180055=BTC-USD270=3.88271=0.6232294660=20250410-22:58:17.12586640=237=236db244-60cd-4f98-9d3e-cdfb70fd02ec10=013
20250410-22:58:17.235874000 : 8=FIXT.1.19=32535=X49=Coinbase56=24ab46f784d1b20db435b852086e325034=4450=TEST52=20250410-22:58:17.127587369=2262=cf1c957f-e1dc-4130-bd81-966e629da3c6268=1279=0269=2278=b9704cf1-f180-4d92-90da-6bb364d4a71583=159736180155=BTC-USD270=3.54271=0.6232294660=20250410-22:58:17.12586637=236db244-60cd-4f98-9d3e-cdfb70fd02ec5797=110=158
20250410-22:58:17.236316000 : 8=FIXT.1.19=28835=X49=Coinbase56=24ab46f784d1b20db435b852086e325034=4550=TEST52=20250410-22:58:17.127635369=2262=cf1c957f-e1dc-4130-bd81-966e629da3c6268=1279=2269=0278=236db244-60cd-4f98-9d3e-cdfb70fd02ec83=159736180255=BTC-USD270=3.88271=0.0000000060=20250410-22:58:17.12586658=FILLED10=174
20250410-22:58:17.290105000 : 8=FIXT.1.19=27735=X49=Coinbase56=24ab46f784d1b20db435b852086e325034=4650=TEST52=20250410-22:58:17.181361369=2262=cf1c957f-e1dc-4130-bd81-966e629da3c6268=1279=0269=083=159736180355=BTC-USD29004=2.208895536660=20250410-22:58:17.17928640=137=8800f0cf-4fcc-4aec-9bac-29bd0207e30b10=094
20250410-22:58:17.290541000 : 8=FIXT.1.19=32535=X49=Coinbase56=24ab46f784d1b20db435b852086e325034=4750=TEST52=20250410-22:58:17.181369369=2262=cf1c957f-e1dc-4130-bd81-966e629da3c6268=1279=0269=2278=b9704cf1-f180-4d92-90da-6bb364d4a71583=159736180455=BTC-USD270=3.54271=0.6239817960=20250410-22:58:17.17928637=8800f0cf-4fcc-4aec-9bac-29bd0207e30b5797=110=207
20250410-22:58:17.290799000 : 8=FIXT.1.19=26435=X49=Coinbase56=24ab46f784d1b20db435b852086e325034=4850=TEST52=20250410-22:58:17.181373369=2262=cf1c957f-e1dc-4130-bd81-966e629da3c6268=1279=2269=0278=8800f0cf-4fcc-4aec-9bac-29bd0207e30b83=159736180555=BTC-USD60=20250410-22:58:17.17928658=FILLED10=113
20250410-22:58:17.316640000 : 8=FIXT.1.19=27335=X49=Coinbase56=24ab46f784d1b20db435b852086e325034=4950=TEST52=20250410-22:58:17.208458369=2262=cf1c957f-e1dc-4130-bd81-966e629da3c6268=1279=0269=183=159736180655=BTC-USD271=0.6214689360=20250410-22:58:17.20725440=137=3e102430-d468-4815-806a-94260523cd5510=129
20250410-22:58:17.317042000 : 8=FIXT.1.19=32535=X49=Coinbase56=24ab46f784d1b20db435b852086e325034=5050=TEST52=20250410-22:58:17.208463369=2262=cf1c957f-e1dc-4130-bd81-966e629da3c6268=1279=0269=2278=4d60a78e-b39b-420e-b830-bc0f3f4fdde283=159736180755=BTC-USD270=3.53271=0.6214689360=20250410-22:58:17.20725437=3e102430-d468-4815-806a-94260523cd555797=210=105
20250410-22:58:17.317457000 : 8=FIXT.1.19=27935=X49=Coinbase56=24ab46f784d1b20db435b852086e325034=5150=TEST52=20250410-22:58:17.208467369=2262=cf1c957f-e1dc-4130-bd81-966e629da3c6268=1279=2269=1278=3e102430-d468-4815-806a-94260523cd5583=159736180855=BTC-USD271=0.0000000060=20250410-22:58:17.20725458=FILLED10=028
20250410-22:58:17.484030000 : 8=FIXT.1.19=28235=X49=Coinbase56=24ab46f784d1b20db435b852086e325034=5250=TEST52=20250410-22:58:17.373598369=2262=cf1c957f-e1dc-4130-bd81-966e629da3c6268=1279=0269=083=159736180955=BTC-USD270=3.72271=0.6232294660=20250410-22:58:17.37209440=237=4dcfab90-e04a-4542-a363-7233265c9def10=120
20250410-22:58:17.484575000 : 8=FIXT.1.19=32535=X49=Coinbase56=24ab46f784d1b20db435b852086e325034=5350=TEST52=20250410-22:58:17.373607369=2262=cf1c957f-e1dc-4130-bd81-966e629da3c6268=1279=0269=2278=b9704cf1-f180-4d92-90da-6bb364d4a71583=159736181055=BTC-USD270=3.54271=0.6232294660=20250410-22:58:17.37209437=4dcfab90-e04a-4542-a363-7233265c9def5797=110=255
20250410-22:58:17.485285000 : 8=FIXT.1.19=28835=X49=Coinbase56=24ab46f784d1b20db435b852086e325034=5450=TEST52=20250410-22:58:17.373611369=2262=cf1c957f-e1dc-4130-bd81-966e629da3c6268=1279=2269=0278=4dcfab90-e04a-4542-a363-7233265c9def83=159736181155=BTC-USD270=3.72271=0.0000000060=20250410-22:58:17.37209458=FILLED10=009
20250410-22:58:17.517551000 : 8=FIXT.1.19=27735=X49=Coinbase56=24ab46f784d1b20db435b852086e325034=5550=TEST52=20250410-22:58:17.408263369=2262=cf1c957f-e1dc-4130-bd81-966e629da3c6268=1279=0269=083=159736181255=BTC-USD29004=2.208895536660=20250410-22:58:17.40664540=137=24bf63e1-2974-4691-9b9c-204ca40c18ba10=069
20250410-22:58:17.518180000 : 8=FIXT.1.19=32535=X49=Coinbase56=24ab46f784d1b20db435b852086e325034=5650=TEST52=20250410-22:58:17.408270369=2262=cf1c957f-e1dc-4130-bd81-966e629da3c6268=1279=0269=2278=b9704cf1-f180-4d92-90da-6bb364d4a71583=159736181355=BTC-USD270=3.54271=0.6239817960=20250410-22:58:17.40664537=24bf63e1-2974-4691-9b9c-204ca40c18ba5797=110=172
20250410-22:58:17.518613000 : 8=FIXT.1.19=26435=X49=Coinbase56=24ab46f784d1b20db435b852086e325034=5750=TEST52=20250410-22:58:17.408275369=2262=cf1c957f-e1dc-4130-bd81-966e629da3c6268=1279=2269=0278=24bf63e1-2974-4691-9b9c-204ca40c18ba83=159736181455=BTC-USD60=20250410-22:58:17.40664558=FILLED10=088
20250410-22:58:17.531804000 : 8=FIXT.1.19=28135=X49=Coinbase56=24ab46f784d1b20db435b852086e325034=5850=TEST52=20250410-22:58:17.423869369=2262=cf1c957f-e1dc-4130-bd81-966e629da3c6268=1279=0269=183=159736181555=BTC-USD270=3.2271=0.6232294660=20250410-22:58:17.42191140=237=2dc89a7e-ca7f-4b9c-b78c-66a80cacc07710=011
20250410-22:58:17.532172000 : 8=FIXT.1.19=32535=X49=Coinbase56=24ab46f784d1b20db435b852086e325034=5950=TEST52=20250410-22:58:17.423875369=2262=cf1c957f-e1dc-4130-bd81-966e629da3c6268=1279=0269=2278=4d60a78e-b39b-420e-b830-bc0f3f4fdde283=159736181655=BTC-USD270=3.53271=0.6232294660=20250410-22:58:17.42191137=2dc89a7e-ca7f-4b9c-b78c-66a80cacc0775797=210=147
20250410-22:58:17.532469000 : 8=FIXT.1.19=28735=X49=Coinbase56=24ab46f784d1b20db435b852086e325034=6050=TEST52=20250410-22:58:17.423879369=2262=cf1c957f-e1dc-4130-bd81-966e629da3c6268=1279=2269=1278=2dc89a7e-ca7f-4b9c-b78c-66a80cacc07783=159736181755=BTC-USD270=3.2271=0.0000000060=20250410-22:58:17.42191158=FILLED10=171
20250410-22:58:17.544864000 : 8=FIXT.1.19=27335=X49=Coinbase56=24ab46f784d1b20db435b852086e325034=6150=TEST52=20250410-22:58:17.436162369=2262=cf1c957f-e1dc-4130-bd81-966e629da3c6268=1279=0269=183=159736181855=BTC-USD271=0.6232294660=20250410-22:58:17.43522540=137=bf327e5b-a3da-4eb6-861d-14db7a1b731810=034
20250410-22:58:17.545316000 : 8=FIXT.1.19=32535=X49=Coinbase56=24ab46f784d1b20db435b852086e325034=6250=TEST52=20250410-22:58:17.436167369=2262=cf1c957f-e1dc-4130-bd81-966e629da3c6268=1279=0269=2278=4d60a78e-b39b-420e-b830-bc0f3f4fdde283=159736181955=BTC-USD270=3.53271=0.6232294660=20250410-22:58:17.43522537=bf327e5b-a3da-4eb6-861d-14db7a1b73185797=210=028
20250410-22:58:17.545524000 : 8=FIXT.1.19=27935=X49=Coinbase56=24ab46f784d1b20db435b852086e325034=6350=TEST52=20250410-22:58:17.436171369=2262=cf1c957f-e1dc-4130-bd81-966e629da3c6268=1279=2269=1278=bf327e5b-a3da-4eb6-861d-14db7a1b731883=159736182055=BTC-USD271=0.0000000060=20250410-22:58:17.43522558=FILLED10=194
20250410-22:58:17.593077000 : 8=FIXT.1.19=28235=X49=Coinbase56=24ab46f784d1b20db435b852086e325034=6450=TEST52=20250410-22:58:17.482905369=2262=cf1c957f-e1dc-4130-bd81-966e629da3c6268=1279=0269=183=159736182155=BTC-USD270=3.22271=0.6232294660=20250410-22:58:17.48090040=237=6181e6c3-114f-45e7-a4c3-5e791464605a10=174
20250410-22:58:17.593549000 : 8=FIXT.1.19=32535=X49=Coinbase56=24ab46f784d1b20db435b852086e325034=6550=TEST52=20250410-22:58:17.482914369=2262=cf1c957f-e1dc-4130-bd81-966e629da3c6268=1279=0269=2278=4d60a78e-b39b-420e-b830-bc0f3f4fdde283=159736182255=BTC-USD270=3.53271=0.6232294660=20250410-22:58:17.48090037=6181e6c3-114f-45e7-a4c3-5e791464605a5797=210=006
20250410-22:58:17.593735000 : 8=FIXT.1.19=28835=X49=Coinbase56=24ab46f784d1b20db435b852086e325034=6650=TEST52=20250410-22:58:17.482918369=2262=cf1c957f-e1dc-4130-bd81-966e629da3c6268=1279=2269=1278=6181e6c3-114f-45e7-a4c3-5e791464605a83=159736182355=BTC-USD270=3.22271=0.0000000060=20250410-22:58:17.48090058=FILLED10=090
20250410-22:58:17.645069000 : 8=FIXT.1.19=28235=X49=Coinbase56=24ab46f784d1b20db435b852086e325034=6750=TEST52=20250410-22:58:17.537178369=2262=cf1c957f-e1dc-4130-bd81-966e629da3c6268=1279=0269=083=159736182455=BTC-USD270=3.72271=0.6232294660=20250410-22:58:17.53553340=237=82c3742e-d795-46b9-88aa-11d22f12631610=193
20250410-22:58:17.645475000 : 8=FIXT.1.19=32535=X49=Coinbase56=24ab46f784d1b20db435b852086e325034=6850=TEST52=20250410-22:58:17.537186369=2262=cf1c957f-e1dc-4130-bd81-966e629da3c6268=1279=0269=2278=b9704cf1-f180-4d92-90da-6bb364d4a71583=159736182555=BTC-USD270=3.54271=0.6232294660=20250410-22:58:17.53553337=82c3742e-d795-46b9-88aa-11d22f1263165797=110=089
20250410-22:58:17.645663000 : 8=FIXT.1.19=28835=X49=Coinbase56=24ab46f784d1b20db435b852086e325034=6950=TEST52=20250410-22:58:17.537189369=2262=cf1c957f-e1dc-4130-bd81-966e629da3c6268=1279=2269=0278=82c3742e-d795-46b9-88aa-11d22f12631683=159736182655=BTC-USD270=3.72271=0.0000000060=20250410-22:58:17.53553358=FILLED10=107
20250410-22:58:17.705073000 : 8=FIXT.1.19=28235=X49=Coinbase56=24ab46f784d1b20db435b852086e325034=7050=TEST52=20250410-22:58:17.596090369=2262=cf1c957f-e1dc-4130-bd81-966e629da3c6268=1279=0269=183=159736182755=BTC-USD270=3.36271=0.6214689360=20250410-22:58:17.59450640=237=a8c1bd34-1adf-49cd-b938-756639fab4a810=236
20250410-22:58:17.705698000 : 8=FIXT.1.19=32535=X49=Coinbase56=24ab46f784d1b20db435b852086e325034=7150=TEST52=20250410-22:58:17.596150369=2262=cf1c957f-e1dc-4130-bd81-966e629da3c6268=1279=0269=2278=4d60a78e-b39b-420e-b830-bc0f3f4fdde283=159736182855=BTC-USD270=3.53271=0.6214689360=20250410-22:58:17.59450637=a8c1bd34-1adf-49cd-b938-756639fab4a85797=210=060
20250410-22:58:17.706455000 : 8=FIXT.1.19=28835=X49=Coinbase56=24ab46f784d1b20db435b852086e325034=7250=TEST52=20250410-22:58:17.596158369=2262=cf1c957f-e1dc-4130-bd81-966e629da3c6268=1279=2269=1278=a8c1bd34-1adf-49cd-b938-756639fab4a883=159736182955=BTC-USD270=3.36271=0.0000000060=20250410-22:58:17.59450658=FILLED10=148
20250410-22:58:17.760318000 : 8=FIXT.1.19=28235=X49=Coinbase56=24ab46f784d1b20db435b852086e325034=7350=TEST52=20250410-22:58:17.652251369=2262=cf1c957f-e1dc-4130-bd81-966e629da3c6268=1279=0269=083=159736183055=BTC-USD270=3.86271=0.6214689360=20250410-22:58:17.65036440=237=bffa25bb-e376-4e71-b064-5f514f92a47710=123
20250410-22:58:17.760925000 : 8=FIXT.1.19=32535=X49=Coinbase56=24ab46f784d1b20db435b852086e325034=7450=TEST52=20250410-22:58:17.652259369=2262=cf1c957f-e1dc-4130-bd81-966e629da3c6268=1279=0269=2278=b9704cf1-f180-4d92-90da-6bb364d4a71583=159736183155=BTC-USD270=3.54271=0.6214689360=20250410-22:58:17.65036437=bffa25bb-e376-4e71-b064-5f514f92a4775797=110=023
20250410-22:58:17.761534000 : 8=FIXT.1.19=28835=X49=Coinbase56=24ab46f784d1b20db435b852086e325034=7550=TEST52=20250410-22:58:17.652263369=2262=cf1c957f-e1dc-4130-bd81-966e629da3c6268=1279=2269=0278=bffa25bb-e376-4e71-b064-5f514f92a47783=159736183255=BTC-USD270=3.86271=0.0000000060=20250410-22:58:17.65036458=FILLED10=033
20250410-22:58:17.972911000 : 8=FIXT.1.19=27735=X49=Coinbase56=24ab46f784d1b20db435b852086e325034=7650=TEST52=20250410-22:58:17.864989369=2262=cf1c957f-e1dc-4130-bd81-966e629da3c6268=1279=0269=083=159736183355=BTC-USD29004=2.208895536660=20250410-22:58:17.86370940=137=7f939986-e713-462d-bb75-c8b49beb72ed10=235
20250410-22:58:17.973530000 : 8=FIXT.1.19=32535=X49=Coinbase56=24ab46f784d1b20db435b852086e325034=7750=TEST52=20250410-22:58:17.864998369=2262=cf1c957f-e1dc-4130-bd81-966e629da3c6268=1279=0269=2278=b9704cf1-f180-4d92-90da-6bb364d4a71583=159736183455=BTC-USD270=3.54271=0.6239817960=20250410-22:58:17.86370937=7f939986-e713-462d-bb75-c8b49beb72ed5797=110=084
20250410-22:58:17.973843000 : 8=FIXT.1.19=26435=X49=Coinbase56=24ab46f784d1b20db435b852086e325034=7850=TEST52=20250410-22:58:17.865002369=2262=cf1c957f-e1dc-4130-bd81-966e629da3c6268=1279=2269=0278=7f939986-e713-462d-bb75-c8b49beb72ed83=159736183555=BTC-USD60=20250410-22:58:17.86370958=FILLED10=228
20250410-22:58:18.002652000 : 8=FIXT.1.19=27335=X49=Coinbase56=24ab46f784d1b20db435b852086e325034=7950=TEST52=20250410-22:58:17.893539369=2262=cf1c957f-e1dc-4130-bd81-966e629da3c6268=1279=0269=183=159736183655=BTC-USD271=0.6214689360=20250410-22:58:17.89249640=137=15420910-22ad-434a-8457-8a80d37d611210=202
20250410-22:58:18.003636000 : 8=FIXT.1.19=32535=X49=Coinbase56=24ab46f784d1b20db435b852086e325034=8050=TEST52=20250410-22:58:17.893547369=2262=cf1c957f-e1dc-4130-bd81-966e629da3c6268=1279=0269=2278=4d60a78e-b39b-420e-b830-bc0f3f4fdde283=159736183755=BTC-USD270=3.53271=0.6214689360=20250410-22:58:17.89249637=15420910-22ad-434a-8457-8a80d37d61125797=210=181
20250410-22:58:18.004973000 : 8=FIXT.1.19=27935=X49=Coinbase56=24ab46f784d1b20db435b852086e325034=8150=TEST52=20250410-22:58:17.893551369=2262=cf1c957f-e1dc-4130-bd81-966e629da3c6268=1279=2269=1278=15420910-22ad-434a-8457-8a80d37d611283=159736183855=BTC-USD271=0.0000000060=20250410-22:58:17.89249658=FILLED10=095
20250410-22:58:18.320250000 : 8=FIXT.1.19=27735=X49=Coinbase56=24ab46f784d1b20db435b852086e325034=8250=TEST52=20250410-22:58:18.209249369=2262=cf1c957f-e1dc-4130-bd81-966e629da3c6268=1279=0269=083=159736183955=BTC-USD29004=2.208895536660=20250410-22:58:18.20794040=137=67ff59e4-25a9-494f-a304-1a63c47400a710=042
20250410-22:58:18.320974000 : 8=FIXT.1.19=32535=X49=Coinbase56=24ab46f784d1b20db435b852086e325034=8350=TEST52=20250410-22:58:18.209255369=2262=cf1c957f-e1dc-4130-bd81-966e629da3c6268=1279=0269=2278=b9704cf1-f180-4d92-90da-6bb364d4a71583=159736184055=BTC-USD270=3.54271=0.6239817960=20250410-22:58:18.20794037=67ff59e4-25a9-494f-a304-1a63c47400a75797=110=135
20250410-22:58:18.321443000 : 8=FIXT.1.19=26435=X49=Coinbase56=24ab46f784d1b20db435b852086e325034=8450=TEST52=20250410-22:58:18.209259369=2262=cf1c957f-e1dc-4130-bd81-966e629da3c6268=1279=2269=0278=67ff59e4-25a9-494f-a304-1a63c47400a783=159736184155=BTC-USD60=20250410-22:58:18.20794058=FILLED10=050
20250410-22:58:18.345838000 : 8=FIXT.1.19=27335=X49=Coinbase56=24ab46f784d1b20db435b852086e325034=8550=TEST52=20250410-22:58:18.237569369=2262=cf1c957f-e1dc-4130-bd81-966e629da3c6268=1279=0269=183=159736184255=BTC-USD271=0.6232294660=20250410-22:58:18.23635040=137=1e3203e4-8650-4a30-852f-b3937ac8beac10=159
20250410-22:58:18.346514000 : 8=FIXT.1.19=32535=X49=Coinbase56=24ab46f784d1b20db435b852086e325034=8650=TEST52=20250410-22:58:18.237576369=2262=cf1c957f-e1dc-4130-bd81-966e629da3c6268=1279=0269=2278=4d60a78e-b39b-420e-b830-bc0f3f4fdde283=159736184355=BTC-USD270=3.53271=0.6232294660=20250410-22:58:18.23635037=1e3203e4-8650-4a30-852f-b3937ac8beac5797=210=146
20250410-22:58:18.346776000 : 8=FIXT.1.19=27935=X49=Coinbase56=24ab46f784d1b20db435b852086e325034=8750=TEST52=20250410-22:58:18.237580369=2262=cf1c957f-e1dc-4130-bd81-966e629da3c6268=1279=2269=1278=1e3203e4-8650-4a30-852f-b3937ac8beac83=159736184455=BTC-USD271=0.0000000060=20250410-22:58:18.23635058=FILLED10=065
20250410-22:58:18.490886000 : 8=FIXT.1.19=27735=X49=Coinbase56=24ab46f784d1b20db435b852086e325034=8850=TEST52=20250410-22:58:18.379761369=2262=cf1c957f-e1dc-4130-bd81-966e629da3c6268=1279=0269=083=159736184555=BTC-USD29004=2.208895536660=20250410-22:58:18.37852740=137=1d4ce34c-9ab8-4203-a32b-11ac582598dd10=188
20250410-22:58:18.491481000 : 8=FIXT.1.19=32535=X49=Coinbase56=24ab46f784d1b20db435b852086e325034=8950=TEST52=20250410-22:58:18.379769369=2262=cf1c957f-e1dc-4130-bd81-966e629da3c6268=1279=0269=2278=b9704cf1-f180-4d92-90da-6bb364d4a71583=159736184655=BTC-USD270=3.54271=0.6239817960=20250410-22:58:18.37852737=1d4ce34c-9ab8-4203-a32b-11ac582598dd5797=110=045
20250410-22:58:18.491795000 : 8=FIXT.1.19=26435=X49=Coinbase56=24ab46f784d1b20db435b852086e325034=9050=TEST52=20250410-22:58:18.379774369=2262=cf1c957f-e1dc-4130-bd81-966e629da3c6268=1279=2269=0278=1d4ce34c-9ab8-4203-a32b-11ac582598dd83=159736184755=BTC-USD60=20250410-22:58:18.37852758=FILLED10=199
20250410-22:58:18.515966000 : 8=FIXT.1.19=27335=X49=Coinbase56=24ab46f784d1b20db435b852086e325034=9150=TEST52=20250410-22:58:18.407953369=2262=cf1c957f-e1dc-4130-bd81-966e629da3c6268=1279=0269=183=159736184855=BTC-USD271=0.6232294660=20250410-22:58:18.40665640=137=d311096c-75f8-4294-9e8a-0582b7b1927810=004
20250410-22:58:18.516416000 : 8=FIXT.1.19=32535=X49=Coinbase56=24ab46f784d1b20db435b852086e325034=9250=TEST52=20250410-22:58:18.407961369=2262=cf1c957f-e1dc-4130-bd81-966e629da3c6268=1279=0269=2278=4d60a78e-b39b-420e-b830-bc0f3f4fdde283=159736184955=BTC-USD270=3.53271=0.6232294660=20250410-22:58:18.40665637=d311096c-75f8-4294-9e8a-0582b7b192785797=210=248
20250410-22:58:18.516672000 : 8=FIXT.1.19=27935=X49=Coinbase56=24ab46f784d1b20db435b852086e325034=9350=TEST52=20250410-22:58:18.407964369=2262=cf1c957f-e1dc-4130-bd81-966e629da3c6268=1279=2269=1278=d311096c-75f8-4294-9e8a-0582b7b1927883=159736185055=BTC-USD271=0.0000000060=20250410-22:58:18.40665658=FILLED10=166
20250410-22:58:18.661192000 : 8=FIXT.1.19=27735=X49=Coinbase56=24ab46f784d1b20db435b852086e325034=9450=TEST52=20250410-22:58:18.551865369=2262=cf1c957f-e1dc-4130-bd81-966e629da3c6268=1279=0269=083=159736185155=BTC-USD29004=2.208895536660=20250410-22:58:18.55008040=137=014f7d76-2039-4a39-908d-a795fa00260410=194
20250410-22:58:18.665694000 : 8=FIXT.1.19=32535=X49=Coinbase56=24ab46f784d1b20db435b852086e325034=9550=TEST52=20250410-22:58:18.551871369=2262=cf1c957f-e1dc-4130-bd81-966e629da3c6268=1279=0269=2278=b9704cf1-f180-4d92-90da-6bb364d4a71583=159736185255=BTC-USD270=3.54271=0.6239817960=20250410-22:58:18.55008037=014f7d76-2039-4a39-908d-a795fa0026045797=110=040
20250410-22:58:18.667883000 : 8=FIXT.1.19=26435=X49=Coinbase56=24ab46f784d1b20db435b852086e325034=9650=TEST52=20250410-22:58:18.551876369=2262=cf1c957f-e1dc-4130-bd81-966e629da3c6268=1279=2269=0278=014f7d76-2039-4a39-908d-a795fa00260483=159736185355=BTC-USD60=20250410-22:58:18.55008058=FILLED10=212
20250410-22:58:18.722075000 : 8=FIXT.1.19=27335=X49=Coinbase56=24ab46f784d1b20db435b852086e325034=9750=TEST52=20250410-22:58:18.579863369=2262=cf1c957f-e1dc-4130-bd81-966e629da3c6268=1279=0269=183=159736185455=BTC-USD271=0.6232294660=20250410-22:58:18.57821140=137=5da60808-fcd2-4d38-b351-728d2f29131810=092
20250410-22:58:18.739126000 : 8=FIXT.1.19=32535=X49=Coinbase56=24ab46f784d1b20db435b852086e325034=9850=TEST52=20250410-22:58:18.579879369=2262=cf1c957f-e1dc-4130-bd81-966e629da3c6268=1279=0269=2278=4d60a78e-b39b-420e-b830-bc0f3f4fdde283=159736185555=BTC-USD270=3.53271=0.6232294660=20250410-22:58:18.57821137=5da60808-fcd2-4d38-b351-728d2f2913185797=210=088
20250410-22:58:18.776800000 : 8=FIXT.1.19=27935=X49=Coinbase56=24ab46f784d1b20db435b852086e325034=9950=TEST52=20250410-22:58:18.579883369=2262=cf1c957f-e1dc-4130-bd81-966e629da3c6268=1279=2269=1278=5da60808-fcd2-4d38-b351-728d2f29131883=159736185655=BTC-USD271=0.0000000060=20250410-22:58:18.57821158=FILLED10=007
20250410-22:58:18.830601000 : 8=FIXT.1.19=27835=X49=Coinbase56=24ab46f784d1b20db435b852086e325034=10050=TEST52=20250410-22:58:18.722714369=2262=cf1c957f-e1dc-4130-bd81-966e629da3c6268=1279=0269=083=159736185755=BTC-USD29004=2.208895536660=20250410-22:58:18.72165840=137=9f9e3e2e-fb36-4906-b568-f1d88dc3341010=195
20250410-22:58:18.831209000 : 8=FIXT.1.19=32635=X49=Coinbase56=24ab46f784d1b20db435b852086e325034=10150=TEST52=20250410-22:58:18.722724369=2262=cf1c957f-e1dc-4130-bd81-966e629da3c6268=1279=0269=2278=b9704cf1-f180-4d92-90da-6bb364d4a71583=159736185855=BTC-USD270=3.54271=0.6239817960=20250410-22:58:18.72165837=9f9e3e2e-fb36-4906-b568-f1d88dc334105797=110=045
20250410-22:58:18.831824000 : 8=FIXT.1.19=26535=X49=Coinbase56=24ab46f784d1b20db435b852086e325034=10250=TEST52=20250410-22:58:18.722728369=2262=cf1c957f-e1dc-4130-bd81-966e629da3c6268=1279=2269=0278=9f9e3e2e-fb36-4906-b568-f1d88dc3341083=159736185955=BTC-USD60=20250410-22:58:18.72165858=FILLED10=216
20250410-22:58:18.852769000 : 8=FIXT.1.19=28335=X49=Coinbase56=24ab46f784d1b20db435b852086e325034=10350=TEST52=20250410-22:58:18.744694369=2262=cf1c957f-e1dc-4130-bd81-966e629da3c6268=1279=0269=083=159736186055=BTC-USD270=3.73271=0.6214689360=20250410-22:58:18.74310540=237=e2470aab-0401-4c84-9460-cbe5808f15cb10=108
20250410-22:58:18.853361000 : 8=FIXT.1.19=32635=X49=Coinbase56=24ab46f784d1b20db435b852086e325034=10450=TEST52=20250410-22:58:18.744699369=2262=cf1c957f-e1dc-4130-bd81-966e629da3c6268=1279=0269=2278=b9704cf1-f180-4d92-90da-6bb364d4a71583=159736186155=BTC-USD270=3.54271=0.6214689360=20250410-22:58:18.74310537=e2470aab-0401-4c84-9460-cbe5808f15cb5797=110=009
20250410-22:58:18.853721000 : 8=FIXT.1.19=28935=X49=Coinbase56=24ab46f784d1b20db435b852086e325034=10550=TEST52=20250410-22:58:18.744703369=2262=cf1c957f-e1dc-4130-bd81-966e629da3c6268=1279=2269=0278=e2470aab-0401-4c84-9460-cbe5808f15cb83=159736186255=BTC-USD270=3.73271=0.0000000060=20250410-22:58:18.74310558=FILLED10=006
20250410-22:58:18.854078000 : 8=FIXT.1.19=28335=X49=Coinbase56=24ab46f784d1b20db435b852086e325034=10650=TEST52=20250410-22:58:18.744708369=2262=cf1c957f-e1dc-4130-bd81-966e629da3c6268=1279=0269=083=159736186355=BTC-USD270=3.76271=0.6214689360=20250410-22:58:18.74310540=237=8affaf11-6cac-461f-81fc-3dea6a8050dc10=150
20250410-22:58:18.854613000 : 8=FIXT.1.19=32635=X49=Coinbase56=24ab46f784d1b20db435b852086e325034=10750=TEST52=20250410-22:58:18.744712369=2262=cf1c957f-e1dc-4130-bd81-966e629da3c6268=1279=0269=2278=b9704cf1-f180-4d92-90da-6bb364d4a71583=159736186455=BTC-USD270=3.54271=0.6214689360=20250410-22:58:18.74310537=8affaf11-6cac-461f-81fc-3dea6a8050dc5797=110=038
20250410-22:58:18.855066000 : 8=FIXT.1.19=28935=X49=Coinbase56=24ab46f784d1b20db435b852086e325034=10850=TEST52=20250410-22:58:18.744778369=2262=cf1c957f-e1dc-4130-bd81-966e629da3c6268=1279=2269=0278=8affaf11-6cac-461f-81fc-3dea6a8050dc83=159736186555=BTC-USD270=3.76271=0.0000000060=20250410-22:58:18.74310558=FILLED10=064
20250410-22:58:18.855268000 : 8=FIXT.1.19=28335=X49=Coinbase56=24ab46f784d1b20db435b852086e325034=10950=TEST52=20250410-22:58:18.744782369=2262=cf1c957f-e1dc-4130-bd81-966e629da3c6268=1279=0269=083=159736186655=BTC-USD270=3.82271=0.6214689360=20250410-22:58:18.74310540=237=4c26654f-d300-4f38-befa-f05c0abe34d010=004
20250410-22:58:18.855486000 : 8=FIXT.1.19=32635=X49=Coinbase56=24ab46f784d1b20db435b852086e325034=11050=TEST52=20250410-22:58:18.744796369=2262=cf1c957f-e1dc-4130-bd81-966e629da3c6268=1279=0269=2278=b9704cf1-f180-4d92-90da-6bb364d4a71583=159736186755=BTC-USD270=3.54271=0.6214689360=20250410-22:58:18.74310537=4c26654f-d300-4f38-befa-f05c0abe34d05797=110=152
20250410-22:58:18.855724000 : 8=FIXT.1.19=28935=X49=Coinbase56=24ab46f784d1b20db435b852086e325034=11150=TEST52=20250410-22:58:18.744802369=2262=cf1c957f-e1dc-4130-bd81-966e629da3c6268=1279=2269=0278=4c26654f-d300-4f38-befa-f05c0abe34d083=159736186855=BTC-USD270=3.82271=0.0000000060=20250410-22:58:18.74310558=FILLED10=151
20250410-22:58:18.859129000 : 8=FIXT.1.19=27435=X49=Coinbase56=24ab46f784d1b20db435b852086e325034=11250=TEST52=20250410-22:58:18.750615369=2262=cf1c957f-e1dc-4130-bd81-966e629da3c6268=1279=0269=183=159736186955=BTC-USD271=0.6232294660=20250410-22:58:18.74945740=137=1f50b1d5-7b8b-4209-b0e0-bc9e9bfa7f0d10=154
20250410-22:58:18.859377000 : 8=FIXT.1.19=32635=X49=Coinbase56=24ab46f784d1b20db435b852086e325034=11350=TEST52=20250410-22:58:18.750619369=2262=cf1c957f-e1dc-4130-bd81-966e629da3c6268=1279=0269=2278=4d60a78e-b39b-420e-b830-bc0f3f4fdde283=159736187055=BTC-USD270=3.53271=0.6232294660=20250410-22:58:18.74945737=1f50b1d5-7b8b-4209-b0e0-bc9e9bfa7f0d5797=210=138
20250410-22:58:18.859555000 : 8=FIXT.1.19=28035=X49=Coinbase56=24ab46f784d1b20db435b852086e325034=11450=TEST52=20250410-22:58:18.750627369=2262=cf1c957f-e1dc-4130-bd81-966e629da3c6268=1279=2269=1278=1f50b1d5-7b8b-4209-b0e0-bc9e9bfa7f0d83=159736187155=BTC-USD271=0.0000000060=20250410-22:58:18.74945758=FILLED10=052
20250410-22:58:18.947144000 : 8=FIXT.1.19=27835=X49=Coinbase56=24ab46f784d1b20db435b852086e325034=11550=TEST52=20250410-22:58:18.838025369=2262=cf1c957f-e1dc-4130-bd81-966e629da3c6268=1279=0269=083=159736187255=BTC-USD29004=2.208895536660=20250410-22:58:18.83615840=137=eed8c514-afa4-4975-aab6-43eed27516ca10=121
20250410-22:58:18.947544000 : 8=FIXT.1.19=32635=X49=Coinbase56=24ab46f784d1b20db435b852086e325034=11650=TEST52=20250410-22:58:18.838034369=2262=cf1c957f-e1dc-4130-bd81-966e629da3c6268=1279=0269=2278=b9704cf1-f180-4d92-90da-6bb364d4a71583=159736187355=BTC-USD270=3.54271=0.6239817960=20250410-22:58:18.83615837=eed8c514-afa4-4975-aab6-43eed27516ca5797=110=226
20250410-22:58:18.947921000 : 8=FIXT.1.19=26535=X49=Coinbase56=24ab46f784d1b20db435b852086e325034=11750=TEST52=20250410-22:58:18.838037369=2262=cf1c957f-e1dc-4130-bd81-966e629da3c6268=1279=2269=0278=eed8c514-afa4-4975-aab6-43eed27516ca83=159736187455=BTC-USD60=20250410-22:58:18.83615858=FILLED10=140
20250410-22:58:18.973471000 : 8=FIXT.1.19=27435=X49=Coinbase56=24ab46f784d1b20db435b852086e325034=11850=TEST52=20250410-22:58:18.865505369=2262=cf1c957f-e1dc-4130-bd81-966e629da3c6268=1279=0269=183=159736187555=BTC-USD271=0.6232294660=20250410-22:58:18.86441840=137=6e6ff228-aa93-42bc-ae4a-11c08ba0782710=059
20250410-22:58:18.974053000 : 8=FIXT.1.19=32635=X49=Coinbase56=24ab46f784d1b20db435b852086e325034=11950=TEST52=20250410-22:58:18.865511369=2262=cf1c957f-e1dc-4130-bd81-966e629da3c6268=1279=0269=2278=4d60a78e-b39b-420e-b830-bc0f3f4fdde283=159736187655=BTC-USD270=3.53271=0.6232294660=20250410-22:58:18.86441837=6e6ff228-aa93-42bc-ae4a-11c08ba078275797=210=045
20250410-22:58:18.974444000 : 8=FIXT.1.19=28035=X49=Coinbase56=24ab46f784d1b20db435b852086e325034=12050=TEST52=20250410-22:58:18.865515369=2262=cf1c957f-e1dc-4130-bd81-966e629da3c6268=1279=2269=1278=6e6ff228-aa93-42bc-ae4a-11c08ba0782783=159736187755=BTC-USD271=0.0000000060=20250410-22:58:18.86441858=FILLED10=211
20250410-22:58:19.017362000 : 8=FIXT.1.19=28335=X49=Coinbase56=24ab46f784d1b20db435b852086e325034=12150=TEST52=20250410-22:58:18.909537369=2262=cf1c957f-e1dc-4130-bd81-966e629da3c6268=1279=0269=183=159736187855=BTC-USD270=3.36271=0.6214689360=20250410-22:58:18.90802040=237=283808ab-72db-4142-81e1-26a180f9aa0a10=063
20250410-22:58:19.018136000 : 8=FIXT.1.19=32635=X49=Coinbase56=24ab46f784d1b20db435b852086e325034=12250=TEST52=20250410-22:58:18.909544369=2262=cf1c957f-e1dc-4130-bd81-966e629da3c6268=1279=0269=2278=4d60a78e-b39b-420e-b830-bc0f3f4fdde283=159736187955=BTC-USD270=3.53271=0.6214689360=20250410-22:58:18.90802037=283808ab-72db-4142-81e1-26a180f9aa0a5797=210=144
20250410-22:58:19.018699000 : 8=FIXT.1.19=28935=X49=Coinbase56=24ab46f784d1b20db435b852086e325034=12350=TEST52=20250410-22:58:18.909548369=2262=cf1c957f-e1dc-4130-bd81-966e629da3c6268=1279=2269=1278=283808ab-72db-4142-81e1-26a180f9aa0a83=159736188055=BTC-USD270=3.36271=0.0000000060=20250410-22:58:18.90802058=FILLED10=219
20250410-22:58:19.019324000 : 8=FIXT.1.19=28335=X49=Coinbase56=24ab46f784d1b20db435b852086e325034=12450=TEST52=20250410-22:58:18.909552369=2262=cf1c957f-e1dc-4130-bd81-966e629da3c6268=1279=0269=183=159736188155=BTC-USD270=3.29271=0.6214689360=20250410-22:58:18.90802040=237=d554f8ad-5c73-493d-8dcf-3afa648fa5f110=078
20250410-22:58:19.019651000 : 8=FIXT.1.19=32635=X49=Coinbase56=24ab46f784d1b20db435b852086e325034=12550=TEST52=20250410-22:58:18.909555369=2262=cf1c957f-e1dc-4130-bd81-966e629da3c6268=1279=0269=2278=4d60a78e-b39b-420e-b830-bc0f3f4fdde283=159736188255=BTC-USD270=3.53271=0.6214689360=20250410-22:58:18.90802037=d554f8ad-5c73-493d-8dcf-3afa648fa5f15797=210=162
20250410-22:58:19.019947000 : 8=FIXT.1.19=28935=X49=Coinbase56=24ab46f784d1b20db435b852086e325034=12650=TEST52=20250410-22:58:18.909559369=2262=cf1c957f-e1dc-4130-bd81-966e629da3c6268=1279=2269=1278=d554f8ad-5c73-493d-8dcf-3afa648fa5f183=159736188355=BTC-USD270=3.29271=0.0000000060=20250410-22:58:18.90802058=FILLED10=248
20250410-22:58:19.020258000 : 8=FIXT.1.19=28335=X49=Coinbase56=24ab46f784d1b20db435b852086e325034=12750=TEST52=20250410-22:58:18.909563369=2262=cf1c957f-e1dc-4130-bd81-966e629da3c6268=1279=0269=183=159736188455=BTC-USD270=3.32271=0.6214689360=20250410-22:58:18.90802040=237=71b0410d-b441-4a96-af1a-f5eb771f002710=107
20250410-22:58:19.020527000 : 8=FIXT.1.19=32635=X49=Coinbase56=24ab46f784d1b20db435b852086e325034=12850=TEST52=20250410-22:58:18.909567369=2262=cf1c957f-e1dc-4130-bd81-966e629da3c6268=1279=0269=2278=4d60a78e-b39b-420e-b830-bc0f3f4fdde283=159736188555=BTC-USD270=3.53271=0.6214689360=20250410-22:58:18.90802037=71b0410d-b441-4a96-af1a-f5eb771f00275797=210=198
20250410-22:58:19.020796000 : 8=FIXT.1.19=28935=X49=Coinbase56=24ab46f784d1b20db435b852086e325034=12950=TEST52=20250410-22:58:18.909570369=2262=cf1c957f-e1dc-4130-bd81-966e629da3c6268=1279=2269=1278=71b0410d-b441-4a96-af1a-f5eb771f002783=159736188655=BTC-USD270=3.32271=0.0000000060=20250410-22:58:18.90802058=FILLED10=012
20250410-22:58:19.402432000 : 8=FIXT.1.19=27835=X49=Coinbase56=24ab46f784d1b20db435b852086e325034=13050=TEST52=20250410-22:58:19.294319369=2262=cf1c957f-e1dc-4130-bd81-966e629da3c6268=1279=0269=083=159736188755=BTC-USD29004=2.208895536660=20250410-22:58:19.29301140=137=f23b894d-7537-47c4-967c-f2d9b214d46110=101
20250410-22:58:19.402921000 : 8=FIXT.1.19=32635=X49=Coinbase56=24ab46f784d1b20db435b852086e325034=13150=TEST52=20250410-22:58:19.294330369=2262=cf1c957f-e1dc-4130-bd81-966e629da3c6268=1279=0269=2278=b9704cf1-f180-4d92-90da-6bb364d4a71583=159736188855=BTC-USD270=3.54271=0.6239817960=20250410-22:58:19.29301137=f23b894d-7537-47c4-967c-f2d9b214d4615797=110=199
20250410-22:58:19.403429000 : 8=FIXT.1.19=26535=X49=Coinbase56=24ab46f784d1b20db435b852086e325034=13250=TEST52=20250410-22:58:19.294334369=2262=cf1c957f-e1dc-4130-bd81-966e629da3c6268=1279=2269=0278=f23b894d-7537-47c4-967c-f2d9b214d46183=159736188955=BTC-USD60=20250410-22:58:19.29301158=FILLED10=114
20250410-22:58:19.431799000 : 8=FIXT.1.19=27435=X49=Coinbase56=24ab46f784d1b20db435b852086e325034=13350=TEST52=20250410-22:58:19.323470369=2262=cf1c957f-e1dc-4130-bd81-966e629da3c6268=1279=0269=183=159736189055=BTC-USD271=0.6232294660=20250410-22:58:19.32177540=137=e91403af-cc9c-45da-9427-3c2e58a9084e10=010
20250410-22:58:19.432265000 : 8=FIXT.1.19=32635=X49=Coinbase56=24ab46f784d1b20db435b852086e325034=13450=TEST52=20250410-22:58:19.323478369=2262=cf1c957f-e1dc-4130-bd81-966e629da3c6268=1279=0269=2278=4d60a78e-b39b-420e-b830-bc0f3f4fdde283=159736189155=BTC-USD270=3.53271=0.6232294660=20250410-22:58:19.32177537=e91403af-cc9c-45da-9427-3c2e58a9084e5797=210=007
20250410-22:58:19.432573000 : 8=FIXT.1.19=28035=X49=Coinbase56=24ab46f784d1b20db435b852086e325034=13550=TEST52=20250410-22:58:19.323482369=2262=cf1c957f-e1dc-4130-bd81-966e629da3c6268=1279=2269=1278=e91403af-cc9c-45da-9427-3c2e58a9084e83=159736189255=BTC-USD271=0.0000000060=20250410-22:58:19.32177558=FILLED10=173
20250410-22:58:19.467277000 : 8=FIXT.1.19=91835=W49=Coinbase56=24ab46f784d1b20db435b852086e325034=13650=TEST52=20250410-22:58:19.359498369=2262=cf1c957f-e1dc-4130-bd81-966e629da3c683=1597361889893=N55=BTC-USD1682=full_trading268=10269=0278=4d60a78e-b39b-420e-b830-bc0f3f4fdde2270=3.53271=277086.17253063269=0278=9d9353ab-229f-423a-89a3-c52a46543bc9270=3.53271=18127.30103418269=0278=9d545208-9fad-4b79-adab-3901b6e5b20f270=3.49271=0.62322946269=0278=628b4f25-c269-4093-9366-675e42d945d3270=3.48271=0.62146893269=0278=dcccb470-c535-433a-9198-4e2b4c26d99d270=3.47271=0.29311495269=0278=f05d9766-970d-44ca-aa4d-e8b2720bbda8270=3.46271=0.29026870269=0278=2c4d7d5a-33aa-4058-b546-480b6a2168a4270=3.44271=0.29828577269=0278=37dbcf16-0b3d-4f67-bc90-e36268b99e0e270=3.42271=0.30270947269=0278=0cf78d7a-78fc-46ab-a95e-2e48497fe549270=3.42271=0.62322946269=0278=4c63c0b7-30e0-4ef1-931f-0090359f978e270=3.41271=0.3215896210=234
20250410-22:58:19.471401000 : 8=FIXT.1.19=14135=334=349=24ab46f784d1b20db435b852086e325052=20250410-22:58:19.47056=Coinbase45=13658=Tag appears more than once371=269372=W373=1310=003
20250410-22:58:19.471636000 : 8=FIXT.1.19=90935=W49=Coinbase56=24ab46f784d1b20db435b852086e325034=13750=TEST52=20250410-22:58:19.359738369=2262=cf1c957f-e1dc-4130-bd81-966e629da3c683=1597361889893=N55=BTC-USD1682=full_trading268=10269=0278=d6b4aa4e-d588-4c96-83aa-8e8d8accb1a4270=3.41271=0.30121104269=0278=88346952-b58e-4a22-8435-e9b3108197d4270=3.41271=0.62432126269=0278=e8b3d8da-1663-413c-b7fb-6aba23b01440270=3.39271=0.31006477269=0278=bcbe17c3-9059-4c38-8ab8-8e78f1ef9062270=3.38271=0.32617981269=0278=817252a3-7c31-4224-a613-160949f0881f270=3.38271=0.62322946269=0278=57bb77fd-337f-49bc-a56f-a4e2dff851ee270=3.37271=0.31071676269=0278=ded4b51d-349f-4726-8379-6761a3576bb6270=3.33271=0.31560513269=0278=ff7aff09-38de-47ac-a3cb-9beacb0b9ad8270=3.33271=0.30682342269=0278=d1da558a-e9d2-4e11-b26e-1eb80a1a34c5270=3.32271=0.31700685269=0278=9ee34527-d4d8-4659-b2ea-cdff3dc4a8fa270=3.32271=0.3218195110=255
20250410-22:58:19.472758000 : 8=FIXT.1.19=14135=334=449=24ab46f784d1b20db435b852086e325052=20250410-22:58:19.47156=Coinbase45=13758=Tag appears more than once371=269372=W373=1310=006
20250410-22:58:19.472922000 : 8=FIXT.1.19=90935=W49=Coinbase56=24ab46f784d1b20db435b852086e325034=13850=TEST52=20250410-22:58:19.359987369=2262=cf1c957f-e1dc-4130-bd81-966e629da3c683=1597361889893=N55=BTC-USD1682=full_trading268=10269=0278=7abf2220-0421-460f-9dbb-14c41564e41a270=3.32271=0.31308436269=0278=69634ec5-f71a-4990-b56d-13c3069a455a270=3.31271=0.32329458269=0278=2f333c17-a386-4d52-8ff1-eadcb99bc22f270=3.31271=0.31999220269=0278=f02efc37-0b1e-470b-99ef-e31012887d73270=3.30271=0.32771570269=0278=6d430950-8078-4987-8995-e581564e368d270=3.29271=0.30702763269=0278=841f895a-cd2d-4082-9a37-b50fc19e35bf270=3.28271=0.32610801269=0278=3cf93093-e42b-4c24-95ea-c367d96427fe270=3.27271=0.33588654269=0278=f29c94bc-d1c2-4145-97b0-ecb77d81a8bf270=3.27271=0.31661408269=0278=d208c4fb-56c6-4911-85c9-77b68a5ba6ab270=3.25271=0.30961623269=0278=e88796ff-68c8-4463-914b-46e09fbaf639270=3.25271=0.3358984510=162
20250410-22:58:19.473788000 : 8=FIXT.1.19=14135=334=549=24ab46f784d1b20db435b852086e325052=20250410-22:58:19.47356=Coinbase45=13858=Tag appears more than once371=269372=W373=1310=010
20250410-22:58:19.473977000 : 8=FIXT.1.19=90935=W49=Coinbase56=24ab46f784d1b20db435b852086e325034=13950=TEST52=20250410-22:58:19.360237369=2262=cf1c957f-e1dc-4130-bd81-966e629da3c683=1597361889893=N55=BTC-USD1682=full_trading268=10269=0278=06f345fb-0292-45fc-8237-9ad1a84b541c270=3.24271=0.31528507269=0278=fa20c2c7-df80-4941-9a9c-a6ef2e579480270=3.23271=0.33432448269=0278=a833d230-a749-4bf4-823e-93adc40b773d270=3.23271=0.31165878269=0278=2abb6e15-b9cd-415b-8c9b-99a61c750310270=3.22271=0.32048714269=0278=ec44a6d8-ae5f-4809-89d7-0f7a3adac547270=3.21271=0.33230954269=0278=9cf61c67-c4fc-4bac-92fd-d4e2b56248aa270=3.21271=0.33583951269=0278=210b2518-bb42-461a-9c7e-b4e04c5ffcc6270=3.21271=0.32669007269=0278=2e3fa1b2-20f1-4694-9be4-322040b75152270=3.21271=0.32907979269=0278=05dd5607-92c9-4296-8cdc-27cdff004dea270=3.21271=0.32776075269=0278=87944de7-a5f1-4033-a3d8-cbc10f3a5232270=3.20271=0.3222517010=101
20250410-22:58:19.475025000 : 8=FIXT.1.19=14135=334=649=24ab46f784d1b20db435b852086e325052=20250410-22:58:19.47456=Coinbase45=13958=Tag appears more than once371=269372=W373=1310=013
20250410-22:58:19.475132000 : 8=FIXT.1.19=91035=W49=Coinbase56=24ab46f784d1b20db435b852086e325034=14050=TEST52=20250410-22:58:19.360487369=2262=cf1c957f-e1dc-4130-bd81-966e629da3c683=1597361889893=N55=BTC-USD1682=full_trading268=10269=0278=30f6bb59-2469-4e6d-8fa5-13666373901f270=3.19271=0.31386496269=0278=6a5d2852-7ddc-456e-acb5-bfadcc0c1360270=3.19271=0.32157390269=0278=5d00d8a2-5aea-4836-ba19-74fe67116df8270=3.18271=0.32651049269=0278=acc71746-3591-4dde-a7e2-c2795d0ad125270=3.17271=0.31577131269=0278=13982796-c2a8-4740-95e2-5aca0fdfd8bb270=3.16271=0.33021170269=0278=9f2f0737-661e-43d7-89f9-959ed5e08306270=3.16271=0.33082075269=0278=7e0e2d14-fa77-4978-8cae-d9660fd13e6d270=3.16271=0.32014975269=0278=82826a7d-848c-4516-a7b6-5ec6881609a8270=2.00271=10.00000000269=0278=590048d5-ee44-49dc-b66d-1a692e055133270=1.94271=0.51546392269=0278=22bdda11-16cd-488b-9fa9-da098dad543e270=1.94271=0.5154639210=158
20250410-22:58:19.475996000 : 8=FIXT.1.19=14135=334=749=24ab46f784d1b20db435b852086e325052=20250410-22:58:19.47556=Coinbase45=14058=Tag appears more than once371=269372=W373=1310=007
20250410-22:58:19.476101000 : 8=FIXT.1.19=90935=W49=Coinbase56=24ab46f784d1b20db435b852086e325034=14150=TEST52=20250410-22:58:19.360738369=2262=cf1c957f-e1dc-4130-bd81-966e629da3c683=1597361889893=N55=BTC-USD1682=full_trading268=10269=0278=d356ef8b-596e-47e7-bf90-cc015b85fc57270=1.93271=0.52331606269=0278=aa8d48bc-97fb-4d00-b923-66d37cc8c66a270=1.93271=0.52331606269=0278=7d51dcb4-a7f8-4cca-b2d0-e902403d1b9f270=1.93271=0.52331606269=0278=f7680950-3af2-4723-a6e4-5cbd528ca900270=1.93271=0.52331606269=0278=fdeff994-4866-47af-9dde-a25947a26606270=1.93271=0.52331606269=0278=65e7e2bb-023d-4936-bb4e-ff7625ba7264270=1.93271=0.52331606269=0278=53732639-572c-4cd5-b61e-e4f534d1d540270=1.93271=0.52331606269=0278=24da8927-1dd1-468b-9437-ff366f5bfa11270=1.93271=0.52331606269=0278=baa5862c-41e8-458c-83d3-c095bb68ed17270=1.93271=0.52331606269=0278=92a3c3e3-7afe-4d02-a0d8-96f512b63bb7270=1.93271=0.5233160610=226
20250410-22:58:19.476952000 : 8=FIXT.1.19=14135=334=849=24ab46f784d1b20db435b852086e325052=20250410-22:58:19.47656=Coinbase45=14158=Tag appears more than once371=269372=W373=1310=010
20250410-22:58:19.477069000 : 8=FIXT.1.19=90935=W49=Coinbase56=24ab46f784d1b20db435b852086e325034=14250=TEST52=20250410-22:58:19.360987369=2262=cf1c957f-e1dc-4130-bd81-966e629da3c683=1597361889893=N55=BTC-USD1682=full_trading268=10269=0278=9d2a564e-f178-4966-9baf-5814a1c1686b270=1.93271=0.52331606269=0278=f9e6b978-87f6-4397-8d82-07cf698c123f270=1.93271=0.52331606269=0278=3e64b388-13d3-441d-b241-aa8dd6fe55e6270=1.93271=0.52331606269=0278=60300433-87b0-4031-bb1e-12cf9d773d3f270=1.93271=0.52331606269=0278=1bdd5f5a-1d99-4eed-af09-c187bcbbd2d8270=1.93271=0.52331606269=0278=4ed6f6b9-77fb-4255-a188-f243dd0cdb3c270=1.93271=0.52331606269=0278=9ad1fc18-5a38-4edb-ac5c-6ac826a8a846270=1.93271=0.52331606269=0278=1c218c8c-baea-4a1f-838e-4a3a94b468e1270=1.93271=0.52331606269=0278=fd70f5e2-d2c9-472a-ab40-a775afafd73d270=1.93271=0.52331606269=0278=96f5e3a5-1c2a-4db6-a3fb-fd1f13d5d559270=1.93271=0.5233160610=234
20250410-22:58:19.478050000 : 8=FIXT.1.19=14135=334=949=24ab46f784d1b20db435b852086e325052=20250410-22:58:19.47756=Coinbase45=14258=Tag appears more than once371=269372=W373=1310=013
20250410-22:58:19.478212000 : 8=FIXT.1.19=90935=W49=Coinbase56=24ab46f784d1b20db435b852086e325034=14350=TEST52=20250410-22:58:19.361238369=2262=cf1c957f-e1dc-4130-bd81-966e629da3c683=1597361889893=N55=BTC-USD1682=full_trading268=10269=0278=4a015a4c-490a-4c40-974f-9dfb7feb335d270=1.93271=0.52331606269=0278=d919363e-2c54-404f-bc0b-063e2f12bec4270=1.93271=0.52331606269=0278=d4636d6c-85c6-4ac9-9afb-70ca636f4ad4270=1.93271=0.52331606269=0278=bda09690-f345-4c33-ae8b-e8c78da11b5a270=1.93271=0.52331606269=0278=1a81ae10-b700-42a0-89a3-7d7a3eea0ebb270=1.93271=0.52331606269=0278=1ace5afa-e550-4abf-a458-52e46e1b54f0270=1.93271=0.52331606269=0278=2332d1c9-67e7-457a-abfe-f5e9a8c2ea05270=1.93271=0.52331606269=0278=6afa1f19-0ec5-49fd-8b74-06a12a6c5ca9270=1.93271=0.52331606269=0278=3fa3413d-c26c-472f-9cc5-da1c48935c63270=1.93271=0.52331606269=0278=3f9e43c4-2e62-4d51-b4cb-ad207c693331270=1.93271=0.5233160610=156
20250410-22:58:19.478925000 : 8=FIXT.1.19=14235=334=1049=24ab46f784d1b20db435b852086e325052=20250410-22:58:19.47856=Coinbase45=14358=Tag appears more than once371=269372=W373=1310=056
20250410-22:58:19.479021000 : 8=FIXT.1.19=90935=W49=Coinbase56=24ab46f784d1b20db435b852086e325034=14450=TEST52=20250410-22:58:19.361488369=2262=cf1c957f-e1dc-4130-bd81-966e629da3c683=1597361889893=N55=BTC-USD1682=full_trading268=10269=0278=29e8bfcf-c764-4f7e-997d-09abf72bbc00270=1.93271=0.52331606269=0278=cf3e8b26-09ae-4dfb-9b84-b12a7e199a5a270=1.93271=0.52331606269=0278=08db3e51-e927-47d3-a9dd-2f887c58dc85270=1.93271=0.52331606269=0278=353ae741-9473-4cc5-9ab7-7e5de8ae55d0270=1.93271=0.52331606269=0278=4d037208-2072-480f-98ac-7be9c24f18f4270=1.93271=0.52331606269=0278=b598f678-da6e-4c01-90ed-d702c42f8a65270=1.93271=0.52331606269=0278=5f69b1a0-b5d1-4715-9be1-9bdf008d97d7270=1.93271=0.52331606269=0278=ef063d15-248a-4eae-97f4-278be5106d80270=1.93271=0.52331606269=0278=f8b20207-84bc-44e9-a2fe-9ad775e2ecb1270=1.93271=0.52331606269=0278=75bce2b7-bc58-4479-8bfb-144f88f2262b270=1.93271=0.5233160610=163
20250410-22:58:19.479847000 : 8=FIXT.1.19=14235=334=1149=24ab46f784d1b20db435b852086e325052=20250410-22:58:19.47956=Coinbase45=14458=Tag appears more than once371=269372=W373=1310=059
20250410-22:58:19.479959000 : 8=FIXT.1.19=90935=W49=Coinbase56=24ab46f784d1b20db435b852086e325034=14550=TEST52=20250410-22:58:19.361737369=2262=cf1c957f-e1dc-4130-bd81-966e629da3c683=1597361889893=N55=BTC-USD1682=full_trading268=10269=0278=1f6e2a79-8b10-4a7f-89de-0f1fa03692c7270=1.93271=0.52331606269=0278=d1b80bf5-9b17-44b4-9577-6fe71170b578270=1.93271=0.52331606269=0278=b891e26a-c20c-4fce-ba1c-487fe139a4cc270=1.93271=0.52331606269=0278=5d06d3f6-3189-4394-b3c5-6a2bda14b6d1270=1.93271=0.52331606269=0278=e5791c0f-3937-4a66-9b98-26f79a3891be270=1.93271=0.52331606269=0278=c62591c6-7dfa-46a7-8f20-6a5f22804999270=1.93271=0.52331606269=0278=7c503558-c0b8-457b-8c46-71ece3f7fc8a270=1.93271=0.52331606269=0278=f763bb56-2f21-4a9b-bd48-f84dc1bd5ee5270=1.93271=0.52331606269=0278=42214b03-1fc2-46b3-9e83-91b23a510e5a270=1.93271=0.52331606269=0278=1c7c52ed-7d39-4326-b3b8-98f05a9b3ef0270=1.93271=0.5233160610=151
20250410-22:58:19.480677000 : 8=FIXT.1.19=14235=334=1249=24ab46f784d1b20db435b852086e325052=20250410-22:58:19.48056=Coinbase45=14558=Tag appears more than once371=269372=W373=1310=053
20250410-22:58:19.480780000 : 8=FIXT.1.19=90935=W49=Coinbase56=24ab46f784d1b20db435b852086e325034=14650=TEST52=20250410-22:58:19.361987369=2262=cf1c957f-e1dc-4130-bd81-966e629da3c683=1597361889893=N55=BTC-USD1682=full_trading268=10269=0278=3313309e-45e7-4e7b-8c55-4f9a8ec1b351270=1.93271=0.52331606269=0278=78801ffb-ec5a-4c74-9d08-3e86fd9db4dd270=1.93271=0.52331606269=0278=abe6eea4-1d9c-47d7-847f-2f44aa561b3f270=1.93271=0.52331606269=0278=6a6eb56d-2010-43e2-b78e-5f098081bb64270=1.93271=0.52331606269=0278=b53c01ff-f450-4b05-8ad1-e7894b45e0e0270=1.93271=0.52331606269=0278=4747863e-c0a6-4ef5-8faf-e8934bca4f8b270=1.93271=0.52331606269=0278=81a8a629-57f4-4e3a-ac25-2e9ee1f357c2270=1.93271=0.52331606269=0278=1e239259-7be4-476a-845d-1b92fd951d8b270=1.93271=0.52331606269=0278=189eb272-48f9-4915-b7e1-a86dcc505c4a270=1.93271=0.52331606269=0278=0562b9f7-aae3-4961-bd97-f5b8cde0ec34270=1.93271=0.5233160610=099
20250410-22:58:19.481663000 : 8=FIXT.1.19=14235=334=1349=24ab46f784d1b20db435b852086e325052=20250410-22:58:19.48156=Coinbase45=14658=Tag appears more than once371=269372=W373=1310=056
20250410-22:58:19.481786000 : 8=FIXT.1.19=91335=W49=Coinbase56=24ab46f784d1b20db435b852086e325034=14750=TEST52=20250410-22:58:19.362238369=2262=cf1c957f-e1dc-4130-bd81-966e629da3c683=1597361889893=N55=BTC-USD1682=full_trading268=10269=0278=5103331b-7300-487b-bc2c-a6032bf4be7e270=1.93271=0.52331606269=0278=78ac85ac-2478-4991-a084-7286982b77cc270=1.93271=0.52331606269=0278=6993b26d-d6dc-4f99-8a53-9500ae5b4ff1270=1.93271=0.52331606269=0278=1c96ab9d-04a6-465a-87e5-3ed33970178f270=1.93271=0.52331606269=0278=6fc0282b-d538-4aa3-8982-bda02bb1b054270=1.93271=0.52331606269=0278=80870aa3-04a2-4d2a-8669-93215130ffee270=1.93271=0.52331606269=0278=b274e872-6923-45fd-b48a-68e685e769cb270=1.93271=0.52331606269=0278=2d4364c0-239c-4f4b-8ce4-2acfe0bb343d270=1.12271=1.00000000269=0278=8fa16a4f-377f-4deb-9a8e-1020aed9edf4270=1.00271=1.00000000269=1278=b9704cf1-f180-4d92-90da-6bb364d4a715270=3.54271=10213.6815146610=199
20250410-22:58:19.482569000 : 8=FIXT.1.19=14235=334=1449=24ab46f784d1b20db435b852086e325052=20250410-22:58:19.48256=Coinbase45=14758=Tag appears more than once371=269372=W373=1310=059
20250410-22:58:19.482690000 : 8=FIXT.1.19=92935=W49=Coinbase56=24ab46f784d1b20db435b852086e325034=14850=TEST52=20250410-22:58:19.362488369=2262=cf1c957f-e1dc-4130-bd81-966e629da3c683=1597361889893=N55=BTC-USD1682=full_trading268=10269=1278=fb329ad8-66e0-4bd9-9197-8f2b7dd2e399270=3.54271=0.29133125269=1278=de4af685-4b2f-44e7-a83c-88865341bc5b270=3.55271=0.28479834269=1278=c5b88ea9-605d-4595-ac52-f7c3f08523ba270=3.55271=17039.00000000269=1278=81523bd3-8912-4789-8761-89a9ee42794b270=3.55271=0.30518966269=1278=60fc75ca-0052-40b7-9f18-a6aad9d31b84270=3.56271=18037.00000000269=1278=ad00e2cd-d925-46a4-9e7e-941c6faed2c7270=3.57271=18027.00000000269=1278=fec191b5-64da-4a15-ab4b-36a0d3d10750270=3.57271=0.29025301269=1278=02a780aa-8154-4638-a5ca-53b8198cc724270=3.58271=16937.00000000269=1278=911349fb-1960-4904-9a38-0e2497fb7ccb270=3.58271=0.29896312269=1278=d91e89d4-ac5c-4853-9879-ec8ff5e00a71270=3.59271=17163.0000000010=054
20250410-22:58:19.483735000 : 8=FIXT.1.19=14235=334=1549=24ab46f784d1b20db435b852086e325052=20250410-22:58:19.48356=Coinbase45=14858=Tag appears more than once371=269372=W373=1310=062
20250410-22:58:19.483911000 : 8=FIXT.1.19=92535=W49=Coinbase56=24ab46f784d1b20db435b852086e325034=14950=TEST52=20250410-22:58:19.362738369=2262=cf1c957f-e1dc-4130-bd81-966e629da3c683=1597361889893=N55=BTC-USD1682=full_trading268=10269=1278=65fee62e-4831-417e-b685-63f584852f5b270=3.59271=0.62146893269=1278=341d0ad8-6c15-4b5e-aebb-e3caa5af575c270=3.60271=17926.00000000269=1278=31cd5634-858c-4d19-9852-dd1d555390b9270=3.60271=0.62322946269=1278=36bdb462-b6b4-4564-87b3-b8d666e9b59e270=3.60271=0.62146893269=1278=7a8d8bf6-0e23-46d3-9ff3-7abdf6f3e1a7270=3.60271=0.62222222269=1278=9d239e03-1215-4cc7-ad44-3f4097ee70ea270=3.61271=18058.08928020269=1278=dbb0f332-4189-4df5-879b-e55860b13def270=3.62271=0.28062774269=1278=f7639c39-7e8b-44d1-a2f2-9807e2a3228c270=3.62271=0.27709851269=1278=83be9389-2099-4173-a322-b0933bc99358270=3.62271=19973.00000000269=1278=b89abc22-6b6c-4474-b3fc-ffe21f05cd4e270=3.63271=20016.0000000010=025
20250410-22:58:19.485143000 : 8=FIXT.1.19=14235=334=1649=24ab46f784d1b20db435b852086e325052=20250410-22:58:19.48456=Coinbase45=14958=Tag appears more than once371=269372=W373=1310=065
20250410-22:58:19.485343000 : 8=FIXT.1.19=90935=W49=Coinbase56=24ab46f784d1b20db435b852086e325034=15050=TEST52=20250410-22:58:19.362988369=2262=cf1c957f-e1dc-4130-bd81-966e629da3c683=1597361889893=N55=BTC-USD1682=full_trading268=10269=1278=3a143af3-3618-4e1a-b27d-9663d34b3635270=3.63271=0.62322946269=1278=ce0af8a3-149c-4603-905a-be65625fe014270=3.64271=0.27806002269=1278=2df25bdf-77c1-42ca-85ce-e0ca83d65a83270=3.68271=0.62322946269=1278=cae3885d-f5b2-4de1-830c-0085e27bbb69270=3.69271=0.27722678269=1278=b9732128-11b1-44fd-bea3-94da9fc853fb270=3.71271=0.28488329269=1278=818b83a4-e14e-4ad5-b094-6733f0504003270=3.75271=0.27930225269=1278=3e6990a0-8ef4-4968-8ee8-89b7346c197d270=3.76271=0.28131365269=1278=342794c8-a9d2-4aa5-9886-a819398d69c6270=3.88271=0.27719712269=1278=2839680b-48b3-4f53-86b1-9269987275e7270=3.91271=0.26621275269=1278=fd7b5361-29f8-4b35-bae5-232a64f657b4270=3.95271=0.2613140610=213
20250410-22:58:19.486813000 : 8=FIXT.1.19=14235=334=1749=24ab46f784d1b20db435b852086e325052=20250410-22:58:19.48556=Coinbase45=15058=Tag appears more than once371=269372=W373=1310=059
20250410-22:58:19.486990000 : 8=FIXT.1.19=92135=W49=Coinbase56=24ab46f784d1b20db435b852086e325034=15150=TEST52=20250410-22:58:19.363238369=2262=cf1c957f-e1dc-4130-bd81-966e629da3c683=1597361889893=N55=BTC-USD1682=full_trading268=10269=1278=5edaeed0-fae9-4f36-8c77-6fbedf61eefc270=4.02271=0.25091227269=1278=fdbbfd04-ba67-4b23-bbc1-f87f929e7e81270=4.07271=0.24812642269=1278=534b2a85-0852-420d-928b-70cdb6ba2457270=4.10271=0.26961968269=1278=b009f8a1-4a39-493b-b96e-d783e981c915270=4.26271=0.25019574269=1278=729a899c-ac2d-4541-b0a2-cbdd5df9bf98270=10.00271=10.00000000269=1278=eb1e5d45-d081-4ef8-a83e-1f5348fbda96270=10.00271=10.00000000269=1278=0cd67977-85eb-45fa-ae72-d45b92ca24f4270=10.00271=10.00000000269=1278=5d931559-6758-4b75-9d6d-6438d25b497f270=10.00271=10.00000000269=1278=57e43d1d-644a-493e-acd3-69dc5e64dcde270=10.00271=10.00000000269=1278=c1566121-2b63-494d-ac2d-973e9f0115c0270=10.00271=10.0000000010=208
20250410-22:58:19.488007000 : 8=FIXT.1.19=14235=334=1849=24ab46f784d1b20db435b852086e325052=20250410-22:58:19.48756=Coinbase45=15158=Tag appears more than once371=269372=W373=1310=063
20250410-22:58:19.488138000 : 8=FIXT.1.19=93035=W49=Coinbase56=24ab46f784d1b20db435b852086e325034=15250=TEST52=20250410-22:58:19.363488369=2262=cf1c957f-e1dc-4130-bd81-966e629da3c683=1597361889893=N55=BTC-USD1682=full_trading268=10269=1278=d0c4a771-9035-4db9-ae7b-ad2d1db5646d270=10.00271=10.00000000269=1278=52c644ea-628a-4576-8e7e-27ec4c90398b270=10.00271=10.00000000269=1278=c3483f66-d8ce-489a-90b9-2bce69e054ee270=10.00271=10.00000000269=1278=55992a5c-cbcd-464a-8f8d-8b58e81e5c0b270=10.00271=10.00000000269=1278=19077009-6f26-4e2d-9dab-04a28231b752270=10.00271=10.00000000269=1278=692097d1-c978-4024-95e9-2bf348b64bbd270=10.00271=10.00000000269=1278=99a92935-11b7-4f21-a64c-c746b53d1777270=10.00271=10.00000000269=1278=dc024b0b-0337-4215-9669-5e5636834397270=10.00271=10.00000000269=1278=c90fcc3a-a36c-4c14-b57f-6db78762e017270=10.00271=10.00000000269=1278=7841891a-bb7c-4034-97c1-41164185edc7270=1000.00271=3.1000000010=244
20250410-22:58:19.488909000 : 8=FIXT.1.19=14235=334=1949=24ab46f784d1b20db435b852086e325052=20250410-22:58:19.48856=Coinbase45=15258=Tag appears more than once371=269372=W373=1310=066
20250410-22:58:19.489033000 : 8=FIXT.1.19=93935=W49=Coinbase56=24ab46f784d1b20db435b852086e325034=15350=TEST52=20250410-22:58:19.363738369=2262=cf1c957f-e1dc-4130-bd81-966e629da3c683=1597361889893=N55=BTC-USD1682=full_trading268=10269=1278=381c9fa7-1add-4dd2-9233-f41e2c8821fe270=1000.00271=3.10000000269=1278=928e65c2-7e2d-478b-9310-414fb77f5aae270=1000.00271=3.10000000269=1278=ad4bd3ac-9276-40d5-90f9-e47b1d8ee953270=1000.00271=3.10000000269=1278=79e799dc-4a3d-4922-ad1a-f74eb7eff789270=1000.00271=3.10000000269=1278=04f642b7-750f-4967-b786-0d48eea0f158270=1000.00271=3.10000000269=1278=d0ad653d-3272-4a3b-ba7a-a52029a67a92270=1000.00271=3.10000000269=1278=cad40464-4c62-4bf3-8444-c487fcc8dd01270=1000.00271=3.10000000269=1278=426c6428-d481-4ff7-9de3-f00ff219d654270=1000.00271=3.10000000269=1278=1ed1152d-8c1a-4b29-acdd-bbd1a5c5f35f270=1000.00271=3.10000000269=1278=66526051-b5cb-442f-af90-c609be0a9796270=1000.00271=3.1000000010=051
20250410-22:58:19.491239000 : 8=FIXT.1.19=14235=334=2049=24ab46f784d1b20db435b852086e325052=20250410-22:58:19.49056=Coinbase45=15358=Tag appears more than once371=269372=W373=1310=052
20250410-22:58:19.627937000 : 8=FIXT.1.19=93935=W49=Coinbase56=24ab46f784d1b20db435b852086e325034=15450=TEST52=20250410-22:58:19.363988369=2262=cf1c957f-e1dc-4130-bd81-966e629da3c683=1597361889893=N55=BTC-USD1682=full_trading268=10269=1278=f68e4659-5785-4ee9-ac24-3186640a2752270=1000.00271=3.10000000269=1278=38070d38-80a9-4898-8ef7-a0a9da5a4123270=1000.00271=3.10000000269=1278=e4d2d308-ed11-49db-850e-3cbd8258395d270=1000.00271=3.10000000269=1278=d6cfaadc-97ea-43c1-898d-40faea9c1477270=1000.00271=3.10000000269=1278=36876bea-9e3a-4018-b0ac-b75cb8c16953270=1000.00271=3.10000000269=1278=eb244bc5-49e8-4aa3-af8b-3d1a67c90a08270=1000.00271=3.10000000269=1278=3efba776-29ad-4aeb-82d8-0824f161471e270=1000.00271=3.10000000269=1278=de0ddebd-0ca8-4eca-9985-77c10c8629a9270=1000.00271=3.10000000269=1278=dde4408a-fb6b-441c-a7f3-7b8b23ffdb1f270=1000.00271=3.10000000269=1278=3ebd6434-070f-4b4d-8cf3-00368112466d270=1000.00271=3.1000000010=146
20250410-22:58:19.628996000 : 8=FIXT.1.19=14235=334=2149=24ab46f784d1b20db435b852086e325052=20250410-22:58:19.62856=Coinbase45=15458=Tag appears more than once371=269372=W373=1310=057
20250410-22:58:19.657970000 : 8=FIXT.1.19=93935=W49=Coinbase56=24ab46f784d1b20db435b852086e325034=15550=TEST52=20250410-22:58:19.364238369=2262=cf1c957f-e1dc-4130-bd81-966e629da3c683=1597361889893=N55=BTC-USD1682=full_trading268=10269=1278=7aa98e13-65f3-4058-9f91-c1f452d02710270=1000.00271=3.10000000269=1278=e86a1fec-3610-460d-8d85-4e1e222ee159270=1000.00271=3.10000000269=1278=6dfac057-72b1-4f2c-b110-03766dea0d31270=1000.00271=3.10000000269=1278=bbb7d0ea-d251-4612-b53e-e528cc0a24ab270=1000.00271=3.10000000269=1278=0782ca37-48cf-4ff3-a74a-35674661586c270=1000.00271=3.10000000269=1278=aead437d-4b62-457f-ac83-62c7cc329fd1270=1000.00271=3.10000000269=1278=af5d47bc-a008-4567-b24f-b0298f250471270=1000.00271=3.10000000269=1278=4c260f58-c427-4a9a-969a-44024ae0c714270=1000.00271=3.10000000269=1278=8c7672e5-7ee8-4fbd-8fdf-7e74e9a77db7270=1000.00271=3.10000000269=1278=b53ec3cc-9abe-4570-b903-34d52148073e270=1000.00271=3.1000000010=166
20250410-22:58:19.658945000 : 8=FIXT.1.19=14235=334=2249=24ab46f784d1b20db435b852086e325052=20250410-22:58:19.65856=Coinbase45=15558=Tag appears more than once371=269372=W373=1310=062
20250410-22:58:19.659085000 : 8=FIXT.1.19=93935=W49=Coinbase56=24ab46f784d1b20db435b852086e325034=15650=TEST52=20250410-22:58:19.364488369=2262=cf1c957f-e1dc-4130-bd81-966e629da3c683=1597361889893=N55=BTC-USD1682=full_trading268=10269=1278=37ce984a-0387-4ac9-9094-b83f722036ba270=1000.00271=3.10000000269=1278=0d383649-dc6c-4df2-b821-aa0018f132c7270=1000.00271=3.10000000269=1278=e39ae0ce-9e7f-4f0d-a765-5308d473bb61270=1000.00271=3.10000000269=1278=4882324e-3b5c-4b7a-b096-e8c6d9888671270=1000.00271=3.10000000269=1278=6e5c7dbd-a2cc-401f-a5b2-3902088f4ab2270=1000.00271=3.10000000269=1278=10ffac08-946a-4a30-b57a-0d78450345d9270=1000.00271=3.10000000269=1278=67784af5-72bf-4d16-a6b3-25336e2c1843270=1000.00271=3.10000000269=1278=4d8b3bbc-0dc2-4044-875c-c079ec538136270=1000.00271=3.10000000269=1278=dfba5f1e-21f5-48e3-adce-b8b6bfe71467270=1000.00271=3.10000000269=1278=e51b4e33-5eaa-46ef-936b-a74a890397e8270=1000.00271=3.1000000010=253
20250410-22:58:19.659768000 : 8=FIXT.1.19=14235=334=2349=24ab46f784d1b20db435b852086e325052=20250410-22:58:19.65956=Coinbase45=15658=Tag appears more than once371=269372=W373=1310=065
20250410-22:58:19.659848000 : 8=FIXT.1.19=93935=W49=Coinbase56=24ab46f784d1b20db435b852086e325034=15750=TEST52=20250410-22:58:19.364738369=2262=cf1c957f-e1dc-4130-bd81-966e629da3c683=1597361889893=N55=BTC-USD1682=full_trading268=10269=1278=8cf5dfa8-858b-48a3-9d94-78522c257473270=1000.00271=3.10000000269=1278=a153b9d2-993d-4f03-a974-b8a081e128e8270=1000.00271=3.10000000269=1278=1eebe866-0f6e-4d4a-a28b-78f4e3368b0a270=1000.00271=3.10000000269=1278=300132d8-113f-4bf7-ba0c-4d93a272f55b270=1000.00271=3.10000000269=1278=757f3122-27d2-4f32-90b8-ead1eef9b936270=1000.00271=3.10000000269=1278=2b68b5de-4153-4cac-ace3-102e4fa788fd270=1000.00271=3.10000000269=1278=b01f252a-1657-4df0-a122-58a23109a7c2270=1000.00271=3.10000000269=1278=dbc57e4e-6abd-4d66-8d18-bd13caaa77b1270=1000.00271=3.10000000269=1278=948b05dc-a481-409f-b8ad-a502eb595906270=1000.00271=3.10000000269=1278=e00f9703-6e16-4237-a2c6-701829d11bf1270=1000.00271=3.1000000010=212
20250410-22:58:19.660494000 : 8=FIXT.1.19=14235=334=2449=24ab46f784d1b20db435b852086e325052=20250410-22:58:19.66056=Coinbase45=15758=Tag appears more than once371=269372=W373=1310=059
20250410-22:58:19.694136000 : 8=FIXT.1.19=93935=W49=Coinbase56=24ab46f784d1b20db435b852086e325034=15850=TEST52=20250410-22:58:19.364988369=2262=cf1c957f-e1dc-4130-bd81-966e629da3c683=1597361889893=N55=BTC-USD1682=full_trading268=10269=1278=fd52f47a-3f11-47bc-9952-9708617d0ecd270=1000.00271=3.10000000269=1278=f7f75b14-27c3-469c-89fb-6a98b43c61bf270=1000.00271=3.10000000269=1278=25dbeb09-7901-4280-b0c3-720d7ed03d7d270=1000.00271=3.10000000269=1278=52164a1f-599f-4c43-a9ed-f93403506e67270=1000.00271=3.10000000269=1278=c71c35ea-f60f-4a41-b43a-4947bbcbafad270=1000.00271=3.10000000269=1278=2de342bc-a1be-46f3-9fc6-731297726934270=1000.00271=3.10000000269=1278=7ff4c5fc-bc9b-4845-940b-4837a672e13a270=1000.00271=3.10000000269=1278=2d270775-33eb-4328-8dad-7d206612f9f6270=1000.00271=3.10000000269=1278=c4754378-f787-4100-81af-564443a86a91270=1000.00271=3.10000000269=1278=59e16255-05eb-4fdc-8be1-3c4f83fc094e270=1000.00271=3.1000000010=063
20250410-22:58:19.695202000 : 8=FIXT.1.19=14235=334=2549=24ab46f784d1b20db435b852086e325052=20250410-22:58:19.69456=Coinbase45=15858=Tag appears more than once371=269372=W373=1310=068
20250410-22:58:19.695315000 : 8=FIXT.1.19=93935=W49=Coinbase56=24ab46f784d1b20db435b852086e325034=15950=TEST52=20250410-22:58:19.365238369=2262=cf1c957f-e1dc-4130-bd81-966e629da3c683=1597361889893=N55=BTC-USD1682=full_trading268=10269=1278=041b2f98-1185-49cb-964a-f0456b71e692270=1000.00271=3.10000000269=1278=9a2f3529-481e-4e50-a123-7a2095fe6b2c270=1000.00271=3.10000000269=1278=9ed552a3-3295-4878-85dd-87b7b5590212270=1000.00271=3.10000000269=1278=54bec5c2-bafd-4d7d-851d-59e3553a053f270=1000.00271=3.10000000269=1278=543c1acf-52f2-442b-a893-f7aa9a5dfbd1270=1000.00271=3.10000000269=1278=fec999be-cbd0-42ef-b9c3-82ca92ef0b58270=1000.00271=3.10000000269=1278=24528176-3fc6-45b2-b2f3-9f784c01495a270=1000.00271=3.10000000269=1278=12081678-66a6-4435-a3d7-b65f959cf2ac270=1000.00271=3.10000000269=1278=e7fb6165-8f1a-4b5e-b095-e232b83ee951270=1000.00271=3.10000000269=1278=83ce6582-410a-40bf-9831-8f3d20e3a629270=1000.00271=3.1000000010=254
20250410-22:58:19.696242000 : 8=FIXT.1.19=14235=334=2649=24ab46f784d1b20db435b852086e325052=20250410-22:58:19.69556=Coinbase45=15958=Tag appears more than once371=269372=W373=1310=071
20250410-22:58:19.696372000 : 8=FIXT.1.19=93935=W49=Coinbase56=24ab46f784d1b20db435b852086e325034=16050=TEST52=20250410-22:58:19.365488369=2262=cf1c957f-e1dc-4130-bd81-966e629da3c683=1597361889893=N55=BTC-USD1682=full_trading268=10269=1278=bc3a930b-0567-46ba-86a4-712f76466b0b270=1000.00271=3.10000000269=1278=15704973-f5ff-457d-ab31-8f99bb76bf7e270=1000.00271=3.10000000269=1278=7159045b-cbd5-458f-b91f-9fa5241b14b5270=1000.00271=3.10000000269=1278=9fa52a90-f03f-4940-b5ee-39ab937b86f1270=1000.00271=3.10000000269=1278=220f55cd-a279-4bf0-9c80-1dca086d85dc270=1000.00271=3.10000000269=1278=2b1eb468-6bcd-4117-a7c0-214d643ddad4270=1000.00271=3.10000000269=1278=cc23185d-e72e-42cb-8210-61bab29cd778270=1000.00271=3.10000000269=1278=69bb228b-973b-4176-8708-3231cc40102a270=1000.00271=3.10000000269=1278=2ec8035d-7962-4195-8388-c9fbad52ac8a270=1000.00271=3.10000000269=1278=7d39e416-0b7b-471f-a9ac-455ab1bce5a7270=1000.00271=3.1000000010=229
20250410-22:58:19.697294000 : 8=FIXT.1.19=14235=334=2749=24ab46f784d1b20db435b852086e325052=20250410-22:58:19.69656=Coinbase45=16058=Tag appears more than once371=269372=W373=1310=065
20250410-22:58:19.697397000 : 8=FIXT.1.19=93935=W49=Coinbase56=24ab46f784d1b20db435b852086e325034=16150=TEST52=20250410-22:58:19.365738369=2262=cf1c957f-e1dc-4130-bd81-966e629da3c683=1597361889893=N55=BTC-USD1682=full_trading268=10269=1278=7067378d-2a65-41f2-acb0-ef30ddbc3e5a270=1000.00271=3.10000000269=1278=bf3fde78-6cff-4477-b381-4b5d2e68f36f270=1000.00271=3.10000000269=1278=93a2a8a3-61d4-410c-9446-8eabaafc5f29270=1000.00271=3.10000000269=1278=5afddb61-63ab-417b-a28a-41c4c03a6612270=1000.00271=3.10000000269=1278=a4280417-189c-4f76-9d2e-6ec652010bf5270=1000.00271=3.10000000269=1278=ddeb78a2-e110-4828-ba3d-c9b4837e7dd7270=1000.00271=3.10000000269=1278=fcec6c90-441a-4f4a-a94e-9003355657ef270=1000.00271=3.10000000269=1278=6db15389-dfb3-4156-8a4e-ce2ac80f2b15270=1000.00271=3.10000000269=1278=47dfefc3-6f05-4b57-8aec-2bf3e6c70c2d270=1000.00271=3.10000000269=1278=fb9fd019-4b4f-4880-82bb-3df6d1ef468a270=1000.00271=3.1000000010=025
20250410-22:58:19.698180000 : 8=FIXT.1.19=14235=334=2849=24ab46f784d1b20db435b852086e325052=20250410-22:58:19.69756=Coinbase45=16158=Tag appears more than once371=269372=W373=1310=068
20250410-22:58:19.698365000 : 8=FIXT.1.19=93935=W49=Coinbase56=24ab46f784d1b20db435b852086e325034=16250=TEST52=20250410-22:58:19.365988369=2262=cf1c957f-e1dc-4130-bd81-966e629da3c683=1597361889893=N55=BTC-USD1682=full_trading268=10269=1278=2cff9acd-42cb-43a5-8d50-51e676b7e763270=1000.00271=3.10000000269=1278=6e6eeb59-4728-4811-9a44-c857df6aca42270=1000.00271=3.10000000269=1278=81798560-263f-4819-a528-5f3fbbc7b042270=1000.00271=3.10000000269=1278=81fbf9a8-82f4-4fe4-9fa5-3773b212ebf4270=1000.00271=3.10000000269=1278=5d3b9566-276d-47fe-a111-12c17f53f501270=1000.00271=3.10000000269=1278=8eb1b3b3-c813-48b1-b839-993672108d91270=1000.00271=3.10000000269=1278=4feb6e93-6149-481b-8d58-e1c8e6c5cda1270=1000.00271=3.10000000269=1278=f8611e72-4056-4b7c-9779-4d54cd151d44270=1000.00271=3.10000000269=1278=7a129f7c-d9ba-4ea3-a267-b7d82b2e07d9270=1000.00271=3.10000000269=1278=01f359f0-c38f-416b-af00-183907218793270=1000.00271=3.1000000010=052
20250410-22:58:19.699046000 : 8=FIXT.1.19=14235=334=2949=24ab46f784d1b20db435b852086e325052=20250410-22:58:19.69856=Coinbase45=16258=Tag appears more than once371=269372=W373=1310=071
20250410-22:58:19.699149000 : 8=FIXT.1.19=93935=W49=Coinbase56=24ab46f784d1b20db435b852086e325034=16350=TEST52=20250410-22:58:19.366238369=2262=cf1c957f-e1dc-4130-bd81-966e629da3c683=1597361889893=N55=BTC-USD1682=full_trading268=10269=1278=11741cec-9c08-4a20-99dc-6b9f63130b0e270=1000.00271=3.10000000269=1278=08db2574-ad52-4520-ab5b-c3c7591eb781270=1000.00271=3.10000000269=1278=b06f2249-179c-4a15-8e98-7b76083b808b270=1000.00271=3.10000000269=1278=9e88fede-6d19-4c1f-863b-5a7d66781436270=1000.00271=3.10000000269=1278=75e1d8b4-7201-41fe-a687-7d93420af323270=1000.00271=3.10000000269=1278=d00aa7dd-ce7f-4f8b-9a2e-880c1ea30845270=1000.00271=3.10000000269=1278=584a483f-23bf-4d8b-809f-69cf3c110f60270=1000.00271=3.10000000269=1278=dc98524e-27e2-4863-99e4-7a0097a6ee90270=1000.00271=3.10000000269=1278=82a11ac9-4f46-44b7-a0bc-a5a4cfe686e0270=1000.00271=3.10000000269=1278=f946bb05-900c-41fc-9908-41489e97ff20270=1000.00271=3.1000000010=212
20250410-22:58:19.699976000 : 8=FIXT.1.19=14235=334=3049=24ab46f784d1b20db435b852086e325052=20250410-22:58:19.69956=Coinbase45=16358=Tag appears more than once371=269372=W373=1310=065
20250410-22:58:19.700074000 : 8=FIXT.1.19=93935=W49=Coinbase56=24ab46f784d1b20db435b852086e325034=16450=TEST52=20250410-22:58:19.366488369=2262=cf1c957f-e1dc-4130-bd81-966e629da3c683=1597361889893=N55=BTC-USD1682=full_trading268=10269=1278=1f9186d6-0312-4677-ba96-fdb014cdff2c270=1000.00271=3.10000000269=1278=c3b67be7-2b63-4884-b311-80f28496c2c4270=1000.00271=3.10000000269=1278=6576c7f8-a4e2-4417-b854-5fef0e705fbe270=1000.00271=3.10000000269=1278=c2102c71-62f0-4eee-ae60-0777ed26a8e6270=1000.00271=3.10000000269=1278=c823a2b6-849e-4839-a2fd-cd9f459cae6c270=1000.00271=3.10000000269=1278=a051e195-4472-4a8a-8591-08a2c04a33c4270=1000.00271=3.10000000269=1278=ec81b8c4-b703-4afd-a701-ce34011f60f6270=1000.00271=3.10000000269=1278=b1172677-f493-4f32-a200-0710cf8c397f270=1000.00271=3.10000000269=1278=b1a58a75-5fca-43db-b9c6-a26920e8f66e270=1000.00271=3.10000000269=1278=038bea41-b91d-4884-b992-3e5431ef9857270=1000.00271=3.1000000010=065
20250410-22:58:19.700675000 : 8=FIXT.1.19=14235=334=3149=24ab46f784d1b20db435b852086e325052=20250410-22:58:19.70056=Coinbase45=16458=Tag appears more than once371=269372=W373=1310=050
20250410-22:58:19.700770000 : 8=FIXT.1.19=93935=W49=Coinbase56=24ab46f784d1b20db435b852086e325034=16550=TEST52=20250410-22:58:19.366738369=2262=cf1c957f-e1dc-4130-bd81-966e629da3c683=1597361889893=N55=BTC-USD1682=full_trading268=10269=1278=55063782-f2ea-4c84-9491-8e8e89d1dfd1270=1000.00271=3.10000000269=1278=bb2011e8-d05d-40ac-9e9c-3b720422e38d270=1000.00271=3.10000000269=1278=64dd3b4a-ce8a-4b63-9937-266e832c0f21270=1000.00271=3.10000000269=1278=d64f7d2a-aa83-486c-92a8-3314c4eddd58270=1000.00271=3.10000000269=1278=0df9641b-d89d-4222-a8ea-bcddf0d555f5270=1000.00271=3.10000000269=1278=7a315b16-a05f-408d-b8c1-2704af9bf767270=1000.00271=3.10000000269=1278=0e9712a8-d00f-4864-a478-f7f591718f91270=1000.00271=3.10000000269=1278=94db025d-eada-49e3-b13c-b667ca07f829270=1000.00271=3.10000000269=1278=a88ccd1f-8f8d-46af-8fb6-20adba35f7d1270=1000.00271=3.10000000269=1278=99d4e235-c8ec-4efc-938c-9a1923eafc96270=1000.00271=3.1000000010=015
20250410-22:58:19.701482000 : 8=FIXT.1.19=14235=334=3249=24ab46f784d1b20db435b852086e325052=20250410-22:58:19.70156=Coinbase45=16558=Tag appears more than once371=269372=W373=1310=053
20250410-22:58:19.701556000 : 8=FIXT.1.19=93935=W49=Coinbase56=24ab46f784d1b20db435b852086e325034=16650=TEST52=20250410-22:58:19.366988369=2262=cf1c957f-e1dc-4130-bd81-966e629da3c683=1597361889893=N55=BTC-USD1682=full_trading268=10269=1278=a4fc7173-7583-4f8b-b256-2921bef83c84270=1000.00271=3.10000000269=1278=18f8afd4-8bbc-4ffa-8e8f-0c1834d74472270=1000.00271=3.10000000269=1278=21fc8cb6-f894-4d09-884e-810b8ebf2ef3270=1000.00271=3.10000000269=1278=0c13b9e6-6797-4b3e-90ce-a1885b26ba53270=1000.00271=3.10000000269=1278=6d8da581-3998-4fc0-99b6-3c5edbd514cb270=1000.00271=3.10000000269=1278=67a70307-be50-4065-872b-47e0de473bc4270=1000.00271=3.10000000269=1278=8ce7be0b-98de-46d0-b1b6-307a4bec36e2270=1000.00271=3.10000000269=1278=856b22f8-5884-4739-adc0-bdd851c5c07d270=1000.00271=3.10000000269=1278=c00ae651-a76b-4bfd-be16-3672b345fe29270=1000.00271=3.10000000269=1278=cae248f9-16fc-44ea-9b79-1dacfc285db6270=1000.00271=3.1000000010=029
20250410-22:58:19.702170000 : 8=FIXT.1.19=14235=334=3349=24ab46f784d1b20db435b852086e325052=20250410-22:58:19.70156=Coinbase45=16658=Tag appears more than once371=269372=W373=1310=055
20250410-22:58:19.702233000 : 8=FIXT.1.19=93935=W49=Coinbase56=24ab46f784d1b20db435b852086e325034=16750=TEST52=20250410-22:58:19.367238369=2262=cf1c957f-e1dc-4130-bd81-966e629da3c683=1597361889893=N55=BTC-USD1682=full_trading268=10269=1278=42bb223c-88c6-4a18-8ff3-4fd8d9efda8d270=1000.00271=3.10000000269=1278=d7188b01-22b6-4837-a720-077601f7f483270=1000.00271=3.10000000269=1278=5d85a0a6-ddd9-4e0e-9a1a-7f418ef588e5270=1000.00271=3.10000000269=1278=bff4c39f-7a80-42ce-a178-b1221792e445270=1000.00271=3.10000000269=1278=9ea3d263-b5ab-46c5-bf27-8c0e3e0e5e9e270=1000.00271=3.10000000269=1278=b93347df-d2ab-48ec-b326-4454e64f1d4e270=1000.00271=3.10000000269=1278=57acc40d-8478-444a-990f-067a8e8e846e270=1000.00271=3.10000000269=1278=34419ae2-2c16-427b-a290-845419760fd5270=1000.00271=3.10000000269=1278=ab41de2d-5def-4986-b56e-243d2f99a57c270=1000.00271=3.10000000269=1278=9025524c-03a9-407a-a58a-5258c4ea0a0b270=1000.00271=3.1000000010=029
20250410-22:58:19.702792000 : 8=FIXT.1.19=14235=334=3449=24ab46f784d1b20db435b852086e325052=20250410-22:58:19.70256=Coinbase45=16758=Tag appears more than once371=269372=W373=1310=058
20250410-22:58:19.702870000 : 8=FIXT.1.19=93935=W49=Coinbase56=24ab46f784d1b20db435b852086e325034=16850=TEST52=20250410-22:58:19.367488369=2262=cf1c957f-e1dc-4130-bd81-966e629da3c683=1597361889893=N55=BTC-USD1682=full_trading268=10269=1278=60766318-112b-4d83-a384-55693de75519270=1000.00271=3.10000000269=1278=c19b6a2c-086b-4fc1-8dfe-51cb2dc12c1d270=1000.00271=3.10000000269=1278=11126433-0f9c-4450-a35a-39b878e85e68270=1000.00271=3.10000000269=1278=e2e620ee-44fb-4630-a890-d331ba5b2fae270=1000.00271=3.10000000269=1278=9ccf6d4b-a6ca-4a1f-a7bb-77f400ace0c8270=1000.00271=3.10000000269=1278=0e8d6c10-8421-4f19-97dc-d70e715d9033270=1000.00271=3.10000000269=1278=f31ecd5d-8231-44ea-a5c2-0fcc5a699401270=1000.00271=3.10000000269=1278=37fbb559-dc52-48fe-ab65-24910edc338a270=1000.00271=3.10000000269=1278=bc1435c5-c59c-4017-9e59-f1073f04c7e2270=1000.00271=3.10000000269=1278=9c8e1397-0cee-4b05-a66f-5594040791c4270=1000.00271=3.1000000010=171
20250410-22:58:19.703373000 : 8=FIXT.1.19=14235=334=3549=24ab46f784d1b20db435b852086e325052=20250410-22:58:19.70356=Coinbase45=16858=Tag appears more than once371=269372=W373=1310=061
20250410-22:58:19.703464000 : 8=FIXT.1.19=93935=W49=Coinbase56=24ab46f784d1b20db435b852086e325034=16950=TEST52=20250410-22:58:19.367738369=2262=cf1c957f-e1dc-4130-bd81-966e629da3c683=1597361889893=N55=BTC-USD1682=full_trading268=10269=1278=248b6703-f829-42bb-a551-4be3075c381e270=1000.00271=3.10000000269=1278=16d257b0-bc92-44f0-822d-3eba61af4bda270=1000.00271=3.10000000269=1278=06257aa1-4043-4cdb-9286-4342b8e59108270=1000.00271=3.10000000269=1278=210ec210-1443-47dc-9e43-9c9ea720a6c3270=1000.00271=3.10000000269=1278=8b79da5d-b78c-4011-b55f-b35c16dc3724270=1000.00271=3.10000000269=1278=076c3703-1104-4e15-a38a-d95bf133f0c5270=1000.00271=3.10000000269=1278=f5a3155c-e449-4102-870d-ab8c8dd24c3d270=1000.00271=3.10000000269=1278=1af2681f-2dec-4d25-aaeb-89b8867b4a3c270=1000.00271=3.10000000269=1278=65c3088d-192a-4213-85a3-7257aa8b20a3270=1000.00271=3.10000000269=1278=2aa7989b-5601-4899-8143-01dda3255e4f270=1000.00271=3.1000000010=147
20250410-22:58:19.703998000 : 8=FIXT.1.19=14235=334=3649=24ab46f784d1b20db435b852086e325052=20250410-22:58:19.70356=Coinbase45=16958=Tag appears more than once371=269372=W373=1310=063
20250410-22:58:19.704070000 : 8=FIXT.1.19=93935=W49=Coinbase56=24ab46f784d1b20db435b852086e325034=17050=TEST52=20250410-22:58:19.367989369=2262=cf1c957f-e1dc-4130-bd81-966e629da3c683=1597361889893=N55=BTC-USD1682=full_trading268=10269=1278=099b432c-fa2e-4fd7-952e-22f6debf6877270=1000.00271=3.10000000269=1278=2e71cc31-1235-4b7b-a728-e3335631fe5a270=1000.00271=3.10000000269=1278=ce471ffc-1e26-4afe-afab-27ee5ac8debe270=1000.00271=3.10000000269=1278=113b7fc6-8574-40eb-8682-d077245b84f2270=1000.00271=3.10000000269=1278=bcebce2c-eda8-4b85-841d-27ede39fc5a1270=1000.00271=3.10000000269=1278=0aedaae5-6cc6-4a34-8e48-5e67a5ccc148270=1000.00271=3.10000000269=1278=206e10a5-1173-4860-87b5-7c88afe061f6270=1000.00271=3.10000000269=1278=5c32d94b-696a-4d9b-afa0-665970356008270=1000.00271=3.10000000269=1278=0b7da819-cc1e-4525-a382-ce5b90dc485c270=1000.00271=3.10000000269=1278=2241b3bf-cbbe-44f2-ac75-8032f6283aa8270=1000.00271=3.1000000010=097
20250410-22:58:19.704683000 : 8=FIXT.1.19=14235=334=3749=24ab46f784d1b20db435b852086e325052=20250410-22:58:19.70456=Coinbase45=17058=Tag appears more than once371=269372=W373=1310=057
20250410-22:58:19.704762000 : 8=FIXT.1.19=93935=W49=Coinbase56=24ab46f784d1b20db435b852086e325034=17150=TEST52=20250410-22:58:19.368239369=2262=cf1c957f-e1dc-4130-bd81-966e629da3c683=1597361889893=N55=BTC-USD1682=full_trading268=10269=1278=88cada69-adb1-466a-afcd-66e063ad27c0270=1000.00271=3.10000000269=1278=34a52ef5-31c1-4c63-9230-21c85a9a6ba3270=1000.00271=3.10000000269=1278=e109c2c8-fb1d-4ef9-a640-368381323507270=1000.00271=3.10000000269=1278=38fd36c4-4c62-4b4c-8f24-1fe39be94fa1270=1000.00271=3.10000000269=1278=f83f64c8-7d33-472d-a516-9b664ff9c966270=1000.00271=3.10000000269=1278=3411c368-380b-42e6-b656-8552d92904d5270=1000.00271=3.10000000269=1278=4803796e-79f3-4aa4-a8cb-37f13899bf01270=1000.00271=3.10000000269=1278=823f8fbf-7e6d-4ae3-adb9-3a822ff6d09a270=1000.00271=3.10000000269=1278=135624df-a204-490f-a68b-63d74ee09908270=1000.00271=3.10000000269=1278=47cfdedf-22b9-402c-93bd-f311103fd3e0270=1000.00271=3.1000000010=173
20250410-22:58:19.705569000 : 8=FIXT.1.19=14235=334=3849=24ab46f784d1b20db435b852086e325052=20250410-22:58:19.70556=Coinbase45=17158=Tag appears more than once371=269372=W373=1310=060
20250410-22:58:19.705674000 : 8=FIXT.1.19=93935=W49=Coinbase56=24ab46f784d1b20db435b852086e325034=17250=TEST52=20250410-22:58:19.368489369=2262=cf1c957f-e1dc-4130-bd81-966e629da3c683=1597361889893=N55=BTC-USD1682=full_trading268=10269=1278=f9173d5e-d872-4661-93f6-28f527e931f7270=1000.00271=3.10000000269=1278=06ab1365-fd39-4701-bd7f-1915ad3c7602270=1000.00271=3.10000000269=1278=012a7c59-5ae4-4da5-97ba-2e3254c889fb270=1000.00271=3.10000000269=1278=a9a0d42f-ad9e-4ea9-8bf0-d5a441fded40270=1000.00271=3.10000000269=1278=f3f3930e-be0e-40b4-a97d-d19501a54885270=1000.00271=3.10000000269=1278=261922d0-5c81-4ab6-832f-4eff45f64890270=1000.00271=3.10000000269=1278=3af4e45f-56f6-4c69-894d-d56a14894a98270=1000.00271=3.10000000269=1278=1c1dd248-49e4-44aa-9e69-323b0f41fa0e270=1000.00271=3.10000000269=1278=b16b002d-1cd6-4869-9c1b-f15c758611bf270=1000.00271=3.10000000269=1278=a0520e61-28ad-448d-87c1-49f0c7358628270=1000.00271=3.1000000010=216
20250410-22:58:19.706471000 : 8=FIXT.1.19=14235=334=3949=24ab46f784d1b20db435b852086e325052=20250410-22:58:19.70556=Coinbase45=17258=Tag appears more than once371=269372=W373=1310=062
20250410-22:58:19.706632000 : 8=FIXT.1.19=93935=W49=Coinbase56=24ab46f784d1b20db435b852086e325034=17350=TEST52=20250410-22:58:19.368739369=2262=cf1c957f-e1dc-4130-bd81-966e629da3c683=1597361889893=N55=BTC-USD1682=full_trading268=10269=1278=152d0b57-086f-48cc-80b3-ff14ee9375ed270=1000.00271=3.10000000269=1278=c55fc264-67d2-4e9c-8cce-6c834feff648270=1000.00271=3.10000000269=1278=27361968-189a-4fa6-a3a2-eead03c640d6270=1000.00271=3.10000000269=1278=f5b01c67-f98f-44b9-a511-7f07f8883d9e270=1000.00271=3.10000000269=1278=75a5c14f-8434-4533-a10e-0bf6e92e1000270=1000.00271=3.10000000269=1278=a9b0a826-3659-4105-9ecc-21bcd27b736f270=1000.00271=3.10000000269=1278=1b1bab77-5c52-459b-98e3-e27ff6f8cd04270=1000.00271=3.10000000269=1278=346695f1-fe03-4364-8fc5-006796c8f82f270=1000.00271=3.10000000269=1278=cbbaa36d-2a03-45a2-a230-bd5845d832cd270=1000.00271=3.10000000269=1278=745d4fc0-6710-4c5c-97c3-7b29c4e06839270=1000.00271=3.1000000010=150
20250410-22:58:19.707428000 : 8=FIXT.1.19=14235=334=4049=24ab46f784d1b20db435b852086e325052=20250410-22:58:19.70656=Coinbase45=17358=Tag appears more than once371=269372=W373=1310=056
20250410-22:58:19.707591000 : 8=FIXT.1.19=93935=W49=Coinbase56=24ab46f784d1b20db435b852086e325034=17450=TEST52=20250410-22:58:19.368989369=2262=cf1c957f-e1dc-4130-bd81-966e629da3c683=1597361889893=N55=BTC-USD1682=full_trading268=10269=1278=e95fdfba-5db2-4461-8e9c-7bfdf8a9238c270=1000.00271=3.10000000269=1278=33611b39-1fbf-45cc-bf5e-a02bc1f84736270=1000.00271=3.10000000269=1278=51f77b2d-1a69-432d-934b-234eb9e1dfac270=1000.00271=3.10000000269=1278=ab09fdc3-8d50-432f-ab0f-97e8627eac24270=1000.00271=3.10000000269=1278=dde04213-6104-44c5-a811-15834c27b515270=1000.00271=3.10000000269=1278=9af2b85c-4997-4e1b-9147-7d400f059b01270=1000.00271=3.10000000269=1278=40870860-7a8a-4419-a117-e511f779abfa270=1000.00271=3.10000000269=1278=3e8fa7bd-dde0-4fe4-bb2e-e6279841b019270=1000.00271=3.10000000269=1278=4dde1422-98d8-405b-88df-bf245291ad7a270=1000.00271=3.10000000269=1278=6ee8b5a8-bc2f-4a0a-9ae4-7ff1b5dae941270=1000.00271=3.1000000010=216
20250410-22:58:19.708210000 : 8=FIXT.1.19=14235=334=4149=24ab46f784d1b20db435b852086e325052=20250410-22:58:19.70756=Coinbase45=17458=Tag appears more than once371=269372=W373=1310=059
20250410-22:58:19.708286000 : 8=FIXT.1.19=93935=W49=Coinbase56=24ab46f784d1b20db435b852086e325034=17550=TEST52=20250410-22:58:19.369239369=2262=cf1c957f-e1dc-4130-bd81-966e629da3c683=1597361889893=N55=BTC-USD1682=full_trading268=10269=1278=3ebc1f7a-2bb5-4ef0-a82f-844b9540f6e8270=1000.00271=3.10000000269=1278=a82d5bb9-1f1a-4575-b580-8d9b60863b10270=1000.00271=3.10000000269=1278=14f89bd5-0233-435c-b608-2e19131b8f6c270=1000.00271=3.10000000269=1278=a2e319e5-aab7-41d4-9d19-98d771a3f1d3270=1000.00271=3.10000000269=1278=dc965e0b-075a-4ba4-a498-02c96d1664ba270=1000.00271=3.10000000269=1278=67b6e68f-ac11-4c05-a54a-2adb555b0123270=1000.00271=3.10000000269=1278=866f52a1-dad9-49d7-ac4a-9da3075407a3270=1000.00271=3.10000000269=1278=0e38234d-a010-40f6-9c6f-a0d574e773cf270=1000.00271=3.10000000269=1278=d6af6749-e3c8-4938-8741-1d5f177cf8e1270=1000.00271=3.10000000269=1278=45ff5e59-2c4d-45ac-9fde-403662dfd1ca270=1000.00271=3.1000000010=079
20250410-22:58:19.708873000 : 8=FIXT.1.19=14235=334=4249=24ab46f784d1b20db435b852086e325052=20250410-22:58:19.70856=Coinbase45=17558=Tag appears more than once371=269372=W373=1310=062
20250410-22:58:19.708989000 : 8=FIXT.1.19=94535=W49=Coinbase56=24ab46f784d1b20db435b852086e325034=17650=TEST52=20250410-22:58:19.369489369=2262=cf1c957f-e1dc-4130-bd81-966e629da3c683=1597361889893=N55=BTC-USD1682=full_trading268=10269=1278=dcac314e-c54f-44e3-b96d-ef71539766ed270=1000.00271=3.10000000269=1278=dd6d14ea-760f-4884-a546-1d3c40ebdd7c270=1000.00271=3.10000000269=1278=4f3da0c6-46eb-4b64-b973-cc43e24abccb270=1000.00271=3.10000000269=1278=aa40cda8-4abd-4f52-999a-1a90ed5bf41a270=1000.00271=3.10000000269=1278=687ee4fc-f626-4e4f-abee-1f0ee5af3f72270=1000.00271=3.10000000269=1278=b1ad1135-67ec-4c96-99cb-a626137f3f16270=10000.00271=1.00000000269=1278=e9320f5f-80ae-41ab-af7a-86518d456fb0270=10000.00271=1.00000000269=1278=cd95aff0-36fa-4804-887f-2c3fce3cdc86270=10000.00271=1.00000000269=1278=fbdbcee1-8c29-4478-97df-358d209d8808270=10000.00271=1.00000000269=1278=140f39da-834b-4e42-8e15-6e25287df1f0270=900000.00271=0.0001111110=142
20250410-22:58:19.709542000 : 8=FIXT.1.19=14235=334=4349=24ab46f784d1b20db435b852086e325052=20250410-22:58:19.70956=Coinbase45=17658=Tag appears more than once371=269372=W373=1310=065
20250410-22:58:19.709621000 : 8=FIXT.1.19=95935=W49=Coinbase56=24ab46f784d1b20db435b852086e325034=17750=TEST52=20250410-22:58:19.369739369=2262=cf1c957f-e1dc-4130-bd81-966e629da3c683=1597361889893=N55=BTC-USD1682=full_trading268=10269=1278=49f064c5-76fe-4b38-bede-48b60a0a5aec270=900000.00271=0.00011111269=1278=681cf73b-9d37-4101-b940-9da9b1ff61ed270=900000.00271=0.00011111269=1278=3dea1587-e474-4258-b6e8-485c21b56670270=900000.00271=0.00011111269=1278=afd96a7b-3d48-459e-b810-e4ee88353a31270=900000.00271=0.00011111269=1278=a68ae029-b920-4ae7-a775-ccdb800fc252270=900000.00271=0.00001111269=1278=d44508b7-1c9f-4b4f-acb8-99c93d2b99e8270=900000.00271=0.00001111269=1278=304ff106-de40-4381-89c5-c93f7f3e32ae270=900000.00271=0.00001111269=1278=08a0fef8-fcbb-4857-8463-2599cf331386270=900000.00271=0.00011111269=1278=07b2856d-f899-417c-82d5-886f0d85125e270=900000.00271=0.00011111269=1278=12ecb45e-6af8-4804-a942-5c997b9d1502270=900000.00271=0.0001111110=231
20250410-22:58:19.710374000 : 8=FIXT.1.19=14235=334=4449=24ab46f784d1b20db435b852086e325052=20250410-22:58:19.70956=Coinbase45=17758=Tag appears more than once371=269372=W373=1310=067
20250410-22:58:19.710469000 : 8=FIXT.1.19=81035=W49=Coinbase56=24ab46f784d1b20db435b852086e325034=17850=TEST52=20250410-22:58:19.369989369=2262=cf1c957f-e1dc-4130-bd81-966e629da3c683=1597361889893=Y55=BTC-USD1682=full_trading268=8269=1278=98676c5f-b851-473c-817a-b29243092a25270=900000.00271=0.00001111269=1278=09afe685-e71f-4ea0-b164-c27737db126d270=900000.00271=0.00001111269=1278=e71ee98f-c329-428d-9893-629b53015ff6270=900000.00271=0.00001111269=1278=124e6fc1-6dde-452b-be03-c00113c8ebdb270=900000.00271=0.00011111269=1278=b71cc7f5-d7c6-4fc0-a0de-59b0eb7fd063270=1000000.00271=1.00000000269=1278=afec127b-a98c-49cb-893f-e385a7e35d32270=1000000.00271=1.00000000269=1278=06df7c57-366d-4d2c-acc2-e6c26d60e9c3270=1000000.00271=1.00000000269=1278=b1c4eb2b-90df-44e0-ae4f-515df4086a9d270=9999999.00271=0.0000100010=130
20250410-22:58:19.711198000 : 8=FIXT.1.19=14235=334=4549=24ab46f784d1b20db435b852086e325052=20250410-22:58:19.71056=Coinbase45=17858=Tag appears more than once371=269372=W373=1310=061
20250410-22:58:19.768703000 : 8=FIXT.1.19=8435=534=4649=24ab46f784d1b20db435b852086e325052=20250410-22:58:19.76756=Coinbase10=186
20250410-22:58:19.876665000 : 8=FIXT.1.19=28435=X49=Coinbase56=24ab46f784d1b20db435b852086e325034=17950=TEST52=20250410-22:58:19.768120369=21262=cf1c957f-e1dc-4130-bd81-966e629da3c6268=1279=0269=083=159736189355=BTC-USD270=3.77271=0.6232294660=20250410-22:58:19.76630140=237=a689ddcb-fb42-4b54-a42b-0914d91f849d10=032
20250410-22:58:19.877166000 : 8=FIXT.1.19=32735=X49=Coinbase56=24ab46f784d1b20db435b852086e325034=18050=TEST52=20250410-22:58:19.768131369=21262=cf1c957f-e1dc-4130-bd81-966e629da3c6268=1279=0269=2278=b9704cf1-f180-4d92-90da-6bb364d4a71583=159736189455=BTC-USD270=3.54271=0.6232294660=20250410-22:58:19.76630137=a689ddcb-fb42-4b54-a42b-0914d91f849d5797=110=173
20250410-22:58:19.877553000 : 8=FIXT.1.19=29035=X49=Coinbase56=24ab46f784d1b20db435b852086e325034=18150=TEST52=20250410-22:58:19.768136369=21262=cf1c957f-e1dc-4130-bd81-966e629da3c6268=1279=2269=0278=a689ddcb-fb42-4b54-a42b-0914d91f849d83=159736189555=BTC-USD270=3.77271=0.0000000060=20250410-22:58:19.76630158=FILLED10=189
20250410-22:58:19.931547000 : 8=FIXT.1.19=28435=X49=Coinbase56=24ab46f784d1b20db435b852086e325034=18250=TEST52=20250410-22:58:19.823471369=32262=cf1c957f-e1dc-4130-bd81-966e629da3c6268=1279=0269=183=159736189655=BTC-USD270=3.27271=0.6232294660=20250410-22:58:19.82181440=237=5b59e255-08c2-4ea5-b42c-7c03ec92a8e210=228
20250410-22:58:19.932076000 : 8=FIXT.1.19=32735=X49=Coinbase56=24ab46f784d1b20db435b852086e325034=18350=TEST52=20250410-22:58:19.823485369=32262=cf1c957f-e1dc-4130-bd81-966e629da3c6268=1279=0269=2278=4d60a78e-b39b-420e-b830-bc0f3f4fdde283=159736189755=BTC-USD270=3.53271=0.6232294660=20250410-22:58:19.82181437=5b59e255-08c2-4ea5-b42c-7c03ec92a8e25797=210=060
20250410-22:58:19.932341000 : 8=FIXT.1.19=29035=X49=Coinbase56=24ab46f784d1b20db435b852086e325034=18450=TEST52=20250410-22:58:19.823489369=32262=cf1c957f-e1dc-4130-bd81-966e629da3c6268=1279=2269=1278=5b59e255-08c2-4ea5-b42c-7c03ec92a8e283=159736189855=BTC-USD270=3.27271=0.0000000060=20250410-22:58:19.82181458=FILLED10=140
20250410-22:58:19.999441000 : 8=FIXT.1.19=12035=549=Coinbase56=24ab46f784d1b20db435b852086e325034=18550=TEST52=20250410-22:58:19.891543369=4558=CLIENT_LOGOUT10=126
20250410-22:59:36.929272000 : 8=FIXT.1.19=21535=A34=149=24ab46f784d1b20db435b852086e325052=20250410-22:59:36.89056=Coinbase95=4496=g4x2C/sY/lfnD/PQwTb+VLWf7AvNqUj4PKzPCdaHtxk=98=0108=30141=Y553=24ab46f784d1b20db435b852086e3250554=akmwnltyfgb1137=910=040
20250410-22:59:37.187907000 : 8=FIXT.1.19=12535=A49=Coinbase56=24ab46f784d1b20db435b852086e325034=150=TEST52=20250410-22:59:37.078997369=198=0108=30141=Y1137=910=219
20250410-22:59:38.652815000 : 8=FIXT.1.19=17835=V34=249=24ab46f784d1b20db435b852086e325052=20250410-22:59:38.65256=Coinbase1128=9146=155=BTC-USD262=951674d8-b877-4a40-8deb-be5318522964263=1264=0267=2269=0269=110=155
20250410-22:59:39.081321000 : 8=FIXT.1.19=28135=X49=Coinbase56=24ab46f784d1b20db435b852086e325034=250=TEST52=20250410-22:59:38.971750369=2262=951674d8-b877-4a40-8deb-be5318522964268=1279=0269=083=159736362155=BTC-USD270=3.87271=0.6232294660=20250410-22:59:38.96953340=237=bade5c88-e834-4e05-884a-24b1c421955110=018
20250410-22:59:39.084952000 : 8=FIXT.1.19=32435=X49=Coinbase56=24ab46f784d1b20db435b852086e325034=350=TEST52=20250410-22:59:38.971759369=2262=951674d8-b877-4a40-8deb-be5318522964268=1279=0269=2278=b9704cf1-f180-4d92-90da-6bb364d4a71583=159736362255=BTC-USD270=3.54271=0.6232294660=20250410-22:59:38.96953337=bade5c88-e834-4e05-884a-24b1c42195515797=110=174
20250410-22:59:39.089637000 : 8=FIXT.1.19=28735=X49=Coinbase56=24ab46f784d1b20db435b852086e325034=450=TEST52=20250410-22:59:38.971763369=2262=951674d8-b877-4a40-8deb-be5318522964268=1279=2269=0278=bade5c88-e834-4e05-884a-24b1c421955183=159736362355=BTC-USD270=3.87271=0.0000000060=20250410-22:59:38.96953358=FILLED10=190
20250410-22:59:39.138068000 : 8=FIXT.1.19=30035=X49=Coinbase56=24ab46f784d1b20db435b852086e325034=550=TEST52=20250410-22:59:39.027587369=2262=951674d8-b877-4a40-8deb-be5318522964268=1279=0269=183=159736362455=BTC-USD270=3.18271=0.5609065129004=1.979999980360=20250410-22:59:39.02637340=237=9124aa57-c79d-405f-84e1-9d662829ce5510=165
20250410-22:59:39.138372000 : 8=FIXT.1.19=32435=X49=Coinbase56=24ab46f784d1b20db435b852086e325034=650=TEST52=20250410-22:59:39.027593369=2262=951674d8-b877-4a40-8deb-be5318522964268=1279=0269=2278=4d60a78e-b39b-420e-b830-bc0f3f4fdde283=159736362555=BTC-USD270=3.53271=0.5609065160=20250410-22:59:39.02637337=9124aa57-c79d-405f-84e1-9d662829ce555797=210=057
20250410-22:59:39.138631000 : 8=FIXT.1.19=27835=X49=Coinbase56=24ab46f784d1b20db435b852086e325034=750=TEST52=20250410-22:59:39.027598369=2262=951674d8-b877-4a40-8deb-be5318522964268=1279=2269=1278=9124aa57-c79d-405f-84e1-9d662829ce5583=159736362655=BTC-USD270=3.18271=060=20250410-22:59:39.02637358=FILLED10=231
20250410-22:59:39.310157000 : 8=FIXT.1.19=28135=X49=Coinbase56=24ab46f784d1b20db435b852086e325034=850=TEST52=20250410-22:59:39.202324369=2262=951674d8-b877-4a40-8deb-be5318522964268=1279=0269=183=159736362755=BTC-USD270=3.24271=0.6232294660=20250410-22:59:39.20076540=237=d83a4dca-f624-46de-ac4d-c72bd5b1897010=230
20250410-22:59:39.310636000 : 8=FIXT.1.19=32435=X49=Coinbase56=24ab46f784d1b20db435b852086e325034=950=TEST52=20250410-22:59:39.202332369=2262=951674d8-b877-4a40-8deb-be5318522964268=1279=0269=2278=4d60a78e-b39b-420e-b830-bc0f3f4fdde283=159736362855=BTC-USD270=3.53271=0.6232294660=20250410-22:59:39.20076537=d83a4dca-f624-46de-ac4d-c72bd5b189705797=210=059
20250410-22:59:39.311002000 : 8=FIXT.1.19=28835=X49=Coinbase56=24ab46f784d1b20db435b852086e325034=1050=TEST52=20250410-22:59:39.202337369=2262=951674d8-b877-4a40-8deb-be5318522964268=1279=2269=1278=d83a4dca-f624-46de-ac4d-c72bd5b1897083=159736362955=BTC-USD270=3.24271=0.0000000060=20250410-22:59:39.20076558=FILLED10=186
20250410-22:59:39.364474000 : 8=FIXT.1.19=28235=X49=Coinbase56=24ab46f784d1b20db435b852086e325034=1150=TEST52=20250410-22:59:39.256265369=2262=951674d8-b877-4a40-8deb-be5318522964268=1279=0269=083=159736363055=BTC-USD270=3.84271=0.6232294660=20250410-22:59:39.25515140=237=52874ea6-7c79-4302-90a8-d889f7a8ecc010=070
20250410-22:59:39.365117000 : 8=FIXT.1.19=32535=X49=Coinbase56=24ab46f784d1b20db435b852086e325034=1250=TEST52=20250410-22:59:39.256274369=2262=951674d8-b877-4a40-8deb-be5318522964268=1279=0269=2278=b9704cf1-f180-4d92-90da-6bb364d4a71583=159736363155=BTC-USD270=3.54271=0.6232294660=20250410-22:59:39.25515137=52874ea6-7c79-4302-90a8-d889f7a8ecc05797=110=220
20250410-22:59:39.365464000 : 8=FIXT.1.19=28835=X49=Coinbase56=24ab46f784d1b20db435b852086e325034=1350=TEST52=20250410-22:59:39.256278369=2262=951674d8-b877-4a40-8deb-be5318522964268=1279=2269=0278=52874ea6-7c79-4302-90a8-d889f7a8ecc083=159736363255=BTC-USD270=3.84271=0.0000000060=20250410-22:59:39.25515158=FILLED10=242
20250410-22:59:40.108088000 : 8=FIXT.1.19=28235=X49=Coinbase56=24ab46f784d1b20db435b852086e325034=1450=TEST52=20250410-22:59:40.000408369=2262=951674d8-b877-4a40-8deb-be5318522964268=1279=0269=083=159736363355=BTC-USD270=3.85271=0.6214689360=20250410-22:59:39.99875340=237=3ea09017-b13b-4c4c-bea7-4641f332125d10=081
20250410-22:59:40.108439000 : 8=FIXT.1.19=32535=X49=Coinbase56=24ab46f784d1b20db435b852086e325034=1550=TEST52=20250410-22:59:40.000420369=2262=951674d8-b877-4a40-8deb-be5318522964268=1279=0269=2278=b9704cf1-f180-4d92-90da-6bb364d4a71583=159736363455=BTC-USD270=3.54271=0.6214689360=20250410-22:59:39.99875337=3ea09017-b13b-4c4c-bea7-4641f332125d5797=110=224
20250410-22:59:40.108636000 : 8=FIXT.1.19=28835=X49=Coinbase56=24ab46f784d1b20db435b852086e325034=1650=TEST52=20250410-22:59:40.000424369=2262=951674d8-b877-4a40-8deb-be5318522964268=1279=2269=0278=3ea09017-b13b-4c4c-bea7-4641f332125d83=159736363555=BTC-USD270=3.85271=0.0000000060=20250410-22:59:39.99875358=FILLED10=242
20250410-22:59:40.164547000 : 8=FIXT.1.19=28235=X49=Coinbase56=24ab46f784d1b20db435b852086e325034=1750=TEST52=20250410-22:59:40.056081369=2262=951674d8-b877-4a40-8deb-be5318522964268=1279=0269=183=159736363655=BTC-USD270=3.26271=0.6214689360=20250410-22:59:40.05440340=237=30febefe-0b2a-4921-9fd3-c50239a42d8d10=218
20250410-22:59:40.165103000 : 8=FIXT.1.19=32535=X49=Coinbase56=24ab46f784d1b20db435b852086e325034=1850=TEST52=20250410-22:59:40.056140369=2262=951674d8-b877-4a40-8deb-be5318522964268=1279=0269=2278=4d60a78e-b39b-420e-b830-bc0f3f4fdde283=159736363755=BTC-USD270=3.53271=0.6214689360=20250410-22:59:40.05440337=30febefe-0b2a-4921-9fd3-c50239a42d8d5797=210=042
20250410-22:59:40.165619000 : 8=FIXT.1.19=28835=X49=Coinbase56=24ab46f784d1b20db435b852086e325034=1950=TEST52=20250410-22:59:40.056146369=2262=951674d8-b877-4a40-8deb-be5318522964268=1279=2269=1278=30febefe-0b2a-4921-9fd3-c50239a42d8d83=159736363855=BTC-USD270=3.26271=0.0000000060=20250410-22:59:40.05440358=FILLED10=127
20250410-22:59:40.682043000 : 8=FIXT.1.19=28135=X49=Coinbase56=24ab46f784d1b20db435b852086e325034=2050=TEST52=20250410-22:59:40.573334369=2262=951674d8-b877-4a40-8deb-be5318522964268=1279=0269=183=159736363955=BTC-USD270=3.3271=0.6232294660=20250410-22:59:40.57140940=237=95f645c3-25f0-4283-92c5-366eabccae5910=046
20250410-22:59:40.682453000 : 8=FIXT.1.19=32535=X49=Coinbase56=24ab46f784d1b20db435b852086e325034=2150=TEST52=20250410-22:59:40.573342369=2262=951674d8-b877-4a40-8deb-be5318522964268=1279=0269=2278=4d60a78e-b39b-420e-b830-bc0f3f4fdde283=159736364055=BTC-USD270=3.53271=0.6232294660=20250410-22:59:40.57140937=95f645c3-25f0-4283-92c5-366eabccae595797=210=174
20250410-22:59:40.682741000 : 8=FIXT.1.19=28735=X49=Coinbase56=24ab46f784d1b20db435b852086e325034=2250=TEST52=20250410-22:59:40.573347369=2262=951674d8-b877-4a40-8deb-be5318522964268=1279=2269=1278=95f645c3-25f0-4283-92c5-366eabccae5983=159736364155=BTC-USD270=3.3271=0.0000000060=20250410-22:59:40.57140958=FILLED10=209
20250410-22:59:40.735682000 : 8=FIXT.1.19=28235=X49=Coinbase56=24ab46f784d1b20db435b852086e325034=2350=TEST52=20250410-22:59:40.627923369=2262=951674d8-b877-4a40-8deb-be5318522964268=1279=0269=083=159736364255=BTC-USD270=3.79271=0.6232294660=20250410-22:59:40.62587440=237=dba25064-87c1-4d7c-9fc3-da7c78fd11da10=040
20250410-22:59:40.736087000 : 8=FIXT.1.19=32535=X49=Coinbase56=24ab46f784d1b20db435b852086e325034=2450=TEST52=20250410-22:59:40.627933369=2262=951674d8-b877-4a40-8deb-be5318522964268=1279=0269=2278=b9704cf1-f180-4d92-90da-6bb364d4a71583=159736364355=BTC-USD270=3.54271=0.6232294660=20250410-22:59:40.62587437=dba25064-87c1-4d7c-9fc3-da7c78fd11da5797=110=187
20250410-22:59:40.736336000 : 8=FIXT.1.19=28835=X49=Coinbase56=24ab46f784d1b20db435b852086e325034=2550=TEST52=20250410-22:59:40.627937369=2262=951674d8-b877-4a40-8deb-be5318522964268=1279=2269=0278=dba25064-87c1-4d7c-9fc3-da7c78fd11da83=159736364455=BTC-USD270=3.79271=0.0000000060=20250410-22:59:40.62587458=FILLED10=213
20250410-22:59:41.491583000 : 8=FIXT.1.19=27735=X49=Coinbase56=24ab46f784d1b20db435b852086e325034=2650=TEST52=20250410-22:59:41.383165369=2262=951674d8-b877-4a40-8deb-be5318522964268=1279=0269=083=159736364555=BTC-USD29004=2.208895536660=20250410-22:59:41.38167240=137=a8625800-56f2-4902-976d-9b263f03f23710=182
20250410-22:59:41.493157000 : 8=FIXT.1.19=32535=X49=Coinbase56=24ab46f784d1b20db435b852086e325034=2750=TEST52=20250410-22:59:41.383173369=2262=951674d8-b877-4a40-8deb-be5318522964268=1279=0269=2278=b9704cf1-f180-4d92-90da-6bb364d4a71583=159736364655=BTC-USD270=3.54271=0.6239817960=20250410-22:59:41.38167237=a8625800-56f2-4902-976d-9b263f03f2375797=110=030
20250410-22:59:41.493721000 : 8=FIXT.1.19=26435=X49=Coinbase56=24ab46f784d1b20db435b852086e325034=2850=TEST52=20250410-22:59:41.383178369=2262=951674d8-b877-4a40-8deb-be5318522964268=1279=2269=0278=a8625800-56f2-4902-976d-9b263f03f23783=159736364755=BTC-USD60=20250410-22:59:41.38167258=FILLED10=202
20250410-22:59:41.530189000 : 8=FIXT.1.19=27335=X49=Coinbase56=24ab46f784d1b20db435b852086e325034=2950=TEST52=20250410-22:59:41.412108369=2262=951674d8-b877-4a40-8deb-be5318522964268=1279=0269=183=159736364855=BTC-USD271=0.6214689360=20250410-22:59:41.41085340=137=d154b392-8ff9-4afe-874c-56b4cf55a95310=001
20250410-22:59:41.530616000 : 8=FIXT.1.19=32535=X49=Coinbase56=24ab46f784d1b20db435b852086e325034=3050=TEST52=20250410-22:59:41.412115369=2262=951674d8-b877-4a40-8deb-be5318522964268=1279=0269=2278=4d60a78e-b39b-420e-b830-bc0f3f4fdde283=159736364955=BTC-USD270=3.53271=0.6214689360=20250410-22:59:41.41085337=d154b392-8ff9-4afe-874c-56b4cf55a9535797=210=235
20250410-22:59:41.530820000 : 8=FIXT.1.19=27935=X49=Coinbase56=24ab46f784d1b20db435b852086e325034=3150=TEST52=20250410-22:59:41.412119369=2262=951674d8-b877-4a40-8deb-be5318522964268=1279=2269=1278=d154b392-8ff9-4afe-874c-56b4cf55a95383=159736365055=BTC-USD271=0.0000000060=20250410-22:59:41.41085358=FILLED10=149
20250410-22:59:41.593778000 : 8=FIXT.1.19=28235=X49=Coinbase56=24ab46f784d1b20db435b852086e325034=3250=TEST52=20250410-22:59:41.486088369=2262=951674d8-b877-4a40-8deb-be5318522964268=1279=0269=183=159736365155=BTC-USD270=3.32271=0.6232294660=20250410-22:59:41.48402740=237=a8e166c4-56c4-4d3e-b73a-d62c8be8975b10=203
20250410-22:59:41.594042000 : 8=FIXT.1.19=32535=X49=Coinbase56=24ab46f784d1b20db435b852086e325034=3350=TEST52=20250410-22:59:41.486165369=2262=951674d8-b877-4a40-8deb-be5318522964268=1279=0269=2278=4d60a78e-b39b-420e-b830-bc0f3f4fdde283=159736365255=BTC-USD270=3.53271=0.6232294660=20250410-22:59:41.48402737=a8e166c4-56c4-4d3e-b73a-d62c8be8975b5797=210=030
20250410-22:59:41.594222000 : 8=FIXT.1.19=28835=X49=Coinbase56=24ab46f784d1b20db435b852086e325034=3450=TEST52=20250410-22:59:41.486176369=2262=951674d8-b877-4a40-8deb-be5318522964268=1279=2269=1278=a8e166c4-56c4-4d3e-b73a-d62c8be8975b83=159736365355=BTC-USD270=3.32271=0.0000000060=20250410-22:59:41.48402758=FILLED10=113
20250410-22:59:41.605616000 : 8=FIXT.1.19=27735=X49=Coinbase56=24ab46f784d1b20db435b852086e325034=3550=TEST52=20250410-22:59:41.497426369=2262=951674d8-b877-4a40-8deb-be5318522964268=1279=0269=083=159736365455=BTC-USD29004=2.208895536660=20250410-22:59:41.49612840=137=10ee44f7-ee46-44c0-9f5a-fef418558be310=018
20250410-22:59:41.605961000 : 8=FIXT.1.19=32535=X49=Coinbase56=24ab46f784d1b20db435b852086e325034=3650=TEST52=20250410-22:59:41.497433369=2262=951674d8-b877-4a40-8deb-be5318522964268=1279=0269=2278=b9704cf1-f180-4d92-90da-6bb364d4a71583=159736365555=BTC-USD270=3.54271=0.6239817960=20250410-22:59:41.49612837=10ee44f7-ee46-44c0-9f5a-fef418558be35797=110=121
20250410-22:59:41.606432000 : 8=FIXT.1.19=26435=X49=Coinbase56=24ab46f784d1b20db435b852086e325034=3750=TEST52=20250410-22:59:41.497437369=2262=951674d8-b877-4a40-8deb-be5318522964268=1279=2269=0278=10ee44f7-ee46-44c0-9f5a-fef418558be383=159736365655=BTC-USD60=20250410-22:59:41.49612858=FILLED10=036
20250410-22:59:41.633568000 : 8=FIXT.1.19=27335=X49=Coinbase56=24ab46f784d1b20db435b852086e325034=3850=TEST52=20250410-22:59:41.525396369=2262=951674d8-b877-4a40-8deb-be5318522964268=1279=0269=183=159736365755=BTC-USD271=0.6232294660=20250410-22:59:41.52421540=137=8ac083c4-2f57-477c-8534-058321bc7efa10=151
20250410-22:59:41.633984000 : 8=FIXT.1.19=32535=X49=Coinbase56=24ab46f784d1b20db435b852086e325034=3950=TEST52=20250410-22:59:41.525403369=2262=951674d8-b877-4a40-8deb-be5318522964268=1279=0269=2278=4d60a78e-b39b-420e-b830-bc0f3f4fdde283=159736365855=BTC-USD270=3.53271=0.6232294660=20250410-22:59:41.52421537=8ac083c4-2f57-477c-8534-058321bc7efa5797=210=129
20250410-22:59:41.634211000 : 8=FIXT.1.19=27935=X49=Coinbase56=24ab46f784d1b20db435b852086e325034=4050=TEST52=20250410-22:59:41.525408369=2262=951674d8-b877-4a40-8deb-be5318522964268=1279=2269=1278=8ac083c4-2f57-477c-8534-058321bc7efa83=159736365955=BTC-USD271=0.0000000060=20250410-22:59:41.52421558=FILLED10=049
20250410-22:59:41.650101000 : 8=FIXT.1.19=28235=X49=Coinbase56=24ab46f784d1b20db435b852086e325034=4150=TEST52=20250410-22:59:41.541087369=2262=951674d8-b877-4a40-8deb-be5318522964268=1279=0269=083=159736366055=BTC-USD270=3.77271=0.6232294660=20250410-22:59:41.53957240=237=443e8e65-686c-4ad7-8ea7-040acabff2b410=245
20250410-22:59:41.650622000 : 8=FIXT.1.19=32535=X49=Coinbase56=24ab46f784d1b20db435b852086e325034=4250=TEST52=20250410-22:59:41.541094369=2262=951674d8-b877-4a40-8deb-be5318522964268=1279=0269=2278=b9704cf1-f180-4d92-90da-6bb364d4a71583=159736366155=BTC-USD270=3.54271=0.6232294660=20250410-22:59:41.53957237=443e8e65-686c-4ad7-8ea7-040acabff2b45797=110=135
20250410-22:59:41.650782000 : 8=FIXT.1.19=28835=X49=Coinbase56=24ab46f784d1b20db435b852086e325034=4350=TEST52=20250410-22:59:41.541098369=2262=951674d8-b877-4a40-8deb-be5318522964268=1279=2269=0278=443e8e65-686c-4ad7-8ea7-040acabff2b483=159736366255=BTC-USD270=3.77271=0.0000000060=20250410-22:59:41.53957258=FILLED10=159
20250410-22:59:41.892178000 : 8=FIXT.1.19=27735=X49=Coinbase56=24ab46f784d1b20db435b852086e325034=4450=TEST52=20250410-22:59:41.784432369=2262=951674d8-b877-4a40-8deb-be5318522964268=1279=0269=083=159736366355=BTC-USD29004=2.208895536660=20250410-22:59:41.78186740=137=12a0dab0-d7e4-4cdc-9d6e-3427eea6367210=047
20250410-22:59:41.892698000 : 8=FIXT.1.19=32535=X49=Coinbase56=24ab46f784d1b20db435b852086e325034=4550=TEST52=20250410-22:59:41.784443369=2262=951674d8-b877-4a40-8deb-be5318522964268=1279=0269=2278=b9704cf1-f180-4d92-90da-6bb364d4a71583=159736366455=BTC-USD270=3.54271=0.6239817960=20250410-22:59:41.78186737=12a0dab0-d7e4-4cdc-9d6e-3427eea636725797=110=154
20250410-22:59:41.893148000 : 8=FIXT.1.19=26435=X49=Coinbase56=24ab46f784d1b20db435b852086e325034=4650=TEST52=20250410-22:59:41.784447369=2262=951674d8-b877-4a40-8deb-be5318522964268=1279=2269=0278=12a0dab0-d7e4-4cdc-9d6e-3427eea6367283=159736366555=BTC-USD60=20250410-22:59:41.78186758=FILLED10=069
20250410-22:59:41.919673000 : 8=FIXT.1.19=27335=X49=Coinbase56=24ab46f784d1b20db435b852086e325034=4750=TEST52=20250410-22:59:41.812181369=2262=951674d8-b877-4a40-8deb-be5318522964268=1279=0269=183=159736366655=BTC-USD271=0.6214689360=20250410-22:59:41.81079540=137=a7124c08-3641-43d0-84a1-da924aeabed710=230
20250410-22:59:41.920089000 : 8=FIXT.1.19=32535=X49=Coinbase56=24ab46f784d1b20db435b852086e325034=4850=TEST52=20250410-22:59:41.812190369=2262=951674d8-b877-4a40-8deb-be5318522964268=1279=0269=2278=4d60a78e-b39b-420e-b830-bc0f3f4fdde283=159736366755=BTC-USD270=3.53271=0.6214689360=20250410-22:59:41.81079537=a7124c08-3641-43d0-84a1-da924aeabed75797=210=219
20250410-22:59:41.920365000 : 8=FIXT.1.19=27935=X49=Coinbase56=24ab46f784d1b20db435b852086e325034=4950=TEST52=20250410-22:59:41.812194369=2262=951674d8-b877-4a40-8deb-be5318522964268=1279=2269=1278=a7124c08-3641-43d0-84a1-da924aeabed783=159736366855=BTC-USD271=0.0000000060=20250410-22:59:41.81079558=FILLED10=142
20250410-22:59:41.937328000 : 8=FIXT.1.19=28235=X49=Coinbase56=24ab46f784d1b20db435b852086e325034=5050=TEST52=20250410-22:59:41.828950369=2262=951674d8-b877-4a40-8deb-be5318522964268=1279=0269=083=159736366955=BTC-USD270=3.72271=0.6232294660=20250410-22:59:41.82716840=237=07609b4d-778b-453f-b199-cc5ec67e79c910=142
20250410-22:59:41.937795000 : 8=FIXT.1.19=32535=X49=Coinbase56=24ab46f784d1b20db435b852086e325034=5150=TEST52=20250410-22:59:41.828958369=2262=951674d8-b877-4a40-8deb-be5318522964268=1279=0269=2278=b9704cf1-f180-4d92-90da-6bb364d4a71583=159736367055=BTC-USD270=3.54271=0.6232294660=20250410-22:59:41.82716837=07609b4d-778b-453f-b199-cc5ec67e79c95797=110=038
20250410-22:59:41.938075000 : 8=FIXT.1.19=28835=X49=Coinbase56=24ab46f784d1b20db435b852086e325034=5250=TEST52=20250410-22:59:41.828962369=2262=951674d8-b877-4a40-8deb-be5318522964268=1279=2269=0278=07609b4d-778b-453f-b199-cc5ec67e79c983=159736367155=BTC-USD270=3.72271=0.0000000060=20250410-22:59:41.82716858=FILLED10=048
20250410-22:59:41.950161000 : 8=FIXT.1.19=27735=X49=Coinbase56=24ab46f784d1b20db435b852086e325034=5350=TEST52=20250410-22:59:41.840785369=2262=951674d8-b877-4a40-8deb-be5318522964268=1279=0269=083=159736367255=BTC-USD29004=2.208895536660=20250410-22:59:41.83949940=137=970e1ec5-d2c7-4cf8-8857-96685bd2408f10=160
20250410-22:59:41.950414000 : 8=FIXT.1.19=32535=X49=Coinbase56=24ab46f784d1b20db435b852086e325034=5450=TEST52=20250410-22:59:41.840803369=2262=951674d8-b877-4a40-8deb-be5318522964268=1279=0269=2278=b9704cf1-f180-4d92-90da-6bb364d4a71583=159736367355=BTC-USD270=3.54271=0.6239817960=20250410-22:59:41.83949937=970e1ec5-d2c7-4cf8-8857-96685bd2408f5797=110=000
20250410-22:59:41.950745000 : 8=FIXT.1.19=26435=X49=Coinbase56=24ab46f784d1b20db435b852086e325034=5550=TEST52=20250410-22:59:41.840807369=2262=951674d8-b877-4a40-8deb-be5318522964268=1279=2269=0278=970e1ec5-d2c7-4cf8-8857-96685bd2408f83=159736367455=BTC-USD60=20250410-22:59:41.83949958=FILLED10=171
20250410-22:59:41.977786000 : 8=FIXT.1.19=27335=X49=Coinbase56=24ab46f784d1b20db435b852086e325034=5650=TEST52=20250410-22:59:41.869244369=2262=951674d8-b877-4a40-8deb-be5318522964268=1279=0269=183=159736367555=BTC-USD271=0.6214689360=20250410-22:59:41.86736740=137=a3b88f02-f200-463d-a482-0f7481439c4f10=120
20250410-22:59:41.978199000 : 8=FIXT.1.19=32535=X49=Coinbase56=24ab46f784d1b20db435b852086e325034=5750=TEST52=20250410-22:59:41.869250369=2262=951674d8-b877-4a40-8deb-be5318522964268=1279=0269=2278=4d60a78e-b39b-420e-b830-bc0f3f4fdde283=159736367655=BTC-USD270=3.53271=0.6214689360=20250410-22:59:41.86736737=a3b88f02-f200-463d-a482-0f7481439c4f5797=210=106
20250410-22:59:41.978587000 : 8=FIXT.1.19=27935=X49=Coinbase56=24ab46f784d1b20db435b852086e325034=5850=TEST52=20250410-22:59:41.869254369=2262=951674d8-b877-4a40-8deb-be5318522964268=1279=2269=1278=a3b88f02-f200-463d-a482-0f7481439c4f83=159736367755=BTC-USD271=0.0000000060=20250410-22:59:41.86736758=FILLED10=029
20250410-22:59:41.991476000 : 8=FIXT.1.19=28135=X49=Coinbase56=24ab46f784d1b20db435b852086e325034=5950=TEST52=20250410-22:59:41.883748369=2262=951674d8-b877-4a40-8deb-be5318522964268=1279=0269=183=159736367855=BTC-USD270=3.3271=0.6232294660=20250410-22:59:41.88199940=237=97e4a215-85b7-4f75-bd58-2b55b4be096310=049
20250410-22:59:41.994218000 : 8=FIXT.1.19=32535=X49=Coinbase56=24ab46f784d1b20db435b852086e325034=6050=TEST52=20250410-22:59:41.883754369=2262=951674d8-b877-4a40-8deb-be5318522964268=1279=0269=2278=4d60a78e-b39b-420e-b830-bc0f3f4fdde283=159736367955=BTC-USD270=3.53271=0.6232294660=20250410-22:59:41.88199937=97e4a215-85b7-4f75-bd58-2b55b4be09635797=210=175
20250410-22:59:41.998670000 : 8=FIXT.1.19=28735=X49=Coinbase56=24ab46f784d1b20db435b852086e325034=6150=TEST52=20250410-22:59:41.883758369=2262=951674d8-b877-4a40-8deb-be5318522964268=1279=2269=1278=97e4a215-85b7-4f75-bd58-2b55b4be096383=159736368055=BTC-USD270=3.3271=0.0000000060=20250410-22:59:41.88199958=FILLED10=200
20250410-22:59:42.063288000 : 8=FIXT.1.19=27735=X49=Coinbase56=24ab46f784d1b20db435b852086e325034=6250=TEST52=20250410-22:59:41.955126369=2262=951674d8-b877-4a40-8deb-be5318522964268=1279=0269=083=159736368155=BTC-USD29004=2.208895536660=20250410-22:59:41.95351340=137=70b0c121-57d1-4a6c-aa3a-b815c076a8d710=181
20250410-22:59:42.063627000 : 8=FIXT.1.19=32535=X49=Coinbase56=24ab46f784d1b20db435b852086e325034=6350=TEST52=20250410-22:59:41.955174369=2262=951674d8-b877-4a40-8deb-be5318522964268=1279=0269=2278=b9704cf1-f180-4d92-90da-6bb364d4a71583=159736368255=BTC-USD270=3.54271=0.6239817960=20250410-22:59:41.95351337=70b0c121-57d1-4a6c-aa3a-b815c076a8d75797=110=033
20250410-22:59:42.064123000 : 8=FIXT.1.19=26435=X49=Coinbase56=24ab46f784d1b20db435b852086e325034=6450=TEST52=20250410-22:59:41.955182369=2262=951674d8-b877-4a40-8deb-be5318522964268=1279=2269=0278=70b0c121-57d1-4a6c-aa3a-b815c076a8d783=159736368355=BTC-USD60=20250410-22:59:41.95351358=FILLED10=199
20250410-22:59:42.091765000 : 8=FIXT.1.19=27335=X49=Coinbase56=24ab46f784d1b20db435b852086e325034=6550=TEST52=20250410-22:59:41.983662369=2262=951674d8-b877-4a40-8deb-be5318522964268=1279=0269=183=159736368455=BTC-USD271=0.6232294660=20250410-22:59:41.98192140=137=231b0c0e-b24a-4cec-9e31-ad40bc8b093910=071
20250410-22:59:42.092427000 : 8=FIXT.1.19=32535=X49=Coinbase56=24ab46f784d1b20db435b852086e325034=6650=TEST52=20250410-22:59:41.983669369=2262=951674d8-b877-4a40-8deb-be5318522964268=1279=0269=2278=4d60a78e-b39b-420e-b830-bc0f3f4fdde283=159736368555=BTC-USD270=3.53271=0.6232294660=20250410-22:59:41.98192137=231b0c0e-b24a-4cec-9e31-ad40bc8b09395797=210=067
20250410-22:59:42.092612000 : 8=FIXT.1.19=27935=X49=Coinbase56=24ab46f784d1b20db435b852086e325034=6750=TEST52=20250410-22:59:41.983673369=2262=951674d8-b877-4a40-8deb-be5318522964268=1279=2269=1278=231b0c0e-b24a-4cec-9e31-ad40bc8b093983=159736368655=BTC-USD271=0.0000000060=20250410-22:59:41.98192158=FILLED10=242
20250410-22:59:42.348759000 : 8=FIXT.1.19=27735=X49=Coinbase56=24ab46f784d1b20db435b852086e325034=6850=TEST52=20250410-22:59:42.240917369=2262=951674d8-b877-4a40-8deb-be5318522964268=1279=0269=083=159736368755=BTC-USD29004=2.208895536660=20250410-22:59:42.23924940=137=21eb678e-ce71-4bb2-977e-a579cf6fafb610=124
20250410-22:59:42.349271000 : 8=FIXT.1.19=32535=X49=Coinbase56=24ab46f784d1b20db435b852086e325034=6950=TEST52=20250410-22:59:42.240925369=2262=951674d8-b877-4a40-8deb-be5318522964268=1279=0269=2278=b9704cf1-f180-4d92-90da-6bb364d4a71583=159736368855=BTC-USD270=3.54271=0.6239817960=20250410-22:59:42.23924937=21eb678e-ce71-4bb2-977e-a579cf6fafb65797=110=228
20250410-22:59:42.349625000 : 8=FIXT.1.19=26435=X49=Coinbase56=24ab46f784d1b20db435b852086e325034=7050=TEST52=20250410-22:59:42.240929369=2262=951674d8-b877-4a40-8deb-be5318522964268=1279=2269=0278=21eb678e-ce71-4bb2-977e-a579cf6fafb683=159736368955=BTC-USD60=20250410-22:59:42.23924958=FILLED10=134
20250410-22:59:42.378108000 : 8=FIXT.1.19=27335=X49=Coinbase56=24ab46f784d1b20db435b852086e325034=7150=TEST52=20250410-22:59:42.269175369=2262=951674d8-b877-4a40-8deb-be5318522964268=1279=0269=183=159736369055=BTC-USD271=0.6232294660=20250410-22:59:42.26717540=137=a290ca57-fd94-43f7-abdb-68ac0175e71b10=084
20250410-22:59:42.378618000 : 8=FIXT.1.19=32535=X49=Coinbase56=24ab46f784d1b20db435b852086e325034=7250=TEST52=20250410-22:59:42.269182369=2262=951674d8-b877-4a40-8deb-be5318522964268=1279=0269=2278=4d60a78e-b39b-420e-b830-bc0f3f4fdde283=159736369155=BTC-USD270=3.53271=0.6232294660=20250410-22:59:42.26717537=a290ca57-fd94-43f7-abdb-68ac0175e71b5797=210=071
20250410-22:59:42.378872000 : 8=FIXT.1.19=27935=X49=Coinbase56=24ab46f784d1b20db435b852086e325034=7350=TEST52=20250410-22:59:42.269186369=2262=951674d8-b877-4a40-8deb-be5318522964268=1279=2269=1278=a290ca57-fd94-43f7-abdb-68ac0175e71b83=159736369255=BTC-USD271=0.0000000060=20250410-22:59:42.26717558=FILLED10=255
20250410-22:59:42.510657000 : 8=FIXT.1.19=28235=X49=Coinbase56=24ab46f784d1b20db435b852086e325034=7450=TEST52=20250410-22:59:42.399997369=2262=951674d8-b877-4a40-8deb-be5318522964268=1279=0269=083=159736369355=BTC-USD270=3.73271=0.6232294660=20250410-22:59:42.39878440=237=c5c82b9a-1cc1-4b28-abad-88eb8c0af57d10=163
20250410-22:59:42.511202000 : 8=FIXT.1.19=32535=X49=Coinbase56=24ab46f784d1b20db435b852086e325034=7550=TEST52=20250410-22:59:42.400005369=2262=951674d8-b877-4a40-8deb-be5318522964268=1279=0269=2278=b9704cf1-f180-4d92-90da-6bb364d4a71583=159736369455=BTC-USD270=3.54271=0.6232294660=20250410-22:59:42.39878437=c5c82b9a-1cc1-4b28-abad-88eb8c0af57d5797=110=022
20250410-22:59:42.511637000 : 8=FIXT.1.19=28835=X49=Coinbase56=24ab46f784d1b20db435b852086e325034=7650=TEST52=20250410-22:59:42.400010369=2262=951674d8-b877-4a40-8deb-be5318522964268=1279=2269=0278=c5c82b9a-1cc1-4b28-abad-88eb8c0af57d83=159736369555=BTC-USD270=3.73271=0.0000000060=20250410-22:59:42.39878458=FILLED10=034
20250410-22:59:42.511976000 : 8=FIXT.1.19=28235=X49=Coinbase56=24ab46f784d1b20db435b852086e325034=7750=TEST52=20250410-22:59:42.400014369=2262=951674d8-b877-4a40-8deb-be5318522964268=1279=0269=083=159736369655=BTC-USD270=3.79271=0.6232294660=20250410-22:59:42.39878440=237=88d7a7a3-5af4-48e6-af6f-ea4cf841b2b610=061
20250410-22:59:42.512244000 : 8=FIXT.1.19=32535=X49=Coinbase56=24ab46f784d1b20db435b852086e325034=7850=TEST52=20250410-22:59:42.400018369=2262=951674d8-b877-4a40-8deb-be5318522964268=1279=0269=2278=b9704cf1-f180-4d92-90da-6bb364d4a71583=159736369755=BTC-USD270=3.54271=0.6232294660=20250410-22:59:42.39878437=88d7a7a3-5af4-48e6-af6f-ea4cf841b2b65797=110=211
20250410-22:59:42.512646000 : 8=FIXT.1.19=28835=X49=Coinbase56=24ab46f784d1b20db435b852086e325034=7950=TEST52=20250410-22:59:42.400022369=2262=951674d8-b877-4a40-8deb-be5318522964268=1279=2269=0278=88d7a7a3-5af4-48e6-af6f-ea4cf841b2b683=159736369855=BTC-USD270=3.79271=0.0000000060=20250410-22:59:42.39878458=FILLED10=228
20250410-22:59:42.620995000 : 8=FIXT.1.19=28235=X49=Coinbase56=24ab46f784d1b20db435b852086e325034=8050=TEST52=20250410-22:59:42.513222369=2262=951674d8-b877-4a40-8deb-be5318522964268=1279=0269=183=159736369955=BTC-USD270=3.32271=0.6232294660=20250410-22:59:42.51157140=237=f8eaba3f-7524-443a-ac03-0214f3186db310=115
20250410-22:59:42.621593000 : 8=FIXT.1.19=32535=X49=Coinbase56=24ab46f784d1b20db435b852086e325034=8150=TEST52=20250410-22:59:42.513228369=2262=951674d8-b877-4a40-8deb-be5318522964268=1279=0269=2278=4d60a78e-b39b-420e-b830-bc0f3f4fdde283=159736370055=BTC-USD270=3.53271=0.6232294660=20250410-22:59:42.51157137=f8eaba3f-7524-443a-ac03-0214f3186db35797=210=190
20250410-22:59:42.621940000 : 8=FIXT.1.19=28835=X49=Coinbase56=24ab46f784d1b20db435b852086e325034=8250=TEST52=20250410-22:59:42.513233369=2262=951674d8-b877-4a40-8deb-be5318522964268=1279=2269=1278=f8eaba3f-7524-443a-ac03-0214f3186db383=159736370155=BTC-USD270=3.32271=0.0000000060=20250410-22:59:42.51157158=FILLED10=011
20250410-22:59:42.622141000 : 8=FIXT.1.19=28235=X49=Coinbase56=24ab46f784d1b20db435b852086e325034=8350=TEST52=20250410-22:59:42.513236369=2262=951674d8-b877-4a40-8deb-be5318522964268=1279=0269=183=159736370255=BTC-USD270=3.25271=0.6232294660=20250410-22:59:42.51157140=237=e24da0e3-bc27-4757-8dc6-76ae06aacc6910=227
20250410-22:59:42.622381000 : 8=FIXT.1.19=32535=X49=Coinbase56=24ab46f784d1b20db435b852086e325034=8450=TEST52=20250410-22:59:42.513240369=2262=951674d8-b877-4a40-8deb-be5318522964268=1279=0269=2278=4d60a78e-b39b-420e-b830-bc0f3f4fdde283=159736370355=BTC-USD270=3.53271=0.6232294660=20250410-22:59:42.51157137=e24da0e3-bc27-4757-8dc6-76ae06aacc695797=210=051
20250410-22:59:42.622693000 : 8=FIXT.1.19=28835=X49=Coinbase56=24ab46f784d1b20db435b852086e325034=8550=TEST52=20250410-22:59:42.513244369=2262=951674d8-b877-4a40-8deb-be5318522964268=1279=2269=1278=e24da0e3-bc27-4757-8dc6-76ae06aacc6983=159736370455=BTC-USD270=3.25271=0.0000000060=20250410-22:59:42.51157158=FILLED10=138
20250410-22:59:42.691093000 : 8=FIXT.1.19=27735=X49=Coinbase56=24ab46f784d1b20db435b852086e325034=8650=TEST52=20250410-22:59:42.583458369=2262=951674d8-b877-4a40-8deb-be5318522964268=1279=0269=083=159736370555=BTC-USD29004=2.208895536660=20250410-22:59:42.58182840=137=604546cf-fc68-4f40-8f6e-5f637a597f3910=159
20250410-22:59:42.691471000 : 8=FIXT.1.19=32535=X49=Coinbase56=24ab46f784d1b20db435b852086e325034=8750=TEST52=20250410-22:59:42.583463369=2262=951674d8-b877-4a40-8deb-be5318522964268=1279=0269=2278=b9704cf1-f180-4d92-90da-6bb364d4a71583=159736370655=BTC-USD270=3.54271=0.6239817960=20250410-22:59:42.58182837=604546cf-fc68-4f40-8f6e-5f637a597f395797=110=004
20250410-22:59:42.691779000 : 8=FIXT.1.19=26435=X49=Coinbase56=24ab46f784d1b20db435b852086e325034=8850=TEST52=20250410-22:59:42.583469369=2262=951674d8-b877-4a40-8deb-be5318522964268=1279=2269=0278=604546cf-fc68-4f40-8f6e-5f637a597f3983=159736370755=BTC-USD60=20250410-22:59:42.58182858=FILLED10=177
20250410-22:59:42.718800000 : 8=FIXT.1.19=27335=X49=Coinbase56=24ab46f784d1b20db435b852086e325034=8950=TEST52=20250410-22:59:42.611210369=2262=951674d8-b877-4a40-8deb-be5318522964268=1279=0269=183=159736370855=BTC-USD271=0.6232294660=20250410-22:59:42.61003940=137=cf72c431-587a-43b9-bb95-09a2a7fa69f710=240
20250410-22:59:42.719138000 : 8=FIXT.1.19=32535=X49=Coinbase56=24ab46f784d1b20db435b852086e325034=9050=TEST52=20250410-22:59:42.611217369=2262=951674d8-b877-4a40-8deb-be5318522964268=1279=0269=2278=4d60a78e-b39b-420e-b830-bc0f3f4fdde283=159736370955=BTC-USD270=3.53271=0.6232294660=20250410-22:59:42.61003937=cf72c431-587a-43b9-bb95-09a2a7fa69f75797=210=227
20250410-22:59:42.719415000 : 8=FIXT.1.19=27935=X49=Coinbase56=24ab46f784d1b20db435b852086e325034=9150=TEST52=20250410-22:59:42.611234369=2262=951674d8-b877-4a40-8deb-be5318522964268=1279=2269=1278=cf72c431-587a-43b9-bb95-09a2a7fa69f783=159736371055=BTC-USD271=0.0000000060=20250410-22:59:42.61003958=FILLED10=141
20250410-22:59:42.811525000 : 8=FIXT.1.19=27735=X49=Coinbase56=24ab46f784d1b20db435b852086e325034=9250=TEST52=20250410-22:59:42.697508369=2262=951674d8-b877-4a40-8deb-be5318522964268=1279=0269=083=159736371155=BTC-USD29004=2.208895536660=20250410-22:59:42.69610140=137=27bb7dfb-3ed2-41e0-b8aa-536da4ef15e210=130
20250410-22:59:42.815432000 : 8=FIXT.1.19=32535=X49=Coinbase56=24ab46f784d1b20db435b852086e325034=9350=TEST52=20250410-22:59:42.697518369=2262=951674d8-b877-4a40-8deb-be5318522964268=1279=0269=2278=b9704cf1-f180-4d92-90da-6bb364d4a71583=159736371255=BTC-USD270=3.54271=0.6239817960=20250410-22:59:42.69610137=27bb7dfb-3ed2-41e0-b8aa-536da4ef15e25797=110=236
20250410-22:59:42.816494000 : 8=FIXT.1.19=26435=X49=Coinbase56=24ab46f784d1b20db435b852086e325034=9450=TEST52=20250410-22:59:42.697522369=2262=951674d8-b877-4a40-8deb-be5318522964268=1279=2269=0278=27bb7dfb-3ed2-41e0-b8aa-536da4ef15e283=159736371355=BTC-USD60=20250410-22:59:42.69610158=FILLED10=142
20250410-22:59:42.834528000 : 8=FIXT.1.19=27335=X49=Coinbase56=24ab46f784d1b20db435b852086e325034=9550=TEST52=20250410-22:59:42.726976369=2262=951674d8-b877-4a40-8deb-be5318522964268=1279=0269=183=159736371455=BTC-USD271=0.6232294660=20250410-22:59:42.72522640=137=b914337b-5a17-4f73-b4c9-d9d3db116d2a10=248
20250410-22:59:42.834858000 : 8=FIXT.1.19=32535=X49=Coinbase56=24ab46f784d1b20db435b852086e325034=9650=TEST52=20250410-22:59:42.726984369=2262=951674d8-b877-4a40-8deb-be5318522964268=1279=0269=2278=4d60a78e-b39b-420e-b830-bc0f3f4fdde283=159736371555=BTC-USD270=3.53271=0.6232294660=20250410-22:59:42.72522637=b914337b-5a17-4f73-b4c9-d9d3db116d2a5797=210=236
20250410-22:59:42.835266000 : 8=FIXT.1.19=27935=X49=Coinbase56=24ab46f784d1b20db435b852086e325034=9750=TEST52=20250410-22:59:42.726989369=2262=951674d8-b877-4a40-8deb-be5318522964268=1279=2269=1278=b914337b-5a17-4f73-b4c9-d9d3db116d2a83=159736371655=BTC-USD271=0.0000000060=20250410-22:59:42.72522658=FILLED10=165
20250410-22:59:42.977587000 : 8=FIXT.1.19=27735=X49=Coinbase56=24ab46f784d1b20db435b852086e325034=9850=TEST52=20250410-22:59:42.869484369=2262=951674d8-b877-4a40-8deb-be5318522964268=1279=0269=083=159736371755=BTC-USD29004=2.208895536660=20250410-22:59:42.86828740=137=ec21016d-3c81-4d7b-80ef-2cfc19c4f2a910=073
20250410-22:59:42.978149000 : 8=FIXT.1.19=32535=X49=Coinbase56=24ab46f784d1b20db435b852086e325034=9950=TEST52=20250410-22:59:42.869492369=2262=951674d8-b877-4a40-8deb-be5318522964268=1279=0269=2278=b9704cf1-f180-4d92-90da-6bb364d4a71583=159736371855=BTC-USD270=3.54271=0.6239817960=20250410-22:59:42.86828737=ec21016d-3c81-4d7b-80ef-2cfc19c4f2a95797=110=177
20250410-22:59:42.978479000 : 8=FIXT.1.19=26535=X49=Coinbase56=24ab46f784d1b20db435b852086e325034=10050=TEST52=20250410-22:59:42.869496369=2262=951674d8-b877-4a40-8deb-be5318522964268=1279=2269=0278=ec21016d-3c81-4d7b-80ef-2cfc19c4f2a983=159736371955=BTC-USD60=20250410-22:59:42.86828758=FILLED10=123
20250410-22:59:43.006751000 : 8=FIXT.1.19=27435=X49=Coinbase56=24ab46f784d1b20db435b852086e325034=10150=TEST52=20250410-22:59:42.899231369=2262=951674d8-b877-4a40-8deb-be5318522964268=1279=0269=183=159736372055=BTC-USD271=0.6232294660=20250410-22:59:42.89776640=137=13c3e1cc-18ab-4e09-ba81-91ae2e95a88110=083
20250410-22:59:43.007291000 : 8=FIXT.1.19=32635=X49=Coinbase56=24ab46f784d1b20db435b852086e325034=10250=TEST52=20250410-22:59:42.899239369=2262=951674d8-b877-4a40-8deb-be5318522964268=1279=0269=2278=4d60a78e-b39b-420e-b830-bc0f3f4fdde283=159736372155=BTC-USD270=3.53271=0.6232294660=20250410-22:59:42.89776637=13c3e1cc-18ab-4e09-ba81-91ae2e95a8815797=210=080
20250410-22:59:43.007515000 : 8=FIXT.1.19=28035=X49=Coinbase56=24ab46f784d1b20db435b852086e325034=10350=TEST52=20250410-22:59:42.899243369=2262=951674d8-b877-4a40-8deb-be5318522964268=1279=2269=1278=13c3e1cc-18ab-4e09-ba81-91ae2e95a88183=159736372255=BTC-USD271=0.0000000060=20250410-22:59:42.89776658=FILLED10=246
20250410-22:59:43.148815000 : 8=FIXT.1.19=27835=X49=Coinbase56=24ab46f784d1b20db435b852086e325034=10450=TEST52=20250410-22:59:43.040598369=2262=951674d8-b877-4a40-8deb-be5318522964268=1279=0269=083=159736372355=BTC-USD29004=2.208895536660=20250410-22:59:43.03924540=137=aea15bb6-5e67-4ab9-8f28-dee5deff0c5c10=031
20250410-22:59:43.149341000 : 8=FIXT.1.19=32635=X49=Coinbase56=24ab46f784d1b20db435b852086e325034=10550=TEST52=20250410-22:59:43.040607369=2262=951674d8-b877-4a40-8deb-be5318522964268=1279=0269=2278=b9704cf1-f180-4d92-90da-6bb364d4a71583=159736372455=BTC-USD270=3.54271=0.6239817960=20250410-22:59:43.03924537=aea15bb6-5e67-4ab9-8f28-dee5deff0c5c5797=110=127
20250410-22:59:43.149649000 : 8=FIXT.1.19=26535=X49=Coinbase56=24ab46f784d1b20db435b852086e325034=10650=TEST52=20250410-22:59:43.040610369=2262=951674d8-b877-4a40-8deb-be5318522964268=1279=2269=0278=aea15bb6-5e67-4ab9-8f28-dee5deff0c5c83=159736372555=BTC-USD60=20250410-22:59:43.03924558=FILLED10=032
20250410-22:59:43.176740000 : 8=FIXT.1.19=27435=X49=Coinbase56=24ab46f784d1b20db435b852086e325034=10750=TEST52=20250410-22:59:43.068077369=2262=951674d8-b877-4a40-8deb-be5318522964268=1279=0269=183=159736372655=BTC-USD271=0.6232294660=20250410-22:59:43.06699140=137=ba67ff03-88bb-4f8d-82bc-b1b0cb5eae3310=018
20250410-22:59:43.177190000 : 8=FIXT.1.19=32635=X49=Coinbase56=24ab46f784d1b20db435b852086e325034=10850=TEST52=20250410-22:59:43.068085369=2262=951674d8-b877-4a40-8deb-be5318522964268=1279=0269=2278=4d60a78e-b39b-420e-b830-bc0f3f4fdde283=159736372755=BTC-USD270=3.53271=0.6232294660=20250410-22:59:43.06699137=ba67ff03-88bb-4f8d-82bc-b1b0cb5eae335797=210=006
20250410-22:59:43.177508000 : 8=FIXT.1.19=28035=X49=Coinbase56=24ab46f784d1b20db435b852086e325034=10950=TEST52=20250410-22:59:43.068090369=2262=951674d8-b877-4a40-8deb-be5318522964268=1279=2269=1278=ba67ff03-88bb-4f8d-82bc-b1b0cb5eae3383=159736372855=BTC-USD271=0.0000000060=20250410-22:59:43.06699158=FILLED10=173
20250410-22:59:43.897905000 : 8=FIXT.1.19=91835=W49=Coinbase56=24ab46f784d1b20db435b852086e325034=11050=TEST52=20250410-22:59:43.783087369=2262=951674d8-b877-4a40-8deb-be531852296483=1597363728893=N55=BTC-USD1682=full_trading268=10269=0278=4d60a78e-b39b-420e-b830-bc0f3f4fdde2270=3.53271=276907.84372673269=0278=9d9353ab-229f-423a-89a3-c52a46543bc9270=3.53271=18127.30103418269=0278=60ef387e-c7ef-4590-9cb0-240627cd53ff270=3.53271=0.62146893269=0278=3cdae5ae-837c-4a5b-a5ef-2ceb99c72588270=3.49271=0.62322946269=0278=dcccb470-c535-433a-9198-4e2b4c26d99d270=3.47271=0.29311495269=0278=f05d9766-970d-44ca-aa4d-e8b2720bbda8270=3.46271=0.29026870269=0278=8d3f921f-0055-4a12-b965-d37ce738bef2270=3.45271=0.62146893269=0278=2c4d7d5a-33aa-4058-b546-480b6a2168a4270=3.44271=0.29828577269=0278=314abbe7-e1d6-4461-885d-59d698b54c70270=3.44271=0.62146893269=0278=f84bd963-8e45-45f8-ab20-f3a0f0cd8523270=3.43271=0.6232294610=071
20250410-22:59:43.900308000 : 8=FIXT.1.19=14135=334=349=24ab46f784d1b20db435b852086e325052=20250410-22:59:43.89956=Coinbase45=11058=Tag appears more than once371=269372=W373=1310=008
20250410-22:59:43.900496000 : 8=FIXT.1.19=90935=W49=Coinbase56=24ab46f784d1b20db435b852086e325034=11150=TEST52=20250410-22:59:43.783320369=2262=951674d8-b877-4a40-8deb-be531852296483=1597363728893=N55=BTC-USD1682=full_trading268=10269=0278=37dbcf16-0b3d-4f67-bc90-e36268b99e0e270=3.42271=0.30270947269=0278=4c63c0b7-30e0-4ef1-931f-0090359f978e270=3.41271=0.32158962269=0278=d6b4aa4e-d588-4c96-83aa-8e8d8accb1a4270=3.41271=0.30121104269=0278=8f4ccf18-7b61-4aaf-b633-4c9fe6cb1e87270=3.41271=0.62146893269=0278=e8b3d8da-1663-413c-b7fb-6aba23b01440270=3.39271=0.31006477269=0278=f2d37f8a-7f08-4991-b48d-cd1c5cc807cd270=3.39271=0.62322946269=0278=3d07f2e2-aadc-4b37-a9d4-7ef57dbc82c9270=3.39271=0.62146893269=0278=bcbe17c3-9059-4c38-8ab8-8e78f1ef9062270=3.38271=0.32617981269=0278=8e7fb58f-b2bc-4821-bca7-d181bf3f47a5270=3.38271=0.62146893269=0278=57bb77fd-337f-49bc-a56f-a4e2dff851ee270=3.37271=0.3107167610=138
20250410-22:59:43.901349000 : 8=FIXT.1.19=14135=334=449=24ab46f784d1b20db435b852086e325052=20250410-22:59:43.90056=Coinbase45=11158=Tag appears more than once371=269372=W373=1310=249
20250410-22:59:43.901462000 : 8=FIXT.1.19=90935=W49=Coinbase56=24ab46f784d1b20db435b852086e325034=11250=TEST52=20250410-22:59:43.783570369=2262=951674d8-b877-4a40-8deb-be531852296483=1597363728893=N55=BTC-USD1682=full_trading268=10269=0278=ded4b51d-349f-4726-8379-6761a3576bb6270=3.33271=0.31560513269=0278=ff7aff09-38de-47ac-a3cb-9beacb0b9ad8270=3.33271=0.30682342269=0278=d1da558a-e9d2-4e11-b26e-1eb80a1a34c5270=3.32271=0.31700685269=0278=9ee34527-d4d8-4659-b2ea-cdff3dc4a8fa270=3.32271=0.32181951269=0278=7abf2220-0421-460f-9dbb-14c41564e41a270=3.32271=0.31308436269=0278=69634ec5-f71a-4990-b56d-13c3069a455a270=3.31271=0.32329458269=0278=2f333c17-a386-4d52-8ff1-eadcb99bc22f270=3.31271=0.31999220269=0278=f02efc37-0b1e-470b-99ef-e31012887d73270=3.30271=0.32771570269=0278=6d430950-8078-4987-8995-e581564e368d270=3.29271=0.30702763269=0278=841f895a-cd2d-4082-9a37-b50fc19e35bf270=3.28271=0.3261080110=130
20250410-22:59:43.902367000 : 8=FIXT.1.19=14135=334=549=24ab46f784d1b20db435b852086e325052=20250410-22:59:43.90156=Coinbase45=11258=Tag appears more than once371=269372=W373=1310=252
20250410-22:59:43.902492000 : 8=FIXT.1.19=90935=W49=Coinbase56=24ab46f784d1b20db435b852086e325034=11350=TEST52=20250410-22:59:43.783820369=2262=951674d8-b877-4a40-8deb-be531852296483=1597363728893=N55=BTC-USD1682=full_trading268=10269=0278=3cf93093-e42b-4c24-95ea-c367d96427fe270=3.27271=0.33588654269=0278=f29c94bc-d1c2-4145-97b0-ecb77d81a8bf270=3.27271=0.31661408269=0278=d208c4fb-56c6-4911-85c9-77b68a5ba6ab270=3.25271=0.30961623269=0278=e88796ff-68c8-4463-914b-46e09fbaf639270=3.25271=0.33589845269=0278=06f345fb-0292-45fc-8237-9ad1a84b541c270=3.24271=0.31528507269=0278=fa20c2c7-df80-4941-9a9c-a6ef2e579480270=3.23271=0.33432448269=0278=a833d230-a749-4bf4-823e-93adc40b773d270=3.23271=0.31165878269=0278=2abb6e15-b9cd-415b-8c9b-99a61c750310270=3.22271=0.32048714269=0278=ec44a6d8-ae5f-4809-89d7-0f7a3adac547270=3.21271=0.33230954269=0278=9cf61c67-c4fc-4bac-92fd-d4e2b56248aa270=3.21271=0.3358395110=100
20250410-22:59:43.903489000 : 8=FIXT.1.19=14135=334=649=24ab46f784d1b20db435b852086e325052=20250410-22:59:43.90256=Coinbase45=11358=Tag appears more than once371=269372=W373=1310=255
20250410-22:59:43.903613000 : 8=FIXT.1.19=90935=W49=Coinbase56=24ab46f784d1b20db435b852086e325034=11450=TEST52=20250410-22:59:43.784070369=2262=951674d8-b877-4a40-8deb-be531852296483=1597363728893=N55=BTC-USD1682=full_trading268=10269=0278=210b2518-bb42-461a-9c7e-b4e04c5ffcc6270=3.21271=0.32669007269=0278=2e3fa1b2-20f1-4694-9be4-322040b75152270=3.21271=0.32907979269=0278=05dd5607-92c9-4296-8cdc-27cdff004dea270=3.21271=0.32776075269=0278=87944de7-a5f1-4033-a3d8-cbc10f3a5232270=3.20271=0.32225170269=0278=30f6bb59-2469-4e6d-8fa5-13666373901f270=3.19271=0.31386496269=0278=6a5d2852-7ddc-456e-acb5-bfadcc0c1360270=3.19271=0.32157390269=0278=5d00d8a2-5aea-4836-ba19-74fe67116df8270=3.18271=0.32651049269=0278=acc71746-3591-4dde-a7e2-c2795d0ad125270=3.17271=0.31577131269=0278=13982796-c2a8-4740-95e2-5aca0fdfd8bb270=3.16271=0.33021170269=0278=9f2f0737-661e-43d7-89f9-959ed5e08306270=3.16271=0.3308207510=071
20250410-22:59:43.904707000 : 8=FIXT.1.19=14135=334=749=24ab46f784d1b20db435b852086e325052=20250410-22:59:43.90456=Coinbase45=11458=Tag appears more than once371=269372=W373=1310=003
20250410-22:59:43.904847000 : 8=FIXT.1.19=91035=W49=Coinbase56=24ab46f784d1b20db435b852086e325034=11550=TEST52=20250410-22:59:43.784320369=2262=951674d8-b877-4a40-8deb-be531852296483=1597363728893=N55=BTC-USD1682=full_trading268=10269=0278=7e0e2d14-fa77-4978-8cae-d9660fd13e6d270=3.16271=0.32014975269=0278=82826a7d-848c-4516-a7b6-5ec6881609a8270=2.00271=10.00000000269=0278=590048d5-ee44-49dc-b66d-1a692e055133270=1.94271=0.51546392269=0278=22bdda11-16cd-488b-9fa9-da098dad543e270=1.94271=0.51546392269=0278=d356ef8b-596e-47e7-bf90-cc015b85fc57270=1.93271=0.52331606269=0278=aa8d48bc-97fb-4d00-b923-66d37cc8c66a270=1.93271=0.52331606269=0278=7d51dcb4-a7f8-4cca-b2d0-e902403d1b9f270=1.93271=0.52331606269=0278=f7680950-3af2-4723-a6e4-5cbd528ca900270=1.93271=0.52331606269=0278=fdeff994-4866-47af-9dde-a25947a26606270=1.93271=0.52331606269=0278=65e7e2bb-023d-4936-bb4e-ff7625ba7264270=1.93271=0.5233160610=046
20250410-22:59:43.906785000 : 8=FIXT.1.19=14135=334=849=24ab46f784d1b20db435b852086e325052=20250410-22:59:43.90556=Coinbase45=11558=Tag appears more than once371=269372=W373=1310=006
20250410-22:59:43.907221000 : 8=FIXT.1.19=90935=W49=Coinbase56=24ab46f784d1b20db435b852086e325034=11650=TEST52=20250410-22:59:43.784570369=2262=951674d8-b877-4a40-8deb-be531852296483=1597363728893=N55=BTC-USD1682=full_trading268=10269=0278=53732639-572c-4cd5-b61e-e4f534d1d540270=1.93271=0.52331606269=0278=24da8927-1dd1-468b-9437-ff366f5bfa11270=1.93271=0.52331606269=0278=baa5862c-41e8-458c-83d3-c095bb68ed17270=1.93271=0.52331606269=0278=92a3c3e3-7afe-4d02-a0d8-96f512b63bb7270=1.93271=0.52331606269=0278=9d2a564e-f178-4966-9baf-5814a1c1686b270=1.93271=0.52331606269=0278=f9e6b978-87f6-4397-8d82-07cf698c123f270=1.93271=0.52331606269=0278=3e64b388-13d3-441d-b241-aa8dd6fe55e6270=1.93271=0.52331606269=0278=60300433-87b0-4031-bb1e-12cf9d773d3f270=1.93271=0.52331606269=0278=1bdd5f5a-1d99-4eed-af09-c187bcbbd2d8270=1.93271=0.52331606269=0278=4ed6f6b9-77fb-4255-a188-f243dd0cdb3c270=1.93271=0.5233160610=065
20250410-22:59:43.908302000 : 8=FIXT.1.19=14135=334=949=24ab46f784d1b20db435b852086e325052=20250410-22:59:43.90756=Coinbase45=11658=Tag appears more than once371=269372=W373=1310=010
20250410-22:59:43.908459000 : 8=FIXT.1.19=90935=W49=Coinbase56=24ab46f784d1b20db435b852086e325034=11750=TEST52=20250410-22:59:43.784820369=2262=951674d8-b877-4a40-8deb-be531852296483=1597363728893=N55=BTC-USD1682=full_trading268=10269=0278=9ad1fc18-5a38-4edb-ac5c-6ac826a8a846270=1.93271=0.52331606269=0278=1c218c8c-baea-4a1f-838e-4a3a94b468e1270=1.93271=0.52331606269=0278=fd70f5e2-d2c9-472a-ab40-a775afafd73d270=1.93271=0.52331606269=0278=96f5e3a5-1c2a-4db6-a3fb-fd1f13d5d559270=1.93271=0.52331606269=0278=4a015a4c-490a-4c40-974f-9dfb7feb335d270=1.93271=0.52331606269=0278=d919363e-2c54-404f-bc0b-063e2f12bec4270=1.93271=0.52331606269=0278=d4636d6c-85c6-4ac9-9afb-70ca636f4ad4270=1.93271=0.52331606269=0278=bda09690-f345-4c33-ae8b-e8c78da11b5a270=1.93271=0.52331606269=0278=1a81ae10-b700-42a0-89a3-7d7a3eea0ebb270=1.93271=0.52331606269=0278=1ace5afa-e550-4abf-a458-52e46e1b54f0270=1.93271=0.5233160610=104
20250410-22:59:43.909538000 : 8=FIXT.1.19=14235=334=1049=24ab46f784d1b20db435b852086e325052=20250410-22:59:43.90856=Coinbase45=11758=Tag appears more than once371=269372=W373=1310=053
20250410-22:59:43.909683000 : 8=FIXT.1.19=90935=W49=Coinbase56=24ab46f784d1b20db435b852086e325034=11850=TEST52=20250410-22:59:43.785070369=2262=951674d8-b877-4a40-8deb-be531852296483=1597363728893=N55=BTC-USD1682=full_trading268=10269=0278=2332d1c9-67e7-457a-abfe-f5e9a8c2ea05270=1.93271=0.52331606269=0278=6afa1f19-0ec5-49fd-8b74-06a12a6c5ca9270=1.93271=0.52331606269=0278=3fa3413d-c26c-472f-9cc5-da1c48935c63270=1.93271=0.52331606269=0278=3f9e43c4-2e62-4d51-b4cb-ad207c693331270=1.93271=0.52331606269=0278=29e8bfcf-c764-4f7e-997d-09abf72bbc00270=1.93271=0.52331606269=0278=cf3e8b26-09ae-4dfb-9b84-b12a7e199a5a270=1.93271=0.52331606269=0278=08db3e51-e927-47d3-a9dd-2f887c58dc85270=1.93271=0.52331606269=0278=353ae741-9473-4cc5-9ab7-7e5de8ae55d0270=1.93271=0.52331606269=0278=4d037208-2072-480f-98ac-7be9c24f18f4270=1.93271=0.52331606269=0278=b598f678-da6e-4c01-90ed-d702c42f8a65270=1.93271=0.5233160610=238
20250410-22:59:43.910423000 : 8=FIXT.1.19=14235=334=1149=24ab46f784d1b20db435b852086e325052=20250410-22:59:43.90956=Coinbase45=11858=Tag appears more than once371=269372=W373=1310=056
20250410-22:59:43.910518000 : 8=FIXT.1.19=90935=W49=Coinbase56=24ab46f784d1b20db435b852086e325034=11950=TEST52=20250410-22:59:43.785320369=2262=951674d8-b877-4a40-8deb-be531852296483=1597363728893=N55=BTC-USD1682=full_trading268=10269=0278=5f69b1a0-b5d1-4715-9be1-9bdf008d97d7270=1.93271=0.52331606269=0278=ef063d15-248a-4eae-97f4-278be5106d80270=1.93271=0.52331606269=0278=f8b20207-84bc-44e9-a2fe-9ad775e2ecb1270=1.93271=0.52331606269=0278=75bce2b7-bc58-4479-8bfb-144f88f2262b270=1.93271=0.52331606269=0278=1f6e2a79-8b10-4a7f-89de-0f1fa03692c7270=1.93271=0.52331606269=0278=d1b80bf5-9b17-44b4-9577-6fe71170b578270=1.93271=0.52331606269=0278=b891e26a-c20c-4fce-ba1c-487fe139a4cc270=1.93271=0.52331606269=0278=5d06d3f6-3189-4394-b3c5-6a2bda14b6d1270=1.93271=0.52331606269=0278=e5791c0f-3937-4a66-9b98-26f79a3891be270=1.93271=0.52331606269=0278=c62591c6-7dfa-46a7-8f20-6a5f22804999270=1.93271=0.5233160610=244
20250410-22:59:43.911281000 : 8=FIXT.1.19=14235=334=1249=24ab46f784d1b20db435b852086e325052=20250410-22:59:43.91056=Coinbase45=11958=Tag appears more than once371=269372=W373=1310=050
20250410-22:59:43.911384000 : 8=FIXT.1.19=90935=W49=Coinbase56=24ab46f784d1b20db435b852086e325034=12050=TEST52=20250410-22:59:43.785570369=2262=951674d8-b877-4a40-8deb-be531852296483=1597363728893=N55=BTC-USD1682=full_trading268=10269=0278=7c503558-c0b8-457b-8c46-71ece3f7fc8a270=1.93271=0.52331606269=0278=f763bb56-2f21-4a9b-bd48-f84dc1bd5ee5270=1.93271=0.52331606269=0278=42214b03-1fc2-46b3-9e83-91b23a510e5a270=1.93271=0.52331606269=0278=1c7c52ed-7d39-4326-b3b8-98f05a9b3ef0270=1.93271=0.52331606269=0278=3313309e-45e7-4e7b-8c55-4f9a8ec1b351270=1.93271=0.52331606269=0278=78801ffb-ec5a-4c74-9d08-3e86fd9db4dd270=1.93271=0.52331606269=0278=abe6eea4-1d9c-47d7-847f-2f44aa561b3f270=1.93271=0.52331606269=0278=6a6eb56d-2010-43e2-b78e-5f098081bb64270=1.93271=0.52331606269=0278=b53c01ff-f450-4b05-8ad1-e7894b45e0e0270=1.93271=0.52331606269=0278=4747863e-c0a6-4ef5-8faf-e8934bca4f8b270=1.93271=0.5233160610=118
20250410-22:59:43.912207000 : 8=FIXT.1.19=14235=334=1349=24ab46f784d1b20db435b852086e325052=20250410-22:59:43.91156=Coinbase45=12058=Tag appears more than once371=269372=W373=1310=044
20250410-22:59:43.912313000 : 8=FIXT.1.19=90935=W49=Coinbase56=24ab46f784d1b20db435b852086e325034=12150=TEST52=20250410-22:59:43.785820369=2262=951674d8-b877-4a40-8deb-be531852296483=1597363728893=N55=BTC-USD1682=full_trading268=10269=0278=81a8a629-57f4-4e3a-ac25-2e9ee1f357c2270=1.93271=0.52331606269=0278=1e239259-7be4-476a-845d-1b92fd951d8b270=1.93271=0.52331606269=0278=189eb272-48f9-4915-b7e1-a86dcc505c4a270=1.93271=0.52331606269=0278=0562b9f7-aae3-4961-bd97-f5b8cde0ec34270=1.93271=0.52331606269=0278=5103331b-7300-487b-bc2c-a6032bf4be7e270=1.93271=0.52331606269=0278=78ac85ac-2478-4991-a084-7286982b77cc270=1.93271=0.52331606269=0278=6993b26d-d6dc-4f99-8a53-9500ae5b4ff1270=1.93271=0.52331606269=0278=1c96ab9d-04a6-465a-87e5-3ed33970178f270=1.93271=0.52331606269=0278=6fc0282b-d538-4aa3-8982-bda02bb1b054270=1.93271=0.52331606269=0278=80870aa3-04a2-4d2a-8669-93215130ffee270=1.93271=0.5233160610=170
20250410-22:59:43.913183000 : 8=FIXT.1.19=14235=334=1449=24ab46f784d1b20db435b852086e325052=20250410-22:59:43.91256=Coinbase45=12158=Tag appears more than once371=269372=W373=1310=047
20250410-22:59:43.913302000 : 8=FIXT.1.19=91735=W49=Coinbase56=24ab46f784d1b20db435b852086e325034=12250=TEST52=20250410-22:59:43.786070369=2262=951674d8-b877-4a40-8deb-be531852296483=1597363728893=N55=BTC-USD1682=full_trading268=10269=0278=b274e872-6923-45fd-b48a-68e685e769cb270=1.93271=0.52331606269=0278=2d4364c0-239c-4f4b-8ce4-2acfe0bb343d270=1.12271=1.00000000269=0278=8fa16a4f-377f-4deb-9a8e-1020aed9edf4270=1.00271=1.00000000269=1278=b9704cf1-f180-4d92-90da-6bb364d4a715270=3.54271=10035.84593777269=1278=fb329ad8-66e0-4bd9-9197-8f2b7dd2e399270=3.54271=0.29133125269=1278=de4af685-4b2f-44e7-a83c-88865341bc5b270=3.55271=0.28479834269=1278=c5b88ea9-605d-4595-ac52-f7c3f08523ba270=3.55271=17039.00000000269=1278=81523bd3-8912-4789-8761-89a9ee42794b270=3.55271=0.30518966269=1278=8bdc1e62-8f2d-4e9e-9328-c4407c160644270=3.55271=0.62146893269=1278=c5002ee9-8886-452f-8096-9226c6557c3b270=3.55271=0.6214689310=193
20250410-22:59:43.914267000 : 8=FIXT.1.19=14235=334=1549=24ab46f784d1b20db435b852086e325052=20250410-22:59:43.91356=Coinbase45=12258=Tag appears more than once371=269372=W373=1310=050
20250410-22:59:44.125348000 : 8=FIXT.1.19=92935=W49=Coinbase56=24ab46f784d1b20db435b852086e325034=12350=TEST52=20250410-22:59:43.786320369=2262=951674d8-b877-4a40-8deb-be531852296483=1597363728893=N55=BTC-USD1682=full_trading268=10269=1278=60fc75ca-0052-40b7-9f18-a6aad9d31b84270=3.56271=18037.00000000269=1278=cc20d23f-fccb-4dcd-bccd-19d2252f2deb270=3.56271=0.62146893269=1278=ad00e2cd-d925-46a4-9e7e-941c6faed2c7270=3.57271=18027.00000000269=1278=fec191b5-64da-4a15-ab4b-36a0d3d10750270=3.57271=0.29025301269=1278=da6ba14c-6293-4b6f-b30a-38fbd8b635e1270=3.57271=0.62322946269=1278=02a780aa-8154-4638-a5ca-53b8198cc724270=3.58271=16937.00000000269=1278=911349fb-1960-4904-9a38-0e2497fb7ccb270=3.58271=0.29896312269=1278=d91e89d4-ac5c-4853-9879-ec8ff5e00a71270=3.59271=17163.00000000269=1278=341d0ad8-6c15-4b5e-aebb-e3caa5af575c270=3.60271=17926.00000000269=1278=77e4de29-012c-4605-ad0d-f027c4fea30c270=3.60271=0.6232294610=200
20250410-22:59:44.126320000 : 8=FIXT.1.19=14235=334=1649=24ab46f784d1b20db435b852086e325052=20250410-22:59:44.12556=Coinbase45=12358=Tag appears more than once371=269372=W373=1310=048
20250410-22:59:44.126428000 : 8=FIXT.1.19=92135=W49=Coinbase56=24ab46f784d1b20db435b852086e325034=12450=TEST52=20250410-22:59:43.786571369=2262=951674d8-b877-4a40-8deb-be531852296483=1597363728893=N55=BTC-USD1682=full_trading268=10269=1278=9d239e03-1215-4cc7-ad44-3f4097ee70ea270=3.61271=18058.08928020269=1278=dbb0f332-4189-4df5-879b-e55860b13def270=3.62271=0.28062774269=1278=f7639c39-7e8b-44d1-a2f2-9807e2a3228c270=3.62271=0.27709851269=1278=83be9389-2099-4173-a322-b0933bc99358270=3.62271=19973.00000000269=1278=b89abc22-6b6c-4474-b3fc-ffe21f05cd4e270=3.63271=20016.00000000269=1278=5c005db7-f01a-4933-851c-c5f397a40fe6270=3.63271=0.62322946269=1278=ce0af8a3-149c-4603-905a-be65625fe014270=3.64271=0.27806002269=1278=0c3722d1-b86a-4607-93c0-7ae4fa61f126270=3.68271=0.62146893269=1278=0a8e230a-8b44-4212-b9fa-35bf70fb7fb2270=3.68271=0.62146893269=1278=cae3885d-f5b2-4de1-830c-0085e27bbb69270=3.69271=0.2772267810=208
20250410-22:59:44.127104000 : 8=FIXT.1.19=14235=334=1749=24ab46f784d1b20db435b852086e325052=20250410-22:59:44.12656=Coinbase45=12458=Tag appears more than once371=269372=W373=1310=051
20250410-22:59:44.127195000 : 8=FIXT.1.19=90935=W49=Coinbase56=24ab46f784d1b20db435b852086e325034=12550=TEST52=20250410-22:59:43.786821369=2262=951674d8-b877-4a40-8deb-be531852296483=1597363728893=N55=BTC-USD1682=full_trading268=10269=1278=ee4f8d87-1ffd-4b7a-a9f9-7852c462d1ab270=3.70271=0.62322946269=1278=b9732128-11b1-44fd-bea3-94da9fc853fb270=3.71271=0.28488329269=1278=818b83a4-e14e-4ad5-b094-6733f0504003270=3.75271=0.27930225269=1278=3e6990a0-8ef4-4968-8ee8-89b7346c197d270=3.76271=0.28131365269=1278=342794c8-a9d2-4aa5-9886-a819398d69c6270=3.88271=0.27719712269=1278=2839680b-48b3-4f53-86b1-9269987275e7270=3.91271=0.26621275269=1278=fd7b5361-29f8-4b35-bae5-232a64f657b4270=3.95271=0.26131406269=1278=5edaeed0-fae9-4f36-8c77-6fbedf61eefc270=4.02271=0.25091227269=1278=fdbbfd04-ba67-4b23-bbc1-f87f929e7e81270=4.07271=0.24812642269=1278=534b2a85-0852-420d-928b-70cdb6ba2457270=4.10271=0.2696196810=073
20250410-22:59:44.127699000 : 8=FIXT.1.19=14235=334=1849=24ab46f784d1b20db435b852086e325052=20250410-22:59:44.12756=Coinbase45=12558=Tag appears more than once371=269372=W373=1310=054
20250410-22:59:44.127839000 : 8=FIXT.1.19=92735=W49=Coinbase56=24ab46f784d1b20db435b852086e325034=12650=TEST52=20250410-22:59:43.787079369=2262=951674d8-b877-4a40-8deb-be531852296483=1597363728893=N55=BTC-USD1682=full_trading268=10269=1278=b009f8a1-4a39-493b-b96e-d783e981c915270=4.26271=0.25019574269=1278=729a899c-ac2d-4541-b0a2-cbdd5df9bf98270=10.00271=10.00000000269=1278=eb1e5d45-d081-4ef8-a83e-1f5348fbda96270=10.00271=10.00000000269=1278=0cd67977-85eb-45fa-ae72-d45b92ca24f4270=10.00271=10.00000000269=1278=5d931559-6758-4b75-9d6d-6438d25b497f270=10.00271=10.00000000269=1278=57e43d1d-644a-493e-acd3-69dc5e64dcde270=10.00271=10.00000000269=1278=c1566121-2b63-494d-ac2d-973e9f0115c0270=10.00271=10.00000000269=1278=d0c4a771-9035-4db9-ae7b-ad2d1db5646d270=10.00271=10.00000000269=1278=52c644ea-628a-4576-8e7e-27ec4c90398b270=10.00271=10.00000000269=1278=c3483f66-d8ce-489a-90b9-2bce69e054ee270=10.00271=10.0000000010=051
20250410-22:59:44.128561000 : 8=FIXT.1.19=14235=334=1949=24ab46f784d1b20db435b852086e325052=20250410-22:59:44.12856=Coinbase45=12658=Tag appears more than once371=269372=W373=1310=057
20250410-22:59:44.128655000 : 8=FIXT.1.19=93335=W49=Coinbase56=24ab46f784d1b20db435b852086e325034=12750=TEST52=20250410-22:59:43.787328369=2262=951674d8-b877-4a40-8deb-be531852296483=1597363728893=N55=BTC-USD1682=full_trading268=10269=1278=55992a5c-cbcd-464a-8f8d-8b58e81e5c0b270=10.00271=10.00000000269=1278=19077009-6f26-4e2d-9dab-04a28231b752270=10.00271=10.00000000269=1278=692097d1-c978-4024-95e9-2bf348b64bbd270=10.00271=10.00000000269=1278=99a92935-11b7-4f21-a64c-c746b53d1777270=10.00271=10.00000000269=1278=dc024b0b-0337-4215-9669-5e5636834397270=10.00271=10.00000000269=1278=c90fcc3a-a36c-4c14-b57f-6db78762e017270=10.00271=10.00000000269=1278=7841891a-bb7c-4034-97c1-41164185edc7270=1000.00271=3.10000000269=1278=381c9fa7-1add-4dd2-9233-f41e2c8821fe270=1000.00271=3.10000000269=1278=928e65c2-7e2d-478b-9310-414fb77f5aae270=1000.00271=3.10000000269=1278=ad4bd3ac-9276-40d5-90f9-e47b1d8ee953270=1000.00271=3.1000000010=159
20250410-22:59:44.129223000 : 8=FIXT.1.19=14235=334=2049=24ab46f784d1b20db435b852086e325052=20250410-22:59:44.12856=Coinbase45=12758=Tag appears more than once371=269372=W373=1310=050
20250410-22:59:44.129292000 : 8=FIXT.1.19=93935=W49=Coinbase56=24ab46f784d1b20db435b852086e325034=12850=TEST52=20250410-22:59:43.787578369=2262=951674d8-b877-4a40-8deb-be531852296483=1597363728893=N55=BTC-USD1682=full_trading268=10269=1278=79e799dc-4a3d-4922-ad1a-f74eb7eff789270=1000.00271=3.10000000269=1278=04f642b7-750f-4967-b786-0d48eea0f158270=1000.00271=3.10000000269=1278=d0ad653d-3272-4a3b-ba7a-a52029a67a92270=1000.00271=3.10000000269=1278=cad40464-4c62-4bf3-8444-c487fcc8dd01270=1000.00271=3.10000000269=1278=426c6428-d481-4ff7-9de3-f00ff219d654270=1000.00271=3.10000000269=1278=1ed1152d-8c1a-4b29-acdd-bbd1a5c5f35f270=1000.00271=3.10000000269=1278=66526051-b5cb-442f-af90-c609be0a9796270=1000.00271=3.10000000269=1278=f68e4659-5785-4ee9-ac24-3186640a2752270=1000.00271=3.10000000269=1278=38070d38-80a9-4898-8ef7-a0a9da5a4123270=1000.00271=3.10000000269=1278=e4d2d308-ed11-49db-850e-3cbd8258395d270=1000.00271=3.1000000010=177
20250410-22:59:44.130021000 : 8=FIXT.1.19=14235=334=2149=24ab46f784d1b20db435b852086e325052=20250410-22:59:44.12956=Coinbase45=12858=Tag appears more than once371=269372=W373=1310=053
20250410-22:59:44.130107000 : 8=FIXT.1.19=93935=W49=Coinbase56=24ab46f784d1b20db435b852086e325034=12950=TEST52=20250410-22:59:43.787828369=2262=951674d8-b877-4a40-8deb-be531852296483=1597363728893=N55=BTC-USD1682=full_trading268=10269=1278=d6cfaadc-97ea-43c1-898d-40faea9c1477270=1000.00271=3.10000000269=1278=36876bea-9e3a-4018-b0ac-b75cb8c16953270=1000.00271=3.10000000269=1278=eb244bc5-49e8-4aa3-af8b-3d1a67c90a08270=1000.00271=3.10000000269=1278=3efba776-29ad-4aeb-82d8-0824f161471e270=1000.00271=3.10000000269=1278=de0ddebd-0ca8-4eca-9985-77c10c8629a9270=1000.00271=3.10000000269=1278=dde4408a-fb6b-441c-a7f3-7b8b23ffdb1f270=1000.00271=3.10000000269=1278=3ebd6434-070f-4b4d-8cf3-00368112466d270=1000.00271=3.10000000269=1278=7aa98e13-65f3-4058-9f91-c1f452d02710270=1000.00271=3.10000000269=1278=e86a1fec-3610-460d-8d85-4e1e222ee159270=1000.00271=3.10000000269=1278=6dfac057-72b1-4f2c-b110-03766dea0d31270=1000.00271=3.1000000010=000
20250410-22:59:44.130880000 : 8=FIXT.1.19=14235=334=2249=24ab46f784d1b20db435b852086e325052=20250410-22:59:44.13056=Coinbase45=12958=Tag appears more than once371=269372=W373=1310=047
20250410-22:59:44.130997000 : 8=FIXT.1.19=93935=W49=Coinbase56=24ab46f784d1b20db435b852086e325034=13050=TEST52=20250410-22:59:43.788078369=2262=951674d8-b877-4a40-8deb-be531852296483=1597363728893=N55=BTC-USD1682=full_trading268=10269=1278=bbb7d0ea-d251-4612-b53e-e528cc0a24ab270=1000.00271=3.10000000269=1278=0782ca37-48cf-4ff3-a74a-35674661586c270=1000.00271=3.10000000269=1278=aead437d-4b62-457f-ac83-62c7cc329fd1270=1000.00271=3.10000000269=1278=af5d47bc-a008-4567-b24f-b0298f250471270=1000.00271=3.10000000269=1278=4c260f58-c427-4a9a-969a-44024ae0c714270=1000.00271=3.10000000269=1278=8c7672e5-7ee8-4fbd-8fdf-7e74e9a77db7270=1000.00271=3.10000000269=1278=b53ec3cc-9abe-4570-b903-34d52148073e270=1000.00271=3.10000000269=1278=37ce984a-0387-4ac9-9094-b83f722036ba270=1000.00271=3.10000000269=1278=0d383649-dc6c-4df2-b821-aa0018f132c7270=1000.00271=3.10000000269=1278=e39ae0ce-9e7f-4f0d-a765-5308d473bb61270=1000.00271=3.1000000010=056
20250410-22:59:44.132138000 : 8=FIXT.1.19=14235=334=2349=24ab46f784d1b20db435b852086e325052=20250410-22:59:44.13156=Coinbase45=13058=Tag appears more than once371=269372=W373=1310=041
20250410-22:59:44.132273000 : 8=FIXT.1.19=93935=W49=Coinbase56=24ab46f784d1b20db435b852086e325034=13150=TEST52=20250410-22:59:43.788329369=2262=951674d8-b877-4a40-8deb-be531852296483=1597363728893=N55=BTC-USD1682=full_trading268=10269=1278=4882324e-3b5c-4b7a-b096-e8c6d9888671270=1000.00271=3.10000000269=1278=6e5c7dbd-a2cc-401f-a5b2-3902088f4ab2270=1000.00271=3.10000000269=1278=10ffac08-946a-4a30-b57a-0d78450345d9270=1000.00271=3.10000000269=1278=67784af5-72bf-4d16-a6b3-25336e2c1843270=1000.00271=3.10000000269=1278=4d8b3bbc-0dc2-4044-875c-c079ec538136270=1000.00271=3.10000000269=1278=dfba5f1e-21f5-48e3-adce-b8b6bfe71467270=1000.00271=3.10000000269=1278=e51b4e33-5eaa-46ef-936b-a74a890397e8270=1000.00271=3.10000000269=1278=8cf5dfa8-858b-48a3-9d94-78522c257473270=1000.00271=3.10000000269=1278=a153b9d2-993d-4f03-a974-b8a081e128e8270=1000.00271=3.10000000269=1278=1eebe866-0f6e-4d4a-a28b-78f4e3368b0a270=1000.00271=3.1000000010=054
20250410-22:59:44.133191000 : 8=FIXT.1.19=14235=334=2449=24ab46f784d1b20db435b852086e325052=20250410-22:59:44.13256=Coinbase45=13158=Tag appears more than once371=269372=W373=1310=044
20250410-22:59:44.133320000 : 8=FIXT.1.19=93935=W49=Coinbase56=24ab46f784d1b20db435b852086e325034=13250=TEST52=20250410-22:59:43.788578369=2262=951674d8-b877-4a40-8deb-be531852296483=1597363728893=N55=BTC-USD1682=full_trading268=10269=1278=300132d8-113f-4bf7-ba0c-4d93a272f55b270=1000.00271=3.10000000269=1278=757f3122-27d2-4f32-90b8-ead1eef9b936270=1000.00271=3.10000000269=1278=2b68b5de-4153-4cac-ace3-102e4fa788fd270=1000.00271=3.10000000269=1278=b01f252a-1657-4df0-a122-58a23109a7c2270=1000.00271=3.10000000269=1278=dbc57e4e-6abd-4d66-8d18-bd13caaa77b1270=1000.00271=3.10000000269=1278=948b05dc-a481-409f-b8ad-a502eb595906270=1000.00271=3.10000000269=1278=e00f9703-6e16-4237-a2c6-701829d11bf1270=1000.00271=3.10000000269=1278=fd52f47a-3f11-47bc-9952-9708617d0ecd270=1000.00271=3.10000000269=1278=f7f75b14-27c3-469c-89fb-6a98b43c61bf270=1000.00271=3.10000000269=1278=25dbeb09-7901-4280-b0c3-720d7ed03d7d270=1000.00271=3.1000000010=006
20250410-22:59:44.134220000 : 8=FIXT.1.19=14235=334=2549=24ab46f784d1b20db435b852086e325052=20250410-22:59:44.13356=Coinbase45=13258=Tag appears more than once371=269372=W373=1310=047
20250410-22:59:44.134321000 : 8=FIXT.1.19=93935=W49=Coinbase56=24ab46f784d1b20db435b852086e325034=13350=TEST52=20250410-22:59:43.788829369=2262=951674d8-b877-4a40-8deb-be531852296483=1597363728893=N55=BTC-USD1682=full_trading268=10269=1278=52164a1f-599f-4c43-a9ed-f93403506e67270=1000.00271=3.10000000269=1278=c71c35ea-f60f-4a41-b43a-4947bbcbafad270=1000.00271=3.10000000269=1278=2de342bc-a1be-46f3-9fc6-731297726934270=1000.00271=3.10000000269=1278=7ff4c5fc-bc9b-4845-940b-4837a672e13a270=1000.00271=3.10000000269=1278=2d270775-33eb-4328-8dad-7d206612f9f6270=1000.00271=3.10000000269=1278=c4754378-f787-4100-81af-564443a86a91270=1000.00271=3.10000000269=1278=59e16255-05eb-4fdc-8be1-3c4f83fc094e270=1000.00271=3.10000000269=1278=041b2f98-1185-49cb-964a-f0456b71e692270=1000.00271=3.10000000269=1278=9a2f3529-481e-4e50-a123-7a2095fe6b2c270=1000.00271=3.10000000269=1278=9ed552a3-3295-4878-85dd-87b7b5590212270=1000.00271=3.1000000010=166
20250410-22:59:44.135311000 : 8=FIXT.1.19=14235=334=2649=24ab46f784d1b20db435b852086e325052=20250410-22:59:44.13456=Coinbase45=13358=Tag appears more than once371=269372=W373=1310=050
20250410-22:59:44.135442000 : 8=FIXT.1.19=93935=W49=Coinbase56=24ab46f784d1b20db435b852086e325034=13450=TEST52=20250410-22:59:43.789079369=2262=951674d8-b877-4a40-8deb-be531852296483=1597363728893=N55=BTC-USD1682=full_trading268=10269=1278=54bec5c2-bafd-4d7d-851d-59e3553a053f270=1000.00271=3.10000000269=1278=543c1acf-52f2-442b-a893-f7aa9a5dfbd1270=1000.00271=3.10000000269=1278=fec999be-cbd0-42ef-b9c3-82ca92ef0b58270=1000.00271=3.10000000269=1278=24528176-3fc6-45b2-b2f3-9f784c01495a270=1000.00271=3.10000000269=1278=12081678-66a6-4435-a3d7-b65f959cf2ac270=1000.00271=3.10000000269=1278=e7fb6165-8f1a-4b5e-b095-e232b83ee951270=1000.00271=3.10000000269=1278=83ce6582-410a-40bf-9831-8f3d20e3a629270=1000.00271=3.10000000269=1278=bc3a930b-0567-46ba-86a4-712f76466b0b270=1000.00271=3.10000000269=1278=15704973-f5ff-457d-ab31-8f99bb76bf7e270=1000.00271=3.10000000269=1278=7159045b-cbd5-458f-b91f-9fa5241b14b5270=1000.00271=3.1000000010=146
20250410-22:59:44.136467000 : 8=FIXT.1.19=14235=334=2749=24ab46f784d1b20db435b852086e325052=20250410-22:59:44.13556=Coinbase45=13458=Tag appears more than once371=269372=W373=1310=053
20250410-22:59:44.136585000 : 8=FIXT.1.19=93935=W49=Coinbase56=24ab46f784d1b20db435b852086e325034=13550=TEST52=20250410-22:59:43.789329369=2262=951674d8-b877-4a40-8deb-be531852296483=1597363728893=N55=BTC-USD1682=full_trading268=10269=1278=9fa52a90-f03f-4940-b5ee-39ab937b86f1270=1000.00271=3.10000000269=1278=220f55cd-a279-4bf0-9c80-1dca086d85dc270=1000.00271=3.10000000269=1278=2b1eb468-6bcd-4117-a7c0-214d643ddad4270=1000.00271=3.10000000269=1278=cc23185d-e72e-42cb-8210-61bab29cd778270=1000.00271=3.10000000269=1278=69bb228b-973b-4176-8708-3231cc40102a270=1000.00271=3.10000000269=1278=2ec8035d-7962-4195-8388-c9fbad52ac8a270=1000.00271=3.10000000269=1278=7d39e416-0b7b-471f-a9ac-455ab1bce5a7270=1000.00271=3.10000000269=1278=7067378d-2a65-41f2-acb0-ef30ddbc3e5a270=1000.00271=3.10000000269=1278=bf3fde78-6cff-4477-b381-4b5d2e68f36f270=1000.00271=3.10000000269=1278=93a2a8a3-61d4-410c-9446-8eabaafc5f29270=1000.00271=3.1000000010=114
20250410-22:59:44.137621000 : 8=FIXT.1.19=14235=334=2849=24ab46f784d1b20db435b852086e325052=20250410-22:59:44.13756=Coinbase45=13558=Tag appears more than once371=269372=W373=1310=057
20250410-22:59:44.137812000 : 8=FIXT.1.19=93935=W49=Coinbase56=24ab46f784d1b20db435b852086e325034=13650=TEST52=20250410-22:59:43.789579369=2262=951674d8-b877-4a40-8deb-be531852296483=1597363728893=N55=BTC-USD1682=full_trading268=10269=1278=5afddb61-63ab-417b-a28a-41c4c03a6612270=1000.00271=3.10000000269=1278=a4280417-189c-4f76-9d2e-6ec652010bf5270=1000.00271=3.10000000269=1278=ddeb78a2-e110-4828-ba3d-c9b4837e7dd7270=1000.00271=3.10000000269=1278=fcec6c90-441a-4f4a-a94e-9003355657ef270=1000.00271=3.10000000269=1278=6db15389-dfb3-4156-8a4e-ce2ac80f2b15270=1000.00271=3.10000000269=1278=47dfefc3-6f05-4b57-8aec-2bf3e6c70c2d270=1000.00271=3.10000000269=1278=fb9fd019-4b4f-4880-82bb-3df6d1ef468a270=1000.00271=3.10000000269=1278=2cff9acd-42cb-43a5-8d50-51e676b7e763270=1000.00271=3.10000000269=1278=6e6eeb59-4728-4811-9a44-c857df6aca42270=1000.00271=3.10000000269=1278=81798560-263f-4819-a528-5f3fbbc7b042270=1000.00271=3.1000000010=168
20250410-22:59:44.138824000 : 8=FIXT.1.19=14235=334=2949=24ab46f784d1b20db435b852086e325052=20250410-22:59:44.13856=Coinbase45=13658=Tag appears more than once371=269372=W373=1310=060
20250410-22:59:44.138955000 : 8=FIXT.1.19=93935=W49=Coinbase56=24ab46f784d1b20db435b852086e325034=13750=TEST52=20250410-22:59:43.789829369=2262=951674d8-b877-4a40-8deb-be531852296483=1597363728893=N55=BTC-USD1682=full_trading268=10269=1278=81fbf9a8-82f4-4fe4-9fa5-3773b212ebf4270=1000.00271=3.10000000269=1278=5d3b9566-276d-47fe-a111-12c17f53f501270=1000.00271=3.10000000269=1278=8eb1b3b3-c813-48b1-b839-993672108d91270=1000.00271=3.10000000269=1278=4feb6e93-6149-481b-8d58-e1c8e6c5cda1270=1000.00271=3.10000000269=1278=f8611e72-4056-4b7c-9779-4d54cd151d44270=1000.00271=3.10000000269=1278=7a129f7c-d9ba-4ea3-a267-b7d82b2e07d9270=1000.00271=3.10000000269=1278=01f359f0-c38f-416b-af00-183907218793270=1000.00271=3.10000000269=1278=11741cec-9c08-4a20-99dc-6b9f63130b0e270=1000.00271=3.10000000269=1278=08db2574-ad52-4520-ab5b-c3c7591eb781270=1000.00271=3.10000000269=1278=b06f2249-179c-4a15-8e98-7b76083b808b270=1000.00271=3.1000000010=200
20250410-22:59:44.139847000 : 8=FIXT.1.19=14235=334=3049=24ab46f784d1b20db435b852086e325052=20250410-22:59:44.13956=Coinbase45=13758=Tag appears more than once371=269372=W373=1310=054
20250410-22:59:44.139961000 : 8=FIXT.1.19=93935=W49=Coinbase56=24ab46f784d1b20db435b852086e325034=13850=TEST52=20250410-22:59:43.790079369=2262=951674d8-b877-4a40-8deb-be531852296483=1597363728893=N55=BTC-USD1682=full_trading268=10269=1278=9e88fede-6d19-4c1f-863b-5a7d66781436270=1000.00271=3.10000000269=1278=75e1d8b4-7201-41fe-a687-7d93420af323270=1000.00271=3.10000000269=1278=d00aa7dd-ce7f-4f8b-9a2e-880c1ea30845270=1000.00271=3.10000000269=1278=584a483f-23bf-4d8b-809f-69cf3c110f60270=1000.00271=3.10000000269=1278=dc98524e-27e2-4863-99e4-7a0097a6ee90270=1000.00271=3.10000000269=1278=82a11ac9-4f46-44b7-a0bc-a5a4cfe686e0270=1000.00271=3.10000000269=1278=f946bb05-900c-41fc-9908-41489e97ff20270=1000.00271=3.10000000269=1278=1f9186d6-0312-4677-ba96-fdb014cdff2c270=1000.00271=3.10000000269=1278=c3b67be7-2b63-4884-b311-80f28496c2c4270=1000.00271=3.10000000269=1278=6576c7f8-a4e2-4417-b854-5fef0e705fbe270=1000.00271=3.1000000010=153
20250410-22:59:44.140664000 : 8=FIXT.1.19=14235=334=3149=24ab46f784d1b20db435b852086e325052=20250410-22:59:44.14056=Coinbase45=13858=Tag appears more than once371=269372=W373=1310=048
20250410-22:59:44.140756000 : 8=FIXT.1.19=93935=W49=Coinbase56=24ab46f784d1b20db435b852086e325034=13950=TEST52=20250410-22:59:43.790329369=2262=951674d8-b877-4a40-8deb-be531852296483=1597363728893=N55=BTC-USD1682=full_trading268=10269=1278=c2102c71-62f0-4eee-ae60-0777ed26a8e6270=1000.00271=3.10000000269=1278=c823a2b6-849e-4839-a2fd-cd9f459cae6c270=1000.00271=3.10000000269=1278=a051e195-4472-4a8a-8591-08a2c04a33c4270=1000.00271=3.10000000269=1278=ec81b8c4-b703-4afd-a701-ce34011f60f6270=1000.00271=3.10000000269=1278=b1172677-f493-4f32-a200-0710cf8c397f270=1000.00271=3.10000000269=1278=b1a58a75-5fca-43db-b9c6-a26920e8f66e270=1000.00271=3.10000000269=1278=038bea41-b91d-4884-b992-3e5431ef9857270=1000.00271=3.10000000269=1278=55063782-f2ea-4c84-9491-8e8e89d1dfd1270=1000.00271=3.10000000269=1278=bb2011e8-d05d-40ac-9e9c-3b720422e38d270=1000.00271=3.10000000269=1278=64dd3b4a-ce8a-4b63-9937-266e832c0f21270=1000.00271=3.1000000010=068
20250410-22:59:44.141524000 : 8=FIXT.1.19=14235=334=3249=24ab46f784d1b20db435b852086e325052=20250410-22:59:44.14156=Coinbase45=13958=Tag appears more than once371=269372=W373=1310=051
20250410-22:59:44.141690000 : 8=FIXT.1.19=93935=W49=Coinbase56=24ab46f784d1b20db435b852086e325034=14050=TEST52=20250410-22:59:43.790579369=2262=951674d8-b877-4a40-8deb-be531852296483=1597363728893=N55=BTC-USD1682=full_trading268=10269=1278=d64f7d2a-aa83-486c-92a8-3314c4eddd58270=1000.00271=3.10000000269=1278=0df9641b-d89d-4222-a8ea-bcddf0d555f5270=1000.00271=3.10000000269=1278=7a315b16-a05f-408d-b8c1-2704af9bf767270=1000.00271=3.10000000269=1278=0e9712a8-d00f-4864-a478-f7f591718f91270=1000.00271=3.10000000269=1278=94db025d-eada-49e3-b13c-b667ca07f829270=1000.00271=3.10000000269=1278=a88ccd1f-8f8d-46af-8fb6-20adba35f7d1270=1000.00271=3.10000000269=1278=99d4e235-c8ec-4efc-938c-9a1923eafc96270=1000.00271=3.10000000269=1278=a4fc7173-7583-4f8b-b256-2921bef83c84270=1000.00271=3.10000000269=1278=18f8afd4-8bbc-4ffa-8e8f-0c1834d74472270=1000.00271=3.10000000269=1278=21fc8cb6-f894-4d09-884e-810b8ebf2ef3270=1000.00271=3.1000000010=006
20250410-22:59:44.142586000 : 8=FIXT.1.19=14235=334=3349=24ab46f784d1b20db435b852086e325052=20250410-22:59:44.14156=Coinbase45=14058=Tag appears more than once371=269372=W373=1310=044
20250410-22:59:44.142738000 : 8=FIXT.1.19=93935=W49=Coinbase56=24ab46f784d1b20db435b852086e325034=14150=TEST52=20250410-22:59:43.790829369=2262=951674d8-b877-4a40-8deb-be531852296483=1597363728893=N55=BTC-USD1682=full_trading268=10269=1278=0c13b9e6-6797-4b3e-90ce-a1885b26ba53270=1000.00271=3.10000000269=1278=6d8da581-3998-4fc0-99b6-3c5edbd514cb270=1000.00271=3.10000000269=1278=67a70307-be50-4065-872b-47e0de473bc4270=1000.00271=3.10000000269=1278=8ce7be0b-98de-46d0-b1b6-307a4bec36e2270=1000.00271=3.10000000269=1278=856b22f8-5884-4739-adc0-bdd851c5c07d270=1000.00271=3.10000000269=1278=c00ae651-a76b-4bfd-be16-3672b345fe29270=1000.00271=3.10000000269=1278=cae248f9-16fc-44ea-9b79-1dacfc285db6270=1000.00271=3.10000000269=1278=42bb223c-88c6-4a18-8ff3-4fd8d9efda8d270=1000.00271=3.10000000269=1278=d7188b01-22b6-4837-a720-077601f7f483270=1000.00271=3.10000000269=1278=5d85a0a6-ddd9-4e0e-9a1a-7f418ef588e5270=1000.00271=3.1000000010=182
20250410-22:59:44.143899000 : 8=FIXT.1.19=14235=334=3449=24ab46f784d1b20db435b852086e325052=20250410-22:59:44.14356=Coinbase45=14158=Tag appears more than once371=269372=W373=1310=048
20250410-22:59:44.144039000 : 8=FIXT.1.19=93935=W49=Coinbase56=24ab46f784d1b20db435b852086e325034=14250=TEST52=20250410-22:59:43.791079369=2262=951674d8-b877-4a40-8deb-be531852296483=1597363728893=N55=BTC-USD1682=full_trading268=10269=1278=bff4c39f-7a80-42ce-a178-b1221792e445270=1000.00271=3.10000000269=1278=9ea3d263-b5ab-46c5-bf27-8c0e3e0e5e9e270=1000.00271=3.10000000269=1278=b93347df-d2ab-48ec-b326-4454e64f1d4e270=1000.00271=3.10000000269=1278=57acc40d-8478-444a-990f-067a8e8e846e270=1000.00271=3.10000000269=1278=34419ae2-2c16-427b-a290-845419760fd5270=1000.00271=3.10000000269=1278=ab41de2d-5def-4986-b56e-243d2f99a57c270=1000.00271=3.10000000269=1278=9025524c-03a9-407a-a58a-5258c4ea0a0b270=1000.00271=3.10000000269=1278=60766318-112b-4d83-a384-55693de75519270=1000.00271=3.10000000269=1278=c19b6a2c-086b-4fc1-8dfe-51cb2dc12c1d270=1000.00271=3.10000000269=1278=11126433-0f9c-4450-a35a-39b878e85e68270=1000.00271=3.1000000010=191
20250410-22:59:44.144874000 : 8=FIXT.1.19=14235=334=3549=24ab46f784d1b20db435b852086e325052=20250410-22:59:44.14456=Coinbase45=14258=Tag appears more than once371=269372=W373=1310=051
20250410-22:59:44.145037000 : 8=FIXT.1.19=93935=W49=Coinbase56=24ab46f784d1b20db435b852086e325034=14350=TEST52=20250410-22:59:43.791329369=2262=951674d8-b877-4a40-8deb-be531852296483=1597363728893=N55=BTC-USD1682=full_trading268=10269=1278=e2e620ee-44fb-4630-a890-d331ba5b2fae270=1000.00271=3.10000000269=1278=9ccf6d4b-a6ca-4a1f-a7bb-77f400ace0c8270=1000.00271=3.10000000269=1278=0e8d6c10-8421-4f19-97dc-d70e715d9033270=1000.00271=3.10000000269=1278=f31ecd5d-8231-44ea-a5c2-0fcc5a699401270=1000.00271=3.10000000269=1278=37fbb559-dc52-48fe-ab65-24910edc338a270=1000.00271=3.10000000269=1278=bc1435c5-c59c-4017-9e59-f1073f04c7e2270=1000.00271=3.10000000269=1278=9c8e1397-0cee-4b05-a66f-5594040791c4270=1000.00271=3.10000000269=1278=248b6703-f829-42bb-a551-4be3075c381e270=1000.00271=3.10000000269=1278=16d257b0-bc92-44f0-822d-3eba61af4bda270=1000.00271=3.10000000269=1278=06257aa1-4043-4cdb-9286-4342b8e59108270=1000.00271=3.1000000010=243
20250410-22:59:44.146156000 : 8=FIXT.1.19=14235=334=3649=24ab46f784d1b20db435b852086e325052=20250410-22:59:44.14556=Coinbase45=14358=Tag appears more than once371=269372=W373=1310=054
20250410-22:59:44.146426000 : 8=FIXT.1.19=93935=W49=Coinbase56=24ab46f784d1b20db435b852086e325034=14450=TEST52=20250410-22:59:43.791579369=2262=951674d8-b877-4a40-8deb-be531852296483=1597363728893=N55=BTC-USD1682=full_trading268=10269=1278=210ec210-1443-47dc-9e43-9c9ea720a6c3270=1000.00271=3.10000000269=1278=8b79da5d-b78c-4011-b55f-b35c16dc3724270=1000.00271=3.10000000269=1278=076c3703-1104-4e15-a38a-d95bf133f0c5270=1000.00271=3.10000000269=1278=f5a3155c-e449-4102-870d-ab8c8dd24c3d270=1000.00271=3.10000000269=1278=1af2681f-2dec-4d25-aaeb-89b8867b4a3c270=1000.00271=3.10000000269=1278=65c3088d-192a-4213-85a3-7257aa8b20a3270=1000.00271=3.10000000269=1278=2aa7989b-5601-4899-8143-01dda3255e4f270=1000.00271=3.10000000269=1278=099b432c-fa2e-4fd7-952e-22f6debf6877270=1000.00271=3.10000000269=1278=2e71cc31-1235-4b7b-a728-e3335631fe5a270=1000.00271=3.10000000269=1278=ce471ffc-1e26-4afe-afab-27ee5ac8debe270=1000.00271=3.1000000010=102
20250410-22:59:44.147472000 : 8=FIXT.1.19=14235=334=3749=24ab46f784d1b20db435b852086e325052=20250410-22:59:44.14656=Coinbase45=14458=Tag appears more than once371=269372=W373=1310=057
20250410-22:59:44.147589000 : 8=FIXT.1.19=93935=W49=Coinbase56=24ab46f784d1b20db435b852086e325034=14550=TEST52=20250410-22:59:43.791829369=2262=951674d8-b877-4a40-8deb-be531852296483=1597363728893=N55=BTC-USD1682=full_trading268=10269=1278=113b7fc6-8574-40eb-8682-d077245b84f2270=1000.00271=3.10000000269=1278=bcebce2c-eda8-4b85-841d-27ede39fc5a1270=1000.00271=3.10000000269=1278=0aedaae5-6cc6-4a34-8e48-5e67a5ccc148270=1000.00271=3.10000000269=1278=206e10a5-1173-4860-87b5-7c88afe061f6270=1000.00271=3.10000000269=1278=5c32d94b-696a-4d9b-afa0-665970356008270=1000.00271=3.10000000269=1278=0b7da819-cc1e-4525-a382-ce5b90dc485c270=1000.00271=3.10000000269=1278=2241b3bf-cbbe-44f2-ac75-8032f6283aa8270=1000.00271=3.10000000269=1278=88cada69-adb1-466a-afcd-66e063ad27c0270=1000.00271=3.10000000269=1278=34a52ef5-31c1-4c63-9230-21c85a9a6ba3270=1000.00271=3.10000000269=1278=e109c2c8-fb1d-4ef9-a640-368381323507270=1000.00271=3.1000000010=163
20250410-22:59:44.148545000 : 8=FIXT.1.19=14235=334=3849=24ab46f784d1b20db435b852086e325052=20250410-22:59:44.14756=Coinbase45=14558=Tag appears more than once371=269372=W373=1310=060
20250410-22:59:44.148664000 : 8=FIXT.1.19=93935=W49=Coinbase56=24ab46f784d1b20db435b852086e325034=14650=TEST52=20250410-22:59:43.792079369=2262=951674d8-b877-4a40-8deb-be531852296483=1597363728893=N55=BTC-USD1682=full_trading268=10269=1278=38fd36c4-4c62-4b4c-8f24-1fe39be94fa1270=1000.00271=3.10000000269=1278=f83f64c8-7d33-472d-a516-9b664ff9c966270=1000.00271=3.10000000269=1278=3411c368-380b-42e6-b656-8552d92904d5270=1000.00271=3.10000000269=1278=4803796e-79f3-4aa4-a8cb-37f13899bf01270=1000.00271=3.10000000269=1278=823f8fbf-7e6d-4ae3-adb9-3a822ff6d09a270=1000.00271=3.10000000269=1278=135624df-a204-490f-a68b-63d74ee09908270=1000.00271=3.10000000269=1278=47cfdedf-22b9-402c-93bd-f311103fd3e0270=1000.00271=3.10000000269=1278=f9173d5e-d872-4661-93f6-28f527e931f7270=1000.00271=3.10000000269=1278=06ab1365-fd39-4701-bd7f-1915ad3c7602270=1000.00271=3.10000000269=1278=012a7c59-5ae4-4da5-97ba-2e3254c889fb270=1000.00271=3.1000000010=012
20250410-22:59:44.149529000 : 8=FIXT.1.19=14235=334=3949=24ab46f784d1b20db435b852086e325052=20250410-22:59:44.14956=Coinbase45=14658=Tag appears more than once371=269372=W373=1310=064
20250410-22:59:44.149670000 : 8=FIXT.1.19=93935=W49=Coinbase56=24ab46f784d1b20db435b852086e325034=14750=TEST52=20250410-22:59:43.792329369=2262=951674d8-b877-4a40-8deb-be531852296483=1597363728893=N55=BTC-USD1682=full_trading268=10269=1278=a9a0d42f-ad9e-4ea9-8bf0-d5a441fded40270=1000.00271=3.10000000269=1278=f3f3930e-be0e-40b4-a97d-d19501a54885270=1000.00271=3.10000000269=1278=261922d0-5c81-4ab6-832f-4eff45f64890270=1000.00271=3.10000000269=1278=3af4e45f-56f6-4c69-894d-d56a14894a98270=1000.00271=3.10000000269=1278=1c1dd248-49e4-44aa-9e69-323b0f41fa0e270=1000.00271=3.10000000269=1278=b16b002d-1cd6-4869-9c1b-f15c758611bf270=1000.00271=3.10000000269=1278=a0520e61-28ad-448d-87c1-49f0c7358628270=1000.00271=3.10000000269=1278=152d0b57-086f-48cc-80b3-ff14ee9375ed270=1000.00271=3.10000000269=1278=c55fc264-67d2-4e9c-8cce-6c834feff648270=1000.00271=3.10000000269=1278=27361968-189a-4fa6-a3a2-eead03c640d6270=1000.00271=3.1000000010=062
20250410-22:59:44.150419000 : 8=FIXT.1.19=14235=334=4049=24ab46f784d1b20db435b852086e325052=20250410-22:59:44.14956=Coinbase45=14758=Tag appears more than once371=269372=W373=1310=057
20250410-22:59:44.150520000 : 8=FIXT.1.19=93935=W49=Coinbase56=24ab46f784d1b20db435b852086e325034=14850=TEST52=20250410-22:59:43.792579369=2262=951674d8-b877-4a40-8deb-be531852296483=1597363728893=N55=BTC-USD1682=full_trading268=10269=1278=f5b01c67-f98f-44b9-a511-7f07f8883d9e270=1000.00271=3.10000000269=1278=75a5c14f-8434-4533-a10e-0bf6e92e1000270=1000.00271=3.10000000269=1278=a9b0a826-3659-4105-9ecc-21bcd27b736f270=1000.00271=3.10000000269=1278=1b1bab77-5c52-459b-98e3-e27ff6f8cd04270=1000.00271=3.10000000269=1278=346695f1-fe03-4364-8fc5-006796c8f82f270=1000.00271=3.10000000269=1278=cbbaa36d-2a03-45a2-a230-bd5845d832cd270=1000.00271=3.10000000269=1278=745d4fc0-6710-4c5c-97c3-7b29c4e06839270=1000.00271=3.10000000269=1278=e95fdfba-5db2-4461-8e9c-7bfdf8a9238c270=1000.00271=3.10000000269=1278=33611b39-1fbf-45cc-bf5e-a02bc1f84736270=1000.00271=3.10000000269=1278=51f77b2d-1a69-432d-934b-234eb9e1dfac270=1000.00271=3.1000000010=134
20250410-22:59:44.151324000 : 8=FIXT.1.19=14235=334=4149=24ab46f784d1b20db435b852086e325052=20250410-22:59:44.15056=Coinbase45=14858=Tag appears more than once371=269372=W373=1310=051
20250410-22:59:44.151404000 : 8=FIXT.1.19=93935=W49=Coinbase56=24ab46f784d1b20db435b852086e325034=14950=TEST52=20250410-22:59:43.792829369=2262=951674d8-b877-4a40-8deb-be531852296483=1597363728893=N55=BTC-USD1682=full_trading268=10269=1278=ab09fdc3-8d50-432f-ab0f-97e8627eac24270=1000.00271=3.10000000269=1278=dde04213-6104-44c5-a811-15834c27b515270=1000.00271=3.10000000269=1278=9af2b85c-4997-4e1b-9147-7d400f059b01270=1000.00271=3.10000000269=1278=40870860-7a8a-4419-a117-e511f779abfa270=1000.00271=3.10000000269=1278=3e8fa7bd-dde0-4fe4-bb2e-e6279841b019270=1000.00271=3.10000000269=1278=4dde1422-98d8-405b-88df-bf245291ad7a270=1000.00271=3.10000000269=1278=6ee8b5a8-bc2f-4a0a-9ae4-7ff1b5dae941270=1000.00271=3.10000000269=1278=3ebc1f7a-2bb5-4ef0-a82f-844b9540f6e8270=1000.00271=3.10000000269=1278=a82d5bb9-1f1a-4575-b580-8d9b60863b10270=1000.00271=3.10000000269=1278=14f89bd5-0233-435c-b608-2e19131b8f6c270=1000.00271=3.1000000010=044
20250410-22:59:44.152289000 : 8=FIXT.1.19=14235=334=4249=24ab46f784d1b20db435b852086e325052=20250410-22:59:44.15156=Coinbase45=14958=Tag appears more than once371=269372=W373=1310=054
20250410-22:59:44.350777000 : 8=FIXT.1.19=93935=W49=Coinbase56=24ab46f784d1b20db435b852086e325034=15050=TEST52=20250410-22:59:43.793079369=2262=951674d8-b877-4a40-8deb-be531852296483=1597363728893=N55=BTC-USD1682=full_trading268=10269=1278=a2e319e5-aab7-41d4-9d19-98d771a3f1d3270=1000.00271=3.10000000269=1278=dc965e0b-075a-4ba4-a498-02c96d1664ba270=1000.00271=3.10000000269=1278=67b6e68f-ac11-4c05-a54a-2adb555b0123270=1000.00271=3.10000000269=1278=866f52a1-dad9-49d7-ac4a-9da3075407a3270=1000.00271=3.10000000269=1278=0e38234d-a010-40f6-9c6f-a0d574e773cf270=1000.00271=3.10000000269=1278=d6af6749-e3c8-4938-8741-1d5f177cf8e1270=1000.00271=3.10000000269=1278=45ff5e59-2c4d-45ac-9fde-403662dfd1ca270=1000.00271=3.10000000269=1278=dcac314e-c54f-44e3-b96d-ef71539766ed270=1000.00271=3.10000000269=1278=dd6d14ea-760f-4884-a546-1d3c40ebdd7c270=1000.00271=3.10000000269=1278=4f3da0c6-46eb-4b64-b973-cc43e24abccb270=1000.00271=3.1000000010=114
20250410-22:59:44.351962000 : 8=FIXT.1.19=14235=334=4349=24ab46f784d1b20db435b852086e325052=20250410-22:59:44.35156=Coinbase45=15058=Tag appears more than once371=269372=W373=1310=049
20250410-22:59:44.352100000 : 8=FIXT.1.19=95135=W49=Coinbase56=24ab46f784d1b20db435b852086e325034=15150=TEST52=20250410-22:59:43.793329369=2262=951674d8-b877-4a40-8deb-be531852296483=1597363728893=N55=BTC-USD1682=full_trading268=10269=1278=aa40cda8-4abd-4f52-999a-1a90ed5bf41a270=1000.00271=3.10000000269=1278=687ee4fc-f626-4e4f-abee-1f0ee5af3f72270=1000.00271=3.10000000269=1278=b1ad1135-67ec-4c96-99cb-a626137f3f16270=10000.00271=1.00000000269=1278=e9320f5f-80ae-41ab-af7a-86518d456fb0270=10000.00271=1.00000000269=1278=cd95aff0-36fa-4804-887f-2c3fce3cdc86270=10000.00271=1.00000000269=1278=fbdbcee1-8c29-4478-97df-358d209d8808270=10000.00271=1.00000000269=1278=140f39da-834b-4e42-8e15-6e25287df1f0270=900000.00271=0.00011111269=1278=49f064c5-76fe-4b38-bede-48b60a0a5aec270=900000.00271=0.00011111269=1278=681cf73b-9d37-4101-b940-9da9b1ff61ed270=900000.00271=0.00011111269=1278=3dea1587-e474-4258-b6e8-485c21b56670270=900000.00271=0.0001111110=049
20250410-22:59:44.352735000 : 8=FIXT.1.19=14235=334=4449=24ab46f784d1b20db435b852086e325052=20250410-22:59:44.35256=Coinbase45=15158=Tag appears more than once371=269372=W373=1310=052
