20250411-01:35:25.395687000 : 8=FIXT.1.19=26435=X49=Coinbase56=24ab46f784d1b20db435b852086e325034=1050=TEST52=20250411-01:35:25.252159369=2262=ac9dc520-fd90-4708-a92a-3ceddd7c32a3268=1279=2269=0278=4a733d79-d868-4ed2-ae59-e8a3297d780983=159755161955=BTC-USD60=20250411-01:35:25.25077058=FILLED10=178
20250411-01:35:25.402829000 : 8=FIXT.1.19=27335=X49=Coinbase56=24ab46f784d1b20db435b852086e325034=1150=TEST52=20250411-01:35:25.280361369=2262=ac9dc520-fd90-4708-a92a-3ceddd7c32a3268=1279=0269=183=159755162055=BTC-USD271=0.6232294660=20250411-01:35:25.27850240=137=7639da8a-b6ec-44ba-8f25-078943c17de410=014
20250411-01:35:25.403048000 : 8=FIXT.1.19=32535=X49=Coinbase56=24ab46f784d1b20db435b852086e325034=1250=TEST52=20250411-01:35:25.280367369=2262=ac9dc520-fd90-4708-a92a-3ceddd7c32a3268=1279=0269=2278=4d60a78e-b39b-420e-b830-bc0f3f4fdde283=159755162155=BTC-USD270=3.53271=0.6232294660=20250411-01:35:25.27850237=7639da8a-b6ec-44ba-8f25-078943c17de45797=210=009
20250411-01:35:25.403451000 : 8=FIXT.1.19=27935=X49=Coinbase56=24ab46f784d1b20db435b852086e325034=1350=TEST52=20250411-01:35:25.280370369=2262=ac9dc520-fd90-4708-a92a-3ceddd7c32a3268=1279=2269=1278=7639da8a-b6ec-44ba-8f25-078943c17de483=159755162255=BTC-USD271=0.0000000060=20250411-01:35:25.27850258=FILLED10=183
20250411-01:35:25.603407000 : 8=FIXT.1.19=27735=X49=Coinbase56=24ab46f784d1b20db435b852086e325034=1450=TEST52=20250411-01:35:25.481247369=2262=ac9dc520-fd90-4708-a92a-3ceddd7c32a3268=1279=0269=083=159755162355=BTC-USD29004=2.208895519560=20250411-01:35:25.47848640=137=f14485ef-20c1-4294-848d-ad2a16b462f210=146
20250411-01:35:25.604194000 : 8=FIXT.1.19=32535=X49=Coinbase56=24ab46f784d1b20db435b852086e325034=1550=TEST52=20250411-01:35:25.481253369=2262=ac9dc520-fd90-4708-a92a-3ceddd7c32a3268=1279=0269=2278=c5b88ea9-605d-4595-ac52-f7c3f08523ba83=159755162455=BTC-USD270=3.55271=0.6222240960=20250411-01:35:25.47848637=f14485ef-20c1-4294-848d-ad2a16b462f25797=110=034
20250411-01:35:25.604502000 : 8=FIXT.1.19=26435=X49=Coinbase56=24ab46f784d1b20db435b852086e325034=1650=TEST52=20250411-01:35:25.481257369=2262=ac9dc520-fd90-4708-a92a-3ceddd7c32a3268=1279=2269=0278=f14485ef-20c1-4294-848d-ad2a16b462f283=159755162555=BTC-USD60=20250411-01:35:25.47848658=FILLED10=163
20250411-01:35:25.633730000 : 8=FIXT.1.19=27335=X49=Coinbase56=24ab46f784d1b20db435b852086e325034=1750=TEST52=20250411-01:35:25.512922369=2262=ac9dc520-fd90-4708-a92a-3ceddd7c32a3268=1279=0269=183=159755162655=BTC-USD271=0.6232294660=20250411-01:35:25.50814040=137=36df62ae-c913-41f5-b72e-3f63232ce7e510=010
20250411-01:35:25.634174000 : 8=FIXT.1.19=32535=X49=Coinbase56=24ab46f784d1b20db435b852086e325034=1850=TEST52=20250411-01:35:25.512933369=2262=ac9dc520-fd90-4708-a92a-3ceddd7c32a3268=1279=0269=2278=4d60a78e-b39b-420e-b830-bc0f3f4fdde283=159755162755=BTC-USD270=3.53271=0.6232294660=20250411-01:35:25.50814037=36df62ae-c913-41f5-b72e-3f63232ce7e55797=210=001
20250411-01:35:25.634367000 : 8=FIXT.1.19=27935=X49=Coinbase56=24ab46f784d1b20db435b852086e325034=1950=TEST52=20250411-01:35:25.512938369=2262=ac9dc520-fd90-4708-a92a-3ceddd7c32a3268=1279=2269=1278=36df62ae-c913-41f5-b72e-3f63232ce7e583=159755162855=BTC-USD271=0.0000000060=20250411-01:35:25.50814058=FILLED10=186
20250411-01:35:25.803717000 : 8=FIXT.1.19=28235=X49=Coinbase56=24ab46f784d1b20db435b852086e325034=2050=TEST52=20250411-01:35:25.680758369=2262=ac9dc520-fd90-4708-a92a-3ceddd7c32a3268=1279=0269=083=159755162955=BTC-USD270=3.77271=0.6232294660=20250411-01:35:25.66827340=237=70985e75-ee3e-40d1-8022-acdab5cc94e510=247
20250411-01:35:25.804485000 : 8=FIXT.1.19=32535=X49=Coinbase56=24ab46f784d1b20db435b852086e325034=2150=TEST52=20250411-01:35:25.680765369=2262=ac9dc520-fd90-4708-a92a-3ceddd7c32a3268=1279=0269=2278=c5b88ea9-605d-4595-ac52-f7c3f08523ba83=159755163055=BTC-USD270=3.55271=0.6232294660=20250411-01:35:25.66827337=70985e75-ee3e-40d1-8022-acdab5cc94e55797=110=188
20250411-01:35:25.804799000 : 8=FIXT.1.19=28835=X49=Coinbase56=24ab46f784d1b20db435b852086e325034=2250=TEST52=20250411-01:35:25.680770369=2262=ac9dc520-fd90-4708-a92a-3ceddd7c32a3268=1279=2269=0278=70985e75-ee3e-40d1-8022-acdab5cc94e583=159755163155=BTC-USD270=3.77271=0.0000000060=20250411-01:35:25.66827358=FILLED10=144
20250411-01:35:25.857292000 : 8=FIXT.1.19=28235=X49=Coinbase56=24ab46f784d1b20db435b852086e325034=2350=TEST52=20250411-01:35:25.736290369=2262=ac9dc520-fd90-4708-a92a-3ceddd7c32a3268=1279=0269=183=159755163255=BTC-USD270=3.35271=0.6232294660=20250411-01:35:25.72343440=237=20a50747-35f9-4de5-95b7-2e0363e6fbc510=085
20250411-01:35:25.857848000 : 8=FIXT.1.19=32535=X49=Coinbase56=24ab46f784d1b20db435b852086e325034=2450=TEST52=20250411-01:35:25.736296369=2262=ac9dc520-fd90-4708-a92a-3ceddd7c32a3268=1279=0269=2278=4d60a78e-b39b-420e-b830-bc0f3f4fdde283=159755163355=BTC-USD270=3.53271=0.6232294660=20250411-01:35:25.72343437=20a50747-35f9-4de5-95b7-2e0363e6fbc55797=210=175
20250411-01:35:25.858056000 : 8=FIXT.1.19=28835=X49=Coinbase56=24ab46f784d1b20db435b852086e325034=2550=TEST52=20250411-01:35:25.736300369=2262=ac9dc520-fd90-4708-a92a-3ceddd7c32a3268=1279=2269=1278=20a50747-35f9-4de5-95b7-2e0363e6fbc583=159755163455=BTC-USD270=3.35271=0.0000000060=20250411-01:35:25.72343458=FILLED10=245
20250411-01:35:26.135337000 : 8=FIXT.1.19=28235=X49=Coinbase56=24ab46f784d1b20db435b852086e325034=2650=TEST52=20250411-01:35:26.011070369=2262=ac9dc520-fd90-4708-a92a-3ceddd7c32a3268=1279=0269=183=159755163555=BTC-USD270=3.23271=0.6232294660=20250411-01:35:26.00996140=237=28254cd7-c616-44f1-8404-dca3cb3e741210=058
20250411-01:35:26.144037000 : 8=FIXT.1.19=32535=X49=Coinbase56=24ab46f784d1b20db435b852086e325034=2750=TEST52=20250411-01:35:26.011134369=2262=ac9dc520-fd90-4708-a92a-3ceddd7c32a3268=1279=0269=2278=4d60a78e-b39b-420e-b830-bc0f3f4fdde283=159755163655=BTC-USD270=3.53271=0.6232294660=20250411-01:35:26.00996137=28254cd7-c616-44f1-8404-dca3cb3e74125797=210=146
20250411-01:35:26.168703000 : 8=FIXT.1.19=28835=X49=Coinbase56=24ab46f784d1b20db435b852086e325034=2850=TEST52=20250411-01:35:26.011139369=2262=ac9dc520-fd90-4708-a92a-3ceddd7c32a3268=1279=2269=1278=28254cd7-c616-44f1-8404-dca3cb3e741283=159755163755=BTC-USD270=3.23271=0.0000000060=20250411-01:35:26.00996158=FILLED10=232
20250411-01:35:26.191915000 : 8=FIXT.1.19=28235=X49=Coinbase56=24ab46f784d1b20db435b852086e325034=2950=TEST52=20250411-01:35:26.066505369=2262=ac9dc520-fd90-4708-a92a-3ceddd7c32a3268=1279=0269=083=159755163855=BTC-USD270=3.71271=0.6232294660=20250411-01:35:26.06538740=237=a71d0ac7-f544-418e-8661-2c0de9cd45a410=185
20250411-01:35:26.194688000 : 8=FIXT.1.19=32535=X49=Coinbase56=24ab46f784d1b20db435b852086e325034=3050=TEST52=20250411-01:35:26.066510369=2262=ac9dc520-fd90-4708-a92a-3ceddd7c32a3268=1279=0269=2278=c5b88ea9-605d-4595-ac52-f7c3f08523ba83=159755163955=BTC-USD270=3.55271=0.6232294660=20250411-01:35:26.06538737=a71d0ac7-f544-418e-8661-2c0de9cd45a45797=110=130
20250411-01:35:26.195389000 : 8=FIXT.1.19=28835=X49=Coinbase56=24ab46f784d1b20db435b852086e325034=3150=TEST52=20250411-01:35:26.066514369=2262=ac9dc520-fd90-4708-a92a-3ceddd7c32a3268=1279=2269=0278=a71d0ac7-f544-418e-8661-2c0de9cd45a483=159755164055=BTC-USD270=3.71271=0.0000000060=20250411-01:35:26.06538758=FILLED10=079
20250411-01:35:26.287367000 : 8=FIXT.1.19=27735=X49=Coinbase56=24ab46f784d1b20db435b852086e325034=3250=TEST52=20250411-01:35:26.166102369=2262=ac9dc520-fd90-4708-a92a-3ceddd7c32a3268=1279=0269=083=159755164155=BTC-USD29004=2.208895519560=20250411-01:35:26.16489740=137=a2ebec02-18dd-40ce-bda0-b7a71066408710=052
20250411-01:35:26.288321000 : 8=FIXT.1.19=32535=X49=Coinbase56=24ab46f784d1b20db435b852086e325034=3350=TEST52=20250411-01:35:26.166109369=2262=ac9dc520-fd90-4708-a92a-3ceddd7c32a3268=1279=0269=2278=c5b88ea9-605d-4595-ac52-f7c3f08523ba83=159755164255=BTC-USD270=3.55271=0.6222240960=20250411-01:35:26.16489737=a2ebec02-18dd-40ce-bda0-b7a7106640875797=110=206
20250411-01:35:26.288510000 : 8=FIXT.1.19=26435=X49=Coinbase56=24ab46f784d1b20db435b852086e325034=3450=TEST52=20250411-01:35:26.166113369=2262=ac9dc520-fd90-4708-a92a-3ceddd7c32a3268=1279=2269=0278=a2ebec02-18dd-40ce-bda0-b7a71066408783=159755164355=BTC-USD60=20250411-01:35:26.16489758=FILLED10=070
20250411-01:35:26.314750000 : 8=FIXT.1.19=27335=X49=Coinbase56=24ab46f784d1b20db435b852086e325034=3550=TEST52=20250411-01:35:26.194010369=2262=ac9dc520-fd90-4708-a92a-3ceddd7c32a3268=1279=0269=183=159755164455=BTC-USD271=0.6197183160=20250411-01:35:26.19288840=137=009fc3a2-ab94-4799-a3fe-c8fcfecb973a10=227
20250411-01:35:26.315280000 : 8=FIXT.1.19=32535=X49=Coinbase56=24ab46f784d1b20db435b852086e325034=3650=TEST52=20250411-01:35:26.194073369=2262=ac9dc520-fd90-4708-a92a-3ceddd7c32a3268=1279=0269=2278=4d60a78e-b39b-420e-b830-bc0f3f4fdde283=159755164555=BTC-USD270=3.53271=0.6197183160=20250411-01:35:26.19288837=009fc3a2-ab94-4799-a3fe-c8fcfecb973a5797=210=225
20250411-01:35:26.316126000 : 8=FIXT.1.19=27935=X49=Coinbase56=24ab46f784d1b20db435b852086e325034=3750=TEST52=20250411-01:35:26.194079369=2262=ac9dc520-fd90-4708-a92a-3ceddd7c32a3268=1279=2269=1278=009fc3a2-ab94-4799-a3fe-c8fcfecb973a83=159755164655=BTC-USD271=0.0000000060=20250411-01:35:26.19288858=FILLED10=153
20250411-01:35:26.436344000 : 8=FIXT.1.19=28235=X49=Coinbase56=24ab46f784d1b20db435b852086e325034=3850=TEST52=20250411-01:35:26.315672369=2262=ac9dc520-fd90-4708-a92a-3ceddd7c32a3268=1279=0269=083=159755164755=BTC-USD270=3.91271=0.6197183160=20250411-01:35:26.31371340=237=5f853980-5ca3-42ff-83f2-39fb5cf7eb1810=204
20250411-01:35:26.436890000 : 8=FIXT.1.19=32535=X49=Coinbase56=24ab46f784d1b20db435b852086e325034=3950=TEST52=20250411-01:35:26.315680369=2262=ac9dc520-fd90-4708-a92a-3ceddd7c32a3268=1279=0269=2278=c5b88ea9-605d-4595-ac52-f7c3f08523ba83=159755164855=BTC-USD270=3.55271=0.6197183160=20250411-01:35:26.31371337=5f853980-5ca3-42ff-83f2-39fb5cf7eb185797=110=159
20250411-01:35:26.437075000 : 8=FIXT.1.19=28835=X49=Coinbase56=24ab46f784d1b20db435b852086e325034=4050=TEST52=20250411-01:35:26.315684369=2262=ac9dc520-fd90-4708-a92a-3ceddd7c32a3268=1279=2269=0278=5f853980-5ca3-42ff-83f2-39fb5cf7eb1883=159755164955=BTC-USD270=3.91271=0.0000000060=20250411-01:35:26.31371358=FILLED10=108
20250411-01:35:26.801726000 : 8=FIXT.1.19=27735=X49=Coinbase56=24ab46f784d1b20db435b852086e325034=4150=TEST52=20250411-01:35:26.680586369=2262=ac9dc520-fd90-4708-a92a-3ceddd7c32a3268=1279=0269=083=159755165055=BTC-USD29004=2.208895519560=20250411-01:35:26.67866440=137=3be207a1-9173-40f5-ba46-570f2e04eabc10=235
20250411-01:35:26.802363000 : 8=FIXT.1.19=32535=X49=Coinbase56=24ab46f784d1b20db435b852086e325034=4250=TEST52=20250411-01:35:26.680594369=2262=ac9dc520-fd90-4708-a92a-3ceddd7c32a3268=1279=0269=2278=c5b88ea9-605d-4595-ac52-f7c3f08523ba83=159755165155=BTC-USD270=3.55271=0.6222240960=20250411-01:35:26.67866437=3be207a1-9173-40f5-ba46-570f2e04eabc5797=110=125
20250411-01:35:26.802557000 : 8=FIXT.1.19=26435=X49=Coinbase56=24ab46f784d1b20db435b852086e325034=4350=TEST52=20250411-01:35:26.680598369=2262=ac9dc520-fd90-4708-a92a-3ceddd7c32a3268=1279=2269=0278=3be207a1-9173-40f5-ba46-570f2e04eabc83=159755165255=BTC-USD60=20250411-01:35:26.67866458=FILLED10=254
20250411-01:35:26.828534000 : 8=FIXT.1.19=27335=X49=Coinbase56=24ab46f784d1b20db435b852086e325034=4450=TEST52=20250411-01:35:26.707842369=2262=ac9dc520-fd90-4708-a92a-3ceddd7c32a3268=1279=0269=183=159755165355=BTC-USD271=0.6197183160=20250411-01:35:26.70690840=137=629acf21-dbfb-4928-a24c-7673acdd0eb310=168
20250411-01:35:26.829217000 : 8=FIXT.1.19=32535=X49=Coinbase56=24ab46f784d1b20db435b852086e325034=4550=TEST52=20250411-01:35:26.707850369=2262=ac9dc520-fd90-4708-a92a-3ceddd7c32a3268=1279=0269=2278=4d60a78e-b39b-420e-b830-bc0f3f4fdde283=159755165455=BTC-USD270=3.53271=0.6197183160=20250411-01:35:26.70690837=629acf21-dbfb-4928-a24c-7673acdd0eb35797=210=156
20250411-01:35:26.829576000 : 8=FIXT.1.19=27935=X49=Coinbase56=24ab46f784d1b20db435b852086e325034=4650=TEST52=20250411-01:35:26.707854369=2262=ac9dc520-fd90-4708-a92a-3ceddd7c32a3268=1279=2269=1278=629acf21-dbfb-4928-a24c-7673acdd0eb383=159755165555=BTC-USD271=0.0000000060=20250411-01:35:26.70690858=FILLED10=082
20250411-01:35:26.972061000 : 8=FIXT.1.19=27735=X49=Coinbase56=24ab46f784d1b20db435b852086e325034=4750=TEST52=20250411-01:35:26.850637369=2262=ac9dc520-fd90-4708-a92a-3ceddd7c32a3268=1279=0269=083=159755165655=BTC-USD29004=2.208895519560=20250411-01:35:26.84994040=137=8faf5e0b-a98c-445b-8e60-fad78dd59f6010=167
20250411-01:35:26.972645000 : 8=FIXT.1.19=32535=X49=Coinbase56=24ab46f784d1b20db435b852086e325034=4850=TEST52=20250411-01:35:26.850641369=2262=ac9dc520-fd90-4708-a92a-3ceddd7c32a3268=1279=0269=2278=c5b88ea9-605d-4595-ac52-f7c3f08523ba83=159755165755=BTC-USD270=3.55271=0.6222240960=20250411-01:35:26.84994037=8faf5e0b-a98c-445b-8e60-fad78dd59f605797=110=053
20250411-01:35:26.972871000 : 8=FIXT.1.19=26435=X49=Coinbase56=24ab46f784d1b20db435b852086e325034=4950=TEST52=20250411-01:35:26.850645369=2262=ac9dc520-fd90-4708-a92a-3ceddd7c32a3268=1279=2269=0278=8faf5e0b-a98c-445b-8e60-fad78dd59f6083=159755165855=BTC-USD60=20250411-01:35:26.84994058=FILLED10=182
20250411-01:35:27.002374000 : 8=FIXT.1.19=27335=X49=Coinbase56=24ab46f784d1b20db435b852086e325034=5050=TEST52=20250411-01:35:26.881227369=2262=ac9dc520-fd90-4708-a92a-3ceddd7c32a3268=1279=0269=183=159755165955=BTC-USD271=0.6232294660=20250411-01:35:26.87936440=137=e7045550-cd8e-4724-bc5a-7a67228fe09310=205
20250411-01:35:27.002936000 : 8=FIXT.1.19=32535=X49=Coinbase56=24ab46f784d1b20db435b852086e325034=5150=TEST52=20250411-01:35:26.881233369=2262=ac9dc520-fd90-4708-a92a-3ceddd7c32a3268=1279=0269=2278=4d60a78e-b39b-420e-b830-bc0f3f4fdde283=159755166055=BTC-USD270=3.53271=0.6232294660=20250411-01:35:26.87936437=e7045550-cd8e-4724-bc5a-7a67228fe0935797=210=182
20250411-01:35:27.003150000 : 8=FIXT.1.19=27935=X49=Coinbase56=24ab46f784d1b20db435b852086e325034=5250=TEST52=20250411-01:35:26.881237369=2262=ac9dc520-fd90-4708-a92a-3ceddd7c32a3268=1279=2269=1278=e7045550-cd8e-4724-bc5a-7a67228fe09383=159755166155=BTC-USD271=0.0000000060=20250411-01:35:26.87936458=FILLED10=110
20250411-01:35:27.030217000 : 8=FIXT.1.19=27735=X49=Coinbase56=24ab46f784d1b20db435b852086e325034=5350=TEST52=20250411-01:35:26.909433369=2262=ac9dc520-fd90-4708-a92a-3ceddd7c32a3268=1279=0269=083=159755166255=BTC-USD29004=2.208895519560=20250411-01:35:26.90716940=137=3dc51b6e-10d1-4739-8c8c-dfa7e513029910=206
20250411-01:35:27.030533000 : 8=FIXT.1.19=32535=X49=Coinbase56=24ab46f784d1b20db435b852086e325034=5450=TEST52=20250411-01:35:26.909438369=2262=ac9dc520-fd90-4708-a92a-3ceddd7c32a3268=1279=0269=2278=c5b88ea9-605d-4595-ac52-f7c3f08523ba83=159755166355=BTC-USD270=3.55271=0.6222240960=20250411-01:35:26.90716937=3dc51b6e-10d1-4739-8c8c-dfa7e51302995797=110=102
20250411-01:35:27.030702000 : 8=FIXT.1.19=26435=X49=Coinbase56=24ab46f784d1b20db435b852086e325034=5550=TEST52=20250411-01:35:26.909442369=2262=ac9dc520-fd90-4708-a92a-3ceddd7c32a3268=1279=2269=0278=3dc51b6e-10d1-4739-8c8c-dfa7e513029983=159755166455=BTC-USD60=20250411-01:35:26.90716958=FILLED10=222
20250411-01:35:27.047499000 : 8=FIXT.1.19=28235=X49=Coinbase56=24ab46f784d1b20db435b852086e325034=5650=TEST52=20250411-01:35:26.926754369=2262=ac9dc520-fd90-4708-a92a-3ceddd7c32a3268=1279=0269=083=159755166555=BTC-USD270=3.75271=0.6197183160=20250411-01:35:26.92551440=237=7c7c615c-7c0c-49a3-8e54-b65da838855910=128
20250411-01:35:27.048116000 : 8=FIXT.1.19=32535=X49=Coinbase56=24ab46f784d1b20db435b852086e325034=5750=TEST52=20250411-01:35:26.926759369=2262=ac9dc520-fd90-4708-a92a-3ceddd7c32a3268=1279=0269=2278=c5b88ea9-605d-4595-ac52-f7c3f08523ba83=159755166655=BTC-USD270=3.55271=0.6197183160=20250411-01:35:26.92551437=7c7c615c-7c0c-49a3-8e54-b65da83885595797=110=087
20250411-01:35:27.048383000 : 8=FIXT.1.19=28835=X49=Coinbase56=24ab46f784d1b20db435b852086e325034=5850=TEST52=20250411-01:35:26.926763369=2262=ac9dc520-fd90-4708-a92a-3ceddd7c32a3268=1279=2269=0278=7c7c615c-7c0c-49a3-8e54-b65da838855983=159755166755=BTC-USD270=3.75271=0.0000000060=20250411-01:35:26.92551458=FILLED10=038
20250411-01:35:27.057369000 : 8=FIXT.1.19=27335=X49=Coinbase56=24ab46f784d1b20db435b852086e325034=5950=TEST52=20250411-01:35:26.936278369=2262=ac9dc520-fd90-4708-a92a-3ceddd7c32a3268=1279=0269=183=159755166855=BTC-USD271=0.6197183160=20250411-01:35:26.93530340=137=b056c5ae-c84a-4c96-bca8-0d1eb56840db10=178
20250411-01:35:27.057551000 : 8=FIXT.1.19=32535=X49=Coinbase56=24ab46f784d1b20db435b852086e325034=6050=TEST52=20250411-01:35:26.936282369=2262=ac9dc520-fd90-4708-a92a-3ceddd7c32a3268=1279=0269=2278=4d60a78e-b39b-420e-b830-bc0f3f4fdde283=159755166955=BTC-USD270=3.53271=0.6197183160=20250411-01:35:26.93530337=b056c5ae-c84a-4c96-bca8-0d1eb56840db5797=210=153
20250411-01:35:27.057712000 : 8=FIXT.1.19=27935=X49=Coinbase56=24ab46f784d1b20db435b852086e325034=6150=TEST52=20250411-01:35:26.936286369=2262=ac9dc520-fd90-4708-a92a-3ceddd7c32a3268=1279=2269=1278=b056c5ae-c84a-4c96-bca8-0d1eb56840db83=159755167055=BTC-USD271=0.0000000060=20250411-01:35:26.93530358=FILLED10=070
20250411-01:35:27.103869000 : 8=FIXT.1.19=28235=X49=Coinbase56=24ab46f784d1b20db435b852086e325034=6250=TEST52=20250411-01:35:26.980392369=2262=ac9dc520-fd90-4708-a92a-3ceddd7c32a3268=1279=0269=183=159755167155=BTC-USD270=3.29271=0.6197183160=20250411-01:35:26.97930540=237=ac5afb60-5d92-4e6c-afcf-ec11aca7024f10=216
20250411-01:35:27.104821000 : 8=FIXT.1.19=32535=X49=Coinbase56=24ab46f784d1b20db435b852086e325034=6350=TEST52=20250411-01:35:26.980397369=2262=ac9dc520-fd90-4708-a92a-3ceddd7c32a3268=1279=0269=2278=4d60a78e-b39b-420e-b830-bc0f3f4fdde283=159755167255=BTC-USD270=3.53271=0.6197183160=20250411-01:35:26.97930537=ac5afb60-5d92-4e6c-afcf-ec11aca7024f5797=210=046
20250411-01:35:27.108336000 : 8=FIXT.1.19=28835=X49=Coinbase56=24ab46f784d1b20db435b852086e325034=6450=TEST52=20250411-01:35:26.980401369=2262=ac9dc520-fd90-4708-a92a-3ceddd7c32a3268=1279=2269=1278=ac5afb60-5d92-4e6c-afcf-ec11aca7024f83=159755167355=BTC-USD270=3.29271=0.0000000060=20250411-01:35:26.97930558=FILLED10=117
20250411-01:35:27.428737000 : 8=FIXT.1.19=27735=X49=Coinbase56=24ab46f784d1b20db435b852086e325034=6550=TEST52=20250411-01:35:27.307958369=2262=ac9dc520-fd90-4708-a92a-3ceddd7c32a3268=1279=0269=083=159755167455=BTC-USD29004=2.208895519560=20250411-01:35:27.30668740=137=a2576331-9eb0-4917-9a41-98812b14064210=179
20250411-01:35:27.429672000 : 8=FIXT.1.19=32535=X49=Coinbase56=24ab46f784d1b20db435b852086e325034=6650=TEST52=20250411-01:35:27.307965369=2262=ac9dc520-fd90-4708-a92a-3ceddd7c32a3268=1279=0269=2278=c5b88ea9-605d-4595-ac52-f7c3f08523ba83=159755167555=BTC-USD270=3.55271=0.6222240960=20250411-01:35:27.30668737=a2576331-9eb0-4917-9a41-98812b1406425797=110=068
20250411-01:35:27.429903000 : 8=FIXT.1.19=26435=X49=Coinbase56=24ab46f784d1b20db435b852086e325034=6750=TEST52=20250411-01:35:27.307968369=2262=ac9dc520-fd90-4708-a92a-3ceddd7c32a3268=1279=2269=0278=a2576331-9eb0-4917-9a41-98812b14064283=159755167655=BTC-USD60=20250411-01:35:27.30668758=FILLED10=196
20250411-01:35:27.435883000 : 8=FIXT.1.19=28135=X49=Coinbase56=24ab46f784d1b20db435b852086e325034=6850=TEST52=20250411-01:35:27.311622369=2262=ac9dc520-fd90-4708-a92a-3ceddd7c32a3268=1279=0269=183=159755167755=BTC-USD270=3.2271=0.6197183160=20250411-01:35:27.31073840=237=3a6b9665-d66c-4000-a60d-9019df255b0510=233
20250411-01:35:27.436255000 : 8=FIXT.1.19=32535=X49=Coinbase56=24ab46f784d1b20db435b852086e325034=6950=TEST52=20250411-01:35:27.311627369=2262=ac9dc520-fd90-4708-a92a-3ceddd7c32a3268=1279=0269=2278=4d60a78e-b39b-420e-b830-bc0f3f4fdde283=159755167855=BTC-USD270=3.53271=0.6197183160=20250411-01:35:27.31073837=3a6b9665-d66c-4000-a60d-9019df255b055797=210=121
20250411-01:35:27.437059000 : 8=FIXT.1.19=28735=X49=Coinbase56=24ab46f784d1b20db435b852086e325034=7050=TEST52=20250411-01:35:27.311631369=2262=ac9dc520-fd90-4708-a92a-3ceddd7c32a3268=1279=2269=1278=3a6b9665-d66c-4000-a60d-9019df255b0583=159755167955=BTC-USD270=3.2271=0.0000000060=20250411-01:35:27.31073858=FILLED10=134
20250411-01:35:27.458094000 : 8=FIXT.1.19=27335=X49=Coinbase56=24ab46f784d1b20db435b852086e325034=7150=TEST52=20250411-01:35:27.336411369=2262=ac9dc520-fd90-4708-a92a-3ceddd7c32a3268=1279=0269=183=159755168055=BTC-USD271=0.6232294660=20250411-01:35:27.33537140=137=debab315-d88a-4e71-8cfe-93a30f21958910=071
20250411-01:35:27.458668000 : 8=FIXT.1.19=32535=X49=Coinbase56=24ab46f784d1b20db435b852086e325034=7250=TEST52=20250411-01:35:27.336416369=2262=ac9dc520-fd90-4708-a92a-3ceddd7c32a3268=1279=0269=2278=4d60a78e-b39b-420e-b830-bc0f3f4fdde283=159755168155=BTC-USD270=3.53271=0.6232294660=20250411-01:35:27.33537137=debab315-d88a-4e71-8cfe-93a30f2195895797=210=065
20250411-01:35:27.458868000 : 8=FIXT.1.19=27935=X49=Coinbase56=24ab46f784d1b20db435b852086e325034=7350=TEST52=20250411-01:35:27.336457369=2262=ac9dc520-fd90-4708-a92a-3ceddd7c32a3268=1279=2269=1278=debab315-d88a-4e71-8cfe-93a30f21958983=159755168255=BTC-USD271=0.0000000060=20250411-01:35:27.33537158=FILLED10=250
20250411-01:35:27.543596000 : 8=FIXT.1.19=27735=X49=Coinbase56=24ab46f784d1b20db435b852086e325034=7450=TEST52=20250411-01:35:27.422860369=2262=ac9dc520-fd90-4708-a92a-3ceddd7c32a3268=1279=0269=083=159755168355=BTC-USD29004=2.208895519560=20250411-01:35:27.42177140=137=8d446cda-e692-47c5-9dc8-092f739e5e1510=222
20250411-01:35:27.544193000 : 8=FIXT.1.19=32535=X49=Coinbase56=24ab46f784d1b20db435b852086e325034=7550=TEST52=20250411-01:35:27.422868369=2262=ac9dc520-fd90-4708-a92a-3ceddd7c32a3268=1279=0269=2278=c5b88ea9-605d-4595-ac52-f7c3f08523ba83=159755168455=BTC-USD270=3.55271=0.6222240960=20250411-01:35:27.42177137=8d446cda-e692-47c5-9dc8-092f739e5e155797=110=121
20250411-01:35:27.544489000 : 8=FIXT.1.19=26435=X49=Coinbase56=24ab46f784d1b20db435b852086e325034=7650=TEST52=20250411-01:35:27.422872369=2262=ac9dc520-fd90-4708-a92a-3ceddd7c32a3268=1279=2269=0278=8d446cda-e692-47c5-9dc8-092f739e5e1583=159755168555=BTC-USD60=20250411-01:35:27.42177158=FILLED10=241
20250411-01:35:27.573583000 : 8=FIXT.1.19=27335=X49=Coinbase56=24ab46f784d1b20db435b852086e325034=7750=TEST52=20250411-01:35:27.451816369=2262=ac9dc520-fd90-4708-a92a-3ceddd7c32a3268=1279=0269=183=159755168655=BTC-USD271=0.6232294660=20250411-01:35:27.45013540=137=f2ab1c78-c6c5-4c65-9952-4464ccf9407d10=251
20250411-01:35:27.573986000 : 8=FIXT.1.19=32535=X49=Coinbase56=24ab46f784d1b20db435b852086e325034=7850=TEST52=20250411-01:35:27.451823369=2262=ac9dc520-fd90-4708-a92a-3ceddd7c32a3268=1279=0269=2278=4d60a78e-b39b-420e-b830-bc0f3f4fdde283=159755168755=BTC-USD270=3.53271=0.6232294660=20250411-01:35:27.45013537=f2ab1c78-c6c5-4c65-9952-4464ccf9407d5797=210=238
20250411-01:35:27.574246000 : 8=FIXT.1.19=27935=X49=Coinbase56=24ab46f784d1b20db435b852086e325034=7950=TEST52=20250411-01:35:27.451827369=2262=ac9dc520-fd90-4708-a92a-3ceddd7c32a3268=1279=2269=1278=f2ab1c78-c6c5-4c65-9952-4464ccf9407d83=159755168855=BTC-USD271=0.0000000060=20250411-01:35:27.45013558=FILLED10=166
20250411-01:35:27.658595000 : 8=FIXT.1.19=27735=X49=Coinbase56=24ab46f784d1b20db435b852086e325034=8050=TEST52=20250411-01:35:27.537485369=2262=ac9dc520-fd90-4708-a92a-3ceddd7c32a3268=1279=0269=083=159755168955=BTC-USD29004=2.208895519560=20250411-01:35:27.53565640=137=2945885b-ef67-457c-b994-9264f0d530d710=103
20250411-01:35:27.658883000 : 8=FIXT.1.19=32535=X49=Coinbase56=24ab46f784d1b20db435b852086e325034=8150=TEST52=20250411-01:35:27.537491369=2262=ac9dc520-fd90-4708-a92a-3ceddd7c32a3268=1279=0269=2278=c5b88ea9-605d-4595-ac52-f7c3f08523ba83=159755169055=BTC-USD270=3.55271=0.6222240960=20250411-01:35:27.53565637=2945885b-ef67-457c-b994-9264f0d530d75797=110=238
20250411-01:35:27.659173000 : 8=FIXT.1.19=26435=X49=Coinbase56=24ab46f784d1b20db435b852086e325034=8250=TEST52=20250411-01:35:27.537494369=2262=ac9dc520-fd90-4708-a92a-3ceddd7c32a3268=1279=2269=0278=2945885b-ef67-457c-b994-9264f0d530d783=159755169155=BTC-USD60=20250411-01:35:27.53565658=FILLED10=110
20250411-01:35:27.687614000 : 8=FIXT.1.19=27335=X49=Coinbase56=24ab46f784d1b20db435b852086e325034=8350=TEST52=20250411-01:35:27.565658369=2262=ac9dc520-fd90-4708-a92a-3ceddd7c32a3268=1279=0269=183=159755169255=BTC-USD271=0.6232294660=20250411-01:35:27.56418340=137=d0c91cc0-c19b-4a72-ada8-3768a7fd063210=079
20250411-01:35:27.688193000 : 8=FIXT.1.19=32535=X49=Coinbase56=24ab46f784d1b20db435b852086e325034=8450=TEST52=20250411-01:35:27.565664369=2262=ac9dc520-fd90-4708-a92a-3ceddd7c32a3268=1279=0269=2278=4d60a78e-b39b-420e-b830-bc0f3f4fdde283=159755169355=BTC-USD270=3.53271=0.6232294660=20250411-01:35:27.56418337=d0c91cc0-c19b-4a72-ada8-3768a7fd06325797=210=065
20250411-01:35:27.688566000 : 8=FIXT.1.19=27935=X49=Coinbase56=24ab46f784d1b20db435b852086e325034=8550=TEST52=20250411-01:35:27.565668369=2262=ac9dc520-fd90-4708-a92a-3ceddd7c32a3268=1279=2269=1278=d0c91cc0-c19b-4a72-ada8-3768a7fd063283=159755169455=BTC-USD271=0.0000000060=20250411-01:35:27.56418358=FILLED10=249
20250411-01:35:27.715246000 : 8=FIXT.1.19=27735=X49=Coinbase56=24ab46f784d1b20db435b852086e325034=8650=TEST52=20250411-01:35:27.594107369=2262=ac9dc520-fd90-4708-a92a-3ceddd7c32a3268=1279=0269=083=159755169555=BTC-USD29004=2.208895519560=20250411-01:35:27.59266540=137=7361d3b9-a119-4956-8eca-bae08b3e137010=212
20250411-01:35:27.715499000 : 8=FIXT.1.19=32535=X49=Coinbase56=24ab46f784d1b20db435b852086e325034=8750=TEST52=20250411-01:35:27.594112369=2262=ac9dc520-fd90-4708-a92a-3ceddd7c32a3268=1279=0269=2278=c5b88ea9-605d-4595-ac52-f7c3f08523ba83=159755169655=BTC-USD270=3.55271=0.6222240960=20250411-01:35:27.59266537=7361d3b9-a119-4956-8eca-bae08b3e13705797=110=099
20250411-01:35:27.715734000 : 8=FIXT.1.19=26435=X49=Coinbase56=24ab46f784d1b20db435b852086e325034=8850=TEST52=20250411-01:35:27.594116369=2262=ac9dc520-fd90-4708-a92a-3ceddd7c32a3268=1279=2269=0278=7361d3b9-a119-4956-8eca-bae08b3e137083=159755169755=BTC-USD60=20250411-01:35:27.59266558=FILLED10=228
20250411-01:35:27.732975000 : 8=FIXT.1.19=28235=X49=Coinbase56=24ab46f784d1b20db435b852086e325034=8950=TEST52=20250411-01:35:27.611770369=2262=ac9dc520-fd90-4708-a92a-3ceddd7c32a3268=1279=0269=183=159755169855=BTC-USD270=3.23271=0.6197183160=20250411-01:35:27.60994740=237=9bf143ac-6a66-48df-9266-7efb391386a810=183
20250411-01:35:27.733538000 : 8=FIXT.1.19=32535=X49=Coinbase56=24ab46f784d1b20db435b852086e325034=9050=TEST52=20250411-01:35:27.611775369=2262=ac9dc520-fd90-4708-a92a-3ceddd7c32a3268=1279=0269=2278=4d60a78e-b39b-420e-b830-bc0f3f4fdde283=159755169955=BTC-USD270=3.53271=0.6197183160=20250411-01:35:27.60994737=9bf143ac-6a66-48df-9266-7efb391386a85797=210=010
20250411-01:35:27.733731000 : 8=FIXT.1.19=28835=X49=Coinbase56=24ab46f784d1b20db435b852086e325034=9150=TEST52=20250411-01:35:27.611779369=2262=ac9dc520-fd90-4708-a92a-3ceddd7c32a3268=1279=2269=1278=9bf143ac-6a66-48df-9266-7efb391386a883=159755170055=BTC-USD270=3.23271=0.0000000060=20250411-01:35:27.60994758=FILLED10=075
20250411-01:35:27.750826000 : 8=FIXT.1.19=27335=X49=Coinbase56=24ab46f784d1b20db435b852086e325034=9250=TEST52=20250411-01:35:27.624022369=2262=ac9dc520-fd90-4708-a92a-3ceddd7c32a3268=1279=0269=183=159755170155=BTC-USD271=0.6197183160=20250411-01:35:27.62250940=137=c3dd0fa6-62bf-4ec3-98bb-94a6f5f8124110=111
20250411-01:35:27.751130000 : 8=FIXT.1.19=32535=X49=Coinbase56=24ab46f784d1b20db435b852086e325034=9350=TEST52=20250411-01:35:27.624027369=2262=ac9dc520-fd90-4708-a92a-3ceddd7c32a3268=1279=0269=2278=4d60a78e-b39b-420e-b830-bc0f3f4fdde283=159755170255=BTC-USD270=3.53271=0.6197183160=20250411-01:35:27.62250937=c3dd0fa6-62bf-4ec3-98bb-94a6f5f812415797=210=105
20250411-01:35:27.751307000 : 8=FIXT.1.19=27935=X49=Coinbase56=24ab46f784d1b20db435b852086e325034=9450=TEST52=20250411-01:35:27.624031369=2262=ac9dc520-fd90-4708-a92a-3ceddd7c32a3268=1279=2269=1278=c3dd0fa6-62bf-4ec3-98bb-94a6f5f8124183=159755170355=BTC-USD271=0.0000000060=20250411-01:35:27.62250958=FILLED10=022
20250411-01:35:27.788494000 : 8=FIXT.1.19=28135=X49=Coinbase56=24ab46f784d1b20db435b852086e325034=9550=TEST52=20250411-01:35:27.667679369=2262=ac9dc520-fd90-4708-a92a-3ceddd7c32a3268=1279=0269=083=159755170455=BTC-USD270=3.8271=0.6197183160=20250411-01:35:27.66580440=237=e6d6b7f8-54ea-43c7-9eb3-01fe4ca6078f10=012
20250411-01:35:27.788742000 : 8=FIXT.1.19=32535=X49=Coinbase56=24ab46f784d1b20db435b852086e325034=9650=TEST52=20250411-01:35:27.667684369=2262=ac9dc520-fd90-4708-a92a-3ceddd7c32a3268=1279=0269=2278=c5b88ea9-605d-4595-ac52-f7c3f08523ba83=159755170555=BTC-USD270=3.55271=0.6197183160=20250411-01:35:27.66580437=e6d6b7f8-54ea-43c7-9eb3-01fe4ca6078f5797=110=015
20250411-01:35:27.788906000 : 8=FIXT.1.19=28735=X49=Coinbase56=24ab46f784d1b20db435b852086e325034=9750=TEST52=20250411-01:35:27.667689369=2262=ac9dc520-fd90-4708-a92a-3ceddd7c32a3268=1279=2269=0278=e6d6b7f8-54ea-43c7-9eb3-01fe4ca6078f83=159755170655=BTC-USD270=3.8271=0.0000000060=20250411-01:35:27.66580458=FILLED10=179
20250411-01:35:27.851118000 : 8=FIXT.1.19=28235=X49=Coinbase56=24ab46f784d1b20db435b852086e325034=9850=TEST52=20250411-01:35:27.725288369=2262=ac9dc520-fd90-4708-a92a-3ceddd7c32a3268=1279=0269=083=159755170755=BTC-USD270=3.86271=0.6197183160=20250411-01:35:27.72440640=237=43969d97-9ed2-47d4-b8ed-e7cad1c62c7810=027
20250411-01:35:27.851702000 : 8=FIXT.1.19=32535=X49=Coinbase56=24ab46f784d1b20db435b852086e325034=9950=TEST52=20250411-01:35:27.725297369=2262=ac9dc520-fd90-4708-a92a-3ceddd7c32a3268=1279=0269=2278=c5b88ea9-605d-4595-ac52-f7c3f08523ba83=159755170855=BTC-USD270=3.55271=0.6197183160=20250411-01:35:27.72440637=43969d97-9ed2-47d4-b8ed-e7cad1c62c785797=110=235
20250411-01:35:27.851934000 : 8=FIXT.1.19=28935=X49=Coinbase56=24ab46f784d1b20db435b852086e325034=10050=TEST52=20250411-01:35:27.725301369=2262=ac9dc520-fd90-4708-a92a-3ceddd7c32a3268=1279=2269=0278=43969d97-9ed2-47d4-b8ed-e7cad1c62c7883=159755170955=BTC-USD270=3.86271=0.0000000060=20250411-01:35:27.72440658=FILLED10=210
20250411-01:35:27.903265000 : 8=FIXT.1.19=28335=X49=Coinbase56=24ab46f784d1b20db435b852086e325034=10150=TEST52=20250411-01:35:27.781620369=2262=ac9dc520-fd90-4708-a92a-3ceddd7c32a3268=1279=0269=183=159755171055=BTC-USD270=3.22271=0.6197183160=20250411-01:35:27.78075640=237=bf0d055f-db43-44a9-ab81-f27aadefd68710=161
20250411-01:35:27.903843000 : 8=FIXT.1.19=32635=X49=Coinbase56=24ab46f784d1b20db435b852086e325034=10250=TEST52=20250411-01:35:27.781625369=2262=ac9dc520-fd90-4708-a92a-3ceddd7c32a3268=1279=0269=2278=4d60a78e-b39b-420e-b830-bc0f3f4fdde283=159755171155=BTC-USD270=3.53271=0.6197183160=20250411-01:35:27.78075637=bf0d055f-db43-44a9-ab81-f27aadefd6875797=210=254
20250411-01:35:27.904073000 : 8=FIXT.1.19=28935=X49=Coinbase56=24ab46f784d1b20db435b852086e325034=10350=TEST52=20250411-01:35:27.781629369=2262=ac9dc520-fd90-4708-a92a-3ceddd7c32a3268=1279=2269=1278=bf0d055f-db43-44a9-ab81-f27aadefd68783=159755171255=BTC-USD270=3.22271=0.0000000060=20250411-01:35:27.78075658=FILLED10=080
20250411-01:35:28.114568000 : 8=FIXT.1.19=28335=X49=Coinbase56=24ab46f784d1b20db435b852086e325034=10450=TEST52=20250411-01:35:27.993248369=2262=ac9dc520-fd90-4708-a92a-3ceddd7c32a3268=1279=0269=183=159755171355=BTC-USD270=3.54271=0.6232294660=20250411-01:35:27.99128640=237=a2fc0e05-08fa-435f-ba57-68aabc3b7b5610=123
20250411-01:35:28.115171000 : 8=FIXT.1.19=27935=X49=Coinbase56=24ab46f784d1b20db435b852086e325034=10550=TEST52=20250411-01:35:27.993254369=2262=ac9dc520-fd90-4708-a92a-3ceddd7c32a3268=1279=0269=1278=a2fc0e05-08fa-435f-ba57-68aabc3b7b5683=159755171455=BTC-USD270=3.54271=0.6232294660=20250411-01:35:27.99128610=226
20250411-01:35:28.115421000 : 8=FIXT.1.19=28335=X49=Coinbase56=24ab46f784d1b20db435b852086e325034=10650=TEST52=20250411-01:35:27.993258369=2262=ac9dc520-fd90-4708-a92a-3ceddd7c32a3268=1279=0269=183=159755171555=BTC-USD270=3.56271=0.6232294660=20250411-01:35:27.99128640=237=a9029294-7550-419b-ba46-4cd8f6ef793910=134
20250411-01:35:28.115906000 : 8=FIXT.1.19=27935=X49=Coinbase56=24ab46f784d1b20db435b852086e325034=10750=TEST52=20250411-01:35:27.993262369=2262=ac9dc520-fd90-4708-a92a-3ceddd7c32a3268=1279=0269=1278=a9029294-7550-419b-ba46-4cd8f6ef793983=159755171655=BTC-USD270=3.56271=0.6232294660=20250411-01:35:27.99128610=235
20250411-01:35:28.288149000 : 8=FIXT.1.19=27835=X49=Coinbase56=24ab46f784d1b20db435b852086e325034=10850=TEST52=20250411-01:35:28.166126369=2262=ac9dc520-fd90-4708-a92a-3ceddd7c32a3268=1279=0269=083=159755171755=BTC-USD29004=2.208895533960=20250411-01:35:28.16485440=137=8720164e-9d43-4fc4-9c89-dfe932e5d54610=228
20250411-01:35:28.288688000 : 8=FIXT.1.19=32635=X49=Coinbase56=24ab46f784d1b20db435b852086e325034=10950=TEST52=20250411-01:35:28.166131369=2262=ac9dc520-fd90-4708-a92a-3ceddd7c32a3268=1279=0269=2278=a2fc0e05-08fa-435f-ba57-68aabc3b7b5683=159755171855=BTC-USD270=3.54271=0.6232294660=20250411-01:35:28.16485437=8720164e-9d43-4fc4-9c89-dfe932e5d5465797=110=245
20250411-01:35:28.288874000 : 8=FIXT.1.19=28935=X49=Coinbase56=24ab46f784d1b20db435b852086e325034=11050=TEST52=20250411-01:35:28.166135369=2262=ac9dc520-fd90-4708-a92a-3ceddd7c32a3268=1279=2269=1278=a2fc0e05-08fa-435f-ba57-68aabc3b7b5683=159755171955=BTC-USD270=3.54271=0.0000000060=20250411-01:35:28.16485458=FILLED10=016
20250411-01:35:28.290258000 : 8=FIXT.1.19=32635=X49=Coinbase56=24ab46f784d1b20db435b852086e325034=11150=TEST52=20250411-01:35:28.166139369=2262=ac9dc520-fd90-4708-a92a-3ceddd7c32a3268=1279=0269=2278=c5b88ea9-605d-4595-ac52-f7c3f08523ba83=159755172055=BTC-USD270=3.55271=0.0007502160=20250411-01:35:28.16485437=8720164e-9d43-4fc4-9c89-dfe932e5d5465797=110=097
20250411-01:35:28.290440000 : 8=FIXT.1.19=26535=X49=Coinbase56=24ab46f784d1b20db435b852086e325034=11250=TEST52=20250411-01:35:28.166142369=2262=ac9dc520-fd90-4708-a92a-3ceddd7c32a3268=1279=2269=0278=8720164e-9d43-4fc4-9c89-dfe932e5d54683=159755172155=BTC-USD60=20250411-01:35:28.16485458=FILLED10=228
20250411-01:35:28.315153000 : 8=FIXT.1.19=27435=X49=Coinbase56=24ab46f784d1b20db435b852086e325034=11350=TEST52=20250411-01:35:28.193906369=2262=ac9dc520-fd90-4708-a92a-3ceddd7c32a3268=1279=0269=183=159755172255=BTC-USD271=0.6232294660=20250411-01:35:28.19250240=137=6603466b-92bd-4b80-9fc7-a0bfaa49161110=010
20250411-01:35:28.315662000 : 8=FIXT.1.19=32635=X49=Coinbase56=24ab46f784d1b20db435b852086e325034=11450=TEST52=20250411-01:35:28.193915369=2262=ac9dc520-fd90-4708-a92a-3ceddd7c32a3268=1279=0269=2278=4d60a78e-b39b-420e-b830-bc0f3f4fdde283=159755172355=BTC-USD270=3.53271=0.6232294660=20250411-01:35:28.19250237=6603466b-92bd-4b80-9fc7-a0bfaa4916115797=210=255
20250411-01:35:28.315928000 : 8=FIXT.1.19=28035=X49=Coinbase56=24ab46f784d1b20db435b852086e325034=11550=TEST52=20250411-01:35:28.193920369=2262=ac9dc520-fd90-4708-a92a-3ceddd7c32a3268=1279=2269=1278=6603466b-92bd-4b80-9fc7-a0bfaa49161183=159755172455=BTC-USD271=0.0000000060=20250411-01:35:28.19250258=FILLED10=166
20250411-01:35:28.343804000 : 8=FIXT.1.19=27835=X49=Coinbase56=24ab46f784d1b20db435b852086e325034=11650=TEST52=20250411-01:35:28.222355369=2262=ac9dc520-fd90-4708-a92a-3ceddd7c32a3268=1279=0269=083=159755172555=BTC-USD29004=2.208895519560=20250411-01:35:28.22100440=137=dcea22c6-923b-4282-80be-b1ed6e40b26010=045
20250411-01:35:28.344401000 : 8=FIXT.1.19=32635=X49=Coinbase56=24ab46f784d1b20db435b852086e325034=11750=TEST52=20250411-01:35:28.222362369=2262=ac9dc520-fd90-4708-a92a-3ceddd7c32a3268=1279=0269=2278=c5b88ea9-605d-4595-ac52-f7c3f08523ba83=159755172655=BTC-USD270=3.55271=0.6222240960=20250411-01:35:28.22100437=dcea22c6-923b-4282-80be-b1ed6e40b2605797=110=190
20250411-01:35:28.344660000 : 8=FIXT.1.19=26535=X49=Coinbase56=24ab46f784d1b20db435b852086e325034=11850=TEST52=20250411-01:35:28.222366369=2262=ac9dc520-fd90-4708-a92a-3ceddd7c32a3268=1279=2269=0278=dcea22c6-923b-4282-80be-b1ed6e40b26083=159755172755=BTC-USD60=20250411-01:35:28.22100458=FILLED10=063
20250411-01:35:28.372065000 : 8=FIXT.1.19=27435=X49=Coinbase56=24ab46f784d1b20db435b852086e325034=11950=TEST52=20250411-01:35:28.251279369=2262=ac9dc520-fd90-4708-a92a-3ceddd7c32a3268=1279=0269=183=159755172855=BTC-USD271=0.6197183160=20250411-01:35:28.24964940=137=f192b964-b738-412c-8006-82265447ca2310=061
20250411-01:35:28.372540000 : 8=FIXT.1.19=32635=X49=Coinbase56=24ab46f784d1b20db435b852086e325034=12050=TEST52=20250411-01:35:28.251287369=2262=ac9dc520-fd90-4708-a92a-3ceddd7c32a3268=1279=0269=2278=4d60a78e-b39b-420e-b830-bc0f3f4fdde283=159755172955=BTC-USD270=3.53271=0.6197183160=20250411-01:35:28.24964937=f192b964-b738-412c-8006-82265447ca235797=210=040
20250411-01:35:28.372942000 : 8=FIXT.1.19=28035=X49=Coinbase56=24ab46f784d1b20db435b852086e325034=12150=TEST52=20250411-01:35:28.251291369=2262=ac9dc520-fd90-4708-a92a-3ceddd7c32a3268=1279=2269=1278=f192b964-b738-412c-8006-82265447ca2383=159755173055=BTC-USD271=0.0000000060=20250411-01:35:28.24964958=FILLED10=195
20250411-01:35:28.684226000 : 8=FIXT.1.19=28335=X49=Coinbase56=24ab46f784d1b20db435b852086e325034=12250=TEST52=20250411-01:35:28.563592369=2262=ac9dc520-fd90-4708-a92a-3ceddd7c32a3268=1279=0269=083=159755173155=BTC-USD270=3.49271=0.6232294660=20250411-01:35:28.56199540=237=4da62911-fff3-47db-8d18-b789dfb6102010=253
20250411-01:35:28.684900000 : 8=FIXT.1.19=27935=X49=Coinbase56=24ab46f784d1b20db435b852086e325034=12350=TEST52=20250411-01:35:28.563600369=2262=ac9dc520-fd90-4708-a92a-3ceddd7c32a3268=1279=0269=0278=4da62911-fff3-47db-8d18-b789dfb6102083=159755173255=BTC-USD270=3.49271=0.6232294660=20250411-01:35:28.56199510=093
20250411-01:35:28.685203000 : 8=FIXT.1.19=28335=X49=Coinbase56=24ab46f784d1b20db435b852086e325034=12450=TEST52=20250411-01:35:28.563604369=2262=ac9dc520-fd90-4708-a92a-3ceddd7c32a3268=1279=0269=083=159755173355=BTC-USD270=3.36271=0.6232294660=20250411-01:35:28.56199540=237=883393d9-ddab-4d23-9273-95fdf9313be210=212
20250411-01:35:28.685395000 : 8=FIXT.1.19=27935=X49=Coinbase56=24ab46f784d1b20db435b852086e325034=12550=TEST52=20250411-01:35:28.563608369=2262=ac9dc520-fd90-4708-a92a-3ceddd7c32a3268=1279=0269=0278=883393d9-ddab-4d23-9273-95fdf9313be283=159755173455=BTC-USD270=3.36271=0.6232294660=20250411-01:35:28.56199510=066
20250411-01:35:28.877460000 : 8=FIXT.1.19=28335=X49=Coinbase56=24ab46f784d1b20db435b852086e325034=12650=TEST52=20250411-01:35:28.755234369=2262=ac9dc520-fd90-4708-a92a-3ceddd7c32a3268=1279=0269=183=159755173555=BTC-USD270=3.22271=0.6232294660=20250411-01:35:28.75367540=237=107e8c68-eb54-4112-939e-732b6b61786310=014
20250411-01:35:28.877975000 : 8=FIXT.1.19=32635=X49=Coinbase56=24ab46f784d1b20db435b852086e325034=12750=TEST52=20250411-01:35:28.755247369=2262=ac9dc520-fd90-4708-a92a-3ceddd7c32a3268=1279=0269=2278=4d60a78e-b39b-420e-b830-bc0f3f4fdde283=159755173655=BTC-USD270=3.53271=0.6232294660=20250411-01:35:28.75367537=107e8c68-eb54-4112-939e-732b6b6178635797=210=106
20250411-01:35:28.879301000 : 8=FIXT.1.19=28935=X49=Coinbase56=24ab46f784d1b20db435b852086e325034=12850=TEST52=20250411-01:35:28.755251369=2262=ac9dc520-fd90-4708-a92a-3ceddd7c32a3268=1279=2269=1278=107e8c68-eb54-4112-939e-732b6b61786383=159755173755=BTC-USD270=3.22271=0.0000000060=20250411-01:35:28.75367558=FILLED10=181
20250411-01:35:28.930651000 : 8=FIXT.1.19=28335=X49=Coinbase56=24ab46f784d1b20db435b852086e325034=12950=TEST52=20250411-01:35:28.810317369=2262=ac9dc520-fd90-4708-a92a-3ceddd7c32a3268=1279=0269=083=159755173855=BTC-USD270=3.79271=0.6232294660=20250411-01:35:28.80903440=237=9c182ddf-2a78-4956-96fd-6028415e4d8710=129
20250411-01:35:28.930864000 : 8=FIXT.1.19=32635=X49=Coinbase56=24ab46f784d1b20db435b852086e325034=13050=TEST52=20250411-01:35:28.810327369=2262=ac9dc520-fd90-4708-a92a-3ceddd7c32a3268=1279=0269=2278=c5b88ea9-605d-4595-ac52-f7c3f08523ba83=159755173955=BTC-USD270=3.55271=0.6232294660=20250411-01:35:28.80903437=9c182ddf-2a78-4956-96fd-6028415e4d875797=110=071
20250411-01:35:28.931106000 : 8=FIXT.1.19=28935=X49=Coinbase56=24ab46f784d1b20db435b852086e325034=13150=TEST52=20250411-01:35:28.810331369=2262=ac9dc520-fd90-4708-a92a-3ceddd7c32a3268=1279=2269=0278=9c182ddf-2a78-4956-96fd-6028415e4d8783=159755174055=BTC-USD270=3.79271=0.0000000060=20250411-01:35:28.80903458=FILLED10=019
20250411-01:35:28.975340000 : 8=FIXT.1.19=27835=X49=Coinbase56=24ab46f784d1b20db435b852086e325034=13250=TEST52=20250411-01:35:28.852010369=2262=ac9dc520-fd90-4708-a92a-3ceddd7c32a3268=1279=0269=083=159755174155=BTC-USD29004=2.208895519560=20250411-01:35:28.85064440=137=be62c1fe-6f6e-4e4d-807f-4a2d6ea290c110=171
20250411-01:35:28.977118000 : 8=FIXT.1.19=32635=X49=Coinbase56=24ab46f784d1b20db435b852086e325034=13350=TEST52=20250411-01:35:28.852084369=2262=ac9dc520-fd90-4708-a92a-3ceddd7c32a3268=1279=0269=2278=c5b88ea9-605d-4595-ac52-f7c3f08523ba83=159755174255=BTC-USD270=3.55271=0.6222240960=20250411-01:35:28.85064437=be62c1fe-6f6e-4e4d-807f-4a2d6ea290c15797=110=073
20250411-01:35:28.977407000 : 8=FIXT.1.19=26535=X49=Coinbase56=24ab46f784d1b20db435b852086e325034=13450=TEST52=20250411-01:35:28.852093369=2262=ac9dc520-fd90-4708-a92a-3ceddd7c32a3268=1279=2269=0278=be62c1fe-6f6e-4e4d-807f-4a2d6ea290c183=159755174355=BTC-USD60=20250411-01:35:28.85064458=FILLED10=198
20250411-01:35:29.027076000 : 8=FIXT.1.19=27435=X49=Coinbase56=24ab46f784d1b20db435b852086e325034=13550=TEST52=20250411-01:35:28.879039369=2262=ac9dc520-fd90-4708-a92a-3ceddd7c32a3268=1279=0269=183=159755174455=BTC-USD271=0.6197183160=20250411-01:35:28.87797240=137=6846eb28-a6f1-450d-9298-94ae8128355010=138
20250411-01:35:29.027746000 : 8=FIXT.1.19=32635=X49=Coinbase56=24ab46f784d1b20db435b852086e325034=13650=TEST52=20250411-01:35:28.879045369=2262=ac9dc520-fd90-4708-a92a-3ceddd7c32a3268=1279=0269=2278=4d60a78e-b39b-420e-b830-bc0f3f4fdde283=159755174555=BTC-USD270=3.53271=0.6197183160=20250411-01:35:28.87797237=6846eb28-a6f1-450d-9298-94ae812835505797=210=124
20250411-01:35:29.027965000 : 8=FIXT.1.19=28035=X49=Coinbase56=24ab46f784d1b20db435b852086e325034=13750=TEST52=20250411-01:35:28.879049369=2262=ac9dc520-fd90-4708-a92a-3ceddd7c32a3268=1279=2269=1278=6846eb28-a6f1-450d-9298-94ae8128355083=159755174655=BTC-USD271=0.0000000060=20250411-01:35:28.87797258=FILLED10=041
20250411-01:35:29.138615000 : 8=FIXT.1.19=27835=X49=Coinbase56=24ab46f784d1b20db435b852086e325034=13850=TEST52=20250411-01:35:28.964588369=2262=ac9dc520-fd90-4708-a92a-3ceddd7c32a3268=1279=0269=083=159755174755=BTC-USD29004=2.208895519560=20250411-01:35:28.96366740=137=a61e7a74-ed8f-4fcf-81e8-788fc4161ee010=190
20250411-01:35:29.139230000 : 8=FIXT.1.19=32635=X49=Coinbase56=24ab46f784d1b20db435b852086e325034=13950=TEST52=20250411-01:35:28.964594369=2262=ac9dc520-fd90-4708-a92a-3ceddd7c32a3268=1279=0269=2278=c5b88ea9-605d-4595-ac52-f7c3f08523ba83=159755174855=BTC-USD270=3.55271=0.6222240960=20250411-01:35:28.96366737=a61e7a74-ed8f-4fcf-81e8-788fc4161ee05797=110=078
20250411-01:35:29.139709000 : 8=FIXT.1.19=26535=X49=Coinbase56=24ab46f784d1b20db435b852086e325034=14050=TEST52=20250411-01:35:28.964599369=2262=ac9dc520-fd90-4708-a92a-3ceddd7c32a3268=1279=2269=0278=a61e7a74-ed8f-4fcf-81e8-788fc4161ee083=159755174955=BTC-USD60=20250411-01:35:28.96366758=FILLED10=199
20250411-01:35:29.141061000 : 8=FIXT.1.19=27435=X49=Coinbase56=24ab46f784d1b20db435b852086e325034=14150=TEST52=20250411-01:35:28.995949369=2262=ac9dc520-fd90-4708-a92a-3ceddd7c32a3268=1279=0269=183=159755175055=BTC-USD271=0.6232294660=20250411-01:35:28.99401140=137=3f360e70-ddcb-42c9-ae89-98ad29cb2f7a10=242
20250411-01:35:29.141559000 : 8=FIXT.1.19=32635=X49=Coinbase56=24ab46f784d1b20db435b852086e325034=14250=TEST52=20250411-01:35:28.995954369=2262=ac9dc520-fd90-4708-a92a-3ceddd7c32a3268=1279=0269=2278=4d60a78e-b39b-420e-b830-bc0f3f4fdde283=159755175155=BTC-USD270=3.53271=0.6232294660=20250411-01:35:28.99401137=3f360e70-ddcb-42c9-ae89-98ad29cb2f7a5797=210=227
20250411-01:35:29.141738000 : 8=FIXT.1.19=28035=X49=Coinbase56=24ab46f784d1b20db435b852086e325034=14350=TEST52=20250411-01:35:28.995957369=2262=ac9dc520-fd90-4708-a92a-3ceddd7c32a3268=1279=2269=1278=3f360e70-ddcb-42c9-ae89-98ad29cb2f7a83=159755175255=BTC-USD271=0.0000000060=20250411-01:35:28.99401158=FILLED10=145
20250411-01:35:29.201629000 : 8=FIXT.1.19=27835=X49=Coinbase56=24ab46f784d1b20db435b852086e325034=14450=TEST52=20250411-01:35:29.080127369=2262=ac9dc520-fd90-4708-a92a-3ceddd7c32a3268=1279=0269=083=159755175355=BTC-USD29004=2.208895519560=20250411-01:35:29.07840940=137=01a08bd0-600b-4a4b-97a3-ba7ac71934ae10=056
20250411-01:35:29.202083000 : 8=FIXT.1.19=32635=X49=Coinbase56=24ab46f784d1b20db435b852086e325034=14550=TEST52=20250411-01:35:29.080141369=2262=ac9dc520-fd90-4708-a92a-3ceddd7c32a3268=1279=0269=2278=c5b88ea9-605d-4595-ac52-f7c3f08523ba83=159755175455=BTC-USD270=3.55271=0.6222240960=20250411-01:35:29.07840937=01a08bd0-600b-4a4b-97a3-ba7ac71934ae5797=110=199
20250411-01:35:29.202592000 : 8=FIXT.1.19=26535=X49=Coinbase56=24ab46f784d1b20db435b852086e325034=14650=TEST52=20250411-01:35:29.080145369=2262=ac9dc520-fd90-4708-a92a-3ceddd7c32a3268=1279=2269=0278=01a08bd0-600b-4a4b-97a3-ba7ac71934ae83=159755175555=BTC-USD60=20250411-01:35:29.07840958=FILLED10=072
20250411-01:35:29.228887000 : 8=FIXT.1.19=27435=X49=Coinbase56=24ab46f784d1b20db435b852086e325034=14750=TEST52=20250411-01:35:29.108140369=2262=ac9dc520-fd90-4708-a92a-3ceddd7c32a3268=1279=0269=183=159755175655=BTC-USD271=0.6232294660=20250411-01:35:29.10642840=137=25dc67bd-9c57-4715-b26f-5a67d24ed6ee10=132
20250411-01:35:29.229291000 : 8=FIXT.1.19=32635=X49=Coinbase56=24ab46f784d1b20db435b852086e325034=14850=TEST52=20250411-01:35:29.108147369=2262=ac9dc520-fd90-4708-a92a-3ceddd7c32a3268=1279=0269=2278=4d60a78e-b39b-420e-b830-bc0f3f4fdde283=159755175755=BTC-USD270=3.53271=0.6232294660=20250411-01:35:29.10642837=25dc67bd-9c57-4715-b26f-5a67d24ed6ee5797=210=128
20250411-01:35:29.229902000 : 8=FIXT.1.19=28035=X49=Coinbase56=24ab46f784d1b20db435b852086e325034=14950=TEST52=20250411-01:35:29.108150369=2262=ac9dc520-fd90-4708-a92a-3ceddd7c32a3268=1279=2269=1278=25dc67bd-9c57-4715-b26f-5a67d24ed6ee83=159755175855=BTC-USD271=0.0000000060=20250411-01:35:29.10642858=FILLED10=037
20250411-01:35:29.431382000 : 8=FIXT.1.19=27835=X49=Coinbase56=24ab46f784d1b20db435b852086e325034=15050=TEST52=20250411-01:35:29.308683369=2262=ac9dc520-fd90-4708-a92a-3ceddd7c32a3268=1279=0269=083=159755175955=BTC-USD29004=2.208895519560=20250411-01:35:29.30751640=137=6afbfb3f-d568-4601-ad4b-15a6d0561a5310=079
20250411-01:35:29.432403000 : 8=FIXT.1.19=32635=X49=Coinbase56=24ab46f784d1b20db435b852086e325034=15150=TEST52=20250411-01:35:29.308690369=2262=ac9dc520-fd90-4708-a92a-3ceddd7c32a3268=1279=0269=2278=c5b88ea9-605d-4595-ac52-f7c3f08523ba83=159755176055=BTC-USD270=3.55271=0.6222240960=20250411-01:35:29.30751637=6afbfb3f-d568-4601-ad4b-15a6d0561a535797=110=215
20250411-01:35:29.432719000 : 8=FIXT.1.19=26535=X49=Coinbase56=24ab46f784d1b20db435b852086e325034=15250=TEST52=20250411-01:35:29.308694369=2262=ac9dc520-fd90-4708-a92a-3ceddd7c32a3268=1279=2269=0278=6afbfb3f-d568-4601-ad4b-15a6d0561a5383=159755176155=BTC-USD60=20250411-01:35:29.30751658=FILLED10=088
20250411-01:35:29.461033000 : 8=FIXT.1.19=27435=X49=Coinbase56=24ab46f784d1b20db435b852086e325034=15350=TEST52=20250411-01:35:29.337488369=2262=ac9dc520-fd90-4708-a92a-3ceddd7c32a3268=1279=0269=183=159755176255=BTC-USD271=0.6232294660=20250411-01:35:29.33607340=137=692f7ea9-be06-4166-be59-0d502007a64210=193
20250411-01:35:29.462000000 : 8=FIXT.1.19=32635=X49=Coinbase56=24ab46f784d1b20db435b852086e325034=15450=TEST52=20250411-01:35:29.337495369=2262=ac9dc520-fd90-4708-a92a-3ceddd7c32a3268=1279=0269=2278=4d60a78e-b39b-420e-b830-bc0f3f4fdde283=159755176355=BTC-USD270=3.53271=0.6232294660=20250411-01:35:29.33607337=692f7ea9-be06-4166-be59-0d502007a6425797=210=180
20250411-01:35:29.462383000 : 8=FIXT.1.19=28035=X49=Coinbase56=24ab46f784d1b20db435b852086e325034=15550=TEST52=20250411-01:35:29.337499369=2262=ac9dc520-fd90-4708-a92a-3ceddd7c32a3268=1279=2269=1278=692f7ea9-be06-4166-be59-0d502007a64283=159755176455=BTC-USD271=0.0000000060=20250411-01:35:29.33607358=FILLED10=099
20250411-01:35:29.600141000 : 8=FIXT.1.19=27835=X49=Coinbase56=24ab46f784d1b20db435b852086e325034=15650=TEST52=20250411-01:35:29.479090369=2262=ac9dc520-fd90-4708-a92a-3ceddd7c32a3268=1279=0269=083=159755176555=BTC-USD29004=2.208895519560=20250411-01:35:29.47791340=137=0454f4b3-f927-4a27-8815-8d6edb096ed210=232
20250411-01:35:29.600771000 : 8=FIXT.1.19=32635=X49=Coinbase56=24ab46f784d1b20db435b852086e325034=15750=TEST52=20250411-01:35:29.479101369=2262=ac9dc520-fd90-4708-a92a-3ceddd7c32a3268=1279=0269=2278=c5b88ea9-605d-4595-ac52-f7c3f08523ba83=159755176655=BTC-USD270=3.55271=0.6222240960=20250411-01:35:29.47791337=0454f4b3-f927-4a27-8815-8d6edb096ed25797=110=116
20250411-01:35:29.601190000 : 8=FIXT.1.19=26535=X49=Coinbase56=24ab46f784d1b20db435b852086e325034=15850=TEST52=20250411-01:35:29.479106369=2262=ac9dc520-fd90-4708-a92a-3ceddd7c32a3268=1279=2269=0278=0454f4b3-f927-4a27-8815-8d6edb096ed283=159755176755=BTC-USD60=20250411-01:35:29.47791358=FILLED10=246
20250411-01:35:29.629817000 : 8=FIXT.1.19=27435=X49=Coinbase56=24ab46f784d1b20db435b852086e325034=15950=TEST52=20250411-01:35:29.508112369=2262=ac9dc520-fd90-4708-a92a-3ceddd7c32a3268=1279=0269=183=159755176855=BTC-USD271=0.6232294660=20250411-01:35:29.50641040=137=3d5eae77-de9f-4fe0-ab95-9536df86df4210=244
20250411-01:35:29.630029000 : 8=FIXT.1.19=32635=X49=Coinbase56=24ab46f784d1b20db435b852086e325034=16050=TEST52=20250411-01:35:29.508118369=2262=ac9dc520-fd90-4708-a92a-3ceddd7c32a3268=1279=0269=2278=4d60a78e-b39b-420e-b830-bc0f3f4fdde283=159755176955=BTC-USD270=3.53271=0.6232294660=20250411-01:35:29.50641037=3d5eae77-de9f-4fe0-ab95-9536df86df425797=210=230
20250411-01:35:29.630196000 : 8=FIXT.1.19=28035=X49=Coinbase56=24ab46f784d1b20db435b852086e325034=16150=TEST52=20250411-01:35:29.508122369=2262=ac9dc520-fd90-4708-a92a-3ceddd7c32a3268=1279=2269=1278=3d5eae77-de9f-4fe0-ab95-9536df86df4283=159755177055=BTC-USD271=0.0000000060=20250411-01:35:29.50641058=FILLED10=131
20250411-01:35:29.944156000 : 8=FIXT.1.19=27835=X49=Coinbase56=24ab46f784d1b20db435b852086e325034=16250=TEST52=20250411-01:35:29.822277369=2262=ac9dc520-fd90-4708-a92a-3ceddd7c32a3268=1279=0269=083=159755177155=BTC-USD29004=2.208895519560=20250411-01:35:29.82105640=137=80b0922c-6484-4cd7-99e6-e0d3564e40c410=163
20250411-01:35:29.945254000 : 8=FIXT.1.19=32635=X49=Coinbase56=24ab46f784d1b20db435b852086e325034=16350=TEST52=20250411-01:35:29.822290369=2262=ac9dc520-fd90-4708-a92a-3ceddd7c32a3268=1279=0269=2278=c5b88ea9-605d-4595-ac52-f7c3f08523ba83=159755177255=BTC-USD270=3.55271=0.6222240960=20250411-01:35:29.82105637=80b0922c-6484-4cd7-99e6-e0d3564e40c45797=110=049
20250411-01:35:29.946289000 : 8=FIXT.1.19=26535=X49=Coinbase56=24ab46f784d1b20db435b852086e325034=16450=TEST52=20250411-01:35:29.822295369=2262=ac9dc520-fd90-4708-a92a-3ceddd7c32a3268=1279=2269=0278=80b0922c-6484-4cd7-99e6-e0d3564e40c483=159755177355=BTC-USD60=20250411-01:35:29.82105658=FILLED10=179
20250411-01:35:29.972182000 : 8=FIXT.1.19=27435=X49=Coinbase56=24ab46f784d1b20db435b852086e325034=16550=TEST52=20250411-01:35:29.850971369=2262=ac9dc520-fd90-4708-a92a-3ceddd7c32a3268=1279=0269=183=159755177455=BTC-USD271=0.6232294660=20250411-01:35:29.84957740=137=d2ebc371-95fe-48e7-9ce9-d08fbfae3a0d10=101
20250411-01:35:29.973353000 : 8=FIXT.1.19=32635=X49=Coinbase56=24ab46f784d1b20db435b852086e325034=16650=TEST52=20250411-01:35:29.850978369=2262=ac9dc520-fd90-4708-a92a-3ceddd7c32a3268=1279=0269=2278=4d60a78e-b39b-420e-b830-bc0f3f4fdde283=159755177555=BTC-USD270=3.53271=0.6232294660=20250411-01:35:29.84957737=d2ebc371-95fe-48e7-9ce9-d08fbfae3a0d5797=210=097
20250411-01:35:29.973956000 : 8=FIXT.1.19=28035=X49=Coinbase56=24ab46f784d1b20db435b852086e325034=16750=TEST52=20250411-01:35:29.850982369=2262=ac9dc520-fd90-4708-a92a-3ceddd7c32a3268=1279=2269=1278=d2ebc371-95fe-48e7-9ce9-d08fbfae3a0d83=159755177655=BTC-USD271=0.0000000060=20250411-01:35:29.84957758=FILLED10=007
20250411-01:35:30.002828000 : 8=FIXT.1.19=27835=X49=Coinbase56=24ab46f784d1b20db435b852086e325034=16850=TEST52=20250411-01:35:29.881584369=2262=ac9dc520-fd90-4708-a92a-3ceddd7c32a3268=1279=0269=083=159755177755=BTC-USD29004=2.208895519560=20250411-01:35:29.87988340=137=8ac6e832-5eab-4738-95fc-b4b6938c991210=056
20250411-01:35:30.003836000 : 8=FIXT.1.19=32635=X49=Coinbase56=24ab46f784d1b20db435b852086e325034=16950=TEST52=20250411-01:35:29.881590369=2262=ac9dc520-fd90-4708-a92a-3ceddd7c32a3268=1279=0269=2278=c5b88ea9-605d-4595-ac52-f7c3f08523ba83=159755177855=BTC-USD270=3.55271=0.6222240960=20250411-01:35:29.87988337=8ac6e832-5eab-4738-95fc-b4b6938c99125797=110=200
20250411-01:35:30.011586000 : 8=FIXT.1.19=26535=X49=Coinbase56=24ab46f784d1b20db435b852086e325034=17050=TEST52=20250411-01:35:29.881593369=2262=ac9dc520-fd90-4708-a92a-3ceddd7c32a3268=1279=2269=0278=8ac6e832-5eab-4738-95fc-b4b6938c991283=159755177955=BTC-USD60=20250411-01:35:29.87988358=FILLED10=063
20250411-01:35:30.018858000 : 8=FIXT.1.19=28335=X49=Coinbase56=24ab46f784d1b20db435b852086e325034=17150=TEST52=20250411-01:35:29.898128369=2262=ac9dc520-fd90-4708-a92a-3ceddd7c32a3268=1279=0269=183=159755178055=BTC-USD270=3.35271=0.6197183160=20250411-01:35:29.89636340=237=8e96492f-6b48-4fce-a569-52feeb8ccbbc10=223
20250411-01:35:30.019228000 : 8=FIXT.1.19=32635=X49=Coinbase56=24ab46f784d1b20db435b852086e325034=17250=TEST52=20250411-01:35:29.898137369=2262=ac9dc520-fd90-4708-a92a-3ceddd7c32a3268=1279=0269=2278=4d60a78e-b39b-420e-b830-bc0f3f4fdde283=159755178155=BTC-USD270=3.53271=0.6197183160=20250411-01:35:29.89636337=8e96492f-6b48-4fce-a569-52feeb8ccbbc5797=210=051
20250411-01:35:30.020371000 : 8=FIXT.1.19=28935=X49=Coinbase56=24ab46f784d1b20db435b852086e325034=17350=TEST52=20250411-01:35:29.898141369=2262=ac9dc520-fd90-4708-a92a-3ceddd7c32a3268=1279=2269=1278=8e96492f-6b48-4fce-a569-52feeb8ccbbc83=159755178255=BTC-USD270=3.35271=0.0000000060=20250411-01:35:29.89636358=FILLED10=128
20250411-01:35:30.030187000 : 8=FIXT.1.19=27435=X49=Coinbase56=24ab46f784d1b20db435b852086e325034=17450=TEST52=20250411-01:35:29.909383369=2262=ac9dc520-fd90-4708-a92a-3ceddd7c32a3268=1279=0269=183=159755178355=BTC-USD271=0.6197183160=20250411-01:35:29.90805040=137=83b72f30-8930-4424-9877-c6f33374818910=246
20250411-01:35:30.031050000 : 8=FIXT.1.19=32635=X49=Coinbase56=24ab46f784d1b20db435b852086e325034=17550=TEST52=20250411-01:35:29.909387369=2262=ac9dc520-fd90-4708-a92a-3ceddd7c32a3268=1279=0269=2278=4d60a78e-b39b-420e-b830-bc0f3f4fdde283=159755178455=BTC-USD270=3.53271=0.6197183160=20250411-01:35:29.90805037=83b72f30-8930-4424-9877-c6f3337481895797=210=239
20250411-01:35:30.031502000 : 8=FIXT.1.19=28035=X49=Coinbase56=24ab46f784d1b20db435b852086e325034=17650=TEST52=20250411-01:35:29.909391369=2262=ac9dc520-fd90-4708-a92a-3ceddd7c32a3268=1279=2269=1278=83b72f30-8930-4424-9877-c6f33374818983=159755178555=BTC-USD271=0.0000000060=20250411-01:35:29.90805058=FILLED10=147
20250411-01:35:30.074385000 : 8=FIXT.1.19=28335=X49=Coinbase56=24ab46f784d1b20db435b852086e325034=17750=TEST52=20250411-01:35:29.953401369=2262=ac9dc520-fd90-4708-a92a-3ceddd7c32a3268=1279=0269=083=159755178655=BTC-USD270=3.88271=0.6197183160=20250411-01:35:29.95191540=237=86c1a369-f850-42ba-bd5d-3862b874546c10=175
20250411-01:35:30.074995000 : 8=FIXT.1.19=32635=X49=Coinbase56=24ab46f784d1b20db435b852086e325034=17850=TEST52=20250411-01:35:29.953406369=2262=ac9dc520-fd90-4708-a92a-3ceddd7c32a3268=1279=0269=2278=c5b88ea9-605d-4595-ac52-f7c3f08523ba83=159755178755=BTC-USD270=3.55271=0.6197183160=20250411-01:35:29.95191537=86c1a369-f850-42ba-bd5d-3862b874546c5797=110=130
20250411-01:35:30.075587000 : 8=FIXT.1.19=28935=X49=Coinbase56=24ab46f784d1b20db435b852086e325034=17950=TEST52=20250411-01:35:29.953411369=2262=ac9dc520-fd90-4708-a92a-3ceddd7c32a3268=1279=2269=0278=86c1a369-f850-42ba-bd5d-3862b874546c83=159755178855=BTC-USD270=3.88271=0.0000000060=20250411-01:35:29.95191558=FILLED10=086
20250411-01:35:30.185989000 : 8=FIXT.1.19=91835=W49=Coinbase56=24ab46f784d1b20db435b852086e325034=18050=TEST52=20250411-01:35:30.065178369=2262=ac9dc520-fd90-4708-a92a-3ceddd7c32a383=1597551788893=N55=BTC-USD1682=full_trading268=10269=0278=4d60a78e-b39b-420e-b830-bc0f3f4fdde2270=3.53271=258549.78366437269=0278=9d9353ab-229f-423a-89a3-c52a46543bc9270=3.53271=18127.30103418269=0278=4da62911-fff3-47db-8d18-b789dfb61020270=3.49271=0.62322946269=0278=f5fc5e68-a52c-44d3-87ef-3785312f4782270=3.48271=0.29310888269=0278=dcccb470-c535-433a-9198-4e2b4c26d99d270=3.47271=0.29311495269=0278=f05d9766-970d-44ca-aa4d-e8b2720bbda8270=3.46271=0.29026870269=0278=911afd4c-2c13-4fb7-a980-efb8f5115621270=3.46271=0.44989377269=0278=2c4d7d5a-33aa-4058-b546-480b6a2168a4270=3.44271=0.29828577269=0278=37dbcf16-0b3d-4f67-bc90-e36268b99e0e270=3.42271=0.30270947269=0278=4c63c0b7-30e0-4ef1-931f-0090359f978e270=3.41271=0.3215896210=135
20250411-01:35:30.189154000 : 8=FIXT.1.19=14135=334=349=24ab46f784d1b20db435b852086e325052=20250411-01:35:30.18856=Coinbase45=18058=Tag appears more than once371=269372=W373=1310=250
20250411-01:35:30.189335000 : 8=FIXT.1.19=90935=W49=Coinbase56=24ab46f784d1b20db435b852086e325034=18150=TEST52=20250411-01:35:30.065419369=2262=ac9dc520-fd90-4708-a92a-3ceddd7c32a383=1597551788893=N55=BTC-USD1682=full_trading268=10269=0278=d6b4aa4e-d588-4c96-83aa-8e8d8accb1a4270=3.41271=0.30121104269=0278=e8b3d8da-1663-413c-b7fb-6aba23b01440270=3.39271=0.31006477269=0278=bcbe17c3-9059-4c38-8ab8-8e78f1ef9062270=3.38271=0.32617981269=0278=57bb77fd-337f-49bc-a56f-a4e2dff851ee270=3.37271=0.31071676269=0278=883393d9-ddab-4d23-9273-95fdf9313be2270=3.36271=0.62322946269=0278=ded4b51d-349f-4726-8379-6761a3576bb6270=3.33271=0.31560513269=0278=ff7aff09-38de-47ac-a3cb-9beacb0b9ad8270=3.33271=0.30682342269=0278=d1da558a-e9d2-4e11-b26e-1eb80a1a34c5270=3.32271=0.31700685269=0278=9ee34527-d4d8-4659-b2ea-cdff3dc4a8fa270=3.32271=0.32181951269=0278=7abf2220-0421-460f-9dbb-14c41564e41a270=3.32271=0.3130843610=254
20250411-01:35:30.190325000 : 8=FIXT.1.19=14135=334=449=24ab46f784d1b20db435b852086e325052=20250411-01:35:30.18956=Coinbase45=18158=Tag appears more than once371=269372=W373=1310=253
20250411-01:35:30.190421000 : 8=FIXT.1.19=90935=W49=Coinbase56=24ab46f784d1b20db435b852086e325034=18250=TEST52=20250411-01:35:30.065669369=2262=ac9dc520-fd90-4708-a92a-3ceddd7c32a383=1597551788893=N55=BTC-USD1682=full_trading268=10269=0278=69634ec5-f71a-4990-b56d-13c3069a455a270=3.31271=0.32329458269=0278=2f333c17-a386-4d52-8ff1-eadcb99bc22f270=3.31271=0.31999220269=0278=f02efc37-0b1e-470b-99ef-e31012887d73270=3.30271=0.32771570269=0278=6d430950-8078-4987-8995-e581564e368d270=3.29271=0.30702763269=0278=841f895a-cd2d-4082-9a37-b50fc19e35bf270=3.28271=0.32610801269=0278=3cf93093-e42b-4c24-95ea-c367d96427fe270=3.27271=0.33588654269=0278=f29c94bc-d1c2-4145-97b0-ecb77d81a8bf270=3.27271=0.31661408269=0278=d208c4fb-56c6-4911-85c9-77b68a5ba6ab270=3.25271=0.30961623269=0278=e88796ff-68c8-4463-914b-46e09fbaf639270=3.25271=0.33589845269=0278=06f345fb-0292-45fc-8237-9ad1a84b541c270=3.24271=0.3152850710=246
20250411-01:35:30.196005000 : 8=FIXT.1.19=14135=334=549=24ab46f784d1b20db435b852086e325052=20250411-01:35:30.19056=Coinbase45=18258=Tag appears more than once371=269372=W373=1310=247
20250411-01:35:30.196921000 : 8=FIXT.1.19=90935=W49=Coinbase56=24ab46f784d1b20db435b852086e325034=18350=TEST52=20250411-01:35:30.065919369=2262=ac9dc520-fd90-4708-a92a-3ceddd7c32a383=1597551788893=N55=BTC-USD1682=full_trading268=10269=0278=fa20c2c7-df80-4941-9a9c-a6ef2e579480270=3.23271=0.33432448269=0278=a833d230-a749-4bf4-823e-93adc40b773d270=3.23271=0.31165878269=0278=2abb6e15-b9cd-415b-8c9b-99a61c750310270=3.22271=0.32048714269=0278=ec44a6d8-ae5f-4809-89d7-0f7a3adac547270=3.21271=0.33230954269=0278=9cf61c67-c4fc-4bac-92fd-d4e2b56248aa270=3.21271=0.33583951269=0278=210b2518-bb42-461a-9c7e-b4e04c5ffcc6270=3.21271=0.32669007269=0278=2e3fa1b2-20f1-4694-9be4-322040b75152270=3.21271=0.32907979269=0278=05dd5607-92c9-4296-8cdc-27cdff004dea270=3.21271=0.32776075269=0278=87944de7-a5f1-4033-a3d8-cbc10f3a5232270=3.20271=0.32225170269=0278=30f6bb59-2469-4e6d-8fa5-13666373901f270=3.19271=0.3138649610=109
20250411-01:35:30.202696000 : 8=FIXT.1.19=14135=334=649=24ab46f784d1b20db435b852086e325052=20250411-01:35:30.19856=Coinbase45=18358=Tag appears more than once371=269372=W373=1310=001
20250411-01:35:30.203053000 : 8=FIXT.1.19=91035=W49=Coinbase56=24ab46f784d1b20db435b852086e325034=18450=TEST52=20250411-01:35:30.066169369=2262=ac9dc520-fd90-4708-a92a-3ceddd7c32a383=1597551788893=N55=BTC-USD1682=full_trading268=10269=0278=6a5d2852-7ddc-456e-acb5-bfadcc0c1360270=3.19271=0.32157390269=0278=5d00d8a2-5aea-4836-ba19-74fe67116df8270=3.18271=0.32651049269=0278=acc71746-3591-4dde-a7e2-c2795d0ad125270=3.17271=0.31577131269=0278=13982796-c2a8-4740-95e2-5aca0fdfd8bb270=3.16271=0.33021170269=0278=9f2f0737-661e-43d7-89f9-959ed5e08306270=3.16271=0.33082075269=0278=7e0e2d14-fa77-4978-8cae-d9660fd13e6d270=3.16271=0.32014975269=0278=82826a7d-848c-4516-a7b6-5ec6881609a8270=2.00271=10.00000000269=0278=590048d5-ee44-49dc-b66d-1a692e055133270=1.94271=0.51546392269=0278=22bdda11-16cd-488b-9fa9-da098dad543e270=1.94271=0.51546392269=0278=d356ef8b-596e-47e7-bf90-cc015b85fc57270=1.93271=0.5233160610=209
20250411-01:35:30.204761000 : 8=FIXT.1.19=14135=334=749=24ab46f784d1b20db435b852086e325052=20250411-01:35:30.20456=Coinbase45=18458=Tag appears more than once371=269372=W373=1310=247
20250411-01:35:30.204892000 : 8=FIXT.1.19=90935=W49=Coinbase56=24ab46f784d1b20db435b852086e325034=18550=TEST52=20250411-01:35:30.066418369=2262=ac9dc520-fd90-4708-a92a-3ceddd7c32a383=1597551788893=N55=BTC-USD1682=full_trading268=10269=0278=aa8d48bc-97fb-4d00-b923-66d37cc8c66a270=1.93271=0.52331606269=0278=7d51dcb4-a7f8-4cca-b2d0-e902403d1b9f270=1.93271=0.52331606269=0278=f7680950-3af2-4723-a6e4-5cbd528ca900270=1.93271=0.52331606269=0278=fdeff994-4866-47af-9dde-a25947a26606270=1.93271=0.52331606269=0278=65e7e2bb-023d-4936-bb4e-ff7625ba7264270=1.93271=0.52331606269=0278=53732639-572c-4cd5-b61e-e4f534d1d540270=1.93271=0.52331606269=0278=24da8927-1dd1-468b-9437-ff366f5bfa11270=1.93271=0.52331606269=0278=baa5862c-41e8-458c-83d3-c095bb68ed17270=1.93271=0.52331606269=0278=92a3c3e3-7afe-4d02-a0d8-96f512b63bb7270=1.93271=0.52331606269=0278=9d2a564e-f178-4966-9baf-5814a1c1686b270=1.93271=0.5233160610=148
20250411-01:35:30.205764000 : 8=FIXT.1.19=14135=334=849=24ab46f784d1b20db435b852086e325052=20250411-01:35:30.20556=Coinbase45=18558=Tag appears more than once371=269372=W373=1310=250
20250411-01:35:30.205852000 : 8=FIXT.1.19=90935=W49=Coinbase56=24ab46f784d1b20db435b852086e325034=18650=TEST52=20250411-01:35:30.066669369=2262=ac9dc520-fd90-4708-a92a-3ceddd7c32a383=1597551788893=N55=BTC-USD1682=full_trading268=10269=0278=f9e6b978-87f6-4397-8d82-07cf698c123f270=1.93271=0.52331606269=0278=3e64b388-13d3-441d-b241-aa8dd6fe55e6270=1.93271=0.52331606269=0278=60300433-87b0-4031-bb1e-12cf9d773d3f270=1.93271=0.52331606269=0278=1bdd5f5a-1d99-4eed-af09-c187bcbbd2d8270=1.93271=0.52331606269=0278=4ed6f6b9-77fb-4255-a188-f243dd0cdb3c270=1.93271=0.52331606269=0278=9ad1fc18-5a38-4edb-ac5c-6ac826a8a846270=1.93271=0.52331606269=0278=1c218c8c-baea-4a1f-838e-4a3a94b468e1270=1.93271=0.52331606269=0278=fd70f5e2-d2c9-472a-ab40-a775afafd73d270=1.93271=0.52331606269=0278=96f5e3a5-1c2a-4db6-a3fb-fd1f13d5d559270=1.93271=0.52331606269=0278=4a015a4c-490a-4c40-974f-9dfb7feb335d270=1.93271=0.5233160610=174
20250411-01:35:30.206694000 : 8=FIXT.1.19=14135=334=949=24ab46f784d1b20db435b852086e325052=20250411-01:35:30.20656=Coinbase45=18658=Tag appears more than once371=269372=W373=1310=253
20250411-01:35:30.206778000 : 8=FIXT.1.19=90935=W49=Coinbase56=24ab46f784d1b20db435b852086e325034=18750=TEST52=20250411-01:35:30.066919369=2262=ac9dc520-fd90-4708-a92a-3ceddd7c32a383=1597551788893=N55=BTC-USD1682=full_trading268=10269=0278=d919363e-2c54-404f-bc0b-063e2f12bec4270=1.93271=0.52331606269=0278=d4636d6c-85c6-4ac9-9afb-70ca636f4ad4270=1.93271=0.52331606269=0278=bda09690-f345-4c33-ae8b-e8c78da11b5a270=1.93271=0.52331606269=0278=1a81ae10-b700-42a0-89a3-7d7a3eea0ebb270=1.93271=0.52331606269=0278=1ace5afa-e550-4abf-a458-52e46e1b54f0270=1.93271=0.52331606269=0278=2332d1c9-67e7-457a-abfe-f5e9a8c2ea05270=1.93271=0.52331606269=0278=6afa1f19-0ec5-49fd-8b74-06a12a6c5ca9270=1.93271=0.52331606269=0278=3fa3413d-c26c-472f-9cc5-da1c48935c63270=1.93271=0.52331606269=0278=3f9e43c4-2e62-4d51-b4cb-ad207c693331270=1.93271=0.52331606269=0278=29e8bfcf-c764-4f7e-997d-09abf72bbc00270=1.93271=0.5233160610=097
20250411-01:35:30.208451000 : 8=FIXT.1.19=14235=334=1049=24ab46f784d1b20db435b852086e325052=20250411-01:35:30.20656=Coinbase45=18758=Tag appears more than once371=269372=W373=1310=039
20250411-01:35:30.208586000 : 8=FIXT.1.19=90935=W49=Coinbase56=24ab46f784d1b20db435b852086e325034=18850=TEST52=20250411-01:35:30.067169369=2262=ac9dc520-fd90-4708-a92a-3ceddd7c32a383=1597551788893=N55=BTC-USD1682=full_trading268=10269=0278=cf3e8b26-09ae-4dfb-9b84-b12a7e199a5a270=1.93271=0.52331606269=0278=08db3e51-e927-47d3-a9dd-2f887c58dc85270=1.93271=0.52331606269=0278=353ae741-9473-4cc5-9ab7-7e5de8ae55d0270=1.93271=0.52331606269=0278=4d037208-2072-480f-98ac-7be9c24f18f4270=1.93271=0.52331606269=0278=b598f678-da6e-4c01-90ed-d702c42f8a65270=1.93271=0.52331606269=0278=5f69b1a0-b5d1-4715-9be1-9bdf008d97d7270=1.93271=0.52331606269=0278=ef063d15-248a-4eae-97f4-278be5106d80270=1.93271=0.52331606269=0278=f8b20207-84bc-44e9-a2fe-9ad775e2ecb1270=1.93271=0.52331606269=0278=75bce2b7-bc58-4479-8bfb-144f88f2262b270=1.93271=0.52331606269=0278=1f6e2a79-8b10-4a7f-89de-0f1fa03692c7270=1.93271=0.5233160610=081
20250411-01:35:30.209613000 : 8=FIXT.1.19=14235=334=1149=24ab46f784d1b20db435b852086e325052=20250411-01:35:30.20856=Coinbase45=18858=Tag appears more than once371=269372=W373=1310=043
20250411-01:35:30.209838000 : 8=FIXT.1.19=90935=W49=Coinbase56=24ab46f784d1b20db435b852086e325034=18950=TEST52=20250411-01:35:30.067419369=2262=ac9dc520-fd90-4708-a92a-3ceddd7c32a383=1597551788893=N55=BTC-USD1682=full_trading268=10269=0278=d1b80bf5-9b17-44b4-9577-6fe71170b578270=1.93271=0.52331606269=0278=b891e26a-c20c-4fce-ba1c-487fe139a4cc270=1.93271=0.52331606269=0278=5d06d3f6-3189-4394-b3c5-6a2bda14b6d1270=1.93271=0.52331606269=0278=e5791c0f-3937-4a66-9b98-26f79a3891be270=1.93271=0.52331606269=0278=c62591c6-7dfa-46a7-8f20-6a5f22804999270=1.93271=0.52331606269=0278=7c503558-c0b8-457b-8c46-71ece3f7fc8a270=1.93271=0.52331606269=0278=f763bb56-2f21-4a9b-bd48-f84dc1bd5ee5270=1.93271=0.52331606269=0278=42214b03-1fc2-46b3-9e83-91b23a510e5a270=1.93271=0.52331606269=0278=1c7c52ed-7d39-4326-b3b8-98f05a9b3ef0270=1.93271=0.52331606269=0278=3313309e-45e7-4e7b-8c55-4f9a8ec1b351270=1.93271=0.5233160610=127
20250411-01:35:30.211272000 : 8=FIXT.1.19=14235=334=1249=24ab46f784d1b20db435b852086e325052=20250411-01:35:30.21056=Coinbase45=18958=Tag appears more than once371=269372=W373=1310=038
20250411-01:35:30.227158000 : 8=FIXT.1.19=90935=W49=Coinbase56=24ab46f784d1b20db435b852086e325034=19050=TEST52=20250411-01:35:30.067669369=2262=ac9dc520-fd90-4708-a92a-3ceddd7c32a383=1597551788893=N55=BTC-USD1682=full_trading268=10269=0278=78801ffb-ec5a-4c74-9d08-3e86fd9db4dd270=1.93271=0.52331606269=0278=abe6eea4-1d9c-47d7-847f-2f44aa561b3f270=1.93271=0.52331606269=0278=6a6eb56d-2010-43e2-b78e-5f098081bb64270=1.93271=0.52331606269=0278=b53c01ff-f450-4b05-8ad1-e7894b45e0e0270=1.93271=0.52331606269=0278=4747863e-c0a6-4ef5-8faf-e8934bca4f8b270=1.93271=0.52331606269=0278=81a8a629-57f4-4e3a-ac25-2e9ee1f357c2270=1.93271=0.52331606269=0278=1e239259-7be4-476a-845d-1b92fd951d8b270=1.93271=0.52331606269=0278=189eb272-48f9-4915-b7e1-a86dcc505c4a270=1.93271=0.52331606269=0278=0562b9f7-aae3-4961-bd97-f5b8cde0ec34270=1.93271=0.52331606269=0278=5103331b-7300-487b-bc2c-a6032bf4be7e270=1.93271=0.5233160610=178
20250411-01:35:30.237250000 : 8=FIXT.1.19=14235=334=1349=24ab46f784d1b20db435b852086e325052=20250411-01:35:30.23556=Coinbase45=19058=Tag appears more than once371=269372=W373=1310=038
20250411-01:35:30.237605000 : 8=FIXT.1.19=91235=W49=Coinbase56=24ab46f784d1b20db435b852086e325034=19150=TEST52=20250411-01:35:30.067919369=2262=ac9dc520-fd90-4708-a92a-3ceddd7c32a383=1597551788893=N55=BTC-USD1682=full_trading268=10269=0278=78ac85ac-2478-4991-a084-7286982b77cc270=1.93271=0.52331606269=0278=6993b26d-d6dc-4f99-8a53-9500ae5b4ff1270=1.93271=0.52331606269=0278=1c96ab9d-04a6-465a-87e5-3ed33970178f270=1.93271=0.52331606269=0278=6fc0282b-d538-4aa3-8982-bda02bb1b054270=1.93271=0.52331606269=0278=80870aa3-04a2-4d2a-8669-93215130ffee270=1.93271=0.52331606269=0278=b274e872-6923-45fd-b48a-68e685e769cb270=1.93271=0.52331606269=0278=2d4364c0-239c-4f4b-8ce4-2acfe0bb343d270=1.12271=1.00000000269=0278=8fa16a4f-377f-4deb-9a8e-1020aed9edf4270=1.00271=1.00000000269=1278=c5b88ea9-605d-4595-ac52-f7c3f08523ba270=3.55271=8537.02984072269=1278=81523bd3-8912-4789-8761-89a9ee42794b270=3.55271=0.3051896610=127
20250411-01:35:30.238924000 : 8=FIXT.1.19=14235=334=1449=24ab46f784d1b20db435b852086e325052=20250411-01:35:30.23856=Coinbase45=19158=Tag appears more than once371=269372=W373=1310=043
20250411-01:35:30.239260000 : 8=FIXT.1.19=92935=W49=Coinbase56=24ab46f784d1b20db435b852086e325034=19250=TEST52=20250411-01:35:30.068169369=2262=ac9dc520-fd90-4708-a92a-3ceddd7c32a383=1597551788893=N55=BTC-USD1682=full_trading268=10269=1278=d08bb7a6-33e2-4882-814d-7bb0629d6f6b270=3.55271=0.41801845269=1278=60fc75ca-0052-40b7-9f18-a6aad9d31b84270=3.56271=18037.00000000269=1278=a9029294-7550-419b-ba46-4cd8f6ef7939270=3.56271=0.62322946269=1278=ad00e2cd-d925-46a4-9e7e-941c6faed2c7270=3.57271=18027.00000000269=1278=fec191b5-64da-4a15-ab4b-36a0d3d10750270=3.57271=0.29025301269=1278=71ec06da-63f1-4c6e-b8d4-d4fa56c3ce8c270=3.57271=0.39080257269=1278=02a780aa-8154-4638-a5ca-53b8198cc724270=3.58271=16937.00000000269=1278=911349fb-1960-4904-9a38-0e2497fb7ccb270=3.58271=0.29896312269=1278=d91e89d4-ac5c-4853-9879-ec8ff5e00a71270=3.59271=17163.00000000269=1278=341d0ad8-6c15-4b5e-aebb-e3caa5af575c270=3.60271=17926.0000000010=055
20250411-01:35:30.240398000 : 8=FIXT.1.19=14235=334=1549=24ab46f784d1b20db435b852086e325052=20250411-01:35:30.23956=Coinbase45=19258=Tag appears more than once371=269372=W373=1310=046
20250411-01:35:30.258475000 : 8=FIXT.1.19=92535=W49=Coinbase56=24ab46f784d1b20db435b852086e325034=19350=TEST52=20250411-01:35:30.068419369=2262=ac9dc520-fd90-4708-a92a-3ceddd7c32a383=1597551788893=N55=BTC-USD1682=full_trading268=10269=1278=9d239e03-1215-4cc7-ad44-3f4097ee70ea270=3.61271=18058.08928020269=1278=dbb0f332-4189-4df5-879b-e55860b13def270=3.62271=0.28062774269=1278=f7639c39-7e8b-44d1-a2f2-9807e2a3228c270=3.62271=0.27709851269=1278=83be9389-2099-4173-a322-b0933bc99358270=3.62271=19973.00000000269=1278=b89abc22-6b6c-4474-b3fc-ffe21f05cd4e270=3.63271=20016.00000000269=1278=ce0af8a3-149c-4603-905a-be65625fe014270=3.64271=0.27806002269=1278=94b8615f-6fa7-4dc9-bbfa-435fe535bebc270=3.64271=22352.63489459269=1278=cae3885d-f5b2-4de1-830c-0085e27bbb69270=3.69271=0.27722678269=1278=b9732128-11b1-44fd-bea3-94da9fc853fb270=3.71271=0.28488329269=1278=818b83a4-e14e-4ad5-b094-6733f0504003270=3.75271=0.2793022510=127
20250411-01:35:30.259791000 : 8=FIXT.1.19=14235=334=1649=24ab46f784d1b20db435b852086e325052=20250411-01:35:30.25956=Coinbase45=19358=Tag appears more than once371=269372=W373=1310=050
20250411-01:35:30.259911000 : 8=FIXT.1.19=91135=W49=Coinbase56=24ab46f784d1b20db435b852086e325034=19450=TEST52=20250411-01:35:30.068669369=2262=ac9dc520-fd90-4708-a92a-3ceddd7c32a383=1597551788893=N55=BTC-USD1682=full_trading268=10269=1278=3e6990a0-8ef4-4968-8ee8-89b7346c197d270=3.76271=0.28131365269=1278=342794c8-a9d2-4aa5-9886-a819398d69c6270=3.88271=0.27719712269=1278=2839680b-48b3-4f53-86b1-9269987275e7270=3.91271=0.26621275269=1278=207d5707-e412-4dc9-bca8-9b1bd7853e92270=3.93271=0.42185728269=1278=fd7b5361-29f8-4b35-bae5-232a64f657b4270=3.95271=0.26131406269=1278=5edaeed0-fae9-4f36-8c77-6fbedf61eefc270=4.02271=0.25091227269=1278=fdbbfd04-ba67-4b23-bbc1-f87f929e7e81270=4.07271=0.24812642269=1278=534b2a85-0852-420d-928b-70cdb6ba2457270=4.10271=0.26961968269=1278=b009f8a1-4a39-493b-b96e-d783e981c915270=4.26271=0.25019574269=1278=729a899c-ac2d-4541-b0a2-cbdd5df9bf98270=10.00271=10.0000000010=200
20250411-01:35:30.261005000 : 8=FIXT.1.19=14235=334=1749=24ab46f784d1b20db435b852086e325052=20250411-01:35:30.26056=Coinbase45=19458=Tag appears more than once371=269372=W373=1310=044
20250411-01:35:30.261139000 : 8=FIXT.1.19=92935=W49=Coinbase56=24ab46f784d1b20db435b852086e325034=19550=TEST52=20250411-01:35:30.068919369=2262=ac9dc520-fd90-4708-a92a-3ceddd7c32a383=1597551788893=N55=BTC-USD1682=full_trading268=10269=1278=eb1e5d45-d081-4ef8-a83e-1f5348fbda96270=10.00271=10.00000000269=1278=0cd67977-85eb-45fa-ae72-d45b92ca24f4270=10.00271=10.00000000269=1278=5d931559-6758-4b75-9d6d-6438d25b497f270=10.00271=10.00000000269=1278=57e43d1d-644a-493e-acd3-69dc5e64dcde270=10.00271=10.00000000269=1278=c1566121-2b63-494d-ac2d-973e9f0115c0270=10.00271=10.00000000269=1278=d0c4a771-9035-4db9-ae7b-ad2d1db5646d270=10.00271=10.00000000269=1278=52c644ea-628a-4576-8e7e-27ec4c90398b270=10.00271=10.00000000269=1278=c3483f66-d8ce-489a-90b9-2bce69e054ee270=10.00271=10.00000000269=1278=55992a5c-cbcd-464a-8f8d-8b58e81e5c0b270=10.00271=10.00000000269=1278=19077009-6f26-4e2d-9dab-04a28231b752270=10.00271=10.0000000010=243
20250411-01:35:30.261918000 : 8=FIXT.1.19=14235=334=1849=24ab46f784d1b20db435b852086e325052=20250411-01:35:30.26156=Coinbase45=19558=Tag appears more than once371=269372=W373=1310=047
20250411-01:35:30.262088000 : 8=FIXT.1.19=93535=W49=Coinbase56=24ab46f784d1b20db435b852086e325034=19650=TEST52=20250411-01:35:30.069169369=2262=ac9dc520-fd90-4708-a92a-3ceddd7c32a383=1597551788893=N55=BTC-USD1682=full_trading268=10269=1278=692097d1-c978-4024-95e9-2bf348b64bbd270=10.00271=10.00000000269=1278=99a92935-11b7-4f21-a64c-c746b53d1777270=10.00271=10.00000000269=1278=dc024b0b-0337-4215-9669-5e5636834397270=10.00271=10.00000000269=1278=c90fcc3a-a36c-4c14-b57f-6db78762e017270=10.00271=10.00000000269=1278=7841891a-bb7c-4034-97c1-41164185edc7270=1000.00271=3.10000000269=1278=381c9fa7-1add-4dd2-9233-f41e2c8821fe270=1000.00271=3.10000000269=1278=928e65c2-7e2d-478b-9310-414fb77f5aae270=1000.00271=3.10000000269=1278=ad4bd3ac-9276-40d5-90f9-e47b1d8ee953270=1000.00271=3.10000000269=1278=79e799dc-4a3d-4922-ad1a-f74eb7eff789270=1000.00271=3.10000000269=1278=04f642b7-750f-4967-b786-0d48eea0f158270=1000.00271=3.1000000010=143
20250411-01:35:30.262918000 : 8=FIXT.1.19=14235=334=1949=24ab46f784d1b20db435b852086e325052=20250411-01:35:30.26256=Coinbase45=19658=Tag appears more than once371=269372=W373=1310=050
20250411-01:35:30.263004000 : 8=FIXT.1.19=93935=W49=Coinbase56=24ab46f784d1b20db435b852086e325034=19750=TEST52=20250411-01:35:30.069419369=2262=ac9dc520-fd90-4708-a92a-3ceddd7c32a383=1597551788893=N55=BTC-USD1682=full_trading268=10269=1278=d0ad653d-3272-4a3b-ba7a-a52029a67a92270=1000.00271=3.10000000269=1278=cad40464-4c62-4bf3-8444-c487fcc8dd01270=1000.00271=3.10000000269=1278=426c6428-d481-4ff7-9de3-f00ff219d654270=1000.00271=3.10000000269=1278=1ed1152d-8c1a-4b29-acdd-bbd1a5c5f35f270=1000.00271=3.10000000269=1278=66526051-b5cb-442f-af90-c609be0a9796270=1000.00271=3.10000000269=1278=f68e4659-5785-4ee9-ac24-3186640a2752270=1000.00271=3.10000000269=1278=38070d38-80a9-4898-8ef7-a0a9da5a4123270=1000.00271=3.10000000269=1278=e4d2d308-ed11-49db-850e-3cbd8258395d270=1000.00271=3.10000000269=1278=d6cfaadc-97ea-43c1-898d-40faea9c1477270=1000.00271=3.10000000269=1278=36876bea-9e3a-4018-b0ac-b75cb8c16953270=1000.00271=3.1000000010=160
20250411-01:35:30.263895000 : 8=FIXT.1.19=14235=334=2049=24ab46f784d1b20db435b852086e325052=20250411-01:35:30.26356=Coinbase45=19758=Tag appears more than once371=269372=W373=1310=044
20250411-01:35:30.299331000 : 8=FIXT.1.19=93935=W49=Coinbase56=24ab46f784d1b20db435b852086e325034=19850=TEST52=20250411-01:35:30.069669369=2262=ac9dc520-fd90-4708-a92a-3ceddd7c32a383=1597551788893=N55=BTC-USD1682=full_trading268=10269=1278=eb244bc5-49e8-4aa3-af8b-3d1a67c90a08270=1000.00271=3.10000000269=1278=3efba776-29ad-4aeb-82d8-0824f161471e270=1000.00271=3.10000000269=1278=de0ddebd-0ca8-4eca-9985-77c10c8629a9270=1000.00271=3.10000000269=1278=dde4408a-fb6b-441c-a7f3-7b8b23ffdb1f270=1000.00271=3.10000000269=1278=3ebd6434-070f-4b4d-8cf3-00368112466d270=1000.00271=3.10000000269=1278=7aa98e13-65f3-4058-9f91-c1f452d02710270=1000.00271=3.10000000269=1278=e86a1fec-3610-460d-8d85-4e1e222ee159270=1000.00271=3.10000000269=1278=6dfac057-72b1-4f2c-b110-03766dea0d31270=1000.00271=3.10000000269=1278=bbb7d0ea-d251-4612-b53e-e528cc0a24ab270=1000.00271=3.10000000269=1278=0782ca37-48cf-4ff3-a74a-35674661586c270=1000.00271=3.1000000010=087
20250411-01:35:30.300124000 : 8=FIXT.1.19=14235=334=2149=24ab46f784d1b20db435b852086e325052=20250411-01:35:30.29956=Coinbase45=19858=Tag appears more than once371=269372=W373=1310=055
20250411-01:35:30.300197000 : 8=FIXT.1.19=93935=W49=Coinbase56=24ab46f784d1b20db435b852086e325034=19950=TEST52=20250411-01:35:30.069919369=2262=ac9dc520-fd90-4708-a92a-3ceddd7c32a383=1597551788893=N55=BTC-USD1682=full_trading268=10269=1278=aead437d-4b62-457f-ac83-62c7cc329fd1270=1000.00271=3.10000000269=1278=af5d47bc-a008-4567-b24f-b0298f250471270=1000.00271=3.10000000269=1278=4c260f58-c427-4a9a-969a-44024ae0c714270=1000.00271=3.10000000269=1278=8c7672e5-7ee8-4fbd-8fdf-7e74e9a77db7270=1000.00271=3.10000000269=1278=b53ec3cc-9abe-4570-b903-34d52148073e270=1000.00271=3.10000000269=1278=37ce984a-0387-4ac9-9094-b83f722036ba270=1000.00271=3.10000000269=1278=0d383649-dc6c-4df2-b821-aa0018f132c7270=1000.00271=3.10000000269=1278=e39ae0ce-9e7f-4f0d-a765-5308d473bb61270=1000.00271=3.10000000269=1278=4882324e-3b5c-4b7a-b096-e8c6d9888671270=1000.00271=3.10000000269=1278=6e5c7dbd-a2cc-401f-a5b2-3902088f4ab2270=1000.00271=3.1000000010=085
20250411-01:35:30.300905000 : 8=FIXT.1.19=14235=334=2249=24ab46f784d1b20db435b852086e325052=20250411-01:35:30.30056=Coinbase45=19958=Tag appears more than once371=269372=W373=1310=040
20250411-01:35:30.300989000 : 8=FIXT.1.19=93935=W49=Coinbase56=24ab46f784d1b20db435b852086e325034=20050=TEST52=20250411-01:35:30.070169369=2262=ac9dc520-fd90-4708-a92a-3ceddd7c32a383=1597551788893=N55=BTC-USD1682=full_trading268=10269=1278=10ffac08-946a-4a30-b57a-0d78450345d9270=1000.00271=3.10000000269=1278=67784af5-72bf-4d16-a6b3-25336e2c1843270=1000.00271=3.10000000269=1278=4d8b3bbc-0dc2-4044-875c-c079ec538136270=1000.00271=3.10000000269=1278=dfba5f1e-21f5-48e3-adce-b8b6bfe71467270=1000.00271=3.10000000269=1278=e51b4e33-5eaa-46ef-936b-a74a890397e8270=1000.00271=3.10000000269=1278=8cf5dfa8-858b-48a3-9d94-78522c257473270=1000.00271=3.10000000269=1278=a153b9d2-993d-4f03-a974-b8a081e128e8270=1000.00271=3.10000000269=1278=1eebe866-0f6e-4d4a-a28b-78f4e3368b0a270=1000.00271=3.10000000269=1278=300132d8-113f-4bf7-ba0c-4d93a272f55b270=1000.00271=3.10000000269=1278=757f3122-27d2-4f32-90b8-ead1eef9b936270=1000.00271=3.1000000010=015
20250411-01:35:30.301836000 : 8=FIXT.1.19=14235=334=2349=24ab46f784d1b20db435b852086e325052=20250411-01:35:30.30156=Coinbase45=20058=Tag appears more than once371=269372=W373=1310=025
20250411-01:35:30.302010000 : 8=FIXT.1.19=93935=W49=Coinbase56=24ab46f784d1b20db435b852086e325034=20150=TEST52=20250411-01:35:30.070420369=2262=ac9dc520-fd90-4708-a92a-3ceddd7c32a383=1597551788893=N55=BTC-USD1682=full_trading268=10269=1278=2b68b5de-4153-4cac-ace3-102e4fa788fd270=1000.00271=3.10000000269=1278=b01f252a-1657-4df0-a122-58a23109a7c2270=1000.00271=3.10000000269=1278=dbc57e4e-6abd-4d66-8d18-bd13caaa77b1270=1000.00271=3.10000000269=1278=948b05dc-a481-409f-b8ad-a502eb595906270=1000.00271=3.10000000269=1278=e00f9703-6e16-4237-a2c6-701829d11bf1270=1000.00271=3.10000000269=1278=fd52f47a-3f11-47bc-9952-9708617d0ecd270=1000.00271=3.10000000269=1278=f7f75b14-27c3-469c-89fb-6a98b43c61bf270=1000.00271=3.10000000269=1278=25dbeb09-7901-4280-b0c3-720d7ed03d7d270=1000.00271=3.10000000269=1278=52164a1f-599f-4c43-a9ed-f93403506e67270=1000.00271=3.10000000269=1278=c71c35ea-f60f-4a41-b43a-4947bbcbafad270=1000.00271=3.1000000010=218
20250411-01:35:30.302914000 : 8=FIXT.1.19=14235=334=2449=24ab46f784d1b20db435b852086e325052=20250411-01:35:30.30256=Coinbase45=20158=Tag appears more than once371=269372=W373=1310=028
20250411-01:35:30.414965000 : 8=FIXT.1.19=93935=W49=Coinbase56=24ab46f784d1b20db435b852086e325034=20250=TEST52=20250411-01:35:30.070669369=2262=ac9dc520-fd90-4708-a92a-3ceddd7c32a383=1597551788893=N55=BTC-USD1682=full_trading268=10269=1278=2de342bc-a1be-46f3-9fc6-731297726934270=1000.00271=3.10000000269=1278=7ff4c5fc-bc9b-4845-940b-4837a672e13a270=1000.00271=3.10000000269=1278=2d270775-33eb-4328-8dad-7d206612f9f6270=1000.00271=3.10000000269=1278=c4754378-f787-4100-81af-564443a86a91270=1000.00271=3.10000000269=1278=59e16255-05eb-4fdc-8be1-3c4f83fc094e270=1000.00271=3.10000000269=1278=041b2f98-1185-49cb-964a-f0456b71e692270=1000.00271=3.10000000269=1278=9a2f3529-481e-4e50-a123-7a2095fe6b2c270=1000.00271=3.10000000269=1278=9ed552a3-3295-4878-85dd-87b7b5590212270=1000.00271=3.10000000269=1278=54bec5c2-bafd-4d7d-851d-59e3553a053f270=1000.00271=3.10000000269=1278=543c1acf-52f2-442b-a893-f7aa9a5dfbd1270=1000.00271=3.1000000010=079
20250411-01:35:30.416153000 : 8=FIXT.1.19=14235=334=2549=24ab46f784d1b20db435b852086e325052=20250411-01:35:30.41556=Coinbase45=20258=Tag appears more than once371=269372=W373=1310=035
20250411-01:35:30.416276000 : 8=FIXT.1.19=93935=W49=Coinbase56=24ab46f784d1b20db435b852086e325034=20350=TEST52=20250411-01:35:30.070919369=2262=ac9dc520-fd90-4708-a92a-3ceddd7c32a383=1597551788893=N55=BTC-USD1682=full_trading268=10269=1278=fec999be-cbd0-42ef-b9c3-82ca92ef0b58270=1000.00271=3.10000000269=1278=24528176-3fc6-45b2-b2f3-9f784c01495a270=1000.00271=3.10000000269=1278=12081678-66a6-4435-a3d7-b65f959cf2ac270=1000.00271=3.10000000269=1278=e7fb6165-8f1a-4b5e-b095-e232b83ee951270=1000.00271=3.10000000269=1278=83ce6582-410a-40bf-9831-8f3d20e3a629270=1000.00271=3.10000000269=1278=bc3a930b-0567-46ba-86a4-712f76466b0b270=1000.00271=3.10000000269=1278=15704973-f5ff-457d-ab31-8f99bb76bf7e270=1000.00271=3.10000000269=1278=7159045b-cbd5-458f-b91f-9fa5241b14b5270=1000.00271=3.10000000269=1278=9fa52a90-f03f-4940-b5ee-39ab937b86f1270=1000.00271=3.10000000269=1278=220f55cd-a279-4bf0-9c80-1dca086d85dc270=1000.00271=3.1000000010=252
20250411-01:35:30.417096000 : 8=FIXT.1.19=14235=334=2649=24ab46f784d1b20db435b852086e325052=20250411-01:35:30.41656=Coinbase45=20358=Tag appears more than once371=269372=W373=1310=038
20250411-01:35:30.417191000 : 8=FIXT.1.19=93935=W49=Coinbase56=24ab46f784d1b20db435b852086e325034=20450=TEST52=20250411-01:35:30.071170369=2262=ac9dc520-fd90-4708-a92a-3ceddd7c32a383=1597551788893=N55=BTC-USD1682=full_trading268=10269=1278=2b1eb468-6bcd-4117-a7c0-214d643ddad4270=1000.00271=3.10000000269=1278=cc23185d-e72e-42cb-8210-61bab29cd778270=1000.00271=3.10000000269=1278=69bb228b-973b-4176-8708-3231cc40102a270=1000.00271=3.10000000269=1278=2ec8035d-7962-4195-8388-c9fbad52ac8a270=1000.00271=3.10000000269=1278=7d39e416-0b7b-471f-a9ac-455ab1bce5a7270=1000.00271=3.10000000269=1278=7067378d-2a65-41f2-acb0-ef30ddbc3e5a270=1000.00271=3.10000000269=1278=bf3fde78-6cff-4477-b381-4b5d2e68f36f270=1000.00271=3.10000000269=1278=93a2a8a3-61d4-410c-9446-8eabaafc5f29270=1000.00271=3.10000000269=1278=5afddb61-63ab-417b-a28a-41c4c03a6612270=1000.00271=3.10000000269=1278=a4280417-189c-4f76-9d2e-6ec652010bf5270=1000.00271=3.1000000010=215
20250411-01:35:30.417817000 : 8=FIXT.1.19=14235=334=2749=24ab46f784d1b20db435b852086e325052=20250411-01:35:30.41756=Coinbase45=20458=Tag appears more than once371=269372=W373=1310=041
20250411-01:35:30.417894000 : 8=FIXT.1.19=93935=W49=Coinbase56=24ab46f784d1b20db435b852086e325034=20550=TEST52=20250411-01:35:30.071419369=2262=ac9dc520-fd90-4708-a92a-3ceddd7c32a383=1597551788893=N55=BTC-USD1682=full_trading268=10269=1278=ddeb78a2-e110-4828-ba3d-c9b4837e7dd7270=1000.00271=3.10000000269=1278=fcec6c90-441a-4f4a-a94e-9003355657ef270=1000.00271=3.10000000269=1278=6db15389-dfb3-4156-8a4e-ce2ac80f2b15270=1000.00271=3.10000000269=1278=47dfefc3-6f05-4b57-8aec-2bf3e6c70c2d270=1000.00271=3.10000000269=1278=fb9fd019-4b4f-4880-82bb-3df6d1ef468a270=1000.00271=3.10000000269=1278=2cff9acd-42cb-43a5-8d50-51e676b7e763270=1000.00271=3.10000000269=1278=6e6eeb59-4728-4811-9a44-c857df6aca42270=1000.00271=3.10000000269=1278=81798560-263f-4819-a528-5f3fbbc7b042270=1000.00271=3.10000000269=1278=81fbf9a8-82f4-4fe4-9fa5-3773b212ebf4270=1000.00271=3.10000000269=1278=5d3b9566-276d-47fe-a111-12c17f53f501270=1000.00271=3.1000000010=224
20250411-01:35:30.418606000 : 8=FIXT.1.19=14235=334=2849=24ab46f784d1b20db435b852086e325052=20250411-01:35:30.41856=Coinbase45=20558=Tag appears more than once371=269372=W373=1310=044
20250411-01:35:30.418794000 : 8=FIXT.1.19=93935=W49=Coinbase56=24ab46f784d1b20db435b852086e325034=20650=TEST52=20250411-01:35:30.071670369=2262=ac9dc520-fd90-4708-a92a-3ceddd7c32a383=1597551788893=N55=BTC-USD1682=full_trading268=10269=1278=8eb1b3b3-c813-48b1-b839-993672108d91270=1000.00271=3.10000000269=1278=4feb6e93-6149-481b-8d58-e1c8e6c5cda1270=1000.00271=3.10000000269=1278=f8611e72-4056-4b7c-9779-4d54cd151d44270=1000.00271=3.10000000269=1278=7a129f7c-d9ba-4ea3-a267-b7d82b2e07d9270=1000.00271=3.10000000269=1278=01f359f0-c38f-416b-af00-183907218793270=1000.00271=3.10000000269=1278=11741cec-9c08-4a20-99dc-6b9f63130b0e270=1000.00271=3.10000000269=1278=08db2574-ad52-4520-ab5b-c3c7591eb781270=1000.00271=3.10000000269=1278=b06f2249-179c-4a15-8e98-7b76083b808b270=1000.00271=3.10000000269=1278=9e88fede-6d19-4c1f-863b-5a7d66781436270=1000.00271=3.10000000269=1278=75e1d8b4-7201-41fe-a687-7d93420af323270=1000.00271=3.1000000010=143
20250411-01:35:30.419770000 : 8=FIXT.1.19=14235=334=2949=24ab46f784d1b20db435b852086e325052=20250411-01:35:30.41956=Coinbase45=20658=Tag appears more than once371=269372=W373=1310=047
20250411-01:35:30.419868000 : 8=FIXT.1.19=93935=W49=Coinbase56=24ab46f784d1b20db435b852086e325034=20750=TEST52=20250411-01:35:30.071920369=2262=ac9dc520-fd90-4708-a92a-3ceddd7c32a383=1597551788893=N55=BTC-USD1682=full_trading268=10269=1278=d00aa7dd-ce7f-4f8b-9a2e-880c1ea30845270=1000.00271=3.10000000269=1278=584a483f-23bf-4d8b-809f-69cf3c110f60270=1000.00271=3.10000000269=1278=dc98524e-27e2-4863-99e4-7a0097a6ee90270=1000.00271=3.10000000269=1278=82a11ac9-4f46-44b7-a0bc-a5a4cfe686e0270=1000.00271=3.10000000269=1278=f946bb05-900c-41fc-9908-41489e97ff20270=1000.00271=3.10000000269=1278=1f9186d6-0312-4677-ba96-fdb014cdff2c270=1000.00271=3.10000000269=1278=c3b67be7-2b63-4884-b311-80f28496c2c4270=1000.00271=3.10000000269=1278=6576c7f8-a4e2-4417-b854-5fef0e705fbe270=1000.00271=3.10000000269=1278=c2102c71-62f0-4eee-ae60-0777ed26a8e6270=1000.00271=3.10000000269=1278=c823a2b6-849e-4839-a2fd-cd9f459cae6c270=1000.00271=3.1000000010=195
20250411-01:35:30.420539000 : 8=FIXT.1.19=14235=334=3049=24ab46f784d1b20db435b852086e325052=20250411-01:35:30.42056=Coinbase45=20758=Tag appears more than once371=269372=W373=1310=032
20250411-01:35:30.420616000 : 8=FIXT.1.19=93935=W49=Coinbase56=24ab46f784d1b20db435b852086e325034=20850=TEST52=20250411-01:35:30.072170369=2262=ac9dc520-fd90-4708-a92a-3ceddd7c32a383=1597551788893=N55=BTC-USD1682=full_trading268=10269=1278=a051e195-4472-4a8a-8591-08a2c04a33c4270=1000.00271=3.10000000269=1278=ec81b8c4-b703-4afd-a701-ce34011f60f6270=1000.00271=3.10000000269=1278=b1172677-f493-4f32-a200-0710cf8c397f270=1000.00271=3.10000000269=1278=b1a58a75-5fca-43db-b9c6-a26920e8f66e270=1000.00271=3.10000000269=1278=038bea41-b91d-4884-b992-3e5431ef9857270=1000.00271=3.10000000269=1278=55063782-f2ea-4c84-9491-8e8e89d1dfd1270=1000.00271=3.10000000269=1278=bb2011e8-d05d-40ac-9e9c-3b720422e38d270=1000.00271=3.10000000269=1278=64dd3b4a-ce8a-4b63-9937-266e832c0f21270=1000.00271=3.10000000269=1278=d64f7d2a-aa83-486c-92a8-3314c4eddd58270=1000.00271=3.10000000269=1278=0df9641b-d89d-4222-a8ea-bcddf0d555f5270=1000.00271=3.1000000010=190
20250411-01:35:30.421265000 : 8=FIXT.1.19=14235=334=3149=24ab46f784d1b20db435b852086e325052=20250411-01:35:30.42056=Coinbase45=20858=Tag appears more than once371=269372=W373=1310=034
20250411-01:35:30.421347000 : 8=FIXT.1.19=93935=W49=Coinbase56=24ab46f784d1b20db435b852086e325034=20950=TEST52=20250411-01:35:30.072420369=2262=ac9dc520-fd90-4708-a92a-3ceddd7c32a383=1597551788893=N55=BTC-USD1682=full_trading268=10269=1278=7a315b16-a05f-408d-b8c1-2704af9bf767270=1000.00271=3.10000000269=1278=0e9712a8-d00f-4864-a478-f7f591718f91270=1000.00271=3.10000000269=1278=94db025d-eada-49e3-b13c-b667ca07f829270=1000.00271=3.10000000269=1278=a88ccd1f-8f8d-46af-8fb6-20adba35f7d1270=1000.00271=3.10000000269=1278=99d4e235-c8ec-4efc-938c-9a1923eafc96270=1000.00271=3.10000000269=1278=a4fc7173-7583-4f8b-b256-2921bef83c84270=1000.00271=3.10000000269=1278=18f8afd4-8bbc-4ffa-8e8f-0c1834d74472270=1000.00271=3.10000000269=1278=21fc8cb6-f894-4d09-884e-810b8ebf2ef3270=1000.00271=3.10000000269=1278=0c13b9e6-6797-4b3e-90ce-a1885b26ba53270=1000.00271=3.10000000269=1278=6d8da581-3998-4fc0-99b6-3c5edbd514cb270=1000.00271=3.1000000010=111
20250411-01:35:30.422094000 : 8=FIXT.1.19=14235=334=3249=24ab46f784d1b20db435b852086e325052=20250411-01:35:30.42156=Coinbase45=20958=Tag appears more than once371=269372=W373=1310=037
20250411-01:35:30.422176000 : 8=FIXT.1.19=93935=W49=Coinbase56=24ab46f784d1b20db435b852086e325034=21050=TEST52=20250411-01:35:30.072670369=2262=ac9dc520-fd90-4708-a92a-3ceddd7c32a383=1597551788893=N55=BTC-USD1682=full_trading268=10269=1278=67a70307-be50-4065-872b-47e0de473bc4270=1000.00271=3.10000000269=1278=8ce7be0b-98de-46d0-b1b6-307a4bec36e2270=1000.00271=3.10000000269=1278=856b22f8-5884-4739-adc0-bdd851c5c07d270=1000.00271=3.10000000269=1278=c00ae651-a76b-4bfd-be16-3672b345fe29270=1000.00271=3.10000000269=1278=cae248f9-16fc-44ea-9b79-1dacfc285db6270=1000.00271=3.10000000269=1278=42bb223c-88c6-4a18-8ff3-4fd8d9efda8d270=1000.00271=3.10000000269=1278=d7188b01-22b6-4837-a720-077601f7f483270=1000.00271=3.10000000269=1278=5d85a0a6-ddd9-4e0e-9a1a-7f418ef588e5270=1000.00271=3.10000000269=1278=bff4c39f-7a80-42ce-a178-b1221792e445270=1000.00271=3.10000000269=1278=9ea3d263-b5ab-46c5-bf27-8c0e3e0e5e9e270=1000.00271=3.1000000010=033
20250411-01:35:30.422851000 : 8=FIXT.1.19=14235=334=3349=24ab46f784d1b20db435b852086e325052=20250411-01:35:30.42256=Coinbase45=21058=Tag appears more than once371=269372=W373=1310=031
20250411-01:35:30.422923000 : 8=FIXT.1.19=93935=W49=Coinbase56=24ab46f784d1b20db435b852086e325034=21150=TEST52=20250411-01:35:30.072920369=2262=ac9dc520-fd90-4708-a92a-3ceddd7c32a383=1597551788893=N55=BTC-USD1682=full_trading268=10269=1278=b93347df-d2ab-48ec-b326-4454e64f1d4e270=1000.00271=3.10000000269=1278=57acc40d-8478-444a-990f-067a8e8e846e270=1000.00271=3.10000000269=1278=34419ae2-2c16-427b-a290-845419760fd5270=1000.00271=3.10000000269=1278=ab41de2d-5def-4986-b56e-243d2f99a57c270=1000.00271=3.10000000269=1278=9025524c-03a9-407a-a58a-5258c4ea0a0b270=1000.00271=3.10000000269=1278=60766318-112b-4d83-a384-55693de75519270=1000.00271=3.10000000269=1278=c19b6a2c-086b-4fc1-8dfe-51cb2dc12c1d270=1000.00271=3.10000000269=1278=11126433-0f9c-4450-a35a-39b878e85e68270=1000.00271=3.10000000269=1278=e2e620ee-44fb-4630-a890-d331ba5b2fae270=1000.00271=3.10000000269=1278=9ccf6d4b-a6ca-4a1f-a7bb-77f400ace0c8270=1000.00271=3.1000000010=219
20250411-01:35:30.423459000 : 8=FIXT.1.19=14235=334=3449=24ab46f784d1b20db435b852086e325052=20250411-01:35:30.42356=Coinbase45=21158=Tag appears more than once371=269372=W373=1310=034
20250411-01:35:30.423517000 : 8=FIXT.1.19=93935=W49=Coinbase56=24ab46f784d1b20db435b852086e325034=21250=TEST52=20250411-01:35:30.073170369=2262=ac9dc520-fd90-4708-a92a-3ceddd7c32a383=1597551788893=N55=BTC-USD1682=full_trading268=10269=1278=0e8d6c10-8421-4f19-97dc-d70e715d9033270=1000.00271=3.10000000269=1278=f31ecd5d-8231-44ea-a5c2-0fcc5a699401270=1000.00271=3.10000000269=1278=37fbb559-dc52-48fe-ab65-24910edc338a270=1000.00271=3.10000000269=1278=bc1435c5-c59c-4017-9e59-f1073f04c7e2270=1000.00271=3.10000000269=1278=9c8e1397-0cee-4b05-a66f-5594040791c4270=1000.00271=3.10000000269=1278=248b6703-f829-42bb-a551-4be3075c381e270=1000.00271=3.10000000269=1278=16d257b0-bc92-44f0-822d-3eba61af4bda270=1000.00271=3.10000000269=1278=06257aa1-4043-4cdb-9286-4342b8e59108270=1000.00271=3.10000000269=1278=210ec210-1443-47dc-9e43-9c9ea720a6c3270=1000.00271=3.10000000269=1278=8b79da5d-b78c-4011-b55f-b35c16dc3724270=1000.00271=3.1000000010=061
20250411-01:35:30.424053000 : 8=FIXT.1.19=14235=334=3549=24ab46f784d1b20db435b852086e325052=20250411-01:35:30.42356=Coinbase45=21258=Tag appears more than once371=269372=W373=1310=036
20250411-01:35:30.424117000 : 8=FIXT.1.19=93935=W49=Coinbase56=24ab46f784d1b20db435b852086e325034=21350=TEST52=20250411-01:35:30.073420369=2262=ac9dc520-fd90-4708-a92a-3ceddd7c32a383=1597551788893=N55=BTC-USD1682=full_trading268=10269=1278=076c3703-1104-4e15-a38a-d95bf133f0c5270=1000.00271=3.10000000269=1278=f5a3155c-e449-4102-870d-ab8c8dd24c3d270=1000.00271=3.10000000269=1278=1af2681f-2dec-4d25-aaeb-89b8867b4a3c270=1000.00271=3.10000000269=1278=65c3088d-192a-4213-85a3-7257aa8b20a3270=1000.00271=3.10000000269=1278=2aa7989b-5601-4899-8143-01dda3255e4f270=1000.00271=3.10000000269=1278=099b432c-fa2e-4fd7-952e-22f6debf6877270=1000.00271=3.10000000269=1278=2e71cc31-1235-4b7b-a728-e3335631fe5a270=1000.00271=3.10000000269=1278=ce471ffc-1e26-4afe-afab-27ee5ac8debe270=1000.00271=3.10000000269=1278=113b7fc6-8574-40eb-8682-d077245b84f2270=1000.00271=3.10000000269=1278=bcebce2c-eda8-4b85-841d-27ede39fc5a1270=1000.00271=3.1000000010=086
20250411-01:35:30.424709000 : 8=FIXT.1.19=14235=334=3649=24ab46f784d1b20db435b852086e325052=20250411-01:35:30.42456=Coinbase45=21358=Tag appears more than once371=269372=W373=1310=039
20250411-01:35:30.424784000 : 8=FIXT.1.19=93935=W49=Coinbase56=24ab46f784d1b20db435b852086e325034=21450=TEST52=20250411-01:35:30.073670369=2262=ac9dc520-fd90-4708-a92a-3ceddd7c32a383=1597551788893=N55=BTC-USD1682=full_trading268=10269=1278=0aedaae5-6cc6-4a34-8e48-5e67a5ccc148270=1000.00271=3.10000000269=1278=206e10a5-1173-4860-87b5-7c88afe061f6270=1000.00271=3.10000000269=1278=5c32d94b-696a-4d9b-afa0-665970356008270=1000.00271=3.10000000269=1278=0b7da819-cc1e-4525-a382-ce5b90dc485c270=1000.00271=3.10000000269=1278=2241b3bf-cbbe-44f2-ac75-8032f6283aa8270=1000.00271=3.10000000269=1278=88cada69-adb1-466a-afcd-66e063ad27c0270=1000.00271=3.10000000269=1278=34a52ef5-31c1-4c63-9230-21c85a9a6ba3270=1000.00271=3.10000000269=1278=e109c2c8-fb1d-4ef9-a640-368381323507270=1000.00271=3.10000000269=1278=38fd36c4-4c62-4b4c-8f24-1fe39be94fa1270=1000.00271=3.10000000269=1278=f83f64c8-7d33-472d-a516-9b664ff9c966270=1000.00271=3.1000000010=079
20250411-01:35:30.425386000 : 8=FIXT.1.19=14235=334=3749=24ab46f784d1b20db435b852086e325052=20250411-01:35:30.42556=Coinbase45=21458=Tag appears more than once371=269372=W373=1310=042
20250411-01:35:30.425465000 : 8=FIXT.1.19=93935=W49=Coinbase56=24ab46f784d1b20db435b852086e325034=21550=TEST52=20250411-01:35:30.073920369=2262=ac9dc520-fd90-4708-a92a-3ceddd7c32a383=1597551788893=N55=BTC-USD1682=full_trading268=10269=1278=3411c368-380b-42e6-b656-8552d92904d5270=1000.00271=3.10000000269=1278=4803796e-79f3-4aa4-a8cb-37f13899bf01270=1000.00271=3.10000000269=1278=823f8fbf-7e6d-4ae3-adb9-3a822ff6d09a270=1000.00271=3.10000000269=1278=135624df-a204-490f-a68b-63d74ee09908270=1000.00271=3.10000000269=1278=47cfdedf-22b9-402c-93bd-f311103fd3e0270=1000.00271=3.10000000269=1278=f9173d5e-d872-4661-93f6-28f527e931f7270=1000.00271=3.10000000269=1278=06ab1365-fd39-4701-bd7f-1915ad3c7602270=1000.00271=3.10000000269=1278=012a7c59-5ae4-4da5-97ba-2e3254c889fb270=1000.00271=3.10000000269=1278=a9a0d42f-ad9e-4ea9-8bf0-d5a441fded40270=1000.00271=3.10000000269=1278=f3f3930e-be0e-40b4-a97d-d19501a54885270=1000.00271=3.1000000010=233
20250411-01:35:30.426333000 : 8=FIXT.1.19=14235=334=3849=24ab46f784d1b20db435b852086e325052=20250411-01:35:30.42556=Coinbase45=21558=Tag appears more than once371=269372=W373=1310=044
20250411-01:35:30.426429000 : 8=FIXT.1.19=93935=W49=Coinbase56=24ab46f784d1b20db435b852086e325034=21650=TEST52=20250411-01:35:30.074170369=2262=ac9dc520-fd90-4708-a92a-3ceddd7c32a383=1597551788893=N55=BTC-USD1682=full_trading268=10269=1278=261922d0-5c81-4ab6-832f-4eff45f64890270=1000.00271=3.10000000269=1278=3af4e45f-56f6-4c69-894d-d56a14894a98270=1000.00271=3.10000000269=1278=1c1dd248-49e4-44aa-9e69-323b0f41fa0e270=1000.00271=3.10000000269=1278=b16b002d-1cd6-4869-9c1b-f15c758611bf270=1000.00271=3.10000000269=1278=a0520e61-28ad-448d-87c1-49f0c7358628270=1000.00271=3.10000000269=1278=152d0b57-086f-48cc-80b3-ff14ee9375ed270=1000.00271=3.10000000269=1278=c55fc264-67d2-4e9c-8cce-6c834feff648270=1000.00271=3.10000000269=1278=27361968-189a-4fa6-a3a2-eead03c640d6270=1000.00271=3.10000000269=1278=f5b01c67-f98f-44b9-a511-7f07f8883d9e270=1000.00271=3.10000000269=1278=75a5c14f-8434-4533-a10e-0bf6e92e1000270=1000.00271=3.1000000010=233
20250411-01:35:30.427160000 : 8=FIXT.1.19=14235=334=3949=24ab46f784d1b20db435b852086e325052=20250411-01:35:30.42656=Coinbase45=21658=Tag appears more than once371=269372=W373=1310=047
20250411-01:35:30.427266000 : 8=FIXT.1.19=93935=W49=Coinbase56=24ab46f784d1b20db435b852086e325034=21750=TEST52=20250411-01:35:30.074420369=2262=ac9dc520-fd90-4708-a92a-3ceddd7c32a383=1597551788893=N55=BTC-USD1682=full_trading268=10269=1278=a9b0a826-3659-4105-9ecc-21bcd27b736f270=1000.00271=3.10000000269=1278=1b1bab77-5c52-459b-98e3-e27ff6f8cd04270=1000.00271=3.10000000269=1278=346695f1-fe03-4364-8fc5-006796c8f82f270=1000.00271=3.10000000269=1278=cbbaa36d-2a03-45a2-a230-bd5845d832cd270=1000.00271=3.10000000269=1278=745d4fc0-6710-4c5c-97c3-7b29c4e06839270=1000.00271=3.10000000269=1278=e95fdfba-5db2-4461-8e9c-7bfdf8a9238c270=1000.00271=3.10000000269=1278=33611b39-1fbf-45cc-bf5e-a02bc1f84736270=1000.00271=3.10000000269=1278=51f77b2d-1a69-432d-934b-234eb9e1dfac270=1000.00271=3.10000000269=1278=ab09fdc3-8d50-432f-ab0f-97e8627eac24270=1000.00271=3.10000000269=1278=dde04213-6104-44c5-a811-15834c27b515270=1000.00271=3.1000000010=171
20250411-01:35:30.427996000 : 8=FIXT.1.19=14235=334=4049=24ab46f784d1b20db435b852086e325052=20250411-01:35:30.42756=Coinbase45=21758=Tag appears more than once371=269372=W373=1310=041
20250411-01:35:30.428099000 : 8=FIXT.1.19=93935=W49=Coinbase56=24ab46f784d1b20db435b852086e325034=21850=TEST52=20250411-01:35:30.074670369=2262=ac9dc520-fd90-4708-a92a-3ceddd7c32a383=1597551788893=N55=BTC-USD1682=full_trading268=10269=1278=9af2b85c-4997-4e1b-9147-7d400f059b01270=1000.00271=3.10000000269=1278=40870860-7a8a-4419-a117-e511f779abfa270=1000.00271=3.10000000269=1278=3e8fa7bd-dde0-4fe4-bb2e-e6279841b019270=1000.00271=3.10000000269=1278=4dde1422-98d8-405b-88df-bf245291ad7a270=1000.00271=3.10000000269=1278=6ee8b5a8-bc2f-4a0a-9ae4-7ff1b5dae941270=1000.00271=3.10000000269=1278=3ebc1f7a-2bb5-4ef0-a82f-844b9540f6e8270=1000.00271=3.10000000269=1278=a82d5bb9-1f1a-4575-b580-8d9b60863b10270=1000.00271=3.10000000269=1278=14f89bd5-0233-435c-b608-2e19131b8f6c270=1000.00271=3.10000000269=1278=a2e319e5-aab7-41d4-9d19-98d771a3f1d3270=1000.00271=3.10000000269=1278=dc965e0b-075a-4ba4-a498-02c96d1664ba270=1000.00271=3.1000000010=238
20250411-01:35:30.428885000 : 8=FIXT.1.19=14235=334=4149=24ab46f784d1b20db435b852086e325052=20250411-01:35:30.42856=Coinbase45=21858=Tag appears more than once371=269372=W373=1310=044
20250411-01:35:30.428974000 : 8=FIXT.1.19=93935=W49=Coinbase56=24ab46f784d1b20db435b852086e325034=21950=TEST52=20250411-01:35:30.074920369=2262=ac9dc520-fd90-4708-a92a-3ceddd7c32a383=1597551788893=N55=BTC-USD1682=full_trading268=10269=1278=67b6e68f-ac11-4c05-a54a-2adb555b0123270=1000.00271=3.10000000269=1278=866f52a1-dad9-49d7-ac4a-9da3075407a3270=1000.00271=3.10000000269=1278=0e38234d-a010-40f6-9c6f-a0d574e773cf270=1000.00271=3.10000000269=1278=d6af6749-e3c8-4938-8741-1d5f177cf8e1270=1000.00271=3.10000000269=1278=45ff5e59-2c4d-45ac-9fde-403662dfd1ca270=1000.00271=3.10000000269=1278=dcac314e-c54f-44e3-b96d-ef71539766ed270=1000.00271=3.10000000269=1278=dd6d14ea-760f-4884-a546-1d3c40ebdd7c270=1000.00271=3.10000000269=1278=4f3da0c6-46eb-4b64-b973-cc43e24abccb270=1000.00271=3.10000000269=1278=aa40cda8-4abd-4f52-999a-1a90ed5bf41a270=1000.00271=3.10000000269=1278=687ee4fc-f626-4e4f-abee-1f0ee5af3f72270=1000.00271=3.1000000010=076
20250411-01:35:30.429549000 : 8=FIXT.1.19=14235=334=4249=24ab46f784d1b20db435b852086e325052=20250411-01:35:30.42956=Coinbase45=21958=Tag appears more than once371=269372=W373=1310=047
20250411-01:35:30.429703000 : 8=FIXT.1.19=95535=W49=Coinbase56=24ab46f784d1b20db435b852086e325034=22050=TEST52=20250411-01:35:30.075170369=2262=ac9dc520-fd90-4708-a92a-3ceddd7c32a383=1597551788893=N55=BTC-USD1682=full_trading268=10269=1278=b1ad1135-67ec-4c96-99cb-a626137f3f16270=10000.00271=1.00000000269=1278=e9320f5f-80ae-41ab-af7a-86518d456fb0270=10000.00271=1.00000000269=1278=cd95aff0-36fa-4804-887f-2c3fce3cdc86270=10000.00271=1.00000000269=1278=fbdbcee1-8c29-4478-97df-358d209d8808270=10000.00271=1.00000000269=1278=140f39da-834b-4e42-8e15-6e25287df1f0270=900000.00271=0.00011111269=1278=49f064c5-76fe-4b38-bede-48b60a0a5aec270=900000.00271=0.00011111269=1278=681cf73b-9d37-4101-b940-9da9b1ff61ed270=900000.00271=0.00011111269=1278=3dea1587-e474-4258-b6e8-485c21b56670270=900000.00271=0.00011111269=1278=afd96a7b-3d48-459e-b810-e4ee88353a31270=900000.00271=0.00011111269=1278=a68ae029-b920-4ae7-a775-ccdb800fc252270=900000.00271=0.0000111110=163
20250411-01:35:30.430332000 : 8=FIXT.1.19=14235=334=4349=24ab46f784d1b20db435b852086e325052=20250411-01:35:30.42956=Coinbase45=22058=Tag appears more than once371=269372=W373=1310=040
20250411-01:35:30.430410000 : 8=FIXT.1.19=96035=W49=Coinbase56=24ab46f784d1b20db435b852086e325034=22150=TEST52=20250411-01:35:30.075420369=2262=ac9dc520-fd90-4708-a92a-3ceddd7c32a383=1597551788893=N55=BTC-USD1682=full_trading268=10269=1278=d44508b7-1c9f-4b4f-acb8-99c93d2b99e8270=900000.00271=0.00001111269=1278=304ff106-de40-4381-89c5-c93f7f3e32ae270=900000.00271=0.00001111269=1278=08a0fef8-fcbb-4857-8463-2599cf331386270=900000.00271=0.00011111269=1278=07b2856d-f899-417c-82d5-886f0d85125e270=900000.00271=0.00011111269=1278=12ecb45e-6af8-4804-a942-5c997b9d1502270=900000.00271=0.00011111269=1278=98676c5f-b851-473c-817a-b29243092a25270=900000.00271=0.00001111269=1278=09afe685-e71f-4ea0-b164-c27737db126d270=900000.00271=0.00001111269=1278=e71ee98f-c329-428d-9893-629b53015ff6270=900000.00271=0.00001111269=1278=124e6fc1-6dde-452b-be03-c00113c8ebdb270=900000.00271=0.00011111269=1278=b71cc7f5-d7c6-4fc0-a0de-59b0eb7fd063270=1000000.00271=1.0000000010=238
20250411-01:35:30.430941000 : 8=FIXT.1.19=14235=334=4449=24ab46f784d1b20db435b852086e325052=20250411-01:35:30.43056=Coinbase45=22158=Tag appears more than once371=269372=W373=1310=034
20250411-01:35:30.431089000 : 8=FIXT.1.19=42935=W49=Coinbase56=24ab46f784d1b20db435b852086e325034=22250=TEST52=20250411-01:35:30.075670369=2262=ac9dc520-fd90-4708-a92a-3ceddd7c32a383=1597551788893=Y55=BTC-USD1682=full_trading268=3269=1278=afec127b-a98c-49cb-893f-e385a7e35d32270=1000000.00271=1.00000000269=1278=06df7c57-366d-4d2c-acc2-e6c26d60e9c3270=1000000.00271=1.00000000269=1278=b1c4eb2b-90df-44e0-ae4f-515df4086a9d270=9999999.00271=0.0000100010=070
20250411-01:35:30.431826000 : 8=FIXT.1.19=14235=334=4549=24ab46f784d1b20db435b852086e325052=20250411-01:35:30.43156=Coinbase45=22258=Tag appears more than once371=269372=W373=1310=037
20250411-01:35:30.431933000 : 8=FIXT.1.19=27835=X49=Coinbase56=24ab46f784d1b20db435b852086e325034=22350=TEST52=20250411-01:35:30.165188369=2262=ac9dc520-fd90-4708-a92a-3ceddd7c32a3268=1279=0269=083=159755178955=BTC-USD29004=2.208895519560=20250411-01:35:30.16401640=137=de7dbb01-0e66-4e94-86a6-530bdef2c40a10=117
20250411-01:35:30.432309000 : 8=FIXT.1.19=32635=X49=Coinbase56=24ab46f784d1b20db435b852086e325034=22450=TEST52=20250411-01:35:30.165199369=2262=ac9dc520-fd90-4708-a92a-3ceddd7c32a3268=1279=0269=2278=c5b88ea9-605d-4595-ac52-f7c3f08523ba83=159755179055=BTC-USD270=3.55271=0.6222240960=20250411-01:35:30.16401637=de7dbb01-0e66-4e94-86a6-530bdef2c40a5797=110=001
20250411-01:35:30.432687000 : 8=FIXT.1.19=26535=X49=Coinbase56=24ab46f784d1b20db435b852086e325034=22550=TEST52=20250411-01:35:30.165204369=2262=ac9dc520-fd90-4708-a92a-3ceddd7c32a3268=1279=2269=0278=de7dbb01-0e66-4e94-86a6-530bdef2c40a83=159755179155=BTC-USD60=20250411-01:35:30.16401658=FILLED10=113
20250411-01:35:30.434108000 : 8=FIXT.1.19=27435=X49=Coinbase56=24ab46f784d1b20db435b852086e325034=22650=TEST52=20250411-01:35:30.194287369=2262=ac9dc520-fd90-4708-a92a-3ceddd7c32a3268=1279=0269=183=159755179255=BTC-USD271=0.6197183160=20250411-01:35:30.19315640=137=7b8881d7-7971-4ec7-bda4-9e7ded9eb36610=157
20250411-01:35:30.434417000 : 8=FIXT.1.19=32635=X49=Coinbase56=24ab46f784d1b20db435b852086e325034=22750=TEST52=20250411-01:35:30.194292369=2262=ac9dc520-fd90-4708-a92a-3ceddd7c32a3268=1279=0269=2278=4d60a78e-b39b-420e-b830-bc0f3f4fdde283=159755179355=BTC-USD270=3.53271=0.6197183160=20250411-01:35:30.19315637=7b8881d7-7971-4ec7-bda4-9e7ded9eb3665797=210=142
20250411-01:35:30.434627000 : 8=FIXT.1.19=28035=X49=Coinbase56=24ab46f784d1b20db435b852086e325034=22850=TEST52=20250411-01:35:30.194297369=2262=ac9dc520-fd90-4708-a92a-3ceddd7c32a3268=1279=2269=1278=7b8881d7-7971-4ec7-bda4-9e7ded9eb36683=159755179455=BTC-USD271=0.0000000060=20250411-01:35:30.19315658=FILLED10=060
20250411-01:35:31.157272000 : 8=FIXT.1.19=27935=X49=Coinbase56=24ab46f784d1b20db435b852086e325034=22950=TEST52=20250411-01:35:31.023521369=45262=ac9dc520-fd90-4708-a92a-3ceddd7c32a3268=1279=0269=083=159755179555=BTC-USD29004=2.208895519560=20250411-01:35:31.02164640=137=446f5a89-bc13-4ad4-8202-b140352b2a1f10=213
20250411-01:35:31.158291000 : 8=FIXT.1.19=32735=X49=Coinbase56=24ab46f784d1b20db435b852086e325034=23050=TEST52=20250411-01:35:31.023587369=45262=ac9dc520-fd90-4708-a92a-3ceddd7c32a3268=1279=0269=2278=c5b88ea9-605d-4595-ac52-f7c3f08523ba83=159755179655=BTC-USD270=3.55271=0.6222240960=20250411-01:35:31.02164637=446f5a89-bc13-4ad4-8202-b140352b2a1f5797=110=107
20250411-01:35:31.158763000 : 8=FIXT.1.19=26635=X49=Coinbase56=24ab46f784d1b20db435b852086e325034=23150=TEST52=20250411-01:35:31.023594369=45262=ac9dc520-fd90-4708-a92a-3ceddd7c32a3268=1279=2269=0278=446f5a89-bc13-4ad4-8202-b140352b2a1f83=159755179755=BTC-USD60=20250411-01:35:31.02164658=FILLED10=230
20250411-01:35:31.161333000 : 8=FIXT.1.19=28435=X49=Coinbase56=24ab46f784d1b20db435b852086e325034=23250=TEST52=20250411-01:35:31.040138369=45262=ac9dc520-fd90-4708-a92a-3ceddd7c32a3268=1279=0269=083=159755179855=BTC-USD270=3.83271=0.6197183160=20250411-01:35:31.03842040=237=a96fe128-e190-4ad0-8242-c34511257df510=126
20250411-01:35:31.161716000 : 8=FIXT.1.19=32735=X49=Coinbase56=24ab46f784d1b20db435b852086e325034=23350=TEST52=20250411-01:35:31.040144369=45262=ac9dc520-fd90-4708-a92a-3ceddd7c32a3268=1279=0269=2278=c5b88ea9-605d-4595-ac52-f7c3f08523ba83=159755179955=BTC-USD270=3.55271=0.6197183160=20250411-01:35:31.03842037=a96fe128-e190-4ad0-8242-c34511257df55797=110=078
20250411-01:35:31.162027000 : 8=FIXT.1.19=29035=X49=Coinbase56=24ab46f784d1b20db435b852086e325034=23450=TEST52=20250411-01:35:31.040148369=45262=ac9dc520-fd90-4708-a92a-3ceddd7c32a3268=1279=2269=0278=a96fe128-e190-4ad0-8242-c34511257df583=159755180055=BTC-USD270=3.83271=0.0000000060=20250411-01:35:31.03842058=FILLED10=010
20250411-01:35:31.175947000 : 8=FIXT.1.19=27535=X49=Coinbase56=24ab46f784d1b20db435b852086e325034=23550=TEST52=20250411-01:35:31.051277369=45262=ac9dc520-fd90-4708-a92a-3ceddd7c32a3268=1279=0269=183=159755180155=BTC-USD271=0.6232294660=20250411-01:35:31.04987740=137=c0dba626-98b2-4009-b7d3-ffd7717723c710=079
20250411-01:35:31.176681000 : 8=FIXT.1.19=32735=X49=Coinbase56=24ab46f784d1b20db435b852086e325034=23650=TEST52=20250411-01:35:31.051282369=45262=ac9dc520-fd90-4708-a92a-3ceddd7c32a3268=1279=0269=2278=4d60a78e-b39b-420e-b830-bc0f3f4fdde283=159755180255=BTC-USD270=3.53271=0.6232294660=20250411-01:35:31.04987737=c0dba626-98b2-4009-b7d3-ffd7717723c75797=210=064
20250411-01:35:31.177197000 : 8=FIXT.1.19=28135=X49=Coinbase56=24ab46f784d1b20db435b852086e325034=23750=TEST52=20250411-01:35:31.051286369=45262=ac9dc520-fd90-4708-a92a-3ceddd7c32a3268=1279=2269=1278=c0dba626-98b2-4009-b7d3-ffd7717723c783=159755180355=BTC-USD271=0.0000000060=20250411-01:35:31.04987758=FILLED10=239
20250411-01:35:31.217616000 : 8=FIXT.1.19=28335=X49=Coinbase56=24ab46f784d1b20db435b852086e325034=23850=TEST52=20250411-01:35:31.096171369=45262=ac9dc520-fd90-4708-a92a-3ceddd7c32a3268=1279=0269=183=159755180455=BTC-USD270=3.3271=0.6197183160=20250411-01:35:31.09450640=237=87c53576-b5c5-4ccf-bc55-27e0b48d576910=200
20250411-01:35:31.218272000 : 8=FIXT.1.19=32735=X49=Coinbase56=24ab46f784d1b20db435b852086e325034=23950=TEST52=20250411-01:35:31.096177369=45262=ac9dc520-fd90-4708-a92a-3ceddd7c32a3268=1279=0269=2278=4d60a78e-b39b-420e-b830-bc0f3f4fdde283=159755180555=BTC-USD270=3.53271=0.6197183160=20250411-01:35:31.09450637=87c53576-b5c5-4ccf-bc55-27e0b48d57695797=210=088
20250411-01:35:31.219990000 : 8=FIXT.1.19=28935=X49=Coinbase56=24ab46f784d1b20db435b852086e325034=24050=TEST52=20250411-01:35:31.096180369=45262=ac9dc520-fd90-4708-a92a-3ceddd7c32a3268=1279=2269=1278=87c53576-b5c5-4ccf-bc55-27e0b48d576983=159755180655=BTC-USD270=3.3271=0.0000000060=20250411-01:35:31.09450658=FILLED10=101
20250411-01:35:31.852158000 : 8=FIXT.1.19=28435=X49=Coinbase56=24ab46f784d1b20db435b852086e325034=24150=TEST52=20250411-01:35:31.727493369=45262=ac9dc520-fd90-4708-a92a-3ceddd7c32a3268=1279=0269=183=159755180755=BTC-USD270=3.35271=0.6232294660=20250411-01:35:31.72557840=237=b2a6bf34-fe14-445f-8123-7993dc9f892010=214
20250411-01:35:31.853643000 : 8=FIXT.1.19=32735=X49=Coinbase56=24ab46f784d1b20db435b852086e325034=24250=TEST52=20250411-01:35:31.727503369=45262=ac9dc520-fd90-4708-a92a-3ceddd7c32a3268=1279=0269=2278=4d60a78e-b39b-420e-b830-bc0f3f4fdde283=159755180855=BTC-USD270=3.53271=0.6232294660=20250411-01:35:31.72557837=b2a6bf34-fe14-445f-8123-7993dc9f89205797=210=034
20250411-01:35:31.855336000 : 8=FIXT.1.19=29035=X49=Coinbase56=24ab46f784d1b20db435b852086e325034=24350=TEST52=20250411-01:35:31.727508369=45262=ac9dc520-fd90-4708-a92a-3ceddd7c32a3268=1279=2269=1278=b2a6bf34-fe14-445f-8123-7993dc9f892083=159755180955=BTC-USD270=3.35271=0.0000000060=20250411-01:35:31.72557858=FILLED10=114
20250411-01:35:31.855712000 : 8=FIXT.1.19=28435=X49=Coinbase56=24ab46f784d1b20db435b852086e325034=24450=TEST52=20250411-01:35:31.727512369=45262=ac9dc520-fd90-4708-a92a-3ceddd7c32a3268=1279=0269=183=159755181055=BTC-USD270=3.24271=0.6232294660=20250411-01:35:31.72557840=237=f074fe6d-745f-4e21-a961-0d69bd9f3edb10=136
20250411-01:35:31.856293000 : 8=FIXT.1.19=32735=X49=Coinbase56=24ab46f784d1b20db435b852086e325034=24550=TEST52=20250411-01:35:31.727516369=45262=ac9dc520-fd90-4708-a92a-3ceddd7c32a3268=1279=0269=2278=4d60a78e-b39b-420e-b830-bc0f3f4fdde283=159755181155=BTC-USD270=3.53271=0.6232294660=20250411-01:35:31.72557837=f074fe6d-745f-4e21-a961-0d69bd9f3edb5797=210=226
20250411-01:35:31.856526000 : 8=FIXT.1.19=29035=X49=Coinbase56=24ab46f784d1b20db435b852086e325034=24650=TEST52=20250411-01:35:31.727520369=45262=ac9dc520-fd90-4708-a92a-3ceddd7c32a3268=1279=2269=1278=f074fe6d-745f-4e21-a961-0d69bd9f3edb83=159755181255=BTC-USD270=3.24271=0.0000000060=20250411-01:35:31.72557858=FILLED10=038
20250411-01:35:31.887717000 : 8=FIXT.1.19=27935=X49=Coinbase56=24ab46f784d1b20db435b852086e325034=24750=TEST52=20250411-01:35:31.766474369=45262=ac9dc520-fd90-4708-a92a-3ceddd7c32a3268=1279=0269=083=159755181355=BTC-USD29004=2.208895519560=20250411-01:35:31.76468740=137=07f65e9a-224e-4c25-8a32-a59252ba292210=212
20250411-01:35:31.888321000 : 8=FIXT.1.19=32735=X49=Coinbase56=24ab46f784d1b20db435b852086e325034=24850=TEST52=20250411-01:35:31.766480369=45262=ac9dc520-fd90-4708-a92a-3ceddd7c32a3268=1279=0269=2278=c5b88ea9-605d-4595-ac52-f7c3f08523ba83=159755181455=BTC-USD270=3.55271=0.6222240960=20250411-01:35:31.76468737=07f65e9a-224e-4c25-8a32-a59252ba29225797=110=100
20250411-01:35:31.888580000 : 8=FIXT.1.19=26635=X49=Coinbase56=24ab46f784d1b20db435b852086e325034=24950=TEST52=20250411-01:35:31.766485369=45262=ac9dc520-fd90-4708-a92a-3ceddd7c32a3268=1279=2269=0278=07f65e9a-224e-4c25-8a32-a59252ba292283=159755181555=BTC-USD60=20250411-01:35:31.76468758=FILLED10=230
20250411-01:35:31.916087000 : 8=FIXT.1.19=27535=X49=Coinbase56=24ab46f784d1b20db435b852086e325034=25050=TEST52=20250411-01:35:31.794953369=45262=ac9dc520-fd90-4708-a92a-3ceddd7c32a3268=1279=0269=183=159755181655=BTC-USD271=0.6232294660=20250411-01:35:31.79317840=137=9a53e15f-a635-478d-8163-d171b0be769510=007
20250411-01:35:31.916502000 : 8=FIXT.1.19=32735=X49=Coinbase56=24ab46f784d1b20db435b852086e325034=25150=TEST52=20250411-01:35:31.794961369=45262=ac9dc520-fd90-4708-a92a-3ceddd7c32a3268=1279=0269=2278=4d60a78e-b39b-420e-b830-bc0f3f4fdde283=159755181755=BTC-USD270=3.53271=0.6232294660=20250411-01:35:31.79317837=9a53e15f-a635-478d-8163-d171b0be76955797=210=251
20250411-01:35:31.916717000 : 8=FIXT.1.19=28135=X49=Coinbase56=24ab46f784d1b20db435b852086e325034=25250=TEST52=20250411-01:35:31.794965369=45262=ac9dc520-fd90-4708-a92a-3ceddd7c32a3268=1279=2269=1278=9a53e15f-a635-478d-8163-d171b0be769583=159755181855=BTC-USD271=0.0000000060=20250411-01:35:31.79317858=FILLED10=170
20250411-01:35:31.961628000 : 8=FIXT.1.19=28435=X49=Coinbase56=24ab46f784d1b20db435b852086e325034=25350=TEST52=20250411-01:35:31.841016369=45262=ac9dc520-fd90-4708-a92a-3ceddd7c32a3268=1279=0269=083=159755181955=BTC-USD270=3.71271=0.6232294660=20250411-01:35:31.83923540=237=e7d27ed2-e443-4fc2-9329-3ba623c7b17510=239
20250411-01:35:31.962353000 : 8=FIXT.1.19=32735=X49=Coinbase56=24ab46f784d1b20db435b852086e325034=25450=TEST52=20250411-01:35:31.841024369=45262=ac9dc520-fd90-4708-a92a-3ceddd7c32a3268=1279=0269=2278=c5b88ea9-605d-4595-ac52-f7c3f08523ba83=159755182055=BTC-USD270=3.55271=0.6232294660=20250411-01:35:31.83923537=e7d27ed2-e443-4fc2-9329-3ba623c7b1755797=110=187
20250411-01:35:31.962695000 : 8=FIXT.1.19=29035=X49=Coinbase56=24ab46f784d1b20db435b852086e325034=25550=TEST52=20250411-01:35:31.841028369=45262=ac9dc520-fd90-4708-a92a-3ceddd7c32a3268=1279=2269=0278=e7d27ed2-e443-4fc2-9329-3ba623c7b17583=159755182155=BTC-USD270=3.71271=0.0000000060=20250411-01:35:31.83923558=FILLED10=136
20250411-01:35:31.963109000 : 8=FIXT.1.19=28435=X49=Coinbase56=24ab46f784d1b20db435b852086e325034=25650=TEST52=20250411-01:35:31.841088369=45262=ac9dc520-fd90-4708-a92a-3ceddd7c32a3268=1279=0269=083=159755182255=BTC-USD270=3.77271=0.6232294660=20250411-01:35:31.83923540=237=5428c901-a912-4411-ab74-5fea8d8948b810=160
20250411-01:35:31.964183000 : 8=FIXT.1.19=32735=X49=Coinbase56=24ab46f784d1b20db435b852086e325034=25750=TEST52=20250411-01:35:31.841097369=45262=ac9dc520-fd90-4708-a92a-3ceddd7c32a3268=1279=0269=2278=c5b88ea9-605d-4595-ac52-f7c3f08523ba83=159755182355=BTC-USD270=3.55271=0.6232294660=20250411-01:35:31.83923537=5428c901-a912-4411-ab74-5fea8d8948b85797=110=112
20250411-01:35:31.965346000 : 8=FIXT.1.19=29035=X49=Coinbase56=24ab46f784d1b20db435b852086e325034=25850=TEST52=20250411-01:35:31.841101369=45262=ac9dc520-fd90-4708-a92a-3ceddd7c32a3268=1279=2269=0278=5428c901-a912-4411-ab74-5fea8d8948b883=159755182455=BTC-USD270=3.77271=0.0000000060=20250411-01:35:31.83923558=FILLED10=049
20250411-01:35:32.173252000 : 8=FIXT.1.19=27935=X49=Coinbase56=24ab46f784d1b20db435b852086e325034=25950=TEST52=20250411-01:35:32.052246369=45262=ac9dc520-fd90-4708-a92a-3ceddd7c32a3268=1279=0269=083=159755182555=BTC-USD29004=2.208895519560=20250411-01:35:32.05111540=137=d34ffb06-3254-496f-b7ce-140110ff82a810=023
20250411-01:35:32.173932000 : 8=FIXT.1.19=32735=X49=Coinbase56=24ab46f784d1b20db435b852086e325034=26050=TEST52=20250411-01:35:32.052255369=45262=ac9dc520-fd90-4708-a92a-3ceddd7c32a3268=1279=0269=2278=c5b88ea9-605d-4595-ac52-f7c3f08523ba83=159755182655=BTC-USD270=3.55271=0.6222240960=20250411-01:35:32.05111537=d34ffb06-3254-496f-b7ce-140110ff82a85797=110=161
20250411-01:35:32.174405000 : 8=FIXT.1.19=26635=X49=Coinbase56=24ab46f784d1b20db435b852086e325034=26150=TEST52=20250411-01:35:32.052259369=45262=ac9dc520-fd90-4708-a92a-3ceddd7c32a3268=1279=2269=0278=d34ffb06-3254-496f-b7ce-140110ff82a883=159755182755=BTC-USD60=20250411-01:35:32.05111558=FILLED10=034
20250411-01:35:32.200473000 : 8=FIXT.1.19=27535=X49=Coinbase56=24ab46f784d1b20db435b852086e325034=26250=TEST52=20250411-01:35:32.079530369=45262=ac9dc520-fd90-4708-a92a-3ceddd7c32a3268=1279=0269=183=159755182855=BTC-USD271=0.6197183160=20250411-01:35:32.07829640=137=28a38de1-9c5a-4245-be0f-955d5fb9c28510=146
20250411-01:35:32.200971000 : 8=FIXT.1.19=32735=X49=Coinbase56=24ab46f784d1b20db435b852086e325034=26350=TEST52=20250411-01:35:32.079540369=45262=ac9dc520-fd90-4708-a92a-3ceddd7c32a3268=1279=0269=2278=4d60a78e-b39b-420e-b830-bc0f3f4fdde283=159755182955=BTC-USD270=3.53271=0.6197183160=20250411-01:35:32.07829637=28a38de1-9c5a-4245-be0f-955d5fb9c2855797=210=136
20250411-01:35:32.201452000 : 8=FIXT.1.19=28135=X49=Coinbase56=24ab46f784d1b20db435b852086e325034=26450=TEST52=20250411-01:35:32.079545369=45262=ac9dc520-fd90-4708-a92a-3ceddd7c32a3268=1279=2269=1278=28a38de1-9c5a-4245-be0f-955d5fb9c28583=159755183055=BTC-USD271=0.0000000060=20250411-01:35:32.07829658=FILLED10=045
20250411-01:35:32.401533000 : 8=FIXT.1.19=27935=X49=Coinbase56=24ab46f784d1b20db435b852086e325034=26550=TEST52=20250411-01:35:32.280364369=45262=ac9dc520-fd90-4708-a92a-3ceddd7c32a3268=1279=0269=083=159755183155=BTC-USD29004=2.208895519560=20250411-01:35:32.27906040=137=91363e81-11eb-4c91-b489-3cc76c4f455710=208
20250411-01:35:32.402616000 : 8=FIXT.1.19=32735=X49=Coinbase56=24ab46f784d1b20db435b852086e325034=26650=TEST52=20250411-01:35:32.280372369=45262=ac9dc520-fd90-4708-a92a-3ceddd7c32a3268=1279=0269=2278=c5b88ea9-605d-4595-ac52-f7c3f08523ba83=159755183255=BTC-USD270=3.55271=0.6222240960=20250411-01:35:32.27906037=91363e81-11eb-4c91-b489-3cc76c4f45575797=110=098
20250411-01:35:32.403635000 : 8=FIXT.1.19=26635=X49=Coinbase56=24ab46f784d1b20db435b852086e325034=26750=TEST52=20250411-01:35:32.280376369=45262=ac9dc520-fd90-4708-a92a-3ceddd7c32a3268=1279=2269=0278=91363e81-11eb-4c91-b489-3cc76c4f455783=159755183355=BTC-USD60=20250411-01:35:32.27906058=FILLED10=227
20250411-01:35:32.418329000 : 8=FIXT.1.19=28435=X49=Coinbase56=24ab46f784d1b20db435b852086e325034=26850=TEST52=20250411-01:35:32.297130369=45262=ac9dc520-fd90-4708-a92a-3ceddd7c32a3268=1279=0269=083=159755183455=BTC-USD270=3.86271=0.6197183160=20250411-01:35:32.29614540=237=826d9c76-247e-49c5-9610-221f7c40be3f10=164
20250411-01:35:32.419708000 : 8=FIXT.1.19=32735=X49=Coinbase56=24ab46f784d1b20db435b852086e325034=26950=TEST52=20250411-01:35:32.297136369=45262=ac9dc520-fd90-4708-a92a-3ceddd7c32a3268=1279=0269=2278=c5b88ea9-605d-4595-ac52-f7c3f08523ba83=159755183555=BTC-USD270=3.55271=0.6197183160=20250411-01:35:32.29614537=826d9c76-247e-49c5-9610-221f7c40be3f5797=110=122
20250411-01:35:32.420263000 : 8=FIXT.1.19=29035=X49=Coinbase56=24ab46f784d1b20db435b852086e325034=27050=TEST52=20250411-01:35:32.297140369=45262=ac9dc520-fd90-4708-a92a-3ceddd7c32a3268=1279=2269=0278=826d9c76-247e-49c5-9610-221f7c40be3f83=159755183655=BTC-USD270=3.86271=0.0000000060=20250411-01:35:32.29614558=FILLED10=057
20250411-01:35:32.431707000 : 8=FIXT.1.19=27535=X49=Coinbase56=24ab46f784d1b20db435b852086e325034=27150=TEST52=20250411-01:35:32.309622369=45262=ac9dc520-fd90-4708-a92a-3ceddd7c32a3268=1279=0269=183=159755183755=BTC-USD271=0.6232294660=20250411-01:35:32.30797540=137=0000b8b2-b815-4982-93db-119a29942a8910=143
20250411-01:35:32.432273000 : 8=FIXT.1.19=32735=X49=Coinbase56=24ab46f784d1b20db435b852086e325034=27250=TEST52=20250411-01:35:32.309628369=45262=ac9dc520-fd90-4708-a92a-3ceddd7c32a3268=1279=0269=2278=4d60a78e-b39b-420e-b830-bc0f3f4fdde283=159755183855=BTC-USD270=3.53271=0.6232294660=20250411-01:35:32.30797537=0000b8b2-b815-4982-93db-119a29942a895797=210=138
20250411-01:35:32.432750000 : 8=FIXT.1.19=28135=X49=Coinbase56=24ab46f784d1b20db435b852086e325034=27350=TEST52=20250411-01:35:32.309631369=45262=ac9dc520-fd90-4708-a92a-3ceddd7c32a3268=1279=2269=1278=0000b8b2-b815-4982-93db-119a29942a8983=159755183955=BTC-USD271=0.0000000060=20250411-01:35:32.30797558=FILLED10=047
20250411-01:35:32.458568000 : 8=FIXT.1.19=27935=X49=Coinbase56=24ab46f784d1b20db435b852086e325034=27450=TEST52=20250411-01:35:32.336983369=45262=ac9dc520-fd90-4708-a92a-3ceddd7c32a3268=1279=0269=083=159755184055=BTC-USD29004=2.208895519560=20250411-01:35:32.33547540=137=fb9902a4-ae31-4f57-a5e2-4f60209e84bb10=093
20250411-01:35:32.459327000 : 8=FIXT.1.19=32735=X49=Coinbase56=24ab46f784d1b20db435b852086e325034=27550=TEST52=20250411-01:35:32.336990369=45262=ac9dc520-fd90-4708-a92a-3ceddd7c32a3268=1279=0269=2278=c5b88ea9-605d-4595-ac52-f7c3f08523ba83=159755184155=BTC-USD270=3.55271=0.6222240960=20250411-01:35:32.33547537=fb9902a4-ae31-4f57-a5e2-4f60209e84bb5797=110=238
20250411-01:35:32.460313000 : 8=FIXT.1.19=26635=X49=Coinbase56=24ab46f784d1b20db435b852086e325034=27650=TEST52=20250411-01:35:32.336994369=45262=ac9dc520-fd90-4708-a92a-3ceddd7c32a3268=1279=2269=0278=fb9902a4-ae31-4f57-a5e2-4f60209e84bb83=159755184255=BTC-USD60=20250411-01:35:32.33547558=FILLED10=111
20250411-01:35:32.474076000 : 8=FIXT.1.19=28435=X49=Coinbase56=24ab46f784d1b20db435b852086e325034=27750=TEST52=20250411-01:35:32.352619369=45262=ac9dc520-fd90-4708-a92a-3ceddd7c32a3268=1279=0269=183=159755184355=BTC-USD270=3.36271=0.6197183160=20250411-01:35:32.35100240=237=4b3e7ecd-27e8-4686-9319-d28413dd486d10=208
20250411-01:35:32.474334000 : 8=FIXT.1.19=32735=X49=Coinbase56=24ab46f784d1b20db435b852086e325034=27850=TEST52=20250411-01:35:32.352624369=45262=ac9dc520-fd90-4708-a92a-3ceddd7c32a3268=1279=0269=2278=4d60a78e-b39b-420e-b830-bc0f3f4fdde283=159755184455=BTC-USD270=3.53271=0.6197183160=20250411-01:35:32.35100237=4b3e7ecd-27e8-4686-9319-d28413dd486d5797=210=031
20250411-01:35:32.474879000 : 8=FIXT.1.19=29035=X49=Coinbase56=24ab46f784d1b20db435b852086e325034=27950=TEST52=20250411-01:35:32.352628369=45262=ac9dc520-fd90-4708-a92a-3ceddd7c32a3268=1279=2269=1278=4b3e7ecd-27e8-4686-9319-d28413dd486d83=159755184555=BTC-USD270=3.36271=0.0000000060=20250411-01:35:32.35100258=FILLED10=109
20250411-01:35:32.487732000 : 8=FIXT.1.19=27535=X49=Coinbase56=24ab46f784d1b20db435b852086e325034=28050=TEST52=20250411-01:35:32.367128369=45262=ac9dc520-fd90-4708-a92a-3ceddd7c32a3268=1279=0269=183=159755184655=BTC-USD271=0.6197183160=20250411-01:35:32.36542440=137=2a77bd9c-1897-4a2d-b7a8-5dabbd2be9c210=066
20250411-01:35:32.488177000 : 8=FIXT.1.19=32735=X49=Coinbase56=24ab46f784d1b20db435b852086e325034=28150=TEST52=20250411-01:35:32.367133369=45262=ac9dc520-fd90-4708-a92a-3ceddd7c32a3268=1279=0269=2278=4d60a78e-b39b-420e-b830-bc0f3f4fdde283=159755184755=BTC-USD270=3.53271=0.6197183160=20250411-01:35:32.36542437=2a77bd9c-1897-4a2d-b7a8-5dabbd2be9c25797=210=051
20250411-01:35:32.488559000 : 8=FIXT.1.19=28135=X49=Coinbase56=24ab46f784d1b20db435b852086e325034=28250=TEST52=20250411-01:35:32.367137369=45262=ac9dc520-fd90-4708-a92a-3ceddd7c32a3268=1279=2269=1278=2a77bd9c-1897-4a2d-b7a8-5dabbd2be9c283=159755184855=BTC-USD271=0.0000000060=20250411-01:35:32.36542458=FILLED10=224
20250411-01:35:32.515489000 : 8=FIXT.1.19=27935=X49=Coinbase56=24ab46f784d1b20db435b852086e325034=28350=TEST52=20250411-01:35:32.394686369=45262=ac9dc520-fd90-4708-a92a-3ceddd7c32a3268=1279=0269=083=159755184955=BTC-USD29004=2.208895519560=20250411-01:35:32.39337240=137=571805ca-1b1c-4ff5-95b8-a2802eb5b33710=054
20250411-01:35:32.515894000 : 8=FIXT.1.19=32735=X49=Coinbase56=24ab46f784d1b20db435b852086e325034=28450=TEST52=20250411-01:35:32.394691369=45262=ac9dc520-fd90-4708-a92a-3ceddd7c32a3268=1279=0269=2278=c5b88ea9-605d-4595-ac52-f7c3f08523ba83=159755185055=BTC-USD270=3.55271=0.6222240960=20250411-01:35:32.39337237=571805ca-1b1c-4ff5-95b8-a2802eb5b3375797=110=188
20250411-01:35:32.516309000 : 8=FIXT.1.19=26635=X49=Coinbase56=24ab46f784d1b20db435b852086e325034=28550=TEST52=20250411-01:35:32.394695369=45262=ac9dc520-fd90-4708-a92a-3ceddd7c32a3268=1279=2269=0278=571805ca-1b1c-4ff5-95b8-a2802eb5b33783=159755185155=BTC-USD60=20250411-01:35:32.39337258=FILLED10=061
20250411-01:35:32.546205000 : 8=FIXT.1.19=27535=X49=Coinbase56=24ab46f784d1b20db435b852086e325034=28650=TEST52=20250411-01:35:32.424826369=45262=ac9dc520-fd90-4708-a92a-3ceddd7c32a3268=1279=0269=183=159755185255=BTC-USD271=0.6232294660=20250411-01:35:32.42333440=137=10d124a1-528d-4d55-93df-97cc86398bb010=032
20250411-01:35:32.546795000 : 8=FIXT.1.19=32735=X49=Coinbase56=24ab46f784d1b20db435b852086e325034=28750=TEST52=20250411-01:35:32.424832369=45262=ac9dc520-fd90-4708-a92a-3ceddd7c32a3268=1279=0269=2278=4d60a78e-b39b-420e-b830-bc0f3f4fdde283=159755185355=BTC-USD270=3.53271=0.6232294660=20250411-01:35:32.42333437=10d124a1-528d-4d55-93df-97cc86398bb05797=210=018
20250411-01:35:32.547204000 : 8=FIXT.1.19=28135=X49=Coinbase56=24ab46f784d1b20db435b852086e325034=28850=TEST52=20250411-01:35:32.424836369=45262=ac9dc520-fd90-4708-a92a-3ceddd7c32a3268=1279=2269=1278=10d124a1-528d-4d55-93df-97cc86398bb083=159755185455=BTC-USD271=0.0000000060=20250411-01:35:32.42333458=FILLED10=193
20250411-01:35:32.858106000 : 8=FIXT.1.19=27935=X49=Coinbase56=24ab46f784d1b20db435b852086e325034=28950=TEST52=20250411-01:35:32.736440369=45262=ac9dc520-fd90-4708-a92a-3ceddd7c32a3268=1279=0269=083=159755185555=BTC-USD29004=2.208895519560=20250411-01:35:32.73536740=137=0753b9ae-a4cf-43c9-9dfe-3d8f74afd07210=004
20250411-01:35:32.858952000 : 8=FIXT.1.19=32735=X49=Coinbase56=24ab46f784d1b20db435b852086e325034=29050=TEST52=20250411-01:35:32.736448369=45262=ac9dc520-fd90-4708-a92a-3ceddd7c32a3268=1279=0269=2278=c5b88ea9-605d-4595-ac52-f7c3f08523ba83=159755185655=BTC-USD270=3.55271=0.6222240960=20250411-01:35:32.73536737=0753b9ae-a4cf-43c9-9dfe-3d8f74afd0725797=110=150
20250411-01:35:32.859514000 : 8=FIXT.1.19=26635=X49=Coinbase56=24ab46f784d1b20db435b852086e325034=29150=TEST52=20250411-01:35:32.736461369=45262=ac9dc520-fd90-4708-a92a-3ceddd7c32a3268=1279=2269=0278=0753b9ae-a4cf-43c9-9dfe-3d8f74afd07283=159755185755=BTC-USD60=20250411-01:35:32.73536758=FILLED10=014
20250411-01:35:32.888153000 : 8=FIXT.1.19=27535=X49=Coinbase56=24ab46f784d1b20db435b852086e325034=29250=TEST52=20250411-01:35:32.765866369=45262=ac9dc520-fd90-4708-a92a-3ceddd7c32a3268=1279=0269=183=159755185855=BTC-USD271=0.6232294660=20250411-01:35:32.76379040=137=5100959f-32b2-4a79-b5b1-3efd03a6b1b110=084
20250411-01:35:32.888498000 : 8=FIXT.1.19=32735=X49=Coinbase56=24ab46f784d1b20db435b852086e325034=29350=TEST52=20250411-01:35:32.765873369=45262=ac9dc520-fd90-4708-a92a-3ceddd7c32a3268=1279=0269=2278=4d60a78e-b39b-420e-b830-bc0f3f4fdde283=159755185955=BTC-USD270=3.53271=0.6232294660=20250411-01:35:32.76379037=5100959f-32b2-4a79-b5b1-3efd03a6b1b15797=210=071
20250411-01:35:32.888708000 : 8=FIXT.1.19=28135=X49=Coinbase56=24ab46f784d1b20db435b852086e325034=29450=TEST52=20250411-01:35:32.765877369=45262=ac9dc520-fd90-4708-a92a-3ceddd7c32a3268=1279=2269=1278=5100959f-32b2-4a79-b5b1-3efd03a6b1b183=159755186055=BTC-USD271=0.0000000060=20250411-01:35:32.76379058=FILLED10=237
20250411-01:35:32.915576000 : 8=FIXT.1.19=27935=X49=Coinbase56=24ab46f784d1b20db435b852086e325034=29550=TEST52=20250411-01:35:32.794332369=45262=ac9dc520-fd90-4708-a92a-3ceddd7c32a3268=1279=0269=083=159755186155=BTC-USD29004=2.208895519560=20250411-01:35:32.79251640=137=a5c7fcb4-3e83-40a5-bf07-0b46a2f7c6c310=186
20250411-01:35:32.916148000 : 8=FIXT.1.19=32735=X49=Coinbase56=24ab46f784d1b20db435b852086e325034=29650=TEST52=20250411-01:35:32.794338369=45262=ac9dc520-fd90-4708-a92a-3ceddd7c32a3268=1279=0269=2278=c5b88ea9-605d-4595-ac52-f7c3f08523ba83=159755186255=BTC-USD270=3.55271=0.6222240960=20250411-01:35:32.79251637=a5c7fcb4-3e83-40a5-bf07-0b46a2f7c6c35797=110=083
20250411-01:35:32.916367000 : 8=FIXT.1.19=26635=X49=Coinbase56=24ab46f784d1b20db435b852086e325034=29750=TEST52=20250411-01:35:32.794342369=45262=ac9dc520-fd90-4708-a92a-3ceddd7c32a3268=1279=2269=0278=a5c7fcb4-3e83-40a5-bf07-0b46a2f7c6c383=159755186355=BTC-USD60=20250411-01:35:32.79251658=FILLED10=203
20250411-01:35:32.945267000 : 8=FIXT.1.19=27535=X49=Coinbase56=24ab46f784d1b20db435b852086e325034=29850=TEST52=20250411-01:35:32.824594369=45262=ac9dc520-fd90-4708-a92a-3ceddd7c32a3268=1279=0269=183=159755186455=BTC-USD271=0.6197183160=20250411-01:35:32.82268840=137=1a236376-97b7-4380-8140-5ce947aeab6f10=016
20250411-01:35:32.945751000 : 8=FIXT.1.19=32735=X49=Coinbase56=24ab46f784d1b20db435b852086e325034=29950=TEST52=20250411-01:35:32.824599369=45262=ac9dc520-fd90-4708-a92a-3ceddd7c32a3268=1279=0269=2278=4d60a78e-b39b-420e-b830-bc0f3f4fdde283=159755186555=BTC-USD270=3.53271=0.6197183160=20250411-01:35:32.82268837=1a236376-97b7-4380-8140-5ce947aeab6f5797=210=010
20250411-01:35:32.945980000 : 8=FIXT.1.19=28135=X49=Coinbase56=24ab46f784d1b20db435b852086e325034=30050=TEST52=20250411-01:35:32.824603369=45262=ac9dc520-fd90-4708-a92a-3ceddd7c32a3268=1279=2269=1278=1a236376-97b7-4380-8140-5ce947aeab6f83=159755186655=BTC-USD271=0.0000000060=20250411-01:35:32.82268858=FILLED10=147
20250411-01:35:32.990465000 : 8=FIXT.1.19=28435=X49=Coinbase56=24ab46f784d1b20db435b852086e325034=30150=TEST52=20250411-01:35:32.868975369=45262=ac9dc520-fd90-4708-a92a-3ceddd7c32a3268=1279=0269=183=159755186755=BTC-USD270=3.27271=0.6232294660=20250411-01:35:32.86791540=237=4330fe98-e2ba-4a15-b1e7-20cd9120033710=197
20250411-01:35:32.990824000 : 8=FIXT.1.19=32735=X49=Coinbase56=24ab46f784d1b20db435b852086e325034=30250=TEST52=20250411-01:35:32.868980369=45262=ac9dc520-fd90-4708-a92a-3ceddd7c32a3268=1279=0269=2278=4d60a78e-b39b-420e-b830-bc0f3f4fdde283=159755186855=BTC-USD270=3.53271=0.6232294660=20250411-01:35:32.86791537=4330fe98-e2ba-4a15-b1e7-20cd912003375797=210=020
20250411-01:35:32.992310000 : 8=FIXT.1.19=29035=X49=Coinbase56=24ab46f784d1b20db435b852086e325034=30350=TEST52=20250411-01:35:32.868985369=45262=ac9dc520-fd90-4708-a92a-3ceddd7c32a3268=1279=2269=1278=4330fe98-e2ba-4a15-b1e7-20cd9120033783=159755186955=BTC-USD270=3.27271=0.0000000060=20250411-01:35:32.86791558=FILLED10=101
20250411-01:35:33.045611000 : 8=FIXT.1.19=28435=X49=Coinbase56=24ab46f784d1b20db435b852086e325034=30450=TEST52=20250411-01:35:32.924388369=45262=ac9dc520-fd90-4708-a92a-3ceddd7c32a3268=1279=0269=083=159755187055=BTC-USD270=3.74271=0.6232294660=20250411-01:35:32.92313240=237=a198ce11-04e6-4c2e-ba7a-efe34c1bf60f10=210
20250411-01:35:33.046654000 : 8=FIXT.1.19=32735=X49=Coinbase56=24ab46f784d1b20db435b852086e325034=30550=TEST52=20250411-01:35:32.924394369=45262=ac9dc520-fd90-4708-a92a-3ceddd7c32a3268=1279=0269=2278=c5b88ea9-605d-4595-ac52-f7c3f08523ba83=159755187155=BTC-USD270=3.55271=0.6232294660=20250411-01:35:32.92313237=a198ce11-04e6-4c2e-ba7a-efe34c1bf60f5797=110=162
20250411-01:35:33.046920000 : 8=FIXT.1.19=29035=X49=Coinbase56=24ab46f784d1b20db435b852086e325034=30650=TEST52=20250411-01:35:32.924398369=45262=ac9dc520-fd90-4708-a92a-3ceddd7c32a3268=1279=2269=0278=a198ce11-04e6-4c2e-ba7a-efe34c1bf60f83=159755187255=BTC-USD270=3.74271=0.0000000060=20250411-01:35:32.92313258=FILLED10=114
20250411-01:35:33.432693000 : 8=FIXT.1.19=27935=X49=Coinbase56=24ab46f784d1b20db435b852086e325034=30750=TEST52=20250411-01:35:33.308526369=45262=ac9dc520-fd90-4708-a92a-3ceddd7c32a3268=1279=0269=083=159755187355=BTC-USD29004=2.208895519560=20250411-01:35:33.30679640=137=54602bae-55a4-4d0b-aeee-7fdb26d7bfe910=078
20250411-01:35:33.434454000 : 8=FIXT.1.19=32735=X49=Coinbase56=24ab46f784d1b20db435b852086e325034=30850=TEST52=20250411-01:35:33.308683369=45262=ac9dc520-fd90-4708-a92a-3ceddd7c32a3268=1279=0269=2278=c5b88ea9-605d-4595-ac52-f7c3f08523ba83=159755187455=BTC-USD270=3.55271=0.6222240960=20250411-01:35:33.30679637=54602bae-55a4-4d0b-aeee-7fdb26d7bfe95797=110=229
20250411-01:35:33.434690000 : 8=FIXT.1.19=26635=X49=Coinbase56=24ab46f784d1b20db435b852086e325034=30950=TEST52=20250411-01:35:33.308837369=45262=ac9dc520-fd90-4708-a92a-3ceddd7c32a3268=1279=2269=0278=54602bae-55a4-4d0b-aeee-7fdb26d7bfe983=159755187555=BTC-USD60=20250411-01:35:33.30679658=FILLED10=099
20250411-01:35:33.458483000 : 8=FIXT.1.19=27535=X49=Coinbase56=24ab46f784d1b20db435b852086e325034=31050=TEST52=20250411-01:35:33.337218369=45262=ac9dc520-fd90-4708-a92a-3ceddd7c32a3268=1279=0269=183=159755187655=BTC-USD271=0.6197183160=20250411-01:35:33.33580040=137=abb1cb14-a595-4ab8-b827-d27dbd42158610=158
20250411-01:35:33.459290000 : 8=FIXT.1.19=32735=X49=Coinbase56=24ab46f784d1b20db435b852086e325034=31150=TEST52=20250411-01:35:33.337227369=45262=ac9dc520-fd90-4708-a92a-3ceddd7c32a3268=1279=0269=2278=4d60a78e-b39b-420e-b830-bc0f3f4fdde283=159755187755=BTC-USD270=3.53271=0.6197183160=20250411-01:35:33.33580037=abb1cb14-a595-4ab8-b827-d27dbd4215865797=210=147
20250411-01:35:33.459626000 : 8=FIXT.1.19=28135=X49=Coinbase56=24ab46f784d1b20db435b852086e325034=31250=TEST52=20250411-01:35:33.337231369=45262=ac9dc520-fd90-4708-a92a-3ceddd7c32a3268=1279=2269=1278=abb1cb14-a595-4ab8-b827-d27dbd42158683=159755187855=BTC-USD271=0.0000000060=20250411-01:35:33.33580058=FILLED10=055
20250411-01:35:33.817538000 : 8=FIXT.1.19=28435=X49=Coinbase56=24ab46f784d1b20db435b852086e325034=31350=TEST52=20250411-01:35:33.669253369=45262=ac9dc520-fd90-4708-a92a-3ceddd7c32a3268=1279=0269=183=159755187955=BTC-USD270=3.35271=0.6232294660=20250411-01:35:33.66776140=237=6f107086-cbed-4c6e-85c7-977b54aeb27110=062
20250411-01:35:33.818776000 : 8=FIXT.1.19=32735=X49=Coinbase56=24ab46f784d1b20db435b852086e325034=31450=TEST52=20250411-01:35:33.669261369=45262=ac9dc520-fd90-4708-a92a-3ceddd7c32a3268=1279=0269=2278=4d60a78e-b39b-420e-b830-bc0f3f4fdde283=159755188055=BTC-USD270=3.53271=0.6232294660=20250411-01:35:33.66776137=6f107086-cbed-4c6e-85c7-977b54aeb2715797=210=136
20250411-01:35:33.820412000 : 8=FIXT.1.19=29035=X49=Coinbase56=24ab46f784d1b20db435b852086e325034=31550=TEST52=20250411-01:35:33.669265369=45262=ac9dc520-fd90-4708-a92a-3ceddd7c32a3268=1279=2269=1278=6f107086-cbed-4c6e-85c7-977b54aeb27183=159755188155=BTC-USD270=3.35271=0.0000000060=20250411-01:35:33.66776158=FILLED10=215
20250411-01:35:33.848368000 : 8=FIXT.1.19=28335=X49=Coinbase56=24ab46f784d1b20db435b852086e325034=31650=TEST52=20250411-01:35:33.726163369=45262=ac9dc520-fd90-4708-a92a-3ceddd7c32a3268=1279=0269=083=159755188255=BTC-USD270=3.8271=0.6232294660=20250411-01:35:33.72516740=237=c3038075-cc17-4768-83eb-82448f2c1bc410=102
20250411-01:35:33.848769000 : 8=FIXT.1.19=32735=X49=Coinbase56=24ab46f784d1b20db435b852086e325034=31750=TEST52=20250411-01:35:33.726173369=45262=ac9dc520-fd90-4708-a92a-3ceddd7c32a3268=1279=0269=2278=c5b88ea9-605d-4595-ac52-f7c3f08523ba83=159755188355=BTC-USD270=3.55271=0.6232294660=20250411-01:35:33.72516737=c3038075-cc17-4768-83eb-82448f2c1bc45797=110=110
20250411-01:35:33.849006000 : 8=FIXT.1.19=28935=X49=Coinbase56=24ab46f784d1b20db435b852086e325034=31850=TEST52=20250411-01:35:33.726178369=45262=ac9dc520-fd90-4708-a92a-3ceddd7c32a3268=1279=2269=0278=c3038075-cc17-4768-83eb-82448f2c1bc483=159755188455=BTC-USD270=3.8271=0.0000000060=20250411-01:35:33.72516758=FILLED10=020
20250411-01:35:34.687648000 : 8=FIXT.1.19=27935=X49=Coinbase56=24ab46f784d1b20db435b852086e325034=31950=TEST52=20250411-01:35:34.508540369=45262=ac9dc520-fd90-4708-a92a-3ceddd7c32a3268=1279=0269=083=159755188555=BTC-USD29004=2.208895519560=20250411-01:35:34.50736740=137=8b7574fa-be6e-4e7a-8944-65f587e7c48b10=137
20250411-01:35:34.689751000 : 8=FIXT.1.19=32735=X49=Coinbase56=24ab46f784d1b20db435b852086e325034=32050=TEST52=20250411-01:35:34.508547369=45262=ac9dc520-fd90-4708-a92a-3ceddd7c32a3268=1279=0269=2278=c5b88ea9-605d-4595-ac52-f7c3f08523ba83=159755188655=BTC-USD270=3.55271=0.6222240960=20250411-01:35:34.50736737=8b7574fa-be6e-4e7a-8944-65f587e7c48b5797=110=026
20250411-01:35:34.690480000 : 8=FIXT.1.19=26635=X49=Coinbase56=24ab46f784d1b20db435b852086e325034=32150=TEST52=20250411-01:35:34.508551369=45262=ac9dc520-fd90-4708-a92a-3ceddd7c32a3268=1279=2269=0278=8b7574fa-be6e-4e7a-8944-65f587e7c48b83=159755188755=BTC-USD60=20250411-01:35:34.50736758=FILLED10=146
20250411-01:35:34.691251000 : 8=FIXT.1.19=27535=X49=Coinbase56=24ab46f784d1b20db435b852086e325034=32250=TEST52=20250411-01:35:34.537437369=45262=ac9dc520-fd90-4708-a92a-3ceddd7c32a3268=1279=0269=183=159755188855=BTC-USD271=0.6197183160=20250411-01:35:34.53579140=137=bc7ad8b9-ceee-4f8f-ba6d-c21bcc66004e10=221
20250411-01:35:34.693197000 : 8=FIXT.1.19=32735=X49=Coinbase56=24ab46f784d1b20db435b852086e325034=32350=TEST52=20250411-01:35:34.537443369=45262=ac9dc520-fd90-4708-a92a-3ceddd7c32a3268=1279=0269=2278=4d60a78e-b39b-420e-b830-bc0f3f4fdde283=159755188955=BTC-USD270=3.53271=0.6197183160=20250411-01:35:34.53579137=bc7ad8b9-ceee-4f8f-ba6d-c21bcc66004e5797=210=207
20250411-01:35:34.693571000 : 8=FIXT.1.19=28135=X49=Coinbase56=24ab46f784d1b20db435b852086e325034=32450=TEST52=20250411-01:35:34.537447369=45262=ac9dc520-fd90-4708-a92a-3ceddd7c32a3268=1279=2269=1278=bc7ad8b9-ceee-4f8f-ba6d-c21bcc66004e83=159755189055=BTC-USD271=0.0000000060=20250411-01:35:34.53579158=FILLED10=115
20250411-01:35:34.703682000 : 8=FIXT.1.19=28335=X49=Coinbase56=24ab46f784d1b20db435b852086e325034=32550=TEST52=20250411-01:35:34.582433369=45262=ac9dc520-fd90-4708-a92a-3ceddd7c32a3268=1279=0269=183=159755189155=BTC-USD270=3.3271=0.6232294660=20250411-01:35:34.58130440=237=8088e52c-fa17-4da0-9ad9-3a1750d783b410=187
20250411-01:35:34.704155000 : 8=FIXT.1.19=32735=X49=Coinbase56=24ab46f784d1b20db435b852086e325034=32650=TEST52=20250411-01:35:34.582441369=45262=ac9dc520-fd90-4708-a92a-3ceddd7c32a3268=1279=0269=2278=4d60a78e-b39b-420e-b830-bc0f3f4fdde283=159755189255=BTC-USD270=3.53271=0.6232294660=20250411-01:35:34.58130437=8088e52c-fa17-4da0-9ad9-3a1750d783b45797=210=068
20250411-01:35:34.706249000 : 8=FIXT.1.19=28935=X49=Coinbase56=24ab46f784d1b20db435b852086e325034=32750=TEST52=20250411-01:35:34.582445369=45262=ac9dc520-fd90-4708-a92a-3ceddd7c32a3268=1279=2269=1278=8088e52c-fa17-4da0-9ad9-3a1750d783b483=159755189355=BTC-USD270=3.3271=0.0000000060=20250411-01:35:34.58130458=FILLED10=102
20250411-01:35:34.760666000 : 8=FIXT.1.19=28435=X49=Coinbase56=24ab46f784d1b20db435b852086e325034=32850=TEST52=20250411-01:35:34.639676369=45262=ac9dc520-fd90-4708-a92a-3ceddd7c32a3268=1279=0269=083=159755189455=BTC-USD270=3.75271=0.6232294660=20250411-01:35:34.63836840=237=a1847edb-6125-4089-ae65-ba5fb290b61e10=061
20250411-01:35:34.761271000 : 8=FIXT.1.19=32735=X49=Coinbase56=24ab46f784d1b20db435b852086e325034=32950=TEST52=20250411-01:35:34.639686369=45262=ac9dc520-fd90-4708-a92a-3ceddd7c32a3268=1279=0269=2278=c5b88ea9-605d-4595-ac52-f7c3f08523ba83=159755189555=BTC-USD270=3.55271=0.6232294660=20250411-01:35:34.63836837=a1847edb-6125-4089-ae65-ba5fb290b61e5797=110=016
20250411-01:35:34.761509000 : 8=FIXT.1.19=29035=X49=Coinbase56=24ab46f784d1b20db435b852086e325034=33050=TEST52=20250411-01:35:34.639690369=45262=ac9dc520-fd90-4708-a92a-3ceddd7c32a3268=1279=2269=0278=a1847edb-6125-4089-ae65-ba5fb290b61e83=159755189655=BTC-USD270=3.75271=0.0000000060=20250411-01:35:34.63836858=FILLED10=207
20250411-01:35:34.817851000 : 8=FIXT.1.19=28435=X49=Coinbase56=24ab46f784d1b20db435b852086e325034=33150=TEST52=20250411-01:35:34.696290369=45262=ac9dc520-fd90-4708-a92a-3ceddd7c32a3268=1279=0269=083=159755189755=BTC-USD270=3.81271=0.6197183160=20250411-01:35:34.69551940=237=973aad6f-42c9-44c6-a283-60075777059a10=132
20250411-01:35:34.818438000 : 8=FIXT.1.19=32735=X49=Coinbase56=24ab46f784d1b20db435b852086e325034=33250=TEST52=20250411-01:35:34.696300369=45262=ac9dc520-fd90-4708-a92a-3ceddd7c32a3268=1279=0269=2278=c5b88ea9-605d-4595-ac52-f7c3f08523ba83=159755189855=BTC-USD270=3.55271=0.6197183160=20250411-01:35:34.69551937=973aad6f-42c9-44c6-a283-60075777059a5797=110=081
20250411-01:35:34.818698000 : 8=FIXT.1.19=29035=X49=Coinbase56=24ab46f784d1b20db435b852086e325034=33350=TEST52=20250411-01:35:34.696304369=45262=ac9dc520-fd90-4708-a92a-3ceddd7c32a3268=1279=2269=0278=973aad6f-42c9-44c6-a283-60075777059a83=159755189955=BTC-USD270=3.81271=0.0000000060=20250411-01:35:34.69551958=FILLED10=029
20250411-01:35:34.876242000 : 8=FIXT.1.19=28435=X49=Coinbase56=24ab46f784d1b20db435b852086e325034=33450=TEST52=20250411-01:35:34.754194369=45262=ac9dc520-fd90-4708-a92a-3ceddd7c32a3268=1279=0269=183=159755190055=BTC-USD270=3.25271=0.6197183160=20250411-01:35:34.75236840=237=6b4fe219-0fbf-4eb1-87fb-b984fa19c98d10=201
20250411-01:35:34.876616000 : 8=FIXT.1.19=32735=X49=Coinbase56=24ab46f784d1b20db435b852086e325034=33550=TEST52=20250411-01:35:34.754203369=45262=ac9dc520-fd90-4708-a92a-3ceddd7c32a3268=1279=0269=2278=4d60a78e-b39b-420e-b830-bc0f3f4fdde283=159755190155=BTC-USD270=3.53271=0.6197183160=20250411-01:35:34.75236837=6b4fe219-0fbf-4eb1-87fb-b984fa19c98d5797=210=021
20250411-01:35:34.878279000 : 8=FIXT.1.19=29035=X49=Coinbase56=24ab46f784d1b20db435b852086e325034=33650=TEST52=20250411-01:35:34.754207369=45262=ac9dc520-fd90-4708-a92a-3ceddd7c32a3268=1279=2269=1278=6b4fe219-0fbf-4eb1-87fb-b984fa19c98d83=159755190255=BTC-USD270=3.25271=0.0000000060=20250411-01:35:34.75236858=FILLED10=097
20250411-01:35:35.487453000 : 8=FIXT.1.19=27935=X49=Coinbase56=24ab46f784d1b20db435b852086e325034=33750=TEST52=20250411-01:35:35.365866369=45262=ac9dc520-fd90-4708-a92a-3ceddd7c32a3268=1279=0269=083=159755190355=BTC-USD29004=2.208895519560=20250411-01:35:35.36458140=137=ffe75e40-c420-454d-942b-8d80af851c4a10=105
20250411-01:35:35.488626000 : 8=FIXT.1.19=32735=X49=Coinbase56=24ab46f784d1b20db435b852086e325034=33850=TEST52=20250411-01:35:35.365873369=45262=ac9dc520-fd90-4708-a92a-3ceddd7c32a3268=1279=0269=2278=c5b88ea9-605d-4595-ac52-f7c3f08523ba83=159755190455=BTC-USD270=3.55271=0.6222240960=20250411-01:35:35.36458137=ffe75e40-c420-454d-942b-8d80af851c4a5797=110=250
20250411-01:35:35.488889000 : 8=FIXT.1.19=26635=X49=Coinbase56=24ab46f784d1b20db435b852086e325034=33950=TEST52=20250411-01:35:35.365877369=45262=ac9dc520-fd90-4708-a92a-3ceddd7c32a3268=1279=2269=0278=ffe75e40-c420-454d-942b-8d80af851c4a83=159755190555=BTC-USD60=20250411-01:35:35.36458158=FILLED10=123
20250411-01:35:35.514247000 : 8=FIXT.1.19=27535=X49=Coinbase56=24ab46f784d1b20db435b852086e325034=34050=TEST52=20250411-01:35:35.393532369=45262=ac9dc520-fd90-4708-a92a-3ceddd7c32a3268=1279=0269=183=159755190655=BTC-USD271=0.6232294660=20250411-01:35:35.39250640=137=810baaaf-cfa7-49d2-a5c2-d210df78a36510=255
20250411-01:35:35.514807000 : 8=FIXT.1.19=32735=X49=Coinbase56=24ab46f784d1b20db435b852086e325034=34150=TEST52=20250411-01:35:35.393538369=45262=ac9dc520-fd90-4708-a92a-3ceddd7c32a3268=1279=0269=2278=4d60a78e-b39b-420e-b830-bc0f3f4fdde283=159755190755=BTC-USD270=3.53271=0.6232294660=20250411-01:35:35.39250637=810baaaf-cfa7-49d2-a5c2-d210df78a3655797=210=250
20250411-01:35:35.515156000 : 8=FIXT.1.19=28135=X49=Coinbase56=24ab46f784d1b20db435b852086e325034=34250=TEST52=20250411-01:35:35.393542369=45262=ac9dc520-fd90-4708-a92a-3ceddd7c32a3268=1279=2269=1278=810baaaf-cfa7-49d2-a5c2-d210df78a36583=159755190855=BTC-USD271=0.0000000060=20250411-01:35:35.39250658=FILLED10=160
20250411-01:35:35.715152000 : 8=FIXT.1.19=27935=X49=Coinbase56=24ab46f784d1b20db435b852086e325034=34350=TEST52=20250411-01:35:35.594408369=45262=ac9dc520-fd90-4708-a92a-3ceddd7c32a3268=1279=0269=083=159755190955=BTC-USD29004=2.208895519560=20250411-01:35:35.59310040=137=6ac866c8-1aea-4297-83b1-af33f2e9525c10=100
20250411-01:35:35.715712000 : 8=FIXT.1.19=32735=X49=Coinbase56=24ab46f784d1b20db435b852086e325034=34450=TEST52=20250411-01:35:35.594413369=45262=ac9dc520-fd90-4708-a92a-3ceddd7c32a3268=1279=0269=2278=c5b88ea9-605d-4595-ac52-f7c3f08523ba83=159755191055=BTC-USD270=3.55271=0.6222240960=20250411-01:35:35.59310037=6ac866c8-1aea-4297-83b1-af33f2e9525c5797=110=234
20250411-01:35:35.715920000 : 8=FIXT.1.19=26635=X49=Coinbase56=24ab46f784d1b20db435b852086e325034=34550=TEST52=20250411-01:35:35.594417369=45262=ac9dc520-fd90-4708-a92a-3ceddd7c32a3268=1279=2269=0278=6ac866c8-1aea-4297-83b1-af33f2e9525c83=159755191155=BTC-USD60=20250411-01:35:35.59310058=FILLED10=107
20250411-01:35:35.744917000 : 8=FIXT.1.19=27535=X49=Coinbase56=24ab46f784d1b20db435b852086e325034=34650=TEST52=20250411-01:35:35.623188369=45262=ac9dc520-fd90-4708-a92a-3ceddd7c32a3268=1279=0269=183=159755191255=BTC-USD271=0.6232294660=20250411-01:35:35.62168640=137=7fb07f3f-fb8a-4b79-ba1e-c6b85ade27b910=130
20250411-01:35:35.745319000 : 8=FIXT.1.19=32735=X49=Coinbase56=24ab46f784d1b20db435b852086e325034=34750=TEST52=20250411-01:35:35.623193369=45262=ac9dc520-fd90-4708-a92a-3ceddd7c32a3268=1279=0269=2278=4d60a78e-b39b-420e-b830-bc0f3f4fdde283=159755191355=BTC-USD270=3.53271=0.6232294660=20250411-01:35:35.62168637=7fb07f3f-fb8a-4b79-ba1e-c6b85ade27b95797=210=115
20250411-01:35:35.745581000 : 8=FIXT.1.19=28135=X49=Coinbase56=24ab46f784d1b20db435b852086e325034=34850=TEST52=20250411-01:35:35.623198369=45262=ac9dc520-fd90-4708-a92a-3ceddd7c32a3268=1279=2269=1278=7fb07f3f-fb8a-4b79-ba1e-c6b85ade27b983=159755191455=BTC-USD271=0.0000000060=20250411-01:35:35.62168658=FILLED10=035
20250411-01:35:36.534232000 : 8=FIXT.1.19=28335=X49=Coinbase56=24ab46f784d1b20db435b852086e325034=34950=TEST52=20250411-01:35:36.411543369=45262=ac9dc520-fd90-4708-a92a-3ceddd7c32a3268=1279=0269=083=159755191555=BTC-USD270=3.8271=0.6232294660=20250411-01:35:36.41030940=237=64ca6acc-29cd-4b20-86b6-7cff3ff45da710=173
20250411-01:35:36.535479000 : 8=FIXT.1.19=32735=X49=Coinbase56=24ab46f784d1b20db435b852086e325034=35050=TEST52=20250411-01:35:36.411555369=45262=ac9dc520-fd90-4708-a92a-3ceddd7c32a3268=1279=0269=2278=c5b88ea9-605d-4595-ac52-f7c3f08523ba83=159755191655=BTC-USD270=3.55271=0.6232294660=20250411-01:35:36.41030937=64ca6acc-29cd-4b20-86b6-7cff3ff45da75797=110=174
20250411-01:35:36.536062000 : 8=FIXT.1.19=28935=X49=Coinbase56=24ab46f784d1b20db435b852086e325034=35150=TEST52=20250411-01:35:36.411560369=45262=ac9dc520-fd90-4708-a92a-3ceddd7c32a3268=1279=2269=0278=64ca6acc-29cd-4b20-86b6-7cff3ff45da783=159755191755=BTC-USD270=3.8271=0.0000000060=20250411-01:35:36.41030958=FILLED10=075
20250411-01:35:36.588026000 : 8=FIXT.1.19=28435=X49=Coinbase56=24ab46f784d1b20db435b852086e325034=35250=TEST52=20250411-01:35:36.467236369=45262=ac9dc520-fd90-4708-a92a-3ceddd7c32a3268=1279=0269=183=159755191855=BTC-USD270=3.29271=0.6232294660=20250411-01:35:36.46608440=237=1ac616ef-6a81-45c4-bbcb-9234d87f313f10=093
20250411-01:35:36.590944000 : 8=FIXT.1.19=32735=X49=Coinbase56=24ab46f784d1b20db435b852086e325034=35350=TEST52=20250411-01:35:36.467243369=45262=ac9dc520-fd90-4708-a92a-3ceddd7c32a3268=1279=0269=2278=4d60a78e-b39b-420e-b830-bc0f3f4fdde283=159755191955=BTC-USD270=3.53271=0.6232294660=20250411-01:35:36.46608437=1ac616ef-6a81-45c4-bbcb-9234d87f313f5797=210=172
20250411-01:35:36.592213000 : 8=FIXT.1.19=29035=X49=Coinbase56=24ab46f784d1b20db435b852086e325034=35450=TEST52=20250411-01:35:36.467248369=45262=ac9dc520-fd90-4708-a92a-3ceddd7c32a3268=1279=2269=1278=1ac616ef-6a81-45c4-bbcb-9234d87f313f83=159755192055=BTC-USD270=3.29271=0.0000000060=20250411-01:35:36.46608458=FILLED10=246
20250411-01:35:36.744741000 : 8=FIXT.1.19=27935=X49=Coinbase56=24ab46f784d1b20db435b852086e325034=35550=TEST52=20250411-01:35:36.623274369=45262=ac9dc520-fd90-4708-a92a-3ceddd7c32a3268=1279=0269=083=159755192155=BTC-USD29004=2.208895519560=20250411-01:35:36.62144540=137=8ff3bdcc-f06d-4731-8464-89b453d8c22610=058
20250411-01:35:36.745550000 : 8=FIXT.1.19=32735=X49=Coinbase56=24ab46f784d1b20db435b852086e325034=35650=TEST52=20250411-01:35:36.623281369=45262=ac9dc520-fd90-4708-a92a-3ceddd7c32a3268=1279=0269=2278=c5b88ea9-605d-4595-ac52-f7c3f08523ba83=159755192255=BTC-USD270=3.55271=0.6222240960=20250411-01:35:36.62144537=8ff3bdcc-f06d-4731-8464-89b453d8c2265797=110=203
20250411-01:35:36.745773000 : 8=FIXT.1.19=26635=X49=Coinbase56=24ab46f784d1b20db435b852086e325034=35750=TEST52=20250411-01:35:36.623286369=45262=ac9dc520-fd90-4708-a92a-3ceddd7c32a3268=1279=2269=0278=8ff3bdcc-f06d-4731-8464-89b453d8c22683=159755192355=BTC-USD60=20250411-01:35:36.62144558=FILLED10=077
20250411-01:35:36.774750000 : 8=FIXT.1.19=27535=X49=Coinbase56=24ab46f784d1b20db435b852086e325034=35850=TEST52=20250411-01:35:36.651586369=45262=ac9dc520-fd90-4708-a92a-3ceddd7c32a3268=1279=0269=183=159755192455=BTC-USD271=0.6232294660=20250411-01:35:36.65022040=137=ea0b7342-ccf7-4885-aca5-fcfee035eea310=113
20250411-01:35:36.775548000 : 8=FIXT.1.19=32735=X49=Coinbase56=24ab46f784d1b20db435b852086e325034=35950=TEST52=20250411-01:35:36.651593369=45262=ac9dc520-fd90-4708-a92a-3ceddd7c32a3268=1279=0269=2278=4d60a78e-b39b-420e-b830-bc0f3f4fdde283=159755192555=BTC-USD270=3.53271=0.6232294660=20250411-01:35:36.65022037=ea0b7342-ccf7-4885-aca5-fcfee035eea35797=210=100
20250411-01:35:36.776120000 : 8=FIXT.1.19=28135=X49=Coinbase56=24ab46f784d1b20db435b852086e325034=36050=TEST52=20250411-01:35:36.651597369=45262=ac9dc520-fd90-4708-a92a-3ceddd7c32a3268=1279=2269=1278=ea0b7342-ccf7-4885-aca5-fcfee035eea383=159755192655=BTC-USD271=0.0000000060=20250411-01:35:36.65022058=FILLED10=010
20250411-01:35:36.972665000 : 8=FIXT.1.19=27935=X49=Coinbase56=24ab46f784d1b20db435b852086e325034=36150=TEST52=20250411-01:35:36.851306369=45262=ac9dc520-fd90-4708-a92a-3ceddd7c32a3268=1279=0269=083=159755192755=BTC-USD29004=2.208895519560=20250411-01:35:36.85027640=137=7093fb21-36dc-4de8-9eda-262ba1c9c70a10=189
20250411-01:35:36.973272000 : 8=FIXT.1.19=32735=X49=Coinbase56=24ab46f784d1b20db435b852086e325034=36250=TEST52=20250411-01:35:36.851315369=45262=ac9dc520-fd90-4708-a92a-3ceddd7c32a3268=1279=0269=2278=c5b88ea9-605d-4595-ac52-f7c3f08523ba83=159755192855=BTC-USD270=3.55271=0.6222240960=20250411-01:35:36.85027637=7093fb21-36dc-4de8-9eda-262ba1c9c70a5797=110=080
20250411-01:35:36.973544000 : 8=FIXT.1.19=26635=X49=Coinbase56=24ab46f784d1b20db435b852086e325034=36350=TEST52=20250411-01:35:36.851319369=45262=ac9dc520-fd90-4708-a92a-3ceddd7c32a3268=1279=2269=0278=7093fb21-36dc-4de8-9eda-262ba1c9c70a83=159755192955=BTC-USD60=20250411-01:35:36.85027658=FILLED10=209
20250411-01:35:37.002053000 : 8=FIXT.1.19=27535=X49=Coinbase56=24ab46f784d1b20db435b852086e325034=36450=TEST52=20250411-01:35:36.880869369=45262=ac9dc520-fd90-4708-a92a-3ceddd7c32a3268=1279=0269=183=159755193055=BTC-USD271=0.6232294660=20250411-01:35:36.87947540=137=657ee6a2-7008-4984-b220-5b83644377c810=142
20250411-01:35:37.002659000 : 8=FIXT.1.19=32735=X49=Coinbase56=24ab46f784d1b20db435b852086e325034=36550=TEST52=20250411-01:35:36.880877369=45262=ac9dc520-fd90-4708-a92a-3ceddd7c32a3268=1279=0269=2278=4d60a78e-b39b-420e-b830-bc0f3f4fdde283=159755193155=BTC-USD270=3.53271=0.6232294660=20250411-01:35:36.87947537=657ee6a2-7008-4984-b220-5b83644377c85797=210=130
20250411-01:35:37.003203000 : 8=FIXT.1.19=28135=X49=Coinbase56=24ab46f784d1b20db435b852086e325034=36650=TEST52=20250411-01:35:36.880881369=45262=ac9dc520-fd90-4708-a92a-3ceddd7c32a3268=1279=2269=1278=657ee6a2-7008-4984-b220-5b83644377c883=159755193255=BTC-USD271=0.0000000060=20250411-01:35:36.87947558=FILLED10=040
20250411-01:35:37.033751000 : 8=FIXT.1.19=27935=X49=Coinbase56=24ab46f784d1b20db435b852086e325034=36750=TEST52=20250411-01:35:36.909196369=45262=ac9dc520-fd90-4708-a92a-3ceddd7c32a3268=1279=0269=083=159755193355=BTC-USD29004=2.208895519560=20250411-01:35:36.90730740=137=c53f6c6a-4c72-402e-9ac1-4cb8957803ad10=110
20250411-01:35:37.034992000 : 8=FIXT.1.19=32735=X49=Coinbase56=24ab46f784d1b20db435b852086e325034=36850=TEST52=20250411-01:35:36.909202369=45262=ac9dc520-fd90-4708-a92a-3ceddd7c32a3268=1279=0269=2278=c5b88ea9-605d-4595-ac52-f7c3f08523ba83=159755193455=BTC-USD270=3.55271=0.6222240960=20250411-01:35:36.90730737=c53f6c6a-4c72-402e-9ac1-4cb8957803ad5797=110=245
20250411-01:35:37.035933000 : 8=FIXT.1.19=26635=X49=Coinbase56=24ab46f784d1b20db435b852086e325034=36950=TEST52=20250411-01:35:36.909206369=45262=ac9dc520-fd90-4708-a92a-3ceddd7c32a3268=1279=2269=0278=c53f6c6a-4c72-402e-9ac1-4cb8957803ad83=159755193555=BTC-USD60=20250411-01:35:36.90730758=FILLED10=118
20250411-01:35:37.058231000 : 8=FIXT.1.19=27535=X49=Coinbase56=24ab46f784d1b20db435b852086e325034=37050=TEST52=20250411-01:35:36.937050369=45262=ac9dc520-fd90-4708-a92a-3ceddd7c32a3268=1279=0269=183=159755193655=BTC-USD271=0.6197183160=20250411-01:35:36.93584140=137=c06b1970-10d1-4a9a-9507-c47a35f22bb110=023
20250411-01:35:37.059069000 : 8=FIXT.1.19=32735=X49=Coinbase56=24ab46f784d1b20db435b852086e325034=37150=TEST52=20250411-01:35:36.937056369=45262=ac9dc520-fd90-4708-a92a-3ceddd7c32a3268=1279=0269=2278=4d60a78e-b39b-420e-b830-bc0f3f4fdde283=159755193755=BTC-USD270=3.53271=0.6197183160=20250411-01:35:36.93584137=c06b1970-10d1-4a9a-9507-c47a35f22bb15797=210=018
20250411-01:35:37.059463000 : 8=FIXT.1.19=28135=X49=Coinbase56=24ab46f784d1b20db435b852086e325034=37250=TEST52=20250411-01:35:36.937068369=45262=ac9dc520-fd90-4708-a92a-3ceddd7c32a3268=1279=2269=1278=c06b1970-10d1-4a9a-9507-c47a35f22bb183=159755193855=BTC-USD271=0.0000000060=20250411-01:35:36.93584158=FILLED10=190
20250411-01:35:37.106011000 : 8=FIXT.1.19=28435=X49=Coinbase56=24ab46f784d1b20db435b852086e325034=37350=TEST52=20250411-01:35:36.984714369=45262=ac9dc520-fd90-4708-a92a-3ceddd7c32a3268=1279=0269=183=159755193955=BTC-USD270=3.29271=0.6232294660=20250411-01:35:36.98345440=237=96ade025-60ab-4c76-ba44-b62f3920090910=215
20250411-01:35:37.106685000 : 8=FIXT.1.19=32735=X49=Coinbase56=24ab46f784d1b20db435b852086e325034=37450=TEST52=20250411-01:35:36.984722369=45262=ac9dc520-fd90-4708-a92a-3ceddd7c32a3268=1279=0269=2278=4d60a78e-b39b-420e-b830-bc0f3f4fdde283=159755194055=BTC-USD270=3.53271=0.6232294660=20250411-01:35:36.98345437=96ade025-60ab-4c76-ba44-b62f392009095797=210=030
20250411-01:35:37.108148000 : 8=FIXT.1.19=29035=X49=Coinbase56=24ab46f784d1b20db435b852086e325034=37550=TEST52=20250411-01:35:36.984726369=45262=ac9dc520-fd90-4708-a92a-3ceddd7c32a3268=1279=2269=1278=96ade025-60ab-4c76-ba44-b62f3920090983=159755194155=BTC-USD270=3.29271=0.0000000060=20250411-01:35:36.98345458=FILLED10=112
20250411-01:35:37.159490000 : 8=FIXT.1.19=28435=X49=Coinbase56=24ab46f784d1b20db435b852086e325034=37650=TEST52=20250411-01:35:37.038314369=45262=ac9dc520-fd90-4708-a92a-3ceddd7c32a3268=1279=0269=083=159755194255=BTC-USD270=3.85271=0.6232294660=20250411-01:35:37.03656140=237=6c862657-c547-48c9-97a7-510ef983b9d810=143
20250411-01:35:37.160007000 : 8=FIXT.1.19=32735=X49=Coinbase56=24ab46f784d1b20db435b852086e325034=37750=TEST52=20250411-01:35:37.038322369=45262=ac9dc520-fd90-4708-a92a-3ceddd7c32a3268=1279=0269=2278=c5b88ea9-605d-4595-ac52-f7c3f08523ba83=159755194355=BTC-USD270=3.55271=0.6232294660=20250411-01:35:37.03656137=6c862657-c547-48c9-97a7-510ef983b9d85797=110=095
20250411-01:35:37.160354000 : 8=FIXT.1.19=29035=X49=Coinbase56=24ab46f784d1b20db435b852086e325034=37850=TEST52=20250411-01:35:37.038326369=45262=ac9dc520-fd90-4708-a92a-3ceddd7c32a3268=1279=2269=0278=6c862657-c547-48c9-97a7-510ef983b9d883=159755194455=BTC-USD270=3.85271=0.0000000060=20250411-01:35:37.03656158=FILLED10=049
20250411-01:35:37.333710000 : 8=FIXT.1.19=28435=X49=Coinbase56=24ab46f784d1b20db435b852086e325034=37950=TEST52=20250411-01:35:37.212576369=45262=ac9dc520-fd90-4708-a92a-3ceddd7c32a3268=1279=0269=183=159755194555=BTC-USD270=3.24271=0.6197183160=20250411-01:35:37.21076840=237=d7d3eb10-b4e8-4f4c-91e8-617e632d553a10=051
20250411-01:35:37.335428000 : 8=FIXT.1.19=8435=534=4649=24ab46f784d1b20db435b852086e325052=20250411-01:35:37.33456=Coinbase10=169
20250411-01:35:37.335638000 : 8=FIXT.1.19=32735=X49=Coinbase56=24ab46f784d1b20db435b852086e325034=38050=TEST52=20250411-01:35:37.212585369=45262=ac9dc520-fd90-4708-a92a-3ceddd7c32a3268=1279=0269=2278=4d60a78e-b39b-420e-b830-bc0f3f4fdde283=159755194655=BTC-USD270=3.53271=0.6197183160=20250411-01:35:37.21076837=d7d3eb10-b4e8-4f4c-91e8-617e632d553a5797=210=128
20250411-01:35:37.336448000 : 8=FIXT.1.19=29035=X49=Coinbase56=24ab46f784d1b20db435b852086e325034=38150=TEST52=20250411-01:35:37.212590369=45262=ac9dc520-fd90-4708-a92a-3ceddd7c32a3268=1279=2269=1278=d7d3eb10-b4e8-4f4c-91e8-617e632d553a83=159755194755=BTC-USD270=3.24271=0.0000000060=20250411-01:35:37.21076858=FILLED10=195
20250411-01:35:37.387762000 : 8=FIXT.1.19=28435=X49=Coinbase56=24ab46f784d1b20db435b852086e325034=38250=TEST52=20250411-01:35:37.266642369=45262=ac9dc520-fd90-4708-a92a-3ceddd7c32a3268=1279=0269=083=159755194855=BTC-USD270=3.76271=0.6197183160=20250411-01:35:37.26544240=237=13b3fcad-6237-4ab0-965c-66f3edd116e410=093
20250411-01:35:37.388343000 : 8=FIXT.1.19=32735=X49=Coinbase56=24ab46f784d1b20db435b852086e325034=38350=TEST52=20250411-01:35:37.266650369=45262=ac9dc520-fd90-4708-a92a-3ceddd7c32a3268=1279=0269=2278=c5b88ea9-605d-4595-ac52-f7c3f08523ba83=159755194955=BTC-USD270=3.55271=0.6197183160=20250411-01:35:37.26544237=13b3fcad-6237-4ab0-965c-66f3edd116e45797=110=045
20250411-01:35:37.388527000 : 8=FIXT.1.19=29035=X49=Coinbase56=24ab46f784d1b20db435b852086e325034=38450=TEST52=20250411-01:35:37.266654369=45262=ac9dc520-fd90-4708-a92a-3ceddd7c32a3268=1279=2269=0278=13b3fcad-6237-4ab0-965c-66f3edd116e483=159755195055=BTC-USD270=3.76271=0.0000000060=20250411-01:35:37.26544258=FILLED10=244
20250411-01:35:37.610717000 : 8=FIXT.1.19=12035=549=Coinbase56=24ab46f784d1b20db435b852086e325034=38550=TEST52=20250411-01:35:37.443285369=4558=CLIENT_LOGOUT10=117
20250411-01:37:29.103397000 : 8=FIXT.1.19=21535=A34=149=24ab46f784d1b20db435b852086e325052=20250411-01:37:29.09056=Coinbase95=4496=KxJrqxjx+bj2MfqybNWIdh5MXG4gJGOZ92BvgeD5X6g=98=0108=30141=Y553=24ab46f784d1b20db435b852086e3250554=akmwnltyfgb1137=910=050
20250411-01:37:29.401513000 : 8=FIXT.1.19=12535=A49=Coinbase56=24ab46f784d1b20db435b852086e325034=150=TEST52=20250411-01:37:29.232883369=198=0108=30141=Y1137=910=200
20250411-01:37:30.786919000 : 8=FIXT.1.19=17835=V34=249=24ab46f784d1b20db435b852086e325052=20250411-01:37:30.78456=Coinbase1128=9146=155=BTC-USD262=363048e5-e368-48b6-a6d9-193fe7c5bbb6263=1264=0267=2269=0269=110=034
20250411-01:37:31.068215000 : 8=FIXT.1.19=27635=X49=Coinbase56=24ab46f784d1b20db435b852086e325034=250=TEST52=20250411-01:37:30.942446369=2262=363048e5-e368-48b6-a6d9-193fe7c5bbb6268=1279=0269=083=159755418555=BTC-USD29004=2.208895519560=20250411-01:37:30.94081540=137=087e319a-1c9c-4cb5-aced-b4bf4446a4c110=157
20250411-01:37:31.069404000 : 8=FIXT.1.19=32435=X49=Coinbase56=24ab46f784d1b20db435b852086e325034=350=TEST52=20250411-01:37:30.942452369=2262=363048e5-e368-48b6-a6d9-193fe7c5bbb6268=1279=0269=2278=c5b88ea9-605d-4595-ac52-f7c3f08523ba83=159755418655=BTC-USD270=3.55271=0.6222240960=20250411-01:37:30.94081537=087e319a-1c9c-4cb5-aced-b4bf4446a4c15797=110=045
20250411-01:37:31.071857000 : 8=FIXT.1.19=26335=X49=Coinbase56=24ab46f784d1b20db435b852086e325034=450=TEST52=20250411-01:37:30.942457369=2262=363048e5-e368-48b6-a6d9-193fe7c5bbb6268=1279=2269=0278=087e319a-1c9c-4cb5-aced-b4bf4446a4c183=159755418755=BTC-USD60=20250411-01:37:30.94081558=FILLED10=175
20250411-01:37:31.091976000 : 8=FIXT.1.19=27235=X49=Coinbase56=24ab46f784d1b20db435b852086e325034=550=TEST52=20250411-01:37:30.969030369=2262=363048e5-e368-48b6-a6d9-193fe7c5bbb6268=1279=0269=183=159755418855=BTC-USD271=0.6232294660=20250411-01:37:30.96699440=137=af9cdb1f-74ff-4db1-93f3-7b922a72c66e10=234
20250411-01:37:31.092810000 : 8=FIXT.1.19=32435=X49=Coinbase56=24ab46f784d1b20db435b852086e325034=650=TEST52=20250411-01:37:30.969037369=2262=363048e5-e368-48b6-a6d9-193fe7c5bbb6268=1279=0269=2278=4d60a78e-b39b-420e-b830-bc0f3f4fdde283=159755418955=BTC-USD270=3.53271=0.6232294660=20250411-01:37:30.96699437=af9cdb1f-74ff-4db1-93f3-7b922a72c66e5797=210=230
20250411-01:37:31.093354000 : 8=FIXT.1.19=27835=X49=Coinbase56=24ab46f784d1b20db435b852086e325034=750=TEST52=20250411-01:37:30.969041369=2262=363048e5-e368-48b6-a6d9-193fe7c5bbb6268=1279=2269=1278=af9cdb1f-74ff-4db1-93f3-7b922a72c66e83=159755419055=BTC-USD271=0.0000000060=20250411-01:37:30.96699458=FILLED10=140
20250411-01:37:31.111372000 : 8=FIXT.1.19=28135=X49=Coinbase56=24ab46f784d1b20db435b852086e325034=850=TEST52=20250411-01:37:30.988850369=2262=363048e5-e368-48b6-a6d9-193fe7c5bbb6268=1279=0269=183=159755419155=BTC-USD270=3.34271=0.6232294660=20250411-01:37:30.98701840=237=bc606869-0107-47ef-b813-9a2ce5450df210=143
20250411-01:37:31.111961000 : 8=FIXT.1.19=32435=X49=Coinbase56=24ab46f784d1b20db435b852086e325034=950=TEST52=20250411-01:37:30.988855369=2262=363048e5-e368-48b6-a6d9-193fe7c5bbb6268=1279=0269=2278=4d60a78e-b39b-420e-b830-bc0f3f4fdde283=159755419255=BTC-USD270=3.53271=0.6232294660=20250411-01:37:30.98701837=bc606869-0107-47ef-b813-9a2ce5450df25797=210=233
20250411-01:37:31.112218000 : 8=FIXT.1.19=28835=X49=Coinbase56=24ab46f784d1b20db435b852086e325034=1050=TEST52=20250411-01:37:30.988859369=2262=363048e5-e368-48b6-a6d9-193fe7c5bbb6268=1279=2269=1278=bc606869-0107-47ef-b813-9a2ce5450df283=159755419355=BTC-USD270=3.34271=0.0000000060=20250411-01:37:30.98701858=FILLED10=104
20250411-01:37:31.171862000 : 8=FIXT.1.19=28135=X49=Coinbase56=24ab46f784d1b20db435b852086e325034=1150=TEST52=20250411-01:37:31.043981369=2262=363048e5-e368-48b6-a6d9-193fe7c5bbb6268=1279=0269=083=159755419455=BTC-USD270=3.8271=0.6232294660=20250411-01:37:31.04245740=237=398edb9f-b49c-4ca5-8b36-6d6b0869189410=195
20250411-01:37:31.172247000 : 8=FIXT.1.19=32535=X49=Coinbase56=24ab46f784d1b20db435b852086e325034=1250=TEST52=20250411-01:37:31.043989369=2262=363048e5-e368-48b6-a6d9-193fe7c5bbb6268=1279=0269=2278=c5b88ea9-605d-4595-ac52-f7c3f08523ba83=159755419555=BTC-USD270=3.55271=0.6232294660=20250411-01:37:31.04245737=398edb9f-b49c-4ca5-8b36-6d6b086918945797=110=210
20250411-01:37:31.172421000 : 8=FIXT.1.19=28735=X49=Coinbase56=24ab46f784d1b20db435b852086e325034=1350=TEST52=20250411-01:37:31.043993369=2262=363048e5-e368-48b6-a6d9-193fe7c5bbb6268=1279=2269=0278=398edb9f-b49c-4ca5-8b36-6d6b0869189483=159755419655=BTC-USD270=3.8271=0.0000000060=20250411-01:37:31.04245758=FILLED10=110
20250411-01:37:31.235041000 : 8=FIXT.1.19=27735=X49=Coinbase56=24ab46f784d1b20db435b852086e325034=1450=TEST52=20250411-01:37:31.111431369=2262=363048e5-e368-48b6-a6d9-193fe7c5bbb6268=1279=0269=083=159755419755=BTC-USD29004=2.208895519560=20250411-01:37:31.10959040=137=6a0f8d11-9770-454f-ab74-ec55b6b5cf7a10=112
20250411-01:37:31.235638000 : 8=FIXT.1.19=32535=X49=Coinbase56=24ab46f784d1b20db435b852086e325034=1550=TEST52=20250411-01:37:31.111436369=2262=363048e5-e368-48b6-a6d9-193fe7c5bbb6268=1279=0269=2278=c5b88ea9-605d-4595-ac52-f7c3f08523ba83=159755419855=BTC-USD270=3.55271=0.6222240960=20250411-01:37:31.10959037=6a0f8d11-9770-454f-ab74-ec55b6b5cf7a5797=110=008
20250411-01:37:31.235910000 : 8=FIXT.1.19=26435=X49=Coinbase56=24ab46f784d1b20db435b852086e325034=1650=TEST52=20250411-01:37:31.111440369=2262=363048e5-e368-48b6-a6d9-193fe7c5bbb6268=1279=2269=0278=6a0f8d11-9770-454f-ab74-ec55b6b5cf7a83=159755419955=BTC-USD60=20250411-01:37:31.10959058=FILLED10=128
20250411-01:37:31.264310000 : 8=FIXT.1.19=27335=X49=Coinbase56=24ab46f784d1b20db435b852086e325034=1750=TEST52=20250411-01:37:31.139206369=2262=363048e5-e368-48b6-a6d9-193fe7c5bbb6268=1279=0269=183=159755420055=BTC-USD271=0.6197183160=20250411-01:37:31.13809940=137=fe364ebf-64e9-4cdb-b9e4-830cc9cf1e9a10=102
20250411-01:37:31.264810000 : 8=FIXT.1.19=32535=X49=Coinbase56=24ab46f784d1b20db435b852086e325034=1850=TEST52=20250411-01:37:31.139296369=2262=363048e5-e368-48b6-a6d9-193fe7c5bbb6268=1279=0269=2278=4d60a78e-b39b-420e-b830-bc0f3f4fdde283=159755420155=BTC-USD270=3.53271=0.6197183160=20250411-01:37:31.13809937=fe364ebf-64e9-4cdb-b9e4-830cc9cf1e9a5797=210=100
20250411-01:37:31.265175000 : 8=FIXT.1.19=27935=X49=Coinbase56=24ab46f784d1b20db435b852086e325034=1950=TEST52=20250411-01:37:31.139300369=2262=363048e5-e368-48b6-a6d9-193fe7c5bbb6268=1279=2269=1278=fe364ebf-64e9-4cdb-b9e4-830cc9cf1e9a83=159755420255=BTC-USD271=0.0000000060=20250411-01:37:31.13809958=FILLED10=008
20250411-01:37:31.463040000 : 8=FIXT.1.19=27735=X49=Coinbase56=24ab46f784d1b20db435b852086e325034=2050=TEST52=20250411-01:37:31.340236369=2262=363048e5-e368-48b6-a6d9-193fe7c5bbb6268=1279=0269=083=159755420355=BTC-USD29004=2.208895519560=20250411-01:37:31.33930640=137=3c632e5e-80c8-4f47-b9e6-07fe132ad52010=005
20250411-01:37:31.463637000 : 8=FIXT.1.19=32535=X49=Coinbase56=24ab46f784d1b20db435b852086e325034=2150=TEST52=20250411-01:37:31.340241369=2262=363048e5-e368-48b6-a6d9-193fe7c5bbb6268=1279=0269=2278=c5b88ea9-605d-4595-ac52-f7c3f08523ba83=159755420455=BTC-USD270=3.55271=0.6222240960=20250411-01:37:31.33930637=3c632e5e-80c8-4f47-b9e6-07fe132ad5205797=110=148
20250411-01:37:31.463819000 : 8=FIXT.1.19=26435=X49=Coinbase56=24ab46f784d1b20db435b852086e325034=2250=TEST52=20250411-01:37:31.340245369=2262=363048e5-e368-48b6-a6d9-193fe7c5bbb6268=1279=2269=0278=3c632e5e-80c8-4f47-b9e6-07fe132ad52083=159755420555=BTC-USD60=20250411-01:37:31.33930658=FILLED10=021
20250411-01:37:31.491921000 : 8=FIXT.1.19=27335=X49=Coinbase56=24ab46f784d1b20db435b852086e325034=2350=TEST52=20250411-01:37:31.368710369=2262=363048e5-e368-48b6-a6d9-193fe7c5bbb6268=1279=0269=183=159755420655=BTC-USD271=0.6232294660=20250411-01:37:31.36706640=137=badcb265-1e94-4aa8-b2ee-44c213ca33b010=221
20250411-01:37:31.492473000 : 8=FIXT.1.19=32535=X49=Coinbase56=24ab46f784d1b20db435b852086e325034=2450=TEST52=20250411-01:37:31.368718369=2262=363048e5-e368-48b6-a6d9-193fe7c5bbb6268=1279=0269=2278=4d60a78e-b39b-420e-b830-bc0f3f4fdde283=159755420755=BTC-USD270=3.53271=0.6232294660=20250411-01:37:31.36706637=badcb265-1e94-4aa8-b2ee-44c213ca33b05797=210=218
20250411-01:37:31.492644000 : 8=FIXT.1.19=27935=X49=Coinbase56=24ab46f784d1b20db435b852086e325034=2550=TEST52=20250411-01:37:31.368722369=2262=363048e5-e368-48b6-a6d9-193fe7c5bbb6268=1279=2269=1278=badcb265-1e94-4aa8-b2ee-44c213ca33b083=159755420855=BTC-USD271=0.0000000060=20250411-01:37:31.36706658=FILLED10=137
20250411-01:37:31.888266000 : 8=FIXT.1.19=28235=X49=Coinbase56=24ab46f784d1b20db435b852086e325034=2650=TEST52=20250411-01:37:31.673758369=2262=363048e5-e368-48b6-a6d9-193fe7c5bbb6268=1279=0269=183=159755420955=BTC-USD270=3.22271=0.6232294660=20250411-01:37:31.67242340=237=a448f2e2-2abd-4f6b-8a85-fe07fe0c77e510=171
20250411-01:37:31.888849000 : 8=FIXT.1.19=32535=X49=Coinbase56=24ab46f784d1b20db435b852086e325034=2750=TEST52=20250411-01:37:31.673763369=2262=363048e5-e368-48b6-a6d9-193fe7c5bbb6268=1279=0269=2278=4d60a78e-b39b-420e-b830-bc0f3f4fdde283=159755421055=BTC-USD270=3.53271=0.6232294660=20250411-01:37:31.67242337=a448f2e2-2abd-4f6b-8a85-fe07fe0c77e55797=210=246
20250411-01:37:31.889056000 : 8=FIXT.1.19=28835=X49=Coinbase56=24ab46f784d1b20db435b852086e325034=2850=TEST52=20250411-01:37:31.673767369=2262=363048e5-e368-48b6-a6d9-193fe7c5bbb6268=1279=2269=1278=a448f2e2-2abd-4f6b-8a85-fe07fe0c77e583=159755421155=BTC-USD270=3.22271=0.0000000060=20250411-01:37:31.67242358=FILLED10=074
20250411-01:37:31.890999000 : 8=FIXT.1.19=28235=X49=Coinbase56=24ab46f784d1b20db435b852086e325034=2950=TEST52=20250411-01:37:31.729142369=2262=363048e5-e368-48b6-a6d9-193fe7c5bbb6268=1279=0269=083=159755421255=BTC-USD270=3.83271=0.6232294660=20250411-01:37:31.72821340=237=a870b9a1-91af-4079-8d64-b0f84e9abd0710=017
20250411-01:37:31.891471000 : 8=FIXT.1.19=32535=X49=Coinbase56=24ab46f784d1b20db435b852086e325034=3050=TEST52=20250411-01:37:31.729151369=2262=363048e5-e368-48b6-a6d9-193fe7c5bbb6268=1279=0269=2278=c5b88ea9-605d-4595-ac52-f7c3f08523ba83=159755421355=BTC-USD270=3.55271=0.6232294660=20250411-01:37:31.72821337=a870b9a1-91af-4079-8d64-b0f84e9abd075797=110=219
20250411-01:37:31.891806000 : 8=FIXT.1.19=28835=X49=Coinbase56=24ab46f784d1b20db435b852086e325034=3150=TEST52=20250411-01:37:31.729155369=2262=363048e5-e368-48b6-a6d9-193fe7c5bbb6268=1279=2269=0278=a870b9a1-91af-4079-8d64-b0f84e9abd0783=159755421455=BTC-USD270=3.83271=0.0000000060=20250411-01:37:31.72821358=FILLED10=180
20250411-01:37:31.920788000 : 8=FIXT.1.19=27735=X49=Coinbase56=24ab46f784d1b20db435b852086e325034=3250=TEST52=20250411-01:37:31.797003369=2262=363048e5-e368-48b6-a6d9-193fe7c5bbb6268=1279=0269=083=159755421555=BTC-USD29004=2.208895519560=20250411-01:37:31.79578540=137=9c2670bf-eace-4765-af3d-5014190ec15110=074
20250411-01:37:31.922401000 : 8=FIXT.1.19=32535=X49=Coinbase56=24ab46f784d1b20db435b852086e325034=3350=TEST52=20250411-01:37:31.797010369=2262=363048e5-e368-48b6-a6d9-193fe7c5bbb6268=1279=0269=2278=c5b88ea9-605d-4595-ac52-f7c3f08523ba83=159755421655=BTC-USD270=3.55271=0.6222240960=20250411-01:37:31.79578537=9c2670bf-eace-4765-af3d-5014190ec1515797=110=219
20250411-01:37:31.922807000 : 8=FIXT.1.19=26435=X49=Coinbase56=24ab46f784d1b20db435b852086e325034=3450=TEST52=20250411-01:37:31.797014369=2262=363048e5-e368-48b6-a6d9-193fe7c5bbb6268=1279=2269=0278=9c2670bf-eace-4765-af3d-5014190ec15183=159755421755=BTC-USD60=20250411-01:37:31.79578558=FILLED10=092
20250411-01:37:31.948230000 : 8=FIXT.1.19=27335=X49=Coinbase56=24ab46f784d1b20db435b852086e325034=3550=TEST52=20250411-01:37:31.825463369=2262=363048e5-e368-48b6-a6d9-193fe7c5bbb6268=1279=0269=183=159755421855=BTC-USD271=0.6197183160=20250411-01:37:31.82391940=137=cd6373c6-24ac-4c23-b074-87e4c9a9ce8510=128
20250411-01:37:31.948661000 : 8=FIXT.1.19=32535=X49=Coinbase56=24ab46f784d1b20db435b852086e325034=3650=TEST52=20250411-01:37:31.825469369=2262=363048e5-e368-48b6-a6d9-193fe7c5bbb6268=1279=0269=2278=4d60a78e-b39b-420e-b830-bc0f3f4fdde283=159755421955=BTC-USD270=3.53271=0.6197183160=20250411-01:37:31.82391937=cd6373c6-24ac-4c23-b074-87e4c9a9ce855797=210=123
20250411-01:37:31.949290000 : 8=FIXT.1.19=27935=X49=Coinbase56=24ab46f784d1b20db435b852086e325034=3750=TEST52=20250411-01:37:31.825473369=2262=363048e5-e368-48b6-a6d9-193fe7c5bbb6268=1279=2269=1278=cd6373c6-24ac-4c23-b074-87e4c9a9ce8583=159755422055=BTC-USD271=0.0000000060=20250411-01:37:31.82391958=FILLED10=031
20250411-01:37:32.120059000 : 8=FIXT.1.19=28235=X49=Coinbase56=24ab46f784d1b20db435b852086e325034=3850=TEST52=20250411-01:37:31.994748369=2262=363048e5-e368-48b6-a6d9-193fe7c5bbb6268=1279=0269=083=159755422155=BTC-USD270=3.51271=0.6232294660=20250411-01:37:31.99305840=237=ba72cf3f-41c9-4712-9bc7-d76d46b07d3810=040
20250411-01:37:32.120815000 : 8=FIXT.1.19=27835=X49=Coinbase56=24ab46f784d1b20db435b852086e325034=3950=TEST52=20250411-01:37:31.994755369=2262=363048e5-e368-48b6-a6d9-193fe7c5bbb6268=1279=0269=0278=ba72cf3f-41c9-4712-9bc7-d76d46b07d3883=159755422255=BTC-USD270=3.51271=0.6232294660=20250411-01:37:31.99305810=144
20250411-01:37:32.503607000 : 8=FIXT.1.19=28135=X49=Coinbase56=24ab46f784d1b20db435b852086e325034=4050=TEST52=20250411-01:37:32.278600369=2262=363048e5-e368-48b6-a6d9-193fe7c5bbb6268=1279=0269=183=159755422355=BTC-USD270=3.6271=0.6232294660=20250411-01:37:32.27704340=237=0b79bd92-8c8f-4c8e-9819-097caafee23f10=074
20250411-01:37:32.506579000 : 8=FIXT.1.19=8335=534=349=24ab46f784d1b20db435b852086e325052=20250411-01:37:32.50456=Coinbase10=109
20250411-01:37:32.506717000 : 8=FIXT.1.19=27735=X49=Coinbase56=24ab46f784d1b20db435b852086e325034=4150=TEST52=20250411-01:37:32.278607369=2262=363048e5-e368-48b6-a6d9-193fe7c5bbb6268=1279=0269=1278=0b79bd92-8c8f-4c8e-9819-097caafee23f83=159755422455=BTC-USD270=3.6271=0.6232294660=20250411-01:37:32.27704310=187
20250411-01:37:32.606451000 : 8=FIXT.1.19=27735=X49=Coinbase56=24ab46f784d1b20db435b852086e325034=4250=TEST52=20250411-01:37:32.482589369=2262=363048e5-e368-48b6-a6d9-193fe7c5bbb6268=1279=0269=083=159755422555=BTC-USD29004=2.208895519560=20250411-01:37:32.48149440=137=c4e75c04-bcf2-4a5b-a20c-f7c3880683bb10=171
20250411-01:37:32.607291000 : 8=FIXT.1.19=32535=X49=Coinbase56=24ab46f784d1b20db435b852086e325034=4350=TEST52=20250411-01:37:32.482597369=2262=363048e5-e368-48b6-a6d9-193fe7c5bbb6268=1279=0269=2278=c5b88ea9-605d-4595-ac52-f7c3f08523ba83=159755422655=BTC-USD270=3.55271=0.6222240960=20250411-01:37:32.48149437=c4e75c04-bcf2-4a5b-a20c-f7c3880683bb5797=110=061
20250411-01:37:32.607799000 : 8=FIXT.1.19=26435=X49=Coinbase56=24ab46f784d1b20db435b852086e325034=4450=TEST52=20250411-01:37:32.482601369=2262=363048e5-e368-48b6-a6d9-193fe7c5bbb6268=1279=2269=0278=c4e75c04-bcf2-4a5b-a20c-f7c3880683bb83=159755422755=BTC-USD60=20250411-01:37:32.48149458=FILLED10=172
20250411-01:37:32.633819000 : 8=FIXT.1.19=27335=X49=Coinbase56=24ab46f784d1b20db435b852086e325034=4550=TEST52=20250411-01:37:32.510820369=2262=363048e5-e368-48b6-a6d9-193fe7c5bbb6268=1279=0269=183=159755422855=BTC-USD271=0.6232294660=20250411-01:37:32.50947140=137=29744c72-9b37-46d7-a853-8ffa5a9b93d410=034
20250411-01:37:32.634589000 : 8=FIXT.1.19=32535=X49=Coinbase56=24ab46f784d1b20db435b852086e325034=4650=TEST52=20250411-01:37:32.510827369=2262=363048e5-e368-48b6-a6d9-193fe7c5bbb6268=1279=0269=2278=4d60a78e-b39b-420e-b830-bc0f3f4fdde283=159755422955=BTC-USD270=3.53271=0.6232294660=20250411-01:37:32.50947137=29744c72-9b37-46d7-a853-8ffa5a9b93d45797=210=030
20250411-01:37:32.634917000 : 8=FIXT.1.19=27935=X49=Coinbase56=24ab46f784d1b20db435b852086e325034=4750=TEST52=20250411-01:37:32.510831369=2262=363048e5-e368-48b6-a6d9-193fe7c5bbb6268=1279=2269=1278=29744c72-9b37-46d7-a853-8ffa5a9b93d483=159755423055=BTC-USD271=0.0000000060=20250411-01:37:32.50947158=FILLED10=196
20250411-01:37:32.686502000 : 8=FIXT.1.19=28235=X49=Coinbase56=24ab46f784d1b20db435b852086e325034=4850=TEST52=20250411-01:37:32.563255369=2262=363048e5-e368-48b6-a6d9-193fe7c5bbb6268=1279=0269=083=159755423155=BTC-USD270=3.41271=0.6232294660=20250411-01:37:32.56187640=237=b2734983-212a-4e68-8881-7c34d1348c7910=006
20250411-01:37:32.687043000 : 8=FIXT.1.19=27835=X49=Coinbase56=24ab46f784d1b20db435b852086e325034=4950=TEST52=20250411-01:37:32.563263369=2262=363048e5-e368-48b6-a6d9-193fe7c5bbb6268=1279=0269=0278=b2734983-212a-4e68-8881-7c34d1348c7983=159755423255=BTC-USD270=3.41271=0.6232294660=20250411-01:37:32.56187610=111
20250411-01:37:32.687983000 : 8=FIXT.1.19=28235=X49=Coinbase56=24ab46f784d1b20db435b852086e325034=5050=TEST52=20250411-01:37:32.565750369=2262=363048e5-e368-48b6-a6d9-193fe7c5bbb6268=1279=0269=183=159755423355=BTC-USD270=3.54271=0.6232294660=20250411-01:37:32.56452240=237=b0ad5dcb-fdab-44f7-9c4c-82ea49f7caa510=089
20250411-01:37:32.688403000 : 8=FIXT.1.19=27835=X49=Coinbase56=24ab46f784d1b20db435b852086e325034=5150=TEST52=20250411-01:37:32.565755369=2262=363048e5-e368-48b6-a6d9-193fe7c5bbb6268=1279=0269=1278=b0ad5dcb-fdab-44f7-9c4c-82ea49f7caa583=159755423455=BTC-USD270=3.54271=0.6232294660=20250411-01:37:32.56452210=200
20250411-01:37:32.689470000 : 8=FIXT.1.19=28135=X49=Coinbase56=24ab46f784d1b20db435b852086e325034=5250=TEST52=20250411-01:37:32.565759369=2262=363048e5-e368-48b6-a6d9-193fe7c5bbb6268=1279=0269=183=159755423555=BTC-USD270=3.6271=0.6232294660=20250411-01:37:32.56452240=237=4a33c614-3ced-4861-aedb-96450518b12510=123
20250411-01:37:32.689663000 : 8=FIXT.1.19=27735=X49=Coinbase56=24ab46f784d1b20db435b852086e325034=5350=TEST52=20250411-01:37:32.565826369=2262=363048e5-e368-48b6-a6d9-193fe7c5bbb6268=1279=0269=1278=4a33c614-3ced-4861-aedb-96450518b12583=159755423655=BTC-USD270=3.6271=0.6232294660=20250411-01:37:32.56452210=224
20250411-01:37:32.732201000 : 8=FIXT.1.19=11835=549=Coinbase56=24ab46f784d1b20db435b852086e325034=5450=TEST52=20250411-01:37:32.609857369=258=CLIENT_LOGOUT10=020
20250411-01:41:40.508991000 : 8=FIXT.1.19=21535=A34=149=24ab46f784d1b20db435b852086e325052=20250411-01:41:40.50056=Coinbase95=4496=ckRMkP9T2InS0FCrRAxIjPp0qh7YnkHyksiEjzokFec=98=0108=30141=Y553=24ab46f784d1b20db435b852086e3250554=akmwnltyfgb1137=910=200
20250411-01:41:40.763364000 : 8=FIXT.1.19=12535=A49=Coinbase56=24ab46f784d1b20db435b852086e325034=150=TEST52=20250411-01:41:40.639719369=198=0108=30141=Y1137=910=197
20250411-01:41:42.253868000 : 8=FIXT.1.19=17835=V34=249=24ab46f784d1b20db435b852086e325052=20250411-01:41:42.25256=Coinbase1128=9146=155=BTC-USD262=019c5c39-7de8-457e-b353-126439f7eeea263=1264=0267=2269=0269=110=020
20250411-01:41:43.798444000 : 8=FIXT.1.19=28135=X49=Coinbase56=24ab46f784d1b20db435b852086e325034=250=TEST52=20250411-01:41:43.626175369=2262=019c5c39-7de8-457e-b353-126439f7eeea268=1279=0269=183=159755926755=BTC-USD270=3.31271=0.6232294660=20250411-01:41:43.62473940=237=9f63d110-2695-48a6-bb5e-bfb326be5cf110=012
20250411-01:41:43.799884000 : 8=FIXT.1.19=32435=X49=Coinbase56=24ab46f784d1b20db435b852086e325034=350=TEST52=20250411-01:41:43.626187369=2262=019c5c39-7de8-457e-b353-126439f7eeea268=1279=0269=2278=4d60a78e-b39b-420e-b830-bc0f3f4fdde283=159755926855=BTC-USD270=3.53271=0.6232294660=20250411-01:41:43.62473937=9f63d110-2695-48a6-bb5e-bfb326be5cf15797=210=103
20250411-01:41:43.802015000 : 8=FIXT.1.19=28735=X49=Coinbase56=24ab46f784d1b20db435b852086e325034=450=TEST52=20250411-01:41:43.626191369=2262=019c5c39-7de8-457e-b353-126439f7eeea268=1279=2269=1278=9f63d110-2695-48a6-bb5e-bfb326be5cf183=159755926955=BTC-USD270=3.31271=0.0000000060=20250411-01:41:43.62473958=FILLED10=178
20250411-01:41:43.802204000 : 8=FIXT.1.19=28135=X49=Coinbase56=24ab46f784d1b20db435b852086e325034=550=TEST52=20250411-01:41:43.626194369=2262=019c5c39-7de8-457e-b353-126439f7eeea268=1279=0269=183=159755927055=BTC-USD270=3.21271=0.6232294660=20250411-01:41:43.62473940=237=83b08ca4-10e1-43bb-aa2e-4404eb110cce10=017
20250411-01:41:43.802356000 : 8=FIXT.1.19=32435=X49=Coinbase56=24ab46f784d1b20db435b852086e325034=650=TEST52=20250411-01:41:43.626196369=2262=019c5c39-7de8-457e-b353-126439f7eeea268=1279=0269=2278=4d60a78e-b39b-420e-b830-bc0f3f4fdde283=159755927155=BTC-USD270=3.53271=0.6232294660=20250411-01:41:43.62473937=83b08ca4-10e1-43bb-aa2e-4404eb110cce5797=210=108
20250411-01:41:43.802525000 : 8=FIXT.1.19=28735=X49=Coinbase56=24ab46f784d1b20db435b852086e325034=750=TEST52=20250411-01:41:43.626276369=2262=019c5c39-7de8-457e-b353-126439f7eeea268=1279=2269=1278=83b08ca4-10e1-43bb-aa2e-4404eb110cce83=159755927255=BTC-USD270=3.21271=0.0000000060=20250411-01:41:43.62473958=FILLED10=186
20250411-01:41:43.860672000 : 8=FIXT.1.19=28135=X49=Coinbase56=24ab46f784d1b20db435b852086e325034=850=TEST52=20250411-01:41:43.739545369=2262=019c5c39-7de8-457e-b353-126439f7eeea268=1279=0269=083=159755927355=BTC-USD270=3.75271=0.6232294660=20250411-01:41:43.73839240=237=4444081c-ce56-4102-98cf-925218a9a03b10=040
20250411-01:41:43.861070000 : 8=FIXT.1.19=32435=X49=Coinbase56=24ab46f784d1b20db435b852086e325034=950=TEST52=20250411-01:41:43.739552369=2262=019c5c39-7de8-457e-b353-126439f7eeea268=1279=0269=2278=c5b88ea9-605d-4595-ac52-f7c3f08523ba83=159755927455=BTC-USD270=3.55271=0.6232294660=20250411-01:41:43.73839237=4444081c-ce56-4102-98cf-925218a9a03b5797=110=248
20250411-01:41:43.861284000 : 8=FIXT.1.19=28835=X49=Coinbase56=24ab46f784d1b20db435b852086e325034=1050=TEST52=20250411-01:41:43.739657369=2262=019c5c39-7de8-457e-b353-126439f7eeea268=1279=2269=0278=4444081c-ce56-4102-98cf-925218a9a03b83=159755927555=BTC-USD270=3.75271=0.0000000060=20250411-01:41:43.73839258=FILLED10=252
20250411-01:41:43.861468000 : 8=FIXT.1.19=28235=X49=Coinbase56=24ab46f784d1b20db435b852086e325034=1150=TEST52=20250411-01:41:43.739660369=2262=019c5c39-7de8-457e-b353-126439f7eeea268=1279=0269=083=159755927655=BTC-USD270=3.74271=0.6232294660=20250411-01:41:43.73839240=237=8b8e4ae3-392f-4e75-9c96-128c18c55f8810=218
20250411-01:41:43.861692000 : 8=FIXT.1.19=32535=X49=Coinbase56=24ab46f784d1b20db435b852086e325034=1250=TEST52=20250411-01:41:43.739664369=2262=019c5c39-7de8-457e-b353-126439f7eeea268=1279=0269=2278=c5b88ea9-605d-4595-ac52-f7c3f08523ba83=159755927755=BTC-USD270=3.55271=0.6232294660=20250411-01:41:43.73839237=8b8e4ae3-392f-4e75-9c96-128c18c55f885797=110=177
20250411-01:41:43.862985000 : 8=FIXT.1.19=28835=X49=Coinbase56=24ab46f784d1b20db435b852086e325034=1350=TEST52=20250411-01:41:43.739666369=2262=019c5c39-7de8-457e-b353-126439f7eeea268=1279=2269=0278=8b8e4ae3-392f-4e75-9c96-128c18c55f8883=159755927855=BTC-USD270=3.74271=0.0000000060=20250411-01:41:43.73839258=FILLED10=136
20250411-01:41:43.977490000 : 8=FIXT.1.19=28235=X49=Coinbase56=24ab46f784d1b20db435b852086e325034=1450=TEST52=20250411-01:41:43.855417369=2262=019c5c39-7de8-457e-b353-126439f7eeea268=1279=0269=083=159755927955=BTC-USD270=3.73271=0.6197183160=20250411-01:41:43.85343040=237=26b05d49-f959-4892-ad91-893b3841c11510=056
20250411-01:41:43.978025000 : 8=FIXT.1.19=32535=X49=Coinbase56=24ab46f784d1b20db435b852086e325034=1550=TEST52=20250411-01:41:43.855427369=2262=019c5c39-7de8-457e-b353-126439f7eeea268=1279=0269=2278=c5b88ea9-605d-4595-ac52-f7c3f08523ba83=159755928055=BTC-USD270=3.55271=0.6197183160=20250411-01:41:43.85343037=26b05d49-f959-4892-ad91-893b3841c1155797=110=004
20250411-01:41:43.978219000 : 8=FIXT.1.19=28835=X49=Coinbase56=24ab46f784d1b20db435b852086e325034=1650=TEST52=20250411-01:41:43.855431369=2262=019c5c39-7de8-457e-b353-126439f7eeea268=1279=2269=0278=26b05d49-f959-4892-ad91-893b3841c11583=159755928155=BTC-USD270=3.73271=0.0000000060=20250411-01:41:43.85343058=FILLED10=209
20250411-01:41:44.030975000 : 8=FIXT.1.19=28235=X49=Coinbase56=24ab46f784d1b20db435b852086e325034=1750=TEST52=20250411-01:41:43.909578369=2262=019c5c39-7de8-457e-b353-126439f7eeea268=1279=0269=183=159755928255=BTC-USD270=3.26271=0.6197183160=20250411-01:41:43.90836640=237=5e2d9560-e4d7-45d1-b372-4ce999660a2910=165
20250411-01:41:44.031462000 : 8=FIXT.1.19=32535=X49=Coinbase56=24ab46f784d1b20db435b852086e325034=1850=TEST52=20250411-01:41:43.909637369=2262=019c5c39-7de8-457e-b353-126439f7eeea268=1279=0269=2278=4d60a78e-b39b-420e-b830-bc0f3f4fdde283=159755928355=BTC-USD270=3.53271=0.6197183160=20250411-01:41:43.90836637=5e2d9560-e4d7-45d1-b372-4ce999660a295797=210=245
20250411-01:41:44.031719000 : 8=FIXT.1.19=28835=X49=Coinbase56=24ab46f784d1b20db435b852086e325034=1950=TEST52=20250411-01:41:43.909642369=2262=019c5c39-7de8-457e-b353-126439f7eeea268=1279=2269=1278=5e2d9560-e4d7-45d1-b372-4ce999660a2983=159755928455=BTC-USD270=3.26271=0.0000000060=20250411-01:41:43.90836658=FILLED10=067
20250411-01:41:46.017639000 : 8=FIXT.1.19=28235=X49=Coinbase56=24ab46f784d1b20db435b852086e325034=2050=TEST52=20250411-01:41:45.890609369=2262=019c5c39-7de8-457e-b353-126439f7eeea268=1279=0269=083=159755928555=BTC-USD270=3.46271=0.6232294660=20250411-01:41:45.88901840=237=faaa5549-18e4-4684-a84e-191ce4a5387d10=251
20250411-01:41:46.018361000 : 8=FIXT.1.19=27835=X49=Coinbase56=24ab46f784d1b20db435b852086e325034=2150=TEST52=20250411-01:41:45.890634369=2262=019c5c39-7de8-457e-b353-126439f7eeea268=1279=0269=0278=faaa5549-18e4-4684-a84e-191ce4a5387d83=159755928655=BTC-USD270=3.46271=0.6232294660=20250411-01:41:45.88901810=099
20250411-01:41:47.591521000 : 8=FIXT.1.19=91735=W49=Coinbase56=24ab46f784d1b20db435b852086e325034=2250=TEST52=20250411-01:41:47.371225369=2262=019c5c39-7de8-457e-b353-126439f7eeea83=1597559286893=N55=BTC-USD1682=full_trading268=10269=0278=4d60a78e-b39b-420e-b830-bc0f3f4fdde2270=3.53271=257817.20772218269=0278=9d9353ab-229f-423a-89a3-c52a46543bc9270=3.53271=18127.30103418269=0278=c5e86443-3181-4c47-9186-a42f3f1b1da4270=3.52271=0.62322946269=0278=f5fc5e68-a52c-44d3-87ef-3785312f4782270=3.48271=0.29310888269=0278=dcccb470-c535-433a-9198-4e2b4c26d99d270=3.47271=0.29311495269=0278=f05d9766-970d-44ca-aa4d-e8b2720bbda8270=3.46271=0.29026870269=0278=faaa5549-18e4-4684-a84e-191ce4a5387d270=3.46271=0.62322946269=0278=2c4d7d5a-33aa-4058-b546-480b6a2168a4270=3.44271=0.29828577269=0278=37dbcf16-0b3d-4f67-bc90-e36268b99e0e270=3.42271=0.30270947269=0278=1964d182-cd76-4c70-b0ef-9300fd125d77270=3.42271=0.6195732510=253
20250411-01:41:47.594656000 : 8=FIXT.1.19=14035=334=349=24ab46f784d1b20db435b852086e325052=20250411-01:41:47.59356=Coinbase45=2258=Tag appears more than once371=269372=W373=1310=201
20250411-01:41:47.594820000 : 8=FIXT.1.19=90835=W49=Coinbase56=24ab46f784d1b20db435b852086e325034=2350=TEST52=20250411-01:41:47.371467369=2262=019c5c39-7de8-457e-b353-126439f7eeea83=1597559286893=N55=BTC-USD1682=full_trading268=10269=0278=4c63c0b7-30e0-4ef1-931f-0090359f978e270=3.41271=0.32158962269=0278=d6b4aa4e-d588-4c96-83aa-8e8d8accb1a4270=3.41271=0.30121104269=0278=e8b3d8da-1663-413c-b7fb-6aba23b01440270=3.39271=0.31006477269=0278=bcbe17c3-9059-4c38-8ab8-8e78f1ef9062270=3.38271=0.32617981269=0278=57436d25-1eb8-454c-82f9-4de35a0e4cb1270=3.38271=0.62322946269=0278=57bb77fd-337f-49bc-a56f-a4e2dff851ee270=3.37271=0.31071676269=0278=9c02d1c1-1136-486a-a678-4349063fe930270=3.36271=0.62322946269=0278=ded4b51d-349f-4726-8379-6761a3576bb6270=3.33271=0.31560513269=0278=ff7aff09-38de-47ac-a3cb-9beacb0b9ad8270=3.33271=0.30682342269=0278=d1da558a-e9d2-4e11-b26e-1eb80a1a34c5270=3.32271=0.3170068510=090
20250411-01:41:47.595653000 : 8=FIXT.1.19=14035=334=449=24ab46f784d1b20db435b852086e325052=20250411-01:41:47.59556=Coinbase45=2358=Tag appears more than once371=269372=W373=1310=205
20250411-01:41:47.595787000 : 8=FIXT.1.19=90835=W49=Coinbase56=24ab46f784d1b20db435b852086e325034=2450=TEST52=20250411-01:41:47.371717369=2262=019c5c39-7de8-457e-b353-126439f7eeea83=1597559286893=N55=BTC-USD1682=full_trading268=10269=0278=9ee34527-d4d8-4659-b2ea-cdff3dc4a8fa270=3.32271=0.32181951269=0278=7abf2220-0421-460f-9dbb-14c41564e41a270=3.32271=0.31308436269=0278=69634ec5-f71a-4990-b56d-13c3069a455a270=3.31271=0.32329458269=0278=2f333c17-a386-4d52-8ff1-eadcb99bc22f270=3.31271=0.31999220269=0278=f02efc37-0b1e-470b-99ef-e31012887d73270=3.30271=0.32771570269=0278=6d430950-8078-4987-8995-e581564e368d270=3.29271=0.30702763269=0278=841f895a-cd2d-4082-9a37-b50fc19e35bf270=3.28271=0.32610801269=0278=3cf93093-e42b-4c24-95ea-c367d96427fe270=3.27271=0.33588654269=0278=f29c94bc-d1c2-4145-97b0-ecb77d81a8bf270=3.27271=0.31661408269=0278=d208c4fb-56c6-4911-85c9-77b68a5ba6ab270=3.25271=0.3096162310=240
20250411-01:41:47.596729000 : 8=FIXT.1.19=14035=334=549=24ab46f784d1b20db435b852086e325052=20250411-01:41:47.59656=Coinbase45=2458=Tag appears more than once371=269372=W373=1310=208
20250411-01:41:47.596802000 : 8=FIXT.1.19=90835=W49=Coinbase56=24ab46f784d1b20db435b852086e325034=2550=TEST52=20250411-01:41:47.371967369=2262=019c5c39-7de8-457e-b353-126439f7eeea83=1597559286893=N55=BTC-USD1682=full_trading268=10269=0278=e88796ff-68c8-4463-914b-46e09fbaf639270=3.25271=0.33589845269=0278=06f345fb-0292-45fc-8237-9ad1a84b541c270=3.24271=0.31528507269=0278=fa20c2c7-df80-4941-9a9c-a6ef2e579480270=3.23271=0.33432448269=0278=a833d230-a749-4bf4-823e-93adc40b773d270=3.23271=0.31165878269=0278=2abb6e15-b9cd-415b-8c9b-99a61c750310270=3.22271=0.32048714269=0278=ec44a6d8-ae5f-4809-89d7-0f7a3adac547270=3.21271=0.33230954269=0278=9cf61c67-c4fc-4bac-92fd-d4e2b56248aa270=3.21271=0.33583951269=0278=210b2518-bb42-461a-9c7e-b4e04c5ffcc6270=3.21271=0.32669007269=0278=2e3fa1b2-20f1-4694-9be4-322040b75152270=3.21271=0.32907979269=0278=05dd5607-92c9-4296-8cdc-27cdff004dea270=3.21271=0.3277607510=250
20250411-01:41:47.597487000 : 8=FIXT.1.19=14035=334=649=24ab46f784d1b20db435b852086e325052=20250411-01:41:47.59756=Coinbase45=2558=Tag appears more than once371=269372=W373=1310=211
20250411-01:41:47.597584000 : 8=FIXT.1.19=90935=W49=Coinbase56=24ab46f784d1b20db435b852086e325034=2650=TEST52=20250411-01:41:47.372218369=2262=019c5c39-7de8-457e-b353-126439f7eeea83=1597559286893=N55=BTC-USD1682=full_trading268=10269=0278=87944de7-a5f1-4033-a3d8-cbc10f3a5232270=3.20271=0.32225170269=0278=30f6bb59-2469-4e6d-8fa5-13666373901f270=3.19271=0.31386496269=0278=6a5d2852-7ddc-456e-acb5-bfadcc0c1360270=3.19271=0.32157390269=0278=5d00d8a2-5aea-4836-ba19-74fe67116df8270=3.18271=0.32651049269=0278=acc71746-3591-4dde-a7e2-c2795d0ad125270=3.17271=0.31577131269=0278=13982796-c2a8-4740-95e2-5aca0fdfd8bb270=3.16271=0.33021170269=0278=9f2f0737-661e-43d7-89f9-959ed5e08306270=3.16271=0.33082075269=0278=7e0e2d14-fa77-4978-8cae-d9660fd13e6d270=3.16271=0.32014975269=0278=82826a7d-848c-4516-a7b6-5ec6881609a8270=2.00271=10.00000000269=0278=590048d5-ee44-49dc-b66d-1a692e055133270=1.94271=0.5154639210=054
20250411-01:41:47.598258000 : 8=FIXT.1.19=14035=334=749=24ab46f784d1b20db435b852086e325052=20250411-01:41:47.59756=Coinbase45=2658=Tag appears more than once371=269372=W373=1310=213
