20250411-01:41:47.598372000 : 8=FIXT.1.19=90835=W49=Coinbase56=24ab46f784d1b20db435b852086e325034=2750=TEST52=20250411-01:41:47.372468369=2262=019c5c39-7de8-457e-b353-126439f7eeea83=1597559286893=N55=BTC-USD1682=full_trading268=10269=0278=22bdda11-16cd-488b-9fa9-da098dad543e270=1.94271=0.51546392269=0278=d356ef8b-596e-47e7-bf90-cc015b85fc57270=1.93271=0.52331606269=0278=aa8d48bc-97fb-4d00-b923-66d37cc8c66a270=1.93271=0.52331606269=0278=7d51dcb4-a7f8-4cca-b2d0-e902403d1b9f270=1.93271=0.52331606269=0278=f7680950-3af2-4723-a6e4-5cbd528ca900270=1.93271=0.52331606269=0278=fdeff994-4866-47af-9dde-a25947a26606270=1.93271=0.52331606269=0278=65e7e2bb-023d-4936-bb4e-ff7625ba7264270=1.93271=0.52331606269=0278=53732639-572c-4cd5-b61e-e4f534d1d540270=1.93271=0.52331606269=0278=24da8927-1dd1-468b-9437-ff366f5bfa11270=1.93271=0.52331606269=0278=baa5862c-41e8-458c-83d3-c095bb68ed17270=1.93271=0.5233160610=197
20250411-01:41:47.598974000 : 8=FIXT.1.19=14035=334=849=24ab46f784d1b20db435b852086e325052=20250411-01:41:47.59856=Coinbase45=2758=Tag appears more than once371=269372=W373=1310=216
20250411-01:41:47.599111000 : 8=FIXT.1.19=90835=W49=Coinbase56=24ab46f784d1b20db435b852086e325034=2850=TEST52=20250411-01:41:47.372717369=2262=019c5c39-7de8-457e-b353-126439f7eeea83=1597559286893=N55=BTC-USD1682=full_trading268=10269=0278=92a3c3e3-7afe-4d02-a0d8-96f512b63bb7270=1.93271=0.52331606269=0278=9d2a564e-f178-4966-9baf-5814a1c1686b270=1.93271=0.52331606269=0278=f9e6b978-87f6-4397-8d82-07cf698c123f270=1.93271=0.52331606269=0278=3e64b388-13d3-441d-b241-aa8dd6fe55e6270=1.93271=0.52331606269=0278=60300433-87b0-4031-bb1e-12cf9d773d3f270=1.93271=0.52331606269=0278=1bdd5f5a-1d99-4eed-af09-c187bcbbd2d8270=1.93271=0.52331606269=0278=4ed6f6b9-77fb-4255-a188-f243dd0cdb3c270=1.93271=0.52331606269=0278=9ad1fc18-5a38-4edb-ac5c-6ac826a8a846270=1.93271=0.52331606269=0278=1c218c8c-baea-4a1f-838e-4a3a94b468e1270=1.93271=0.52331606269=0278=fd70f5e2-d2c9-472a-ab40-a775afafd73d270=1.93271=0.5233160610=240
20250411-01:41:47.599827000 : 8=FIXT.1.19=14035=334=949=24ab46f784d1b20db435b852086e325052=20250411-01:41:47.59956=Coinbase45=2858=Tag appears more than once371=269372=W373=1310=219
20250411-01:41:47.599922000 : 8=FIXT.1.19=90835=W49=Coinbase56=24ab46f784d1b20db435b852086e325034=2950=TEST52=20250411-01:41:47.372967369=2262=019c5c39-7de8-457e-b353-126439f7eeea83=1597559286893=N55=BTC-USD1682=full_trading268=10269=0278=96f5e3a5-1c2a-4db6-a3fb-fd1f13d5d559270=1.93271=0.52331606269=0278=4a015a4c-490a-4c40-974f-9dfb7feb335d270=1.93271=0.52331606269=0278=d919363e-2c54-404f-bc0b-063e2f12bec4270=1.93271=0.52331606269=0278=d4636d6c-85c6-4ac9-9afb-70ca636f4ad4270=1.93271=0.52331606269=0278=bda09690-f345-4c33-ae8b-e8c78da11b5a270=1.93271=0.52331606269=0278=1a81ae10-b700-42a0-89a3-7d7a3eea0ebb270=1.93271=0.52331606269=0278=1ace5afa-e550-4abf-a458-52e46e1b54f0270=1.93271=0.52331606269=0278=2332d1c9-67e7-457a-abfe-f5e9a8c2ea05270=1.93271=0.52331606269=0278=6afa1f19-0ec5-49fd-8b74-06a12a6c5ca9270=1.93271=0.52331606269=0278=3fa3413d-c26c-472f-9cc5-da1c48935c63270=1.93271=0.5233160610=226
20250411-01:41:47.600590000 : 8=FIXT.1.19=14135=334=1049=24ab46f784d1b20db435b852086e325052=20250411-01:41:47.60056=Coinbase45=2958=Tag appears more than once371=269372=W373=1310=244
20250411-01:41:47.600673000 : 8=FIXT.1.19=90835=W49=Coinbase56=24ab46f784d1b20db435b852086e325034=3050=TEST52=20250411-01:41:47.373218369=2262=019c5c39-7de8-457e-b353-126439f7eeea83=1597559286893=N55=BTC-USD1682=full_trading268=10269=0278=3f9e43c4-2e62-4d51-b4cb-ad207c693331270=1.93271=0.52331606269=0278=29e8bfcf-c764-4f7e-997d-09abf72bbc00270=1.93271=0.52331606269=0278=cf3e8b26-09ae-4dfb-9b84-b12a7e199a5a270=1.93271=0.52331606269=0278=08db3e51-e927-47d3-a9dd-2f887c58dc85270=1.93271=0.52331606269=0278=353ae741-9473-4cc5-9ab7-7e5de8ae55d0270=1.93271=0.52331606269=0278=4d037208-2072-480f-98ac-7be9c24f18f4270=1.93271=0.52331606269=0278=b598f678-da6e-4c01-90ed-d702c42f8a65270=1.93271=0.52331606269=0278=5f69b1a0-b5d1-4715-9be1-9bdf008d97d7270=1.93271=0.52331606269=0278=ef063d15-248a-4eae-97f4-278be5106d80270=1.93271=0.52331606269=0278=f8b20207-84bc-44e9-a2fe-9ad775e2ecb1270=1.93271=0.5233160610=189
20250411-01:41:47.601437000 : 8=FIXT.1.19=14135=334=1149=24ab46f784d1b20db435b852086e325052=20250411-01:41:47.60056=Coinbase45=3058=Tag appears more than once371=269372=W373=1310=237
20250411-01:41:47.601529000 : 8=FIXT.1.19=90835=W49=Coinbase56=24ab46f784d1b20db435b852086e325034=3150=TEST52=20250411-01:41:47.373468369=2262=019c5c39-7de8-457e-b353-126439f7eeea83=1597559286893=N55=BTC-USD1682=full_trading268=10269=0278=75bce2b7-bc58-4479-8bfb-144f88f2262b270=1.93271=0.52331606269=0278=1f6e2a79-8b10-4a7f-89de-0f1fa03692c7270=1.93271=0.52331606269=0278=d1b80bf5-9b17-44b4-9577-6fe71170b578270=1.93271=0.52331606269=0278=b891e26a-c20c-4fce-ba1c-487fe139a4cc270=1.93271=0.52331606269=0278=5d06d3f6-3189-4394-b3c5-6a2bda14b6d1270=1.93271=0.52331606269=0278=e5791c0f-3937-4a66-9b98-26f79a3891be270=1.93271=0.52331606269=0278=c62591c6-7dfa-46a7-8f20-6a5f22804999270=1.93271=0.52331606269=0278=7c503558-c0b8-457b-8c46-71ece3f7fc8a270=1.93271=0.52331606269=0278=f763bb56-2f21-4a9b-bd48-f84dc1bd5ee5270=1.93271=0.52331606269=0278=42214b03-1fc2-46b3-9e83-91b23a510e5a270=1.93271=0.5233160610=011
20250411-01:41:47.602251000 : 8=FIXT.1.19=14135=334=1249=24ab46f784d1b20db435b852086e325052=20250411-01:41:47.60156=Coinbase45=3158=Tag appears more than once371=269372=W373=1310=240
20250411-01:41:47.602403000 : 8=FIXT.1.19=90835=W49=Coinbase56=24ab46f784d1b20db435b852086e325034=3250=TEST52=20250411-01:41:47.373718369=2262=019c5c39-7de8-457e-b353-126439f7eeea83=1597559286893=N55=BTC-USD1682=full_trading268=10269=0278=1c7c52ed-7d39-4326-b3b8-98f05a9b3ef0270=1.93271=0.52331606269=0278=3313309e-45e7-4e7b-8c55-4f9a8ec1b351270=1.93271=0.52331606269=0278=78801ffb-ec5a-4c74-9d08-3e86fd9db4dd270=1.93271=0.52331606269=0278=abe6eea4-1d9c-47d7-847f-2f44aa561b3f270=1.93271=0.52331606269=0278=6a6eb56d-2010-43e2-b78e-5f098081bb64270=1.93271=0.52331606269=0278=b53c01ff-f450-4b05-8ad1-e7894b45e0e0270=1.93271=0.52331606269=0278=4747863e-c0a6-4ef5-8faf-e8934bca4f8b270=1.93271=0.52331606269=0278=81a8a629-57f4-4e3a-ac25-2e9ee1f357c2270=1.93271=0.52331606269=0278=1e239259-7be4-476a-845d-1b92fd951d8b270=1.93271=0.52331606269=0278=189eb272-48f9-4915-b7e1-a86dcc505c4a270=1.93271=0.5233160610=103
20250411-01:41:47.603053000 : 8=FIXT.1.19=14135=334=1349=24ab46f784d1b20db435b852086e325052=20250411-01:41:47.60256=Coinbase45=3258=Tag appears more than once371=269372=W373=1310=243
20250411-01:41:47.898280000 : 8=FIXT.1.19=90835=W49=Coinbase56=24ab46f784d1b20db435b852086e325034=3350=TEST52=20250411-01:41:47.373968369=2262=019c5c39-7de8-457e-b353-126439f7eeea83=1597559286893=N55=BTC-USD1682=full_trading268=10269=0278=0562b9f7-aae3-4961-bd97-f5b8cde0ec34270=1.93271=0.52331606269=0278=5103331b-7300-487b-bc2c-a6032bf4be7e270=1.93271=0.52331606269=0278=78ac85ac-2478-4991-a084-7286982b77cc270=1.93271=0.52331606269=0278=6993b26d-d6dc-4f99-8a53-9500ae5b4ff1270=1.93271=0.52331606269=0278=1c96ab9d-04a6-465a-87e5-3ed33970178f270=1.93271=0.52331606269=0278=6fc0282b-d538-4aa3-8982-bda02bb1b054270=1.93271=0.52331606269=0278=80870aa3-04a2-4d2a-8669-93215130ffee270=1.93271=0.52331606269=0278=b274e872-6923-45fd-b48a-68e685e769cb270=1.93271=0.52331606269=0278=2d4364c0-239c-4f4b-8ce4-2acfe0bb343d270=1.12271=1.00000000269=0278=8fa16a4f-377f-4deb-9a8e-1020aed9edf4270=1.00271=1.0000000010=011
20250411-01:41:47.899853000 : 8=FIXT.1.19=14135=334=1449=24ab46f784d1b20db435b852086e325052=20250411-01:41:47.89956=Coinbase45=3358=Tag appears more than once371=269372=W373=1310=007
20250411-01:41:47.900053000 : 8=FIXT.1.19=92735=W49=Coinbase56=24ab46f784d1b20db435b852086e325034=3450=TEST52=20250411-01:41:47.374218369=2262=019c5c39-7de8-457e-b353-126439f7eeea83=1597559286893=N55=BTC-USD1682=full_trading268=10269=1278=c5b88ea9-605d-4595-ac52-f7c3f08523ba270=3.55271=7800.02222216269=1278=81523bd3-8912-4789-8761-89a9ee42794b270=3.55271=0.30518966269=1278=ded84bb8-1c05-468c-8083-8094fdba553a270=3.55271=0.62322946269=1278=60fc75ca-0052-40b7-9f18-a6aad9d31b84270=3.56271=18037.00000000269=1278=ad00e2cd-d925-46a4-9e7e-941c6faed2c7270=3.57271=18027.00000000269=1278=fec191b5-64da-4a15-ab4b-36a0d3d10750270=3.57271=0.29025301269=1278=02a780aa-8154-4638-a5ca-53b8198cc724270=3.58271=16937.00000000269=1278=911349fb-1960-4904-9a38-0e2497fb7ccb270=3.58271=0.29896312269=1278=d91e89d4-ac5c-4853-9879-ec8ff5e00a71270=3.59271=17163.00000000269=1278=dd32d4f9-0ad4-4eb3-a0ec-809f9aac8c2d270=3.59271=0.6197183110=059
20250411-01:41:47.900594000 : 8=FIXT.1.19=14135=334=1549=24ab46f784d1b20db435b852086e325052=20250411-01:41:47.90056=Coinbase45=3458=Tag appears more than once371=269372=W373=1310=248
20250411-01:41:47.900680000 : 8=FIXT.1.19=92835=W49=Coinbase56=24ab46f784d1b20db435b852086e325034=3550=TEST52=20250411-01:41:47.374468369=2262=019c5c39-7de8-457e-b353-126439f7eeea83=1597559286893=N55=BTC-USD1682=full_trading268=10269=1278=341d0ad8-6c15-4b5e-aebb-e3caa5af575c270=3.60271=17926.00000000269=1278=9d239e03-1215-4cc7-ad44-3f4097ee70ea270=3.61271=18058.08928020269=1278=dbb0f332-4189-4df5-879b-e55860b13def270=3.62271=0.28062774269=1278=f7639c39-7e8b-44d1-a2f2-9807e2a3228c270=3.62271=0.27709851269=1278=83be9389-2099-4173-a322-b0933bc99358270=3.62271=19973.00000000269=1278=b89abc22-6b6c-4474-b3fc-ffe21f05cd4e270=3.63271=20016.00000000269=1278=ce0af8a3-149c-4603-905a-be65625fe014270=3.64271=0.27806002269=1278=94b8615f-6fa7-4dc9-bbfa-435fe535bebc270=3.64271=22352.63489459269=1278=5e09602b-cc79-41d1-b8fb-c3c76ed5d601270=3.68271=0.62322946269=1278=cae3885d-f5b2-4de1-830c-0085e27bbb69270=3.69271=0.2772267810=010
20250411-01:41:47.901713000 : 8=FIXT.1.19=14135=334=1649=24ab46f784d1b20db435b852086e325052=20250411-01:41:47.90156=Coinbase45=3558=Tag appears more than once371=269372=W373=1310=251
20250411-01:41:47.901828000 : 8=FIXT.1.19=90835=W49=Coinbase56=24ab46f784d1b20db435b852086e325034=3650=TEST52=20250411-01:41:47.374718369=2262=019c5c39-7de8-457e-b353-126439f7eeea83=1597559286893=N55=BTC-USD1682=full_trading268=10269=1278=b9732128-11b1-44fd-bea3-94da9fc853fb270=3.71271=0.28488329269=1278=818b83a4-e14e-4ad5-b094-6733f0504003270=3.75271=0.27930225269=1278=3e6990a0-8ef4-4968-8ee8-89b7346c197d270=3.76271=0.28131365269=1278=342794c8-a9d2-4aa5-9886-a819398d69c6270=3.88271=0.27719712269=1278=2839680b-48b3-4f53-86b1-9269987275e7270=3.91271=0.26621275269=1278=fd7b5361-29f8-4b35-bae5-232a64f657b4270=3.95271=0.26131406269=1278=5edaeed0-fae9-4f36-8c77-6fbedf61eefc270=4.02271=0.25091227269=1278=fdbbfd04-ba67-4b23-bbc1-f87f929e7e81270=4.07271=0.24812642269=1278=534b2a85-0852-420d-928b-70cdb6ba2457270=4.10271=0.26961968269=1278=b009f8a1-4a39-493b-b96e-d783e981c915270=4.26271=0.2501957410=179
20250411-01:41:47.902422000 : 8=FIXT.1.19=14135=334=1749=24ab46f784d1b20db435b852086e325052=20250411-01:41:47.90256=Coinbase45=3658=Tag appears more than once371=269372=W373=1310=254
20250411-01:41:47.902514000 : 8=FIXT.1.19=92835=W49=Coinbase56=24ab46f784d1b20db435b852086e325034=3750=TEST52=20250411-01:41:47.374968369=2262=019c5c39-7de8-457e-b353-126439f7eeea83=1597559286893=N55=BTC-USD1682=full_trading268=10269=1278=729a899c-ac2d-4541-b0a2-cbdd5df9bf98270=10.00271=10.00000000269=1278=eb1e5d45-d081-4ef8-a83e-1f5348fbda96270=10.00271=10.00000000269=1278=0cd67977-85eb-45fa-ae72-d45b92ca24f4270=10.00271=10.00000000269=1278=5d931559-6758-4b75-9d6d-6438d25b497f270=10.00271=10.00000000269=1278=57e43d1d-644a-493e-acd3-69dc5e64dcde270=10.00271=10.00000000269=1278=c1566121-2b63-494d-ac2d-973e9f0115c0270=10.00271=10.00000000269=1278=d0c4a771-9035-4db9-ae7b-ad2d1db5646d270=10.00271=10.00000000269=1278=52c644ea-628a-4576-8e7e-27ec4c90398b270=10.00271=10.00000000269=1278=c3483f66-d8ce-489a-90b9-2bce69e054ee270=10.00271=10.00000000269=1278=55992a5c-cbcd-464a-8f8d-8b58e81e5c0b270=10.00271=10.0000000010=130
20250411-01:41:47.903401000 : 8=FIXT.1.19=14135=334=1849=24ab46f784d1b20db435b852086e325052=20250411-01:41:47.90256=Coinbase45=3758=Tag appears more than once371=269372=W373=1310=000
20250411-01:41:47.903505000 : 8=FIXT.1.19=93335=W49=Coinbase56=24ab46f784d1b20db435b852086e325034=3850=TEST52=20250411-01:41:47.375218369=2262=019c5c39-7de8-457e-b353-126439f7eeea83=1597559286893=N55=BTC-USD1682=full_trading268=10269=1278=19077009-6f26-4e2d-9dab-04a28231b752270=10.00271=10.00000000269=1278=692097d1-c978-4024-95e9-2bf348b64bbd270=10.00271=10.00000000269=1278=99a92935-11b7-4f21-a64c-c746b53d1777270=10.00271=10.00000000269=1278=dc024b0b-0337-4215-9669-5e5636834397270=10.00271=10.00000000269=1278=c90fcc3a-a36c-4c14-b57f-6db78762e017270=10.00271=10.00000000269=1278=7841891a-bb7c-4034-97c1-41164185edc7270=1000.00271=3.10000000269=1278=381c9fa7-1add-4dd2-9233-f41e2c8821fe270=1000.00271=3.10000000269=1278=928e65c2-7e2d-478b-9310-414fb77f5aae270=1000.00271=3.10000000269=1278=ad4bd3ac-9276-40d5-90f9-e47b1d8ee953270=1000.00271=3.10000000269=1278=79e799dc-4a3d-4922-ad1a-f74eb7eff789270=1000.00271=3.1000000010=055
20250411-01:41:47.904188000 : 8=FIXT.1.19=14135=334=1949=24ab46f784d1b20db435b852086e325052=20250411-01:41:47.90356=Coinbase45=3858=Tag appears more than once371=269372=W373=1310=003
20250411-01:41:47.904346000 : 8=FIXT.1.19=93835=W49=Coinbase56=24ab46f784d1b20db435b852086e325034=3950=TEST52=20250411-01:41:47.375469369=2262=019c5c39-7de8-457e-b353-126439f7eeea83=1597559286893=N55=BTC-USD1682=full_trading268=10269=1278=04f642b7-750f-4967-b786-0d48eea0f158270=1000.00271=3.10000000269=1278=d0ad653d-3272-4a3b-ba7a-a52029a67a92270=1000.00271=3.10000000269=1278=cad40464-4c62-4bf3-8444-c487fcc8dd01270=1000.00271=3.10000000269=1278=426c6428-d481-4ff7-9de3-f00ff219d654270=1000.00271=3.10000000269=1278=1ed1152d-8c1a-4b29-acdd-bbd1a5c5f35f270=1000.00271=3.10000000269=1278=66526051-b5cb-442f-af90-c609be0a9796270=1000.00271=3.10000000269=1278=f68e4659-5785-4ee9-ac24-3186640a2752270=1000.00271=3.10000000269=1278=38070d38-80a9-4898-8ef7-a0a9da5a4123270=1000.00271=3.10000000269=1278=e4d2d308-ed11-49db-850e-3cbd8258395d270=1000.00271=3.10000000269=1278=d6cfaadc-97ea-43c1-898d-40faea9c1477270=1000.00271=3.1000000010=078
20250411-01:41:47.905115000 : 8=FIXT.1.19=14135=334=2049=24ab46f784d1b20db435b852086e325052=20250411-01:41:47.90456=Coinbase45=3958=Tag appears more than once371=269372=W373=1310=253
20250411-01:41:47.905262000 : 8=FIXT.1.19=93835=W49=Coinbase56=24ab46f784d1b20db435b852086e325034=4050=TEST52=20250411-01:41:47.375718369=2262=019c5c39-7de8-457e-b353-126439f7eeea83=1597559286893=N55=BTC-USD1682=full_trading268=10269=1278=36876bea-9e3a-4018-b0ac-b75cb8c16953270=1000.00271=3.10000000269=1278=eb244bc5-49e8-4aa3-af8b-3d1a67c90a08270=1000.00271=3.10000000269=1278=3efba776-29ad-4aeb-82d8-0824f161471e270=1000.00271=3.10000000269=1278=de0ddebd-0ca8-4eca-9985-77c10c8629a9270=1000.00271=3.10000000269=1278=dde4408a-fb6b-441c-a7f3-7b8b23ffdb1f270=1000.00271=3.10000000269=1278=3ebd6434-070f-4b4d-8cf3-00368112466d270=1000.00271=3.10000000269=1278=7aa98e13-65f3-4058-9f91-c1f452d02710270=1000.00271=3.10000000269=1278=e86a1fec-3610-460d-8d85-4e1e222ee159270=1000.00271=3.10000000269=1278=6dfac057-72b1-4f2c-b110-03766dea0d31270=1000.00271=3.10000000269=1278=bbb7d0ea-d251-4612-b53e-e528cc0a24ab270=1000.00271=3.1000000010=243
20250411-01:41:47.905982000 : 8=FIXT.1.19=14135=334=2149=24ab46f784d1b20db435b852086e325052=20250411-01:41:47.90556=Coinbase45=4058=Tag appears more than once371=269372=W373=1310=247
20250411-01:41:47.906157000 : 8=FIXT.1.19=93835=W49=Coinbase56=24ab46f784d1b20db435b852086e325034=4150=TEST52=20250411-01:41:47.375968369=2262=019c5c39-7de8-457e-b353-126439f7eeea83=1597559286893=N55=BTC-USD1682=full_trading268=10269=1278=0782ca37-48cf-4ff3-a74a-35674661586c270=1000.00271=3.10000000269=1278=aead437d-4b62-457f-ac83-62c7cc329fd1270=1000.00271=3.10000000269=1278=af5d47bc-a008-4567-b24f-b0298f250471270=1000.00271=3.10000000269=1278=4c260f58-c427-4a9a-969a-44024ae0c714270=1000.00271=3.10000000269=1278=8c7672e5-7ee8-4fbd-8fdf-7e74e9a77db7270=1000.00271=3.10000000269=1278=b53ec3cc-9abe-4570-b903-34d52148073e270=1000.00271=3.10000000269=1278=37ce984a-0387-4ac9-9094-b83f722036ba270=1000.00271=3.10000000269=1278=0d383649-dc6c-4df2-b821-aa0018f132c7270=1000.00271=3.10000000269=1278=e39ae0ce-9e7f-4f0d-a765-5308d473bb61270=1000.00271=3.10000000269=1278=4882324e-3b5c-4b7a-b096-e8c6d9888671270=1000.00271=3.1000000010=170
20250411-01:41:47.906771000 : 8=FIXT.1.19=14135=334=2249=24ab46f784d1b20db435b852086e325052=20250411-01:41:47.90656=Coinbase45=4158=Tag appears more than once371=269372=W373=1310=250
20250411-01:41:47.906852000 : 8=FIXT.1.19=93835=W49=Coinbase56=24ab46f784d1b20db435b852086e325034=4250=TEST52=20250411-01:41:47.376218369=2262=019c5c39-7de8-457e-b353-126439f7eeea83=1597559286893=N55=BTC-USD1682=full_trading268=10269=1278=6e5c7dbd-a2cc-401f-a5b2-3902088f4ab2270=1000.00271=3.10000000269=1278=10ffac08-946a-4a30-b57a-0d78450345d9270=1000.00271=3.10000000269=1278=67784af5-72bf-4d16-a6b3-25336e2c1843270=1000.00271=3.10000000269=1278=4d8b3bbc-0dc2-4044-875c-c079ec538136270=1000.00271=3.10000000269=1278=dfba5f1e-21f5-48e3-adce-b8b6bfe71467270=1000.00271=3.10000000269=1278=e51b4e33-5eaa-46ef-936b-a74a890397e8270=1000.00271=3.10000000269=1278=8cf5dfa8-858b-48a3-9d94-78522c257473270=1000.00271=3.10000000269=1278=a153b9d2-993d-4f03-a974-b8a081e128e8270=1000.00271=3.10000000269=1278=1eebe866-0f6e-4d4a-a28b-78f4e3368b0a270=1000.00271=3.10000000269=1278=300132d8-113f-4bf7-ba0c-4d93a272f55b270=1000.00271=3.1000000010=186
20250411-01:41:47.907448000 : 8=FIXT.1.19=14135=334=2349=24ab46f784d1b20db435b852086e325052=20250411-01:41:47.90756=Coinbase45=4258=Tag appears more than once371=269372=W373=1310=253
20250411-01:41:47.907532000 : 8=FIXT.1.19=93835=W49=Coinbase56=24ab46f784d1b20db435b852086e325034=4350=TEST52=20250411-01:41:47.376468369=2262=019c5c39-7de8-457e-b353-126439f7eeea83=1597559286893=N55=BTC-USD1682=full_trading268=10269=1278=757f3122-27d2-4f32-90b8-ead1eef9b936270=1000.00271=3.10000000269=1278=2b68b5de-4153-4cac-ace3-102e4fa788fd270=1000.00271=3.10000000269=1278=b01f252a-1657-4df0-a122-58a23109a7c2270=1000.00271=3.10000000269=1278=dbc57e4e-6abd-4d66-8d18-bd13caaa77b1270=1000.00271=3.10000000269=1278=948b05dc-a481-409f-b8ad-a502eb595906270=1000.00271=3.10000000269=1278=e00f9703-6e16-4237-a2c6-701829d11bf1270=1000.00271=3.10000000269=1278=fd52f47a-3f11-47bc-9952-9708617d0ecd270=1000.00271=3.10000000269=1278=f7f75b14-27c3-469c-89fb-6a98b43c61bf270=1000.00271=3.10000000269=1278=25dbeb09-7901-4280-b0c3-720d7ed03d7d270=1000.00271=3.10000000269=1278=52164a1f-599f-4c43-a9ed-f93403506e67270=1000.00271=3.1000000010=028
20250411-01:41:47.908065000 : 8=FIXT.1.19=14135=334=2449=24ab46f784d1b20db435b852086e325052=20250411-01:41:47.90756=Coinbase45=4358=Tag appears more than once371=269372=W373=1310=255
20250411-01:41:47.908198000 : 8=FIXT.1.19=93835=W49=Coinbase56=24ab46f784d1b20db435b852086e325034=4450=TEST52=20250411-01:41:47.376718369=2262=019c5c39-7de8-457e-b353-126439f7eeea83=1597559286893=N55=BTC-USD1682=full_trading268=10269=1278=c71c35ea-f60f-4a41-b43a-4947bbcbafad270=1000.00271=3.10000000269=1278=2de342bc-a1be-46f3-9fc6-731297726934270=1000.00271=3.10000000269=1278=7ff4c5fc-bc9b-4845-940b-4837a672e13a270=1000.00271=3.10000000269=1278=2d270775-33eb-4328-8dad-7d206612f9f6270=1000.00271=3.10000000269=1278=c4754378-f787-4100-81af-564443a86a91270=1000.00271=3.10000000269=1278=59e16255-05eb-4fdc-8be1-3c4f83fc094e270=1000.00271=3.10000000269=1278=041b2f98-1185-49cb-964a-f0456b71e692270=1000.00271=3.10000000269=1278=9a2f3529-481e-4e50-a123-7a2095fe6b2c270=1000.00271=3.10000000269=1278=9ed552a3-3295-4878-85dd-87b7b5590212270=1000.00271=3.10000000269=1278=54bec5c2-bafd-4d7d-851d-59e3553a053f270=1000.00271=3.1000000010=219
20250411-01:41:47.909092000 : 8=FIXT.1.19=14135=334=2549=24ab46f784d1b20db435b852086e325052=20250411-01:41:47.90856=Coinbase45=4458=Tag appears more than once371=269372=W373=1310=002
20250411-01:41:47.909203000 : 8=FIXT.1.19=93835=W49=Coinbase56=24ab46f784d1b20db435b852086e325034=4550=TEST52=20250411-01:41:47.376969369=2262=019c5c39-7de8-457e-b353-126439f7eeea83=1597559286893=N55=BTC-USD1682=full_trading268=10269=1278=543c1acf-52f2-442b-a893-f7aa9a5dfbd1270=1000.00271=3.10000000269=1278=fec999be-cbd0-42ef-b9c3-82ca92ef0b58270=1000.00271=3.10000000269=1278=24528176-3fc6-45b2-b2f3-9f784c01495a270=1000.00271=3.10000000269=1278=12081678-66a6-4435-a3d7-b65f959cf2ac270=1000.00271=3.10000000269=1278=e7fb6165-8f1a-4b5e-b095-e232b83ee951270=1000.00271=3.10000000269=1278=83ce6582-410a-40bf-9831-8f3d20e3a629270=1000.00271=3.10000000269=1278=bc3a930b-0567-46ba-86a4-712f76466b0b270=1000.00271=3.10000000269=1278=15704973-f5ff-457d-ab31-8f99bb76bf7e270=1000.00271=3.10000000269=1278=7159045b-cbd5-458f-b91f-9fa5241b14b5270=1000.00271=3.10000000269=1278=9fa52a90-f03f-4940-b5ee-39ab937b86f1270=1000.00271=3.1000000010=152
20250411-01:41:47.909921000 : 8=FIXT.1.19=14135=334=2649=24ab46f784d1b20db435b852086e325052=20250411-01:41:47.90956=Coinbase45=4558=Tag appears more than once371=269372=W373=1310=005
20250411-01:41:47.910023000 : 8=FIXT.1.19=93835=W49=Coinbase56=24ab46f784d1b20db435b852086e325034=4650=TEST52=20250411-01:41:47.377218369=2262=019c5c39-7de8-457e-b353-126439f7eeea83=1597559286893=N55=BTC-USD1682=full_trading268=10269=1278=220f55cd-a279-4bf0-9c80-1dca086d85dc270=1000.00271=3.10000000269=1278=2b1eb468-6bcd-4117-a7c0-214d643ddad4270=1000.00271=3.10000000269=1278=cc23185d-e72e-42cb-8210-61bab29cd778270=1000.00271=3.10000000269=1278=69bb228b-973b-4176-8708-3231cc40102a270=1000.00271=3.10000000269=1278=2ec8035d-7962-4195-8388-c9fbad52ac8a270=1000.00271=3.10000000269=1278=7d39e416-0b7b-471f-a9ac-455ab1bce5a7270=1000.00271=3.10000000269=1278=7067378d-2a65-41f2-acb0-ef30ddbc3e5a270=1000.00271=3.10000000269=1278=bf3fde78-6cff-4477-b381-4b5d2e68f36f270=1000.00271=3.10000000269=1278=93a2a8a3-61d4-410c-9446-8eabaafc5f29270=1000.00271=3.10000000269=1278=5afddb61-63ab-417b-a28a-41c4c03a6612270=1000.00271=3.1000000010=206
20250411-01:41:47.910705000 : 8=FIXT.1.19=14135=334=2749=24ab46f784d1b20db435b852086e325052=20250411-01:41:47.91056=Coinbase45=4658=Tag appears more than once371=269372=W373=1310=255
20250411-01:41:47.910799000 : 8=FIXT.1.19=93835=W49=Coinbase56=24ab46f784d1b20db435b852086e325034=4750=TEST52=20250411-01:41:47.377469369=2262=019c5c39-7de8-457e-b353-126439f7eeea83=1597559286893=N55=BTC-USD1682=full_trading268=10269=1278=a4280417-189c-4f76-9d2e-6ec652010bf5270=1000.00271=3.10000000269=1278=ddeb78a2-e110-4828-ba3d-c9b4837e7dd7270=1000.00271=3.10000000269=1278=fcec6c90-441a-4f4a-a94e-9003355657ef270=1000.00271=3.10000000269=1278=6db15389-dfb3-4156-8a4e-ce2ac80f2b15270=1000.00271=3.10000000269=1278=47dfefc3-6f05-4b57-8aec-2bf3e6c70c2d270=1000.00271=3.10000000269=1278=fb9fd019-4b4f-4880-82bb-3df6d1ef468a270=1000.00271=3.10000000269=1278=2cff9acd-42cb-43a5-8d50-51e676b7e763270=1000.00271=3.10000000269=1278=6e6eeb59-4728-4811-9a44-c857df6aca42270=1000.00271=3.10000000269=1278=81798560-263f-4819-a528-5f3fbbc7b042270=1000.00271=3.10000000269=1278=81fbf9a8-82f4-4fe4-9fa5-3773b212ebf4270=1000.00271=3.1000000010=039
20250411-01:41:47.911460000 : 8=FIXT.1.19=14135=334=2849=24ab46f784d1b20db435b852086e325052=20250411-01:41:47.91156=Coinbase45=4758=Tag appears more than once371=269372=W373=1310=002
20250411-01:41:47.911544000 : 8=FIXT.1.19=93835=W49=Coinbase56=24ab46f784d1b20db435b852086e325034=4850=TEST52=20250411-01:41:47.377719369=2262=019c5c39-7de8-457e-b353-126439f7eeea83=1597559286893=N55=BTC-USD1682=full_trading268=10269=1278=5d3b9566-276d-47fe-a111-12c17f53f501270=1000.00271=3.10000000269=1278=8eb1b3b3-c813-48b1-b839-993672108d91270=1000.00271=3.10000000269=1278=4feb6e93-6149-481b-8d58-e1c8e6c5cda1270=1000.00271=3.10000000269=1278=f8611e72-4056-4b7c-9779-4d54cd151d44270=1000.00271=3.10000000269=1278=7a129f7c-d9ba-4ea3-a267-b7d82b2e07d9270=1000.00271=3.10000000269=1278=01f359f0-c38f-416b-af00-183907218793270=1000.00271=3.10000000269=1278=11741cec-9c08-4a20-99dc-6b9f63130b0e270=1000.00271=3.10000000269=1278=08db2574-ad52-4520-ab5b-c3c7591eb781270=1000.00271=3.10000000269=1278=b06f2249-179c-4a15-8e98-7b76083b808b270=1000.00271=3.10000000269=1278=9e88fede-6d19-4c1f-863b-5a7d66781436270=1000.00271=3.1000000010=203
20250411-01:41:47.912212000 : 8=FIXT.1.19=14135=334=2949=24ab46f784d1b20db435b852086e325052=20250411-01:41:47.91156=Coinbase45=4858=Tag appears more than once371=269372=W373=1310=004
20250411-01:41:47.912307000 : 8=FIXT.1.19=93835=W49=Coinbase56=24ab46f784d1b20db435b852086e325034=4950=TEST52=20250411-01:41:47.377969369=2262=019c5c39-7de8-457e-b353-126439f7eeea83=1597559286893=N55=BTC-USD1682=full_trading268=10269=1278=75e1d8b4-7201-41fe-a687-7d93420af323270=1000.00271=3.10000000269=1278=d00aa7dd-ce7f-4f8b-9a2e-880c1ea30845270=1000.00271=3.10000000269=1278=584a483f-23bf-4d8b-809f-69cf3c110f60270=1000.00271=3.10000000269=1278=dc98524e-27e2-4863-99e4-7a0097a6ee90270=1000.00271=3.10000000269=1278=82a11ac9-4f46-44b7-a0bc-a5a4cfe686e0270=1000.00271=3.10000000269=1278=f946bb05-900c-41fc-9908-41489e97ff20270=1000.00271=3.10000000269=1278=1f9186d6-0312-4677-ba96-fdb014cdff2c270=1000.00271=3.10000000269=1278=c3b67be7-2b63-4884-b311-80f28496c2c4270=1000.00271=3.10000000269=1278=6576c7f8-a4e2-4417-b854-5fef0e705fbe270=1000.00271=3.10000000269=1278=c2102c71-62f0-4eee-ae60-0777ed26a8e6270=1000.00271=3.1000000010=007
20250411-01:41:47.912945000 : 8=FIXT.1.19=14135=334=3049=24ab46f784d1b20db435b852086e325052=20250411-01:41:47.91256=Coinbase45=4958=Tag appears more than once371=269372=W373=1310=254
20250411-01:41:47.913030000 : 8=FIXT.1.19=93835=W49=Coinbase56=24ab46f784d1b20db435b852086e325034=5050=TEST52=20250411-01:41:47.378219369=2262=019c5c39-7de8-457e-b353-126439f7eeea83=1597559286893=N55=BTC-USD1682=full_trading268=10269=1278=c823a2b6-849e-4839-a2fd-cd9f459cae6c270=1000.00271=3.10000000269=1278=a051e195-4472-4a8a-8591-08a2c04a33c4270=1000.00271=3.10000000269=1278=ec81b8c4-b703-4afd-a701-ce34011f60f6270=1000.00271=3.10000000269=1278=b1172677-f493-4f32-a200-0710cf8c397f270=1000.00271=3.10000000269=1278=b1a58a75-5fca-43db-b9c6-a26920e8f66e270=1000.00271=3.10000000269=1278=038bea41-b91d-4884-b992-3e5431ef9857270=1000.00271=3.10000000269=1278=55063782-f2ea-4c84-9491-8e8e89d1dfd1270=1000.00271=3.10000000269=1278=bb2011e8-d05d-40ac-9e9c-3b720422e38d270=1000.00271=3.10000000269=1278=64dd3b4a-ce8a-4b63-9937-266e832c0f21270=1000.00271=3.10000000269=1278=d64f7d2a-aa83-486c-92a8-3314c4eddd58270=1000.00271=3.1000000010=213
20250411-01:41:47.913655000 : 8=FIXT.1.19=14135=334=3149=24ab46f784d1b20db435b852086e325052=20250411-01:41:47.91356=Coinbase45=5058=Tag appears more than once371=269372=W373=1310=248
20250411-01:41:47.913758000 : 8=FIXT.1.19=93835=W49=Coinbase56=24ab46f784d1b20db435b852086e325034=5150=TEST52=20250411-01:41:47.378469369=2262=019c5c39-7de8-457e-b353-126439f7eeea83=1597559286893=N55=BTC-USD1682=full_trading268=10269=1278=0df9641b-d89d-4222-a8ea-bcddf0d555f5270=1000.00271=3.10000000269=1278=7a315b16-a05f-408d-b8c1-2704af9bf767270=1000.00271=3.10000000269=1278=0e9712a8-d00f-4864-a478-f7f591718f91270=1000.00271=3.10000000269=1278=94db025d-eada-49e3-b13c-b667ca07f829270=1000.00271=3.10000000269=1278=a88ccd1f-8f8d-46af-8fb6-20adba35f7d1270=1000.00271=3.10000000269=1278=99d4e235-c8ec-4efc-938c-9a1923eafc96270=1000.00271=3.10000000269=1278=a4fc7173-7583-4f8b-b256-2921bef83c84270=1000.00271=3.10000000269=1278=18f8afd4-8bbc-4ffa-8e8f-0c1834d74472270=1000.00271=3.10000000269=1278=21fc8cb6-f894-4d09-884e-810b8ebf2ef3270=1000.00271=3.10000000269=1278=0c13b9e6-6797-4b3e-90ce-a1885b26ba53270=1000.00271=3.1000000010=255
20250411-01:41:47.914469000 : 8=FIXT.1.19=14135=334=3249=24ab46f784d1b20db435b852086e325052=20250411-01:41:47.91456=Coinbase45=5158=Tag appears more than once371=269372=W373=1310=251
20250411-01:41:47.914562000 : 8=FIXT.1.19=93835=W49=Coinbase56=24ab46f784d1b20db435b852086e325034=5250=TEST52=20250411-01:41:47.378719369=2262=019c5c39-7de8-457e-b353-126439f7eeea83=1597559286893=N55=BTC-USD1682=full_trading268=10269=1278=6d8da581-3998-4fc0-99b6-3c5edbd514cb270=1000.00271=3.10000000269=1278=67a70307-be50-4065-872b-47e0de473bc4270=1000.00271=3.10000000269=1278=8ce7be0b-98de-46d0-b1b6-307a4bec36e2270=1000.00271=3.10000000269=1278=856b22f8-5884-4739-adc0-bdd851c5c07d270=1000.00271=3.10000000269=1278=c00ae651-a76b-4bfd-be16-3672b345fe29270=1000.00271=3.10000000269=1278=cae248f9-16fc-44ea-9b79-1dacfc285db6270=1000.00271=3.10000000269=1278=42bb223c-88c6-4a18-8ff3-4fd8d9efda8d270=1000.00271=3.10000000269=1278=d7188b01-22b6-4837-a720-077601f7f483270=1000.00271=3.10000000269=1278=5d85a0a6-ddd9-4e0e-9a1a-7f418ef588e5270=1000.00271=3.10000000269=1278=bff4c39f-7a80-42ce-a178-b1221792e445270=1000.00271=3.1000000010=015
20250411-01:41:47.915157000 : 8=FIXT.1.19=14135=334=3349=24ab46f784d1b20db435b852086e325052=20250411-01:41:47.91456=Coinbase45=5258=Tag appears more than once371=269372=W373=1310=253
20250411-01:41:47.915255000 : 8=FIXT.1.19=93835=W49=Coinbase56=24ab46f784d1b20db435b852086e325034=5350=TEST52=20250411-01:41:47.378969369=2262=019c5c39-7de8-457e-b353-126439f7eeea83=1597559286893=N55=BTC-USD1682=full_trading268=10269=1278=9ea3d263-b5ab-46c5-bf27-8c0e3e0e5e9e270=1000.00271=3.10000000269=1278=b93347df-d2ab-48ec-b326-4454e64f1d4e270=1000.00271=3.10000000269=1278=57acc40d-8478-444a-990f-067a8e8e846e270=1000.00271=3.10000000269=1278=34419ae2-2c16-427b-a290-845419760fd5270=1000.00271=3.10000000269=1278=ab41de2d-5def-4986-b56e-243d2f99a57c270=1000.00271=3.10000000269=1278=9025524c-03a9-407a-a58a-5258c4ea0a0b270=1000.00271=3.10000000269=1278=60766318-112b-4d83-a384-55693de75519270=1000.00271=3.10000000269=1278=c19b6a2c-086b-4fc1-8dfe-51cb2dc12c1d270=1000.00271=3.10000000269=1278=11126433-0f9c-4450-a35a-39b878e85e68270=1000.00271=3.10000000269=1278=e2e620ee-44fb-4630-a890-d331ba5b2fae270=1000.00271=3.1000000010=162
20250411-01:41:47.915885000 : 8=FIXT.1.19=14135=334=3449=24ab46f784d1b20db435b852086e325052=20250411-01:41:47.91556=Coinbase45=5358=Tag appears more than once371=269372=W373=1310=000
20250411-01:41:47.915984000 : 8=FIXT.1.19=93835=W49=Coinbase56=24ab46f784d1b20db435b852086e325034=5450=TEST52=20250411-01:41:47.379219369=2262=019c5c39-7de8-457e-b353-126439f7eeea83=1597559286893=N55=BTC-USD1682=full_trading268=10269=1278=9ccf6d4b-a6ca-4a1f-a7bb-77f400ace0c8270=1000.00271=3.10000000269=1278=0e8d6c10-8421-4f19-97dc-d70e715d9033270=1000.00271=3.10000000269=1278=f31ecd5d-8231-44ea-a5c2-0fcc5a699401270=1000.00271=3.10000000269=1278=37fbb559-dc52-48fe-ab65-24910edc338a270=1000.00271=3.10000000269=1278=bc1435c5-c59c-4017-9e59-f1073f04c7e2270=1000.00271=3.10000000269=1278=9c8e1397-0cee-4b05-a66f-5594040791c4270=1000.00271=3.10000000269=1278=248b6703-f829-42bb-a551-4be3075c381e270=1000.00271=3.10000000269=1278=16d257b0-bc92-44f0-822d-3eba61af4bda270=1000.00271=3.10000000269=1278=06257aa1-4043-4cdb-9286-4342b8e59108270=1000.00271=3.10000000269=1278=210ec210-1443-47dc-9e43-9c9ea720a6c3270=1000.00271=3.1000000010=145
20250411-01:41:47.916773000 : 8=FIXT.1.19=14135=334=3549=24ab46f784d1b20db435b852086e325052=20250411-01:41:47.91656=Coinbase45=5458=Tag appears more than once371=269372=W373=1310=003
20250411-01:41:47.916879000 : 8=FIXT.1.19=93835=W49=Coinbase56=24ab46f784d1b20db435b852086e325034=5550=TEST52=20250411-01:41:47.379469369=2262=019c5c39-7de8-457e-b353-126439f7eeea83=1597559286893=N55=BTC-USD1682=full_trading268=10269=1278=8b79da5d-b78c-4011-b55f-b35c16dc3724270=1000.00271=3.10000000269=1278=076c3703-1104-4e15-a38a-d95bf133f0c5270=1000.00271=3.10000000269=1278=f5a3155c-e449-4102-870d-ab8c8dd24c3d270=1000.00271=3.10000000269=1278=1af2681f-2dec-4d25-aaeb-89b8867b4a3c270=1000.00271=3.10000000269=1278=65c3088d-192a-4213-85a3-7257aa8b20a3270=1000.00271=3.10000000269=1278=2aa7989b-5601-4899-8143-01dda3255e4f270=1000.00271=3.10000000269=1278=099b432c-fa2e-4fd7-952e-22f6debf6877270=1000.00271=3.10000000269=1278=2e71cc31-1235-4b7b-a728-e3335631fe5a270=1000.00271=3.10000000269=1278=ce471ffc-1e26-4afe-afab-27ee5ac8debe270=1000.00271=3.10000000269=1278=113b7fc6-8574-40eb-8682-d077245b84f2270=1000.00271=3.1000000010=123
20250411-01:41:47.917545000 : 8=FIXT.1.19=14135=334=3649=24ab46f784d1b20db435b852086e325052=20250411-01:41:47.91756=Coinbase45=5558=Tag appears more than once371=269372=W373=1310=006
20250411-01:41:47.917640000 : 8=FIXT.1.19=93835=W49=Coinbase56=24ab46f784d1b20db435b852086e325034=5650=TEST52=20250411-01:41:47.379719369=2262=019c5c39-7de8-457e-b353-126439f7eeea83=1597559286893=N55=BTC-USD1682=full_trading268=10269=1278=bcebce2c-eda8-4b85-841d-27ede39fc5a1270=1000.00271=3.10000000269=1278=0aedaae5-6cc6-4a34-8e48-5e67a5ccc148270=1000.00271=3.10000000269=1278=206e10a5-1173-4860-87b5-7c88afe061f6270=1000.00271=3.10000000269=1278=5c32d94b-696a-4d9b-afa0-665970356008270=1000.00271=3.10000000269=1278=0b7da819-cc1e-4525-a382-ce5b90dc485c270=1000.00271=3.10000000269=1278=2241b3bf-cbbe-44f2-ac75-8032f6283aa8270=1000.00271=3.10000000269=1278=88cada69-adb1-466a-afcd-66e063ad27c0270=1000.00271=3.10000000269=1278=34a52ef5-31c1-4c63-9230-21c85a9a6ba3270=1000.00271=3.10000000269=1278=e109c2c8-fb1d-4ef9-a640-368381323507270=1000.00271=3.10000000269=1278=38fd36c4-4c62-4b4c-8f24-1fe39be94fa1270=1000.00271=3.1000000010=237
20250411-01:41:47.918384000 : 8=FIXT.1.19=14135=334=3749=24ab46f784d1b20db435b852086e325052=20250411-01:41:47.91856=Coinbase45=5658=Tag appears more than once371=269372=W373=1310=009
20250411-01:41:47.918475000 : 8=FIXT.1.19=93835=W49=Coinbase56=24ab46f784d1b20db435b852086e325034=5750=TEST52=20250411-01:41:47.379969369=2262=019c5c39-7de8-457e-b353-126439f7eeea83=1597559286893=N55=BTC-USD1682=full_trading268=10269=1278=f83f64c8-7d33-472d-a516-9b664ff9c966270=1000.00271=3.10000000269=1278=3411c368-380b-42e6-b656-8552d92904d5270=1000.00271=3.10000000269=1278=4803796e-79f3-4aa4-a8cb-37f13899bf01270=1000.00271=3.10000000269=1278=823f8fbf-7e6d-4ae3-adb9-3a822ff6d09a270=1000.00271=3.10000000269=1278=135624df-a204-490f-a68b-63d74ee09908270=1000.00271=3.10000000269=1278=47cfdedf-22b9-402c-93bd-f311103fd3e0270=1000.00271=3.10000000269=1278=f9173d5e-d872-4661-93f6-28f527e931f7270=1000.00271=3.10000000269=1278=06ab1365-fd39-4701-bd7f-1915ad3c7602270=1000.00271=3.10000000269=1278=012a7c59-5ae4-4da5-97ba-2e3254c889fb270=1000.00271=3.10000000269=1278=a9a0d42f-ad9e-4ea9-8bf0-d5a441fded40270=1000.00271=3.1000000010=035
20250411-01:41:47.919141000 : 8=FIXT.1.19=14135=334=3849=24ab46f784d1b20db435b852086e325052=20250411-01:41:47.91856=Coinbase45=5758=Tag appears more than once371=269372=W373=1310=011
20250411-01:41:47.919230000 : 8=FIXT.1.19=93835=W49=Coinbase56=24ab46f784d1b20db435b852086e325034=5850=TEST52=20250411-01:41:47.380219369=2262=019c5c39-7de8-457e-b353-126439f7eeea83=1597559286893=N55=BTC-USD1682=full_trading268=10269=1278=f3f3930e-be0e-40b4-a97d-d19501a54885270=1000.00271=3.10000000269=1278=261922d0-5c81-4ab6-832f-4eff45f64890270=1000.00271=3.10000000269=1278=3af4e45f-56f6-4c69-894d-d56a14894a98270=1000.00271=3.10000000269=1278=1c1dd248-49e4-44aa-9e69-323b0f41fa0e270=1000.00271=3.10000000269=1278=b16b002d-1cd6-4869-9c1b-f15c758611bf270=1000.00271=3.10000000269=1278=a0520e61-28ad-448d-87c1-49f0c7358628270=1000.00271=3.10000000269=1278=152d0b57-086f-48cc-80b3-ff14ee9375ed270=1000.00271=3.10000000269=1278=c55fc264-67d2-4e9c-8cce-6c834feff648270=1000.00271=3.10000000269=1278=27361968-189a-4fa6-a3a2-eead03c640d6270=1000.00271=3.10000000269=1278=f5b01c67-f98f-44b9-a511-7f07f8883d9e270=1000.00271=3.1000000010=147
20250411-01:41:47.919763000 : 8=FIXT.1.19=14135=334=3949=24ab46f784d1b20db435b852086e325052=20250411-01:41:47.91956=Coinbase45=5858=Tag appears more than once371=269372=W373=1310=014
20250411-01:41:47.919840000 : 8=FIXT.1.19=93835=W49=Coinbase56=24ab46f784d1b20db435b852086e325034=5950=TEST52=20250411-01:41:47.380469369=2262=019c5c39-7de8-457e-b353-126439f7eeea83=1597559286893=N55=BTC-USD1682=full_trading268=10269=1278=75a5c14f-8434-4533-a10e-0bf6e92e1000270=1000.00271=3.10000000269=1278=a9b0a826-3659-4105-9ecc-21bcd27b736f270=1000.00271=3.10000000269=1278=1b1bab77-5c52-459b-98e3-e27ff6f8cd04270=1000.00271=3.10000000269=1278=346695f1-fe03-4364-8fc5-006796c8f82f270=1000.00271=3.10000000269=1278=cbbaa36d-2a03-45a2-a230-bd5845d832cd270=1000.00271=3.10000000269=1278=745d4fc0-6710-4c5c-97c3-7b29c4e06839270=1000.00271=3.10000000269=1278=e95fdfba-5db2-4461-8e9c-7bfdf8a9238c270=1000.00271=3.10000000269=1278=33611b39-1fbf-45cc-bf5e-a02bc1f84736270=1000.00271=3.10000000269=1278=51f77b2d-1a69-432d-934b-234eb9e1dfac270=1000.00271=3.10000000269=1278=ab09fdc3-8d50-432f-ab0f-97e8627eac24270=1000.00271=3.1000000010=076
20250411-01:41:47.920520000 : 8=FIXT.1.19=14135=334=4049=24ab46f784d1b20db435b852086e325052=20250411-01:41:47.92056=Coinbase45=5958=Tag appears more than once371=269372=W373=1310=255
20250411-01:41:48.121961000 : 8=FIXT.1.19=93835=W49=Coinbase56=24ab46f784d1b20db435b852086e325034=6050=TEST52=20250411-01:41:47.380719369=2262=019c5c39-7de8-457e-b353-126439f7eeea83=1597559286893=N55=BTC-USD1682=full_trading268=10269=1278=dde04213-6104-44c5-a811-15834c27b515270=1000.00271=3.10000000269=1278=9af2b85c-4997-4e1b-9147-7d400f059b01270=1000.00271=3.10000000269=1278=40870860-7a8a-4419-a117-e511f779abfa270=1000.00271=3.10000000269=1278=3e8fa7bd-dde0-4fe4-bb2e-e6279841b019270=1000.00271=3.10000000269=1278=4dde1422-98d8-405b-88df-bf245291ad7a270=1000.00271=3.10000000269=1278=6ee8b5a8-bc2f-4a0a-9ae4-7ff1b5dae941270=1000.00271=3.10000000269=1278=3ebc1f7a-2bb5-4ef0-a82f-844b9540f6e8270=1000.00271=3.10000000269=1278=a82d5bb9-1f1a-4575-b580-8d9b60863b10270=1000.00271=3.10000000269=1278=14f89bd5-0233-435c-b608-2e19131b8f6c270=1000.00271=3.10000000269=1278=a2e319e5-aab7-41d4-9d19-98d771a3f1d3270=1000.00271=3.1000000010=026
20250411-01:41:48.122710000 : 8=FIXT.1.19=14135=334=4149=24ab46f784d1b20db435b852086e325052=20250411-01:41:48.12256=Coinbase45=6058=Tag appears more than once371=269372=W373=1310=243
20250411-01:41:48.122925000 : 8=FIXT.1.19=93835=W49=Coinbase56=24ab46f784d1b20db435b852086e325034=6150=TEST52=20250411-01:41:47.380969369=2262=019c5c39-7de8-457e-b353-126439f7eeea83=1597559286893=N55=BTC-USD1682=full_trading268=10269=1278=dc965e0b-075a-4ba4-a498-02c96d1664ba270=1000.00271=3.10000000269=1278=67b6e68f-ac11-4c05-a54a-2adb555b0123270=1000.00271=3.10000000269=1278=866f52a1-dad9-49d7-ac4a-9da3075407a3270=1000.00271=3.10000000269=1278=0e38234d-a010-40f6-9c6f-a0d574e773cf270=1000.00271=3.10000000269=1278=d6af6749-e3c8-4938-8741-1d5f177cf8e1270=1000.00271=3.10000000269=1278=45ff5e59-2c4d-45ac-9fde-403662dfd1ca270=1000.00271=3.10000000269=1278=dcac314e-c54f-44e3-b96d-ef71539766ed270=1000.00271=3.10000000269=1278=dd6d14ea-760f-4884-a546-1d3c40ebdd7c270=1000.00271=3.10000000269=1278=4f3da0c6-46eb-4b64-b973-cc43e24abccb270=1000.00271=3.10000000269=1278=aa40cda8-4abd-4f52-999a-1a90ed5bf41a270=1000.00271=3.1000000010=127
20250411-01:41:48.123729000 : 8=FIXT.1.19=14135=334=4249=24ab46f784d1b20db435b852086e325052=20250411-01:41:48.12356=Coinbase45=6158=Tag appears more than once371=269372=W373=1310=246
20250411-01:41:48.123827000 : 8=FIXT.1.19=95235=W49=Coinbase56=24ab46f784d1b20db435b852086e325034=6250=TEST52=20250411-01:41:47.381219369=2262=019c5c39-7de8-457e-b353-126439f7eeea83=1597559286893=N55=BTC-USD1682=full_trading268=10269=1278=687ee4fc-f626-4e4f-abee-1f0ee5af3f72270=1000.00271=3.10000000269=1278=b1ad1135-67ec-4c96-99cb-a626137f3f16270=10000.00271=1.00000000269=1278=e9320f5f-80ae-41ab-af7a-86518d456fb0270=10000.00271=1.00000000269=1278=cd95aff0-36fa-4804-887f-2c3fce3cdc86270=10000.00271=1.00000000269=1278=fbdbcee1-8c29-4478-97df-358d209d8808270=10000.00271=1.00000000269=1278=140f39da-834b-4e42-8e15-6e25287df1f0270=900000.00271=0.00011111269=1278=49f064c5-76fe-4b38-bede-48b60a0a5aec270=900000.00271=0.00011111269=1278=681cf73b-9d37-4101-b940-9da9b1ff61ed270=900000.00271=0.00011111269=1278=3dea1587-e474-4258-b6e8-485c21b56670270=900000.00271=0.00011111269=1278=afd96a7b-3d48-459e-b810-e4ee88353a31270=900000.00271=0.0001111110=070
20250411-01:41:48.124915000 : 8=FIXT.1.19=14135=334=4349=24ab46f784d1b20db435b852086e325052=20250411-01:41:48.12456=Coinbase45=6258=Tag appears more than once371=269372=W373=1310=249
20250411-01:41:48.125302000 : 8=FIXT.1.19=95835=W49=Coinbase56=24ab46f784d1b20db435b852086e325034=6350=TEST52=20250411-01:41:47.381470369=2262=019c5c39-7de8-457e-b353-126439f7eeea83=1597559286893=N55=BTC-USD1682=full_trading268=10269=1278=a68ae029-b920-4ae7-a775-ccdb800fc252270=900000.00271=0.00001111269=1278=d44508b7-1c9f-4b4f-acb8-99c93d2b99e8270=900000.00271=0.00001111269=1278=304ff106-de40-4381-89c5-c93f7f3e32ae270=900000.00271=0.00001111269=1278=08a0fef8-fcbb-4857-8463-2599cf331386270=900000.00271=0.00011111269=1278=07b2856d-f899-417c-82d5-886f0d85125e270=900000.00271=0.00011111269=1278=12ecb45e-6af8-4804-a942-5c997b9d1502270=900000.00271=0.00011111269=1278=98676c5f-b851-473c-817a-b29243092a25270=900000.00271=0.00001111269=1278=09afe685-e71f-4ea0-b164-c27737db126d270=900000.00271=0.00001111269=1278=e71ee98f-c329-428d-9893-629b53015ff6270=900000.00271=0.00001111269=1278=124e6fc1-6dde-452b-be03-c00113c8ebdb270=900000.00271=0.0001111110=114
20250411-01:41:48.126254000 : 8=FIXT.1.19=14135=334=4449=24ab46f784d1b20db435b852086e325052=20250411-01:41:48.12556=Coinbase45=6358=Tag appears more than once371=269372=W373=1310=252
20250411-01:41:48.126352000 : 8=FIXT.1.19=50535=W49=Coinbase56=24ab46f784d1b20db435b852086e325034=6450=TEST52=20250411-01:41:47.381720369=2262=019c5c39-7de8-457e-b353-126439f7eeea83=1597559286893=Y55=BTC-USD1682=full_trading268=4269=1278=b71cc7f5-d7c6-4fc0-a0de-59b0eb7fd063270=1000000.00271=1.00000000269=1278=afec127b-a98c-49cb-893f-e385a7e35d32270=1000000.00271=1.00000000269=1278=06df7c57-366d-4d2c-acc2-e6c26d60e9c3270=1000000.00271=1.00000000269=1278=b1c4eb2b-90df-44e0-ae4f-515df4086a9d270=9999999.00271=0.0000100010=255
20250411-01:41:48.127050000 : 8=FIXT.1.19=14135=334=4549=24ab46f784d1b20db435b852086e325052=20250411-01:41:48.12656=Coinbase45=6458=Tag appears more than once371=269372=W373=1310=255
20250411-01:41:48.127245000 : 8=FIXT.1.19=28335=X49=Coinbase56=24ab46f784d1b20db435b852086e325034=6550=TEST52=20250411-01:41:47.889680369=13262=019c5c39-7de8-457e-b353-126439f7eeea268=1279=0269=183=159755928755=BTC-USD270=3.58271=0.6232294660=20250411-01:41:47.88824740=237=d6d42763-f076-4800-8560-4b92781d13fc10=134
20250411-01:41:48.127709000 : 8=FIXT.1.19=27935=X49=Coinbase56=24ab46f784d1b20db435b852086e325034=6650=TEST52=20250411-01:41:47.889689369=13262=019c5c39-7de8-457e-b353-126439f7eeea268=1279=0269=1278=d6d42763-f076-4800-8560-4b92781d13fc83=159755928855=BTC-USD270=3.58271=0.6232294660=20250411-01:41:47.88824710=249
20250411-01:41:48.717845000 : 8=FIXT.1.19=28335=X49=Coinbase56=24ab46f784d1b20db435b852086e325034=6750=TEST52=20250411-01:41:48.542632369=45262=019c5c39-7de8-457e-b353-126439f7eeea268=1279=0269=083=159755928955=BTC-USD270=3.83271=0.6232294660=20250411-01:41:48.54097640=237=b86d9d63-3600-4698-a2b2-c0e74ff9838610=229
20250411-01:41:48.718772000 : 8=FIXT.1.19=32635=X49=Coinbase56=24ab46f784d1b20db435b852086e325034=6850=TEST52=20250411-01:41:48.542644369=45262=019c5c39-7de8-457e-b353-126439f7eeea268=1279=0269=2278=c5b88ea9-605d-4595-ac52-f7c3f08523ba83=159755929055=BTC-USD270=3.55271=0.6232294660=20250411-01:41:48.54097637=b86d9d63-3600-4698-a2b2-c0e74ff983865797=110=178
20250411-01:41:48.718953000 : 8=FIXT.1.19=28935=X49=Coinbase56=24ab46f784d1b20db435b852086e325034=6950=TEST52=20250411-01:41:48.542647369=45262=019c5c39-7de8-457e-b353-126439f7eeea268=1279=2269=0278=b86d9d63-3600-4698-a2b2-c0e74ff9838683=159755929155=BTC-USD270=3.83271=0.0000000060=20250411-01:41:48.54097658=FILLED10=138
20250411-01:41:48.723084000 : 8=FIXT.1.19=28235=X49=Coinbase56=24ab46f784d1b20db435b852086e325034=7050=TEST52=20250411-01:41:48.596397369=45262=019c5c39-7de8-457e-b353-126439f7eeea268=1279=0269=183=159755929255=BTC-USD270=3.2271=0.6232294660=20250411-01:41:48.59529240=237=8de6a901-1de0-49e4-bcd6-f415ba2b01cc10=171
20250411-01:41:48.723341000 : 8=FIXT.1.19=32635=X49=Coinbase56=24ab46f784d1b20db435b852086e325034=7150=TEST52=20250411-01:41:48.596405369=45262=019c5c39-7de8-457e-b353-126439f7eeea268=1279=0269=2278=4d60a78e-b39b-420e-b830-bc0f3f4fdde283=159755929355=BTC-USD270=3.53271=0.6232294660=20250411-01:41:48.59529237=8de6a901-1de0-49e4-bcd6-f415ba2b01cc5797=210=044
20250411-01:41:48.723499000 : 8=FIXT.1.19=28835=X49=Coinbase56=24ab46f784d1b20db435b852086e325034=7250=TEST52=20250411-01:41:48.596409369=45262=019c5c39-7de8-457e-b353-126439f7eeea268=1279=2269=1278=8de6a901-1de0-49e4-bcd6-f415ba2b01cc83=159755929455=BTC-USD270=3.2271=0.0000000060=20250411-01:41:48.59529258=FILLED10=077
20250411-01:41:51.982951000 : 8=FIXT.1.19=28335=X49=Coinbase56=24ab46f784d1b20db435b852086e325034=7350=TEST52=20250411-01:41:51.855612369=45262=019c5c39-7de8-457e-b353-126439f7eeea268=1279=0269=183=159755929555=BTC-USD270=3.19271=0.6232294660=20250411-01:41:51.85438640=237=0006adea-4fdb-4254-8624-101f971ea83510=232
20250411-01:41:51.984824000 : 8=FIXT.1.19=32635=X49=Coinbase56=24ab46f784d1b20db435b852086e325034=7450=TEST52=20250411-01:41:51.855624369=45262=019c5c39-7de8-457e-b353-126439f7eeea268=1279=0269=2278=4d60a78e-b39b-420e-b830-bc0f3f4fdde283=159755929655=BTC-USD270=3.53271=0.6232294660=20250411-01:41:51.85438637=0006adea-4fdb-4254-8624-101f971ea8355797=210=061
20250411-01:41:51.985580000 : 8=FIXT.1.19=28935=X49=Coinbase56=24ab46f784d1b20db435b852086e325034=7550=TEST52=20250411-01:41:51.855628369=45262=019c5c39-7de8-457e-b353-126439f7eeea268=1279=2269=1278=0006adea-4fdb-4254-8624-101f971ea83583=159755929755=BTC-USD270=3.19271=0.0000000060=20250411-01:41:51.85438658=FILLED10=151
20250411-01:41:52.039719000 : 8=FIXT.1.19=28335=X49=Coinbase56=24ab46f784d1b20db435b852086e325034=7650=TEST52=20250411-01:41:51.913131369=45262=019c5c39-7de8-457e-b353-126439f7eeea268=1279=0269=083=159755929855=BTC-USD270=3.84271=0.6232294660=20250411-01:41:51.91163440=237=7a660c22-d256-4927-b3d8-db1b8b03711910=180
20250411-01:41:52.040522000 : 8=FIXT.1.19=32635=X49=Coinbase56=24ab46f784d1b20db435b852086e325034=7750=TEST52=20250411-01:41:51.913140369=45262=019c5c39-7de8-457e-b353-126439f7eeea268=1279=0269=2278=c5b88ea9-605d-4595-ac52-f7c3f08523ba83=159755929955=BTC-USD270=3.55271=0.6232294660=20250411-01:41:51.91163437=7a660c22-d256-4927-b3d8-db1b8b0371195797=110=134
20250411-01:41:52.041125000 : 8=FIXT.1.19=28935=X49=Coinbase56=24ab46f784d1b20db435b852086e325034=7850=TEST52=20250411-01:41:51.913143369=45262=019c5c39-7de8-457e-b353-126439f7eeea268=1279=2269=0278=7a660c22-d256-4927-b3d8-db1b8b03711983=159755930055=BTC-USD270=3.84271=0.0000000060=20250411-01:41:51.91163458=FILLED10=077
20250411-01:41:52.410412000 : 8=FIXT.1.19=29135=X49=Coinbase56=24ab46f784d1b20db435b852086e325034=7950=TEST52=20250411-01:41:52.283243369=45262=019c5c39-7de8-457e-b353-126439f7eeea268=1279=2269=0278=c5e86443-3181-4c47-9186-a42f3f1b1da483=159755930155=BTC-USD270=3.52271=0.6232294660=20250411-01:41:52.28132258=CANCELED10=230
20250411-01:41:53.127289000 : 8=FIXT.1.19=28335=X49=Coinbase56=24ab46f784d1b20db435b852086e325034=8050=TEST52=20250411-01:41:52.999572369=45262=019c5c39-7de8-457e-b353-126439f7eeea268=1279=0269=183=159755930255=BTC-USD270=3.24271=0.6197183160=20250411-01:41:52.99794240=237=22db2fd0-56f1-4370-9ae1-a2a0234745c010=226
20250411-01:41:53.128169000 : 8=FIXT.1.19=32635=X49=Coinbase56=24ab46f784d1b20db435b852086e325034=8150=TEST52=20250411-01:41:52.999584369=45262=019c5c39-7de8-457e-b353-126439f7eeea268=1279=0269=2278=4d60a78e-b39b-420e-b830-bc0f3f4fdde283=159755930355=BTC-USD270=3.53271=0.6197183160=20250411-01:41:52.99794237=22db2fd0-56f1-4370-9ae1-a2a0234745c05797=210=059
20250411-01:41:53.128432000 : 8=FIXT.1.19=28935=X49=Coinbase56=24ab46f784d1b20db435b852086e325034=8250=TEST52=20250411-01:41:52.999587369=45262=019c5c39-7de8-457e-b353-126439f7eeea268=1279=2269=1278=22db2fd0-56f1-4370-9ae1-a2a0234745c083=159755930455=BTC-USD270=3.24271=0.0000000060=20250411-01:41:52.99794258=FILLED10=142
20250411-01:41:53.181108000 : 8=FIXT.1.19=28335=X49=Coinbase56=24ab46f784d1b20db435b852086e325034=8350=TEST52=20250411-01:41:53.054111369=45262=019c5c39-7de8-457e-b353-126439f7eeea268=1279=0269=083=159755930555=BTC-USD270=3.76271=0.6197183160=20250411-01:41:53.05269740=237=e6ed58c5-abf4-460f-b28f-daa4aa639ca510=049
20250411-01:41:53.181662000 : 8=FIXT.1.19=32635=X49=Coinbase56=24ab46f784d1b20db435b852086e325034=8450=TEST52=20250411-01:41:53.054124369=45262=019c5c39-7de8-457e-b353-126439f7eeea268=1279=0269=2278=c5b88ea9-605d-4595-ac52-f7c3f08523ba83=159755930655=BTC-USD270=3.55271=0.6197183160=20250411-01:41:53.05269737=e6ed58c5-abf4-460f-b28f-daa4aa639ca55797=110=006
20250411-01:41:53.182240000 : 8=FIXT.1.19=28935=X49=Coinbase56=24ab46f784d1b20db435b852086e325034=8550=TEST52=20250411-01:41:53.054128369=45262=019c5c39-7de8-457e-b353-126439f7eeea268=1279=2269=0278=e6ed58c5-abf4-460f-b28f-daa4aa639ca583=159755930755=BTC-USD270=3.76271=0.0000000060=20250411-01:41:53.05269758=FILLED10=223
20250411-01:41:53.667298000 : 8=FIXT.1.19=8435=534=4649=24ab46f784d1b20db435b852086e325052=20250411-01:41:53.66656=Coinbase10=172
20250411-01:41:53.838660000 : 8=FIXT.1.19=29135=X49=Coinbase56=24ab46f784d1b20db435b852086e325034=8650=TEST52=20250411-01:41:53.711422369=45262=019c5c39-7de8-457e-b353-126439f7eeea268=1279=2269=1278=dd32d4f9-0ad4-4eb3-a0ec-809f9aac8c2d83=159755930855=BTC-USD270=3.59271=0.6197183160=20250411-01:41:53.71033458=CANCELED10=108
20250411-01:41:53.895320000 : 8=FIXT.1.19=11935=549=Coinbase56=24ab46f784d1b20db435b852086e325034=8750=TEST52=20250411-01:41:53.767950369=4558=CLIENT_LOGOUT10=079
20250411-01:42:59.484052000 : 8=FIXT.1.19=21535=A34=149=24ab46f784d1b20db435b852086e325052=20250411-01:42:59.46856=Coinbase95=4496=c6MxMdGtS1GjrWrj2/qy97VVrSf2lWnWaRR7QftJsXA=98=0108=30141=Y553=24ab46f784d1b20db435b852086e3250554=akmwnltyfgb1137=910=104
20250411-01:42:59.738308000 : 8=FIXT.1.19=12535=A49=Coinbase56=24ab46f784d1b20db435b852086e325034=150=TEST52=20250411-01:42:59.610721369=198=0108=30141=Y1137=910=190
20250411-01:43:01.232324000 : 8=FIXT.1.19=17835=V34=249=24ab46f784d1b20db435b852086e325052=20250411-01:43:01.23156=Coinbase1128=9146=155=BTC-USD262=8f577b39-f6d4-4f82-9420-b6d054c2580a263=1264=0267=2269=0269=110=171
20250411-01:43:01.559242000 : 8=FIXT.1.19=28035=X49=Coinbase56=24ab46f784d1b20db435b852086e325034=250=TEST52=20250411-01:43:01.432489369=2262=8f577b39-f6d4-4f82-9420-b6d054c2580a268=1279=0269=183=159756078255=BTC-USD270=3.6271=0.6232294660=20250411-01:43:01.43075240=237=c2eca99d-67ae-4543-b7eb-03eade66a20a10=238
20250411-01:43:01.560035000 : 8=FIXT.1.19=27635=X49=Coinbase56=24ab46f784d1b20db435b852086e325034=350=TEST52=20250411-01:43:01.432496369=2262=8f577b39-f6d4-4f82-9420-b6d054c2580a268=1279=0269=1278=c2eca99d-67ae-4543-b7eb-03eade66a20a83=159756078355=BTC-USD270=3.6271=0.6232294660=20250411-01:43:01.43075210=086
20250411-01:43:01.700747000 : 8=FIXT.1.19=30035=X49=Coinbase56=24ab46f784d1b20db435b852086e325034=450=TEST52=20250411-01:43:01.571724369=2262=8f577b39-f6d4-4f82-9420-b6d054c2580a268=1279=0269=083=159756078455=BTC-USD270=3.75271=0.6588255129004=2.338830560560=20250411-01:43:01.57026240=237=f50cc6ff-45a0-4291-bcfa-73bda0e99ffa10=254
20250411-01:43:01.701645000 : 8=FIXT.1.19=32435=X49=Coinbase56=24ab46f784d1b20db435b852086e325034=550=TEST52=20250411-01:43:01.571731369=2262=8f577b39-f6d4-4f82-9420-b6d054c2580a268=1279=0269=2278=c5b88ea9-605d-4595-ac52-f7c3f08523ba83=159756078555=BTC-USD270=3.55271=0.6588255160=20250411-01:43:01.57026237=f50cc6ff-45a0-4291-bcfa-73bda0e99ffa5797=110=048
20250411-01:43:01.702227000 : 8=FIXT.1.19=27835=X49=Coinbase56=24ab46f784d1b20db435b852086e325034=650=TEST52=20250411-01:43:01.571736369=2262=8f577b39-f6d4-4f82-9420-b6d054c2580a268=1279=2269=0278=f50cc6ff-45a0-4291-bcfa-73bda0e99ffa83=159756078655=BTC-USD270=3.75271=060=20250411-01:43:01.57026258=FILLED10=087
20250411-01:43:01.753315000 : 8=FIXT.1.19=28135=X49=Coinbase56=24ab46f784d1b20db435b852086e325034=750=TEST52=20250411-01:43:01.627781369=2262=8f577b39-f6d4-4f82-9420-b6d054c2580a268=1279=0269=183=159756078755=BTC-USD270=3.19271=0.6232294660=20250411-01:43:01.62682140=237=0b529e3c-e72e-40e1-a56a-e1aa0531add110=187
20250411-01:43:01.754104000 : 8=FIXT.1.19=32435=X49=Coinbase56=24ab46f784d1b20db435b852086e325034=850=TEST52=20250411-01:43:01.627799369=2262=8f577b39-f6d4-4f82-9420-b6d054c2580a268=1279=0269=2278=4d60a78e-b39b-420e-b830-bc0f3f4fdde283=159756078855=BTC-USD270=3.53271=0.6232294660=20250411-01:43:01.62682137=0b529e3c-e72e-40e1-a56a-e1aa0531add15797=210=022
20250411-01:43:01.755707000 : 8=FIXT.1.19=28735=X49=Coinbase56=24ab46f784d1b20db435b852086e325034=950=TEST52=20250411-01:43:01.627803369=2262=8f577b39-f6d4-4f82-9420-b6d054c2580a268=1279=2269=1278=0b529e3c-e72e-40e1-a56a-e1aa0531add183=159756078955=BTC-USD270=3.19271=0.0000000060=20250411-01:43:01.62682158=FILLED10=094
20250411-01:43:01.843485000 : 8=FIXT.1.19=28235=X49=Coinbase56=24ab46f784d1b20db435b852086e325034=1050=TEST52=20250411-01:43:01.717481369=2262=8f577b39-f6d4-4f82-9420-b6d054c2580a268=1279=0269=083=159756079055=BTC-USD270=3.44271=0.6232294660=20250411-01:43:01.71582640=237=e6e9a6da-f739-4bdd-80cd-c459bf7a4dd910=161
20250411-01:43:01.844314000 : 8=FIXT.1.19=27835=X49=Coinbase56=24ab46f784d1b20db435b852086e325034=1150=TEST52=20250411-01:43:01.717488369=2262=8f577b39-f6d4-4f82-9420-b6d054c2580a268=1279=0269=0278=e6e9a6da-f739-4bdd-80cd-c459bf7a4dd983=159756079155=BTC-USD270=3.44271=0.6232294660=20250411-01:43:01.71582610=018
20250411-01:43:02.618970000 : 8=FIXT.1.19=28235=X49=Coinbase56=24ab46f784d1b20db435b852086e325034=1250=TEST52=20250411-01:43:02.487268369=2262=8f577b39-f6d4-4f82-9420-b6d054c2580a268=1279=0269=083=159756079255=BTC-USD270=3.73271=0.6232294660=20250411-01:43:02.48551140=237=7da65e48-3494-44bc-adcd-04d11cd3ed0a10=041
20250411-01:43:02.628993000 : 8=FIXT.1.19=32535=X49=Coinbase56=24ab46f784d1b20db435b852086e325034=1350=TEST52=20250411-01:43:02.487278369=2262=8f577b39-f6d4-4f82-9420-b6d054c2580a268=1279=0269=2278=c5b88ea9-605d-4595-ac52-f7c3f08523ba83=159756079355=BTC-USD270=3.55271=0.6232294660=20250411-01:43:02.48551137=7da65e48-3494-44bc-adcd-04d11cd3ed0a5797=110=254
20250411-01:43:02.630534000 : 8=FIXT.1.19=28835=X49=Coinbase56=24ab46f784d1b20db435b852086e325034=1450=TEST52=20250411-01:43:02.487282369=2262=8f577b39-f6d4-4f82-9420-b6d054c2580a268=1279=2269=0278=7da65e48-3494-44bc-adcd-04d11cd3ed0a83=159756079455=BTC-USD270=3.73271=0.0000000060=20250411-01:43:02.48551158=FILLED10=205
20250411-01:43:02.668082000 : 8=FIXT.1.19=28235=X49=Coinbase56=24ab46f784d1b20db435b852086e325034=1550=TEST52=20250411-01:43:02.541852369=2262=8f577b39-f6d4-4f82-9420-b6d054c2580a268=1279=0269=183=159756079555=BTC-USD270=3.35271=0.6232294660=20250411-01:43:02.54059440=237=f0fb461e-6ae5-45ef-ab75-f4affee2d5f410=204
20250411-01:43:02.670227000 : 8=FIXT.1.19=32535=X49=Coinbase56=24ab46f784d1b20db435b852086e325034=1650=TEST52=20250411-01:43:02.541862369=2262=8f577b39-f6d4-4f82-9420-b6d054c2580a268=1279=0269=2278=4d60a78e-b39b-420e-b830-bc0f3f4fdde283=159756079655=BTC-USD270=3.53271=0.6232294660=20250411-01:43:02.54059437=f0fb461e-6ae5-45ef-ab75-f4affee2d5f45797=210=033
20250411-01:43:02.674136000 : 8=FIXT.1.19=28835=X49=Coinbase56=24ab46f784d1b20db435b852086e325034=1750=TEST52=20250411-01:43:02.541866369=2262=8f577b39-f6d4-4f82-9420-b6d054c2580a268=1279=2269=1278=f0fb461e-6ae5-45ef-ab75-f4affee2d5f483=159756079755=BTC-USD270=3.35271=0.0000000060=20250411-01:43:02.54059458=FILLED10=121
20250411-01:43:02.728278000 : 8=FIXT.1.19=28235=X49=Coinbase56=24ab46f784d1b20db435b852086e325034=1850=TEST52=20250411-01:43:02.601482369=2262=8f577b39-f6d4-4f82-9420-b6d054c2580a268=1279=0269=183=159756079855=BTC-USD270=3.27271=0.6232294660=20250411-01:43:02.60056540=237=d9af8b91-2a1b-4b02-a88a-70bf0cd6a41e10=033
20250411-01:43:02.729084000 : 8=FIXT.1.19=32535=X49=Coinbase56=24ab46f784d1b20db435b852086e325034=1950=TEST52=20250411-01:43:02.601543369=2262=8f577b39-f6d4-4f82-9420-b6d054c2580a268=1279=0269=2278=4d60a78e-b39b-420e-b830-bc0f3f4fdde283=159756079955=BTC-USD270=3.53271=0.6232294660=20250411-01:43:02.60056537=d9af8b91-2a1b-4b02-a88a-70bf0cd6a41e5797=210=114
20250411-01:43:02.732040000 : 8=FIXT.1.19=28835=X49=Coinbase56=24ab46f784d1b20db435b852086e325034=2050=TEST52=20250411-01:43:02.601552369=2262=8f577b39-f6d4-4f82-9420-b6d054c2580a268=1279=2269=1278=d9af8b91-2a1b-4b02-a88a-70bf0cd6a41e83=159756080055=BTC-USD270=3.27271=0.0000000060=20250411-01:43:02.60056558=FILLED10=172
20250411-01:43:02.782586000 : 8=FIXT.1.19=28235=X49=Coinbase56=24ab46f784d1b20db435b852086e325034=2150=TEST52=20250411-01:43:02.656107369=2262=8f577b39-f6d4-4f82-9420-b6d054c2580a268=1279=0269=083=159756080155=BTC-USD270=3.73271=0.6232294660=20250411-01:43:02.65428140=237=1f615616-3276-403b-b5ed-cdd104152a6310=242
20250411-01:43:02.784579000 : 8=FIXT.1.19=8335=534=349=24ab46f784d1b20db435b852086e325052=20250411-01:43:02.78456=Coinbase10=113
20250411-01:43:02.784714000 : 8=FIXT.1.19=32535=X49=Coinbase56=24ab46f784d1b20db435b852086e325034=2250=TEST52=20250411-01:43:02.656115369=2262=8f577b39-f6d4-4f82-9420-b6d054c2580a268=1279=0269=2278=c5b88ea9-605d-4595-ac52-f7c3f08523ba83=159756080255=BTC-USD270=3.55271=0.6232294660=20250411-01:43:02.65428137=1f615616-3276-403b-b5ed-cdd104152a635797=110=197
20250411-01:43:02.784996000 : 8=FIXT.1.19=28835=X49=Coinbase56=24ab46f784d1b20db435b852086e325034=2350=TEST52=20250411-01:43:02.656119369=2262=8f577b39-f6d4-4f82-9420-b6d054c2580a268=1279=2269=0278=1f615616-3276-403b-b5ed-cdd104152a6383=159756080355=BTC-USD270=3.73271=0.0000000060=20250411-01:43:02.65428158=FILLED10=157
20250411-01:43:03.062589000 : 8=FIXT.1.19=11835=549=Coinbase56=24ab46f784d1b20db435b852086e325034=2450=TEST52=20250411-01:43:02.885605369=258=CLIENT_LOGOUT10=008
20250411-02:24:44.509833000 : 8=FIXT.1.19=21535=A34=149=24ab46f784d1b20db435b852086e325052=20250411-02:24:44.50256=Coinbase95=4496=ZBgwA/t1WLmASv0hReJ76yKejIxtTGs5CdVdWHXET34=98=0108=30141=Y553=24ab46f784d1b20db435b852086e3250554=akmwnltyfgb1137=910=189
20250411-02:24:44.768005000 : 8=FIXT.1.19=12535=A49=Coinbase56=24ab46f784d1b20db435b852086e325034=150=TEST52=20250411-02:24:44.717012369=198=0108=30141=Y1137=910=186
20250411-02:24:46.273625000 : 8=FIXT.1.19=17835=V34=249=24ab46f784d1b20db435b852086e325052=20250411-02:24:46.27256=Coinbase1128=9146=155=BTC-USD262=fabc71d1-a705-413e-8282-a681c602a690263=1264=0267=2269=0269=110=205
20250411-02:24:46.507442000 : 8=FIXT.1.19=27235=X49=Coinbase56=24ab46f784d1b20db435b852086e325034=250=TEST52=20250411-02:24:46.457738369=2262=fabc71d1-a705-413e-8282-a681c602a690268=1279=0269=183=159761177955=BTC-USD271=0.6214689360=20250411-02:24:46.45581240=137=d0f69b22-689f-408a-9f41-324c79e5e4f710=182
20250411-02:24:46.508266000 : 8=FIXT.1.19=32435=X49=Coinbase56=24ab46f784d1b20db435b852086e325034=350=TEST52=20250411-02:24:46.457744369=2262=fabc71d1-a705-413e-8282-a681c602a690268=1279=0269=2278=24de32b2-a7f5-469c-a714-c9b10ee2cce583=159761178055=BTC-USD270=3.54271=0.6214689360=20250411-02:24:46.45581237=d0f69b22-689f-408a-9f41-324c79e5e4f75797=210=113
20250411-02:24:46.509522000 : 8=FIXT.1.19=27835=X49=Coinbase56=24ab46f784d1b20db435b852086e325034=450=TEST52=20250411-02:24:46.457749369=2262=fabc71d1-a705-413e-8282-a681c602a690268=1279=2269=1278=d0f69b22-689f-408a-9f41-324c79e5e4f783=159761178155=BTC-USD271=0.0000000060=20250411-02:24:46.45581258=FILLED10=083
20250411-02:24:46.518778000 : 8=FIXT.1.19=28135=X49=Coinbase56=24ab46f784d1b20db435b852086e325034=550=TEST52=20250411-02:24:46.468983369=2262=fabc71d1-a705-413e-8282-a681c602a690268=1279=0269=183=159761178255=BTC-USD270=3.23271=0.6214689360=20250411-02:24:46.46765040=237=c04fc136-118e-4579-89e8-cf5d3d38a1c810=128
20250411-02:24:46.518985000 : 8=FIXT.1.19=32435=X49=Coinbase56=24ab46f784d1b20db435b852086e325034=650=TEST52=20250411-02:24:46.468989369=2262=fabc71d1-a705-413e-8282-a681c602a690268=1279=0269=2278=24de32b2-a7f5-469c-a714-c9b10ee2cce583=159761178355=BTC-USD270=3.54271=0.6214689360=20250411-02:24:46.46765037=c04fc136-118e-4579-89e8-cf5d3d38a1c85797=210=175
20250411-02:24:46.519660000 : 8=FIXT.1.19=28735=X49=Coinbase56=24ab46f784d1b20db435b852086e325034=750=TEST52=20250411-02:24:46.468993369=2262=fabc71d1-a705-413e-8282-a681c602a690268=1279=2269=1278=c04fc136-118e-4579-89e8-cf5d3d38a1c883=159761178455=BTC-USD270=3.23271=0.0000000060=20250411-02:24:46.46765058=FILLED10=036
20250411-02:24:46.990175000 : 8=FIXT.1.19=27635=X49=Coinbase56=24ab46f784d1b20db435b852086e325034=850=TEST52=20250411-02:24:46.941923369=2262=fabc71d1-a705-413e-8282-a681c602a690268=1279=0269=083=159761178555=BTC-USD29004=2.208895519560=20250411-02:24:46.94080240=137=0ec30ac9-ac96-498f-a6c5-707165e991b610=174
20250411-02:24:46.992192000 : 8=FIXT.1.19=32435=X49=Coinbase56=24ab46f784d1b20db435b852086e325034=950=TEST52=20250411-02:24:46.941939369=2262=fabc71d1-a705-413e-8282-a681c602a690268=1279=0269=2278=c5b88ea9-605d-4595-ac52-f7c3f08523ba83=159761178655=BTC-USD270=3.55271=0.6222240960=20250411-02:24:46.94080237=0ec30ac9-ac96-498f-a6c5-707165e991b65797=110=072
20250411-02:24:46.993123000 : 8=FIXT.1.19=26435=X49=Coinbase56=24ab46f784d1b20db435b852086e325034=1050=TEST52=20250411-02:24:46.941944369=2262=fabc71d1-a705-413e-8282-a681c602a690268=1279=2269=0278=0ec30ac9-ac96-498f-a6c5-707165e991b683=159761178755=BTC-USD60=20250411-02:24:46.94080258=FILLED10=233
20250411-02:24:47.019621000 : 8=FIXT.1.19=27335=X49=Coinbase56=24ab46f784d1b20db435b852086e325034=1150=TEST52=20250411-02:24:46.971339369=2262=fabc71d1-a705-413e-8282-a681c602a690268=1279=0269=183=159761178855=BTC-USD271=0.6214689360=20250411-02:24:46.96965040=137=35fe2587-61e9-486f-85f6-0ffa1060234110=131
20250411-02:24:47.019996000 : 8=FIXT.1.19=32535=X49=Coinbase56=24ab46f784d1b20db435b852086e325034=1250=TEST52=20250411-02:24:46.971348369=2262=fabc71d1-a705-413e-8282-a681c602a690268=1279=0269=2278=24de32b2-a7f5-469c-a714-c9b10ee2cce583=159761178955=BTC-USD270=3.54271=0.6214689360=20250411-02:24:46.96965037=35fe2587-61e9-486f-85f6-0ffa106023415797=210=074
20250411-02:24:47.020340000 : 8=FIXT.1.19=27935=X49=Coinbase56=24ab46f784d1b20db435b852086e325034=1350=TEST52=20250411-02:24:46.971352369=2262=fabc71d1-a705-413e-8282-a681c602a690268=1279=2269=1278=35fe2587-61e9-486f-85f6-0ffa1060234183=159761179055=BTC-USD271=0.0000000060=20250411-02:24:46.96965058=FILLED10=025
20250411-02:24:47.052681000 : 8=FIXT.1.19=27735=X49=Coinbase56=24ab46f784d1b20db435b852086e325034=1450=TEST52=20250411-02:24:47.001413369=2262=fabc71d1-a705-413e-8282-a681c602a690268=1279=0269=083=159761179155=BTC-USD29004=2.208895519560=20250411-02:24:46.99910640=137=5f590bc1-88d9-49b0-a641-63d26247e45b10=108
20250411-02:24:47.054543000 : 8=FIXT.1.19=32535=X49=Coinbase56=24ab46f784d1b20db435b852086e325034=1550=TEST52=20250411-02:24:47.001420369=2262=fabc71d1-a705-413e-8282-a681c602a690268=1279=0269=2278=c5b88ea9-605d-4595-ac52-f7c3f08523ba83=159761179255=BTC-USD270=3.55271=0.6222240960=20250411-02:24:46.99910637=5f590bc1-88d9-49b0-a641-63d26247e45b5797=110=253
20250411-02:24:47.055040000 : 8=FIXT.1.19=26435=X49=Coinbase56=24ab46f784d1b20db435b852086e325034=1650=TEST52=20250411-02:24:47.001565369=2262=fabc71d1-a705-413e-8282-a681c602a690268=1279=2269=0278=5f590bc1-88d9-49b0-a641-63d26247e45b83=159761179355=BTC-USD60=20250411-02:24:46.99910658=FILLED10=132
20250411-02:24:47.079468000 : 8=FIXT.1.19=27335=X49=Coinbase56=24ab46f784d1b20db435b852086e325034=1750=TEST52=20250411-02:24:47.028649369=2262=fabc71d1-a705-413e-8282-a681c602a690268=1279=0269=183=159761179455=BTC-USD271=0.6197183160=20250411-02:24:47.02672540=137=392c1cf3-c20d-46cd-96d2-7d67ea6381b010=039
20250411-02:24:47.079816000 : 8=FIXT.1.19=32535=X49=Coinbase56=24ab46f784d1b20db435b852086e325034=1850=TEST52=20250411-02:24:47.028658369=2262=fabc71d1-a705-413e-8282-a681c602a690268=1279=0269=2278=24de32b2-a7f5-469c-a714-c9b10ee2cce583=159761179555=BTC-USD270=3.54271=0.6197183160=20250411-02:24:47.02672537=392c1cf3-c20d-46cd-96d2-7d67ea6381b05797=210=238
20250411-02:24:47.080061000 : 8=FIXT.1.19=27935=X49=Coinbase56=24ab46f784d1b20db435b852086e325034=1950=TEST52=20250411-02:24:47.028663369=2262=fabc71d1-a705-413e-8282-a681c602a690268=1279=2269=1278=392c1cf3-c20d-46cd-96d2-7d67ea6381b083=159761179655=BTC-USD271=0.0000000060=20250411-02:24:47.02672558=FILLED10=202
20250411-02:24:47.375894000 : 8=FIXT.1.19=28235=X49=Coinbase56=24ab46f784d1b20db435b852086e325034=2050=TEST52=20250411-02:24:47.327292369=2262=fabc71d1-a705-413e-8282-a681c602a690268=1279=0269=183=159761179755=BTC-USD270=3.32271=0.6214689360=20250411-02:24:47.32610540=237=fc84589a-3814-44f3-9ac7-6ca0cbcac43910=244
20250411-02:24:47.378736000 : 8=FIXT.1.19=32535=X49=Coinbase56=24ab46f784d1b20db435b852086e325034=2150=TEST52=20250411-02:24:47.327304369=2262=fabc71d1-a705-413e-8282-a681c602a690268=1279=0269=2278=24de32b2-a7f5-469c-a714-c9b10ee2cce583=159761179855=BTC-USD270=3.54271=0.6214689360=20250411-02:24:47.32610537=fc84589a-3814-44f3-9ac7-6ca0cbcac4395797=210=023
20250411-02:24:47.379058000 : 8=FIXT.1.19=28835=X49=Coinbase56=24ab46f784d1b20db435b852086e325034=2250=TEST52=20250411-02:24:47.327307369=2262=fabc71d1-a705-413e-8282-a681c602a690268=1279=2269=1278=fc84589a-3814-44f3-9ac7-6ca0cbcac43983=159761179955=BTC-USD270=3.32271=0.0000000060=20250411-02:24:47.32610558=FILLED10=148
20250411-02:24:47.432673000 : 8=FIXT.1.19=28235=X49=Coinbase56=24ab46f784d1b20db435b852086e325034=2350=TEST52=20250411-02:24:47.383627369=2262=fabc71d1-a705-413e-8282-a681c602a690268=1279=0269=083=159761180055=BTC-USD270=3.81271=0.6214689360=20250411-02:24:47.38253040=237=2175c8ab-0625-4684-86aa-4555bbff619e10=100
20250411-02:24:47.433057000 : 8=FIXT.1.19=32535=X49=Coinbase56=24ab46f784d1b20db435b852086e325034=2450=TEST52=20250411-02:24:47.383634369=2262=fabc71d1-a705-413e-8282-a681c602a690268=1279=0269=2278=c5b88ea9-605d-4595-ac52-f7c3f08523ba83=159761180155=BTC-USD270=3.55271=0.6214689360=20250411-02:24:47.38253037=2175c8ab-0625-4684-86aa-4555bbff619e5797=110=055
20250411-02:24:47.433443000 : 8=FIXT.1.19=28835=X49=Coinbase56=24ab46f784d1b20db435b852086e325034=2550=TEST52=20250411-02:24:47.383638369=2262=fabc71d1-a705-413e-8282-a681c602a690268=1279=2269=0278=2175c8ab-0625-4684-86aa-4555bbff619e83=159761180255=BTC-USD270=3.81271=0.0000000060=20250411-02:24:47.38253058=FILLED10=009
20250411-02:24:47.677757000 : 8=FIXT.1.19=27735=X49=Coinbase56=24ab46f784d1b20db435b852086e325034=2650=TEST52=20250411-02:24:47.628740369=2262=fabc71d1-a705-413e-8282-a681c602a690268=1279=0269=083=159761180355=BTC-USD29004=2.208895519560=20250411-02:24:47.62702340=137=be1f5abf-90c7-4983-8b3e-d3c3c916bf7210=095
20250411-02:24:47.678991000 : 8=FIXT.1.19=32535=X49=Coinbase56=24ab46f784d1b20db435b852086e325034=2750=TEST52=20250411-02:24:47.628751369=2262=fabc71d1-a705-413e-8282-a681c602a690268=1279=0269=2278=c5b88ea9-605d-4595-ac52-f7c3f08523ba83=159761180455=BTC-USD270=3.55271=0.6222240960=20250411-02:24:47.62702337=be1f5abf-90c7-4983-8b3e-d3c3c916bf725797=110=244
20250411-02:24:47.679263000 : 8=FIXT.1.19=26435=X49=Coinbase56=24ab46f784d1b20db435b852086e325034=2850=TEST52=20250411-02:24:47.628756369=2262=fabc71d1-a705-413e-8282-a681c602a690268=1279=2269=0278=be1f5abf-90c7-4983-8b3e-d3c3c916bf7283=159761180555=BTC-USD60=20250411-02:24:47.62702358=FILLED10=118
20250411-02:24:47.706654000 : 8=FIXT.1.19=27335=X49=Coinbase56=24ab46f784d1b20db435b852086e325034=2950=TEST52=20250411-02:24:47.657301369=2262=fabc71d1-a705-413e-8282-a681c602a690268=1279=0269=183=159761180655=BTC-USD271=0.6197183160=20250411-02:24:47.65637640=137=044188df-1a4a-446d-b965-8c575f10109810=112
20250411-02:24:47.707154000 : 8=FIXT.1.19=32535=X49=Coinbase56=24ab46f784d1b20db435b852086e325034=3050=TEST52=20250411-02:24:47.657314369=2262=fabc71d1-a705-413e-8282-a681c602a690268=1279=0269=2278=24de32b2-a7f5-469c-a714-c9b10ee2cce583=159761180755=BTC-USD270=3.54271=0.6197183160=20250411-02:24:47.65637637=044188df-1a4a-446d-b965-8c575f1010985797=210=050
20250411-02:24:47.707599000 : 8=FIXT.1.19=27935=X49=Coinbase56=24ab46f784d1b20db435b852086e325034=3150=TEST52=20250411-02:24:47.657447369=2262=fabc71d1-a705-413e-8282-a681c602a690268=1279=2269=1278=044188df-1a4a-446d-b965-8c575f10109883=159761180855=BTC-USD271=0.0000000060=20250411-02:24:47.65637658=FILLED10=025
20250411-02:24:47.736517000 : 8=FIXT.1.19=27735=X49=Coinbase56=24ab46f784d1b20db435b852086e325034=3250=TEST52=20250411-02:24:47.686344369=2262=fabc71d1-a705-413e-8282-a681c602a690268=1279=0269=083=159761180955=BTC-USD29004=2.208895519560=20250411-02:24:47.68446240=137=f50d27cf-cd3d-4d9e-8c0d-1edbf185627010=153
20250411-02:24:47.737031000 : 8=FIXT.1.19=32535=X49=Coinbase56=24ab46f784d1b20db435b852086e325034=3350=TEST52=20250411-02:24:47.686351369=2262=fabc71d1-a705-413e-8282-a681c602a690268=1279=0269=2278=c5b88ea9-605d-4595-ac52-f7c3f08523ba83=159761181055=BTC-USD270=3.55271=0.6222240960=20250411-02:24:47.68446237=f50d27cf-cd3d-4d9e-8c0d-1edbf18562705797=110=033
20250411-02:24:47.737542000 : 8=FIXT.1.19=26435=X49=Coinbase56=24ab46f784d1b20db435b852086e325034=3450=TEST52=20250411-02:24:47.686356369=2262=fabc71d1-a705-413e-8282-a681c602a690268=1279=2269=0278=f50d27cf-cd3d-4d9e-8c0d-1edbf185627083=159761181155=BTC-USD60=20250411-02:24:47.68446258=FILLED10=163
20250411-02:24:47.763823000 : 8=FIXT.1.19=27335=X49=Coinbase56=24ab46f784d1b20db435b852086e325034=3550=TEST52=20250411-02:24:47.714734369=2262=fabc71d1-a705-413e-8282-a681c602a690268=1279=0269=183=159761181255=BTC-USD271=0.6197183160=20250411-02:24:47.71279140=137=7a0fb7e6-a032-4889-8289-9046e136a6be10=161
20250411-02:24:47.764194000 : 8=FIXT.1.19=32535=X49=Coinbase56=24ab46f784d1b20db435b852086e325034=3650=TEST52=20250411-02:24:47.714804369=2262=fabc71d1-a705-413e-8282-a681c602a690268=1279=0269=2278=24de32b2-a7f5-469c-a714-c9b10ee2cce583=159761181355=BTC-USD270=3.54271=0.6197183160=20250411-02:24:47.71279137=7a0fb7e6-a032-4889-8289-9046e136a6be5797=210=102
20250411-02:24:47.764419000 : 8=FIXT.1.19=27935=X49=Coinbase56=24ab46f784d1b20db435b852086e325034=3750=TEST52=20250411-02:24:47.714808369=2262=fabc71d1-a705-413e-8282-a681c602a690268=1279=2269=1278=7a0fb7e6-a032-4889-8289-9046e136a6be83=159761181455=BTC-USD271=0.0000000060=20250411-02:24:47.71279158=FILLED10=074
20250411-02:24:47.792034000 : 8=FIXT.1.19=27735=X49=Coinbase56=24ab46f784d1b20db435b852086e325034=3850=TEST52=20250411-02:24:47.742913369=2262=fabc71d1-a705-413e-8282-a681c602a690268=1279=0269=083=159761181555=BTC-USD29004=2.208895519560=20250411-02:24:47.74172240=137=fa6f731f-0c1f-4e37-b6d2-0c1e5cbae2fa10=222
20250411-02:24:47.793031000 : 8=FIXT.1.19=32535=X49=Coinbase56=24ab46f784d1b20db435b852086e325034=3950=TEST52=20250411-02:24:47.742922369=2262=fabc71d1-a705-413e-8282-a681c602a690268=1279=0269=2278=c5b88ea9-605d-4595-ac52-f7c3f08523ba83=159761181655=BTC-USD270=3.55271=0.6222240960=20250411-02:24:47.74172237=fa6f731f-0c1f-4e37-b6d2-0c1e5cbae2fa5797=110=113
20250411-02:24:47.793732000 : 8=FIXT.1.19=26435=X49=Coinbase56=24ab46f784d1b20db435b852086e325034=4050=TEST52=20250411-02:24:47.742926369=2262=fabc71d1-a705-413e-8282-a681c602a690268=1279=2269=0278=fa6f731f-0c1f-4e37-b6d2-0c1e5cbae2fa83=159761181755=BTC-USD60=20250411-02:24:47.74172258=FILLED10=233
20250411-02:24:47.818556000 : 8=FIXT.1.19=27335=X49=Coinbase56=24ab46f784d1b20db435b852086e325034=4150=TEST52=20250411-02:24:47.770146369=2262=fabc71d1-a705-413e-8282-a681c602a690268=1279=0269=183=159761181855=BTC-USD271=0.6197183160=20250411-02:24:47.76915740=137=bba880aa-37a7-48a4-ab7d-895b5cf9f18910=154
20250411-02:24:47.818999000 : 8=FIXT.1.19=32535=X49=Coinbase56=24ab46f784d1b20db435b852086e325034=4250=TEST52=20250411-02:24:47.770163369=2262=fabc71d1-a705-413e-8282-a681c602a690268=1279=0269=2278=24de32b2-a7f5-469c-a714-c9b10ee2cce583=159761181955=BTC-USD270=3.54271=0.6197183160=20250411-02:24:47.76915737=bba880aa-37a7-48a4-ab7d-895b5cf9f1895797=210=096
20250411-02:24:47.819350000 : 8=FIXT.1.19=27935=X49=Coinbase56=24ab46f784d1b20db435b852086e325034=4350=TEST52=20250411-02:24:47.770168369=2262=fabc71d1-a705-413e-8282-a681c602a690268=1279=2269=1278=bba880aa-37a7-48a4-ab7d-895b5cf9f18983=159761182055=BTC-USD271=0.0000000060=20250411-02:24:47.76915758=FILLED10=060
20250411-02:24:47.991851000 : 8=FIXT.1.19=30735=X49=Coinbase56=24ab46f784d1b20db435b852086e325034=4450=TEST52=20250411-02:24:47.942819369=2262=fabc71d1-a705-413e-8282-a681c602a690268=1279=1269=1278=bd6dda75-3981-41f3-b37c-0e106f949e0183=159761182155=BTC-USD270=3.7271=0.4833138860=20250411-02:24:47.94137558=CHANGE_REASON_MODIFY_ORDER10=073
20250411-02:24:48.278386000 : 8=FIXT.1.19=30635=X49=Coinbase56=24ab46f784d1b20db435b852086e325034=4550=TEST52=20250411-02:24:48.228849369=2262=fabc71d1-a705-413e-8282-a681c602a690268=1279=1269=1278=bd6dda75-3981-41f3-b37c-0e106f949e0183=159761182255=BTC-USD270=3.7271=0.441729960=20250411-02:24:48.22698558=CHANGE_REASON_MODIFY_ORDER10=029
20250411-02:24:48.362911000 : 8=FIXT.1.19=27735=X49=Coinbase56=24ab46f784d1b20db435b852086e325034=4650=TEST52=20250411-02:24:48.314292369=2262=fabc71d1-a705-413e-8282-a681c602a690268=1279=0269=083=159761182355=BTC-USD29004=2.208895519560=20250411-02:24:48.31256540=137=fd71f6cb-78a7-4efd-bd1e-25b3b49118ab10=184
20250411-02:24:48.363242000 : 8=FIXT.1.19=32535=X49=Coinbase56=24ab46f784d1b20db435b852086e325034=4750=TEST52=20250411-02:24:48.314301369=2262=fabc71d1-a705-413e-8282-a681c602a690268=1279=0269=2278=c5b88ea9-605d-4595-ac52-f7c3f08523ba83=159761182455=BTC-USD270=3.55271=0.6222240960=20250411-02:24:48.31256537=fd71f6cb-78a7-4efd-bd1e-25b3b49118ab5797=110=066
20250411-02:24:48.364920000 : 8=FIXT.1.19=26435=X49=Coinbase56=24ab46f784d1b20db435b852086e325034=4850=TEST52=20250411-02:24:48.314305369=2262=fabc71d1-a705-413e-8282-a681c602a690268=1279=2269=0278=fd71f6cb-78a7-4efd-bd1e-25b3b49118ab83=159761182555=BTC-USD60=20250411-02:24:48.31256558=FILLED10=195
20250411-02:24:48.392615000 : 8=FIXT.1.19=27335=X49=Coinbase56=24ab46f784d1b20db435b852086e325034=4950=TEST52=20250411-02:24:48.343008369=2262=fabc71d1-a705-413e-8282-a681c602a690268=1279=0269=183=159761182655=BTC-USD271=0.6214689360=20250411-02:24:48.34166640=137=84014da4-e53f-498b-b540-73f354d3b69310=157
20250411-02:24:48.392979000 : 8=FIXT.1.19=32535=X49=Coinbase56=24ab46f784d1b20db435b852086e325034=5050=TEST52=20250411-02:24:48.343020369=2262=fabc71d1-a705-413e-8282-a681c602a690268=1279=0269=2278=24de32b2-a7f5-469c-a714-c9b10ee2cce583=159761182755=BTC-USD270=3.54271=0.6214689360=20250411-02:24:48.34166637=84014da4-e53f-498b-b540-73f354d3b6935797=210=085
20250411-02:24:48.393245000 : 8=FIXT.1.19=27935=X49=Coinbase56=24ab46f784d1b20db435b852086e325034=5150=TEST52=20250411-02:24:48.343060369=2262=fabc71d1-a705-413e-8282-a681c602a690268=1279=2269=1278=84014da4-e53f-498b-b540-73f354d3b69383=159761182855=BTC-USD271=0.0000000060=20250411-02:24:48.34166658=FILLED10=054
20250411-02:24:48.649052000 : 8=FIXT.1.19=27735=X49=Coinbase56=24ab46f784d1b20db435b852086e325034=5250=TEST52=20250411-02:24:48.599876369=2262=fabc71d1-a705-413e-8282-a681c602a690268=1279=0269=083=159761182955=BTC-USD29004=2.208895519560=20250411-02:24:48.59853440=137=6d994d7b-1670-42b3-8346-38a2f7a932fb10=154
20250411-02:24:48.650288000 : 8=FIXT.1.19=32535=X49=Coinbase56=24ab46f784d1b20db435b852086e325034=5350=TEST52=20250411-02:24:48.599960369=2262=fabc71d1-a705-413e-8282-a681c602a690268=1279=0269=2278=c5b88ea9-605d-4595-ac52-f7c3f08523ba83=159761183055=BTC-USD270=3.55271=0.6222240960=20250411-02:24:48.59853437=6d994d7b-1670-42b3-8346-38a2f7a932fb5797=110=030
20250411-02:24:48.650508000 : 8=FIXT.1.19=26435=X49=Coinbase56=24ab46f784d1b20db435b852086e325034=5450=TEST52=20250411-02:24:48.599972369=2262=fabc71d1-a705-413e-8282-a681c602a690268=1279=2269=0278=6d994d7b-1670-42b3-8346-38a2f7a932fb83=159761183155=BTC-USD60=20250411-02:24:48.59853458=FILLED10=158
20250411-02:24:48.676566000 : 8=FIXT.1.19=27335=X49=Coinbase56=24ab46f784d1b20db435b852086e325034=5550=TEST52=20250411-02:24:48.628154369=2262=fabc71d1-a705-413e-8282-a681c602a690268=1279=0269=183=159761183255=BTC-USD271=0.6214689360=20250411-02:24:48.62691540=137=fc6a13a0-f7b4-41d5-93d3-d58495de0f5710=051
20250411-02:24:48.676810000 : 8=FIXT.1.19=32535=X49=Coinbase56=24ab46f784d1b20db435b852086e325034=5650=TEST52=20250411-02:24:48.628286369=2262=fabc71d1-a705-413e-8282-a681c602a690268=1279=0269=2278=24de32b2-a7f5-469c-a714-c9b10ee2cce583=159761183355=BTC-USD270=3.54271=0.6214689360=20250411-02:24:48.62691537=fc6a13a0-f7b4-41d5-93d3-d58495de0f575797=210=000
20250411-02:24:48.677178000 : 8=FIXT.1.19=27935=X49=Coinbase56=24ab46f784d1b20db435b852086e325034=5750=TEST52=20250411-02:24:48.628291369=2262=fabc71d1-a705-413e-8282-a681c602a690268=1279=2269=1278=fc6a13a0-f7b4-41d5-93d3-d58495de0f5783=159761183455=BTC-USD271=0.0000000060=20250411-02:24:48.62691558=FILLED10=217
20250411-02:24:49.221197000 : 8=FIXT.1.19=27735=X49=Coinbase56=24ab46f784d1b20db435b852086e325034=5850=TEST52=20250411-02:24:49.172092369=2262=fabc71d1-a705-413e-8282-a681c602a690268=1279=0269=083=159761183555=BTC-USD29004=2.208895519560=20250411-02:24:49.17055040=137=38265a3b-e2d5-41fe-a781-185ef055642210=107
20250411-02:24:49.223388000 : 8=FIXT.1.19=32535=X49=Coinbase56=24ab46f784d1b20db435b852086e325034=5950=TEST52=20250411-02:24:49.172123369=2262=fabc71d1-a705-413e-8282-a681c602a690268=1279=0269=2278=c5b88ea9-605d-4595-ac52-f7c3f08523ba83=159761183655=BTC-USD270=3.55271=0.6222240960=20250411-02:24:49.17055037=38265a3b-e2d5-41fe-a781-185ef05564225797=110=249
20250411-02:24:49.224298000 : 8=FIXT.1.19=26435=X49=Coinbase56=24ab46f784d1b20db435b852086e325034=6050=TEST52=20250411-02:24:49.172128369=2262=fabc71d1-a705-413e-8282-a681c602a690268=1279=2269=0278=38265a3b-e2d5-41fe-a781-185ef055642283=159761183755=BTC-USD60=20250411-02:24:49.17055058=FILLED10=114
20250411-02:24:49.247463000 : 8=FIXT.1.19=27335=X49=Coinbase56=24ab46f784d1b20db435b852086e325034=6150=TEST52=20250411-02:24:49.198949369=2262=fabc71d1-a705-413e-8282-a681c602a690268=1279=0269=183=159761183855=BTC-USD271=0.6214689360=20250411-02:24:49.19796840=137=c63d2a7c-ab70-4436-9f5c-0a55d69b3a3410=068
20250411-02:24:49.248163000 : 8=FIXT.1.19=32535=X49=Coinbase56=24ab46f784d1b20db435b852086e325034=6250=TEST52=20250411-02:24:49.198957369=2262=fabc71d1-a705-413e-8282-a681c602a690268=1279=0269=2278=24de32b2-a7f5-469c-a714-c9b10ee2cce583=159761183955=BTC-USD270=3.54271=0.6214689360=20250411-02:24:49.19796837=c63d2a7c-ab70-4436-9f5c-0a55d69b3a345797=210=010
20250411-02:24:49.248553000 : 8=FIXT.1.19=27935=X49=Coinbase56=24ab46f784d1b20db435b852086e325034=6350=TEST52=20250411-02:24:49.198962369=2262=fabc71d1-a705-413e-8282-a681c602a690268=1279=2269=1278=c63d2a7c-ab70-4436-9f5c-0a55d69b3a3483=159761184055=BTC-USD271=0.0000000060=20250411-02:24:49.19796858=FILLED10=218
20250411-02:24:49.320079000 : 8=FIXT.1.19=28235=X49=Coinbase56=24ab46f784d1b20db435b852086e325034=6450=TEST52=20250411-02:24:49.270045369=2262=fabc71d1-a705-413e-8282-a681c602a690268=1279=0269=183=159761184155=BTC-USD270=3.24271=0.6214689360=20250411-02:24:49.26892640=237=91b98226-0660-4fd8-bb65-0f356aa550da10=102
20250411-02:24:49.320517000 : 8=FIXT.1.19=32535=X49=Coinbase56=24ab46f784d1b20db435b852086e325034=6550=TEST52=20250411-02:24:49.270054369=2262=fabc71d1-a705-413e-8282-a681c602a690268=1279=0269=2278=24de32b2-a7f5-469c-a714-c9b10ee2cce583=159761184255=BTC-USD270=3.54271=0.6214689360=20250411-02:24:49.26892637=91b98226-0660-4fd8-bb65-0f356aa550da5797=210=142
20250411-02:24:49.320766000 : 8=FIXT.1.19=28835=X49=Coinbase56=24ab46f784d1b20db435b852086e325034=6650=TEST52=20250411-02:24:49.270128369=2262=fabc71d1-a705-413e-8282-a681c602a690268=1279=2269=1278=91b98226-0660-4fd8-bb65-0f356aa550da83=159761184355=BTC-USD270=3.24271=0.0000000060=20250411-02:24:49.26892658=FILLED10=011
20250411-02:24:49.375344000 : 8=FIXT.1.19=28235=X49=Coinbase56=24ab46f784d1b20db435b852086e325034=6750=TEST52=20250411-02:24:49.326206369=2262=fabc71d1-a705-413e-8282-a681c602a690268=1279=0269=083=159761184455=BTC-USD270=3.84271=0.6214689360=20250411-02:24:49.32436840=237=76be99a0-350c-4657-bef9-7977f20720ce10=131
20250411-02:24:49.375666000 : 8=FIXT.1.19=32535=X49=Coinbase56=24ab46f784d1b20db435b852086e325034=6850=TEST52=20250411-02:24:49.326216369=2262=fabc71d1-a705-413e-8282-a681c602a690268=1279=0269=2278=c5b88ea9-605d-4595-ac52-f7c3f08523ba83=159761184555=BTC-USD270=3.55271=0.6214689360=20250411-02:24:49.32436837=76be99a0-350c-4657-bef9-7977f20720ce5797=110=086
20250411-02:24:49.375811000 : 8=FIXT.1.19=28835=X49=Coinbase56=24ab46f784d1b20db435b852086e325034=6950=TEST52=20250411-02:24:49.326220369=2262=fabc71d1-a705-413e-8282-a681c602a690268=1279=2269=0278=76be99a0-350c-4657-bef9-7977f20720ce83=159761184655=BTC-USD270=3.84271=0.0000000060=20250411-02:24:49.32436858=FILLED10=034
20250411-02:24:49.678351000 : 8=FIXT.1.19=27735=X49=Coinbase56=24ab46f784d1b20db435b852086e325034=7050=TEST52=20250411-02:24:49.628682369=2262=fabc71d1-a705-413e-8282-a681c602a690268=1279=0269=083=159761184755=BTC-USD29004=2.208895519560=20250411-02:24:49.62654940=137=100e939d-9df7-4347-989c-cafaf452709c10=248
20250411-02:24:49.679755000 : 8=FIXT.1.19=32535=X49=Coinbase56=24ab46f784d1b20db435b852086e325034=7150=TEST52=20250411-02:24:49.628694369=2262=fabc71d1-a705-413e-8282-a681c602a690268=1279=0269=2278=c5b88ea9-605d-4595-ac52-f7c3f08523ba83=159761184855=BTC-USD270=3.55271=0.6222240960=20250411-02:24:49.62654937=100e939d-9df7-4347-989c-cafaf452709c5797=110=142
20250411-02:24:49.680054000 : 8=FIXT.1.19=26435=X49=Coinbase56=24ab46f784d1b20db435b852086e325034=7250=TEST52=20250411-02:24:49.628698369=2262=fabc71d1-a705-413e-8282-a681c602a690268=1279=2269=0278=100e939d-9df7-4347-989c-cafaf452709c83=159761184955=BTC-USD60=20250411-02:24:49.62654958=FILLED10=015
20250411-02:24:49.705716000 : 8=FIXT.1.19=27335=X49=Coinbase56=24ab46f784d1b20db435b852086e325034=7350=TEST52=20250411-02:24:49.657230369=2262=fabc71d1-a705-413e-8282-a681c602a690268=1279=0269=183=159761185055=BTC-USD271=0.6197183160=20250411-02:24:49.65603740=137=eaac9be1-4082-433b-b05b-12f2d61a305f10=057
20250411-02:24:49.706225000 : 8=FIXT.1.19=32535=X49=Coinbase56=24ab46f784d1b20db435b852086e325034=7450=TEST52=20250411-02:24:49.657237369=2262=fabc71d1-a705-413e-8282-a681c602a690268=1279=0269=2278=24de32b2-a7f5-469c-a714-c9b10ee2cce583=159761185155=BTC-USD270=3.54271=0.6197183160=20250411-02:24:49.65603737=eaac9be1-4082-433b-b05b-12f2d61a305f5797=210=007
20250411-02:24:49.706561000 : 8=FIXT.1.19=27935=X49=Coinbase56=24ab46f784d1b20db435b852086e325034=7550=TEST52=20250411-02:24:49.657241369=2262=fabc71d1-a705-413e-8282-a681c602a690268=1279=2269=1278=eaac9be1-4082-433b-b05b-12f2d61a305f83=159761185255=BTC-USD271=0.0000000060=20250411-02:24:49.65603758=FILLED10=226
20250411-02:24:49.778391000 : 8=FIXT.1.19=30135=X49=Coinbase56=24ab46f784d1b20db435b852086e325034=7650=TEST52=20250411-02:24:49.728941369=2262=fabc71d1-a705-413e-8282-a681c602a690268=1279=0269=083=159761185355=BTC-USD270=3.82271=0.6672719929004=2.368815564560=20250411-02:24:49.72734640=237=133603b5-2fc6-43df-aa92-502f30dc58e710=081
20250411-02:24:49.778751000 : 8=FIXT.1.19=32535=X49=Coinbase56=24ab46f784d1b20db435b852086e325034=7750=TEST52=20250411-02:24:49.729018369=2262=fabc71d1-a705-413e-8282-a681c602a690268=1279=0269=2278=c5b88ea9-605d-4595-ac52-f7c3f08523ba83=159761185455=BTC-USD270=3.55271=0.6672719960=20250411-02:24:49.72734637=133603b5-2fc6-43df-aa92-502f30dc58e75797=110=121
20250411-02:24:49.778922000 : 8=FIXT.1.19=27935=X49=Coinbase56=24ab46f784d1b20db435b852086e325034=7850=TEST52=20250411-02:24:49.729057369=2262=fabc71d1-a705-413e-8282-a681c602a690268=1279=2269=0278=133603b5-2fc6-43df-aa92-502f30dc58e783=159761185555=BTC-USD270=3.82271=060=20250411-02:24:49.72734658=FILLED10=149
20250411-02:24:49.832091000 : 8=FIXT.1.19=30135=X49=Coinbase56=24ab46f784d1b20db435b852086e325034=7950=TEST52=20250411-02:24:49.782746369=2262=fabc71d1-a705-413e-8282-a681c602a690268=1279=0269=183=159761185655=BTC-USD270=3.32271=0.5819209029004=2.059999986060=20250411-02:24:49.78146540=237=f3545cef-7831-4ad5-b206-9fcfa940ced410=248
20250411-02:24:49.832887000 : 8=FIXT.1.19=32535=X49=Coinbase56=24ab46f784d1b20db435b852086e325034=8050=TEST52=20250411-02:24:49.782762369=2262=fabc71d1-a705-413e-8282-a681c602a690268=1279=0269=2278=24de32b2-a7f5-469c-a714-c9b10ee2cce583=159761185755=BTC-USD270=3.54271=0.5819209060=20250411-02:24:49.78146537=f3545cef-7831-4ad5-b206-9fcfa940ced45797=210=097
20250411-02:24:49.833147000 : 8=FIXT.1.19=27935=X49=Coinbase56=24ab46f784d1b20db435b852086e325034=8150=TEST52=20250411-02:24:49.782767369=2262=fabc71d1-a705-413e-8282-a681c602a690268=1279=2269=1278=f3545cef-7831-4ad5-b206-9fcfa940ced483=159761185855=BTC-USD270=3.32271=060=20250411-02:24:49.78146558=FILLED10=055
20250411-02:24:50.535611000 : 8=FIXT.1.19=27735=X49=Coinbase56=24ab46f784d1b20db435b852086e325034=8250=TEST52=20250411-02:24:50.485974369=2262=fabc71d1-a705-413e-8282-a681c602a690268=1279=0269=083=159761185955=BTC-USD29004=2.208895519560=20250411-02:24:50.48418740=137=79200bef-13a0-4c42-8aa8-1f4b054a4c7610=202
20250411-02:24:50.538232000 : 8=FIXT.1.19=32535=X49=Coinbase56=24ab46f784d1b20db435b852086e325034=8350=TEST52=20250411-02:24:50.485985369=2262=fabc71d1-a705-413e-8282-a681c602a690268=1279=0269=2278=c5b88ea9-605d-4595-ac52-f7c3f08523ba83=159761186055=BTC-USD270=3.55271=0.6222240960=20250411-02:24:50.48418737=79200bef-13a0-4c42-8aa8-1f4b054a4c765797=110=086
20250411-02:24:50.539104000 : 8=FIXT.1.19=26435=X49=Coinbase56=24ab46f784d1b20db435b852086e325034=8450=TEST52=20250411-02:24:50.485989369=2262=fabc71d1-a705-413e-8282-a681c602a690268=1279=2269=0278=79200bef-13a0-4c42-8aa8-1f4b054a4c7683=159761186155=BTC-USD60=20250411-02:24:50.48418758=FILLED10=215
20250411-02:24:50.564624000 : 8=FIXT.1.19=27335=X49=Coinbase56=24ab46f784d1b20db435b852086e325034=8550=TEST52=20250411-02:24:50.514496369=2262=fabc71d1-a705-413e-8282-a681c602a690268=1279=0269=183=159761186255=BTC-USD271=0.6214689360=20250411-02:24:50.51259440=137=a115f186-2d2a-4e55-a57a-0e8b63efb20610=024
20250411-02:24:50.565118000 : 8=FIXT.1.19=32535=X49=Coinbase56=24ab46f784d1b20db435b852086e325034=8650=TEST52=20250411-02:24:50.514505369=2262=fabc71d1-a705-413e-8282-a681c602a690268=1279=0269=2278=24de32b2-a7f5-469c-a714-c9b10ee2cce583=159761186355=BTC-USD270=3.54271=0.6214689360=20250411-02:24:50.51259437=a115f186-2d2a-4e55-a57a-0e8b63efb2065797=210=214
20250411-02:24:50.565418000 : 8=FIXT.1.19=27935=X49=Coinbase56=24ab46f784d1b20db435b852086e325034=8750=TEST52=20250411-02:24:50.514509369=2262=fabc71d1-a705-413e-8282-a681c602a690268=1279=2269=1278=a115f186-2d2a-4e55-a57a-0e8b63efb20683=159761186455=BTC-USD271=0.0000000060=20250411-02:24:50.51259458=FILLED10=183
20250411-02:24:50.650282000 : 8=FIXT.1.19=27735=X49=Coinbase56=24ab46f784d1b20db435b852086e325034=8850=TEST52=20250411-02:24:50.600701369=2262=fabc71d1-a705-413e-8282-a681c602a690268=1279=0269=083=159761186555=BTC-USD29004=2.208895519560=20250411-02:24:50.59901540=137=041f72d0-9583-4f40-8599-3e7e3d57f4e210=075
20250411-02:24:50.650599000 : 8=FIXT.1.19=32535=X49=Coinbase56=24ab46f784d1b20db435b852086e325034=8950=TEST52=20250411-02:24:50.600710369=2262=fabc71d1-a705-413e-8282-a681c602a690268=1279=0269=2278=c5b88ea9-605d-4595-ac52-f7c3f08523ba83=159761186655=BTC-USD270=3.55271=0.6222240960=20250411-02:24:50.59901537=041f72d0-9583-4f40-8599-3e7e3d57f4e25797=110=222
20250411-02:24:50.651060000 : 8=FIXT.1.19=26435=X49=Coinbase56=24ab46f784d1b20db435b852086e325034=9050=TEST52=20250411-02:24:50.600718369=2262=fabc71d1-a705-413e-8282-a681c602a690268=1279=2269=0278=041f72d0-9583-4f40-8599-3e7e3d57f4e283=159761186755=BTC-USD60=20250411-02:24:50.59901558=FILLED10=090
20250411-02:24:50.676709000 : 8=FIXT.1.19=27335=X49=Coinbase56=24ab46f784d1b20db435b852086e325034=9150=TEST52=20250411-02:24:50.628658369=2262=fabc71d1-a705-413e-8282-a681c602a690268=1279=0269=183=159761186855=BTC-USD271=0.6214689360=20250411-02:24:50.62736740=137=7b274c4f-d826-40d7-99b3-a0e602e2914310=165
20250411-02:24:50.678003000 : 8=FIXT.1.19=32535=X49=Coinbase56=24ab46f784d1b20db435b852086e325034=9250=TEST52=20250411-02:24:50.628728369=2262=fabc71d1-a705-413e-8282-a681c602a690268=1279=0269=2278=24de32b2-a7f5-469c-a714-c9b10ee2cce583=159761186955=BTC-USD270=3.54271=0.6214689360=20250411-02:24:50.62736737=7b274c4f-d826-40d7-99b3-a0e602e291435797=210=106
20250411-02:24:50.678191000 : 8=FIXT.1.19=27935=X49=Coinbase56=24ab46f784d1b20db435b852086e325034=9350=TEST52=20250411-02:24:50.628736369=2262=fabc71d1-a705-413e-8282-a681c602a690268=1279=2269=1278=7b274c4f-d826-40d7-99b3-a0e602e2914383=159761187055=BTC-USD271=0.0000000060=20250411-02:24:50.62736758=FILLED10=061
20250411-02:24:50.806963000 : 8=FIXT.1.19=28235=X49=Coinbase56=24ab46f784d1b20db435b852086e325034=9450=TEST52=20250411-02:24:50.757873369=2262=fabc71d1-a705-413e-8282-a681c602a690268=1279=0269=183=159761187155=BTC-USD270=3.33271=0.6214689360=20250411-02:24:50.75467640=237=3957641b-efeb-44ed-98af-b051b691c10510=215
20250411-02:24:50.807391000 : 8=FIXT.1.19=32535=X49=Coinbase56=24ab46f784d1b20db435b852086e325034=9550=TEST52=20250411-02:24:50.757941369=2262=fabc71d1-a705-413e-8282-a681c602a690268=1279=0269=2278=24de32b2-a7f5-469c-a714-c9b10ee2cce583=159761187255=BTC-USD270=3.54271=0.6214689360=20250411-02:24:50.75467637=3957641b-efeb-44ed-98af-b051b691c1055797=210=251
20250411-02:24:50.807640000 : 8=FIXT.1.19=28835=X49=Coinbase56=24ab46f784d1b20db435b852086e325034=9650=TEST52=20250411-02:24:50.757947369=2262=fabc71d1-a705-413e-8282-a681c602a690268=1279=2269=1278=3957641b-efeb-44ed-98af-b051b691c10583=159761187355=BTC-USD270=3.33271=0.0000000060=20250411-02:24:50.75467658=FILLED10=124
20250411-02:24:50.862776000 : 8=FIXT.1.19=28235=X49=Coinbase56=24ab46f784d1b20db435b852086e325034=9750=TEST52=20250411-02:24:50.813035369=2262=fabc71d1-a705-413e-8282-a681c602a690268=1279=0269=083=159761187455=BTC-USD270=3.77271=0.6214689360=20250411-02:24:50.81178840=237=f7e45840-4a54-482d-82c5-1d044388456810=190
20250411-02:24:50.863112000 : 8=FIXT.1.19=32535=X49=Coinbase56=24ab46f784d1b20db435b852086e325034=9850=TEST52=20250411-02:24:50.813043369=2262=fabc71d1-a705-413e-8282-a681c602a690268=1279=0269=2278=c5b88ea9-605d-4595-ac52-f7c3f08523ba83=159761187555=BTC-USD270=3.55271=0.6214689360=20250411-02:24:50.81178837=f7e45840-4a54-482d-82c5-1d04438845685797=110=141
20250411-02:24:50.863439000 : 8=FIXT.1.19=28835=X49=Coinbase56=24ab46f784d1b20db435b852086e325034=9950=TEST52=20250411-02:24:50.813047369=2262=fabc71d1-a705-413e-8282-a681c602a690268=1279=2269=0278=f7e45840-4a54-482d-82c5-1d044388456883=159761187655=BTC-USD270=3.77271=0.0000000060=20250411-02:24:50.81178858=FILLED10=100
20250411-02:24:51.508598000 : 8=FIXT.1.19=91835=W49=Coinbase56=24ab46f784d1b20db435b852086e325034=10050=TEST52=20250411-02:24:51.459577369=2262=fabc71d1-a705-413e-8282-a681c602a69083=1597611876893=N55=BTC-USD1682=full_trading268=10269=0278=24de32b2-a7f5-469c-a714-c9b10ee2cce5270=3.54271=25774.04084697269=0278=c6a6f469-efa2-413e-a05b-2c33614cb7e1270=3.54271=272279.26699541269=0278=f5fc5e68-a52c-44d3-87ef-3785312f4782270=3.48271=0.29310888269=0278=dcccb470-c535-433a-9198-4e2b4c26d99d270=3.47271=0.29311495269=0278=f05d9766-970d-44ca-aa4d-e8b2720bbda8270=3.46271=0.29026870269=0278=2c4d7d5a-33aa-4058-b546-480b6a2168a4270=3.44271=0.29828577269=0278=37dbcf16-0b3d-4f67-bc90-e36268b99e0e270=3.42271=0.30270947269=0278=4c63c0b7-30e0-4ef1-931f-0090359f978e270=3.41271=0.32158962269=0278=d6b4aa4e-d588-4c96-83aa-8e8d8accb1a4270=3.41271=0.30121104269=0278=e8b3d8da-1663-413c-b7fb-6aba23b01440270=3.39271=0.3100647710=160
20250411-02:24:51.512608000 : 8=FIXT.1.19=14135=334=349=24ab46f784d1b20db435b852086e325052=20250411-02:24:51.51156=Coinbase45=10058=Tag appears more than once371=269372=W373=1310=234
20250411-02:24:51.512813000 : 8=FIXT.1.19=90935=W49=Coinbase56=24ab46f784d1b20db435b852086e325034=10150=TEST52=20250411-02:24:51.459818369=2262=fabc71d1-a705-413e-8282-a681c602a69083=1597611876893=N55=BTC-USD1682=full_trading268=10269=0278=bcbe17c3-9059-4c38-8ab8-8e78f1ef9062270=3.38271=0.32617981269=0278=57bb77fd-337f-49bc-a56f-a4e2dff851ee270=3.37271=0.31071676269=0278=ded4b51d-349f-4726-8379-6761a3576bb6270=3.33271=0.31560513269=0278=ff7aff09-38de-47ac-a3cb-9beacb0b9ad8270=3.33271=0.30682342269=0278=d1da558a-e9d2-4e11-b26e-1eb80a1a34c5270=3.32271=0.31700685269=0278=9ee34527-d4d8-4659-b2ea-cdff3dc4a8fa270=3.32271=0.32181951269=0278=7abf2220-0421-460f-9dbb-14c41564e41a270=3.32271=0.31308436269=0278=69634ec5-f71a-4990-b56d-13c3069a455a270=3.31271=0.32329458269=0278=2f333c17-a386-4d52-8ff1-eadcb99bc22f270=3.31271=0.31999220269=0278=f02efc37-0b1e-470b-99ef-e31012887d73270=3.30271=0.3277157010=255
20250411-02:24:51.513432000 : 8=FIXT.1.19=14135=334=449=24ab46f784d1b20db435b852086e325052=20250411-02:24:51.51356=Coinbase45=10158=Tag appears more than once371=269372=W373=1310=238
20250411-02:24:51.513509000 : 8=FIXT.1.19=90935=W49=Coinbase56=24ab46f784d1b20db435b852086e325034=10250=TEST52=20250411-02:24:51.460068369=2262=fabc71d1-a705-413e-8282-a681c602a69083=1597611876893=N55=BTC-USD1682=full_trading268=10269=0278=6d430950-8078-4987-8995-e581564e368d270=3.29271=0.30702763269=0278=841f895a-cd2d-4082-9a37-b50fc19e35bf270=3.28271=0.32610801269=0278=3cf93093-e42b-4c24-95ea-c367d96427fe270=3.27271=0.33588654269=0278=f29c94bc-d1c2-4145-97b0-ecb77d81a8bf270=3.27271=0.31661408269=0278=d208c4fb-56c6-4911-85c9-77b68a5ba6ab270=3.25271=0.30961623269=0278=e88796ff-68c8-4463-914b-46e09fbaf639270=3.25271=0.33589845269=0278=06f345fb-0292-45fc-8237-9ad1a84b541c270=3.24271=0.31528507269=0278=fa20c2c7-df80-4941-9a9c-a6ef2e579480270=3.23271=0.33432448269=0278=a833d230-a749-4bf4-823e-93adc40b773d270=3.23271=0.31165878269=0278=2abb6e15-b9cd-415b-8c9b-99a61c750310270=3.22271=0.3204871410=018
20250411-02:24:51.514067000 : 8=FIXT.1.19=14135=334=549=24ab46f784d1b20db435b852086e325052=20250411-02:24:51.51356=Coinbase45=10258=Tag appears more than once371=269372=W373=1310=240
20250411-02:24:51.514231000 : 8=FIXT.1.19=90935=W49=Coinbase56=24ab46f784d1b20db435b852086e325034=10350=TEST52=20250411-02:24:51.460318369=2262=fabc71d1-a705-413e-8282-a681c602a69083=1597611876893=N55=BTC-USD1682=full_trading268=10269=0278=ec44a6d8-ae5f-4809-89d7-0f7a3adac547270=3.21271=0.33230954269=0278=9cf61c67-c4fc-4bac-92fd-d4e2b56248aa270=3.21271=0.33583951269=0278=210b2518-bb42-461a-9c7e-b4e04c5ffcc6270=3.21271=0.32669007269=0278=2e3fa1b2-20f1-4694-9be4-322040b75152270=3.21271=0.32907979269=0278=05dd5607-92c9-4296-8cdc-27cdff004dea270=3.21271=0.32776075269=0278=87944de7-a5f1-4033-a3d8-cbc10f3a5232270=3.20271=0.32225170269=0278=30f6bb59-2469-4e6d-8fa5-13666373901f270=3.19271=0.31386496269=0278=6a5d2852-7ddc-456e-acb5-bfadcc0c1360270=3.19271=0.32157390269=0278=5d00d8a2-5aea-4836-ba19-74fe67116df8270=3.18271=0.32651049269=0278=acc71746-3591-4dde-a7e2-c2795d0ad125270=3.17271=0.3157713110=069
20250411-02:24:51.514824000 : 8=FIXT.1.19=14135=334=649=24ab46f784d1b20db435b852086e325052=20250411-02:24:51.51456=Coinbase45=10358=Tag appears more than once371=269372=W373=1310=243
20250411-02:24:51.514903000 : 8=FIXT.1.19=91035=W49=Coinbase56=24ab46f784d1b20db435b852086e325034=10450=TEST52=20250411-02:24:51.460568369=2262=fabc71d1-a705-413e-8282-a681c602a69083=1597611876893=N55=BTC-USD1682=full_trading268=10269=0278=13982796-c2a8-4740-95e2-5aca0fdfd8bb270=3.16271=0.33021170269=0278=9f2f0737-661e-43d7-89f9-959ed5e08306270=3.16271=0.33082075269=0278=7e0e2d14-fa77-4978-8cae-d9660fd13e6d270=3.16271=0.32014975269=0278=82826a7d-848c-4516-a7b6-5ec6881609a8270=2.00271=10.00000000269=0278=590048d5-ee44-49dc-b66d-1a692e055133270=1.94271=0.51546392269=0278=22bdda11-16cd-488b-9fa9-da098dad543e270=1.94271=0.51546392269=0278=d356ef8b-596e-47e7-bf90-cc015b85fc57270=1.93271=0.52331606269=0278=aa8d48bc-97fb-4d00-b923-66d37cc8c66a270=1.93271=0.52331606269=0278=7d51dcb4-a7f8-4cca-b2d0-e902403d1b9f270=1.93271=0.52331606269=0278=f7680950-3af2-4723-a6e4-5cbd528ca900270=1.93271=0.5233160610=162
20250411-02:24:51.515586000 : 8=FIXT.1.19=14135=334=749=24ab46f784d1b20db435b852086e325052=20250411-02:24:51.51556=Coinbase45=10458=Tag appears more than once371=269372=W373=1310=246
20250411-02:24:51.515691000 : 8=FIXT.1.19=90935=W49=Coinbase56=24ab46f784d1b20db435b852086e325034=10550=TEST52=20250411-02:24:51.460818369=2262=fabc71d1-a705-413e-8282-a681c602a69083=1597611876893=N55=BTC-USD1682=full_trading268=10269=0278=fdeff994-4866-47af-9dde-a25947a26606270=1.93271=0.52331606269=0278=65e7e2bb-023d-4936-bb4e-ff7625ba7264270=1.93271=0.52331606269=0278=53732639-572c-4cd5-b61e-e4f534d1d540270=1.93271=0.52331606269=0278=24da8927-1dd1-468b-9437-ff366f5bfa11270=1.93271=0.52331606269=0278=baa5862c-41e8-458c-83d3-c095bb68ed17270=1.93271=0.52331606269=0278=92a3c3e3-7afe-4d02-a0d8-96f512b63bb7270=1.93271=0.52331606269=0278=9d2a564e-f178-4966-9baf-5814a1c1686b270=1.93271=0.52331606269=0278=f9e6b978-87f6-4397-8d82-07cf698c123f270=1.93271=0.52331606269=0278=3e64b388-13d3-441d-b241-aa8dd6fe55e6270=1.93271=0.52331606269=0278=60300433-87b0-4031-bb1e-12cf9d773d3f270=1.93271=0.5233160610=010
20250411-02:24:51.516562000 : 8=FIXT.1.19=14135=334=849=24ab46f784d1b20db435b852086e325052=20250411-02:24:51.51656=Coinbase45=10558=Tag appears more than once371=269372=W373=1310=249
20250411-02:24:51.516693000 : 8=FIXT.1.19=90935=W49=Coinbase56=24ab46f784d1b20db435b852086e325034=10650=TEST52=20250411-02:24:51.461068369=2262=fabc71d1-a705-413e-8282-a681c602a69083=1597611876893=N55=BTC-USD1682=full_trading268=10269=0278=1bdd5f5a-1d99-4eed-af09-c187bcbbd2d8270=1.93271=0.52331606269=0278=4ed6f6b9-77fb-4255-a188-f243dd0cdb3c270=1.93271=0.52331606269=0278=9ad1fc18-5a38-4edb-ac5c-6ac826a8a846270=1.93271=0.52331606269=0278=1c218c8c-baea-4a1f-838e-4a3a94b468e1270=1.93271=0.52331606269=0278=fd70f5e2-d2c9-472a-ab40-a775afafd73d270=1.93271=0.52331606269=0278=96f5e3a5-1c2a-4db6-a3fb-fd1f13d5d559270=1.93271=0.52331606269=0278=4a015a4c-490a-4c40-974f-9dfb7feb335d270=1.93271=0.52331606269=0278=d919363e-2c54-404f-bc0b-063e2f12bec4270=1.93271=0.52331606269=0278=d4636d6c-85c6-4ac9-9afb-70ca636f4ad4270=1.93271=0.52331606269=0278=bda09690-f345-4c33-ae8b-e8c78da11b5a270=1.93271=0.5233160610=094
20250411-02:24:51.517417000 : 8=FIXT.1.19=14135=334=949=24ab46f784d1b20db435b852086e325052=20250411-02:24:51.51756=Coinbase45=10658=Tag appears more than once371=269372=W373=1310=252
20250411-02:24:51.517497000 : 8=FIXT.1.19=90935=W49=Coinbase56=24ab46f784d1b20db435b852086e325034=10750=TEST52=20250411-02:24:51.461318369=2262=fabc71d1-a705-413e-8282-a681c602a69083=1597611876893=N55=BTC-USD1682=full_trading268=10269=0278=1a81ae10-b700-42a0-89a3-7d7a3eea0ebb270=1.93271=0.52331606269=0278=1ace5afa-e550-4abf-a458-52e46e1b54f0270=1.93271=0.52331606269=0278=2332d1c9-67e7-457a-abfe-f5e9a8c2ea05270=1.93271=0.52331606269=0278=6afa1f19-0ec5-49fd-8b74-06a12a6c5ca9270=1.93271=0.52331606269=0278=3fa3413d-c26c-472f-9cc5-da1c48935c63270=1.93271=0.52331606269=0278=3f9e43c4-2e62-4d51-b4cb-ad207c693331270=1.93271=0.52331606269=0278=29e8bfcf-c764-4f7e-997d-09abf72bbc00270=1.93271=0.52331606269=0278=cf3e8b26-09ae-4dfb-9b84-b12a7e199a5a270=1.93271=0.52331606269=0278=08db3e51-e927-47d3-a9dd-2f887c58dc85270=1.93271=0.52331606269=0278=353ae741-9473-4cc5-9ab7-7e5de8ae55d0270=1.93271=0.5233160610=091
20250411-02:24:51.518122000 : 8=FIXT.1.19=14235=334=1049=24ab46f784d1b20db435b852086e325052=20250411-02:24:51.51756=Coinbase45=10758=Tag appears more than once371=269372=W373=1310=038
20250411-02:24:51.518233000 : 8=FIXT.1.19=90935=W49=Coinbase56=24ab46f784d1b20db435b852086e325034=10850=TEST52=20250411-02:24:51.461568369=2262=fabc71d1-a705-413e-8282-a681c602a69083=1597611876893=N55=BTC-USD1682=full_trading268=10269=0278=4d037208-2072-480f-98ac-7be9c24f18f4270=1.93271=0.52331606269=0278=b598f678-da6e-4c01-90ed-d702c42f8a65270=1.93271=0.52331606269=0278=5f69b1a0-b5d1-4715-9be1-9bdf008d97d7270=1.93271=0.52331606269=0278=ef063d15-248a-4eae-97f4-278be5106d80270=1.93271=0.52331606269=0278=f8b20207-84bc-44e9-a2fe-9ad775e2ecb1270=1.93271=0.52331606269=0278=75bce2b7-bc58-4479-8bfb-144f88f2262b270=1.93271=0.52331606269=0278=1f6e2a79-8b10-4a7f-89de-0f1fa03692c7270=1.93271=0.52331606269=0278=d1b80bf5-9b17-44b4-9577-6fe71170b578270=1.93271=0.52331606269=0278=b891e26a-c20c-4fce-ba1c-487fe139a4cc270=1.93271=0.52331606269=0278=5d06d3f6-3189-4394-b3c5-6a2bda14b6d1270=1.93271=0.5233160610=153
20250411-02:24:51.518945000 : 8=FIXT.1.19=14235=334=1149=24ab46f784d1b20db435b852086e325052=20250411-02:24:51.51856=Coinbase45=10858=Tag appears more than once371=269372=W373=1310=041
20250411-02:24:51.519078000 : 8=FIXT.1.19=90935=W49=Coinbase56=24ab46f784d1b20db435b852086e325034=10950=TEST52=20250411-02:24:51.461818369=2262=fabc71d1-a705-413e-8282-a681c602a69083=1597611876893=N55=BTC-USD1682=full_trading268=10269=0278=e5791c0f-3937-4a66-9b98-26f79a3891be270=1.93271=0.52331606269=0278=c62591c6-7dfa-46a7-8f20-6a5f22804999270=1.93271=0.52331606269=0278=7c503558-c0b8-457b-8c46-71ece3f7fc8a270=1.93271=0.52331606269=0278=f763bb56-2f21-4a9b-bd48-f84dc1bd5ee5270=1.93271=0.52331606269=0278=42214b03-1fc2-46b3-9e83-91b23a510e5a270=1.93271=0.52331606269=0278=1c7c52ed-7d39-4326-b3b8-98f05a9b3ef0270=1.93271=0.52331606269=0278=3313309e-45e7-4e7b-8c55-4f9a8ec1b351270=1.93271=0.52331606269=0278=78801ffb-ec5a-4c74-9d08-3e86fd9db4dd270=1.93271=0.52331606269=0278=abe6eea4-1d9c-47d7-847f-2f44aa561b3f270=1.93271=0.52331606269=0278=6a6eb56d-2010-43e2-b78e-5f098081bb64270=1.93271=0.5233160610=085
20250411-02:24:51.519608000 : 8=FIXT.1.19=14235=334=1249=24ab46f784d1b20db435b852086e325052=20250411-02:24:51.51956=Coinbase45=10958=Tag appears more than once371=269372=W373=1310=044
20250411-02:24:51.735465000 : 8=FIXT.1.19=90935=W49=Coinbase56=24ab46f784d1b20db435b852086e325034=11050=TEST52=20250411-02:24:51.462068369=2262=fabc71d1-a705-413e-8282-a681c602a69083=1597611876893=N55=BTC-USD1682=full_trading268=10269=0278=b53c01ff-f450-4b05-8ad1-e7894b45e0e0270=1.93271=0.52331606269=0278=4747863e-c0a6-4ef5-8faf-e8934bca4f8b270=1.93271=0.52331606269=0278=81a8a629-57f4-4e3a-ac25-2e9ee1f357c2270=1.93271=0.52331606269=0278=1e239259-7be4-476a-845d-1b92fd951d8b270=1.93271=0.52331606269=0278=189eb272-48f9-4915-b7e1-a86dcc505c4a270=1.93271=0.52331606269=0278=0562b9f7-aae3-4961-bd97-f5b8cde0ec34270=1.93271=0.52331606269=0278=5103331b-7300-487b-bc2c-a6032bf4be7e270=1.93271=0.52331606269=0278=78ac85ac-2478-4991-a084-7286982b77cc270=1.93271=0.52331606269=0278=6993b26d-d6dc-4f99-8a53-9500ae5b4ff1270=1.93271=0.52331606269=0278=1c96ab9d-04a6-465a-87e5-3ed33970178f270=1.93271=0.5233160610=239
20250411-02:24:51.736514000 : 8=FIXT.1.19=14235=334=1349=24ab46f784d1b20db435b852086e325052=20250411-02:24:51.73556=Coinbase45=11058=Tag appears more than once371=269372=W373=1310=037
20250411-02:24:51.736643000 : 8=FIXT.1.19=92035=W49=Coinbase56=24ab46f784d1b20db435b852086e325034=11150=TEST52=20250411-02:24:51.462318369=2262=fabc71d1-a705-413e-8282-a681c602a69083=1597611876893=N55=BTC-USD1682=full_trading268=10269=0278=6fc0282b-d538-4aa3-8982-bda02bb1b054270=1.93271=0.52331606269=0278=80870aa3-04a2-4d2a-8669-93215130ffee270=1.93271=0.52331606269=0278=b274e872-6923-45fd-b48a-68e685e769cb270=1.93271=0.52331606269=0278=2d4364c0-239c-4f4b-8ce4-2acfe0bb343d270=1.12271=1.00000000269=0278=8fa16a4f-377f-4deb-9a8e-1020aed9edf4270=1.00271=1.00000000269=1278=c5b88ea9-605d-4595-ac52-f7c3f08523ba270=3.55271=2659.70088664269=1278=81523bd3-8912-4789-8761-89a9ee42794b270=3.55271=0.30518966269=1278=60fc75ca-0052-40b7-9f18-a6aad9d31b84270=3.56271=18037.00000000269=1278=ad00e2cd-d925-46a4-9e7e-941c6faed2c7270=3.57271=18027.00000000269=1278=fec191b5-64da-4a15-ab4b-36a0d3d10750270=3.57271=0.2902530110=112
20250411-02:24:51.737157000 : 8=FIXT.1.19=14235=334=1449=24ab46f784d1b20db435b852086e325052=20250411-02:24:51.73656=Coinbase45=11158=Tag appears more than once371=269372=W373=1310=040
20250411-02:24:51.737239000 : 8=FIXT.1.19=93335=W49=Coinbase56=24ab46f784d1b20db435b852086e325034=11250=TEST52=20250411-02:24:51.462568369=2262=fabc71d1-a705-413e-8282-a681c602a69083=1597611876893=N55=BTC-USD1682=full_trading268=10269=1278=02a780aa-8154-4638-a5ca-53b8198cc724270=3.58271=16937.00000000269=1278=911349fb-1960-4904-9a38-0e2497fb7ccb270=3.58271=0.29896312269=1278=d91e89d4-ac5c-4853-9879-ec8ff5e00a71270=3.59271=17163.00000000269=1278=341d0ad8-6c15-4b5e-aebb-e3caa5af575c270=3.60271=17926.00000000269=1278=9d239e03-1215-4cc7-ad44-3f4097ee70ea270=3.61271=18058.08928020269=1278=dbb0f332-4189-4df5-879b-e55860b13def270=3.62271=0.28062774269=1278=f7639c39-7e8b-44d1-a2f2-9807e2a3228c270=3.62271=0.27709851269=1278=83be9389-2099-4173-a322-b0933bc99358270=3.62271=19973.00000000269=1278=b89abc22-6b6c-4474-b3fc-ffe21f05cd4e270=3.63271=20016.00000000269=1278=ce0af8a3-149c-4603-905a-be65625fe014270=3.64271=0.2780600210=062
20250411-02:24:51.737699000 : 8=FIXT.1.19=14235=334=1549=24ab46f784d1b20db435b852086e325052=20250411-02:24:51.73756=Coinbase45=11258=Tag appears more than once371=269372=W373=1310=043
20250411-02:24:51.737804000 : 8=FIXT.1.19=91735=W49=Coinbase56=24ab46f784d1b20db435b852086e325034=11350=TEST52=20250411-02:24:51.462818369=2262=fabc71d1-a705-413e-8282-a681c602a69083=1597611876893=N55=BTC-USD1682=full_trading268=10269=1278=94b8615f-6fa7-4dc9-bbfa-435fe535bebc270=3.64271=22352.63489459269=1278=8e4ddffe-04fe-418a-8103-cd8143be68f8270=3.65271=19640.75109509269=1278=cae3885d-f5b2-4de1-830c-0085e27bbb69270=3.69271=0.27722678269=1278=bd6dda75-3981-41f3-b37c-0e106f949e01270=3.70271=0.44172990269=1278=b9732128-11b1-44fd-bea3-94da9fc853fb270=3.71271=0.28488329269=1278=818b83a4-e14e-4ad5-b094-6733f0504003270=3.75271=0.27930225269=1278=3e6990a0-8ef4-4968-8ee8-89b7346c197d270=3.76271=0.28131365269=1278=342794c8-a9d2-4aa5-9886-a819398d69c6270=3.88271=0.27719712269=1278=2839680b-48b3-4f53-86b1-9269987275e7270=3.91271=0.26621275269=1278=fd7b5361-29f8-4b35-bae5-232a64f657b4270=3.95271=0.2613140610=024
20250411-02:24:51.738403000 : 8=FIXT.1.19=14235=334=1649=24ab46f784d1b20db435b852086e325052=20250411-02:24:51.73856=Coinbase45=11358=Tag appears more than once371=269372=W373=1310=046
20250411-02:24:51.738481000 : 8=FIXT.1.19=92135=W49=Coinbase56=24ab46f784d1b20db435b852086e325034=11450=TEST52=20250411-02:24:51.463068369=2262=fabc71d1-a705-413e-8282-a681c602a69083=1597611876893=N55=BTC-USD1682=full_trading268=10269=1278=5edaeed0-fae9-4f36-8c77-6fbedf61eefc270=4.02271=0.25091227269=1278=fdbbfd04-ba67-4b23-bbc1-f87f929e7e81270=4.07271=0.24812642269=1278=534b2a85-0852-420d-928b-70cdb6ba2457270=4.10271=0.26961968269=1278=b009f8a1-4a39-493b-b96e-d783e981c915270=4.26271=0.25019574269=1278=729a899c-ac2d-4541-b0a2-cbdd5df9bf98270=10.00271=10.00000000269=1278=eb1e5d45-d081-4ef8-a83e-1f5348fbda96270=10.00271=10.00000000269=1278=0cd67977-85eb-45fa-ae72-d45b92ca24f4270=10.00271=10.00000000269=1278=5d931559-6758-4b75-9d6d-6438d25b497f270=10.00271=10.00000000269=1278=57e43d1d-644a-493e-acd3-69dc5e64dcde270=10.00271=10.00000000269=1278=c1566121-2b63-494d-ac2d-973e9f0115c0270=10.00271=10.0000000010=025
20250411-02:24:51.738929000 : 8=FIXT.1.19=14235=334=1749=24ab46f784d1b20db435b852086e325052=20250411-02:24:51.73856=Coinbase45=11458=Tag appears more than once371=269372=W373=1310=048
20250411-02:24:51.739036000 : 8=FIXT.1.19=93035=W49=Coinbase56=24ab46f784d1b20db435b852086e325034=11550=TEST52=20250411-02:24:51.463319369=2262=fabc71d1-a705-413e-8282-a681c602a69083=1597611876893=N55=BTC-USD1682=full_trading268=10269=1278=d0c4a771-9035-4db9-ae7b-ad2d1db5646d270=10.00271=10.00000000269=1278=52c644ea-628a-4576-8e7e-27ec4c90398b270=10.00271=10.00000000269=1278=c3483f66-d8ce-489a-90b9-2bce69e054ee270=10.00271=10.00000000269=1278=55992a5c-cbcd-464a-8f8d-8b58e81e5c0b270=10.00271=10.00000000269=1278=19077009-6f26-4e2d-9dab-04a28231b752270=10.00271=10.00000000269=1278=692097d1-c978-4024-95e9-2bf348b64bbd270=10.00271=10.00000000269=1278=99a92935-11b7-4f21-a64c-c746b53d1777270=10.00271=10.00000000269=1278=dc024b0b-0337-4215-9669-5e5636834397270=10.00271=10.00000000269=1278=c90fcc3a-a36c-4c14-b57f-6db78762e017270=10.00271=10.00000000269=1278=7841891a-bb7c-4034-97c1-41164185edc7270=1000.00271=3.1000000010=053
20250411-02:24:51.739570000 : 8=FIXT.1.19=14235=334=1849=24ab46f784d1b20db435b852086e325052=20250411-02:24:51.73956=Coinbase45=11558=Tag appears more than once371=269372=W373=1310=051
20250411-02:24:51.739643000 : 8=FIXT.1.19=93935=W49=Coinbase56=24ab46f784d1b20db435b852086e325034=11650=TEST52=20250411-02:24:51.463569369=2262=fabc71d1-a705-413e-8282-a681c602a69083=1597611876893=N55=BTC-USD1682=full_trading268=10269=1278=381c9fa7-1add-4dd2-9233-f41e2c8821fe270=1000.00271=3.10000000269=1278=928e65c2-7e2d-478b-9310-414fb77f5aae270=1000.00271=3.10000000269=1278=ad4bd3ac-9276-40d5-90f9-e47b1d8ee953270=1000.00271=3.10000000269=1278=79e799dc-4a3d-4922-ad1a-f74eb7eff789270=1000.00271=3.10000000269=1278=04f642b7-750f-4967-b786-0d48eea0f158270=1000.00271=3.10000000269=1278=d0ad653d-3272-4a3b-ba7a-a52029a67a92270=1000.00271=3.10000000269=1278=cad40464-4c62-4bf3-8444-c487fcc8dd01270=1000.00271=3.10000000269=1278=426c6428-d481-4ff7-9de3-f00ff219d654270=1000.00271=3.10000000269=1278=1ed1152d-8c1a-4b29-acdd-bbd1a5c5f35f270=1000.00271=3.10000000269=1278=66526051-b5cb-442f-af90-c609be0a9796270=1000.00271=3.1000000010=125
20250411-02:24:51.740157000 : 8=FIXT.1.19=14235=334=1949=24ab46f784d1b20db435b852086e325052=20250411-02:24:51.73956=Coinbase45=11658=Tag appears more than once371=269372=W373=1310=053
20250411-02:24:51.740242000 : 8=FIXT.1.19=93935=W49=Coinbase56=24ab46f784d1b20db435b852086e325034=11750=TEST52=20250411-02:24:51.463818369=2262=fabc71d1-a705-413e-8282-a681c602a69083=1597611876893=N55=BTC-USD1682=full_trading268=10269=1278=f68e4659-5785-4ee9-ac24-3186640a2752270=1000.00271=3.10000000269=1278=38070d38-80a9-4898-8ef7-a0a9da5a4123270=1000.00271=3.10000000269=1278=e4d2d308-ed11-49db-850e-3cbd8258395d270=1000.00271=3.10000000269=1278=d6cfaadc-97ea-43c1-898d-40faea9c1477270=1000.00271=3.10000000269=1278=36876bea-9e3a-4018-b0ac-b75cb8c16953270=1000.00271=3.10000000269=1278=eb244bc5-49e8-4aa3-af8b-3d1a67c90a08270=1000.00271=3.10000000269=1278=3efba776-29ad-4aeb-82d8-0824f161471e270=1000.00271=3.10000000269=1278=de0ddebd-0ca8-4eca-9985-77c10c8629a9270=1000.00271=3.10000000269=1278=dde4408a-fb6b-441c-a7f3-7b8b23ffdb1f270=1000.00271=3.10000000269=1278=3ebd6434-070f-4b4d-8cf3-00368112466d270=1000.00271=3.1000000010=210
20250411-02:24:51.740857000 : 8=FIXT.1.19=14235=334=2049=24ab46f784d1b20db435b852086e325052=20250411-02:24:51.74056=Coinbase45=11758=Tag appears more than once371=269372=W373=1310=038
20250411-02:24:51.740942000 : 8=FIXT.1.19=93935=W49=Coinbase56=24ab46f784d1b20db435b852086e325034=11850=TEST52=20250411-02:24:51.464068369=2262=fabc71d1-a705-413e-8282-a681c602a69083=1597611876893=N55=BTC-USD1682=full_trading268=10269=1278=7aa98e13-65f3-4058-9f91-c1f452d02710270=1000.00271=3.10000000269=1278=e86a1fec-3610-460d-8d85-4e1e222ee159270=1000.00271=3.10000000269=1278=6dfac057-72b1-4f2c-b110-03766dea0d31270=1000.00271=3.10000000269=1278=bbb7d0ea-d251-4612-b53e-e528cc0a24ab270=1000.00271=3.10000000269=1278=0782ca37-48cf-4ff3-a74a-35674661586c270=1000.00271=3.10000000269=1278=aead437d-4b62-457f-ac83-62c7cc329fd1270=1000.00271=3.10000000269=1278=af5d47bc-a008-4567-b24f-b0298f250471270=1000.00271=3.10000000269=1278=4c260f58-c427-4a9a-969a-44024ae0c714270=1000.00271=3.10000000269=1278=8c7672e5-7ee8-4fbd-8fdf-7e74e9a77db7270=1000.00271=3.10000000269=1278=b53ec3cc-9abe-4570-b903-34d52148073e270=1000.00271=3.1000000010=239
20250411-02:24:51.741593000 : 8=FIXT.1.19=14235=334=2149=24ab46f784d1b20db435b852086e325052=20250411-02:24:51.74156=Coinbase45=11858=Tag appears more than once371=269372=W373=1310=041
20250411-02:24:51.742996000 : 8=FIXT.1.19=93935=W49=Coinbase56=24ab46f784d1b20db435b852086e325034=11950=TEST52=20250411-02:24:51.464318369=2262=fabc71d1-a705-413e-8282-a681c602a69083=1597611876893=N55=BTC-USD1682=full_trading268=10269=1278=37ce984a-0387-4ac9-9094-b83f722036ba270=1000.00271=3.10000000269=1278=0d383649-dc6c-4df2-b821-aa0018f132c7270=1000.00271=3.10000000269=1278=e39ae0ce-9e7f-4f0d-a765-5308d473bb61270=1000.00271=3.10000000269=1278=4882324e-3b5c-4b7a-b096-e8c6d9888671270=1000.00271=3.10000000269=1278=6e5c7dbd-a2cc-401f-a5b2-3902088f4ab2270=1000.00271=3.10000000269=1278=10ffac08-946a-4a30-b57a-0d78450345d9270=1000.00271=3.10000000269=1278=67784af5-72bf-4d16-a6b3-25336e2c1843270=1000.00271=3.10000000269=1278=4d8b3bbc-0dc2-4044-875c-c079ec538136270=1000.00271=3.10000000269=1278=dfba5f1e-21f5-48e3-adce-b8b6bfe71467270=1000.00271=3.10000000269=1278=e51b4e33-5eaa-46ef-936b-a74a890397e8270=1000.00271=3.1000000010=061
20250411-02:24:51.743758000 : 8=FIXT.1.19=14235=334=2249=24ab46f784d1b20db435b852086e325052=20250411-02:24:51.74356=Coinbase45=11958=Tag appears more than once371=269372=W373=1310=045
20250411-02:24:51.743864000 : 8=FIXT.1.19=93935=W49=Coinbase56=24ab46f784d1b20db435b852086e325034=12050=TEST52=20250411-02:24:51.464569369=2262=fabc71d1-a705-413e-8282-a681c602a69083=1597611876893=N55=BTC-USD1682=full_trading268=10269=1278=8cf5dfa8-858b-48a3-9d94-78522c257473270=1000.00271=3.10000000269=1278=a153b9d2-993d-4f03-a974-b8a081e128e8270=1000.00271=3.10000000269=1278=1eebe866-0f6e-4d4a-a28b-78f4e3368b0a270=1000.00271=3.10000000269=1278=300132d8-113f-4bf7-ba0c-4d93a272f55b270=1000.00271=3.10000000269=1278=757f3122-27d2-4f32-90b8-ead1eef9b936270=1000.00271=3.10000000269=1278=2b68b5de-4153-4cac-ace3-102e4fa788fd270=1000.00271=3.10000000269=1278=b01f252a-1657-4df0-a122-58a23109a7c2270=1000.00271=3.10000000269=1278=dbc57e4e-6abd-4d66-8d18-bd13caaa77b1270=1000.00271=3.10000000269=1278=948b05dc-a481-409f-b8ad-a502eb595906270=1000.00271=3.10000000269=1278=e00f9703-6e16-4237-a2c6-701829d11bf1270=1000.00271=3.1000000010=021
20250411-02:24:51.744725000 : 8=FIXT.1.19=14235=334=2349=24ab46f784d1b20db435b852086e325052=20250411-02:24:51.74456=Coinbase45=12058=Tag appears more than once371=269372=W373=1310=039
20250411-02:24:51.744822000 : 8=FIXT.1.19=93935=W49=Coinbase56=24ab46f784d1b20db435b852086e325034=12150=TEST52=20250411-02:24:51.464818369=2262=fabc71d1-a705-413e-8282-a681c602a69083=1597611876893=N55=BTC-USD1682=full_trading268=10269=1278=fd52f47a-3f11-47bc-9952-9708617d0ecd270=1000.00271=3.10000000269=1278=f7f75b14-27c3-469c-89fb-6a98b43c61bf270=1000.00271=3.10000000269=1278=25dbeb09-7901-4280-b0c3-720d7ed03d7d270=1000.00271=3.10000000269=1278=52164a1f-599f-4c43-a9ed-f93403506e67270=1000.00271=3.10000000269=1278=c71c35ea-f60f-4a41-b43a-4947bbcbafad270=1000.00271=3.10000000269=1278=2de342bc-a1be-46f3-9fc6-731297726934270=1000.00271=3.10000000269=1278=7ff4c5fc-bc9b-4845-940b-4837a672e13a270=1000.00271=3.10000000269=1278=2d270775-33eb-4328-8dad-7d206612f9f6270=1000.00271=3.10000000269=1278=c4754378-f787-4100-81af-564443a86a91270=1000.00271=3.10000000269=1278=59e16255-05eb-4fdc-8be1-3c4f83fc094e270=1000.00271=3.1000000010=118
20250411-02:24:51.745488000 : 8=FIXT.1.19=14235=334=2449=24ab46f784d1b20db435b852086e325052=20250411-02:24:51.74556=Coinbase45=12158=Tag appears more than once371=269372=W373=1310=042
20250411-02:24:51.745555000 : 8=FIXT.1.19=93935=W49=Coinbase56=24ab46f784d1b20db435b852086e325034=12250=TEST52=20250411-02:24:51.465068369=2262=fabc71d1-a705-413e-8282-a681c602a69083=1597611876893=N55=BTC-USD1682=full_trading268=10269=1278=041b2f98-1185-49cb-964a-f0456b71e692270=1000.00271=3.10000000269=1278=9a2f3529-481e-4e50-a123-7a2095fe6b2c270=1000.00271=3.10000000269=1278=9ed552a3-3295-4878-85dd-87b7b5590212270=1000.00271=3.10000000269=1278=54bec5c2-bafd-4d7d-851d-59e3553a053f270=1000.00271=3.10000000269=1278=543c1acf-52f2-442b-a893-f7aa9a5dfbd1270=1000.00271=3.10000000269=1278=fec999be-cbd0-42ef-b9c3-82ca92ef0b58270=1000.00271=3.10000000269=1278=24528176-3fc6-45b2-b2f3-9f784c01495a270=1000.00271=3.10000000269=1278=12081678-66a6-4435-a3d7-b65f959cf2ac270=1000.00271=3.10000000269=1278=e7fb6165-8f1a-4b5e-b095-e232b83ee951270=1000.00271=3.10000000269=1278=83ce6582-410a-40bf-9831-8f3d20e3a629270=1000.00271=3.1000000010=062
20250411-02:24:51.746384000 : 8=FIXT.1.19=14235=334=2549=24ab46f784d1b20db435b852086e325052=20250411-02:24:51.74556=Coinbase45=12258=Tag appears more than once371=269372=W373=1310=044
20250411-02:24:51.746480000 : 8=FIXT.1.19=93935=W49=Coinbase56=24ab46f784d1b20db435b852086e325034=12350=TEST52=20250411-02:24:51.465319369=2262=fabc71d1-a705-413e-8282-a681c602a69083=1597611876893=N55=BTC-USD1682=full_trading268=10269=1278=bc3a930b-0567-46ba-86a4-712f76466b0b270=1000.00271=3.10000000269=1278=15704973-f5ff-457d-ab31-8f99bb76bf7e270=1000.00271=3.10000000269=1278=7159045b-cbd5-458f-b91f-9fa5241b14b5270=1000.00271=3.10000000269=1278=9fa52a90-f03f-4940-b5ee-39ab937b86f1270=1000.00271=3.10000000269=1278=220f55cd-a279-4bf0-9c80-1dca086d85dc270=1000.00271=3.10000000269=1278=2b1eb468-6bcd-4117-a7c0-214d643ddad4270=1000.00271=3.10000000269=1278=cc23185d-e72e-42cb-8210-61bab29cd778270=1000.00271=3.10000000269=1278=69bb228b-973b-4176-8708-3231cc40102a270=1000.00271=3.10000000269=1278=2ec8035d-7962-4195-8388-c9fbad52ac8a270=1000.00271=3.10000000269=1278=7d39e416-0b7b-471f-a9ac-455ab1bce5a7270=1000.00271=3.1000000010=038
20250411-02:24:51.747277000 : 8=FIXT.1.19=14235=334=2649=24ab46f784d1b20db435b852086e325052=20250411-02:24:51.74656=Coinbase45=12358=Tag appears more than once371=269372=W373=1310=047
20250411-02:24:51.747365000 : 8=FIXT.1.19=93935=W49=Coinbase56=24ab46f784d1b20db435b852086e325034=12450=TEST52=20250411-02:24:51.465569369=2262=fabc71d1-a705-413e-8282-a681c602a69083=1597611876893=N55=BTC-USD1682=full_trading268=10269=1278=7067378d-2a65-41f2-acb0-ef30ddbc3e5a270=1000.00271=3.10000000269=1278=bf3fde78-6cff-4477-b381-4b5d2e68f36f270=1000.00271=3.10000000269=1278=93a2a8a3-61d4-410c-9446-8eabaafc5f29270=1000.00271=3.10000000269=1278=5afddb61-63ab-417b-a28a-41c4c03a6612270=1000.00271=3.10000000269=1278=a4280417-189c-4f76-9d2e-6ec652010bf5270=1000.00271=3.10000000269=1278=ddeb78a2-e110-4828-ba3d-c9b4837e7dd7270=1000.00271=3.10000000269=1278=fcec6c90-441a-4f4a-a94e-9003355657ef270=1000.00271=3.10000000269=1278=6db15389-dfb3-4156-8a4e-ce2ac80f2b15270=1000.00271=3.10000000269=1278=47dfefc3-6f05-4b57-8aec-2bf3e6c70c2d270=1000.00271=3.10000000269=1278=fb9fd019-4b4f-4880-82bb-3df6d1ef468a270=1000.00271=3.1000000010=099
20250411-02:24:51.748203000 : 8=FIXT.1.19=14235=334=2749=24ab46f784d1b20db435b852086e325052=20250411-02:24:51.74756=Coinbase45=12458=Tag appears more than once371=269372=W373=1310=050
20250411-02:24:51.748322000 : 8=FIXT.1.19=93935=W49=Coinbase56=24ab46f784d1b20db435b852086e325034=12550=TEST52=20250411-02:24:51.465819369=2262=fabc71d1-a705-413e-8282-a681c602a69083=1597611876893=N55=BTC-USD1682=full_trading268=10269=1278=2cff9acd-42cb-43a5-8d50-51e676b7e763270=1000.00271=3.10000000269=1278=6e6eeb59-4728-4811-9a44-c857df6aca42270=1000.00271=3.10000000269=1278=81798560-263f-4819-a528-5f3fbbc7b042270=1000.00271=3.10000000269=1278=81fbf9a8-82f4-4fe4-9fa5-3773b212ebf4270=1000.00271=3.10000000269=1278=5d3b9566-276d-47fe-a111-12c17f53f501270=1000.00271=3.10000000269=1278=8eb1b3b3-c813-48b1-b839-993672108d91270=1000.00271=3.10000000269=1278=4feb6e93-6149-481b-8d58-e1c8e6c5cda1270=1000.00271=3.10000000269=1278=f8611e72-4056-4b7c-9779-4d54cd151d44270=1000.00271=3.10000000269=1278=7a129f7c-d9ba-4ea3-a267-b7d82b2e07d9270=1000.00271=3.10000000269=1278=01f359f0-c38f-416b-af00-183907218793270=1000.00271=3.1000000010=117
20250411-02:24:51.749112000 : 8=FIXT.1.19=14235=334=2849=24ab46f784d1b20db435b852086e325052=20250411-02:24:51.74856=Coinbase45=12558=Tag appears more than once371=269372=W373=1310=053
20250411-02:24:51.749210000 : 8=FIXT.1.19=93935=W49=Coinbase56=24ab46f784d1b20db435b852086e325034=12650=TEST52=20250411-02:24:51.466069369=2262=fabc71d1-a705-413e-8282-a681c602a69083=1597611876893=N55=BTC-USD1682=full_trading268=10269=1278=11741cec-9c08-4a20-99dc-6b9f63130b0e270=1000.00271=3.10000000269=1278=08db2574-ad52-4520-ab5b-c3c7591eb781270=1000.00271=3.10000000269=1278=b06f2249-179c-4a15-8e98-7b76083b808b270=1000.00271=3.10000000269=1278=9e88fede-6d19-4c1f-863b-5a7d66781436270=1000.00271=3.10000000269=1278=75e1d8b4-7201-41fe-a687-7d93420af323270=1000.00271=3.10000000269=1278=d00aa7dd-ce7f-4f8b-9a2e-880c1ea30845270=1000.00271=3.10000000269=1278=584a483f-23bf-4d8b-809f-69cf3c110f60270=1000.00271=3.10000000269=1278=dc98524e-27e2-4863-99e4-7a0097a6ee90270=1000.00271=3.10000000269=1278=82a11ac9-4f46-44b7-a0bc-a5a4cfe686e0270=1000.00271=3.10000000269=1278=f946bb05-900c-41fc-9908-41489e97ff20270=1000.00271=3.1000000010=030
20250411-02:24:51.749900000 : 8=FIXT.1.19=14235=334=2949=24ab46f784d1b20db435b852086e325052=20250411-02:24:51.74956=Coinbase45=12658=Tag appears more than once371=269372=W373=1310=056
20250411-02:24:51.749994000 : 8=FIXT.1.19=93935=W49=Coinbase56=24ab46f784d1b20db435b852086e325034=12750=TEST52=20250411-02:24:51.466319369=2262=fabc71d1-a705-413e-8282-a681c602a69083=1597611876893=N55=BTC-USD1682=full_trading268=10269=1278=1f9186d6-0312-4677-ba96-fdb014cdff2c270=1000.00271=3.10000000269=1278=c3b67be7-2b63-4884-b311-80f28496c2c4270=1000.00271=3.10000000269=1278=6576c7f8-a4e2-4417-b854-5fef0e705fbe270=1000.00271=3.10000000269=1278=c2102c71-62f0-4eee-ae60-0777ed26a8e6270=1000.00271=3.10000000269=1278=c823a2b6-849e-4839-a2fd-cd9f459cae6c270=1000.00271=3.10000000269=1278=a051e195-4472-4a8a-8591-08a2c04a33c4270=1000.00271=3.10000000269=1278=ec81b8c4-b703-4afd-a701-ce34011f60f6270=1000.00271=3.10000000269=1278=b1172677-f493-4f32-a200-0710cf8c397f270=1000.00271=3.10000000269=1278=b1a58a75-5fca-43db-b9c6-a26920e8f66e270=1000.00271=3.10000000269=1278=038bea41-b91d-4884-b992-3e5431ef9857270=1000.00271=3.1000000010=130
20250411-02:24:51.750622000 : 8=FIXT.1.19=14235=334=3049=24ab46f784d1b20db435b852086e325052=20250411-02:24:51.75056=Coinbase45=12758=Tag appears more than once371=269372=W373=1310=041
20250411-02:24:51.750710000 : 8=FIXT.1.19=93935=W49=Coinbase56=24ab46f784d1b20db435b852086e325034=12850=TEST52=20250411-02:24:51.466569369=2262=fabc71d1-a705-413e-8282-a681c602a69083=1597611876893=N55=BTC-USD1682=full_trading268=10269=1278=55063782-f2ea-4c84-9491-8e8e89d1dfd1270=1000.00271=3.10000000269=1278=bb2011e8-d05d-40ac-9e9c-3b720422e38d270=1000.00271=3.10000000269=1278=64dd3b4a-ce8a-4b63-9937-266e832c0f21270=1000.00271=3.10000000269=1278=d64f7d2a-aa83-486c-92a8-3314c4eddd58270=1000.00271=3.10000000269=1278=0df9641b-d89d-4222-a8ea-bcddf0d555f5270=1000.00271=3.10000000269=1278=7a315b16-a05f-408d-b8c1-2704af9bf767270=1000.00271=3.10000000269=1278=0e9712a8-d00f-4864-a478-f7f591718f91270=1000.00271=3.10000000269=1278=94db025d-eada-49e3-b13c-b667ca07f829270=1000.00271=3.10000000269=1278=a88ccd1f-8f8d-46af-8fb6-20adba35f7d1270=1000.00271=3.10000000269=1278=99d4e235-c8ec-4efc-938c-9a1923eafc96270=1000.00271=3.1000000010=089
20250411-02:24:51.751331000 : 8=FIXT.1.19=14235=334=3149=24ab46f784d1b20db435b852086e325052=20250411-02:24:51.75156=Coinbase45=12858=Tag appears more than once371=269372=W373=1310=044
20250411-02:24:51.751411000 : 8=FIXT.1.19=93935=W49=Coinbase56=24ab46f784d1b20db435b852086e325034=12950=TEST52=20250411-02:24:51.466820369=2262=fabc71d1-a705-413e-8282-a681c602a69083=1597611876893=N55=BTC-USD1682=full_trading268=10269=1278=a4fc7173-7583-4f8b-b256-2921bef83c84270=1000.00271=3.10000000269=1278=18f8afd4-8bbc-4ffa-8e8f-0c1834d74472270=1000.00271=3.10000000269=1278=21fc8cb6-f894-4d09-884e-810b8ebf2ef3270=1000.00271=3.10000000269=1278=0c13b9e6-6797-4b3e-90ce-a1885b26ba53270=1000.00271=3.10000000269=1278=6d8da581-3998-4fc0-99b6-3c5edbd514cb270=1000.00271=3.10000000269=1278=67a70307-be50-4065-872b-47e0de473bc4270=1000.00271=3.10000000269=1278=8ce7be0b-98de-46d0-b1b6-307a4bec36e2270=1000.00271=3.10000000269=1278=856b22f8-5884-4739-adc0-bdd851c5c07d270=1000.00271=3.10000000269=1278=c00ae651-a76b-4bfd-be16-3672b345fe29270=1000.00271=3.10000000269=1278=cae248f9-16fc-44ea-9b79-1dacfc285db6270=1000.00271=3.1000000010=086
20250411-02:24:51.751889000 : 8=FIXT.1.19=14235=334=3249=24ab46f784d1b20db435b852086e325052=20250411-02:24:51.75156=Coinbase45=12958=Tag appears more than once371=269372=W373=1310=046
20250411-02:24:51.751978000 : 8=FIXT.1.19=93935=W49=Coinbase56=24ab46f784d1b20db435b852086e325034=13050=TEST52=20250411-02:24:51.467069369=2262=fabc71d1-a705-413e-8282-a681c602a69083=1597611876893=N55=BTC-USD1682=full_trading268=10269=1278=42bb223c-88c6-4a18-8ff3-4fd8d9efda8d270=1000.00271=3.10000000269=1278=d7188b01-22b6-4837-a720-077601f7f483270=1000.00271=3.10000000269=1278=5d85a0a6-ddd9-4e0e-9a1a-7f418ef588e5270=1000.00271=3.10000000269=1278=bff4c39f-7a80-42ce-a178-b1221792e445270=1000.00271=3.10000000269=1278=9ea3d263-b5ab-46c5-bf27-8c0e3e0e5e9e270=1000.00271=3.10000000269=1278=b93347df-d2ab-48ec-b326-4454e64f1d4e270=1000.00271=3.10000000269=1278=57acc40d-8478-444a-990f-067a8e8e846e270=1000.00271=3.10000000269=1278=34419ae2-2c16-427b-a290-845419760fd5270=1000.00271=3.10000000269=1278=ab41de2d-5def-4986-b56e-243d2f99a57c270=1000.00271=3.10000000269=1278=9025524c-03a9-407a-a58a-5258c4ea0a0b270=1000.00271=3.1000000010=094
20250411-02:24:51.752840000 : 8=FIXT.1.19=14235=334=3349=24ab46f784d1b20db435b852086e325052=20250411-02:24:51.75256=Coinbase45=13058=Tag appears more than once371=269372=W373=1310=040
20250411-02:24:51.752921000 : 8=FIXT.1.19=93935=W49=Coinbase56=24ab46f784d1b20db435b852086e325034=13150=TEST52=20250411-02:24:51.467319369=2262=fabc71d1-a705-413e-8282-a681c602a69083=1597611876893=N55=BTC-USD1682=full_trading268=10269=1278=60766318-112b-4d83-a384-55693de75519270=1000.00271=3.10000000269=1278=c19b6a2c-086b-4fc1-8dfe-51cb2dc12c1d270=1000.00271=3.10000000269=1278=11126433-0f9c-4450-a35a-39b878e85e68270=1000.00271=3.10000000269=1278=e2e620ee-44fb-4630-a890-d331ba5b2fae270=1000.00271=3.10000000269=1278=9ccf6d4b-a6ca-4a1f-a7bb-77f400ace0c8270=1000.00271=3.10000000269=1278=0e8d6c10-8421-4f19-97dc-d70e715d9033270=1000.00271=3.10000000269=1278=f31ecd5d-8231-44ea-a5c2-0fcc5a699401270=1000.00271=3.10000000269=1278=37fbb559-dc52-48fe-ab65-24910edc338a270=1000.00271=3.10000000269=1278=bc1435c5-c59c-4017-9e59-f1073f04c7e2270=1000.00271=3.10000000269=1278=9c8e1397-0cee-4b05-a66f-5594040791c4270=1000.00271=3.1000000010=227
20250411-02:24:51.753800000 : 8=FIXT.1.19=14235=334=3449=24ab46f784d1b20db435b852086e325052=20250411-02:24:51.75356=Coinbase45=13158=Tag appears more than once371=269372=W373=1310=043
20250411-02:24:51.753904000 : 8=FIXT.1.19=93935=W49=Coinbase56=24ab46f784d1b20db435b852086e325034=13250=TEST52=20250411-02:24:51.467569369=2262=fabc71d1-a705-413e-8282-a681c602a69083=1597611876893=N55=BTC-USD1682=full_trading268=10269=1278=248b6703-f829-42bb-a551-4be3075c381e270=1000.00271=3.10000000269=1278=16d257b0-bc92-44f0-822d-3eba61af4bda270=1000.00271=3.10000000269=1278=06257aa1-4043-4cdb-9286-4342b8e59108270=1000.00271=3.10000000269=1278=210ec210-1443-47dc-9e43-9c9ea720a6c3270=1000.00271=3.10000000269=1278=8b79da5d-b78c-4011-b55f-b35c16dc3724270=1000.00271=3.10000000269=1278=076c3703-1104-4e15-a38a-d95bf133f0c5270=1000.00271=3.10000000269=1278=f5a3155c-e449-4102-870d-ab8c8dd24c3d270=1000.00271=3.10000000269=1278=1af2681f-2dec-4d25-aaeb-89b8867b4a3c270=1000.00271=3.10000000269=1278=65c3088d-192a-4213-85a3-7257aa8b20a3270=1000.00271=3.10000000269=1278=2aa7989b-5601-4899-8143-01dda3255e4f270=1000.00271=3.1000000010=212
20250411-02:24:51.754605000 : 8=FIXT.1.19=14235=334=3549=24ab46f784d1b20db435b852086e325052=20250411-02:24:51.75456=Coinbase45=13258=Tag appears more than once371=269372=W373=1310=046
20250411-02:24:51.754690000 : 8=FIXT.1.19=93935=W49=Coinbase56=24ab46f784d1b20db435b852086e325034=13350=TEST52=20250411-02:24:51.467819369=2262=fabc71d1-a705-413e-8282-a681c602a69083=1597611876893=N55=BTC-USD1682=full_trading268=10269=1278=099b432c-fa2e-4fd7-952e-22f6debf6877270=1000.00271=3.10000000269=1278=2e71cc31-1235-4b7b-a728-e3335631fe5a270=1000.00271=3.10000000269=1278=ce471ffc-1e26-4afe-afab-27ee5ac8debe270=1000.00271=3.10000000269=1278=113b7fc6-8574-40eb-8682-d077245b84f2270=1000.00271=3.10000000269=1278=bcebce2c-eda8-4b85-841d-27ede39fc5a1270=1000.00271=3.10000000269=1278=0aedaae5-6cc6-4a34-8e48-5e67a5ccc148270=1000.00271=3.10000000269=1278=206e10a5-1173-4860-87b5-7c88afe061f6270=1000.00271=3.10000000269=1278=5c32d94b-696a-4d9b-afa0-665970356008270=1000.00271=3.10000000269=1278=0b7da819-cc1e-4525-a382-ce5b90dc485c270=1000.00271=3.10000000269=1278=2241b3bf-cbbe-44f2-ac75-8032f6283aa8270=1000.00271=3.1000000010=161
20250411-02:24:51.755459000 : 8=FIXT.1.19=14235=334=3649=24ab46f784d1b20db435b852086e325052=20250411-02:24:51.75556=Coinbase45=13358=Tag appears more than once371=269372=W373=1310=049
20250411-02:24:51.755548000 : 8=FIXT.1.19=93935=W49=Coinbase56=24ab46f784d1b20db435b852086e325034=13450=TEST52=20250411-02:24:51.468069369=2262=fabc71d1-a705-413e-8282-a681c602a69083=1597611876893=N55=BTC-USD1682=full_trading268=10269=1278=88cada69-adb1-466a-afcd-66e063ad27c0270=1000.00271=3.10000000269=1278=34a52ef5-31c1-4c63-9230-21c85a9a6ba3270=1000.00271=3.10000000269=1278=e109c2c8-fb1d-4ef9-a640-368381323507270=1000.00271=3.10000000269=1278=38fd36c4-4c62-4b4c-8f24-1fe39be94fa1270=1000.00271=3.10000000269=1278=f83f64c8-7d33-472d-a516-9b664ff9c966270=1000.00271=3.10000000269=1278=3411c368-380b-42e6-b656-8552d92904d5270=1000.00271=3.10000000269=1278=4803796e-79f3-4aa4-a8cb-37f13899bf01270=1000.00271=3.10000000269=1278=823f8fbf-7e6d-4ae3-adb9-3a822ff6d09a270=1000.00271=3.10000000269=1278=135624df-a204-490f-a68b-63d74ee09908270=1000.00271=3.10000000269=1278=47cfdedf-22b9-402c-93bd-f311103fd3e0270=1000.00271=3.1000000010=246
20250411-02:24:51.756413000 : 8=FIXT.1.19=14235=334=3749=24ab46f784d1b20db435b852086e325052=20250411-02:24:51.75556=Coinbase45=13458=Tag appears more than once371=269372=W373=1310=051
20250411-02:24:51.756518000 : 8=FIXT.1.19=93935=W49=Coinbase56=24ab46f784d1b20db435b852086e325034=13550=TEST52=20250411-02:24:51.468320369=2262=fabc71d1-a705-413e-8282-a681c602a69083=1597611876893=N55=BTC-USD1682=full_trading268=10269=1278=f9173d5e-d872-4661-93f6-28f527e931f7270=1000.00271=3.10000000269=1278=06ab1365-fd39-4701-bd7f-1915ad3c7602270=1000.00271=3.10000000269=1278=012a7c59-5ae4-4da5-97ba-2e3254c889fb270=1000.00271=3.10000000269=1278=a9a0d42f-ad9e-4ea9-8bf0-d5a441fded40270=1000.00271=3.10000000269=1278=f3f3930e-be0e-40b4-a97d-d19501a54885270=1000.00271=3.10000000269=1278=261922d0-5c81-4ab6-832f-4eff45f64890270=1000.00271=3.10000000269=1278=3af4e45f-56f6-4c69-894d-d56a14894a98270=1000.00271=3.10000000269=1278=1c1dd248-49e4-44aa-9e69-323b0f41fa0e270=1000.00271=3.10000000269=1278=b16b002d-1cd6-4869-9c1b-f15c758611bf270=1000.00271=3.10000000269=1278=a0520e61-28ad-448d-87c1-49f0c7358628270=1000.00271=3.1000000010=016
20250411-02:24:51.757359000 : 8=FIXT.1.19=14235=334=3849=24ab46f784d1b20db435b852086e325052=20250411-02:24:51.75656=Coinbase45=13558=Tag appears more than once371=269372=W373=1310=054
20250411-02:24:51.757453000 : 8=FIXT.1.19=93935=W49=Coinbase56=24ab46f784d1b20db435b852086e325034=13650=TEST52=20250411-02:24:51.468570369=2262=fabc71d1-a705-413e-8282-a681c602a69083=1597611876893=N55=BTC-USD1682=full_trading268=10269=1278=152d0b57-086f-48cc-80b3-ff14ee9375ed270=1000.00271=3.10000000269=1278=c55fc264-67d2-4e9c-8cce-6c834feff648270=1000.00271=3.10000000269=1278=27361968-189a-4fa6-a3a2-eead03c640d6270=1000.00271=3.10000000269=1278=f5b01c67-f98f-44b9-a511-7f07f8883d9e270=1000.00271=3.10000000269=1278=75a5c14f-8434-4533-a10e-0bf6e92e1000270=1000.00271=3.10000000269=1278=a9b0a826-3659-4105-9ecc-21bcd27b736f270=1000.00271=3.10000000269=1278=1b1bab77-5c52-459b-98e3-e27ff6f8cd04270=1000.00271=3.10000000269=1278=346695f1-fe03-4364-8fc5-006796c8f82f270=1000.00271=3.10000000269=1278=cbbaa36d-2a03-45a2-a230-bd5845d832cd270=1000.00271=3.10000000269=1278=745d4fc0-6710-4c5c-97c3-7b29c4e06839270=1000.00271=3.1000000010=215
20250411-02:24:51.758265000 : 8=FIXT.1.19=14235=334=3949=24ab46f784d1b20db435b852086e325052=20250411-02:24:51.75756=Coinbase45=13658=Tag appears more than once371=269372=W373=1310=057
20250411-02:24:51.962163000 : 8=FIXT.1.19=93935=W49=Coinbase56=24ab46f784d1b20db435b852086e325034=13750=TEST52=20250411-02:24:51.468821369=2262=fabc71d1-a705-413e-8282-a681c602a69083=1597611876893=N55=BTC-USD1682=full_trading268=10269=1278=e95fdfba-5db2-4461-8e9c-7bfdf8a9238c270=1000.00271=3.10000000269=1278=33611b39-1fbf-45cc-bf5e-a02bc1f84736270=1000.00271=3.10000000269=1278=51f77b2d-1a69-432d-934b-234eb9e1dfac270=1000.00271=3.10000000269=1278=ab09fdc3-8d50-432f-ab0f-97e8627eac24270=1000.00271=3.10000000269=1278=dde04213-6104-44c5-a811-15834c27b515270=1000.00271=3.10000000269=1278=9af2b85c-4997-4e1b-9147-7d400f059b01270=1000.00271=3.10000000269=1278=40870860-7a8a-4419-a117-e511f779abfa270=1000.00271=3.10000000269=1278=3e8fa7bd-dde0-4fe4-bb2e-e6279841b019270=1000.00271=3.10000000269=1278=4dde1422-98d8-405b-88df-bf245291ad7a270=1000.00271=3.10000000269=1278=6ee8b5a8-bc2f-4a0a-9ae4-7ff1b5dae941270=1000.00271=3.1000000010=017
20250411-02:24:51.963280000 : 8=FIXT.1.19=14235=334=4049=24ab46f784d1b20db435b852086e325052=20250411-02:24:51.96256=Coinbase45=13758=Tag appears more than once371=269372=W373=1310=048
20250411-02:24:51.963428000 : 8=FIXT.1.19=93935=W49=Coinbase56=24ab46f784d1b20db435b852086e325034=13850=TEST52=20250411-02:24:51.469070369=2262=fabc71d1-a705-413e-8282-a681c602a69083=1597611876893=N55=BTC-USD1682=full_trading268=10269=1278=3ebc1f7a-2bb5-4ef0-a82f-844b9540f6e8270=1000.00271=3.10000000269=1278=a82d5bb9-1f1a-4575-b580-8d9b60863b10270=1000.00271=3.10000000269=1278=14f89bd5-0233-435c-b608-2e19131b8f6c270=1000.00271=3.10000000269=1278=a2e319e5-aab7-41d4-9d19-98d771a3f1d3270=1000.00271=3.10000000269=1278=dc965e0b-075a-4ba4-a498-02c96d1664ba270=1000.00271=3.10000000269=1278=67b6e68f-ac11-4c05-a54a-2adb555b0123270=1000.00271=3.10000000269=1278=866f52a1-dad9-49d7-ac4a-9da3075407a3270=1000.00271=3.10000000269=1278=0e38234d-a010-40f6-9c6f-a0d574e773cf270=1000.00271=3.10000000269=1278=d6af6749-e3c8-4938-8741-1d5f177cf8e1270=1000.00271=3.10000000269=1278=45ff5e59-2c4d-45ac-9fde-403662dfd1ca270=1000.00271=3.1000000010=144
20250411-02:24:51.964089000 : 8=FIXT.1.19=14235=334=4149=24ab46f784d1b20db435b852086e325052=20250411-02:24:51.96356=Coinbase45=13858=Tag appears more than once371=269372=W373=1310=051
20250411-02:24:51.964244000 : 8=FIXT.1.19=94535=W49=Coinbase56=24ab46f784d1b20db435b852086e325034=13950=TEST52=20250411-02:24:51.469320369=2262=fabc71d1-a705-413e-8282-a681c602a69083=1597611876893=N55=BTC-USD1682=full_trading268=10269=1278=dcac314e-c54f-44e3-b96d-ef71539766ed270=1000.00271=3.10000000269=1278=dd6d14ea-760f-4884-a546-1d3c40ebdd7c270=1000.00271=3.10000000269=1278=4f3da0c6-46eb-4b64-b973-cc43e24abccb270=1000.00271=3.10000000269=1278=aa40cda8-4abd-4f52-999a-1a90ed5bf41a270=1000.00271=3.10000000269=1278=687ee4fc-f626-4e4f-abee-1f0ee5af3f72270=1000.00271=3.10000000269=1278=b1ad1135-67ec-4c96-99cb-a626137f3f16270=10000.00271=1.00000000269=1278=e9320f5f-80ae-41ab-af7a-86518d456fb0270=10000.00271=1.00000000269=1278=cd95aff0-36fa-4804-887f-2c3fce3cdc86270=10000.00271=1.00000000269=1278=fbdbcee1-8c29-4478-97df-358d209d8808270=10000.00271=1.00000000269=1278=140f39da-834b-4e42-8e15-6e25287df1f0270=900000.00271=0.0001111110=198
20250411-02:24:51.964837000 : 8=FIXT.1.19=14235=334=4249=24ab46f784d1b20db435b852086e325052=20250411-02:24:51.96456=Coinbase45=13958=Tag appears more than once371=269372=W373=1310=054
20250411-02:24:51.964947000 : 8=FIXT.1.19=95935=W49=Coinbase56=24ab46f784d1b20db435b852086e325034=14050=TEST52=20250411-02:24:51.469570369=2262=fabc71d1-a705-413e-8282-a681c602a69083=1597611876893=N55=BTC-USD1682=full_trading268=10269=1278=49f064c5-76fe-4b38-bede-48b60a0a5aec270=900000.00271=0.00011111269=1278=681cf73b-9d37-4101-b940-9da9b1ff61ed270=900000.00271=0.00011111269=1278=3dea1587-e474-4258-b6e8-485c21b56670270=900000.00271=0.00011111269=1278=afd96a7b-3d48-459e-b810-e4ee88353a31270=900000.00271=0.00011111269=1278=a68ae029-b920-4ae7-a775-ccdb800fc252270=900000.00271=0.00001111269=1278=d44508b7-1c9f-4b4f-acb8-99c93d2b99e8270=900000.00271=0.00001111269=1278=304ff106-de40-4381-89c5-c93f7f3e32ae270=900000.00271=0.00001111269=1278=08a0fef8-fcbb-4857-8463-2599cf331386270=900000.00271=0.00011111269=1278=07b2856d-f899-417c-82d5-886f0d85125e270=900000.00271=0.00011111269=1278=12ecb45e-6af8-4804-a942-5c997b9d1502270=900000.00271=0.0001111110=031
20250411-02:24:51.965554000 : 8=FIXT.1.19=14235=334=4349=24ab46f784d1b20db435b852086e325052=20250411-02:24:51.96556=Coinbase45=14058=Tag appears more than once371=269372=W373=1310=048
20250411-02:24:51.965625000 : 8=FIXT.1.19=81035=W49=Coinbase56=24ab46f784d1b20db435b852086e325034=14150=TEST52=20250411-02:24:51.469820369=2262=fabc71d1-a705-413e-8282-a681c602a69083=1597611876893=Y55=BTC-USD1682=full_trading268=8269=1278=98676c5f-b851-473c-817a-b29243092a25270=900000.00271=0.00001111269=1278=09afe685-e71f-4ea0-b164-c27737db126d270=900000.00271=0.00001111269=1278=e71ee98f-c329-428d-9893-629b53015ff6270=900000.00271=0.00001111269=1278=124e6fc1-6dde-452b-be03-c00113c8ebdb270=900000.00271=0.00011111269=1278=b71cc7f5-d7c6-4fc0-a0de-59b0eb7fd063270=1000000.00271=1.00000000269=1278=afec127b-a98c-49cb-893f-e385a7e35d32270=1000000.00271=1.00000000269=1278=06df7c57-366d-4d2c-acc2-e6c26d60e9c3270=1000000.00271=1.00000000269=1278=b1c4eb2b-90df-44e0-ae4f-515df4086a9d270=9999999.00271=0.0000100010=177
20250411-02:24:51.966189000 : 8=FIXT.1.19=14235=334=4449=24ab46f784d1b20db435b852086e325052=20250411-02:24:51.96556=Coinbase45=14158=Tag appears more than once371=269372=W373=1310=050
20250411-02:24:51.966321000 : 8=FIXT.1.19=28335=X49=Coinbase56=24ab46f784d1b20db435b852086e325034=14250=TEST52=20250411-02:24:51.556511369=2262=fabc71d1-a705-413e-8282-a681c602a690268=1279=0269=083=159761187755=BTC-USD270=3.89271=0.6197183160=20250411-02:24:51.55499540=237=4f550112-facb-4e60-a1b7-79e311c42be510=239
20250411-02:24:51.967750000 : 8=FIXT.1.19=32635=X49=Coinbase56=24ab46f784d1b20db435b852086e325034=14350=TEST52=20250411-02:24:51.556525369=2262=fabc71d1-a705-413e-8282-a681c602a690268=1279=0269=2278=c5b88ea9-605d-4595-ac52-f7c3f08523ba83=159761187855=BTC-USD270=3.55271=0.6197183160=20250411-02:24:51.55499537=4f550112-facb-4e60-a1b7-79e311c42be55797=110=193
20250411-02:24:51.967977000 : 8=FIXT.1.19=28935=X49=Coinbase56=24ab46f784d1b20db435b852086e325034=14450=TEST52=20250411-02:24:51.556530369=2262=fabc71d1-a705-413e-8282-a681c602a690268=1279=2269=0278=4f550112-facb-4e60-a1b7-79e311c42be583=159761187955=BTC-USD270=3.89271=0.0000000060=20250411-02:24:51.55499558=FILLED10=150
20250411-02:24:51.968443000 : 8=FIXT.1.19=28335=X49=Coinbase56=24ab46f784d1b20db435b852086e325034=14550=TEST52=20250411-02:24:51.612675369=2262=fabc71d1-a705-413e-8282-a681c602a690268=1279=0269=183=159761188055=BTC-USD270=3.35271=0.6197183160=20250411-02:24:51.61076040=237=67d65264-fa72-4350-b873-3a6acabc5a6710=185
20250411-02:24:51.968631000 : 8=FIXT.1.19=32635=X49=Coinbase56=24ab46f784d1b20db435b852086e325034=14650=TEST52=20250411-02:24:51.612687369=2262=fabc71d1-a705-413e-8282-a681c602a690268=1279=0269=2278=24de32b2-a7f5-469c-a714-c9b10ee2cce583=159761188155=BTC-USD270=3.54271=0.6197183160=20250411-02:24:51.61076037=67d65264-fa72-4350-b873-3a6acabc5a675797=210=226
20250411-02:24:51.968826000 : 8=FIXT.1.19=28935=X49=Coinbase56=24ab46f784d1b20db435b852086e325034=14750=TEST52=20250411-02:24:51.612708369=2262=fabc71d1-a705-413e-8282-a681c602a690268=1279=2269=1278=67d65264-fa72-4350-b873-3a6acabc5a6783=159761188255=BTC-USD270=3.35271=0.0000000060=20250411-02:24:51.61076058=FILLED10=092
20250411-02:24:52.134806000 : 8=FIXT.1.19=27935=X49=Coinbase56=24ab46f784d1b20db435b852086e325034=14850=TEST52=20250411-02:24:52.085349369=39262=fabc71d1-a705-413e-8282-a681c602a690268=1279=0269=083=159761188355=BTC-USD29004=2.208895519560=20250411-02:24:52.08374740=137=f030c2b1-2828-49c5-935f-42d2023ee63610=172
20250411-02:24:52.135225000 : 8=FIXT.1.19=32735=X49=Coinbase56=24ab46f784d1b20db435b852086e325034=14950=TEST52=20250411-02:24:52.085367369=39262=fabc71d1-a705-413e-8282-a681c602a690268=1279=0269=2278=c5b88ea9-605d-4595-ac52-f7c3f08523ba83=159761188455=BTC-USD270=3.55271=0.6222240960=20250411-02:24:52.08374737=f030c2b1-2828-49c5-935f-42d2023ee6365797=110=063
20250411-02:24:52.135539000 : 8=FIXT.1.19=26635=X49=Coinbase56=24ab46f784d1b20db435b852086e325034=15050=TEST52=20250411-02:24:52.085373369=39262=fabc71d1-a705-413e-8282-a681c602a690268=1279=2269=0278=f030c2b1-2828-49c5-935f-42d2023ee63683=159761188555=BTC-USD60=20250411-02:24:52.08374758=FILLED10=176
20250411-02:24:52.163548000 : 8=FIXT.1.19=27535=X49=Coinbase56=24ab46f784d1b20db435b852086e325034=15150=TEST52=20250411-02:24:52.114696369=39262=fabc71d1-a705-413e-8282-a681c602a690268=1279=0269=183=159761188655=BTC-USD271=0.6214689360=20250411-02:24:52.11302840=137=0cc311d0-7263-442a-8f51-6050cc383f2510=179
20250411-02:24:52.164730000 : 8=FIXT.1.19=32735=X49=Coinbase56=24ab46f784d1b20db435b852086e325034=15250=TEST52=20250411-02:24:52.114706369=39262=fabc71d1-a705-413e-8282-a681c602a690268=1279=0269=2278=24de32b2-a7f5-469c-a714-c9b10ee2cce583=159761188755=BTC-USD270=3.54271=0.6214689360=20250411-02:24:52.11302837=0cc311d0-7263-442a-8f51-6050cc383f255797=210=114
20250411-02:24:52.165024000 : 8=FIXT.1.19=28135=X49=Coinbase56=24ab46f784d1b20db435b852086e325034=15350=TEST52=20250411-02:24:52.114711369=39262=fabc71d1-a705-413e-8282-a681c602a690268=1279=2269=1278=0cc311d0-7263-442a-8f51-6050cc383f2583=159761188855=BTC-USD271=0.0000000060=20250411-02:24:52.11302858=FILLED10=066
20250411-02:24:53.208342000 : 8=FIXT.1.19=28435=X49=Coinbase56=24ab46f784d1b20db435b852086e325034=15450=TEST52=20250411-02:24:53.156685369=44262=fabc71d1-a705-413e-8282-a681c602a690268=1279=0269=183=159761188955=BTC-USD270=3.21271=0.6214689360=20250411-02:24:53.15549140=237=665ec373-8efb-446e-9429-c7732e2b443310=184
20250411-02:24:53.212186000 : 8=FIXT.1.19=32735=X49=Coinbase56=24ab46f784d1b20db435b852086e325034=15550=TEST52=20250411-02:24:53.156762369=44262=fabc71d1-a705-413e-8282-a681c602a690268=1279=0269=2278=24de32b2-a7f5-469c-a714-c9b10ee2cce583=159761189055=BTC-USD270=3.54271=0.6214689360=20250411-02:24:53.15549137=665ec373-8efb-446e-9429-c7732e2b44335797=210=214
20250411-02:24:53.217311000 : 8=FIXT.1.19=29035=X49=Coinbase56=24ab46f784d1b20db435b852086e325034=15650=TEST52=20250411-02:24:53.156770369=44262=fabc71d1-a705-413e-8282-a681c602a690268=1279=2269=1278=665ec373-8efb-446e-9429-c7732e2b443383=159761189155=BTC-USD270=3.21271=0.0000000060=20250411-02:24:53.15549158=FILLED10=068
20250411-02:24:53.260971000 : 8=FIXT.1.19=28435=X49=Coinbase56=24ab46f784d1b20db435b852086e325034=15750=TEST52=20250411-02:24:53.211684369=44262=fabc71d1-a705-413e-8282-a681c602a690268=1279=0269=083=159761189255=BTC-USD270=3.83271=0.6214689360=20250411-02:24:53.20983840=237=4807c81c-b0a4-41c0-80a3-8adf5b93450b10=243
20250411-02:24:53.261391000 : 8=FIXT.1.19=32735=X49=Coinbase56=24ab46f784d1b20db435b852086e325034=15850=TEST52=20250411-02:24:53.211694369=44262=fabc71d1-a705-413e-8282-a681c602a690268=1279=0269=2278=c5b88ea9-605d-4595-ac52-f7c3f08523ba83=159761189355=BTC-USD270=3.55271=0.6214689360=20250411-02:24:53.20983837=4807c81c-b0a4-41c0-80a3-8adf5b93450b5797=110=199
20250411-02:24:53.261641000 : 8=FIXT.1.19=29035=X49=Coinbase56=24ab46f784d1b20db435b852086e325034=15950=TEST52=20250411-02:24:53.211700369=44262=fabc71d1-a705-413e-8282-a681c602a690268=1279=2269=0278=4807c81c-b0a4-41c0-80a3-8adf5b93450b83=159761189455=BTC-USD270=3.83271=0.0000000060=20250411-02:24:53.20983858=FILLED10=130
20250411-02:24:53.448663000 : 8=FIXT.1.19=27935=X49=Coinbase56=24ab46f784d1b20db435b852086e325034=16050=TEST52=20250411-02:24:53.399520369=44262=fabc71d1-a705-413e-8282-a681c602a690268=1279=0269=083=159761189555=BTC-USD29004=2.208895519560=20250411-02:24:53.39847340=137=c4d54b67-40da-4c8b-9c22-961883dfa02510=066
20250411-02:24:53.451368000 : 8=FIXT.1.19=8435=534=4549=24ab46f784d1b20db435b852086e325052=20250411-02:24:53.45056=Coinbase10=164
20250411-02:24:53.451571000 : 8=FIXT.1.19=32735=X49=Coinbase56=24ab46f784d1b20db435b852086e325034=16150=TEST52=20250411-02:24:53.399536369=44262=fabc71d1-a705-413e-8282-a681c602a690268=1279=0269=2278=c5b88ea9-605d-4595-ac52-f7c3f08523ba83=159761189655=BTC-USD270=3.55271=0.6222240960=20250411-02:24:53.39847337=c4d54b67-40da-4c8b-9c22-961883dfa0255797=110=220
20250411-02:24:53.452238000 : 8=FIXT.1.19=26635=X49=Coinbase56=24ab46f784d1b20db435b852086e325034=16250=TEST52=20250411-02:24:53.399541369=44262=fabc71d1-a705-413e-8282-a681c602a690268=1279=2269=0278=c4d54b67-40da-4c8b-9c22-961883dfa02583=159761189755=BTC-USD60=20250411-02:24:53.39847358=FILLED10=085
20250411-02:24:53.478212000 : 8=FIXT.1.19=27535=X49=Coinbase56=24ab46f784d1b20db435b852086e325034=16350=TEST52=20250411-02:24:53.429155369=44262=fabc71d1-a705-413e-8282-a681c602a690268=1279=0269=183=159761189855=BTC-USD271=0.6197183160=20250411-02:24:53.42759340=137=24eaeb9e-8177-4dba-b89d-3d1febef65f310=148
20250411-02:24:53.478597000 : 8=FIXT.1.19=32735=X49=Coinbase56=24ab46f784d1b20db435b852086e325034=16450=TEST52=20250411-02:24:53.429164369=44262=fabc71d1-a705-413e-8282-a681c602a690268=1279=0269=2278=24de32b2-a7f5-469c-a714-c9b10ee2cce583=159761189955=BTC-USD270=3.54271=0.6197183160=20250411-02:24:53.42759337=24eaeb9e-8177-4dba-b89d-3d1febef65f35797=210=091
20250411-02:24:53.478806000 : 8=FIXT.1.19=28135=X49=Coinbase56=24ab46f784d1b20db435b852086e325034=16550=TEST52=20250411-02:24:53.429169369=44262=fabc71d1-a705-413e-8282-a681c602a690268=1279=2269=1278=24eaeb9e-8177-4dba-b89d-3d1febef65f383=159761190055=BTC-USD271=0.0000000060=20250411-02:24:53.42759358=FILLED10=037
20250411-02:24:53.505648000 : 8=FIXT.1.19=27935=X49=Coinbase56=24ab46f784d1b20db435b852086e325034=16650=TEST52=20250411-02:24:53.456900369=44262=fabc71d1-a705-413e-8282-a681c602a690268=1279=0269=083=159761190155=BTC-USD29004=2.208895519560=20250411-02:24:53.45572940=137=77ca9103-b4ff-4c6f-b299-21ed24dded5a10=247
20250411-02:24:53.505963000 : 8=FIXT.1.19=32735=X49=Coinbase56=24ab46f784d1b20db435b852086e325034=16750=TEST52=20250411-02:24:53.456908369=44262=fabc71d1-a705-413e-8282-a681c602a690268=1279=0269=2278=c5b88ea9-605d-4595-ac52-f7c3f08523ba83=159761190255=BTC-USD270=3.55271=0.6222240960=20250411-02:24:53.45572937=77ca9103-b4ff-4c6f-b299-21ed24dded5a5797=110=146
20250411-02:24:53.506156000 : 8=FIXT.1.19=26635=X49=Coinbase56=24ab46f784d1b20db435b852086e325034=16850=TEST52=20250411-02:24:53.456913369=44262=fabc71d1-a705-413e-8282-a681c602a690268=1279=2269=0278=77ca9103-b4ff-4c6f-b299-21ed24dded5a83=159761190355=BTC-USD60=20250411-02:24:53.45572958=FILLED10=011
20250411-02:24:53.535490000 : 8=FIXT.1.19=27535=X49=Coinbase56=24ab46f784d1b20db435b852086e325034=16950=TEST52=20250411-02:24:53.485213369=44262=fabc71d1-a705-413e-8282-a681c602a690268=1279=0269=183=159761190455=BTC-USD271=0.6197183160=20250411-02:24:53.48409740=137=9cb22509-560a-4702-b5e2-3eaf5d3ff1c310=132
20250411-02:24:53.535685000 : 8=FIXT.1.19=32735=X49=Coinbase56=24ab46f784d1b20db435b852086e325034=17050=TEST52=20250411-02:24:53.485218369=44262=fabc71d1-a705-413e-8282-a681c602a690268=1279=0269=2278=24de32b2-a7f5-469c-a714-c9b10ee2cce583=159761190555=BTC-USD270=3.54271=0.6197183160=20250411-02:24:53.48409737=9cb22509-560a-4702-b5e2-3eaf5d3ff1c35797=210=071
20250411-02:24:53.535990000 : 8=FIXT.1.19=28135=X49=Coinbase56=24ab46f784d1b20db435b852086e325034=17150=TEST52=20250411-02:24:53.485237369=44262=fabc71d1-a705-413e-8282-a681c602a690268=1279=2269=1278=9cb22509-560a-4702-b5e2-3eaf5d3ff1c383=159761190655=BTC-USD271=0.0000000060=20250411-02:24:53.48409758=FILLED10=031
20250411-02:24:53.679621000 : 8=FIXT.1.19=12035=549=Coinbase56=24ab46f784d1b20db435b852086e325034=17250=TEST52=20250411-02:24:53.631008369=4458=CLIENT_LOGOUT10=099
20250411-02:25:43.409490000 : 8=FIXT.1.19=21535=A34=149=24ab46f784d1b20db435b852086e325052=20250411-02:25:43.40256=Coinbase95=4496=e+SQxnf6enEY/TtrZCVEhqqs78lGTIcsXQjODGU73L8=98=0108=30141=Y553=24ab46f784d1b20db435b852086e3250554=akmwnltyfgb1137=910=244
20250411-02:25:43.666059000 : 8=FIXT.1.19=12535=A49=Coinbase56=24ab46f784d1b20db435b852086e325034=150=TEST52=20250411-02:25:43.618569369=198=0108=30141=Y1137=910=203
20250411-02:25:44.697814000 : 8=FIXT.1.19=17835=V34=249=24ab46f784d1b20db435b852086e325052=20250411-02:25:44.69756=Coinbase1128=9146=155=BTC-USD262=48a79146-4783-4c48-8be7-366e1d05df72263=1264=0267=2269=0269=110=157
20250411-02:25:46.099291000 : 8=FIXT.1.19=28935=X49=Coinbase56=24ab46f784d1b20db435b852086e325034=250=TEST52=20250411-02:25:46.053880369=2262=48a79146-4783-4c48-8be7-366e1d05df72268=1279=2269=1278=35bd0c73-3015-442f-95b8-35fe08d2843a83=159761279655=BTC-USD270=3.59271=0.6214689360=20250411-02:25:46.05287358=CANCELED10=022
20250411-02:25:46.232988000 : 8=FIXT.1.19=30035=X49=Coinbase56=24ab46f784d1b20db435b852086e325034=350=TEST52=20250411-02:25:46.186946369=2262=48a79146-4783-4c48-8be7-366e1d05df72268=1279=0269=183=159761279755=BTC-USD270=3.35271=0.5875706229004=2.079999994860=20250411-02:25:46.18583240=237=430eee4c-f658-419e-97b2-40715c290e6910=169
20250411-02:25:46.235956000 : 8=FIXT.1.19=32435=X49=Coinbase56=24ab46f784d1b20db435b852086e325034=450=TEST52=20250411-02:25:46.186952369=2262=48a79146-4783-4c48-8be7-366e1d05df72268=1279=0269=2278=24de32b2-a7f5-469c-a714-c9b10ee2cce583=159761279855=BTC-USD270=3.54271=0.5875706260=20250411-02:25:46.18583237=430eee4c-f658-419e-97b2-40715c290e695797=210=014
20250411-02:25:46.240500000 : 8=FIXT.1.19=27835=X49=Coinbase56=24ab46f784d1b20db435b852086e325034=550=TEST52=20250411-02:25:46.187001369=2262=48a79146-4783-4c48-8be7-366e1d05df72268=1279=2269=1278=430eee4c-f658-419e-97b2-40715c290e6983=159761279955=BTC-USD270=3.35271=060=20250411-02:25:46.18583258=FILLED10=206
20250411-02:25:46.286985000 : 8=FIXT.1.19=28135=X49=Coinbase56=24ab46f784d1b20db435b852086e325034=650=TEST52=20250411-02:25:46.241992369=2262=48a79146-4783-4c48-8be7-366e1d05df72268=1279=0269=083=159761280055=BTC-USD270=3.76271=0.6197183160=20250411-02:25:46.24037740=237=6857888c-5a50-40cf-9ef4-35ae686c260710=221
20250411-02:25:46.287312000 : 8=FIXT.1.19=32435=X49=Coinbase56=24ab46f784d1b20db435b852086e325034=750=TEST52=20250411-02:25:46.242001369=2262=48a79146-4783-4c48-8be7-366e1d05df72268=1279=0269=2278=c5b88ea9-605d-4595-ac52-f7c3f08523ba83=159761280155=BTC-USD270=3.55271=0.6197183160=20250411-02:25:46.24037737=6857888c-5a50-40cf-9ef4-35ae686c26075797=110=156
20250411-02:25:46.287677000 : 8=FIXT.1.19=28735=X49=Coinbase56=24ab46f784d1b20db435b852086e325034=850=TEST52=20250411-02:25:46.242005369=2262=48a79146-4783-4c48-8be7-366e1d05df72268=1279=2269=0278=6857888c-5a50-40cf-9ef4-35ae686c260783=159761280255=BTC-USD270=3.76271=0.0000000060=20250411-02:25:46.24037758=FILLED10=117
20250411-02:25:47.534632000 : 8=FIXT.1.19=28135=X49=Coinbase56=24ab46f784d1b20db435b852086e325034=950=TEST52=20250411-02:25:47.445734369=2262=48a79146-4783-4c48-8be7-366e1d05df72268=1279=0269=083=159761280355=BTC-USD270=3.73271=0.6197183160=20250411-02:25:47.44409040=237=8413d8d5-6d70-4b09-9ce8-28a21b96c27d10=004
20250411-02:25:47.535255000 : 8=FIXT.1.19=32535=X49=Coinbase56=24ab46f784d1b20db435b852086e325034=1050=TEST52=20250411-02:25:47.445744369=2262=48a79146-4783-4c48-8be7-366e1d05df72268=1279=0269=2278=c5b88ea9-605d-4595-ac52-f7c3f08523ba83=159761280455=BTC-USD270=3.55271=0.6197183160=20250411-02:25:47.44409037=8413d8d5-6d70-4b09-9ce8-28a21b96c27d5797=110=001
20250411-02:25:47.535520000 : 8=FIXT.1.19=28835=X49=Coinbase56=24ab46f784d1b20db435b852086e325034=1150=TEST52=20250411-02:25:47.445749369=2262=48a79146-4783-4c48-8be7-366e1d05df72268=1279=2269=0278=8413d8d5-6d70-4b09-9ce8-28a21b96c27d83=159761280555=BTC-USD270=3.73271=0.0000000060=20250411-02:25:47.44409058=FILLED10=216
20250411-02:25:47.546016000 : 8=FIXT.1.19=28135=X49=Coinbase56=24ab46f784d1b20db435b852086e325034=1250=TEST52=20250411-02:25:47.498196369=2262=48a79146-4783-4c48-8be7-366e1d05df72268=1279=0269=183=159761280655=BTC-USD270=3.3271=0.6197183160=20250411-02:25:47.49703440=237=87463ab3-8e47-4b9f-a6a9-5f9a9cf7779e10=136
20250411-02:25:47.546410000 : 8=FIXT.1.19=32535=X49=Coinbase56=24ab46f784d1b20db435b852086e325034=1350=TEST52=20250411-02:25:47.498208369=2262=48a79146-4783-4c48-8be7-366e1d05df72268=1279=0269=2278=24de32b2-a7f5-469c-a714-c9b10ee2cce583=159761280755=BTC-USD270=3.54271=0.6197183160=20250411-02:25:47.49703437=87463ab3-8e47-4b9f-a6a9-5f9a9cf7779e5797=210=222
20250411-02:25:47.546733000 : 8=FIXT.1.19=28735=X49=Coinbase56=24ab46f784d1b20db435b852086e325034=1450=TEST52=20250411-02:25:47.498212369=2262=48a79146-4783-4c48-8be7-366e1d05df72268=1279=2269=1278=87463ab3-8e47-4b9f-a6a9-5f9a9cf7779e83=159761280855=BTC-USD270=3.3271=0.0000000060=20250411-02:25:47.49703458=FILLED10=035
20250411-02:25:48.956617000 : 8=FIXT.1.19=29035=X49=Coinbase56=24ab46f784d1b20db435b852086e325034=1550=TEST52=20250411-02:25:48.911394369=2262=48a79146-4783-4c48-8be7-366e1d05df72268=1279=2269=1278=4f78ecf6-5046-4c1c-b83e-c71789a249ab83=159761280955=BTC-USD270=3.56271=0.6214689360=20250411-02:25:48.91066858=CANCELED10=232
20250411-02:25:49.090132000 : 8=FIXT.1.19=28235=X49=Coinbase56=24ab46f784d1b20db435b852086e325034=1650=TEST52=20250411-02:25:49.044916369=2262=48a79146-4783-4c48-8be7-366e1d05df72268=1279=0269=083=159761281055=BTC-USD270=3.82271=0.6214689360=20250411-02:25:49.04328940=237=9df34577-ffb6-4db2-bb5e-089a288de59610=217
20250411-02:25:49.090700000 : 8=FIXT.1.19=32535=X49=Coinbase56=24ab46f784d1b20db435b852086e325034=1750=TEST52=20250411-02:25:49.044982369=2262=48a79146-4783-4c48-8be7-366e1d05df72268=1279=0269=2278=c5b88ea9-605d-4595-ac52-f7c3f08523ba83=159761281155=BTC-USD270=3.55271=0.6214689360=20250411-02:25:49.04328937=9df34577-ffb6-4db2-bb5e-089a288de5965797=110=176
20250411-02:25:49.091094000 : 8=FIXT.1.19=28835=X49=Coinbase56=24ab46f784d1b20db435b852086e325034=1850=TEST52=20250411-02:25:49.044990369=2262=48a79146-4783-4c48-8be7-366e1d05df72268=1279=2269=0278=9df34577-ffb6-4db2-bb5e-089a288de59683=159761281255=BTC-USD270=3.82271=0.0000000060=20250411-02:25:49.04328958=FILLED10=126
20250411-02:25:49.144568000 : 8=FIXT.1.19=28135=X49=Coinbase56=24ab46f784d1b20db435b852086e325034=1950=TEST52=20250411-02:25:49.098135369=2262=48a79146-4783-4c48-8be7-366e1d05df72268=1279=0269=183=159761281355=BTC-USD270=3.3271=0.6214689360=20250411-02:25:49.09691340=237=7f20882b-168c-473a-953d-86a70665462310=079
20250411-02:25:49.144988000 : 8=FIXT.1.19=32535=X49=Coinbase56=24ab46f784d1b20db435b852086e325034=2050=TEST52=20250411-02:25:49.098144369=2262=48a79146-4783-4c48-8be7-366e1d05df72268=1279=0269=2278=24de32b2-a7f5-469c-a714-c9b10ee2cce583=159761281455=BTC-USD270=3.54271=0.6214689360=20250411-02:25:49.09691337=7f20882b-168c-473a-953d-86a7066546235797=210=162
20250411-02:25:49.145152000 : 8=FIXT.1.19=28735=X49=Coinbase56=24ab46f784d1b20db435b852086e325034=2150=TEST52=20250411-02:25:49.098149369=2262=48a79146-4783-4c48-8be7-366e1d05df72268=1279=2269=1278=7f20882b-168c-473a-953d-86a70665462383=159761281555=BTC-USD270=3.3271=0.0000000060=20250411-02:25:49.09691358=FILLED10=238
20250411-02:25:49.546819000 : 8=FIXT.1.19=28235=X49=Coinbase56=24ab46f784d1b20db435b852086e325034=2250=TEST52=20250411-02:25:49.500960369=2262=48a79146-4783-4c48-8be7-366e1d05df72268=1279=0269=183=159761281655=BTC-USD270=3.25271=0.6214689360=20250411-02:25:49.49980240=237=c9fbb708-bb0a-4540-ae82-bde6e5b7ea2b10=117
20250411-02:25:49.548507000 : 8=FIXT.1.19=32535=X49=Coinbase56=24ab46f784d1b20db435b852086e325034=2350=TEST52=20250411-02:25:49.500968369=2262=48a79146-4783-4c48-8be7-366e1d05df72268=1279=0269=2278=24de32b2-a7f5-469c-a714-c9b10ee2cce583=159761281755=BTC-USD270=3.54271=0.6214689360=20250411-02:25:49.49980237=c9fbb708-bb0a-4540-ae82-bde6e5b7ea2b5797=210=164
20250411-02:25:49.548760000 : 8=FIXT.1.19=28835=X49=Coinbase56=24ab46f784d1b20db435b852086e325034=2450=TEST52=20250411-02:25:49.500972369=2262=48a79146-4783-4c48-8be7-366e1d05df72268=1279=2269=1278=c9fbb708-bb0a-4540-ae82-bde6e5b7ea2b83=159761281855=BTC-USD270=3.25271=0.0000000060=20250411-02:25:49.49980258=FILLED10=027
20250411-02:25:49.603144000 : 8=FIXT.1.19=28235=X49=Coinbase56=24ab46f784d1b20db435b852086e325034=2550=TEST52=20250411-02:25:49.556522369=2262=48a79146-4783-4c48-8be7-366e1d05df72268=1279=0269=083=159761281955=BTC-USD270=3.83271=0.6214689360=20250411-02:25:49.55522640=237=1202076c-16a0-406c-b7d0-6d8e7772534810=160
20250411-02:25:49.603528000 : 8=FIXT.1.19=32535=X49=Coinbase56=24ab46f784d1b20db435b852086e325034=2650=TEST52=20250411-02:25:49.556530369=2262=48a79146-4783-4c48-8be7-366e1d05df72268=1279=0269=2278=c5b88ea9-605d-4595-ac52-f7c3f08523ba83=159761282055=BTC-USD270=3.55271=0.6214689360=20250411-02:25:49.55522637=1202076c-16a0-406c-b7d0-6d8e777253485797=110=105
20250411-02:25:49.603937000 : 8=FIXT.1.19=28835=X49=Coinbase56=24ab46f784d1b20db435b852086e325034=2750=TEST52=20250411-02:25:49.556535369=2262=48a79146-4783-4c48-8be7-366e1d05df72268=1279=2269=0278=1202076c-16a0-406c-b7d0-6d8e7772534883=159761282155=BTC-USD270=3.83271=0.0000000060=20250411-02:25:49.55522658=FILLED10=062
20250411-02:25:49.931426000 : 8=FIXT.1.19=91735=W49=Coinbase56=24ab46f784d1b20db435b852086e325034=2850=TEST52=20250411-02:25:49.886203369=2262=48a79146-4783-4c48-8be7-366e1d05df7283=1597612821893=N55=BTC-USD1682=full_trading268=10269=0278=24de32b2-a7f5-469c-a714-c9b10ee2cce5270=3.54271=25679.10657430269=0278=c6a6f469-efa2-413e-a05b-2c33614cb7e1270=3.54271=272279.26699541269=0278=f5fc5e68-a52c-44d3-87ef-3785312f4782270=3.48271=0.29310888269=0278=dcccb470-c535-433a-9198-4e2b4c26d99d270=3.47271=0.29311495269=0278=f05d9766-970d-44ca-aa4d-e8b2720bbda8270=3.46271=0.29026870269=0278=2c4d7d5a-33aa-4058-b546-480b6a2168a4270=3.44271=0.29828577269=0278=37dbcf16-0b3d-4f67-bc90-e36268b99e0e270=3.42271=0.30270947269=0278=4c63c0b7-30e0-4ef1-931f-0090359f978e270=3.41271=0.32158962269=0278=d6b4aa4e-d588-4c96-83aa-8e8d8accb1a4270=3.41271=0.30121104269=0278=37c1f8af-c90b-46b4-af60-c63d95716c96270=3.41271=0.6214689310=034
20250411-02:25:49.935299000 : 8=FIXT.1.19=14035=334=349=24ab46f784d1b20db435b852086e325052=20250411-02:25:49.93256=Coinbase45=2858=Tag appears more than once371=269372=W373=1310=209
20250411-02:25:49.935901000 : 8=FIXT.1.19=90835=W49=Coinbase56=24ab46f784d1b20db435b852086e325034=2950=TEST52=20250411-02:25:49.886446369=2262=48a79146-4783-4c48-8be7-366e1d05df7283=1597612821893=N55=BTC-USD1682=full_trading268=10269=0278=e8b3d8da-1663-413c-b7fb-6aba23b01440270=3.39271=0.31006477269=0278=bcbe17c3-9059-4c38-8ab8-8e78f1ef9062270=3.38271=0.32617981269=0278=57bb77fd-337f-49bc-a56f-a4e2dff851ee270=3.37271=0.31071676269=0278=ded4b51d-349f-4726-8379-6761a3576bb6270=3.33271=0.31560513269=0278=ff7aff09-38de-47ac-a3cb-9beacb0b9ad8270=3.33271=0.30682342269=0278=d1da558a-e9d2-4e11-b26e-1eb80a1a34c5270=3.32271=0.31700685269=0278=9ee34527-d4d8-4659-b2ea-cdff3dc4a8fa270=3.32271=0.32181951269=0278=7abf2220-0421-460f-9dbb-14c41564e41a270=3.32271=0.31308436269=0278=69634ec5-f71a-4990-b56d-13c3069a455a270=3.31271=0.32329458269=0278=2f333c17-a386-4d52-8ff1-eadcb99bc22f270=3.31271=0.3199922010=232
20250411-02:25:49.936846000 : 8=FIXT.1.19=14035=334=449=24ab46f784d1b20db435b852086e325052=20250411-02:25:49.93656=Coinbase45=2958=Tag appears more than once371=269372=W373=1310=215
20250411-02:25:49.936966000 : 8=FIXT.1.19=90835=W49=Coinbase56=24ab46f784d1b20db435b852086e325034=3050=TEST52=20250411-02:25:49.886695369=2262=48a79146-4783-4c48-8be7-366e1d05df7283=1597612821893=N55=BTC-USD1682=full_trading268=10269=0278=f02efc37-0b1e-470b-99ef-e31012887d73270=3.30271=0.32771570269=0278=6d430950-8078-4987-8995-e581564e368d270=3.29271=0.30702763269=0278=841f895a-cd2d-4082-9a37-b50fc19e35bf270=3.28271=0.32610801269=0278=3cf93093-e42b-4c24-95ea-c367d96427fe270=3.27271=0.33588654269=0278=f29c94bc-d1c2-4145-97b0-ecb77d81a8bf270=3.27271=0.31661408269=0278=d208c4fb-56c6-4911-85c9-77b68a5ba6ab270=3.25271=0.30961623269=0278=e88796ff-68c8-4463-914b-46e09fbaf639270=3.25271=0.33589845269=0278=06f345fb-0292-45fc-8237-9ad1a84b541c270=3.24271=0.31528507269=0278=fa20c2c7-df80-4941-9a9c-a6ef2e579480270=3.23271=0.33432448269=0278=a833d230-a749-4bf4-823e-93adc40b773d270=3.23271=0.3116587810=148
20250411-02:25:49.937780000 : 8=FIXT.1.19=14035=334=549=24ab46f784d1b20db435b852086e325052=20250411-02:25:49.93756=Coinbase45=3058=Tag appears more than once371=269372=W373=1310=209
20250411-02:25:49.937931000 : 8=FIXT.1.19=90835=W49=Coinbase56=24ab46f784d1b20db435b852086e325034=3150=TEST52=20250411-02:25:49.886945369=2262=48a79146-4783-4c48-8be7-366e1d05df7283=1597612821893=N55=BTC-USD1682=full_trading268=10269=0278=2abb6e15-b9cd-415b-8c9b-99a61c750310270=3.22271=0.32048714269=0278=ec44a6d8-ae5f-4809-89d7-0f7a3adac547270=3.21271=0.33230954269=0278=9cf61c67-c4fc-4bac-92fd-d4e2b56248aa270=3.21271=0.33583951269=0278=210b2518-bb42-461a-9c7e-b4e04c5ffcc6270=3.21271=0.32669007269=0278=2e3fa1b2-20f1-4694-9be4-322040b75152270=3.21271=0.32907979269=0278=05dd5607-92c9-4296-8cdc-27cdff004dea270=3.21271=0.32776075269=0278=87944de7-a5f1-4033-a3d8-cbc10f3a5232270=3.20271=0.32225170269=0278=30f6bb59-2469-4e6d-8fa5-13666373901f270=3.19271=0.31386496269=0278=6a5d2852-7ddc-456e-acb5-bfadcc0c1360270=3.19271=0.32157390269=0278=5d00d8a2-5aea-4836-ba19-74fe67116df8270=3.18271=0.3265104910=228
20250411-02:25:49.938673000 : 8=FIXT.1.19=14035=334=649=24ab46f784d1b20db435b852086e325052=20250411-02:25:49.93856=Coinbase45=3158=Tag appears more than once371=269372=W373=1310=212
20250411-02:25:49.938804000 : 8=FIXT.1.19=90935=W49=Coinbase56=24ab46f784d1b20db435b852086e325034=3250=TEST52=20250411-02:25:49.887195369=2262=48a79146-4783-4c48-8be7-366e1d05df7283=1597612821893=N55=BTC-USD1682=full_trading268=10269=0278=acc71746-3591-4dde-a7e2-c2795d0ad125270=3.17271=0.31577131269=0278=13982796-c2a8-4740-95e2-5aca0fdfd8bb270=3.16271=0.33021170269=0278=9f2f0737-661e-43d7-89f9-959ed5e08306270=3.16271=0.33082075269=0278=7e0e2d14-fa77-4978-8cae-d9660fd13e6d270=3.16271=0.32014975269=0278=82826a7d-848c-4516-a7b6-5ec6881609a8270=2.00271=10.00000000269=0278=590048d5-ee44-49dc-b66d-1a692e055133270=1.94271=0.51546392269=0278=22bdda11-16cd-488b-9fa9-da098dad543e270=1.94271=0.51546392269=0278=d356ef8b-596e-47e7-bf90-cc015b85fc57270=1.93271=0.52331606269=0278=aa8d48bc-97fb-4d00-b923-66d37cc8c66a270=1.93271=0.52331606269=0278=7d51dcb4-a7f8-4cca-b2d0-e902403d1b9f270=1.93271=0.5233160610=166
20250411-02:25:49.942086000 : 8=FIXT.1.19=14035=334=749=24ab46f784d1b20db435b852086e325052=20250411-02:25:49.93956=Coinbase45=3258=Tag appears more than once371=269372=W373=1310=215
20250411-02:25:49.942321000 : 8=FIXT.1.19=90835=W49=Coinbase56=24ab46f784d1b20db435b852086e325034=3350=TEST52=20250411-02:25:49.887445369=2262=48a79146-4783-4c48-8be7-366e1d05df7283=1597612821893=N55=BTC-USD1682=full_trading268=10269=0278=f7680950-3af2-4723-a6e4-5cbd528ca900270=1.93271=0.52331606269=0278=fdeff994-4866-47af-9dde-a25947a26606270=1.93271=0.52331606269=0278=65e7e2bb-023d-4936-bb4e-ff7625ba7264270=1.93271=0.52331606269=0278=53732639-572c-4cd5-b61e-e4f534d1d540270=1.93271=0.52331606269=0278=24da8927-1dd1-468b-9437-ff366f5bfa11270=1.93271=0.52331606269=0278=baa5862c-41e8-458c-83d3-c095bb68ed17270=1.93271=0.52331606269=0278=92a3c3e3-7afe-4d02-a0d8-96f512b63bb7270=1.93271=0.52331606269=0278=9d2a564e-f178-4966-9baf-5814a1c1686b270=1.93271=0.52331606269=0278=f9e6b978-87f6-4397-8d82-07cf698c123f270=1.93271=0.52331606269=0278=3e64b388-13d3-441d-b241-aa8dd6fe55e6270=1.93271=0.5233160610=233
20250411-02:25:49.970506000 : 8=FIXT.1.19=14035=334=849=24ab46f784d1b20db435b852086e325052=20250411-02:25:49.96856=Coinbase45=3358=Tag appears more than once371=269372=W373=1310=219
20250411-02:25:49.970689000 : 8=FIXT.1.19=90835=W49=Coinbase56=24ab46f784d1b20db435b852086e325034=3450=TEST52=20250411-02:25:49.887695369=2262=48a79146-4783-4c48-8be7-366e1d05df7283=1597612821893=N55=BTC-USD1682=full_trading268=10269=0278=60300433-87b0-4031-bb1e-12cf9d773d3f270=1.93271=0.52331606269=0278=1bdd5f5a-1d99-4eed-af09-c187bcbbd2d8270=1.93271=0.52331606269=0278=4ed6f6b9-77fb-4255-a188-f243dd0cdb3c270=1.93271=0.52331606269=0278=9ad1fc18-5a38-4edb-ac5c-6ac826a8a846270=1.93271=0.52331606269=0278=1c218c8c-baea-4a1f-838e-4a3a94b468e1270=1.93271=0.52331606269=0278=fd70f5e2-d2c9-472a-ab40-a775afafd73d270=1.93271=0.52331606269=0278=96f5e3a5-1c2a-4db6-a3fb-fd1f13d5d559270=1.93271=0.52331606269=0278=4a015a4c-490a-4c40-974f-9dfb7feb335d270=1.93271=0.52331606269=0278=d919363e-2c54-404f-bc0b-063e2f12bec4270=1.93271=0.52331606269=0278=d4636d6c-85c6-4ac9-9afb-70ca636f4ad4270=1.93271=0.5233160610=005
20250411-02:25:49.976041000 : 8=FIXT.1.19=14035=334=949=24ab46f784d1b20db435b852086e325052=20250411-02:25:49.97156=Coinbase45=3458=Tag appears more than once371=269372=W373=1310=215
20250411-02:25:49.976194000 : 8=FIXT.1.19=90835=W49=Coinbase56=24ab46f784d1b20db435b852086e325034=3550=TEST52=20250411-02:25:49.887945369=2262=48a79146-4783-4c48-8be7-366e1d05df7283=1597612821893=N55=BTC-USD1682=full_trading268=10269=0278=bda09690-f345-4c33-ae8b-e8c78da11b5a270=1.93271=0.52331606269=0278=1a81ae10-b700-42a0-89a3-7d7a3eea0ebb270=1.93271=0.52331606269=0278=1ace5afa-e550-4abf-a458-52e46e1b54f0270=1.93271=0.52331606269=0278=2332d1c9-67e7-457a-abfe-f5e9a8c2ea05270=1.93271=0.52331606269=0278=6afa1f19-0ec5-49fd-8b74-06a12a6c5ca9270=1.93271=0.52331606269=0278=3fa3413d-c26c-472f-9cc5-da1c48935c63270=1.93271=0.52331606269=0278=3f9e43c4-2e62-4d51-b4cb-ad207c693331270=1.93271=0.52331606269=0278=29e8bfcf-c764-4f7e-997d-09abf72bbc00270=1.93271=0.52331606269=0278=cf3e8b26-09ae-4dfb-9b84-b12a7e199a5a270=1.93271=0.52331606269=0278=08db3e51-e927-47d3-a9dd-2f887c58dc85270=1.93271=0.5233160610=081
20250411-02:25:49.977260000 : 8=FIXT.1.19=14135=334=1049=24ab46f784d1b20db435b852086e325052=20250411-02:25:49.97656=Coinbase45=3558=Tag appears more than once371=269372=W373=1310=006
20250411-02:25:49.977422000 : 8=FIXT.1.19=90835=W49=Coinbase56=24ab46f784d1b20db435b852086e325034=3650=TEST52=20250411-02:25:49.888195369=2262=48a79146-4783-4c48-8be7-366e1d05df7283=1597612821893=N55=BTC-USD1682=full_trading268=10269=0278=353ae741-9473-4cc5-9ab7-7e5de8ae55d0270=1.93271=0.52331606269=0278=4d037208-2072-480f-98ac-7be9c24f18f4270=1.93271=0.52331606269=0278=b598f678-da6e-4c01-90ed-d702c42f8a65270=1.93271=0.52331606269=0278=5f69b1a0-b5d1-4715-9be1-9bdf008d97d7270=1.93271=0.52331606269=0278=ef063d15-248a-4eae-97f4-278be5106d80270=1.93271=0.52331606269=0278=f8b20207-84bc-44e9-a2fe-9ad775e2ecb1270=1.93271=0.52331606269=0278=75bce2b7-bc58-4479-8bfb-144f88f2262b270=1.93271=0.52331606269=0278=1f6e2a79-8b10-4a7f-89de-0f1fa03692c7270=1.93271=0.52331606269=0278=d1b80bf5-9b17-44b4-9577-6fe71170b578270=1.93271=0.52331606269=0278=b891e26a-c20c-4fce-ba1c-487fe139a4cc270=1.93271=0.5233160610=120
20250411-02:25:49.978266000 : 8=FIXT.1.19=14135=334=1149=24ab46f784d1b20db435b852086e325052=20250411-02:25:49.97756=Coinbase45=3658=Tag appears more than once371=269372=W373=1310=009
20250411-02:25:49.978381000 : 8=FIXT.1.19=90835=W49=Coinbase56=24ab46f784d1b20db435b852086e325034=3750=TEST52=20250411-02:25:49.888445369=2262=48a79146-4783-4c48-8be7-366e1d05df7283=1597612821893=N55=BTC-USD1682=full_trading268=10269=0278=5d06d3f6-3189-4394-b3c5-6a2bda14b6d1270=1.93271=0.52331606269=0278=e5791c0f-3937-4a66-9b98-26f79a3891be270=1.93271=0.52331606269=0278=c62591c6-7dfa-46a7-8f20-6a5f22804999270=1.93271=0.52331606269=0278=7c503558-c0b8-457b-8c46-71ece3f7fc8a270=1.93271=0.52331606269=0278=f763bb56-2f21-4a9b-bd48-f84dc1bd5ee5270=1.93271=0.52331606269=0278=42214b03-1fc2-46b3-9e83-91b23a510e5a270=1.93271=0.52331606269=0278=1c7c52ed-7d39-4326-b3b8-98f05a9b3ef0270=1.93271=0.52331606269=0278=3313309e-45e7-4e7b-8c55-4f9a8ec1b351270=1.93271=0.52331606269=0278=78801ffb-ec5a-4c74-9d08-3e86fd9db4dd270=1.93271=0.52331606269=0278=abe6eea4-1d9c-47d7-847f-2f44aa561b3f270=1.93271=0.5233160610=031
20250411-02:25:49.979234000 : 8=FIXT.1.19=14135=334=1249=24ab46f784d1b20db435b852086e325052=20250411-02:25:49.97856=Coinbase45=3758=Tag appears more than once371=269372=W373=1310=012
20250411-02:25:50.153706000 : 8=FIXT.1.19=90835=W49=Coinbase56=24ab46f784d1b20db435b852086e325034=3850=TEST52=20250411-02:25:49.888695369=2262=48a79146-4783-4c48-8be7-366e1d05df7283=1597612821893=N55=BTC-USD1682=full_trading268=10269=0278=6a6eb56d-2010-43e2-b78e-5f098081bb64270=1.93271=0.52331606269=0278=b53c01ff-f450-4b05-8ad1-e7894b45e0e0270=1.93271=0.52331606269=0278=4747863e-c0a6-4ef5-8faf-e8934bca4f8b270=1.93271=0.52331606269=0278=81a8a629-57f4-4e3a-ac25-2e9ee1f357c2270=1.93271=0.52331606269=0278=1e239259-7be4-476a-845d-1b92fd951d8b270=1.93271=0.52331606269=0278=189eb272-48f9-4915-b7e1-a86dcc505c4a270=1.93271=0.52331606269=0278=0562b9f7-aae3-4961-bd97-f5b8cde0ec34270=1.93271=0.52331606269=0278=5103331b-7300-487b-bc2c-a6032bf4be7e270=1.93271=0.52331606269=0278=78ac85ac-2478-4991-a084-7286982b77cc270=1.93271=0.52331606269=0278=6993b26d-d6dc-4f99-8a53-9500ae5b4ff1270=1.93271=0.5233160610=140
20250411-02:25:50.154899000 : 8=FIXT.1.19=14135=334=1349=24ab46f784d1b20db435b852086e325052=20250411-02:25:50.15456=Coinbase45=3858=Tag appears more than once371=269372=W373=1310=248
20250411-02:25:50.155044000 : 8=FIXT.1.19=91935=W49=Coinbase56=24ab46f784d1b20db435b852086e325034=3950=TEST52=20250411-02:25:49.888945369=2262=48a79146-4783-4c48-8be7-366e1d05df7283=1597612821893=N55=BTC-USD1682=full_trading268=10269=0278=1c96ab9d-04a6-465a-87e5-3ed33970178f270=1.93271=0.52331606269=0278=6fc0282b-d538-4aa3-8982-bda02bb1b054270=1.93271=0.52331606269=0278=80870aa3-04a2-4d2a-8669-93215130ffee270=1.93271=0.52331606269=0278=b274e872-6923-45fd-b48a-68e685e769cb270=1.93271=0.52331606269=0278=2d4364c0-239c-4f4b-8ce4-2acfe0bb343d270=1.12271=1.00000000269=0278=8fa16a4f-377f-4deb-9a8e-1020aed9edf4270=1.00271=1.00000000269=1278=c5b88ea9-605d-4595-ac52-f7c3f08523ba270=3.55271=2564.38274225269=1278=81523bd3-8912-4789-8761-89a9ee42794b270=3.55271=0.30518966269=1278=60fc75ca-0052-40b7-9f18-a6aad9d31b84270=3.56271=18037.00000000269=1278=ad00e2cd-d925-46a4-9e7e-941c6faed2c7270=3.57271=18027.0000000010=184
20250411-02:25:50.155798000 : 8=FIXT.1.19=14135=334=1449=24ab46f784d1b20db435b852086e325052=20250411-02:25:50.15556=Coinbase45=3958=Tag appears more than once371=269372=W373=1310=251
20250411-02:25:50.155984000 : 8=FIXT.1.19=92835=W49=Coinbase56=24ab46f784d1b20db435b852086e325034=4050=TEST52=20250411-02:25:49.889195369=2262=48a79146-4783-4c48-8be7-366e1d05df7283=1597612821893=N55=BTC-USD1682=full_trading268=10269=1278=fec191b5-64da-4a15-ab4b-36a0d3d10750270=3.57271=0.29025301269=1278=b570d5e7-e6d2-48a5-8ea6-577412381e01270=3.57271=0.62146893269=1278=02a780aa-8154-4638-a5ca-53b8198cc724270=3.58271=16937.00000000269=1278=911349fb-1960-4904-9a38-0e2497fb7ccb270=3.58271=0.29896312269=1278=d91e89d4-ac5c-4853-9879-ec8ff5e00a71270=3.59271=17163.00000000269=1278=341d0ad8-6c15-4b5e-aebb-e3caa5af575c270=3.60271=17926.00000000269=1278=9d239e03-1215-4cc7-ad44-3f4097ee70ea270=3.61271=18058.08928020269=1278=dbb0f332-4189-4df5-879b-e55860b13def270=3.62271=0.28062774269=1278=f7639c39-7e8b-44d1-a2f2-9807e2a3228c270=3.62271=0.27709851269=1278=83be9389-2099-4173-a322-b0933bc99358270=3.62271=19973.0000000010=070
20250411-02:25:50.156752000 : 8=FIXT.1.19=14135=334=1549=24ab46f784d1b20db435b852086e325052=20250411-02:25:50.15656=Coinbase45=4058=Tag appears more than once371=269372=W373=1310=245
20250411-02:25:50.156929000 : 8=FIXT.1.19=92035=W49=Coinbase56=24ab46f784d1b20db435b852086e325034=4150=TEST52=20250411-02:25:49.889445369=2262=48a79146-4783-4c48-8be7-366e1d05df7283=1597612821893=N55=BTC-USD1682=full_trading268=10269=1278=b89abc22-6b6c-4474-b3fc-ffe21f05cd4e270=3.63271=20016.00000000269=1278=ce0af8a3-149c-4603-905a-be65625fe014270=3.64271=0.27806002269=1278=94b8615f-6fa7-4dc9-bbfa-435fe535bebc270=3.64271=22352.63489459269=1278=8e4ddffe-04fe-418a-8103-cd8143be68f8270=3.65271=19640.75109509269=1278=0a82a322-1508-45c4-a7d4-419c43806baa270=3.65271=0.62146893269=1278=cae3885d-f5b2-4de1-830c-0085e27bbb69270=3.69271=0.27722678269=1278=512e457a-a9d3-4274-8f25-345fa0dd60dc270=3.70271=0.62146893269=1278=b9732128-11b1-44fd-bea3-94da9fc853fb270=3.71271=0.28488329269=1278=818b83a4-e14e-4ad5-b094-6733f0504003270=3.75271=0.27930225269=1278=3e6990a0-8ef4-4968-8ee8-89b7346c197d270=3.76271=0.2813136510=035
20250411-02:25:50.157843000 : 8=FIXT.1.19=14135=334=1649=24ab46f784d1b20db435b852086e325052=20250411-02:25:50.15756=Coinbase45=4158=Tag appears more than once371=269372=W373=1310=248
20250411-02:25:50.161235000 : 8=FIXT.1.19=91435=W49=Coinbase56=24ab46f784d1b20db435b852086e325034=4250=TEST52=20250411-02:25:49.889695369=2262=48a79146-4783-4c48-8be7-366e1d05df7283=1597612821893=N55=BTC-USD1682=full_trading268=10269=1278=342794c8-a9d2-4aa5-9886-a819398d69c6270=3.88271=0.27719712269=1278=2839680b-48b3-4f53-86b1-9269987275e7270=3.91271=0.26621275269=1278=fd7b5361-29f8-4b35-bae5-232a64f657b4270=3.95271=0.26131406269=1278=5edaeed0-fae9-4f36-8c77-6fbedf61eefc270=4.02271=0.25091227269=1278=fdbbfd04-ba67-4b23-bbc1-f87f929e7e81270=4.07271=0.24812642269=1278=534b2a85-0852-420d-928b-70cdb6ba2457270=4.10271=0.26961968269=1278=b009f8a1-4a39-493b-b96e-d783e981c915270=4.26271=0.25019574269=1278=729a899c-ac2d-4541-b0a2-cbdd5df9bf98270=10.00271=10.00000000269=1278=eb1e5d45-d081-4ef8-a83e-1f5348fbda96270=10.00271=10.00000000269=1278=0cd67977-85eb-45fa-ae72-d45b92ca24f4270=10.00271=10.0000000010=000
20250411-02:25:50.162303000 : 8=FIXT.1.19=14135=334=1749=24ab46f784d1b20db435b852086e325052=20250411-02:25:50.16156=Coinbase45=4258=Tag appears more than once371=269372=W373=1310=245
20250411-02:25:50.162409000 : 8=FIXT.1.19=92835=W49=Coinbase56=24ab46f784d1b20db435b852086e325034=4350=TEST52=20250411-02:25:49.889946369=2262=48a79146-4783-4c48-8be7-366e1d05df7283=1597612821893=N55=BTC-USD1682=full_trading268=10269=1278=5d931559-6758-4b75-9d6d-6438d25b497f270=10.00271=10.00000000269=1278=57e43d1d-644a-493e-acd3-69dc5e64dcde270=10.00271=10.00000000269=1278=c1566121-2b63-494d-ac2d-973e9f0115c0270=10.00271=10.00000000269=1278=d0c4a771-9035-4db9-ae7b-ad2d1db5646d270=10.00271=10.00000000269=1278=52c644ea-628a-4576-8e7e-27ec4c90398b270=10.00271=10.00000000269=1278=c3483f66-d8ce-489a-90b9-2bce69e054ee270=10.00271=10.00000000269=1278=55992a5c-cbcd-464a-8f8d-8b58e81e5c0b270=10.00271=10.00000000269=1278=19077009-6f26-4e2d-9dab-04a28231b752270=10.00271=10.00000000269=1278=692097d1-c978-4024-95e9-2bf348b64bbd270=10.00271=10.00000000269=1278=99a92935-11b7-4f21-a64c-c746b53d1777270=10.00271=10.0000000010=187
20250411-02:25:50.163210000 : 8=FIXT.1.19=14135=334=1849=24ab46f784d1b20db435b852086e325052=20250411-02:25:50.16256=Coinbase45=4358=Tag appears more than once371=269372=W373=1310=248
20250411-02:25:50.163316000 : 8=FIXT.1.19=93635=W49=Coinbase56=24ab46f784d1b20db435b852086e325034=4450=TEST52=20250411-02:25:49.890196369=2262=48a79146-4783-4c48-8be7-366e1d05df7283=1597612821893=N55=BTC-USD1682=full_trading268=10269=1278=dc024b0b-0337-4215-9669-5e5636834397270=10.00271=10.00000000269=1278=c90fcc3a-a36c-4c14-b57f-6db78762e017270=10.00271=10.00000000269=1278=7841891a-bb7c-4034-97c1-41164185edc7270=1000.00271=3.10000000269=1278=381c9fa7-1add-4dd2-9233-f41e2c8821fe270=1000.00271=3.10000000269=1278=928e65c2-7e2d-478b-9310-414fb77f5aae270=1000.00271=3.10000000269=1278=ad4bd3ac-9276-40d5-90f9-e47b1d8ee953270=1000.00271=3.10000000269=1278=79e799dc-4a3d-4922-ad1a-f74eb7eff789270=1000.00271=3.10000000269=1278=04f642b7-750f-4967-b786-0d48eea0f158270=1000.00271=3.10000000269=1278=d0ad653d-3272-4a3b-ba7a-a52029a67a92270=1000.00271=3.10000000269=1278=cad40464-4c62-4bf3-8444-c487fcc8dd01270=1000.00271=3.1000000010=165
20250411-02:25:50.164040000 : 8=FIXT.1.19=14135=334=1949=24ab46f784d1b20db435b852086e325052=20250411-02:25:50.16356=Coinbase45=4458=Tag appears more than once371=269372=W373=1310=251
20250411-02:25:50.164145000 : 8=FIXT.1.19=93835=W49=Coinbase56=24ab46f784d1b20db435b852086e325034=4550=TEST52=20250411-02:25:49.890446369=2262=48a79146-4783-4c48-8be7-366e1d05df7283=1597612821893=N55=BTC-USD1682=full_trading268=10269=1278=426c6428-d481-4ff7-9de3-f00ff219d654270=1000.00271=3.10000000269=1278=1ed1152d-8c1a-4b29-acdd-bbd1a5c5f35f270=1000.00271=3.10000000269=1278=66526051-b5cb-442f-af90-c609be0a9796270=1000.00271=3.10000000269=1278=f68e4659-5785-4ee9-ac24-3186640a2752270=1000.00271=3.10000000269=1278=38070d38-80a9-4898-8ef7-a0a9da5a4123270=1000.00271=3.10000000269=1278=e4d2d308-ed11-49db-850e-3cbd8258395d270=1000.00271=3.10000000269=1278=d6cfaadc-97ea-43c1-898d-40faea9c1477270=1000.00271=3.10000000269=1278=36876bea-9e3a-4018-b0ac-b75cb8c16953270=1000.00271=3.10000000269=1278=eb244bc5-49e8-4aa3-af8b-3d1a67c90a08270=1000.00271=3.10000000269=1278=3efba776-29ad-4aeb-82d8-0824f161471e270=1000.00271=3.1000000010=169
20250411-02:25:50.164839000 : 8=FIXT.1.19=14135=334=2049=24ab46f784d1b20db435b852086e325052=20250411-02:25:50.16456=Coinbase45=4558=Tag appears more than once371=269372=W373=1310=245
20250411-02:25:50.164965000 : 8=FIXT.1.19=93835=W49=Coinbase56=24ab46f784d1b20db435b852086e325034=4650=TEST52=20250411-02:25:49.890696369=2262=48a79146-4783-4c48-8be7-366e1d05df7283=1597612821893=N55=BTC-USD1682=full_trading268=10269=1278=de0ddebd-0ca8-4eca-9985-77c10c8629a9270=1000.00271=3.10000000269=1278=dde4408a-fb6b-441c-a7f3-7b8b23ffdb1f270=1000.00271=3.10000000269=1278=3ebd6434-070f-4b4d-8cf3-00368112466d270=1000.00271=3.10000000269=1278=7aa98e13-65f3-4058-9f91-c1f452d02710270=1000.00271=3.10000000269=1278=e86a1fec-3610-460d-8d85-4e1e222ee159270=1000.00271=3.10000000269=1278=6dfac057-72b1-4f2c-b110-03766dea0d31270=1000.00271=3.10000000269=1278=bbb7d0ea-d251-4612-b53e-e528cc0a24ab270=1000.00271=3.10000000269=1278=0782ca37-48cf-4ff3-a74a-35674661586c270=1000.00271=3.10000000269=1278=aead437d-4b62-457f-ac83-62c7cc329fd1270=1000.00271=3.10000000269=1278=af5d47bc-a008-4567-b24f-b0298f250471270=1000.00271=3.1000000010=138
20250411-02:25:50.165763000 : 8=FIXT.1.19=14135=334=2149=24ab46f784d1b20db435b852086e325052=20250411-02:25:50.16556=Coinbase45=4658=Tag appears more than once371=269372=W373=1310=248
20250411-02:25:50.165862000 : 8=FIXT.1.19=93835=W49=Coinbase56=24ab46f784d1b20db435b852086e325034=4750=TEST52=20250411-02:25:49.890946369=2262=48a79146-4783-4c48-8be7-366e1d05df7283=1597612821893=N55=BTC-USD1682=full_trading268=10269=1278=4c260f58-c427-4a9a-969a-44024ae0c714270=1000.00271=3.10000000269=1278=8c7672e5-7ee8-4fbd-8fdf-7e74e9a77db7270=1000.00271=3.10000000269=1278=b53ec3cc-9abe-4570-b903-34d52148073e270=1000.00271=3.10000000269=1278=37ce984a-0387-4ac9-9094-b83f722036ba270=1000.00271=3.10000000269=1278=0d383649-dc6c-4df2-b821-aa0018f132c7270=1000.00271=3.10000000269=1278=e39ae0ce-9e7f-4f0d-a765-5308d473bb61270=1000.00271=3.10000000269=1278=4882324e-3b5c-4b7a-b096-e8c6d9888671270=1000.00271=3.10000000269=1278=6e5c7dbd-a2cc-401f-a5b2-3902088f4ab2270=1000.00271=3.10000000269=1278=10ffac08-946a-4a30-b57a-0d78450345d9270=1000.00271=3.10000000269=1278=67784af5-72bf-4d16-a6b3-25336e2c1843270=1000.00271=3.1000000010=252
20250411-02:25:50.166532000 : 8=FIXT.1.19=14135=334=2249=24ab46f784d1b20db435b852086e325052=20250411-02:25:50.16656=Coinbase45=4758=Tag appears more than once371=269372=W373=1310=251
20250411-02:25:50.166627000 : 8=FIXT.1.19=93835=W49=Coinbase56=24ab46f784d1b20db435b852086e325034=4850=TEST52=20250411-02:25:49.891196369=2262=48a79146-4783-4c48-8be7-366e1d05df7283=1597612821893=N55=BTC-USD1682=full_trading268=10269=1278=4d8b3bbc-0dc2-4044-875c-c079ec538136270=1000.00271=3.10000000269=1278=dfba5f1e-21f5-48e3-adce-b8b6bfe71467270=1000.00271=3.10000000269=1278=e51b4e33-5eaa-46ef-936b-a74a890397e8270=1000.00271=3.10000000269=1278=8cf5dfa8-858b-48a3-9d94-78522c257473270=1000.00271=3.10000000269=1278=a153b9d2-993d-4f03-a974-b8a081e128e8270=1000.00271=3.10000000269=1278=1eebe866-0f6e-4d4a-a28b-78f4e3368b0a270=1000.00271=3.10000000269=1278=300132d8-113f-4bf7-ba0c-4d93a272f55b270=1000.00271=3.10000000269=1278=757f3122-27d2-4f32-90b8-ead1eef9b936270=1000.00271=3.10000000269=1278=2b68b5de-4153-4cac-ace3-102e4fa788fd270=1000.00271=3.10000000269=1278=b01f252a-1657-4df0-a122-58a23109a7c2270=1000.00271=3.1000000010=143
20250411-02:25:50.167385000 : 8=FIXT.1.19=14135=334=2349=24ab46f784d1b20db435b852086e325052=20250411-02:25:50.16656=Coinbase45=4858=Tag appears more than once371=269372=W373=1310=253
20250411-02:25:50.167477000 : 8=FIXT.1.19=93835=W49=Coinbase56=24ab46f784d1b20db435b852086e325034=4950=TEST52=20250411-02:25:49.891446369=2262=48a79146-4783-4c48-8be7-366e1d05df7283=1597612821893=N55=BTC-USD1682=full_trading268=10269=1278=dbc57e4e-6abd-4d66-8d18-bd13caaa77b1270=1000.00271=3.10000000269=1278=948b05dc-a481-409f-b8ad-a502eb595906270=1000.00271=3.10000000269=1278=e00f9703-6e16-4237-a2c6-701829d11bf1270=1000.00271=3.10000000269=1278=fd52f47a-3f11-47bc-9952-9708617d0ecd270=1000.00271=3.10000000269=1278=f7f75b14-27c3-469c-89fb-6a98b43c61bf270=1000.00271=3.10000000269=1278=25dbeb09-7901-4280-b0c3-720d7ed03d7d270=1000.00271=3.10000000269=1278=52164a1f-599f-4c43-a9ed-f93403506e67270=1000.00271=3.10000000269=1278=c71c35ea-f60f-4a41-b43a-4947bbcbafad270=1000.00271=3.10000000269=1278=2de342bc-a1be-46f3-9fc6-731297726934270=1000.00271=3.10000000269=1278=7ff4c5fc-bc9b-4845-940b-4837a672e13a270=1000.00271=3.1000000010=105
20250411-02:25:50.168131000 : 8=FIXT.1.19=14135=334=2449=24ab46f784d1b20db435b852086e325052=20250411-02:25:50.16756=Coinbase45=4958=Tag appears more than once371=269372=W373=1310=000
20250411-02:25:50.168220000 : 8=FIXT.1.19=93835=W49=Coinbase56=24ab46f784d1b20db435b852086e325034=5050=TEST52=20250411-02:25:49.891696369=2262=48a79146-4783-4c48-8be7-366e1d05df7283=1597612821893=N55=BTC-USD1682=full_trading268=10269=1278=2d270775-33eb-4328-8dad-7d206612f9f6270=1000.00271=3.10000000269=1278=c4754378-f787-4100-81af-564443a86a91270=1000.00271=3.10000000269=1278=59e16255-05eb-4fdc-8be1-3c4f83fc094e270=1000.00271=3.10000000269=1278=041b2f98-1185-49cb-964a-f0456b71e692270=1000.00271=3.10000000269=1278=9a2f3529-481e-4e50-a123-7a2095fe6b2c270=1000.00271=3.10000000269=1278=9ed552a3-3295-4878-85dd-87b7b5590212270=1000.00271=3.10000000269=1278=54bec5c2-bafd-4d7d-851d-59e3553a053f270=1000.00271=3.10000000269=1278=543c1acf-52f2-442b-a893-f7aa9a5dfbd1270=1000.00271=3.10000000269=1278=fec999be-cbd0-42ef-b9c3-82ca92ef0b58270=1000.00271=3.10000000269=1278=24528176-3fc6-45b2-b2f3-9f784c01495a270=1000.00271=3.1000000010=135
20250411-02:25:50.169013000 : 8=FIXT.1.19=14135=334=2549=24ab46f784d1b20db435b852086e325052=20250411-02:25:50.16856=Coinbase45=5058=Tag appears more than once371=269372=W373=1310=250
20250411-02:25:50.169131000 : 8=FIXT.1.19=93835=W49=Coinbase56=24ab46f784d1b20db435b852086e325034=5150=TEST52=20250411-02:25:49.891946369=2262=48a79146-4783-4c48-8be7-366e1d05df7283=1597612821893=N55=BTC-USD1682=full_trading268=10269=1278=12081678-66a6-4435-a3d7-b65f959cf2ac270=1000.00271=3.10000000269=1278=e7fb6165-8f1a-4b5e-b095-e232b83ee951270=1000.00271=3.10000000269=1278=83ce6582-410a-40bf-9831-8f3d20e3a629270=1000.00271=3.10000000269=1278=bc3a930b-0567-46ba-86a4-712f76466b0b270=1000.00271=3.10000000269=1278=15704973-f5ff-457d-ab31-8f99bb76bf7e270=1000.00271=3.10000000269=1278=7159045b-cbd5-458f-b91f-9fa5241b14b5270=1000.00271=3.10000000269=1278=9fa52a90-f03f-4940-b5ee-39ab937b86f1270=1000.00271=3.10000000269=1278=220f55cd-a279-4bf0-9c80-1dca086d85dc270=1000.00271=3.10000000269=1278=2b1eb468-6bcd-4117-a7c0-214d643ddad4270=1000.00271=3.10000000269=1278=cc23185d-e72e-42cb-8210-61bab29cd778270=1000.00271=3.1000000010=117
20250411-02:25:50.170003000 : 8=FIXT.1.19=14135=334=2649=24ab46f784d1b20db435b852086e325052=20250411-02:25:50.16956=Coinbase45=5158=Tag appears more than once371=269372=W373=1310=253
20250411-02:25:50.170096000 : 8=FIXT.1.19=93835=W49=Coinbase56=24ab46f784d1b20db435b852086e325034=5250=TEST52=20250411-02:25:49.892196369=2262=48a79146-4783-4c48-8be7-366e1d05df7283=1597612821893=N55=BTC-USD1682=full_trading268=10269=1278=69bb228b-973b-4176-8708-3231cc40102a270=1000.00271=3.10000000269=1278=2ec8035d-7962-4195-8388-c9fbad52ac8a270=1000.00271=3.10000000269=1278=7d39e416-0b7b-471f-a9ac-455ab1bce5a7270=1000.00271=3.10000000269=1278=7067378d-2a65-41f2-acb0-ef30ddbc3e5a270=1000.00271=3.10000000269=1278=bf3fde78-6cff-4477-b381-4b5d2e68f36f270=1000.00271=3.10000000269=1278=93a2a8a3-61d4-410c-9446-8eabaafc5f29270=1000.00271=3.10000000269=1278=5afddb61-63ab-417b-a28a-41c4c03a6612270=1000.00271=3.10000000269=1278=a4280417-189c-4f76-9d2e-6ec652010bf5270=1000.00271=3.10000000269=1278=ddeb78a2-e110-4828-ba3d-c9b4837e7dd7270=1000.00271=3.10000000269=1278=fcec6c90-441a-4f4a-a94e-9003355657ef270=1000.00271=3.1000000010=218
20250411-02:25:50.170799000 : 8=FIXT.1.19=14135=334=2749=24ab46f784d1b20db435b852086e325052=20250411-02:25:50.17056=Coinbase45=5258=Tag appears more than once371=269372=W373=1310=247
20250411-02:25:50.170891000 : 8=FIXT.1.19=93835=W49=Coinbase56=24ab46f784d1b20db435b852086e325034=5350=TEST52=20250411-02:25:49.892446369=2262=48a79146-4783-4c48-8be7-366e1d05df7283=1597612821893=N55=BTC-USD1682=full_trading268=10269=1278=6db15389-dfb3-4156-8a4e-ce2ac80f2b15270=1000.00271=3.10000000269=1278=47dfefc3-6f05-4b57-8aec-2bf3e6c70c2d270=1000.00271=3.10000000269=1278=fb9fd019-4b4f-4880-82bb-3df6d1ef468a270=1000.00271=3.10000000269=1278=2cff9acd-42cb-43a5-8d50-51e676b7e763270=1000.00271=3.10000000269=1278=6e6eeb59-4728-4811-9a44-c857df6aca42270=1000.00271=3.10000000269=1278=81798560-263f-4819-a528-5f3fbbc7b042270=1000.00271=3.10000000269=1278=81fbf9a8-82f4-4fe4-9fa5-3773b212ebf4270=1000.00271=3.10000000269=1278=5d3b9566-276d-47fe-a111-12c17f53f501270=1000.00271=3.10000000269=1278=8eb1b3b3-c813-48b1-b839-993672108d91270=1000.00271=3.10000000269=1278=4feb6e93-6149-481b-8d58-e1c8e6c5cda1270=1000.00271=3.1000000010=165
20250411-02:25:50.171489000 : 8=FIXT.1.19=14135=334=2849=24ab46f784d1b20db435b852086e325052=20250411-02:25:50.17156=Coinbase45=5358=Tag appears more than once371=269372=W373=1310=250
20250411-02:25:50.171572000 : 8=FIXT.1.19=93835=W49=Coinbase56=24ab46f784d1b20db435b852086e325034=5450=TEST52=20250411-02:25:49.892696369=2262=48a79146-4783-4c48-8be7-366e1d05df7283=1597612821893=N55=BTC-USD1682=full_trading268=10269=1278=f8611e72-4056-4b7c-9779-4d54cd151d44270=1000.00271=3.10000000269=1278=7a129f7c-d9ba-4ea3-a267-b7d82b2e07d9270=1000.00271=3.10000000269=1278=01f359f0-c38f-416b-af00-183907218793270=1000.00271=3.10000000269=1278=11741cec-9c08-4a20-99dc-6b9f63130b0e270=1000.00271=3.10000000269=1278=08db2574-ad52-4520-ab5b-c3c7591eb781270=1000.00271=3.10000000269=1278=b06f2249-179c-4a15-8e98-7b76083b808b270=1000.00271=3.10000000269=1278=9e88fede-6d19-4c1f-863b-5a7d66781436270=1000.00271=3.10000000269=1278=75e1d8b4-7201-41fe-a687-7d93420af323270=1000.00271=3.10000000269=1278=d00aa7dd-ce7f-4f8b-9a2e-880c1ea30845270=1000.00271=3.10000000269=1278=584a483f-23bf-4d8b-809f-69cf3c110f60270=1000.00271=3.1000000010=026
20250411-02:25:50.172308000 : 8=FIXT.1.19=14135=334=2949=24ab46f784d1b20db435b852086e325052=20250411-02:25:50.17156=Coinbase45=5458=Tag appears more than once371=269372=W373=1310=252
